{
    "registryname": "Giga_CosmicCasket",
    "localizedname": "§7熵能§5奇点§e演算阵列§f",
    "failure-action": "still",
    "has_factroy": "yes",
    "requires-blueprint": false,
    "factory-only": true,
    "color": "191970",
    "parts": [
        {
            "x": 0,
            "y": 0,
            "z": 0,
            "elements": [
                "modularmachinery:blockcontroller@2"
            ]
        },
        {
            "x": -11,
            "y": 2,
            "z": 15,
            "elements": [
                "contenttweaker:spacexmachineblock@0"
            ]
        },
        {
            "x": -3,
            "y": 0,
            "z": 5,
            "elements": [
                "contenttweaker:asteroidcontrolblock@0"
            ]
        },
        {
            "x": 1,
            "y": -14,
            "z": 15,
            "elements": [
                "contenttweaker:spacexmachineblock@0"
            ]
        },
        {
            "x": -1,
            "y": 8,
            "z": 23,
            "elements": [
                "contenttweaker:spacexmachineblock@0"
            ]
        },
        {
            "x": -9,
            "y": 0,
            "z": 20,
            "elements": [
                "contenttweaker:dimensiontwistblock@0"
            ]
        },
        {
            "x": 0,
            "y": -7,
            "z": 24,
            "elements": [
                "contenttweaker:stablestructure@0"
            ]
        },
        {
            "x": -7,
            "y": 1,
            "z": 21,
            "elements": [
                "contenttweaker:dimensiontwistblock@0"
            ]
        },
        {
            "x": -5,
            "y": -1,
            "z": 21,
            "elements": [
                "contenttweaker:spacexmachineblock@0"
            ]
        },
        {
            "x": -1,
            "y": 7,
            "z": 23,
            "elements": [
                "contenttweaker:spacexmachineblock@0"
            ]
        },
        {
            "x": 3,
            "y": -2,
            "z": 23,
            "elements": [
                "contenttweaker:spacexmachineblock@0"
            ]
        },
        {
            "x": 8,
            "y": -1,
            "z": 7,
            "elements": [
                "contenttweaker:spacexmachineblock@0"
            ]
        },
        {
            "x": 1,
            "y": 14,
            "z": 16,
            "elements": [
                "contenttweaker:spacexmachineblock@0"
            ]
        },
        {
            "x": 0,
            "y": -6,
            "z": 24,
            "elements": [
                "contenttweaker:stablestructure@0"
            ]
        },
        {
            "x": 1,
            "y": 0,
            "z": 0,
            "elements": [
                "casings_all",
                "modularmachinery:blockmepatternprovider",
                "modularmachinery:blockmepatternmirrorimage"
            ]
        },
        {
            "x": 2,
            "y": 0,
            "z": 22,
            "elements": [
                "contenttweaker:asteroidcontrolblock@0"
            ]
        },
        {
            "x": 0,
            "y": -9,
            "z": 24,
            "elements": [
                "contenttweaker:spacexmachineblock@0"
            ]
        },
        {
            "x": -12,
            "y": 1,
            "z": 11,
            "elements": [
                "contenttweaker:spacexmachineblock@0"
            ]
        },
        {
            "x": -6,
            "y": -1,
            "z": 21,
            "elements": [
                "contenttweaker:spacexmachineblock@0"
            ]
        },
        {
            "x": 9,
            "y": 0,
            "z": 7,
            "elements": [
                "contenttweaker:novamatrix@0"
            ]
        },
        {
            "x": -10,
            "y": 0,
            "z": 12,
            "elements": [
                "contenttweaker:dimensiontwistblock@0"
            ]
        },
        {
            "x": -10,
            "y": -1,
            "z": 11,
            "elements": [
                "contenttweaker:spacexmachineblock@0"
            ]
        },
        {
            "x": 1,
            "y": -13,
            "z": 16,
            "elements": [
                "contenttweaker:spacexmachineblock@0"
            ]
        },
        {
            "x": 0,
            "y": -11,
            "z": 21,
            "elements": [
                "contenttweaker:stablestructure@0"
            ]
        },
        {
            "x": -1,
            "y": 9,
            "z": 23,
            "elements": [
                "contenttweaker:spacexmachineblock@0"
            ]
        },
        {
            "x": 0,
            "y": -8,
            "z": 24,
            "elements": [
                "contenttweaker:spacexmachineblock@0"
            ]
        },
        {
            "x": -1,
            "y": -10,
            "z": 22,
            "elements": [
                "contenttweaker:spacexmachineblock@0"
            ]
        },
        {
            "x": -10,
            "y": 1,
            "z": 12,
            "elements": [
                "contenttweaker:spacexmachineblock@0"
            ]
        },
        {
            "x": -10,
            "y": 1,
            "z": 16,
            "elements": [
                "contenttweaker:dimensiontwistblock@0"
            ]
        },
        {
            "x": 9,
            "y": 1,
            "z": 7,
            "elements": [
                "contenttweaker:dimensiontwistblock@0"
            ]
        },
        {
            "x": 2,
            "y": 0,
            "z": 0,
            "elements": [
                "casings_all",
                "modularmachinery:blockmepatternprovider",
                "modularmachinery:blockmepatternmirrorimage"
            ]
        },
        {
            "x": 6,
            "y": 1,
            "z": 4,
            "elements": [
                "contenttweaker:dimensiontwistblock@0"
            ]
        },
        {
            "x": 4,
            "y": 1,
            "z": 23,
            "elements": [
                "contenttweaker:dimensiontwistblock@0"
            ]
        },
        {
            "x": 9,
            "y": 2,
            "z": 7,
            "elements": [
                "contenttweaker:spacexmachineblock@0"
            ]
        },
        {
            "x": 1,
            "y": 8,
            "z": 23,
            "elements": [
                "contenttweaker:spacexmachineblock@0"
            ]
        },
        {
            "x": -5,
            "y": 0,
            "z": 5,
            "elements": [
                "contenttweaker:dimensiontwistblock@0"
            ]
        },
        {
            "x": -11,
            "y": -2,
            "z": 12,
            "elements": [
                "contenttweaker:spacexmachineblock@0"
            ]
        },
        {
            "x": -1,
            "y": -14,
            "z": 15,
            "elements": [
                "contenttweaker:spacexmachineblock@0"
            ]
        },
        {
            "x": -1,
            "y": 10,
            "z": 22,
            "elements": [
                "contenttweaker:spacexmachineblock@0"
            ]
        },
        {
            "x": 4,
            "y": -1,
            "z": 23,
            "elements": [
                "contenttweaker:dimensiontwistblock@0"
            ]
        },
        {
            "x": 5,
            "y": 0,
            "z": 23,
            "elements": [
                "contenttweaker:dimensiontwistblock@0"
            ]
        },
        {
            "x": 4,
            "y": 2,
            "z": 23,
            "elements": [
                "contenttweaker:spacexmachineblock@0"
            ]
        },
        {
            "x": -8,
            "y": -2,
            "z": 20,
            "elements": [
                "contenttweaker:spacexmachineblock@0"
            ]
        },
        {
            "x": 1,
            "y": 7,
            "z": 23,
            "elements": [
                "contenttweaker:spacexmachineblock@0"
            ]
        },
        {
            "x": 10,
            "y": 2,
            "z": 16,
            "elements": [
                "contenttweaker:spacexmachineblock@0"
            ]
        },
        {
            "x": -11,
            "y": -1,
            "z": 12,
            "elements": [
                "contenttweaker:dimensiontwistblock@0"
            ]
        },
        {
            "x": -11,
            "y": -4,
            "z": 12,
            "elements": [
                "contenttweaker:spacexmachineblock@0"
            ]
        },
        {
            "x": -1,
            "y": 0,
            "z": 0,
            "elements": [
                "casings_all",
                "modularmachinery:blockmepatternprovider",
                "modularmachinery:blockmepatternmirrorimage"
            ]
        },
        {
            "x": -8,
            "y": -6,
            "z": 12,
            "elements": [
                "contenttweaker:spacexmachineblock@0"
            ]
        },
        {
            "x": 5,
            "y": 1,
            "z": 23,
            "elements": [
                "contenttweaker:spacexmachineblock@0"
            ]
        },
        {
            "x": -1,
            "y": 13,
            "z": 18,
            "elements": [
                "contenttweaker:spacexmachineblock@0"
            ]
        },
        {
            "x": 0,
            "y": -14,
            "z": 15,
            "elements": [
                "contenttweaker:stablestructure@0"
            ]
        },
        {
            "x": -10,
            "y": 0,
            "z": 20,
            "elements": [
                "contenttweaker:asteroidcontrolblock@0"
            ]
        },
        {
            "x": 0,
            "y": 0,
            "z": 5,
            "elements": [
                "contenttweaker:novamatrix@0"
            ]
        },
        {
            "x": 3,
            "y": -1,
            "z": 23,
            "elements": [
                "contenttweaker:dimensiontwistblock@0"
            ]
        },
        {
            "x": -11,
            "y": -1,
            "z": 16,
            "elements": [
                "contenttweaker:spacexmachineblock@0"
            ]
        },
        {
            "x": 5,
            "y": -1,
            "z": 4,
            "elements": [
                "contenttweaker:dimensiontwistblock@0"
            ]
        },
        {
            "x": 8,
            "y": 0,
            "z": 18,
            "elements": [
                "contenttweaker:dimensiontwistblock@0"
            ]
        },
        {
            "x": 1,
            "y": 9,
            "z": 23,
            "elements": [
                "contenttweaker:spacexmachineblock@0"
            ]
        },
        {
            "x": 3,
            "y": 0,
            "z": 3,
            "elements": [
                "contenttweaker:novamatrix@0"
            ]
        },
        {
            "x": -11,
            "y": -3,
            "z": 12,
            "elements": [
                "contenttweaker:spacexmachineblock@0"
            ]
        },
        {
            "x": -11,
            "y": 1,
            "z": 9,
            "elements": [
                "contenttweaker:spacexmachineblock@0"
            ]
        },
        {
            "x": -11,
            "y": -1,
            "z": 9,
            "elements": [
                "contenttweaker:spacexmachineblock@0"
            ]
        },
        {
            "x": 4,
            "y": 0,
            "z": 23,
            "elements": [
                "contenttweaker:novamatrix@0"
            ]
        },
        {
            "x": 6,
            "y": -1,
            "z": 23,
            "elements": [
                "contenttweaker:spacexmachineblock@0"
            ]
        },
        {
            "x": -3,
            "y": 0,
            "z": 22,
            "elements": [
                "contenttweaker:dimensiontwistblock@0"
            ]
        },
        {
            "x": 11,
            "y": 0,
            "z": 19,
            "elements": [
                "contenttweaker:asteroidcontrolblock@0"
            ]
        },
        {
            "x": -7,
            "y": 0,
            "z": 5,
            "elements": [
                "contenttweaker:novamatrix@0"
            ]
        },
        {
            "x": -8,
            "y": 2,
            "z": 20,
            "elements": [
                "contenttweaker:spacexmachineblock@0"
            ]
        },
        {
            "x": -13,
            "y": 1,
            "z": 13,
            "elements": [
                "contenttweaker:spacexmachineblock@0"
            ]
        },
        {
            "x": -13,
            "y": 0,
            "z": 12,
            "elements": [
                "contenttweaker:asteroidcontrolblock@0"
            ]
        },
        {
            "x": -11,
            "y": -2,
            "z": 13,
            "elements": [
                "contenttweaker:spacexmachineblock@0"
            ]
        },
        {
            "x": -12,
            "y": 0,
            "z": 15,
            "elements": [
                "contenttweaker:dimensiontwistblock@0"
            ]
        },
        {
            "x": -5,
            "y": 0,
            "z": 20,
            "elements": [
                "contenttweaker:asteroidcontrolblock@0"
            ]
        },
        {
            "x": -10,
            "y": 0,
            "z": 10,
            "elements": [
                "contenttweaker:novamatrix@0"
            ]
        },
        {
            "x": 0,
            "y": 1,
            "z": 4,
            "elements": [
                "contenttweaker:spacexmachineblock@0"
            ]
        },
        {
            "x": 7,
            "y": 0,
            "z": 23,
            "elements": [
                "contenttweaker:asteroidcontrolblock@0"
            ]
        },
        {
            "x": -13,
            "y": 2,
            "z": 13,
            "elements": [
                "contenttweaker:spacexmachineblock@0"
            ]
        },
        {
            "x": -7,
            "y": 2,
            "z": 5,
            "elements": [
                "contenttweaker:spacexmachineblock@0"
            ]
        },
        {
            "x": 10,
            "y": -1,
            "z": 19,
            "elements": [
                "contenttweaker:spacexmachineblock@0"
            ]
        },
        {
            "x": 8,
            "y": 0,
            "z": 17,
            "elements": [
                "contenttweaker:asteroidcontrolblock@0"
            ]
        },
        {
            "x": -11,
            "y": -3,
            "z": 13,
            "elements": [
                "contenttweaker:darkmatterblock@0"
            ]
        },
        {
            "x": 9,
            "y": 2,
            "z": 8,
            "elements": [
                "contenttweaker:spacexmachineblock@0"
            ]
        },
        {
            "x": -8,
            "y": -6,
            "z": 13,
            "elements": [
                "contenttweaker:darkmatterblock@0"
            ]
        },
        {
            "x": -9,
            "y": 0,
            "z": 10,
            "elements": [
                "contenttweaker:dimensiontwistblock@0"
            ]
        },
        {
            "x": 9,
            "y": 1,
            "z": 8,
            "elements": [
                "contenttweaker:dimensiontwistblock@0"
            ]
        },
        {
            "x": -8,
            "y": 0,
            "z": 20,
            "elements": [
                "contenttweaker:novamatrix@0"
            ]
        },
        {
            "x": -11,
            "y": -4,
            "z": 13,
            "elements": [
                "contenttweaker:darkmatterblock@0"
            ]
        },
        {
            "x": 3,
            "y": 1,
            "z": 4,
            "elements": [
                "contenttweaker:spacexmachineblock@0"
            ]
        },
        {
            "x": 3,
            "y": 2,
            "z": 3,
            "elements": [
                "contenttweaker:spacexmachineblock@0"
            ]
        },
        {
            "x": -9,
            "y": 0,
            "z": 15,
            "elements": [
                "contenttweaker:asteroidcontrolblock@0"
            ]
        },
        {
            "x": -13,
            "y": 0,
            "z": 13,
            "elements": [
                "contenttweaker:novamatrix@0"
            ]
        },
        {
            "x": -10,
            "y": 2,
            "z": 10,
            "elements": [
                "contenttweaker:spacexmachineblock@0"
            ]
        },
        {
            "x": -4,
            "y": -1,
            "z": 4,
            "elements": [
                "contenttweaker:spacexmachineblock@0"
            ]
        },
        {
            "x": -8,
            "y": -7,
            "z": 13,
            "elements": [
                "contenttweaker:spacexmachineblock@0"
            ]
        },
        {
            "x": -11,
            "y": -5,
            "z": 13,
            "elements": [
                "contenttweaker:spacexmachineblock@0"
            ]
        },
        {
            "x": -2,
            "y": 0,
            "z": 0,
            "elements": [
                "casings_all",
                "modularmachinery:blockmepatternprovider",
                "modularmachinery:blockmepatternmirrorimage"
            ]
        },
        {
            "x": -1,
            "y": 0,
            "z": 22,
            "elements": [
                "contenttweaker:asteroidcontrolblock@0"
            ]
        },
        {
            "x": -1,
            "y": 13,
            "z": 17,
            "elements": [
                "contenttweaker:spacexmachineblock@0"
            ]
        },
        {
            "x": -1,
            "y": -12,
            "z": 20,
            "elements": [
                "contenttweaker:spacexmachineblock@0"
            ]
        },
        {
            "x": 0,
            "y": -1,
            "z": 23,
            "elements": [
                "contenttweaker:spacexmachineblock@0"
            ]
        },
        {
            "x": 10,
            "y": -1,
            "z": 17,
            "elements": [
                "contenttweaker:dimensiontwistblock@0"
            ]
        },
        {
            "x": 0,
            "y": 0,
            "z": 10,
            "elements": [
                "contenttweaker:darkmatterblock@0"
            ]
        },
        {
            "x": -7,
            "y": -1,
            "z": 4,
            "elements": [
                "contenttweaker:spacexmachineblock@0"
            ]
        },
        {
            "x": 10,
            "y": -2,
            "z": 17,
            "elements": [
                "contenttweaker:spacexmachineblock@0"
            ]
        },
        {
            "x": 7,
            "y": -6,
            "z": 12,
            "elements": [
                "contenttweaker:spacexmachineblock@0"
            ]
        },
        {
            "x": 6,
            "y": 0,
            "z": 3,
            "elements": [
                "contenttweaker:dimensiontwistblock@0"
            ]
        },
        {
            "x": -1,
            "y": 0,
            "z": 26,
            "elements": [
                "contenttweaker:asteroidcontrolblock@0"
            ]
        },
        {
            "x": 1,
            "y": 0,
            "z": 23,
            "elements": [
                "contenttweaker:dimensiontwistblock@0"
            ]
        },
        {
            "x": 6,
            "y": 0,
            "z": 6,
            "elements": [
                "contenttweaker:asteroidcontrolblock@0"
            ]
        },
        {
            "x": -4,
            "y": 0,
            "z": 5,
            "elements": [
                "contenttweaker:asteroidcontrolblock@0"
            ]
        },
        {
            "x": 9,
            "y": -1,
            "z": 9,
            "elements": [
                "contenttweaker:spacexmachineblock@0"
            ]
        },
        {
            "x": 0,
            "y": -12,
            "z": 20,
            "elements": [
                "contenttweaker:stablestructure@0"
            ]
        },
        {
            "x": 11,
            "y": 1,
            "z": 17,
            "elements": [
                "contenttweaker:spacexmachineblock@0"
            ]
        },
        {
            "x": -8,
            "y": -1,
            "z": 21,
            "elements": [
                "contenttweaker:spacexmachineblock@0"
            ]
        },
        {
            "x": -8,
            "y": 1,
            "z": 21,
            "elements": [
                "contenttweaker:spacexmachineblock@0"
            ]
        },
        {
            "x": 1,
            "y": 1,
            "z": 23,
            "elements": [
                "contenttweaker:spacexmachineblock@0"
            ]
        },
        {
            "x": -4,
            "y": 0,
            "z": 22,
            "elements": [
                "contenttweaker:dimensiontwistblock@0"
            ]
        },
        {
            "x": -6,
            "y": 1,
            "z": 4,
            "elements": [
                "contenttweaker:dimensiontwistblock@0"
            ]
        },
        {
            "x": 11,
            "y": 0,
            "z": 17,
            "elements": [
                "contenttweaker:dimensiontwistblock@0"
            ]
        },
        {
            "x": 10,
            "y": -4,
            "z": 14,
            "elements": [
                "contenttweaker:spacexmachineblock@0"
            ]
        },
        {
            "x": -6,
            "y": 2,
            "z": 22,
            "elements": [
                "contenttweaker:spacexmachineblock@0"
            ]
        },
        {
            "x": -2,
            "y": 0,
            "z": 25,
            "elements": [
                "contenttweaker:dimensiontwistblock@0"
            ]
        },
        {
            "x": 4,
            "y": 1,
            "z": 24,
            "elements": [
                "contenttweaker:spacexmachineblock@0"
            ]
        },
        {
            "x": 12,
            "y": 0,
            "z": 11,
            "elements": [
                "contenttweaker:dimensiontwistblock@0"
            ]
        },
        {
            "x": -2,
            "y": 1,
            "z": 23,
            "elements": [
                "contenttweaker:spacexmachineblock@0"
            ]
        },
        {
            "x": 12,
            "y": 0,
            "z": 13,
            "elements": [
                "contenttweaker:dimensiontwistblock@0"
            ]
        },
        {
            "x": -5,
            "y": -2,
            "z": 22,
            "elements": [
                "contenttweaker:spacexmachineblock@0"
            ]
        },
        {
            "x": -4,
            "y": 1,
            "z": 4,
            "elements": [
                "contenttweaker:spacexmachineblock@0"
            ]
        },
        {
            "x": -7,
            "y": 0,
            "z": 22,
            "elements": [
                "contenttweaker:dimensiontwistblock@0"
            ]
        },
        {
            "x": 5,
            "y": 0,
            "z": 5,
            "elements": [
                "contenttweaker:dimensiontwistblock@0"
            ]
        },
        {
            "x": 11,
            "y": -2,
            "z": 14,
            "elements": [
                "contenttweaker:spacexmachineblock@0"
            ]
        },
        {
            "x": 4,
            "y": 2,
            "z": 3,
            "elements": [
                "contenttweaker:spacexmachineblock@0"
            ]
        },
        {
            "x": 0,
            "y": -6,
            "z": 25,
            "elements": [
                "contenttweaker:spacexmachineblock@0"
            ]
        },
        {
            "x": 5,
            "y": 0,
            "z": 24,
            "elements": [
                "contenttweaker:asteroidcontrolblock@0"
            ]
        },
        {
            "x": 4,
            "y": 0,
            "z": 3,
            "elements": [
                "contenttweaker:novamatrix@0"
            ]
        },
        {
            "x": -1,
            "y": -11,
            "z": 21,
            "elements": [
                "contenttweaker:spacexmachineblock@0"
            ]
        },
        {
            "x": -5,
            "y": -1,
            "z": 4,
            "elements": [
                "contenttweaker:dimensiontwistblock@0"
            ]
        },
        {
            "x": 10,
            "y": -5,
            "z": 14,
            "elements": [
                "contenttweaker:spacexmachineblock@0"
            ]
        },
        {
            "x": 11,
            "y": -1,
            "z": 13,
            "elements": [
                "contenttweaker:dimensiontwistblock@0"
            ]
        },
        {
            "x": 10,
            "y": -6,
            "z": 13,
            "elements": [
                "contenttweaker:spacexmachineblock@0"
            ]
        },
        {
            "x": 11,
            "y": -3,
            "z": 14,
            "elements": [
                "contenttweaker:spacexmachineblock@0"
            ]
        },
        {
            "x": 4,
            "y": -1,
            "z": 24,
            "elements": [
                "contenttweaker:spacexmachineblock@0"
            ]
        },
        {
            "x": 0,
            "y": 14,
            "z": 13,
            "elements": [
                "contenttweaker:novamatrix@0"
            ]
        },
        {
            "x": 11,
            "y": -4,
            "z": 14,
            "elements": [
                "contenttweaker:spacexmachineblock@0"
            ]
        },
        {
            "x": 9,
            "y": 5,
            "z": 13,
            "elements": [
                "contenttweaker:stablestructure@0"
            ]
        },
        {
            "x": 7,
            "y": -7,
            "z": 13,
            "elements": [
                "contenttweaker:spacexmachineblock@0"
            ]
        },
        {
            "x": 4,
            "y": 0,
            "z": 24,
            "elements": [
                "contenttweaker:dimensiontwistblock@0"
            ]
        },
        {
            "x": -5,
            "y": 0,
            "z": 23,
            "elements": [
                "contenttweaker:dimensiontwistblock@0"
            ]
        },
        {
            "x": 8,
            "y": 0,
            "z": 19,
            "elements": [
                "contenttweaker:dimensiontwistblock@0"
            ]
        },
        {
            "x": 12,
            "y": 3,
            "z": 13,
            "elements": [
                "contenttweaker:spacexmachineblock@0"
            ]
        },
        {
            "x": -3,
            "y": -2,
            "z": 23,
            "elements": [
                "contenttweaker:spacexmachineblock@0"
            ]
        },
        {
            "x": -5,
            "y": 1,
            "z": 23,
            "elements": [
                "contenttweaker:spacexmachineblock@0"
            ]
        },
        {
            "x": -6,
            "y": 0,
            "z": 22,
            "elements": [
                "contenttweaker:novamatrix@0"
            ]
        },
        {
            "x": -6,
            "y": 1,
            "z": 21,
            "elements": [
                "contenttweaker:spacexmachineblock@0"
            ]
        },
        {
            "x": -13,
            "y": 0,
            "z": 15,
            "elements": [
                "contenttweaker:asteroidcontrolblock@0"
            ]
        },
        {
            "x": 0,
            "y": 15,
            "z": 14,
            "elements": [
                "contenttweaker:spacexmachineblock@0"
            ]
        },
        {
            "x": -9,
            "y": -1,
            "z": 16,
            "elements": [
                "contenttweaker:spacexmachineblock@0"
            ]
        },
        {
            "x": 11,
            "y": 4,
            "z": 12,
            "elements": [
                "contenttweaker:spacexmachineblock@0"
            ]
        },
        {
            "x": 12,
            "y": 4,
            "z": 13,
            "elements": [
                "contenttweaker:spacexmachineblock@0"
            ]
        },
        {
            "x": 9,
            "y": 0,
            "z": 14,
            "elements": [
                "contenttweaker:asteroidcontrolblock@0"
            ]
        },
        {
            "x": 6,
            "y": 0,
            "z": 5,
            "elements": [
                "contenttweaker:dimensiontwistblock@0"
            ]
        },
        {
            "x": -6,
            "y": -1,
            "z": 23,
            "elements": [
                "contenttweaker:spacexmachineblock@0"
            ]
        },
        {
            "x": 7,
            "y": -6,
            "z": 13,
            "elements": [
                "contenttweaker:darkmatterblock@0"
            ]
        },
        {
            "x": 1,
            "y": 0,
            "z": 3,
            "elements": [
                "contenttweaker:dimensiontwistblock@0"
            ]
        },
        {
            "x": -2,
            "y": 0,
            "z": 23,
            "elements": [
                "contenttweaker:dimensiontwistblock@0"
            ]
        },
        {
            "x": 0,
            "y": -4,
            "z": 25,
            "elements": [
                "contenttweaker:stablestructure@0"
            ]
        },
        {
            "x": 9,
            "y": 6,
            "z": 13,
            "elements": [
                "contenttweaker:darkmatterblock@0"
            ]
        },
        {
            "x": 3,
            "y": -1,
            "z": 24,
            "elements": [
                "contenttweaker:spacexmachineblock@0"
            ]
        },
        {
            "x": 12,
            "y": 1,
            "z": 13,
            "elements": [
                "contenttweaker:spacexmachineblock@0"
            ]
        },
        {
            "x": -4,
            "y": 0,
            "z": 25,
            "elements": [
                "contenttweaker:asteroidcontrolblock@0"
            ]
        },
        {
            "x": 2,
            "y": 1,
            "z": 24,
            "elements": [
                "contenttweaker:dimensiontwistblock@0"
            ]
        },
        {
            "x": 9,
            "y": 0,
            "z": 6,
            "elements": [
                "contenttweaker:dimensiontwistblock@0"
            ]
        },
        {
            "x": 9,
            "y": 6,
            "z": 14,
            "elements": [
                "contenttweaker:spacexmachineblock@0"
            ]
        },
        {
            "x": 1,
            "y": -10,
            "z": 22,
            "elements": [
                "contenttweaker:spacexmachineblock@0"
            ]
        },
        {
            "x": 11,
            "y": 2,
            "z": 12,
            "elements": [
                "contenttweaker:spacexmachineblock@0"
            ]
        },
        {
            "x": 6,
            "y": 0,
            "z": 13,
            "elements": [
                "contenttweaker:darkmatterblock@0"
            ]
        },
        {
            "x": -7,
            "y": -1,
            "z": 21,
            "elements": [
                "contenttweaker:dimensiontwistblock@0"
            ]
        },
        {
            "x": 7,
            "y": -5,
            "z": 13,
            "elements": [
                "contenttweaker:asteroidcontrolblock@0"
            ]
        },
        {
            "x": 8,
            "y": -1,
            "z": 8,
            "elements": [
                "contenttweaker:spacexmachineblock@0"
            ]
        },
        {
            "x": 9,
            "y": 5,
            "z": 14,
            "elements": [
                "contenttweaker:spacexmachineblock@0"
            ]
        },
        {
            "x": 7,
            "y": -2,
            "z": 5,
            "elements": [
                "contenttweaker:spacexmachineblock@0"
            ]
        },
        {
            "x": 3,
            "y": 0,
            "z": 5,
            "elements": [
                "contenttweaker:asteroidcontrolblock@0"
            ]
        },
        {
            "x": 9,
            "y": 7,
            "z": 13,
            "elements": [
                "contenttweaker:spacexmachineblock@0"
            ]
        },
        {
            "x": 8,
            "y": 1,
            "z": 19,
            "elements": [
                "contenttweaker:spacexmachineblock@0"
            ]
        },
        {
            "x": 2,
            "y": 2,
            "z": 24,
            "elements": [
                "contenttweaker:spacexmachineblock@0"
            ]
        },
        {
            "x": -3,
            "y": -1,
            "z": 4,
            "elements": [
                "contenttweaker:spacexmachineblock@0"
            ]
        },
        {
            "x": 12,
            "y": 2,
            "z": 13,
            "elements": [
                "contenttweaker:spacexmachineblock@0"
            ]
        },
        {
            "x": -3,
            "y": -1,
            "z": 23,
            "elements": [
                "contenttweaker:dimensiontwistblock@0"
            ]
        },
        {
            "x": 9,
            "y": 1,
            "z": 6,
            "elements": [
                "contenttweaker:spacexmachineblock@0"
            ]
        },
        {
            "x": -9,
            "y": 1,
            "z": 8,
            "elements": [
                "contenttweaker:dimensiontwistblock@0"
            ]
        },
        {
            "x": 11,
            "y": 3,
            "z": 12,
            "elements": [
                "contenttweaker:spacexmachineblock@0"
            ]
        },
        {
            "x": -4,
            "y": -2,
            "z": 3,
            "elements": [
                "contenttweaker:spacexmachineblock@0"
            ]
        },
        {
            "x": 9,
            "y": 0,
            "z": 8,
            "elements": [
                "contenttweaker:novamatrix@0"
            ]
        },
        {
            "x": -6,
            "y": 0,
            "z": 3,
            "elements": [
                "contenttweaker:dimensiontwistblock@0"
            ]
        },
        {
            "x": -11,
            "y": 1,
            "z": 16,
            "elements": [
                "contenttweaker:spacexmachineblock@0"
            ]
        },
        {
            "x": 11,
            "y": 0,
            "z": 12,
            "elements": [
                "contenttweaker:novamatrix@0"
            ]
        },
        {
            "x": 5,
            "y": 0,
            "z": 13,
            "elements": [
                "contenttweaker:darkmatterblock@0"
            ]
        },
        {
            "x": 0,
            "y": 14,
            "z": 14,
            "elements": [
                "contenttweaker:stablestructure@0"
            ]
        },
        {
            "x": -1,
            "y": 12,
            "z": 19,
            "elements": [
                "contenttweaker:spacexmachineblock@0"
            ]
        },
        {
            "x": -3,
            "y": 1,
            "z": 4,
            "elements": [
                "contenttweaker:spacexmachineblock@0"
            ]
        },
        {
            "x": 1,
            "y": 5,
            "z": 24,
            "elements": [
                "contenttweaker:spacexmachineblock@0"
            ]
        },
        {
            "x": 2,
            "y": 0,
            "z": 24,
            "elements": [
                "contenttweaker:novamatrix@0"
            ]
        },
        {
            "x": 0,
            "y": -9,
            "z": 23,
            "elements": [
                "contenttweaker:stablestructure@0"
            ]
        },
        {
            "x": 8,
            "y": -2,
            "z": 6,
            "elements": [
                "contenttweaker:spacexmachineblock@0"
            ]
        },
        {
            "x": 8,
            "y": 0,
            "z": 5,
            "elements": [
                "contenttweaker:dimensiontwistblock@0"
            ]
        },
        {
            "x": 11,
            "y": 1,
            "z": 12,
            "elements": [
                "contenttweaker:dimensiontwistblock@0"
            ]
        },
        {
            "x": 8,
            "y": -1,
            "z": 6,
            "elements": [
                "contenttweaker:dimensiontwistblock@0"
            ]
        },
        {
            "x": 1,
            "y": 7,
            "z": 24,
            "elements": [
                "contenttweaker:spacexmachineblock@0"
            ]
        },
        {
            "x": 0,
            "y": 0,
            "z": 8,
            "elements": [
                "contenttweaker:darkmatterblock@0"
            ]
        },
        {
            "x": -9,
            "y": 2,
            "z": 8,
            "elements": [
                "contenttweaker:spacexmachineblock@0"
            ]
        },
        {
            "x": 1,
            "y": 6,
            "z": 24,
            "elements": [
                "contenttweaker:spacexmachineblock@0"
            ]
        },
        {
            "x": -5,
            "y": 0,
            "z": 3,
            "elements": [
                "contenttweaker:dimensiontwistblock@0"
            ]
        },
        {
            "x": 1,
            "y": -1,
            "z": 24,
            "elements": [
                "contenttweaker:dimensiontwistblock@0"
            ]
        },
        {
            "x": 0,
            "y": -8,
            "z": 23,
            "elements": [
                "contenttweaker:stablestructure@0"
            ]
        },
        {
            "x": 3,
            "y": -2,
            "z": 3,
            "elements": [
                "contenttweaker:spacexmachineblock@0"
            ]
        },
        {
            "x": 8,
            "y": 5,
            "z": 13,
            "elements": [
                "contenttweaker:stablestructure@0"
            ]
        },
        {
            "x": 11,
            "y": -1,
            "z": 14,
            "elements": [
                "contenttweaker:dimensiontwistblock@0"
            ]
        },
        {
            "x": 8,
            "y": 0,
            "z": 13,
            "elements": [
                "contenttweaker:novamatrix@0"
            ]
        },
        {
            "x": -11,
            "y": 1,
            "z": 11,
            "elements": [
                "contenttweaker:dimensiontwistblock@0"
            ]
        },
        {
            "x": 11,
            "y": -3,
            "z": 12,
            "elements": [
                "contenttweaker:spacexmachineblock@0"
            ]
        },
        {
            "x": 11,
            "y": 2,
            "z": 13,
            "elements": [
                "contenttweaker:spacexmachineblock@0"
            ]
        },
        {
            "x": 0,
            "y": -15,
            "z": 16,
            "elements": [
                "contenttweaker:spacexmachineblock@0"
            ]
        },
        {
            "x": 1,
            "y": 2,
            "z": 25,
            "elements": [
                "contenttweaker:spacexmachineblock@0"
            ]
        },
        {
            "x": -10,
            "y": -1,
            "z": 16,
            "elements": [
                "contenttweaker:dimensiontwistblock@0"
            ]
        },
        {
            "x": 1,
            "y": 0,
            "z": 24,
            "elements": [
                "contenttweaker:novamatrix@0"
            ]
        },
        {
            "x": 10,
            "y": -1,
            "z": 12,
            "elements": [
                "contenttweaker:spacexmachineblock@0"
            ]
        },
        {
            "x": -1,
            "y": 12,
            "z": 18,
            "elements": [
                "contenttweaker:spacexmachineblock@0"
            ]
        },
        {
            "x": -10,
            "y": 1,
            "z": 9,
            "elements": [
                "contenttweaker:dimensiontwistblock@0"
            ]
        },
        {
            "x": -3,
            "y": 2,
            "z": 3,
            "elements": [
                "contenttweaker:spacexmachineblock@0"
            ]
        },
        {
            "x": 8,
            "y": 6,
            "z": 13,
            "elements": [
                "contenttweaker:darkmatterblock@0"
            ]
        },
        {
            "x": 12,
            "y": 0,
            "z": 14,
            "elements": [
                "contenttweaker:dimensiontwistblock@0"
            ]
        },
        {
            "x": 0,
            "y": 0,
            "z": 3,
            "elements": [
                "contenttweaker:dimensiontwistblock@0"
            ]
        },
        {
            "x": 11,
            "y": -4,
            "z": 12,
            "elements": [
                "contenttweaker:spacexmachineblock@0"
            ]
        },
        {
            "x": 8,
            "y": 1,
            "z": 18,
            "elements": [
                "contenttweaker:spacexmachineblock@0"
            ]
        },
        {
            "x": 0,
            "y": -1,
            "z": 24,
            "elements": [
                "contenttweaker:dimensiontwistblock@0"
            ]
        },
        {
            "x": 0,
            "y": -10,
            "z": 23,
            "elements": [
                "contenttweaker:spacexmachineblock@0"
            ]
        },
        {
            "x": -9,
            "y": 1,
            "z": 16,
            "elements": [
                "contenttweaker:spacexmachineblock@0"
            ]
        },
        {
            "x": 11,
            "y": 1,
            "z": 13,
            "elements": [
                "contenttweaker:dimensiontwistblock@0"
            ]
        },
        {
            "x": 0,
            "y": 0,
            "z": 20,
            "elements": [
                "contenttweaker:darkmatterblock@0"
            ]
        },
        {
            "x": 1,
            "y": 1,
            "z": 24,
            "elements": [
                "contenttweaker:dimensiontwistblock@0"
            ]
        },
        {
            "x": 12,
            "y": 1,
            "z": 14,
            "elements": [
                "contenttweaker:spacexmachineblock@0"
            ]
        },
        {
            "x": 13,
            "y": -2,
            "z": 13,
            "elements": [
                "contenttweaker:spacexmachineblock@0"
            ]
        },
        {
            "x": -6,
            "y": 0,
            "z": 5,
            "elements": [
                "contenttweaker:dimensiontwistblock@0"
            ]
        },
        {
            "x": 8,
            "y": -1,
            "z": 20,
            "elements": [
                "contenttweaker:dimensiontwistblock@0"
            ]
        },
        {
            "x": -9,
            "y": 0,
            "z": 8,
            "elements": [
                "contenttweaker:novamatrix@0"
            ]
        },
        {
            "x": 8,
            "y": -5,
            "z": 13,
            "elements": [
                "contenttweaker:stablestructure@0"
            ]
        },
        {
            "x": -5,
            "y": 1,
            "z": 4,
            "elements": [
                "contenttweaker:dimensiontwistblock@0"
            ]
        },
        {
            "x": 11,
            "y": 0,
            "z": 13,
            "elements": [
                "contenttweaker:novamatrix@0"
            ]
        },
        {
            "x": 8,
            "y": 6,
            "z": 12,
            "elements": [
                "contenttweaker:spacexmachineblock@0"
            ]
        },
        {
            "x": -1,
            "y": 5,
            "z": 24,
            "elements": [
                "contenttweaker:spacexmachineblock@0"
            ]
        },
        {
            "x": 11,
            "y": -1,
            "z": 12,
            "elements": [
                "contenttweaker:dimensiontwistblock@0"
            ]
        },
        {
            "x": 1,
            "y": 2,
            "z": 24,
            "elements": [
                "contenttweaker:spacexmachineblock@0"
            ]
        },
        {
            "x": 10,
            "y": -4,
            "z": 12,
            "elements": [
                "contenttweaker:spacexmachineblock@0"
            ]
        },
        {
            "x": -9,
            "y": -1,
            "z": 9,
            "elements": [
                "contenttweaker:spacexmachineblock@0"
            ]
        },
        {
            "x": 10,
            "y": -1,
            "z": 13,
            "elements": [
                "contenttweaker:spacexmachineblock@0"
            ]
        },
        {
            "x": -1,
            "y": 6,
            "z": 24,
            "elements": [
                "contenttweaker:spacexmachineblock@0"
            ]
        },
        {
            "x": 11,
            "y": -2,
            "z": 12,
            "elements": [
                "contenttweaker:spacexmachineblock@0"
            ]
        },
        {
            "x": -3,
            "y": 0,
            "z": 3,
            "elements": [
                "contenttweaker:novamatrix@0"
            ]
        },
        {
            "x": -10,
            "y": -1,
            "z": 8,
            "elements": [
                "contenttweaker:spacexmachineblock@0"
            ]
        },
        {
            "x": 8,
            "y": -6,
            "z": 14,
            "elements": [
                "contenttweaker:spacexmachineblock@0"
            ]
        },
        {
            "x": -3,
            "y": -2,
            "z": 3,
            "elements": [
                "contenttweaker:spacexmachineblock@0"
            ]
        },
        {
            "x": 8,
            "y": 1,
            "z": 13,
            "elements": [
                "contenttweaker:dimensiontwistblock@0"
            ]
        },
        {
            "x": -7,
            "y": -2,
            "z": 5,
            "elements": [
                "contenttweaker:spacexmachineblock@0"
            ]
        },
        {
            "x": 9,
            "y": 0,
            "z": 12,
            "elements": [
                "contenttweaker:asteroidcontrolblock@0"
            ]
        },
        {
            "x": 10,
            "y": -2,
            "z": 13,
            "elements": [
                "contenttweaker:stablestructure@0"
            ]
        },
        {
            "x": 10,
            "y": -5,
            "z": 12,
            "elements": [
                "contenttweaker:spacexmachineblock@0"
            ]
        },
        {
            "x": 12,
            "y": 0,
            "z": 12,
            "elements": [
                "contenttweaker:dimensiontwistblock@0"
            ]
        },
        {
            "x": -9,
            "y": 0,
            "z": 5,
            "elements": [
                "contenttweaker:asteroidcontrolblock@0"
            ]
        },
        {
            "x": 0,
            "y": -2,
            "z": 25,
            "elements": [
                "contenttweaker:stablestructure@0"
            ]
        },
        {
            "x": 0,
            "y": -1,
            "z": 4,
            "elements": [
                "contenttweaker:spacexmachineblock@0"
            ]
        },
        {
            "x": 11,
            "y": 0,
            "z": 18,
            "elements": [
                "contenttweaker:asteroidcontrolblock@0"
            ]
        },
        {
            "x": -8,
            "y": 0,
            "z": 10,
            "elements": [
                "contenttweaker:asteroidcontrolblock@0"
            ]
        },
        {
            "x": -1,
            "y": 7,
            "z": 24,
            "elements": [
                "contenttweaker:spacexmachineblock@0"
            ]
        },
        {
            "x": 11,
            "y": -5,
            "z": 13,
            "elements": [
                "contenttweaker:spacexmachineblock@0"
            ]
        },
        {
            "x": 9,
            "y": 1,
            "z": 20,
            "elements": [
                "contenttweaker:spacexmachineblock@0"
            ]
        },
        {
            "x": -10,
            "y": 0,
            "z": 15,
            "elements": [
                "contenttweaker:dimensiontwistblock@0"
            ]
        },
        {
            "x": 6,
            "y": 6,
            "z": 13,
            "elements": [
                "contenttweaker:novamatrix@0"
            ]
        },
        {
            "x": 10,
            "y": -3,
            "z": 13,
            "elements": [
                "contenttweaker:stablestructure@0"
            ]
        },
        {
            "x": -2,
            "y": 2,
            "z": 24,
            "elements": [
                "contenttweaker:spacexmachineblock@0"
            ]
        },
        {
            "x": 12,
            "y": 1,
            "z": 12,
            "elements": [
                "contenttweaker:spacexmachineblock@0"
            ]
        },
        {
            "x": 9,
            "y": 1,
            "z": 13,
            "elements": [
                "contenttweaker:spacexmachineblock@0"
            ]
        },
        {
            "x": -2,
            "y": 1,
            "z": 24,
            "elements": [
                "contenttweaker:dimensiontwistblock@0"
            ]
        },
        {
            "x": -2,
            "y": 0,
            "z": 3,
            "elements": [
                "contenttweaker:dimensiontwistblock@0"
            ]
        },
        {
            "x": 11,
            "y": -4,
            "z": 13,
            "elements": [
                "contenttweaker:darkmatterblock@0"
            ]
        },
        {
            "x": 10,
            "y": -1,
            "z": 18,
            "elements": [
                "contenttweaker:spacexmachineblock@0"
            ]
        },
        {
            "x": 1,
            "y": 0,
            "z": 25,
            "elements": [
                "contenttweaker:dimensiontwistblock@0"
            ]
        },
        {
            "x": 9,
            "y": 0,
            "z": 13,
            "elements": [
                "contenttweaker:asteroidcontrolblock@0"
            ]
        },
        {
            "x": 0,
            "y": -2,
            "z": 24,
            "elements": [
                "contenttweaker:spacexmachineblock@0"
            ]
        },
        {
            "x": 11,
            "y": -2,
            "z": 13,
            "elements": [
                "contenttweaker:spacexmachineblock@0"
            ]
        },
        {
            "x": -2,
            "y": 0,
            "z": 24,
            "elements": [
                "contenttweaker:novamatrix@0"
            ]
        },
        {
            "x": -6,
            "y": 0,
            "z": 20,
            "elements": [
                "contenttweaker:asteroidcontrolblock@0"
            ]
        },
        {
            "x": 10,
            "y": -5,
            "z": 13,
            "elements": [
                "contenttweaker:darkmatterblock@0"
            ]
        },
        {
            "x": -11,
            "y": -2,
            "z": 15,
            "elements": [
                "contenttweaker:spacexmachineblock@0"
            ]
        },
        {
            "x": -12,
            "y": -1,
            "z": 11,
            "elements": [
                "contenttweaker:spacexmachineblock@0"
            ]
        },
        {
            "x": -11,
            "y": 0,
            "z": 10,
            "elements": [
                "contenttweaker:dimensiontwistblock@0"
            ]
        },
        {
            "x": -6,
            "y": -1,
            "z": 4,
            "elements": [
                "contenttweaker:dimensiontwistblock@0"
            ]
        },
        {
            "x": 11,
            "y": -3,
            "z": 13,
            "elements": [
                "contenttweaker:darkmatterblock@0"
            ]
        },
        {
            "x": 9,
            "y": 6,
            "z": 12,
            "elements": [
                "contenttweaker:spacexmachineblock@0"
            ]
        },
        {
            "x": -3,
            "y": -1,
            "z": 24,
            "elements": [
                "contenttweaker:spacexmachineblock@0"
            ]
        },
        {
            "x": -1,
            "y": 0,
            "z": 3,
            "elements": [
                "contenttweaker:dimensiontwistblock@0"
            ]
        },
        {
            "x": 0,
            "y": 1,
            "z": 21,
            "elements": [
                "contenttweaker:dimensiontwistblock@0"
            ]
        },
        {
            "x": 8,
            "y": -1,
            "z": 13,
            "elements": [
                "contenttweaker:dimensiontwistblock@0"
            ]
        },
        {
            "x": -1,
            "y": -13,
            "z": 16,
            "elements": [
                "contenttweaker:spacexmachineblock@0"
            ]
        },
        {
            "x": 2,
            "y": 0,
            "z": 26,
            "elements": [
                "contenttweaker:asteroidcontrolblock@0"
            ]
        },
        {
            "x": 10,
            "y": -4,
            "z": 13,
            "elements": [
                "contenttweaker:stablestructure@0"
            ]
        },
        {
            "x": 9,
            "y": 5,
            "z": 12,
            "elements": [
                "contenttweaker:spacexmachineblock@0"
            ]
        },
        {
            "x": 10,
            "y": 2,
            "z": 10,
            "elements": [
                "contenttweaker:spacexmachineblock@0"
            ]
        },
        {
            "x": 4,
            "y": 1,
            "z": 4,
            "elements": [
                "contenttweaker:spacexmachineblock@0"
            ]
        },
        {
            "x": 9,
            "y": 0,
            "z": 21,
            "elements": [
                "contenttweaker:asteroidcontrolblock@0"
            ]
        },
        {
            "x": 0,
            "y": 13,
            "z": 20,
            "elements": [
                "contenttweaker:spacexmachineblock@0"
            ]
        },
        {
            "x": -10,
            "y": -4,
            "z": 13,
            "elements": [
                "contenttweaker:stablestructure@0"
            ]
        },
        {
            "x": -8,
            "y": 0,
            "z": 8,
            "elements": [
                "contenttweaker:dimensiontwistblock@0"
            ]
        },
        {
            "x": 6,
            "y": -1,
            "z": 4,
            "elements": [
                "contenttweaker:dimensiontwistblock@0"
            ]
        },
        {
            "x": 7,
            "y": 0,
            "z": 4,
            "elements": [
                "contenttweaker:dimensiontwistblock@0"
            ]
        },
        {
            "x": -12,
            "y": 0,
            "z": 13,
            "elements": [
                "contenttweaker:dimensiontwistblock@0"
            ]
        },
        {
            "x": 9,
            "y": 1,
            "z": 10,
            "elements": [
                "contenttweaker:spacexmachineblock@0"
            ]
        },
        {
            "x": -4,
            "y": -1,
            "z": 2,
            "elements": [
                "contenttweaker:spacexmachineblock@0"
            ]
        },
        {
            "x": 12,
            "y": -1,
            "z": 11,
            "elements": [
                "contenttweaker:spacexmachineblock@0"
            ]
        },
        {
            "x": 10,
            "y": 0,
            "z": 10,
            "elements": [
                "contenttweaker:novamatrix@0"
            ]
        },
        {
            "x": -4,
            "y": 1,
            "z": 24,
            "elements": [
                "contenttweaker:spacexmachineblock@0"
            ]
        },
        {
            "x": 8,
            "y": 1,
            "z": 7,
            "elements": [
                "contenttweaker:spacexmachineblock@0"
            ]
        },
        {
            "x": 7,
            "y": 1,
            "z": 4,
            "elements": [
                "contenttweaker:spacexmachineblock@0"
            ]
        },
        {
            "x": 8,
            "y": 0,
            "z": 6,
            "elements": [
                "contenttweaker:novamatrix@0"
            ]
        },
        {
            "x": -12,
            "y": 0,
            "z": 9,
            "elements": [
                "contenttweaker:asteroidcontrolblock@0"
            ]
        },
        {
            "x": -9,
            "y": -2,
            "z": 8,
            "elements": [
                "contenttweaker:spacexmachineblock@0"
            ]
        },
        {
            "x": 1,
            "y": -7,
            "z": 24,
            "elements": [
                "contenttweaker:spacexmachineblock@0"
            ]
        },
        {
            "x": 3,
            "y": 1,
            "z": 2,
            "elements": [
                "contenttweaker:spacexmachineblock@0"
            ]
        },
        {
            "x": -8,
            "y": -1,
            "z": 7,
            "elements": [
                "contenttweaker:spacexmachineblock@0"
            ]
        },
        {
            "x": 11,
            "y": -1,
            "z": 10,
            "elements": [
                "contenttweaker:spacexmachineblock@0"
            ]
        },
        {
            "x": 3,
            "y": -1,
            "z": 4,
            "elements": [
                "contenttweaker:spacexmachineblock@0"
            ]
        },
        {
            "x": 0,
            "y": -1,
            "z": 26,
            "elements": [
                "contenttweaker:spacexmachineblock@0"
            ]
        },
        {
            "x": 0,
            "y": -14,
            "z": 18,
            "elements": [
                "contenttweaker:spacexmachineblock@0"
            ]
        },
        {
            "x": 10,
            "y": 1,
            "z": 10,
            "elements": [
                "contenttweaker:dimensiontwistblock@0"
            ]
        },
        {
            "x": -9,
            "y": 0,
            "z": 13,
            "elements": [
                "contenttweaker:asteroidcontrolblock@0"
            ]
        },
        {
            "x": 8,
            "y": 2,
            "z": 6,
            "elements": [
                "contenttweaker:spacexmachineblock@0"
            ]
        },
        {
            "x": 4,
            "y": 0,
            "z": 4,
            "elements": [
                "contenttweaker:dimensiontwistblock@0"
            ]
        },
        {
            "x": -9,
            "y": 0,
            "z": 18,
            "elements": [
                "contenttweaker:novamatrix@0"
            ]
        },
        {
            "x": -12,
            "y": 2,
            "z": 13,
            "elements": [
                "contenttweaker:spacexmachineblock@0"
            ]
        },
        {
            "x": -11,
            "y": 1,
            "z": 17,
            "elements": [
                "contenttweaker:spacexmachineblock@0"
            ]
        },
        {
            "x": 0,
            "y": -3,
            "z": 26,
            "elements": [
                "contenttweaker:spacexmachineblock@0"
            ]
        },
        {
            "x": 1,
            "y": 5,
            "z": 25,
            "elements": [
                "contenttweaker:spacexmachineblock@0"
            ]
        },
        {
            "x": 11,
            "y": -1,
            "z": 16,
            "elements": [
                "contenttweaker:spacexmachineblock@0"
            ]
        },
        {
            "x": 5,
            "y": 0,
            "z": 20,
            "elements": [
                "contenttweaker:asteroidcontrolblock@0"
            ]
        },
        {
            "x": -7,
            "y": -6,
            "z": 13,
            "elements": [
                "contenttweaker:darkmatterblock@0"
            ]
        },
        {
            "x": 11,
            "y": 3,
            "z": 13,
            "elements": [
                "contenttweaker:darkmatterblock@0"
            ]
        },
        {
            "x": 0,
            "y": -13,
            "z": 17,
            "elements": [
                "contenttweaker:stablestructure@0"
            ]
        },
        {
            "x": 0,
            "y": 12,
            "z": 21,
            "elements": [
                "contenttweaker:spacexmachineblock@0"
            ]
        },
        {
            "x": 4,
            "y": 0,
            "z": 25,
            "elements": [
                "contenttweaker:asteroidcontrolblock@0"
            ]
        },
        {
            "x": 2,
            "y": -1,
            "z": 2,
            "elements": [
                "contenttweaker:dimensiontwistblock@0"
            ]
        },
        {
            "x": 0,
            "y": 1,
            "z": 2,
            "elements": [
                "contenttweaker:dimensiontwistblock@0"
            ]
        },
        {
            "x": -12,
            "y": 1,
            "z": 14,
            "elements": [
                "contenttweaker:spacexmachineblock@0"
            ]
        },
        {
            "x": 9,
            "y": 0,
            "z": 15,
            "elements": [
                "contenttweaker:asteroidcontrolblock@0"
            ]
        },
        {
            "x": -10,
            "y": -2,
            "z": 13,
            "elements": [
                "contenttweaker:stablestructure@0"
            ]
        },
        {
            "x": 1,
            "y": 4,
            "z": 25,
            "elements": [
                "contenttweaker:spacexmachineblock@0"
            ]
        },
        {
            "x": -2,
            "y": -1,
            "z": 24,
            "elements": [
                "contenttweaker:dimensiontwistblock@0"
            ]
        },
        {
            "x": 8,
            "y": -6,
            "z": 13,
            "elements": [
                "contenttweaker:darkmatterblock@0"
            ]
        },
        {
            "x": 7,
            "y": -1,
            "z": 20,
            "elements": [
                "contenttweaker:spacexmachineblock@0"
            ]
        },
        {
            "x": 0,
            "y": 13,
            "z": 21,
            "elements": [
                "contenttweaker:spacexmachineblock@0"
            ]
        },
        {
            "x": -9,
            "y": 2,
            "z": 18,
            "elements": [
                "contenttweaker:spacexmachineblock@0"
            ]
        },
        {
            "x": 13,
            "y": -1,
            "z": 13,
            "elements": [
                "contenttweaker:spacexmachineblock@0"
            ]
        },
        {
            "x": -12,
            "y": 4,
            "z": 13,
            "elements": [
                "contenttweaker:spacexmachineblock@0"
            ]
        },
        {
            "x": -8,
            "y": 0,
            "z": 18,
            "elements": [
                "contenttweaker:dimensiontwistblock@0"
            ]
        },
        {
            "x": 11,
            "y": 5,
            "z": 13,
            "elements": [
                "contenttweaker:spacexmachineblock@0"
            ]
        },
        {
            "x": 12,
            "y": 0,
            "z": 10,
            "elements": [
                "contenttweaker:asteroidcontrolblock@0"
            ]
        },
        {
            "x": 0,
            "y": -5,
            "z": 26,
            "elements": [
                "contenttweaker:spacexmachineblock@0"
            ]
        },
        {
            "x": 13,
            "y": 0,
            "z": 11,
            "elements": [
                "contenttweaker:asteroidcontrolblock@0"
            ]
        },
        {
            "x": -9,
            "y": -2,
            "z": 18,
            "elements": [
                "contenttweaker:spacexmachineblock@0"
            ]
        },
        {
            "x": 9,
            "y": -1,
            "z": 10,
            "elements": [
                "contenttweaker:spacexmachineblock@0"
            ]
        },
        {
            "x": -3,
            "y": 1,
            "z": 2,
            "elements": [
                "contenttweaker:spacexmachineblock@0"
            ]
        },
        {
            "x": 8,
            "y": 7,
            "z": 13,
            "elements": [
                "contenttweaker:spacexmachineblock@0"
            ]
        },
        {
            "x": 12,
            "y": 0,
            "z": 16,
            "elements": [
                "contenttweaker:asteroidcontrolblock@0"
            ]
        },
        {
            "x": -1,
            "y": 1,
            "z": 24,
            "elements": [
                "contenttweaker:dimensiontwistblock@0"
            ]
        },
        {
            "x": -1,
            "y": -12,
            "z": 18,
            "elements": [
                "contenttweaker:spacexmachineblock@0"
            ]
        },
        {
            "x": 0,
            "y": 12,
            "z": 20,
            "elements": [
                "contenttweaker:stablestructure@0"
            ]
        },
        {
            "x": 6,
            "y": 0,
            "z": 20,
            "elements": [
                "contenttweaker:asteroidcontrolblock@0"
            ]
        },
        {
            "x": -3,
            "y": 0,
            "z": 13,
            "elements": [
                "contenttweaker:darkmatterblock@0"
            ]
        },
        {
            "x": 9,
            "y": 0,
            "z": 10,
            "elements": [
                "contenttweaker:dimensiontwistblock@0"
            ]
        },
        {
            "x": 6,
            "y": -2,
            "z": 4,
            "elements": [
                "contenttweaker:spacexmachineblock@0"
            ]
        },
        {
            "x": -7,
            "y": 0,
            "z": 18,
            "elements": [
                "contenttweaker:asteroidcontrolblock@0"
            ]
        },
        {
            "x": 0,
            "y": 15,
            "z": 15,
            "elements": [
                "contenttweaker:spacexmachineblock@0"
            ]
        },
        {
            "x": -4,
            "y": -2,
            "z": 23,
            "elements": [
                "contenttweaker:spacexmachineblock@0"
            ]
        },
        {
            "x": 2,
            "y": 0,
            "z": 25,
            "elements": [
                "contenttweaker:dimensiontwistblock@0"
            ]
        },
        {
            "x": -10,
            "y": 0,
            "z": 18,
            "elements": [
                "contenttweaker:dimensiontwistblock@0"
            ]
        },
        {
            "x": -1,
            "y": 5,
            "z": 25,
            "elements": [
                "contenttweaker:spacexmachineblock@0"
            ]
        },
        {
            "x": 5,
            "y": 0,
            "z": 21,
            "elements": [
                "contenttweaker:dimensiontwistblock@0"
            ]
        },
        {
            "x": 7,
            "y": -2,
            "z": 21,
            "elements": [
                "contenttweaker:spacexmachineblock@0"
            ]
        },
        {
            "x": -10,
            "y": -5,
            "z": 14,
            "elements": [
                "contenttweaker:spacexmachineblock@0"
            ]
        },
        {
            "x": -1,
            "y": 11,
            "z": 20,
            "elements": [
                "contenttweaker:spacexmachineblock@0"
            ]
        },
        {
            "x": -2,
            "y": 1,
            "z": 2,
            "elements": [
                "contenttweaker:dimensiontwistblock@0"
            ]
        },
        {
            "x": 1,
            "y": 0,
            "z": 1,
            "elements": [
                "contenttweaker:dimensiontwistblock@0"
            ]
        },
        {
            "x": -9,
            "y": 0,
            "z": 6,
            "elements": [
                "contenttweaker:dimensiontwistblock@0"
            ]
        },
        {
            "x": 0,
            "y": -1,
            "z": 2,
            "elements": [
                "contenttweaker:dimensiontwistblock@0"
            ]
        },
        {
            "x": -2,
            "y": -1,
            "z": 25,
            "elements": [
                "contenttweaker:spacexmachineblock@0"
            ]
        },
        {
            "x": -1,
            "y": -8,
            "z": 23,
            "elements": [
                "contenttweaker:spacexmachineblock@0"
            ]
        },
        {
            "x": 5,
            "y": 1,
            "z": 21,
            "elements": [
                "contenttweaker:spacexmachineblock@0"
            ]
        },
        {
            "x": 7,
            "y": -1,
            "z": 21,
            "elements": [
                "contenttweaker:dimensiontwistblock@0"
            ]
        },
        {
            "x": 8,
            "y": 2,
            "z": 20,
            "elements": [
                "contenttweaker:spacexmachineblock@0"
            ]
        },
        {
            "x": 0,
            "y": 0,
            "z": 13,
            "elements": [
                "contenttweaker:novamatrix@0"
            ]
        },
        {
            "x": -12,
            "y": 0,
            "z": 16,
            "elements": [
                "contenttweaker:asteroidcontrolblock@0"
            ]
        },
        {
            "x": 2,
            "y": 1,
            "z": 25,
            "elements": [
                "contenttweaker:spacexmachineblock@0"
            ]
        },
        {
            "x": -1,
            "y": 12,
            "z": 20,
            "elements": [
                "contenttweaker:spacexmachineblock@0"
            ]
        },
        {
            "x": -1,
            "y": 0,
            "z": 25,
            "elements": [
                "contenttweaker:dimensiontwistblock@0"
            ]
        },
        {
            "x": 3,
            "y": 0,
            "z": 13,
            "elements": [
                "contenttweaker:darkmatterblock@0"
            ]
        },
        {
            "x": -1,
            "y": 1,
            "z": 25,
            "elements": [
                "contenttweaker:spacexmachineblock@0"
            ]
        },
        {
            "x": 1,
            "y": -2,
            "z": 25,
            "elements": [
                "contenttweaker:spacexmachineblock@0"
            ]
        },
        {
            "x": -1,
            "y": -13,
            "z": 17,
            "elements": [
                "contenttweaker:spacexmachineblock@0"
            ]
        },
        {
            "x": 1,
            "y": -1,
            "z": 25,
            "elements": [
                "contenttweaker:spacexmachineblock@0"
            ]
        },
        {
            "x": 6,
            "y": 0,
            "z": 21,
            "elements": [
                "contenttweaker:dimensiontwistblock@0"
            ]
        },
        {
            "x": 0,
            "y": 0,
            "z": 9,
            "elements": [
                "contenttweaker:darkmatterblock@0"
            ]
        },
        {
            "x": 4,
            "y": 0,
            "z": 1,
            "elements": [
                "contenttweaker:asteroidcontrolblock@0"
            ]
        },
        {
            "x": 8,
            "y": 1,
            "z": 20,
            "elements": [
                "contenttweaker:dimensiontwistblock@0"
            ]
        },
        {
            "x": -10,
            "y": 1,
            "z": 7,
            "elements": [
                "contenttweaker:spacexmachineblock@0"
            ]
        },
        {
            "x": -9,
            "y": 1,
            "z": 9,
            "elements": [
                "contenttweaker:spacexmachineblock@0"
            ]
        },
        {
            "x": -10,
            "y": -5,
            "z": 12,
            "elements": [
                "contenttweaker:spacexmachineblock@0"
            ]
        },
        {
            "x": -1,
            "y": 1,
            "z": 2,
            "elements": [
                "contenttweaker:dimensiontwistblock@0"
            ]
        },
        {
            "x": -9,
            "y": -1,
            "z": 17,
            "elements": [
                "contenttweaker:spacexmachineblock@0"
            ]
        },
        {
            "x": 1,
            "y": -5,
            "z": 24,
            "elements": [
                "contenttweaker:spacexmachineblock@0"
            ]
        },
        {
            "x": -1,
            "y": -1,
            "z": 2,
            "elements": [
                "contenttweaker:dimensiontwistblock@0"
            ]
        },
        {
            "x": -12,
            "y": -1,
            "z": 12,
            "elements": [
                "contenttweaker:spacexmachineblock@0"
            ]
        },
        {
            "x": 1,
            "y": -12,
            "z": 18,
            "elements": [
                "contenttweaker:spacexmachineblock@0"
            ]
        },
        {
            "x": 6,
            "y": 1,
            "z": 21,
            "elements": [
                "contenttweaker:spacexmachineblock@0"
            ]
        },
        {
            "x": 8,
            "y": 0,
            "z": 20,
            "elements": [
                "contenttweaker:novamatrix@0"
            ]
        },
        {
            "x": 0,
            "y": 11,
            "z": 21,
            "elements": [
                "contenttweaker:stablestructure@0"
            ]
        },
        {
            "x": 9,
            "y": 2,
            "z": 19,
            "elements": [
                "contenttweaker:spacexmachineblock@0"
            ]
        },
        {
            "x": 11,
            "y": 4,
            "z": 14,
            "elements": [
                "contenttweaker:spacexmachineblock@0"
            ]
        },
        {
            "x": 5,
            "y": 0,
            "z": 6,
            "elements": [
                "contenttweaker:asteroidcontrolblock@0"
            ]
        },
        {
            "x": 2,
            "y": 0,
            "z": 13,
            "elements": [
                "contenttweaker:darkmatterblock@0"
            ]
        },
        {
            "x": -6,
            "y": 0,
            "z": 23,
            "elements": [
                "contenttweaker:dimensiontwistblock@0"
            ]
        },
        {
            "x": -9,
            "y": 0,
            "z": 9,
            "elements": [
                "contenttweaker:dimensiontwistblock@0"
            ]
        },
        {
            "x": 0,
            "y": -13,
            "z": 19,
            "elements": [
                "contenttweaker:spacexmachineblock@0"
            ]
        },
        {
            "x": 3,
            "y": 0,
            "z": 21,
            "elements": [
                "contenttweaker:asteroidcontrolblock@0"
            ]
        },
        {
            "x": 1,
            "y": -3,
            "z": 25,
            "elements": [
                "contenttweaker:spacexmachineblock@0"
            ]
        },
        {
            "x": 10,
            "y": 0,
            "z": 11,
            "elements": [
                "contenttweaker:dimensiontwistblock@0"
            ]
        },
        {
            "x": -1,
            "y": 2,
            "z": 25,
            "elements": [
                "contenttweaker:spacexmachineblock@0"
            ]
        },
        {
            "x": -13,
            "y": -2,
            "z": 13,
            "elements": [
                "contenttweaker:spacexmachineblock@0"
            ]
        },
        {
            "x": -1,
            "y": 10,
            "z": 21,
            "elements": [
                "contenttweaker:spacexmachineblock@0"
            ]
        },
        {
            "x": -9,
            "y": -5,
            "z": 12,
            "elements": [
                "contenttweaker:spacexmachineblock@0"
            ]
        },
        {
            "x": -2,
            "y": -1,
            "z": 2,
            "elements": [
                "contenttweaker:dimensiontwistblock@0"
            ]
        },
        {
            "x": -4,
            "y": 1,
            "z": 2,
            "elements": [
                "contenttweaker:spacexmachineblock@0"
            ]
        },
        {
            "x": 5,
            "y": -1,
            "z": 21,
            "elements": [
                "contenttweaker:spacexmachineblock@0"
            ]
        },
        {
            "x": 10,
            "y": 1,
            "z": 11,
            "elements": [
                "contenttweaker:spacexmachineblock@0"
            ]
        },
        {
            "x": 11,
            "y": 2,
            "z": 14,
            "elements": [
                "contenttweaker:spacexmachineblock@0"
            ]
        },
        {
            "x": -10,
            "y": -1,
            "z": 9,
            "elements": [
                "contenttweaker:dimensiontwistblock@0"
            ]
        },
        {
            "x": -1,
            "y": 3,
            "z": 25,
            "elements": [
                "contenttweaker:spacexmachineblock@0"
            ]
        },
        {
            "x": -10,
            "y": -2,
            "z": 9,
            "elements": [
                "contenttweaker:spacexmachineblock@0"
            ]
        },
        {
            "x": 1,
            "y": -4,
            "z": 25,
            "elements": [
                "contenttweaker:spacexmachineblock@0"
            ]
        },
        {
            "x": -1,
            "y": 4,
            "z": 25,
            "elements": [
                "contenttweaker:spacexmachineblock@0"
            ]
        },
        {
            "x": -1,
            "y": 11,
            "z": 21,
            "elements": [
                "contenttweaker:spacexmachineblock@0"
            ]
        },
        {
            "x": -10,
            "y": 1,
            "z": 17,
            "elements": [
                "contenttweaker:dimensiontwistblock@0"
            ]
        },
        {
            "x": 11,
            "y": -2,
            "z": 11,
            "elements": [
                "contenttweaker:spacexmachineblock@0"
            ]
        },
        {
            "x": 6,
            "y": -1,
            "z": 3,
            "elements": [
                "contenttweaker:spacexmachineblock@0"
            ]
        },
        {
            "x": 8,
            "y": 6,
            "z": 14,
            "elements": [
                "contenttweaker:spacexmachineblock@0"
            ]
        },
        {
            "x": -10,
            "y": -6,
            "z": 13,
            "elements": [
                "contenttweaker:spacexmachineblock@0"
            ]
        },
        {
            "x": 1,
            "y": -13,
            "z": 17,
            "elements": [
                "contenttweaker:spacexmachineblock@0"
            ]
        },
        {
            "x": 1,
            "y": -5,
            "z": 25,
            "elements": [
                "contenttweaker:spacexmachineblock@0"
            ]
        },
        {
            "x": 8,
            "y": 0,
            "z": 21,
            "elements": [
                "contenttweaker:dimensiontwistblock@0"
            ]
        },
        {
            "x": 0,
            "y": 14,
            "z": 19,
            "elements": [
                "contenttweaker:spacexmachineblock@0"
            ]
        },
        {
            "x": 0,
            "y": 0,
            "z": 16,
            "elements": [
                "contenttweaker:darkmatterblock@0"
            ]
        },
        {
            "x": 1,
            "y": 1,
            "z": 2,
            "elements": [
                "contenttweaker:dimensiontwistblock@0"
            ]
        },
        {
            "x": 9,
            "y": 0,
            "z": 11,
            "elements": [
                "contenttweaker:asteroidcontrolblock@0"
            ]
        },
        {
            "x": 1,
            "y": -1,
            "z": 2,
            "elements": [
                "contenttweaker:dimensiontwistblock@0"
            ]
        },
        {
            "x": 11,
            "y": 0,
            "z": 14,
            "elements": [
                "contenttweaker:novamatrix@0"
            ]
        },
        {
            "x": -10,
            "y": 0,
            "z": 6,
            "elements": [
                "contenttweaker:asteroidcontrolblock@0"
            ]
        },
        {
            "x": -11,
            "y": -1,
            "z": 17,
            "elements": [
                "contenttweaker:spacexmachineblock@0"
            ]
        },
        {
            "x": 8,
            "y": -1,
            "z": 21,
            "elements": [
                "contenttweaker:spacexmachineblock@0"
            ]
        },
        {
            "x": -10,
            "y": -1,
            "z": 12,
            "elements": [
                "contenttweaker:spacexmachineblock@0"
            ]
        },
        {
            "x": 11,
            "y": -1,
            "z": 11,
            "elements": [
                "contenttweaker:dimensiontwistblock@0"
            ]
        },
        {
            "x": -12,
            "y": 1,
            "z": 12,
            "elements": [
                "contenttweaker:spacexmachineblock@0"
            ]
        },
        {
            "x": 8,
            "y": 1,
            "z": 21,
            "elements": [
                "contenttweaker:spacexmachineblock@0"
            ]
        },
        {
            "x": -9,
            "y": 1,
            "z": 19,
            "elements": [
                "contenttweaker:dimensiontwistblock@0"
            ]
        },
        {
            "x": -9,
            "y": -6,
            "z": 13,
            "elements": [
                "contenttweaker:darkmatterblock@0"
            ]
        },
        {
            "x": -3,
            "y": 0,
            "z": 1,
            "elements": [
                "contenttweaker:asteroidcontrolblock@0"
            ]
        },
        {
            "x": -10,
            "y": 4,
            "z": 13,
            "elements": [
                "contenttweaker:stablestructure@0"
            ]
        },
        {
            "x": 10,
            "y": 2,
            "z": 17,
            "elements": [
                "contenttweaker:spacexmachineblock@0"
            ]
        },
        {
            "x": -11,
            "y": 3,
            "z": 12,
            "elements": [
                "contenttweaker:spacexmachineblock@0"
            ]
        },
        {
            "x": 0,
            "y": 0,
            "z": 15,
            "elements": [
                "contenttweaker:darkmatterblock@0"
            ]
        },
        {
            "x": -9,
            "y": -1,
            "z": 19,
            "elements": [
                "contenttweaker:dimensiontwistblock@0"
            ]
        },
        {
            "x": 7,
            "y": 0,
            "z": 3,
            "elements": [
                "contenttweaker:asteroidcontrolblock@0"
            ]
        },
        {
            "x": -7,
            "y": 6,
            "z": 13,
            "elements": [
                "contenttweaker:darkmatterblock@0"
            ]
        },
        {
            "x": 10,
            "y": 1,
            "z": 9,
            "elements": [
                "contenttweaker:dimensiontwistblock@0"
            ]
        },
        {
            "x": -4,
            "y": 0,
            "z": 13,
            "elements": [
                "contenttweaker:darkmatterblock@0"
            ]
        },
        {
            "x": 10,
            "y": 2,
            "z": 9,
            "elements": [
                "contenttweaker:spacexmachineblock@0"
            ]
        },
        {
            "x": -10,
            "y": 6,
            "z": 13,
            "elements": [
                "contenttweaker:spacexmachineblock@0"
            ]
        },
        {
            "x": 11,
            "y": -1,
            "z": 9,
            "elements": [
                "contenttweaker:spacexmachineblock@0"
            ]
        },
        {
            "x": -8,
            "y": -1,
            "z": 19,
            "elements": [
                "contenttweaker:spacexmachineblock@0"
            ]
        },
        {
            "x": -10,
            "y": 1,
            "z": 19,
            "elements": [
                "contenttweaker:spacexmachineblock@0"
            ]
        },
        {
            "x": 0,
            "y": 0,
            "z": 6,
            "elements": [
                "contenttweaker:darkmatterblock@0"
            ]
        },
        {
            "x": 0,
            "y": 0,
            "z": 1,
            "elements": [
                "contenttweaker:dimensiontwistblock@0"
            ]
        },
        {
            "x": 3,
            "y": -1,
            "z": 2,
            "elements": [
                "contenttweaker:spacexmachineblock@0"
            ]
        },
        {
            "x": 0,
            "y": -14,
            "z": 13,
            "elements": [
                "contenttweaker:novamatrix@0"
            ]
        },
        {
            "x": 12,
            "y": 0,
            "z": 9,
            "elements": [
                "contenttweaker:asteroidcontrolblock@0"
            ]
        },
        {
            "x": -9,
            "y": 5,
            "z": 14,
            "elements": [
                "contenttweaker:spacexmachineblock@0"
            ]
        },
        {
            "x": -1,
            "y": 0,
            "z": 13,
            "elements": [
                "contenttweaker:darkmatterblock@0"
            ]
        },
        {
            "x": -1,
            "y": 0,
            "z": 1,
            "elements": [
                "contenttweaker:dimensiontwistblock@0"
            ]
        },
        {
            "x": -10,
            "y": -2,
            "z": 10,
            "elements": [
                "contenttweaker:spacexmachineblock@0"
            ]
        },
        {
            "x": 5,
            "y": -2,
            "z": 22,
            "elements": [
                "contenttweaker:spacexmachineblock@0"
            ]
        },
        {
            "x": 3,
            "y": 0,
            "z": 22,
            "elements": [
                "contenttweaker:dimensiontwistblock@0"
            ]
        },
        {
            "x": 0,
            "y": -15,
            "z": 14,
            "elements": [
                "contenttweaker:spacexmachineblock@0"
            ]
        },
        {
            "x": 6,
            "y": 1,
            "z": 22,
            "elements": [
                "contenttweaker:dimensiontwistblock@0"
            ]
        },
        {
            "x": -10,
            "y": -1,
            "z": 14,
            "elements": [
                "contenttweaker:spacexmachineblock@0"
            ]
        },
        {
            "x": -12,
            "y": 0,
            "z": 10,
            "elements": [
                "contenttweaker:asteroidcontrolblock@0"
            ]
        },
        {
            "x": -9,
            "y": 1,
            "z": 7,
            "elements": [
                "contenttweaker:dimensiontwistblock@0"
            ]
        },
        {
            "x": -4,
            "y": 2,
            "z": 23,
            "elements": [
                "contenttweaker:spacexmachineblock@0"
            ]
        },
        {
            "x": -7,
            "y": 0,
            "z": 6,
            "elements": [
                "contenttweaker:dimensiontwistblock@0"
            ]
        },
        {
            "x": 1,
            "y": -8,
            "z": 23,
            "elements": [
                "contenttweaker:spacexmachineblock@0"
            ]
        },
        {
            "x": 5,
            "y": -1,
            "z": 22,
            "elements": [
                "contenttweaker:dimensiontwistblock@0"
            ]
        },
        {
            "x": -10,
            "y": 0,
            "z": 13,
            "elements": [
                "contenttweaker:dimensiontwistblock@0"
            ]
        },
        {
            "x": 6,
            "y": 0,
            "z": 22,
            "elements": [
                "contenttweaker:novamatrix@0"
            ]
        },
        {
            "x": -10,
            "y": 5,
            "z": 14,
            "elements": [
                "contenttweaker:spacexmachineblock@0"
            ]
        },
        {
            "x": -10,
            "y": -1,
            "z": 10,
            "elements": [
                "contenttweaker:dimensiontwistblock@0"
            ]
        },
        {
            "x": -11,
            "y": 2,
            "z": 13,
            "elements": [
                "contenttweaker:spacexmachineblock@0"
            ]
        },
        {
            "x": 10,
            "y": 0,
            "z": 17,
            "elements": [
                "contenttweaker:novamatrix@0"
            ]
        },
        {
            "x": -11,
            "y": 1,
            "z": 12,
            "elements": [
                "contenttweaker:dimensiontwistblock@0"
            ]
        },
        {
            "x": -8,
            "y": 1,
            "z": 19,
            "elements": [
                "contenttweaker:spacexmachineblock@0"
            ]
        },
        {
            "x": -2,
            "y": 0,
            "z": 1,
            "elements": [
                "contenttweaker:dimensiontwistblock@0"
            ]
        },
        {
            "x": -8,
            "y": 0,
            "z": 5,
            "elements": [
                "contenttweaker:dimensiontwistblock@0"
            ]
        },
        {
            "x": 0,
            "y": 0,
            "z": 22,
            "elements": [
                "contenttweaker:asteroidcontrolblock@0"
            ]
        },
        {
            "x": 3,
            "y": 1,
            "z": 22,
            "elements": [
                "contenttweaker:spacexmachineblock@0"
            ]
        },
        {
            "x": -10,
            "y": -1,
            "z": 7,
            "elements": [
                "contenttweaker:spacexmachineblock@0"
            ]
        },
        {
            "x": -6,
            "y": -6,
            "z": 13,
            "elements": [
                "contenttweaker:novamatrix@0"
            ]
        },
        {
            "x": -7,
            "y": 0,
            "z": 8,
            "elements": [
                "contenttweaker:asteroidcontrolblock@0"
            ]
        },
        {
            "x": -3,
            "y": -1,
            "z": 2,
            "elements": [
                "contenttweaker:spacexmachineblock@0"
            ]
        },
        {
            "x": 0,
            "y": 1,
            "z": 22,
            "elements": [
                "contenttweaker:spacexmachineblock@0"
            ]
        },
        {
            "x": -6,
            "y": 0,
            "z": 6,
            "elements": [
                "contenttweaker:asteroidcontrolblock@0"
            ]
        },
        {
            "x": -11,
            "y": 0,
            "z": 13,
            "elements": [
                "contenttweaker:novamatrix@0"
            ]
        },
        {
            "x": -8,
            "y": 1,
            "z": 5,
            "elements": [
                "contenttweaker:spacexmachineblock@0"
            ]
        },
        {
            "x": -4,
            "y": 0,
            "z": 23,
            "elements": [
                "contenttweaker:novamatrix@0"
            ]
        },
        {
            "x": 6,
            "y": 2,
            "z": 22,
            "elements": [
                "contenttweaker:spacexmachineblock@0"
            ]
        },
        {
            "x": -8,
            "y": -2,
            "z": 6,
            "elements": [
                "contenttweaker:spacexmachineblock@0"
            ]
        },
        {
            "x": -10,
            "y": 2,
            "z": 13,
            "elements": [
                "contenttweaker:stablestructure@0"
            ]
        },
        {
            "x": 0,
            "y": 14,
            "z": 15,
            "elements": [
                "contenttweaker:stablestructure@0"
            ]
        },
        {
            "x": 1,
            "y": -12,
            "z": 20,
            "elements": [
                "contenttweaker:spacexmachineblock@0"
            ]
        },
        {
            "x": -10,
            "y": 1,
            "z": 14,
            "elements": [
                "contenttweaker:spacexmachineblock@0"
            ]
        },
        {
            "x": 1,
            "y": -11,
            "z": 20,
            "elements": [
                "contenttweaker:spacexmachineblock@0"
            ]
        },
        {
            "x": 9,
            "y": 0,
            "z": 9,
            "elements": [
                "contenttweaker:dimensiontwistblock@0"
            ]
        },
        {
            "x": -8,
            "y": 0,
            "z": 13,
            "elements": [
                "contenttweaker:novamatrix@0"
            ]
        },
        {
            "x": -1,
            "y": 0,
            "z": 23,
            "elements": [
                "contenttweaker:dimensiontwistblock@0"
            ]
        },
        {
            "x": 7,
            "y": 0,
            "z": 8,
