{
    "registryname": "Mega_PsionicSiphonMatrix",
    "localizedname": "§d灵能§e虹吸§c矩阵",
    "failure-action": "still",
    "requires-blueprint": false,
    "has-factory": true,
    "factory-only": true,
    "color": "191970",
    "parts": [
        {
            "x": 0,
            "y": 0,
            "z": 0,
            "elements": [
                "modularmachinery:blockfactorycontroller@2"
            ]
        },
        {
            "x": -5,
            "y": 11,
            "z": 11,
            "elements": [
                "contenttweaker:spacexmachineblock@0"
            ]
        },
        {
            "x": -2,
            "y": -6,
            "z": 10,
            "elements": [
                "contenttweaker:superglasswhite@0"
            ]
        },
        {
            "x": 0,
            "y": -2,
            "z": 0,
            "elements": [
                "contenttweaker:spacexmachineblock@0"
            ]
        },
        {
            "x": -4,
            "y": -2,
            "z": 10,
            "elements": [
                "contenttweaker:superglasswhite@0"
            ]
        },
        {
            "x": -6,
            "y": 0,
            "z": 10,
            "elements": [
                "contenttweaker:gama_tial_coil_block@0"
            ]
        },
        {
            "x": -1,
            "y": 0,
            "z": 19,
            "elements": [
                "contenttweaker:gama_tial_coil_block@0"
            ]
        },
        {
            "x": -1,
            "y": -11,
            "z": 11,
            "elements": [
                "casings_all",
                "modularmachinery:blockmepatternprovider",
                "modularmachinery:blockmepatternmirrorimage"
            ]
        },
        {
            "x": -5,
            "y": 2,
            "z": 10,
            "elements": [
                "contenttweaker:superglasswhite@0"
            ]
        },
        {
            "x": -2,
            "y": 5,
            "z": 11,
            "elements": [
                "contenttweaker:superglasswhite@0"
            ]
        },
        {
            "x": 1,
            "y": -5,
            "z": 12,
            "elements": [
                "astralsorcery:fluidblockliquidstarlight@1"
            ]
        },
        {
            "x": -10,
            "y": 3,
            "z": 12,
            "elements": [
                "contenttweaker:spacexmachineblock@0"
            ]
        },
        {
            "x": -8,
            "y": -2,
            "z": 12,
            "elements": [
                "contenttweaker:superglasswhite@0"
            ]
        },
        {
            "x": -10,
            "y": -1,
            "z": 11,
            "elements": [
                "contenttweaker:spacexmachineblock@0"
            ]
        },
        {
            "x": 1,
            "y": 5,
            "z": 9,
            "elements": [
                "contenttweaker:superglasswhite@0"
            ]
        },
        {
            "x": 1,
            "y": -9,
            "z": 12,
            "elements": [
                "contenttweaker:stablestructure@0"
            ]
        },
        {
            "x": 5,
            "y": -11,
            "z": 11,
            "elements": [
                "contenttweaker:spacexmachineblock@0"
            ]
        },
        {
            "x": 2,
            "y": -9,
            "z": 11,
            "elements": [
                "contenttweaker:stablestructure@0"
            ]
        },
        {
            "x": 0,
            "y": -10,
            "z": 10,
            "elements": [
                "contenttweaker:spacexmachineblock@0"
            ]
        },
        {
            "x": -1,
            "y": -8,
            "z": 10,
            "elements": [
                "contenttweaker:infinite_coil@0"
            ]
        },
        {
            "x": 3,
            "y": -1,
            "z": 9,
            "elements": [
                "contenttweaker:superglasswhite@0"
            ]
        },
        {
            "x": -1,
            "y": -7,
            "z": 11,
            "elements": [
                "contenttweaker:infinite_coil@0"
            ]
        },
        {
            "x": 2,
            "y": 0,
            "z": 0,
            "elements": [
                "contenttweaker:spacexmachineblock@0"
            ]
        },
        {
            "x": 2,
            "y": 1,
            "z": 17,
            "elements": [
                "contenttweaker:superglasswhite@0"
            ]
        },
        {
            "x": -1,
            "y": -2,
            "z": 5,
            "elements": [
                "contenttweaker:superglasswhite@0"
            ]
        },
        {
            "x": -2,
            "y": -2,
            "z": 10,
            "elements": [
                "astralsorcery:fluidblockliquidstarlight@0"
            ]
        },
        {
            "x": -7,
            "y": 2,
            "z": 10,
            "elements": [
                "contenttweaker:superglasswhite@0"
            ]
        },
        {
            "x": -4,
            "y": 0,
            "z": 10,
            "elements": [
                "astralsorcery:fluidblockliquidstarlight@0"
            ]
        },
        {
            "x": -3,
            "y": 3,
            "z": 11,
            "elements": [
                "chisel:futura@2"
            ]
        },
        {
            "x": 2,
            "y": -5,
            "z": 11,
            "elements": [
                "contenttweaker:superglasswhite@0"
            ]
        },
        {
            "x": -2,
            "y": 1,
            "z": 11,
            "elements": [
                "astralsorcery:fluidblockliquidstarlight@1"
            ]
        },
        {
            "x": -2,
            "y": -10,
            "z": 12,
            "elements": [
                "contenttweaker:spacexmachineblock@0"
            ]
        },
        {
            "x": -1,
            "y": -3,
            "z": 11,
            "elements": [
                "astralsorcery:fluidblockliquidstarlight@1"
            ]
        },
        {
            "x": 0,
            "y": -1,
            "z": 11,
            "elements": [
                "astralsorcery:fluidblockliquidstarlight@0"
            ]
        },
        {
            "x": 0,
            "y": 2,
            "z": 5,
            "elements": [
                "contenttweaker:superglasswhite@0"
            ]
        },
        {
            "x": 2,
            "y": -10,
            "z": 10,
            "elements": [
                "contenttweaker:spacexmachineblock@0"
            ]
        },
        {
            "x": 2,
            "y": -6,
            "z": 10,
            "elements": [
                "contenttweaker:superglasswhite@0"
            ]
        },
        {
            "x": -3,
            "y": 0,
            "z": 22,
            "elements": [
                "contenttweaker:spacexmachineblock@0"
            ]
        },
        {
            "x": 11,
            "y": 0,
            "z": 19,
            "elements": [
                "contenttweaker:spacexmachineblock@0"
            ]
        },
        {
            "x": 4,
            "y": 0,
            "z": 0,
            "elements": [
                "contenttweaker:spacexmachineblock@0"
            ]
        },
        {
            "x": -1,
            "y": 6,
            "z": 12,
            "elements": [
                "astralsorcery:fluidblockliquidstarlight@0"
            ]
        },
        {
            "x": 1,
            "y": -2,
            "z": 5,
            "elements": [
                "contenttweaker:superglasswhite@0"
            ]
        },
        {
            "x": 1,
            "y": -8,
            "z": 10,
            "elements": [
                "contenttweaker:infinite_coil@0"
            ]
        },
        {
            "x": 2,
            "y": -1,
            "z": 4,
            "elements": [
                "contenttweaker:superglasswhite@0"
            ]
        },
        {
            "x": -9,
            "y": 11,
            "z": 11,
            "elements": [
                "contenttweaker:spacexmachineblock@0"
            ]
        },
        {
            "x": -8,
            "y": -2,
            "z": 10,
            "elements": [
                "contenttweaker:superglasswhite@0"
            ]
        },
        {
            "x": 0,
            "y": 1,
            "z": 4,
            "elements": [
                "contenttweaker:gama_tial_coil_block@0"
            ]
        },
        {
            "x": -1,
            "y": -4,
            "z": 10,
            "elements": [
                "astralsorcery:fluidblockliquidstarlight@1"
            ]
        },
        {
            "x": -10,
            "y": 0,
            "z": 10,
            "elements": [
                "contenttweaker:spacexmachineblock@0"
            ]
        },
        {
            "x": 0,
            "y": -10,
            "z": 0,
            "elements": [
                "contenttweaker:spacexmachineblock@0"
            ]
        },
        {
            "x": -1,
            "y": 1,
            "z": 16,
            "elements": [
                "astralsorcery:fluidblockliquidstarlight@0"
            ]
        },
        {
            "x": -9,
            "y": 2,
            "z": 10,
            "elements": [
                "contenttweaker:stablestructure@0"
            ]
        },
        {
            "x": 1,
            "y": -1,
            "z": 16,
            "elements": [
                "astralsorcery:fluidblockliquidstarlight@1"
            ]
        },
        {
            "x": -11,
            "y": 7,
            "z": 11,
            "elements": [
                "contenttweaker:spacexmachineblock@0"
            ]
        },
        {
            "x": 1,
            "y": 9,
            "z": 9,
            "elements": [
                "contenttweaker:stablestructure@0"
            ]
        },
        {
            "x": -3,
            "y": -3,
            "z": 11,
            "elements": [
                "chisel:futura@2"
            ]
        },
        {
            "x": 7,
            "y": 1,
            "z": 9,
            "elements": [
                "contenttweaker:superglasswhite@0"
            ]
        },
        {
            "x": -1,
            "y": 4,
            "z": 12,
            "elements": [
                "astralsorcery:fluidblockliquidstarlight@1"
            ]
        },
        {
            "x": 0,
            "y": -5,
            "z": 11,
            "elements": [
                "contenttweaker:infinite_coil@0"
            ]
        },
        {
            "x": -8,
            "y": 1,
            "z": 11,
            "elements": [
                "contenttweaker:gama_tial_coil_block@0"
            ]
        },
        {
            "x": -2,
            "y": 3,
            "z": 9,
            "elements": [
                "chisel:futura@2"
            ]
        },
        {
            "x": -6,
            "y": -1,
            "z": 11,
            "elements": [
                "contenttweaker:gama_tial_coil_block@0"
            ]
        },
        {
            "x": -1,
            "y": 5,
            "z": 12,
            "elements": [
                "astralsorcery:fluidblockliquidstarlight@1"
            ]
        },
        {
            "x": 1,
            "y": -11,
            "z": 11,
            "elements": [
                "casings_all",
                "modularmachinery:blockmepatternprovider",
                "modularmachinery:blockmepatternmirrorimage"
            ]
        },
        {
            "x": -2,
            "y": -9,
            "z": 11,
            "elements": [
                "contenttweaker:stablestructure@0"
            ]
        },
        {
            "x": 0,
            "y": -3,
            "z": 9,
            "elements": [
                "contenttweaker:superglasswhite@0"
            ]
        },
        {
            "x": 2,
            "y": 3,
            "z": 12,
            "elements": [
                "contenttweaker:superglasswhite@0"
            ]
        },
        {
            "x": -2,
            "y": 0,
            "z": 0,
            "elements": [
                "contenttweaker:spacexmachineblock@0"
            ]
        },
        {
            "x": 0,
            "y": 11,
            "z": 6,
            "elements": [
                "contenttweaker:spacexmachineblock@0"
            ]
        },
        {
            "x": -1,
            "y": 0,
            "z": 22,
            "elements": [
                "casings_all",
                "modularmachinery:blockmepatternprovider",
                "modularmachinery:blockmepatternmirrorimage"
            ]
        },
        {
            "x": -11,
            "y": 11,
            "z": 11,
            "elements": [
                "contenttweaker:spacexmachineblock@0"
            ]
        },
        {
            "x": -1,
            "y": 0,
            "z": 5,
            "elements": [
                "contenttweaker:gama_tial_coil_block@0"
            ]
        },
        {
            "x": 0,
            "y": 0,
            "z": 10,
            "elements": [
                "astralsorcery:fluidblockliquidstarlight@1"
            ]
        },
        {
            "x": 0,
            "y": -6,
            "z": 0,
            "elements": [
                "contenttweaker:spacexmachineblock@0"
            ]
        },
        {
            "x": -3,
            "y": 2,
            "z": 10,
            "elements": [
                "contenttweaker:superglasswhite@0"
            ]
        },
        {
            "x": 1,
            "y": 1,
            "z": 16,
            "elements": [
                "astralsorcery:fluidblockliquidstarlight@1"
            ]
        },
        {
            "x": 4,
            "y": -2,
            "z": 12,
            "elements": [
                "contenttweaker:superglasswhite@0"
            ]
        },
        {
            "x": 2,
            "y": -2,
            "z": 10,
            "elements": [
                "astralsorcery:fluidblockliquidstarlight@0"
            ]
        },
        {
            "x": -1,
            "y": 2,
            "z": 12,
            "elements": [
                "astralsorcery:fluidblockliquidstarlight@1"
            ]
        },
        {
            "x": 0,
            "y": 4,
            "z": 10,
            "elements": [
                "astralsorcery:fluidblockliquidstarlight@1"
            ]
        },
        {
            "x": -6,
            "y": 1,
            "z": 11,
            "elements": [
                "contenttweaker:gama_tial_coil_block@0"
            ]
        },
        {
            "x": 2,
            "y": -1,
            "z": 7,
            "elements": [
                "contenttweaker:superglasswhite@0"
            ]
        },
        {
            "x": 1,
            "y": -1,
            "z": 12,
            "elements": [
                "astralsorcery:fluidblockliquidstarlight@1"
            ]
        },
        {
            "x": 9,
            "y": -1,
            "z": 9,
            "elements": [
                "contenttweaker:stablestructure@0"
            ]
        },
        {
            "x": 1,
            "y": 1,
            "z": 9,
            "elements": [
                "astralsorcery:fluidblockliquidstarlight@1"
            ]
        },
        {
            "x": 0,
            "y": 2,
            "z": 7,
            "elements": [
                "contenttweaker:superglasswhite@0"
            ]
        },
        {
            "x": -1,
            "y": 1,
            "z": 12,
            "elements": [
                "astralsorcery:fluidblockliquidstarlight@1"
            ]
        },
        {
            "x": -1,
            "y": 2,
            "z": 19,
            "elements": [
                "contenttweaker:superglasswhite@0"
            ]
        },
        {
            "x": -4,
            "y": -1,
            "z": 11,
            "elements": [
                "astralsorcery:fluidblockliquidstarlight@0"
            ]
        },
        {
            "x": 0,
            "y": -9,
            "z": 11,
            "elements": [
                "contenttweaker:stablestructure@0"
            ]
        },
        {
            "x": -1,
            "y": 0,
            "z": 12,
            "elements": [
                "astralsorcery:fluidblockliquidstarlight@1"
            ]
        },
        {
            "x": -2,
            "y": -10,
            "z": 10,
            "elements": [
                "contenttweaker:spacexmachineblock@0"
            ]
        },
        {
            "x": 1,
            "y": -1,
            "z": 19,
            "elements": [
                "contenttweaker:gama_tial_coil_block@0"
            ]
        },
        {
            "x": -2,
            "y": -5,
            "z": 11,
            "elements": [
                "contenttweaker:superglasswhite@0"
            ]
        },
        {
            "x": 11,
            "y": 0,
            "z": 17,
            "elements": [
                "contenttweaker:spacexmachineblock@0"
            ]
        },
        {
            "x": -1,
            "y": 1,
            "z": 19,
            "elements": [
                "contenttweaker:gama_tial_coil_block@0"
            ]
        },
        {
            "x": 0,
            "y": 1,
            "z": 8,
            "elements": [
                "astralsorcery:fluidblockliquidstarlight@0"
            ]
        },
        {
            "x": 5,
            "y": 2,
            "z": 12,
            "elements": [
                "contenttweaker:superglasswhite@0"
            ]
        },
        {
            "x": 1,
            "y": -9,
            "z": 9,
            "elements": [
                "contenttweaker:stablestructure@0"
            ]
        },
        {
            "x": 8,
            "y": 0,
            "z": 0,
            "elements": [
                "contenttweaker:spacexmachineblock@0"
            ]
        },
        {
            "x": -9,
            "y": -11,
            "z": 11,
            "elements": [
                "contenttweaker:spacexmachineblock@0"
            ]
        },
        {
            "x": 3,
            "y": 11,
            "z": 11,
            "elements": [
                "contenttweaker:spacexmachineblock@0"
            ]
        },
        {
            "x": 0,
            "y": 9,
            "z": 11,
            "elements": [
                "contenttweaker:stablestructure@0"
            ]
        },
        {
            "x": -7,
            "y": 0,
            "z": 22,
            "elements": [
                "contenttweaker:spacexmachineblock@0"
            ]
        },
        {
            "x": -1,
            "y": -5,
            "z": 9,
            "elements": [
                "contenttweaker:superglasswhite@0"
            ]
        },
        {
            "x": 0,
            "y": 8,
            "z": 10,
            "elements": [
                "contenttweaker:gama_tial_coil_block@0"
            ]
        },
        {
            "x": -3,
            "y": 10,
            "z": 10,
            "elements": [
                "contenttweaker:spacexmachineblock@0"
            ]
        },
        {
            "x": 3,
            "y": 0,
            "z": 8,
            "elements": [
                "chisel:futura@2"
            ]
        },
        {
            "x": 3,
            "y": 2,
            "z": 10,
            "elements": [
                "contenttweaker:superglasswhite@0"
            ]
        },
        {
            "x": 0,
            "y": -11,
            "z": 9,
            "elements": [
                "contenttweaker:spacexmachineblock@0"
            ]
        },
        {
            "x": 0,
            "y": 2,
            "z": 8,
            "elements": [
                "contenttweaker:superglasswhite@0"
            ]
        },
        {
            "x": 0,
            "y": 11,
            "z": 13,
            "elements": [
                "contenttweaker:spacexmachineblock@0"
            ]
        },
        {
            "x": -2,
            "y": -1,
            "z": 18,
            "elements": [
                "contenttweaker:superglasswhite@0"
            ]
        },
        {
            "x": 7,
            "y": -1,
            "z": 12,
            "elements": [
                "astralsorcery:fluidblockliquidstarlight@1"
            ]
        },
        {
            "x": 0,
            "y": 3,
            "z": 8,
            "elements": [
                "chisel:futura@2"
            ]
        },
        {
            "x": 5,
            "y": 1,
            "z": 12,
            "elements": [
                "astralsorcery:fluidblockliquidstarlight@1"
            ]
        },
        {
            "x": -1,
            "y": -2,
            "z": 8,
            "elements": [
                "contenttweaker:superglasswhite@0"
            ]
        },
        {
            "x": 2,
            "y": -1,
            "z": 21,
            "elements": [
                "contenttweaker:spacexmachineblock@0"
            ]
        },
        {
            "x": -5,
            "y": -1,
            "z": 9,
            "elements": [
                "contenttweaker:superglasswhite@0"
            ]
        },
        {
            "x": -1,
            "y": 0,
            "z": 18,
            "elements": [
                "contenttweaker:gama_tial_coil_block@0"
            ]
        },
        {
            "x": 1,
            "y": -2,
            "z": 18,
            "elements": [
                "contenttweaker:superglasswhite@0"
            ]
        },
        {
            "x": -1,
            "y": -3,
            "z": 8,
            "elements": [
                "chisel:futura@2"
            ]
        },
        {
            "x": 5,
            "y": 0,
            "z": 12,
            "elements": [
                "astralsorcery:fluidblockliquidstarlight@0"
            ]
        },
        {
            "x": -5,
            "y": 1,
            "z": 9,
            "elements": [
                "contenttweaker:superglasswhite@0"
            ]
        },
        {
            "x": -1,
            "y": 1,
            "z": 18,
            "elements": [
                "astralsorcery:fluidblockliquidstarlight@1"
            ]
        },
        {
            "x": 6,
            "y": 0,
            "z": 13,
            "elements": [
                "contenttweaker:superglasswhite@0"
            ]
        },
        {
            "x": 10,
            "y": 0,
            "z": 0,
            "elements": [
                "contenttweaker:spacexmachineblock@0"
            ]
        },
        {
            "x": 0,
            "y": -7,
            "z": 9,
            "elements": [
                "contenttweaker:superglasswhite@0"
            ]
        },
        {
            "x": -2,
            "y": 1,
            "z": 4,
            "elements": [
                "contenttweaker:superglasswhite@0"
            ]
        },
        {
            "x": -3,
            "y": -11,
            "z": 11,
            "elements": [
                "contenttweaker:spacexmachineblock@0"
            ]
        },
        {
            "x": 0,
            "y": 9,
            "z": 13,
            "elements": [
                "contenttweaker:stablestructure@0"
            ]
        },
        {
            "x": 6,
            "y": -2,
            "z": 10,
            "elements": [
                "contenttweaker:superglasswhite@0"
            ]
        },
        {
            "x": -2,
            "y": 8,
            "z": 10,
            "elements": [
                "contenttweaker:superglasswhite@0"
            ]
        },
        {
            "x": 5,
            "y": -1,
            "z": 13,
            "elements": [
                "contenttweaker:superglasswhite@0"
            ]
        },
        {
            "x": 5,
            "y": 1,
            "z": 13,
            "elements": [
                "contenttweaker:superglasswhite@0"
            ]
        },
        {
            "x": 6,
            "y": 1,
            "z": 11,
            "elements": [
                "contenttweaker:gama_tial_coil_block@0"
            ]
        },
        {
            "x": 1,
            "y": 6,
            "z": 10,
            "elements": [
                "astralsorcery:fluidblockliquidstarlight@0"
            ]
        },
        {
            "x": 4,
            "y": 0,
            "z": 10,
            "elements": [
                "astralsorcery:fluidblockliquidstarlight@1"
            ]
        },
        {
            "x": 1,
            "y": 2,
            "z": 10,
            "elements": [
                "astralsorcery:fluidblockliquidstarlight@1"
            ]
        },
        {
            "x": 11,
            "y": 0,
            "z": 12,
            "elements": [
                "casings_all",
                "modularmachinery:blockmepatternprovider",
                "modularmachinery:blockmepatternmirrorimage"
            ]
        },
        {
            "x": -1,
            "y": -1,
            "z": 8,
            "elements": [
                "astralsorcery:fluidblockliquidstarlight@1"
            ]
        },
        {
            "x": 0,
            "y": 7,
            "z": 13,
            "elements": [
                "contenttweaker:superglasswhite@0"
            ]
        },
        {
            "x": 1,
            "y": -2,
            "z": 15,
            "elements": [
                "contenttweaker:superglasswhite@0"
            ]
        },
        {
            "x": -1,
            "y": 8,
            "z": 12,
            "elements": [
                "contenttweaker:gama_tial_coil_block@0"
            ]
        },
        {
            "x": 1,
            "y": 2,
            "z": 3,
            "elements": [
                "contenttweaker:superglasswhite@0"
            ]
        },
        {
            "x": 4,
            "y": -1,
            "z": 13,
            "elements": [
                "contenttweaker:superglasswhite@0"
            ]
        },
        {
            "x": 0,
            "y": 8,
            "z": 13,
            "elements": [
                "contenttweaker:superglasswhite@0"
            ]
        },
        {
            "x": -3,
            "y": -1,
            "z": 9,
            "elements": [
                "contenttweaker:superglasswhite@0"
            ]
        },
        {
            "x": 3,
            "y": -11,
            "z": 11,
            "elements": [
                "contenttweaker:spacexmachineblock@0"
            ]
        },
        {
            "x": 6,
            "y": 1,
            "z": 13,
            "elements": [
                "contenttweaker:superglasswhite@0"
            ]
        },
        {
            "x": -1,
            "y": 10,
            "z": 12,
            "elements": [
                "contenttweaker:spacexmachineblock@0"
            ]
        },
        {
            "x": -2,
            "y": -1,
            "z": 4,
            "elements": [
                "contenttweaker:superglasswhite@0"
            ]
        },
        {
            "x": 2,
            "y": 7,
            "z": 12,
            "elements": [
                "contenttweaker:superglasswhite@0"
            ]
        },
        {
            "x": -3,
            "y": 1,
            "z": 9,
            "elements": [
                "contenttweaker:superglasswhite@0"
            ]
        },
        {
            "x": -1,
            "y": 9,
            "z": 12,
            "elements": [
                "contenttweaker:stablestructure@0"
            ]
        },
        {
            "x": -4,
            "y": 0,
            "z": 0,
            "elements": [
                "contenttweaker:spacexmachineblock@0"
            ]
        },
        {
            "x": 8,
            "y": 0,
            "z": 13,
            "elements": [
                "contenttweaker:superglasswhite@0"
            ]
        },
        {
            "x": 0,
            "y": 11,
            "z": 8,
            "elements": [
                "contenttweaker:spacexmachineblock@0"
            ]
        },
        {
            "x": -11,
            "y": 0,
            "z": 22,
            "elements": [
                "contenttweaker:spacexmachineblock@0"
            ]
        },
        {
            "x": -1,
            "y": 2,
            "z": 17,
            "elements": [
                "contenttweaker:superglasswhite@0"
            ]
        },
        {
            "x": 0,
            "y": -2,
            "z": 10,
            "elements": [
                "astralsorcery:fluidblockliquidstarlight@0"
            ]
        },
        {
            "x": 3,
            "y": 3,
            "z": 11,
            "elements": [
                "chisel:futura@2"
            ]
        },
        {
            "x": 0,
            "y": 0,
            "z": 3,
            "elements": [
                "contenttweaker:gama_tial_coil_block@0"
            ]
        },
        {
            "x": -2,
            "y": 0,
            "z": 10,
            "elements": [
                "astralsorcery:fluidblockliquidstarlight@1"
            ]
        },
        {
            "x": 10,
            "y": -2,
            "z": 12,
            "elements": [
                "contenttweaker:spacexmachineblock@0"
            ]
        },
        {
            "x": 0,
            "y": 1,
            "z": 11,
            "elements": [
                "astralsorcery:fluidblockliquidstarlight@0"
            ]
        },
        {
            "x": 2,
            "y": -1,
            "z": 11,
            "elements": [
                "astralsorcery:fluidblockliquidstarlight@1"
            ]
        },
        {
            "x": 0,
            "y": 0,
            "z": 20,
            "elements": [
                "contenttweaker:stablestructure@0"
            ]
        },
        {
            "x": -2,
            "y": 4,
            "z": 10,
            "elements": [
                "contenttweaker:superglasswhite@0"
            ]
        },
        {
            "x": -1,
            "y": 0,
            "z": 15,
            "elements": [
                "astralsorcery:fluidblockliquidstarlight@1"
            ]
        },
        {
            "x": -11,
            "y": 3,
            "z": 11,
            "elements": [
                "contenttweaker:spacexmachineblock@0"
            ]
        },
        {
            "x": -1,
            "y": -3,
            "z": 21,
            "elements": [
                "contenttweaker:spacexmachineblock@0"
            ]
        },
        {
            "x": 10,
            "y": -3,
            "z": 12,
            "elements": [
                "contenttweaker:spacexmachineblock@0"
            ]
        },
        {
            "x": 0,
            "y": 10,
            "z": 14,
            "elements": [
                "contenttweaker:spacexmachineblock@0"
            ]
        },
        {
            "x": 1,
            "y": -5,
            "z": 9,
            "elements": [
                "contenttweaker:superglasswhite@0"
            ]
        },
        {
            "x": 10,
            "y": -1,
            "z": 13,
            "elements": [
                "contenttweaker:spacexmachineblock@0"
            ]
        },
        {
            "x": 9,
            "y": 1,
            "z": 12,
            "elements": [
                "contenttweaker:stablestructure@0"
            ]
        },
        {
            "x": 0,
            "y": 10,
            "z": 8,
            "elements": [
                "contenttweaker:spacexmachineblock@0"
            ]
        },
        {
            "x": -9,
            "y": -1,
            "z": 9,
            "elements": [
                "contenttweaker:stablestructure@0"
            ]
        },
        {
            "x": -10,
            "y": 0,
            "z": 0,
            "elements": [
                "contenttweaker:spacexmachineblock@0"
            ]
        },
        {
            "x": -1,
            "y": 1,
            "z": 9,
            "elements": [
                "astralsorcery:fluidblockliquidstarlight@1"
            ]
        },
        {
            "x": 9,
            "y": -11,
            "z": 11,
            "elements": [
                "contenttweaker:spacexmachineblock@0"
            ]
        },
        {
            "x": 0,
            "y": -11,
            "z": 16,
            "elements": [
                "contenttweaker:spacexmachineblock@0"
            ]
        },
        {
            "x": 10,
            "y": -2,
            "z": 13,
            "elements": [
                "contenttweaker:spacexmachineblock@0"
            ]
        },
        {
            "x": 0,
            "y": -6,
            "z": 10,
            "elements": [
                "contenttweaker:infinite_coil@0"
            ]
        },
        {
            "x": -3,
            "y": 11,
            "z": 11,
            "elements": [
                "contenttweaker:spacexmachineblock@0"
            ]
        },
        {
            "x": 0,
            "y": -1,
            "z": 4,
            "elements": [
                "contenttweaker:gama_tial_coil_block@0"
            ]
        },
        {
            "x": 11,
            "y": 0,
            "z": 18,
            "elements": [
                "contenttweaker:spacexmachineblock@0"
            ]
        },
        {
            "x": -8,
            "y": 0,
            "z": 10,
            "elements": [
                "contenttweaker:gama_tial_coil_block@0"
            ]
        },
        {
            "x": -9,
            "y": 0,
            "z": 22,
            "elements": [
                "contenttweaker:spacexmachineblock@0"
            ]
        },
        {
            "x": 2,
            "y": 1,
            "z": 4,
            "elements": [
                "contenttweaker:superglasswhite@0"
            ]
        },
        {
            "x": -6,
            "y": -2,
            "z": 10,
            "elements": [
                "contenttweaker:superglasswhite@0"
            ]
        },
        {
            "x": 11,
            "y": 0,
            "z": 21,
            "elements": [
                "contenttweaker:spacexmachineblock@0"
            ]
        },
        {
            "x": -1,
            "y": 2,
            "z": 3,
            "elements": [
                "contenttweaker:superglasswhite@0"
            ]
        },
        {
            "x": 0,
            "y": 5,
            "z": 11,
            "elements": [
                "contenttweaker:gama_tial_coil_block@0"
            ]
        },
        {
            "x": 2,
            "y": -1,
            "z": 14,
            "elements": [
                "contenttweaker:superglasswhite@0"
            ]
        },
        {
            "x": 1,
            "y": 3,
            "z": 11,
            "elements": [
                "astralsorcery:fluidblockliquidstarlight@0"
            ]
        },
        {
            "x": -2,
            "y": 0,
            "z": 3,
            "elements": [
                "contenttweaker:superglasswhite@0"
            ]
        },
        {
            "x": 0,
            "y": -2,
            "z": 3,
            "elements": [
                "contenttweaker:superglasswhite@0"
            ]
        },
        {
            "x": 3,
            "y": -3,
            "z": 11,
            "elements": [
                "chisel:futura@2"
            ]
        },
        {
            "x": -2,
            "y": -3,
            "z": 9,
            "elements": [
                "chisel:futura@2"
            ]
        },
        {
            "x": 0,
            "y": 1,
            "z": 21,
            "elements": [
                "contenttweaker:spacexmachineblock@0"
            ]
        },
        {
            "x": 1,
            "y": -1,
            "z": 9,
            "elements": [
                "astralsorcery:fluidblockliquidstarlight@1"
            ]
        },
        {
            "x": -7,
            "y": 1,
            "z": 9,
            "elements": [
                "contenttweaker:superglasswhite@0"
            ]
        },
        {
            "x": 0,
            "y": 2,
            "z": 16,
            "elements": [
                "contenttweaker:superglasswhite@0"
            ]
        },
        {
            "x": 1,
            "y": 6,
            "z": 11,
            "elements": [
                "contenttweaker:gama_tial_coil_block@0"
            ]
        },
        {
            "x": 0,
            "y": 11,
            "z": 12,
            "elements": [
                "casings_all",
                "modularmachinery:blockmepatternprovider",
                "modularmachinery:blockmepatternmirrorimage"
            ]
        },
        {
            "x": -1,
            "y": -1,
            "z": 19,
            "elements": [
                "contenttweaker:gama_tial_coil_block@0"
            ]
        },
        {
            "x": 7,
            "y": 2,
            "z": 11,
            "elements": [
                "contenttweaker:superglasswhite@0"
            ]
        },
        {
            "x": 0,
            "y": 8,
            "z": 9,
            "elements": [
                "contenttweaker:superglasswhite@0"
            ]
        },
        {
            "x": 1,
            "y": 7,
            "z": 11,
            "elements": [
                "contenttweaker:gama_tial_coil_block@0"
            ]
        },
        {
            "x": 0,
            "y": 7,
            "z": 9,
            "elements": [
                "contenttweaker:superglasswhite@0"
            ]
        },
        {
            "x": 4,
            "y": 1,
            "z": 11,
            "elements": [
                "astralsorcery:fluidblockliquidstarlight@1"
            ]
        },
        {
            "x": 0,
            "y": 6,
            "z": 9,
            "elements": [
                "contenttweaker:superglasswhite@0"
            ]
        },
        {
            "x": 10,
            "y": 0,
            "z": 10,
            "elements": [
                "contenttweaker:spacexmachineblock@0"
            ]
        },
        {
            "x": 2,
            "y": 1,
            "z": 14,
            "elements": [
                "contenttweaker:superglasswhite@0"
            ]
        },
        {
            "x": -1,
            "y": 3,
            "z": 14,
            "elements": [
                "chisel:futura@2"
            ]
        },
        {
            "x": 3,
            "y": 1,
            "z": 9,
            "elements": [
                "contenttweaker:superglasswhite@0"
            ]
        },
        {
            "x": -1,
            "y": -1,
            "z": 12,
            "elements": [
                "astralsorcery:fluidblockliquidstarlight@1"
            ]
        },
        {
            "x": 2,
            "y": -10,
            "z": 13,
            "elements": [
                "contenttweaker:spacexmachineblock@0"
            ]
        },
        {
            "x": -3,
            "y": 1,
            "z": 12,
            "elements": [
                "astralsorcery:fluidblockliquidstarlight@0"
            ]
        },
        {
            "x": 9,
            "y": 2,
            "z": 10,
            "elements": [
                "contenttweaker:stablestructure@0"
            ]
        },
        {
            "x": 1,
            "y": 4,
            "z": 11,
            "elements": [
                "astralsorcery:fluidblockliquidstarlight@1"
            ]
        },
        {
            "x": 7,
            "y": 0,
            "z": 11,
            "elements": [
                "contenttweaker:gama_tial_coil_block@0"
            ]
        },
        {
            "x": -1,
            "y": -8,
            "z": 13,
            "elements": [
                "contenttweaker:superglasswhite@0"
            ]
        },
        {
            "x": 2,
            "y": -7,
            "z": 12,
            "elements": [
                "contenttweaker:superglasswhite@0"
            ]
        },
        {
            "x": 2,
            "y": 1,
            "z": 21,
            "elements": [
                "contenttweaker:spacexmachineblock@0"
            ]
        },
        {
            "x": -11,
            "y": 0,
            "z": 1,
            "elements": [
                "contenttweaker:spacexmachineblock@0"
            ]
        },
        {
            "x": 6,
            "y": -2,
            "z": 11,
            "elements": [
                "contenttweaker:superglasswhite@0"
            ]
        },
        {
            "x": -1,
            "y": 0,
            "z": 21,
            "elements": [
                "contenttweaker:spacexmachineblock@0"
            ]
        },
        {
            "x": -3,
            "y": 2,
            "z": 13,
            "elements": [
                "chisel:futura@2"
            ]
        },
        {
            "x": 1,
            "y": 11,
            "z": 11,
            "elements": [
                "casings_all",
                "modularmachinery:blockmepatternprovider",
                "modularmachinery:blockmepatternmirrorimage"
            ]
        },
        {
            "x": 3,
            "y": 10,
            "z": 10,
            "elements": [
                "contenttweaker:spacexmachineblock@0"
            ]
        },
        {
            "x": 11,
            "y": -10,
            "z": 11,
            "elements": [
                "contenttweaker:spacexmachineblock@0"
            ]
        },
        {
            "x": -2,
            "y": 2,
            "z": 8,
            "elements": [
                "chisel:futura@2"
            ]
        },
        {
            "x": -1,
            "y": -4,
            "z": 13,
            "elements": [
                "contenttweaker:superglasswhite@0"
            ]
        },
        {
            "x": -2,
            "y": -1,
            "z": 14,
            "elements": [
                "contenttweaker:superglasswhite@0"
            ]
        },
        {
            "x": -10,
            "y": -2,
            "z": 13,
            "elements": [
                "contenttweaker:spacexmachineblock@0"
            ]
        },
        {
            "x": 1,
            "y": 10,
            "z": 11,
            "elements": [
                "contenttweaker:spacexmachineblock@0"
            ]
        },
        {
            "x": 1,
            "y": 0,
            "z": 8,
            "elements": [
                "astralsorcery:fluidblockliquidstarlight@0"
            ]
        },
        {
            "x": 0,
            "y": 2,
            "z": 9,
            "elements": [
                "astralsorcery:fluidblockliquidstarlight@1"
            ]
        },
        {
            "x": 1,
            "y": -3,
            "z": 14,
            "elements": [
                "chisel:futura@2"
            ]
        },
        {
            "x": 2,
            "y": 1,
            "z": 7,
            "elements": [
                "contenttweaker:superglasswhite@0"
            ]
        },
        {
            "x": -2,
            "y": -1,
            "z": 17,
            "elements": [
                "contenttweaker:superglasswhite@0"
            ]
        },
        {
            "x": 6,
            "y": -1,
            "z": 11,
            "elements": [
                "contenttweaker:gama_tial_coil_block@0"
            ]
        },
        {
            "x": 0,
            "y": 3,
            "z": 9,
            "elements": [
                "contenttweaker:superglasswhite@0"
            ]
        },
        {
            "x": 7,
            "y": 2,
            "z": 10,
            "elements": [
                "contenttweaker:superglasswhite@0"
            ]
        },
        {
            "x": -2,
            "y": -1,
            "z": 7,
            "elements": [
                "contenttweaker:superglasswhite@0"
            ]
        },
        {
            "x": 1,
            "y": -3,
            "z": 21,
            "elements": [
                "contenttweaker:spacexmachineblock@0"
            ]
        },
        {
            "x": 5,
            "y": -1,
            "z": 12,
            "elements": [
                "astralsorcery:fluidblockliquidstarlight@1"
            ]
        },
        {
            "x": -1,
            "y": 2,
            "z": 21,
            "elements": [
                "contenttweaker:spacexmachineblock@0"
            ]
        },
        {
            "x": 2,
            "y": 0,
            "z": 6,
            "elements": [
                "contenttweaker:superglasswhite@0"
            ]
        },
        {
            "x": 0,
            "y": 11,
            "z": 20,
            "elements": [
                "contenttweaker:spacexmachineblock@0"
            ]
        },
        {
            "x": 0,
            "y": 3,
            "z": 12,
            "elements": [
                "astralsorcery:fluidblockliquidstarlight@0"
            ]
        },
        {
            "x": -1,
            "y": 2,
            "z": 6,
            "elements": [
                "contenttweaker:superglasswhite@0"
            ]
        },
        {
            "x": 3,
            "y": 1,
            "z": 12,
            "elements": [
                "astralsorcery:fluidblockliquidstarlight@0"
            ]
        },
        {
            "x": 2,
            "y": -3,
            "z": 9,
            "elements": [
                "chisel:futura@2"
            ]
        },
        {
            "x": 6,
            "y": 0,
            "z": 9,
            "elements": [
                "contenttweaker:superglasswhite@0"
            ]
        },
        {
            "x": -1,
            "y": 3,
            "z": 21,
            "elements": [
                "contenttweaker:spacexmachineblock@0"
            ]
        },
        {
            "x": 1,
            "y": 8,
            "z": 11,
            "elements": [
                "contenttweaker:gama_tial_coil_block@0"
            ]
        },
        {
            "x": 5,
            "y": -1,
            "z": 9,
            "elements": [
                "contenttweaker:superglasswhite@0"
            ]
        },
        {
            "x": 11,
            "y": -11,
            "z": 11,
            "elements": [
                "contenttweaker:spacexmachineblock@0"
            ]
        },
        {
            "x": 0,
            "y": 4,
            "z": 9,
            "elements": [
                "contenttweaker:superglasswhite@0"
            ]
        },
        {
            "x": -1,
            "y": -2,
            "z": 9,
            "elements": [
                "astralsorcery:fluidblockliquidstarlight@0"
            ]
        },
        {
            "x": 3,
            "y": 2,
            "z": 13,
            "elements": [
                "chisel:futura@2"
            ]
        },
        {
            "x": 1,
            "y": 9,
            "z": 10,
            "elements": [
                "contenttweaker:stablestructure@0"
            ]
        },
        {
            "x": 6,
            "y": 1,
            "z": 10,
            "elements": [
                "astralsorcery:fluidblockliquidstarlight@0"
            ]
        },
        {
            "x": 1,
            "y": 10,
            "z": 10,
            "elements": [
                "contenttweaker:spacexmachineblock@0"
            ]
        },
        {
            "x": 1,
            "y": 0,
            "z": 1,
            "elements": [
                "contenttweaker:spacexmachineblock@0"
            ]
        },
        {
            "x": -1,
            "y": 0,
            "z": 8,
            "elements": [
                "astralsorcery:fluidblockliquidstarlight@1"
            ]
        },
        {
            "x": 8,
            "y": -2,
            "z": 10,
            "elements": [
                "contenttweaker:superglasswhite@0"
            ]
        },
        {
            "x": 11,
            "y": -6,
            "z": 11,
            "elements": [
                "contenttweaker:spacexmachineblock@0"
            ]
        },
        {
            "x": 0,
            "y": -11,
            "z": 19,
            "elements": [
                "contenttweaker:spacexmachineblock@0"
            ]
        },
        {
            "x": 0,
            "y": 0,
            "z": 13,
            "elements": [
                "astralsorcery:fluidblockliquidstarlight@0"
            ]
        },
        {
            "x": 8,
            "y": -1,
            "z": 11,
            "elements": [
                "contenttweaker:gama_tial_coil_block@0"
            ]
        },
        {
            "x": 6,
            "y": 0,
            "z": 10,
            "elements": [
                "contenttweaker:gama_tial_coil_block@0"
            ]
        },
        {
            "x": 2,
            "y": -3,
            "z": 12,
            "elements": [
                "contenttweaker:superglasswhite@0"
            ]
        },
        {
            "x": 11,
            "y": -7,
            "z": 11,
            "elements": [
                "contenttweaker:spacexmachineblock@0"
            ]
        },
        {
            "x": 0,
            "y": 0,
            "z": 9,
            "elements": [
                "astralsorcery:fluidblockliquidstarlight@1"
            ]
        },
        {
            "x": 7,
            "y": 1,
            "z": 10,
            "elements": [
                "astralsorcery:fluidblockliquidstarlight@0"
            ]
        },
        {
            "x": -1,
            "y": 1,
            "z": 2,
            "elements": [
                "contenttweaker:stablestructure@0"
            ]
        },
        {
            "x": -9,
            "y": 1,
            "z": 9,
            "elements": [
                "contenttweaker:stablestructure@0"
            ]
        },
        {
            "x": -1,
            "y": -1,
            "z": 2,
            "elements": [
                "contenttweaker:stablestructure@0"
            ]
        },
        {
            "x": 11,
            "y": -8,
            "z": 11,
            "elements": [
                "contenttweaker:spacexmachineblock@0"
            ]
        },
        {
            "x": -1,
            "y": -10,
            "z": 8,
            "elements": [
                "contenttweaker:spacexmachineblock@0"
            ]
        },
        {
            "x": 7,
            "y": 11,
            "z": 11,
            "elements": [
                "contenttweaker:spacexmachineblock@0"
            ]
        },
        {
            "x": -1,
            "y": 10,
            "z": 13,
            "elements": [
                "contenttweaker:spacexmachineblock@0"
            ]
        },
        {
            "x": -1,
            "y": -1,
            "z": 9,
            "elements": [
                "astralsorcery:fluidblockliquidstarlight@1"
            ]
        },
        {
            "x": 0,
            "y": 7,
            "z": 12,
            "elements": [
                "contenttweaker:gama_tial_coil_block@0"
            ]
        },
        {
            "x": -1,
            "y": -2,
            "z": 16,
            "elements": [
                "contenttweaker:superglasswhite@0"
            ]
        },
        {
            "x": 2,
            "y": 0,
            "z": 13,
            "elements": [
                "astralsorcery:fluidblockliquidstarlight@1"
            ]
        },
        {
            "x": -1,
            "y": -9,
            "z": 9,
            "elements": [
                "contenttweaker:stablestructure@0"
            ]
        },
        {
            "x": -1,
            "y": 6,
            "z": 13,
            "elements": [
                "contenttweaker:superglasswhite@0"
            ]
        },
        {
            "x": 0,
            "y": 4,
            "z": 13,
            "elements": [
                "contenttweaker:superglasswhite@0"
            ]
        },
        {
            "x": -3,
            "y": 0,
            "z": 8,
            "elements": [
                "chisel:futura@2"
            ]
        },
        {
            "x": 11,
            "y": -3,
            "z": 11,
            "elements": [
                "contenttweaker:spacexmachineblock@0"
            ]
        },
        {
            "x": -1,
            "y": -1,
            "z": 16,
            "elements": [
                "astralsorcery:fluidblockliquidstarlight@1"
            ]
        },
        {
            "x": -10,
            "y": -3,
            "z": 12,
            "elements": [
                "contenttweaker:spacexmachineblock@0"
            ]
        },
        {
            "x": 10,
            "y": 1,
            "z": 11,
            "elements": [
                "contenttweaker:spacexmachineblock@0"
            ]
        },
        {
            "x": -1,
            "y": -8,
            "z": 9,
            "elements": [
                "contenttweaker:superglasswhite@0"
            ]
        },
        {
            "x": 2,
            "y": -2,
            "z": 13,
            "elements": [
                "astralsorcery:fluidblockliquidstarlight@0"
            ]
        },
        {
            "x": -6,
            "y": 0,
            "z": 9,
            "elements": [
                "contenttweaker:superglasswhite@0"
            ]
        },
        {
            "x": 11,
            "y": -2,
            "z": 11,
            "elements": [
                "contenttweaker:spacexmachineblock@0"
            ]
        },
        {
            "x": 2,
            "y": 0,
            "z": 20,
            "elements": [
                "contenttweaker:stablestructure@0"
            ]
        },
        {
            "x": -1,
            "y": -4,
            "z": 9,
            "elements": [
                "contenttweaker:superglasswhite@0"
            ]
        },
        {
            "x": 0,
            "y": 0,
            "z": 16,
            "elements": [
                "contenttweaker:gama_tial_coil_block@0"
            ]
        },
        {
            "x": 1,
            "y": 1,
            "z": 2,
            "elements": [
                "contenttweaker:stablestructure@0"
            ]
        },
        {
            "x": 1,
            "y": -1,
            "z": 2,
            "elements": [
                "contenttweaker:stablestructure@0"
            ]
        },
        {
            "x": 5,
            "y": -1,
            "z": 10,
            "elements": [
                "astralsorcery:fluidblockliquidstarlight@0"
            ]
        },
        {
            "x": -7,
            "y": -1,
            "z": 9,
            "elements": [
                "contenttweaker:superglasswhite@0"
            ]
        },
        {
            "x": -1,
            "y": -10,
            "z": 9,
            "elements": [
                "contenttweaker:spacexmachineblock@0"
            ]
        },
        {
            "x": 11,
            "y": 0,
            "z": 14,
            "elements": [
                "contenttweaker:spacexmachineblock@0"
            ]
        },
        {
            "x": -8,
            "y": 0,
            "z": 0,
            "elements": [
                "contenttweaker:spacexmachineblock@0"
            ]
        },
        {
            "x": 1,
            "y": -10,
            "z": 8,
            "elements": [
                "contenttweaker:spacexmachineblock@0"
            ]
        },
        {
            "x": 11,
            "y": -4,
            "z": 11,
            "elements": [
                "contenttweaker:spacexmachineblock@0"
            ]
        },
        {
            "x": -3,
            "y": 0,
            "z": 1,
            "elements": [
                "contenttweaker:spacexmachineblock@0"
            ]
        },
        {
            "x": -1,
            "y": 2,
            "z": 13,
            "elements": [
                "astralsorcery:fluidblockliquidstarlight@0"
            ]
        },
        {
            "x": 0,
            "y": 2,
            "z": 1,
            "elements": [
                "contenttweaker:spacexmachineblock@0"
            ]
        },
        {
            "x": 1,
            "y": -4,
            "z": 13,
            "elements": [
                "contenttweaker:superglasswhite@0"
            ]
        },
        {
            "x": -1,
            "y": 1,
            "z": 20,
            "elements": [
                "contenttweaker:stablestructure@0"
            ]
        },
        {
            "x": -4,
            "y": 0,
            "z": 13,
            "elements": [
                "contenttweaker:superglasswhite@0"
            ]
        },
        {
            "x": -9,
            "y": -1,
            "z": 12,
            "elements": [
                "contenttweaker:stablestructure@0"
            ]
        },
        {
            "x": 0,
            "y": 2,
            "z": 15,
            "elements": [
                "contenttweaker:superglasswhite@0"
            ]
        },
        {
            "x": 0,
            "y": -3,
            "z": 12,
            "elements": [
                "astralsorcery:fluidblockliquidstarlight@1"
            ]
        },
        {
            "x": -1,
            "y": -2,
            "z": 15,
            "elements": [
                "contenttweaker:superglasswhite@0"
            ]
        },
        {
            "x": 0,
            "y": -1,
            "z": 7,
            "elements": [
                "astralsorcery:fluidblockliquidstarlight@0"
            ]
        },
        {
            "x": -1,
            "y": 2,
            "z": 20,
            "elements": [
                "contenttweaker:stablestructure@0"
            ]
        },
        {
            "x": 0,
            "y": 0,
            "z": 6,
            "elements": [
                "contenttweaker:gama_tial_coil_block@0"
            ]
        },
        {
            "x": 0,
            "y": 3,
            "z": 22,
            "elements": [
                "contenttweaker:spacexmachineblock@0"
            ]
        },
        {
            "x": -2,
            "y": 3,
            "z": 12,
            "elements": [
                "contenttweaker:superglasswhite@0"
            ]
        },
        {
            "x": 0,
            "y": -11,
            "z": 2,
            "elements": [
                "contenttweaker:spacexmachineblock@0"
            ]
        },
        {
            "x": -1,
            "y": -1,
            "z": 15,
            "elements": [
                "astralsorcery:fluidblockliquidstarlight@1"
            ]
        },
        {
            "x": 0,
            "y": 2,
            "z": 22,
            "elements": [
                "contenttweaker:spacexmachineblock@0"
            ]
        },
        {
            "x": 9,
            "y": 0,
            "z": 22,
            "elements": [
                "contenttweaker:spacexmachineblock@0"
            ]
        },
        {
            "x": -1,
            "y": 0,
            "z": 1,
            "elements": [
                "contenttweaker:spacexmachineblock@0"
            ]
        },
        {
            "x": -10,
            "y": -2,
            "z": 10,
            "elements": [
                "contenttweaker:spacexmachineblock@0"
            ]
        },
        {
            "x": 0,
            "y": 5,
            "z": 22,
            "elements": [
                "contenttweaker:spacexmachineblock@0"
            ]
        },
        {
            "x": -1,
            "y": -2,
            "z": 1,
            "elements": [
                "contenttweaker:spacexmachineblock@0"
            ]
        },
        {
            "x": 3,
            "y": 0,
            "z": 22,
            "elements": [
                "contenttweaker:spacexmachineblock@0"
            ]
        },
        {
            "x": -2,
            "y": 2,
            "z": 1,
            "elements": [
                "contenttweaker:spacexmachineblock@0"
            ]
        },
        {
            "x": -10,
            "y": -1,
            "z": 14,
            "elements": [
                "contenttweaker:spacexmachineblock@0"
            ]
        },
        {
            "x": -10,
            "y": 0,
            "z": 13,
            "elements": [
                "contenttweaker:spacexmachineblock@0"
            ]
        },
        {
            "x": -2,
            "y": -2,
            "z": 13,
            "elements": [
                "astralsorcery:fluidblockliquidstarlight@0"
            ]
        },
        {
            "x": -3,
            "y": -1,
            "z": 12,
            "elements": [
                "astralsorcery:fluidblockliquidstarlight@0"
            ]
        },
        {
            "x": 0,
            "y": 7,
            "z": 22,
            "elements": [
                "contenttweaker:spacexmachineblock@0"
            ]
        },
        {
            "x": -5,
            "y": 1,
            "z": 12,
            "elements": [
                "astralsorcery:fluidblockliquidstarlight@0"
            ]
        },
        {
            "x": 0,
            "y": 1,
            "z": 15,
            "elements": [
                "astralsorcery:fluidblockliquidstarlight@0"
            ]
        },
        {
            "x": 1,
            "y": -8,
            "z": 13,
            "elements": [
                "contenttweaker:superglasswhite@0"
            ]
        },
        {
            "x": 0,
            "y": -7,
            "z": 12,
            "elements": [
                "contenttweaker:infinite_coil@0"
            ]
        },
        {
            "x": 0,
            "y": 6,
            "z": 22,
            "elements": [
                "contenttweaker:spacexmachineblock@0"
            ]
        },
        {
            "x": 1,
            "y": 0,
            "z": 18,
            "elements": [
                "contenttweaker:gama_tial_coil_block@0"
            ]
        },
        {
            "x": 0,
            "y": 1,
            "z": 22,
            "elements": [
                "casings_all",
                "modularmachinery:blockmepatternprovider",
                "modularmachinery:blockmepatternmirrorimage"
            ]
        },
        {
            "x": -11,
            "y": 0,
            "z": 5,
            "elements": [
                "contenttweaker:spacexmachineblock@0"
            ]
        },
        {
            "x": -2,
            "y": -1,
            "z": 20,
            "elements": [
                "contenttweaker:stablestructure@0"
            ]
        },
        {
            "x": 1,
            "y": -2,
            "z": 1,
            "elements": [
                "contenttweaker:spacexmachineblock@0"
            ]
        },
        {
            "x": 1,
            "y": 0,
            "z": 5,
            "elements": [
                "contenttweaker:gama_tial_coil_block@0"
            ]
        },
        {
            "x": -1,
            "y": -3,
            "z": 14,
            "elements": [
                "chisel:futura@2"
            ]
        },
        {
            "x": 0,
            "y": 11,
            "z": 15,
            "elements": [
                "contenttweaker:spacexmachineblock@0"
            ]
        },
        {
            "x": 1,
            "y": -2,
            "z": 8,
            "elements": [
                "contenttweaker:superglasswhite@0"
            ]
        },
        {
            "x": -10,
            "y": 1,
            "z": 14,
            "elements": [
                "contenttweaker:spacexmachineblock@0"
            ]
        },
        {
            "x": -8,
            "y": 0,
            "z": 13,
            "elements": [
                "contenttweaker:superglasswhite@0"
            ]
        },
        {
            "x": 0,
            "y": -1,
            "z": 17,
            "elements": [
                "contenttweaker:gama_tial_coil_block@0"
            ]
        },
        {
            "x": 1,
            "y": 1,
            "z": 5,
            "elements": [
                "astralsorcery:fluidblockliquidstarlight@0"
            ]
        },
        {
            "x": 0,
            "y": 9,
            "z": 22,
            "elements": [
                "contenttweaker:spacexmachineblock@0"
            ]
        },
        {
            "x": -5,
            "y": -1,
            "z": 12,
            "elements": [
                "astralsorcery:fluidblockliquidstarlight@1"
            ]
        },
        {
            "x": -2,
            "y": -10,
            "z": 13,
            "elements": [
                "contenttweaker:spacexmachineblock@0"
            ]
        },
        {
            "x": -7,
            "y": 1,
            "z": 12,
            "elements": [
                "astralsorcery:fluidblockliquidstarlight@0"
            ]
        },
        {
            "x": -2,
            "y": 1,
            "z": 7,
            "elements": [
                "contenttweaker:superglasswhite@0"
            ]
        },
        {
            "x": 0,
            "y": 10,
            "z": 22,
            "elements": [
                "contenttweaker:spacexmachineblock@0"
            ]
        },
        {
            "x": -2,
            "y": -7,
            "z": 12,
            "elements": [
                "contenttweaker:superglasswhite@0"
            ]
        },
        {
            "x": -2,
            "y": -1,
            "z": 21,
            "elements": [
                "contenttweaker:spacexmachineblock@0"
            ]
        },
        {
            "x": 0,
            "y": -6,
            "z": 13,
            "elements": [
                "contenttweaker:superglasswhite@0"
            ]
        },
        {
            "x": -11,
            "y": 0,
            "z": 4,
            "elements": [
                "contenttweaker:spacexmachineblock@0"
            ]
        },
        {
            "x": 0,
            "y": 11,
            "z": 22,
            "elements": [
                "contenttweaker:spacexmachineblock@0"
            ]
        },
        {
            "x": 0,
            "y": -11,
            "z": 12,
            "elements": [
                "casings_all",
                "modularmachinery:blockmepatternprovider",
                "modularmachinery:blockmepatternmirrorimage"
            ]
        },
        {
            "x": 5,
            "y": 0,
            "z": 22,
            "elements": [
                "contenttweaker:spacexmachineblock@0"
            ]
        },
        {
            "x": 0,
            "y": -1,
            "z": 5,
            "elements": [
                "contenttweaker:gama_tial_coil_block@0"
            ]
        },
        {
            "x": 0,
            "y": 11,
            "z": 16,
            "elements": [
                "contenttweaker:spacexmachineblock@0"
            ]
        },
        {
            "x": -2,
            "y": -2,
            "z": 21,
            "elements": [
                "contenttweaker:spacexmachineblock@0"
            ]
        },
        {
            "x": -7,
            "y": -11,
            "z": 11,
            "elements": [
                "contenttweaker:spacexmachineblock@0"
            ]
        },
        {
            "x": -2,
            "y": 1,
            "z": 17,
            "elements": [
                "contenttweaker:superglasswhite@0"
            ]
        },
        {
            "x": 0,
            "y": 11,
            "z": 2,
            "elements": [
                "contenttweaker:spacexmachineblock@0"
            ]
        },
        {
            "x": -2,
            "y": 9,
            "z": 11,
            "elements": [
                "contenttweaker:stablestructure@0"
            ]
        },
        {
            "x": 3,
            "y": 0,
            "z": 1,
            "elements": [
                "contenttweaker:spacexmachineblock@0"
            ]
        },
        {
            "x": 0,
            "y": 11,
            "z": 9,
            "elements": [
                "contenttweaker:spacexmachineblock@0"
            ]
        },
        {
            "x": 2,
            "y": 2,
            "z": 1,
            "elements": [
                "contenttweaker:spacexmachineblock@0"
            ]
        },
        {
            "x": -2,
            "y": -3,
            "z": 12,
            "elements": [
                "contenttweaker:superglasswhite@0"
            ]
        },
        {
            "x": -1,
            "y": -5,
            "z": 12,
            "elements": [
                "astralsorcery:fluidblockliquidstarlight@1"
            ]
        },
        {
            "x": -6,
            "y": 0,
            "z": 13,
            "elements": [
                "contenttweaker:superglasswhite@0"
            ]
        },
        {
            "x": 0,
            "y": 1,
            "z": 14,
            "elements": [
                "astralsorcery:fluidblockliquidstarlight@1"
            ]
        },
        {
            "x": 2,
            "y": 2,
            "z": 8,
            "elements": [
                "chisel:futura@2"
            ]
        },
        {
            "x": -7,
            "y": -1,
            "z": 12,
            "elements": [
                "astralsorcery:fluidblockliquidstarlight@2"
            ]
        },
        {
            "x": 0,
            "y": 10,
            "z": 9,
            "elements": [
                "contenttweaker:spacexmachineblock@0"
            ]
        },
        {
            "x": -11,
            "y": 0,
            "z": 18,
            "elements": [
                "contenttweaker:spacexmachineblock@0"
            ]
        },
        {
            "x": 0,
            "y": -10,
            "z": 13,
            "elements": [
                "contenttweaker:spacexmachineblock@0"
            ]
        },
        {
            "x": -9,
            "y": 1,
            "z": 12,
            "elements": [
                "contenttweaker:stablestructure@0"
            ]
        },
        {
            "x": 0,
            "y": 1,
            "z": 7,
            "elements": [
                "astralsorcery:fluidblockliquidstarlight@1"
            ]
        },
        {
            "x": -2,
            "y": 0,
            "z": 6,
            "elements": [
                "contenttweaker:superglasswhite@0"
            ]
        },
        {
            "x": 9,
            "y": 1,
            "z": 9,
            "elements": [
                "contenttweaker:stablestructure@0"
            ]
        },
        {
            "x": -1,
            "y": -9,
            "z": 12,
            "elements": [
                "contenttweaker:stablestructure@0"
            ]
        },
        {
            "x": 4,
            "y": 0,
            "z": 13,
            "elements": [
                "contenttweaker:superglasswhite@0"
            ]
        },
        {
            "x": 1,
            "y": 9,
            "z": 12,
            "elements": [
                "contenttweaker:stablestructure@0"
            ]
        },
        {
            "x": -11,
            "y": 0,
            "z": 9,
            "elements": [
                "contenttweaker:spacexmachineblock@0"
            ]
        },
        {
            "x": -6,
            "y": 1,
            "z": 10,
            "elements": [
                "astralsorcery:fluidblockliquidstarlight@1"
            ]
        },
        {
            "x": 1,
            "y": 0,
            "z": 14,
            "elements": [
                "astralsorcery:fluidblockliquidstarlight@0"
            ]
        },
        {
            "x": -2,
            "y": 4,
            "z": 11,
            "elements": [
                "contenttweaker:superglasswhite@0"
            ]
        },
        {
            "x": 3,
            "y": -1,
            "z": 13,
            "elements": [
                "contenttweaker:superglasswhite@0"
            ]
        },
        {
            "x": 3,
            "y": -2,
            "z": 9,
            "elements": [
                "chisel:futura@2"
            ]
        },
        {
            "x": -2,
            "y": 3,
            "z": 13,
            "elements": [
                "chisel:futura@2"
            ]
        },
        {
            "x": 0,
            "y": -1,
            "z": 0,
            "elements": [
                "casings_all",
                "modularmachinery:blockmepatternprovider",
                "modularmachinery:blockmepatternmirrorimage"
            ]
        },
        {
            "x": -2,
            "y": -5,
            "z": 10,
            "elements": [
                "contenttweaker:superglasswhite@0"
            ]
        },
        {
            "x": 0,
            "y": -1,
            "z": 14,
            "elements": [
                "astralsorcery:fluidblockliquidstarlight@1"
            ]
        },
        {
            "x": 8,
            "y": 0,
            "z": 22,
            "elements": [
                "contenttweaker:spacexmachineblock@0"
            ]
        },
        {
            "x": 0,
            "y": 11,
            "z": 3,
            "elements": [
                "contenttweaker:spacexmachineblock@0"
            ]
        },
        {
            "x": 1,
            "y": 5,
            "z": 13,
            "elements": [
                "contenttweaker:superglasswhite@0"
            ]
        },
        {
            "x": 7,
            "y": 1,
            "z": 13,
            "elements": [
                "contenttweaker:superglasswhite@0"
            ]
        },
        {
            "x": -4,
            "y": -1,
            "z": 10,
            "elements": [
                "astralsorcery:fluidblockliquidstarlight@0"
            ]
        },
        {
            "x": -2,
            "y": 10,
            "z": 13,
            "elements": [
                "contenttweaker:spacexmachineblock@0"
            ]
        },
        {
            "x": 0,
            "y": 11,
            "z": 18,
            "elements": [
                "contenttweaker:spacexmachineblock@0"
            ]
        },
        {
            "x": 2,
            "y": -10,
            "z": 11,
            "elements": [
                "contenttweaker:spacexmachineblock@0"
            ]
        },
        {
            "x": -1,
            "y": -8,
            "z": 11,
            "elements": [
                "contenttweaker:infinite_coil@0"
            ]
        },
        {
            "x": 0,
            "y": -9,
            "z": 10,
            "elements": [
                "contenttweaker:stablestructure@0"
            ]
        },
        {
            "x": -2,
            "y": 10,
            "z": 9,
            "elements": [
                "contenttweaker:spacexmachineblock@0"
            ]
        },
        {
            "x": -10,
            "y": -2,
            "z": 11,
            "elements": [
                "contenttweaker:spacexmachineblock@0"
            ]
        },
        {
            "x": 1,
            "y": 10,
            "z": 12,
            "elements": [
                "contenttweaker:spacexmachineblock@0"
            ]
        },
        {
            "x": -2,
            "y": 1,
            "z": 5,
            "elements": [
                "contenttweaker:superglasswhite@0"
            ]
        },
        {
            "x": 1,
            "y": 1,
            "z": 14,
            "elements": [
                "astralsorcery:fluidblockliquidstarlight@0"
            ]
        },
        {
            "x": -4,
            "y": 1,
            "z": 10,
            "elements": [
                "astralsorcery:fluidblockliquidstarlight@1"
            ]
        },
        {
            "x": -2,
            "y": -1,
            "z": 10,
            "elements": [
                "astralsorcery:fluidblockliquidstarlight@1"
            ]
        },
        {
            "x": -3,
            "y": -1,
            "z": 13,
            "elements": [
                "contenttweaker:superglasswhite@0"
            ]
        },
        {
            "x": 1,
            "y": 0,
            "z": 6,
            "elements": [
                "astralsorcery:fluidblockliquidstarlight@0"
            ]
        },
        {
            "x": -3,
            "y": 2,
            "z": 11,
            "elements": [
                "contenttweaker:superglasswhite@0"
            ]
        },
        {
            "x": -1,
            "y": -7,
            "z": 10,
            "elements": [
                "astralsorcery:fluidblockliquidstarlight@1"
            ]
        },
        {
            "x": -2,
            "y": 0,
            "z": 13,
            "elements": [
                "astralsorcery:fluidblockliquidstarlight@1"
            ]
        },
        {
            "x": 1,
            "y": 3,
            "z": 14,
            "elements": [
                "chisel:futura@2"
            ]
        },
        {
            "x": 0,
            "y": -11,
            "z": 3,
            "elements": [
                "contenttweaker:spacexmachineblock@0"
            ]
        },
        {
            "x": -2,
            "y": 2,
            "z": 13,
            "elements": [
                "astralsorcery:fluidblockliquidstarlight@0"
            ]
        },
        {
            "x": 2,
            "y": -9,
            "z": 10,
            "elements": [
                "contenttweaker:stablestructure@0"
            ]
        },
        {
            "x": 2,
            "y": -6,
            "z": 11,
            "elements": [
                "contenttweaker:superglasswhite@0"
            ]
        },
        {
            "x": 1,
            "y": 9,
            "z": 13,
            "elements": [
                "contenttweaker:stablestructure@0"
            ]
        },
        {
            "x": -1,
            "y": -4,
            "z": 11,
            "elements": [
                "astralsorcery:fluidblockliquidstarlight@1"
            ]
        },
        {
            "x": -9,
            "y": 2,
            "z": 11,
            "elements": [
                "contenttweaker:stablestructure@0"
            ]
        },
        {
            "x": 0,
            "y": -2,
            "z": 6,
            "elements": [
                "contenttweaker:superglasswhite@0"
            ]
        },
        {
            "x": -2,
            "y": 0,
            "z": 11,
            "elements": [
                "astralsorcery:fluidblockliquidstarlight@0"
            ]
        },
        {
            "x": 0,
            "y": -1,
            "z": 6,
            "elements": [
                "astralsorcery:fluidblockliquidstarlight@0"
            ]
        },
        {
            "x": 0,
            "y": -2,
            "z": 11,
            "elements": [
                "astralsorcery:fluidblockliquidstarlight@1"
            ]
        },
        {
            "x": 0,
            "y": 1,
            "z": 5,
            "elements": [
                "contenttweaker:gama_tial_coil_block@0"
            ]
        },
        {
            "x": 0,
            "y": -3,
            "z": 13,
            "elements": [
                "contenttweaker:superglasswhite@0"
            ]
        },
        {
            "x": -11,
            "y": 6,
            "z": 11,
            "elements": [
                "contenttweaker:spacexmachineblock@0"
            ]
        },
        {
            "x": -2,
            "y": 2,
            "z": 14,
            "elements": [
                "chisel:futura@2"
            ]
        },
        {
            "x": 0,
            "y": -9,
            "z": 0,
            "elements": [
                "contenttweaker:spacexmachineblock@0"
            ]
        },
        {
            "x": 1,
            "y": 0,
            "z": 9,
            "elements": [
                "astralsorcery:fluidblockliquidstarlight@1"
            ]
        },
        {
            "x": 1,
            "y": 3,
            "z": 12,
            "elements": [
                "astralsorcery:fluidblockliquidstarlight@0"
            ]
        },
        {
            "x": -2,
            "y": 8,
            "z": 12,
            "elements": [
                "contenttweaker:superglasswhite@0"
            ]
        },
        {
            "x": -2,
            "y": 2,
            "z": 9,
            "elements": [
                "astralsorcery:fluidblockliquidstarlight@0"
            ]
        },
        {
            "x": 1,
            "y": -7,
            "z": 10,
            "elements": [
                "astralsorcery:fluidblockliquidstarlight@1"
            ]
        },
        {
            "x": 1,
            "y": 2,
            "z": 6,
            "elements": [
                "contenttweaker:superglasswhite@0"
            ]
        },
        {
            "x": 0,
            "y": 2,
            "z": 4,
            "elements": [
                "contenttweaker:superglasswhite@0"
            ]
        },
        {
            "x": -1,
            "y": -3,
            "z": 10,
            "elements": [
                "astralsorcery:fluidblockliquidstarlight@1"
            ]
        },
        {
            "x": -10,
            "y": 1,
            "z": 10,
            "elements": [
                "contenttweaker:spacexmachineblock@0"
            ]
        },
        {
            "x": -11,
            "y": 0,
            "z": 14,
            "elements": [
                "contenttweaker:spacexmachineblock@0"
            ]
        },
        {
            "x": 2,
            "y": -5,
            "z": 10,
            "elements": [
                "contenttweaker:superglasswhite@0"
            ]
        },
        {
            "x": -8,
            "y": -1,
            "z": 10,
            "elements": [
                "contenttweaker:gama_tial_coil_block@0"
            ]
        },
        {
            "x": 1,
            "y": 2,
            "z": 12,
            "elements": [
                "astralsorcery:fluidblockliquidstarlight@1"
            ]
        },
        {
            "x": 1,
            "y": 2,
            "z": 16,
            "elements": [
                "contenttweaker:superglasswhite@0"
            ]
        },
        {
            "x": -2,
            "y": -10,
            "z": 11,
            "elements": [
                "contenttweaker:spacexmachineblock@0"
            ]
        },
        {
            "x": 1,
            "y": 1,
            "z": 12,
            "elements": [
                "astralsorcery:fluidblockliquidstarlight@1"
            ]
        },
        {
            "x": 2,
            "y": 0,
            "z": 16,
            "elements": [
                "contenttweaker:superglasswhite@0"
            ]
        },
        {
            "x": 0,
            "y": -6,
            "z": 11,
            "elements": [
                "contenttweaker:infinite_coil@0"
            ]
        },
        {
            "x": -6,
            "y": -2,
            "z": 11,
            "elements": [
                "contenttweaker:superglasswhite@0"
            ]
        },
        {
            "x": 0,
            "y": 2,
            "z": 18,
            "elements": [
                "contenttweaker:superglasswhite@0"
            ]
        },
        {
            "x": -8,
            "y": 0,
            "z": 11,
            "elements": [
                "contenttweaker:gama_tial_coil_block@0"
            ]
        },
        {
            "x": 2,
            "y": 1,
            "z": 5,
            "elements": [
                "contenttweaker:superglasswhite@0"
            ]
        },
        {
            "x": -11,
            "y": 10,
            "z": 11,
            "elements": [
                "contenttweaker:spacexmachineblock@0"
            ]
        },
        {
            "x": 2,
            "y": -1,
            "z": 10,
            "elements": [
                "astralsorcery:fluidblockliquidstarlight@1"
            ]
        },
        {
            "x": 1,
            "y": 6,
            "z": 12,
            "elements": [
                "astralsorcery:fluidblockliquidstarlight@0"
            ]
        },
        {
            "x": 0,
            "y": 1,
            "z": 10,
            "elements": [
                "astralsorcery:fluidblockliquidstarlight@1"
            ]
        },
        {
            "x": -3,
            "y": 3,
            "z": 10,
            "elements": [
                "chisel:futura@2"
            ]
        },
        {
            "x": -11,
            "y": 0,
            "z": 6,
            "elements": [
                "contenttweaker:spacexmachineblock@0"
            ]
        },
        {
            "x": 1,
            "y": 1,
            "z": 13,
            "elements": [
                "astralsorcery:fluidblockliquidstarlight@1"
            ]
        },
        {
            "x": 11,
            "y": 0,
            "z": 1,
            "elements": [
                "contenttweaker:spacexmachineblock@0"
            ]
        },
        {
            "x": 7,
            "y": 0,
            "z": 9,
            "elements": [
                "contenttweaker:superglasswhite@0"
            ]
        },
        {
            "x": 4,
            "y": 0,
            "z": 12,
            "elements": [
                "astralsorcery:fluidblockliquidstarlight@0"
            ]
        },
        {
            "x": 0,
            "y": -5,
            "z": 0,
            "elements": [
                "contenttweaker:spacexmachineblock@0"
            ]
        },
        {
            "x": 1,
            "y": 4,
            "z": 9,
            "elements": [
                "contenttweaker:superglasswhite@0"
            ]
        },
        {
            "x": -2,
            "y": 4,
            "z": 12,
            "elements": [
                "contenttweaker:superglasswhite@0"
            ]
        },
        {
            "x": 1,
            "y": 7,
            "z": 12,
            "elements": [
                "astralsorcery:fluidblockliquidstarlight@0"
            ]
        },
        {
            "x": 0,
            "y": -2,
            "z": 16,
            "elements": [
                "contenttweaker:superglasswhite@0"
            ]
        },
        {
            "x": -1,
            "y": 2,
            "z": 16,
            "elements": [
                "contenttweaker:superglasswhite@0"
            ]
        },
        {
            "x": 0,
            "y": -10,
            "z": 11,
            "elements": [
                "contenttweaker:spacexmachineblock@0"
            ]
        },
        {
            "x": 0,
            "y": -3,
            "z": 14,
            "elements": [
                "chisel:futura@2"
            ]
        },
        {
            "x": -2,
            "y": -6,
            "z": 11,
            "elements": [
                "contenttweaker:superglasswhite@0"
            ]
        },
        {
            "x": -2,
            "y": -9,
            "z": 10,
            "elements": [
                "contenttweaker:stablestructure@0"
            ]
        },
        {
            "x": 1,
            "y": 8,
            "z": 9,
            "elements": [
                "contenttweaker:superglasswhite@0"
            ]
        },
        {
            "x": -5,
            "y": 2,
            "z": 11,
            "elements": [
                "contenttweaker:superglasswhite@0"
            ]
        },
        {
            "x": -2,
            "y": -1,
            "z": 5,
            "elements": [
                "contenttweaker:superglasswhite@0"
            ]
        },
        {
            "x": -4,
            "y": -2,
            "z": 11,
            "elements": [
                "contenttweaker:superglasswhite@0"
            ]
        },
        {
            "x": 1,
            "y": 5,
            "z": 12,
            "elements": [
                "astralsorcery:fluidblockliquidstarlight@1"
            ]
        },
        {
            "x": -6,
            "y": 0,
            "z": 11,
            "elements": [
                "contenttweaker:gama_tial_coil_block@0"
            ]
        },
        {
            "x": 3,
            "y": -2,
            "z": 13,
            "elements": [
                "chisel:futura@2"
            ]
        },
        {
            "x": 1,
            "y": 1,
            "z": 3,
            "elements": [
                "contenttweaker:gama_tial_coil_block@0"
            ]
        },
        {
            "x": 3,
            "y": -3,
            "z": 10,
            "elements": [
                "chisel:futura@2"
            ]
        },
        {
            "x": 2,
            "y": 1,
            "z": 2,
            "elements": [
                "contenttweaker:stablestructure@0"
            ]
        },
        {
            "x": 6,
            "y": -1,
            "z": 12,
            "elements": [
                "astralsorcery:fluidblockliquidstarlight@0"
            ]
        },
        {
            "x": -3,
            "y": 0,
            "z": 9,
            "elements": [
                "contenttweaker:superglasswhite@0"
            ]
        },
        {
            "x": 3,
            "y": 10,
            "z": 11,
            "elements": [
                "contenttweaker:spacexmachineblock@0"
            ]
        },
        {
            "x": 6,
            "y": -2,
            "z": 12,
            "elements": [
                "contenttweaker:superglasswhite@0"
            ]
        },
        {
            "x": -1,
            "y": 0,
            "z": 4,
            "elements": [
                "contenttweaker:gama_tial_coil_block@0"
            ]
        },
        {
            "x": 6,
            "y": 11,
            "z": 11,
            "elements": [
                "contenttweaker:spacexmachineblock@0"
            ]
        },
        {
            "x": 0,
            "y": 8,
            "z": 11,
            "elements": [
                "contenttweaker:gama_tial_coil_block@0"
            ]
        },
        {
            "x": 2,
            "y": 0,
            "z": 2,
            "elements": [
                "contenttweaker:stablestructure@0"
            ]
        },
        {
            "x": 2,
            "y": -2,
            "z": 21,
            "elements": [
                "contenttweaker:spacexmachineblock@0"
            ]
        },
        {
            "x": -2,
            "y": 0,
            "z": 16,
            "elements": [
                "contenttweaker:superglasswhite@0"
            ]
        },
        {
            "x": 1,
            "y": -2,
            "z": 4,
            "elements": [
                "contenttweaker:superglasswhite@0"
            ]
        },
        {
            "x": -2,
            "y": 9,
            "z": 10,
            "elements": [
                "contenttweaker:stablestructure@0"
            ]
        },
        {
            "x": 0,
            "y": 5,
            "z": 10,
            "elements": [
                "astralsorcery:fluidblockliquidstarlight@0"
            ]
        },
        {
            "x": 1,
            "y": -10,
            "z": 9,
            "elements": [
                "contenttweaker:spacexmachineblock@0"
            ]
        },
        {
            "x": 0,
            "y": -8,
            "z": 9,
            "elements": [
                "contenttweaker:superglasswhite@0"
            ]
        },
        {
            "x": -1,
            "y": -6,
            "z": 9,
            "elements": [
                "contenttweaker:superglasswhite@0"
            ]
        },
        {
            "x": -5,
            "y": 0,
            "z": 9,
            "elements": [
                "contenttweaker:superglasswhite@0"
            ]
        },
        {
            "x": -3,
            "y": -2,
            "z": 9,
            "elements": [
                "chisel:futura@2"
            ]
        },
        {
            "x": 0,
            "y": -4,
            "z": 9,
            "elements": [
                "contenttweaker:superglasswhite@0"
            ]
        },
        {
            "x": 1,
            "y": 3,
            "z": 10,
            "elements": [
                "astralsorcery:fluidblockliquidstarlight@0"
            ]
        },
        {
            "x": 6,
            "y": -1,
            "z": 10,
            "elements": [
                "astralsorcery:fluidblockliquidstarlight@0"
            ]
        },
        {
            "x": 4,
            "y": 1,
            "z": 10,
            "elements": [
                "astralsorcery:fluidblockliquidstarlight@0"
            ]
        },
        {
            "x": 6,
            "y": 0,
            "z": 11,
            "elements": [
                "contenttweaker:gama_tial_coil_block@0"
            ]
        },
        {
            "x": 0,
            "y": 0,
            "z": 18,
            "elements": [
                "contenttweaker:gama_tial_coil_block@0"
            ]
        },
        {
            "x": 1,
            "y": 7,
            "z": 10,
            "elements": [
                "astralsorcery:fluidblockliquidstarlight@0"
            ]
        },
        {
            "x": -1,
            "y": -2,
            "z": 4,
            "elements": [
                "contenttweaker:superglasswhite@0"
            ]
        },
        {
            "x": 0,
            "y": 9,
            "z": 10,
            "elements": [
                "contenttweaker:stablestructure@0"
            ]
        },
        {
            "x": -2,
            "y": 5,
            "z": 10,
            "elements": [
                "contenttweaker:superglasswhite@0"
            ]
        },
        {
            "x": 2,
            "y": -1,
            "z": 5,
            "elements": [
                "contenttweaker:superglasswhite@0"
            ]
        },
        {
            "x": -1,
            "y": -2,
            "z": 18,
            "elements": [
                "contenttweaker:superglasswhite@0"
            ]
        },
        {
            "x": 10,
            "y": 0,
            "z": 12,
            "elements": [
                "contenttweaker:spacexmachineblock@0"
            ]
        },
        {
            "x": -2,
            "y": 1,
            "z": 10,
            "elements": [
                "astralsorcery:fluidblockliquidstarlight@1"
            ]
        },
        {
            "x": -7,
            "y": 0,
            "z": 9,
            "elements": [
                "contenttweaker:superglasswhite@0"
            ]
        },
        {
            "x": 0,
            "y": -1,
            "z": 10,
            "elements": [
                "astralsorcery:fluidblockliquidstarlight@1"
            ]
        },
        {
            "x": -1,
            "y": -1,
