{
    "registryname": "spacestation_i",
    "localizedname": "§2探索者§b空间站-§9I级§e深空巨构装配体",
    "failure-action": "still",
    "requires-blueprint": false,
    "color": "808080",
    "parts": [
        {
            "x": 0,
            "y": 0,
            "z": 0,
            "elements": [
                "modularmachinery:blockcontroller@2"
            ]
        },
        {
            "x": -2,
            "y": -19,
            "z": -2,
            "elements": [
                "minecraft:quartz_stairs@4"
            ]
        },
        {
            "x": 1,
            "y": -21,
            "z": -2,
            "elements": [
                "chisel:factory@15"
            ]
        },
        {
            "x": 14,
            "y": -9,
            "z": 1,
            "elements": [
                "modularmachinery:blockcasing@0"
            ]
        },
        {
            "x": 2,
            "y": -13,
            "z": -3,
            "elements": [
                "chisel:factory@15"
            ]
        },
        {
            "x": 0,
            "y": -16,
            "z": 3,
            "elements": [
                "chisel:glasspane@9"
            ]
        },
        {
            "x": 2,
            "y": -6,
            "z": 0,
            "elements": [
                "thermalfoundation:glass_alloy@7"
            ]
        },
        {
            "x": 3,
            "y": -8,
            "z": 0,
            "elements": [
                "modularmachinery:blockcasing@0"
            ]
        },
        {
            "x": -13,
            "y": -10,
            "z": 8,
            "elements": [
                "modularmachinery:blockcasing@0"
            ]
        },
        {
            "x": -13,
            "y": -9,
            "z": -7,
            "elements": [
                "avaritia:block_resource@2"
            ]
        },
        {
            "x": 2,
            "y": -23,
            "z": 1,
            "elements": [
                "minecraft:quartz_stairs@7"
            ]
        },
        {
            "x": 14,
            "y": -9,
            "z": -1,
            "elements": [
                "modularmachinery:blockcasing@0"
            ]
        },
        {
            "x": -13,
            "y": -8,
            "z": 8,
            "elements": [
                "modularmachinery:blockcasing@0"
            ]
        },
        {
            "x": 4,
            "y": -10,
            "z": 0,
            "elements": [
                "modularmachinery:blockcasing@0"
            ]
        },
        {
            "x": -1,
            "y": -11,
            "z": -3,
            "elements": [
                "minecraft:quartz_stairs@2"
            ]
        },
        {
            "x": 1,
            "y": 0,
            "z": 0,
            "elements": [
                "casings_all"
            ]
        },
        {
            "x": 1,
            "y": -22,
            "z": -2,
            "elements": [
                "chisel:factory@15"
            ]
        },
        {
            "x": -2,
            "y": -10,
            "z": 15,
            "elements": [
                "modularmachinery:blockcasing@0"
            ]
        },
        {
            "x": 2,
            "y": -22,
            "z": 1,
            "elements": [
                "chisel:factory@15"
            ]
        },
        {
            "x": -13,
            "y": -10,
            "z": -8,
            "elements": [
                "modularmachinery:blockcasing@0"
            ]
        },
        {
            "x": 11,
            "y": -9,
            "z": 1,
            "elements": [
                "modularmachinery:blockcasing@0"
            ]
        },
        {
            "x": -13,
            "y": -8,
            "z": -7,
            "elements": [
                "modularmachinery:blockcasing@0"
            ]
        },
        {
            "x": 1,
            "y": -23,
            "z": -2,
            "elements": [
                "minecraft:quartz_stairs@5"
            ]
        },
        {
            "x": -15,
            "y": -9,
            "z": 3,
            "elements": [
                "avaritia:block_resource@2"
            ]
        },
        {
            "x": 2,
            "y": -8,
            "z": 0,
            "elements": [
                "chisel:technicalnew@2"
            ]
        },
        {
            "x": 2,
            "y": -15,
            "z": -3,
            "elements": [
                "chisel:factory@15"
            ]
        },
        {
            "x": -1,
            "y": -19,
            "z": 1,
            "elements": [
                "chisel:factory@10"
            ]
        },
        {
            "x": 11,
            "y": -9,
            "z": -1,
            "elements": [
                "modularmachinery:blockcasing@0"
            ]
        },
        {
            "x": 1,
            "y": -9,
            "z": 12,
            "elements": [
                "modularmachinery:blockcasing@0"
            ]
        },
        {
            "x": -1,
            "y": -15,
            "z": -3,
            "elements": [
                "chisel:glasspane@9"
            ]
        },
        {
            "x": 2,
            "y": -21,
            "z": 1,
            "elements": [
                "chisel:factory@15"
            ]
        },
        {
            "x": 0,
            "y": -14,
            "z": 3,
            "elements": [
                "chisel:glasspane@9"
            ]
        },
        {
            "x": 5,
            "y": -10,
            "z": 0,
            "elements": [
                "modularmachinery:blockcasing@0"
            ]
        },
        {
            "x": -2,
            "y": -8,
            "z": 15,
            "elements": [
                "modularmachinery:blockcasing@0"
            ]
        },
        {
            "x": -2,
            "y": -18,
            "z": -2,
            "elements": [
                "chisel:factory@10"
            ]
        },
        {
            "x": 0,
            "y": -10,
            "z": 10,
            "elements": [
                "modularmachinery:blockcasing@0"
            ]
        },
        {
            "x": -13,
            "y": -9,
            "z": 8,
            "elements": [
                "avaritia:block_resource@2"
            ]
        },
        {
            "x": -1,
            "y": -9,
            "z": -3,
            "elements": [
                "modularmachinery:blockcasing@0"
            ]
        },
        {
            "x": -13,
            "y": -10,
            "z": -7,
            "elements": [
                "modularmachinery:blockcasing@0"
            ]
        },
        {
            "x": 2,
            "y": 0,
            "z": 0,
            "elements": [
                "chisel:technicalnew@2"
            ]
        },
        {
            "x": 14,
            "y": -8,
            "z": -4,
            "elements": [
                "modularmachinery:blockcasing@0"
            ]
        },
        {
            "x": -2,
            "y": -2,
            "z": 0,
            "elements": [
                "thermalfoundation:glass_alloy@7"
            ]
        },
        {
            "x": -13,
            "y": -8,
            "z": -8,
            "elements": [
                "modularmachinery:blockcasing@0"
            ]
        },
        {
            "x": 2,
            "y": -19,
            "z": 1,
            "elements": [
                "chisel:factory@6"
            ]
        },
        {
            "x": 0,
            "y": -10,
            "z": 5,
            "elements": [
                "modularmachinery:blockcasing@0"
            ]
        },
        {
            "x": 0,
            "y": -12,
            "z": 3,
            "elements": [
                "chisel:technicalnew@2"
            ]
        },
        {
            "x": -4,
            "y": -9,
            "z": 1,
            "elements": [
                "modularmachinery:blockcasing@0"
            ]
        },
        {
            "x": -1,
            "y": -17,
            "z": -3,
            "elements": [
                "chisel:glasspane@9"
            ]
        },
        {
            "x": -3,
            "y": -8,
            "z": 15,
            "elements": [
                "modularmachinery:blockcasing@0"
            ]
        },
        {
            "x": 2,
            "y": -10,
            "z": 0,
            "elements": [
                "chisel:technicalnew@2"
            ]
        },
        {
            "x": -13,
            "y": -9,
            "z": -8,
            "elements": [
                "avaritia:block_resource@2"
            ]
        },
        {
            "x": -1,
            "y": 0,
            "z": 0,
            "elements": [
                "casings_all"
            ]
        },
        {
            "x": 2,
            "y": -20,
            "z": 1,
            "elements": [
                "chisel:factory@15"
            ]
        },
        {
            "x": 1,
            "y": -19,
            "z": -2,
            "elements": [
                "chisel:factory@6"
            ]
        },
        {
            "x": -2,
            "y": -4,
            "z": 0,
            "elements": [
                "thermalfoundation:glass_alloy@7"
            ]
        },
        {
            "x": 14,
            "y": -10,
            "z": -4,
            "elements": [
                "modularmachinery:blockcasing@0"
            ]
        },
        {
            "x": 1,
            "y": -20,
            "z": -2,
            "elements": [
                "chisel:factory@15"
            ]
        },
        {
            "x": 4,
            "y": -8,
            "z": 0,
            "elements": [
                "modularmachinery:blockcasing@0"
            ]
        },
        {
            "x": 0,
            "y": -8,
            "z": 5,
            "elements": [
                "modularmachinery:blockcasing@0"
            ]
        },
        {
            "x": 7,
            "y": -10,
            "z": 0,
            "elements": [
                "modularmachinery:blockcasing@0"
            ]
        },
        {
            "x": 0,
            "y": -10,
            "z": 3,
            "elements": [
                "modularmachinery:blockcasing@0"
            ]
        },
        {
            "x": -3,
            "y": -10,
            "z": 15,
            "elements": [
                "modularmachinery:blockcasing@0"
            ]
        },
        {
            "x": 2,
            "y": -11,
            "z": -3,
            "elements": [
                "minecraft:quartz_stairs@1"
            ]
        },
        {
            "x": -1,
            "y": -19,
            "z": -3,
            "elements": [
                "minecraft:quartz_stairs@6"
            ]
        },
        {
            "x": -8,
            "y": -8,
            "z": 13,
            "elements": [
                "modularmachinery:blockcasing@0"
            ]
        },
        {
            "x": 2,
            "y": -10,
            "z": 1,
            "elements": [
                "chisel:technicalnew@2"
            ]
        },
        {
            "x": 3,
            "y": -14,
            "z": 0,
            "elements": [
                "chisel:glasspane@9"
            ]
        },
        {
            "x": 2,
            "y": -9,
            "z": 1,
            "elements": [
                "chisel:technicalnew@2"
            ]
        },
        {
            "x": 7,
            "y": -8,
            "z": 0,
            "elements": [
                "modularmachinery:blockcasing@0"
            ]
        },
        {
            "x": -8,
            "y": -9,
            "z": 13,
            "elements": [
                "avaritia:block_resource@2"
            ]
        },
        {
            "x": -1,
            "y": -11,
            "z": 1,
            "elements": [
                "chisel:factory@10"
            ]
        },
        {
            "x": -1,
            "y": -8,
            "z": 15,
            "elements": [
                "modularmachinery:blockcasing@0"
            ]
        },
        {
            "x": 11,
            "y": -9,
            "z": -10,
            "elements": [
                "avaritia:block_resource@2"
            ]
        },
        {
            "x": 1,
            "y": -9,
            "z": 11,
            "elements": [
                "modularmachinery:blockcasing@0"
            ]
        },
        {
            "x": 0,
            "y": -10,
            "z": 0,
            "elements": [
                "contenttweaker:fallenstarforcefieldcontrolblock@0"
            ]
        },
        {
            "x": 10,
            "y": -8,
            "z": -11,
            "elements": [
                "modularmachinery:blockcasing@0"
            ]
        },
        {
            "x": 0,
            "y": -8,
            "z": -12,
            "elements": [
                "modularmachinery:blockcasing@0"
            ]
        },
        {
            "x": 2,
            "y": -10,
            "z": 15,
            "elements": [
                "modularmachinery:blockcasing@0"
            ]
        },
        {
            "x": -1,
            "y": -9,
            "z": -7,
            "elements": [
                "modularmachinery:blockcasing@0"
            ]
        },
        {
            "x": 3,
            "y": -16,
            "z": 0,
            "elements": [
                "chisel:glasspane@9"
            ]
        },
        {
            "x": 6,
            "y": -8,
            "z": 0,
            "elements": [
                "modularmachinery:blockcasing@0"
            ]
        },
        {
            "x": 12,
            "y": -9,
            "z": 9,
            "elements": [
                "avaritia:block_resource@2"
            ]
        },
        {
            "x": 2,
            "y": -8,
            "z": 15,
            "elements": [
                "modularmachinery:blockcasing@0"
            ]
        },
        {
            "x": 9,
            "y": -10,
            "z": 0,
            "elements": [
                "modularmachinery:blockcasing@0"
            ]
        },
        {
            "x": 2,
            "y": -11,
            "z": 1,
            "elements": [
                "chisel:factory@6"
            ]
        },
        {
            "x": -2,
            "y": 0,
            "z": 0,
            "elements": [
                "chisel:technicalnew@2"
            ]
        },
        {
            "x": -1,
            "y": -10,
            "z": 15,
            "elements": [
                "modularmachinery:blockcasing@0"
            ]
        },
        {
            "x": 0,
            "y": -12,
            "z": 0,
            "elements": [
                "contenttweaker:fallenstarforcefieldcontrolblock@0"
            ]
        },
        {
            "x": 15,
            "y": -8,
            "z": 2,
            "elements": [
                "modularmachinery:blockcasing@0"
            ]
        },
        {
            "x": 7,
            "y": -10,
            "z": 13,
            "elements": [
                "modularmachinery:blockcasing@0"
            ]
        },
        {
            "x": -1,
            "y": -7,
            "z": 1,
            "elements": [
                "minecraft:quartz_stairs@4"
            ]
        },
        {
            "x": 8,
            "y": -9,
            "z": 1,
            "elements": [
                "modularmachinery:blockcasing@0"
            ]
        },
        {
            "x": -1,
            "y": -9,
            "z": -6,
            "elements": [
                "modularmachinery:blockcasing@0"
            ]
        },
        {
            "x": -1,
            "y": -9,
            "z": 11,
            "elements": [
                "modularmachinery:blockcasing@0"
            ]
        },
        {
            "x": 6,
            "y": -10,
            "z": 0,
            "elements": [
                "modularmachinery:blockcasing@0"
            ]
        },
        {
            "x": -3,
            "y": -8,
            "z": 0,
            "elements": [
                "modularmachinery:blockcasing@0"
            ]
        },
        {
            "x": 2,
            "y": -19,
            "z": -3,
            "elements": [
                "minecraft:quartz_stairs@5"
            ]
        },
        {
            "x": 3,
            "y": -12,
            "z": 0,
            "elements": [
                "chisel:technicalnew@2"
            ]
        },
        {
            "x": 0,
            "y": -18,
            "z": 3,
            "elements": [
                "chisel:technicalnew@2"
            ]
        },
        {
            "x": -1,
            "y": -13,
            "z": -3,
            "elements": [
                "chisel:glasspane@9"
            ]
        },
        {
            "x": -7,
            "y": -9,
            "z": 1,
            "elements": [
                "modularmachinery:blockcasing@0"
            ]
        },
        {
            "x": 10,
            "y": -10,
            "z": -11,
            "elements": [
                "modularmachinery:blockcasing@0"
            ]
        },
        {
            "x": 2,
            "y": -17,
            "z": -3,
            "elements": [
                "chisel:factory@15"
            ]
        },
        {
            "x": 0,
            "y": -9,
            "z": 11,
            "elements": [
                "avaritia:block_resource@2"
            ]
        },
        {
            "x": 0,
            "y": -8,
            "z": 0,
            "elements": [
                "contenttweaker:fallenstarforcefieldcontrolblock@0"
            ]
        },
        {
            "x": 14,
            "y": -9,
            "z": 4,
            "elements": [
                "avaritia:block_resource@2"
            ]
        },
        {
            "x": -8,
            "y": -10,
            "z": 13,
            "elements": [
                "modularmachinery:blockcasing@0"
            ]
        },
        {
            "x": 3,
            "y": -10,
            "z": 0,
            "elements": [
                "modularmachinery:blockcasing@0"
            ]
        },
        {
            "x": 1,
            "y": -9,
            "z": 9,
            "elements": [
                "modularmachinery:blockcasing@0"
            ]
        },
        {
            "x": -1,
            "y": -9,
            "z": 4,
            "elements": [
                "modularmachinery:blockcasing@0"
            ]
        },
        {
            "x": -13,
            "y": -9,
            "z": -1,
            "elements": [
                "modularmachinery:blockcasing@0"
            ]
        },
        {
            "x": -7,
            "y": -10,
            "z": -13,
            "elements": [
                "modularmachinery:blockcasing@0"
            ]
        },
        {
            "x": 12,
            "y": -10,
            "z": 0,
            "elements": [
                "modularmachinery:blockcasing@0"
            ]
        },
        {
            "x": 2,
            "y": -12,
            "z": 3,
            "elements": [
                "chisel:factory@15"
            ]
        },
        {
            "x": -1,
            "y": -9,
            "z": -10,
            "elements": [
                "modularmachinery:blockcasing@0"
            ]
        },
        {
            "x": -5,
            "y": -8,
            "z": 0,
            "elements": [
                "modularmachinery:blockcasing@0"
            ]
        },
        {
            "x": 14,
            "y": -8,
            "z": 6,
            "elements": [
                "modularmachinery:blockcasing@0"
            ]
        },
        {
            "x": -10,
            "y": -9,
            "z": 1,
            "elements": [
                "modularmachinery:blockcasing@0"
            ]
        },
        {
            "x": 0,
            "y": -9,
            "z": 9,
            "elements": [
                "avaritia:block_resource@2"
            ]
        },
        {
            "x": -8,
            "y": -9,
            "z": -1,
            "elements": [
                "modularmachinery:blockcasing@0"
            ]
        },
        {
            "x": -9,
            "y": -10,
            "z": -12,
            "elements": [
                "modularmachinery:blockcasing@0"
            ]
        },
        {
            "x": -1,
            "y": -22,
            "z": 2,
            "elements": [
                "chisel:factory@15"
            ]
        },
        {
            "x": 7,
            "y": -8,
            "z": 13,
            "elements": [
                "modularmachinery:blockcasing@0"
            ]
        },
        {
            "x": 10,
            "y": -8,
            "z": 0,
            "elements": [
                "modularmachinery:blockcasing@0"
            ]
        },
        {
            "x": -1,
            "y": -23,
            "z": 2,
            "elements": [
                "minecraft:quartz_stairs@4"
            ]
        },
        {
            "x": 13,
            "y": -10,
            "z": 0,
            "elements": [
                "modularmachinery:blockcasing@0"
            ]
        },
        {
            "x": 14,
            "y": -9,
            "z": -5,
            "elements": [
                "avaritia:block_resource@2"
            ]
        },
        {
            "x": -7,
            "y": -8,
            "z": -13,
            "elements": [
                "modularmachinery:blockcasing@0"
            ]
        },
        {
            "x": 14,
            "y": -9,
            "z": 6,
            "elements": [
                "avaritia:block_resource@2"
            ]
        },
        {
            "x": 14,
            "y": -10,
            "z": 6,
            "elements": [
                "modularmachinery:blockcasing@0"
            ]
        },
        {
            "x": 0,
            "y": -9,
            "z": -15,
            "elements": [
                "avaritia:block_resource@2"
            ]
        },
        {
            "x": -9,
            "y": -9,
            "z": -12,
            "elements": [
                "avaritia:block_resource@2"
            ]
        },
        {
            "x": -1,
            "y": -23,
            "z": -1,
            "elements": [
                "minecraft:quartz_stairs@4"
            ]
        },
        {
            "x": -13,
            "y": -9,
            "z": 1,
            "elements": [
                "modularmachinery:blockcasing@0"
            ]
        },
        {
            "x": 7,
            "y": -9,
            "z": 13,
            "elements": [
                "avaritia:block_resource@2"
            ]
        },
        {
            "x": -7,
            "y": -9,
            "z": -13,
            "elements": [
                "avaritia:block_resource@2"
            ]
        },
        {
            "x": -1,
            "y": -9,
            "z": -5,
            "elements": [
                "modularmachinery:blockcasing@0"
            ]
        },
        {
            "x": -1,
            "y": -12,
            "z": 3,
            "elements": [
                "chisel:technicalnew@2"
            ]
        },
        {
            "x": -9,
            "y": -8,
            "z": -12,
            "elements": [
                "modularmachinery:blockcasing@0"
            ]
        },
        {
            "x": 1,
            "y": -9,
            "z": 4,
            "elements": [
                "modularmachinery:blockcasing@0"
            ]
        },
        {
            "x": 2,
            "y": -16,
            "z": 3,
            "elements": [
                "chisel:factory@15"
            ]
        },
        {
            "x": -1,
            "y": -20,
            "z": 2,
            "elements": [
                "chisel:factory@15"
            ]
        },
        {
            "x": -11,
            "y": -9,
            "z": -1,
            "elements": [
                "modularmachinery:blockcasing@0"
            ]
        },
        {
            "x": 9,
            "y": -8,
            "z": 0,
            "elements": [
                "modularmachinery:blockcasing@0"
            ]
        },
        {
            "x": 1,
            "y": -9,
            "z": -10,
            "elements": [
                "modularmachinery:blockcasing@0"
            ]
        },
        {
            "x": 10,
            "y": -10,
            "z": 0,
            "elements": [
                "modularmachinery:blockcasing@0"
            ]
        },
        {
            "x": -4,
            "y": -10,
            "z": -14,
            "elements": [
                "modularmachinery:blockcasing@0"
            ]
        },
        {
            "x": 3,
            "y": -9,
            "z": -15,
            "elements": [
                "avaritia:block_resource@2"
            ]
        },
        {
            "x": -1,
            "y": -21,
            "z": 2,
            "elements": [
                "chisel:factory@15"
            ]
        },
        {
            "x": 1,
            "y": -11,
            "z": -3,
            "elements": [
                "minecraft:quartz_stairs@2"
            ]
        },
        {
            "x": 0,
            "y": -9,
            "z": -5,
            "elements": [
                "avaritia:block_resource@2"
            ]
        },
        {
            "x": 1,
            "y": -9,
            "z": -3,
            "elements": [
                "modularmachinery:blockcasing@0"
            ]
        },
        {
            "x": -4,
            "y": -9,
            "z": -14,
            "elements": [
                "avaritia:block_resource@2"
            ]
        },
        {
            "x": -10,
            "y": -9,
            "z": -1,
            "elements": [
                "modularmachinery:blockcasing@0"
            ]
        },
        {
            "x": 12,
            "y": -8,
            "z": 0,
            "elements": [
                "modularmachinery:blockcasing@0"
            ]
        },
        {
            "x": -4,
            "y": -8,
            "z": -14,
            "elements": [
                "modularmachinery:blockcasing@0"
            ]
        },
        {
            "x": 0,
            "y": -9,
            "z": -12,
            "elements": [
                "avaritia:block_resource@2"
            ]
        },
        {
            "x": 15,
            "y": -10,
            "z": 0,
            "elements": [
                "modularmachinery:blockcasing@0"
            ]
        },
        {
            "x": 2,
            "y": -14,
            "z": 3,
            "elements": [
                "chisel:factory@15"
            ]
        },
        {
            "x": -1,
            "y": -9,
            "z": -13,
            "elements": [
                "modularmachinery:blockcasing@0"
            ]
        },
        {
            "x": -10,
            "y": -9,
            "z": -11,
            "elements": [
                "avaritia:block_resource@2"
            ]
        },
        {
            "x": 2,
            "y": -18,
            "z": 2,
            "elements": [
                "chisel:factory@10"
            ]
        },
        {
            "x": -1,
            "y": -19,
            "z": 2,
            "elements": [
                "chisel:factory@6"
            ]
        },
        {
            "x": 0,
            "y": -10,
            "z": -12,
            "elements": [
                "modularmachinery:blockcasing@0"
            ]
        },
        {
            "x": 15,
            "y": -8,
            "z": 0,
            "elements": [
                "modularmachinery:blockcasing@0"
            ]
        },
        {
            "x": -2,
            "y": -22,
            "z": -1,
            "elements": [
                "chisel:factory@15"
            ]
        },
        {
            "x": -2,
            "y": -6,
            "z": 0,
            "elements": [
                "thermalfoundation:glass_alloy@7"
            ]
        },
        {
            "x": -1,
            "y": -1,
            "z": -3,
            "elements": [
                "minecraft:end_rod@2"
            ]
        },
        {
            "x": 0,
            "y": -8,
            "z": -4,
            "elements": [
                "modularmachinery:blockcasing@0"
            ]
        },
        {
            "x": -2,
            "y": -23,
            "z": -1,
            "elements": [
                "minecraft:quartz_stairs@6"
            ]
        },
        {
            "x": 2,
            "y": -19,
            "z": 2,
            "elements": [
                "minecraft:quartz_stairs@5"
            ]
        },
        {
            "x": -1,
            "y": -9,
            "z": -14,
            "elements": [
                "modularmachinery:blockcasing@0"
            ]
        },
        {
            "x": -2,
            "y": -20,
            "z": 0,
            "elements": [
                "thermalfoundation:glass_alloy@7"
            ]
        },
        {
            "x": -4,
            "y": -9,
            "z": -1,
            "elements": [
                "modularmachinery:blockcasing@0"
            ]
        },
        {
            "x": 12,
            "y": -10,
            "z": -9,
            "elements": [
                "modularmachinery:blockcasing@0"
            ]
        },
        {
            "x": 0,
            "y": -9,
            "z": 4,
            "elements": [
                "avaritia:block_resource@2"
            ]
        },
        {
            "x": 0,
            "y": -8,
            "z": 3,
            "elements": [
                "modularmachinery:blockcasing@0"
            ]
        },
        {
            "x": -14,
            "y": -9,
            "z": 0,
            "elements": [
                "avaritia:block_resource@2"
            ]
        },
        {
            "x": -2,
            "y": -8,
            "z": 0,
            "elements": [
                "chisel:technicalnew@2"
            ]
        },
        {
            "x": 0,
            "y": -10,
            "z": -4,
            "elements": [
                "modularmachinery:blockcasing@0"
            ]
        },
        {
            "x": -5,
            "y": -10,
            "z": 0,
            "elements": [
                "modularmachinery:blockcasing@0"
            ]
        },
        {
            "x": -1,
            "y": -10,
            "z": 2,
            "elements": [
                "chisel:technicalnew@2"
            ]
        },
        {
            "x": 12,
            "y": -8,
            "z": -9,
            "elements": [
                "modularmachinery:blockcasing@0"
            ]
        },
        {
            "x": -7,
            "y": -9,
            "z": -1,
            "elements": [
                "modularmachinery:blockcasing@0"
            ]
        },
        {
            "x": -1,
            "y": -9,
            "z": 2,
            "elements": [
                "chisel:technicalnew@2"
            ]
        },
        {
            "x": -14,
            "y": -9,
            "z": 6,
            "elements": [
                "avaritia:block_resource@2"
            ]
        },
        {
            "x": -13,
            "y": -8,
            "z": 7,
            "elements": [
                "modularmachinery:blockcasing@0"
            ]
        },
        {
            "x": -2,
            "y": -20,
            "z": -1,
            "elements": [
                "chisel:factory@15"
            ]
        },
        {
            "x": -1,
            "y": -11,
            "z": 2,
            "elements": [
                "chisel:factory@6"
            ]
        },
        {
            "x": -13,
            "y": -9,
            "z": 7,
            "elements": [
                "avaritia:block_resource@2"
            ]
        },
        {
            "x": 1,
            "y": -8,
            "z": 15,
            "elements": [
                "modularmachinery:blockcasing@0"
            ]
        },
        {
            "x": 0,
            "y": -8,
            "z": 10,
            "elements": [
                "modularmachinery:blockcasing@0"
            ]
        },
        {
            "x": 1,
            "y": -1,
            "z": -3,
            "elements": [
                "minecraft:end_rod@2"
            ]
        },
        {
            "x": -1,
            "y": -9,
            "z": -8,
            "elements": [
                "modularmachinery:blockcasing@0"
            ]
        },
        {
            "x": -2,
            "y": -19,
            "z": -1,
            "elements": [
                "chisel:factory@6"
            ]
        },
        {
            "x": -2,
            "y": -10,
            "z": 0,
            "elements": [
                "chisel:technicalnew@2"
            ]
        },
        {
            "x": -14,
            "y": -10,
            "z": 6,
            "elements": [
                "modularmachinery:blockcasing@0"
            ]
        },
        {
            "x": -8,
            "y": -10,
            "z": 0,
            "elements": [
                "modularmachinery:blockcasing@0"
            ]
        },
        {
            "x": -11,
            "y": -8,
            "z": 0,
            "elements": [
                "modularmachinery:blockcasing@0"
            ]
        },
        {
            "x": -13,
            "y": -10,
            "z": 7,
            "elements": [
                "modularmachinery:blockcasing@0"
            ]
        },
        {
            "x": -14,
            "y": -9,
            "z": -1,
            "elements": [
                "modularmachinery:blockcasing@0"
            ]
        },
        {
            "x": -1,
            "y": -23,
            "z": 1,
            "elements": [
                "minecraft:quartz_stairs@7"
            ]
        },
        {
            "x": 1,
            "y": -10,
            "z": 15,
            "elements": [
                "modularmachinery:blockcasing@0"
            ]
        },
        {
            "x": -14,
            "y": -8,
            "z": 6,
            "elements": [
                "modularmachinery:blockcasing@0"
            ]
        },
        {
            "x": 1,
            "y": -23,
            "z": -1,
            "elements": [
                "minecraft:quartz_stairs@6"
            ]
        },
        {
            "x": -2,
            "y": -21,
            "z": -1,
            "elements": [
                "chisel:factory@15"
            ]
        },
        {
            "x": -8,
            "y": -8,
            "z": 0,
            "elements": [
                "modularmachinery:blockcasing@0"
            ]
        },
        {
            "x": 0,
            "y": -9,
            "z": -8,
            "elements": [
                "avaritia:block_resource@2"
            ]
        },
        {
            "x": -5,
            "y": -9,
            "z": -1,
            "elements": [
                "modularmachinery:blockcasing@0"
            ]
        },
        {
            "x": -2,
            "y": -10,
            "z": 1,
            "elements": [
                "chisel:technicalnew@2"
            ]
        },
        {
            "x": -12,
            "y": -8,
            "z": 0,
            "elements": [
                "modularmachinery:blockcasing@0"
            ]
        },
        {
            "x": 4,
            "y": -9,
            "z": 14,
            "elements": [
                "avaritia:block_resource@2"
            ]
        },
        {
            "x": -1,
            "y": -6,
            "z": -2,
            "elements": [
                "chisel:technicalnew@2"
            ]
        },
        {
            "x": 1,
            "y": -9,
            "z": 2,
            "elements": [
                "chisel:technicalnew@2"
            ]
        },
        {
            "x": 0,
            "y": -29,
            "z": 0,
            "elements": [
                "chisel:factory@15"
            ]
        },
        {
            "x": -1,
            "y": -9,
            "z": -9,
            "elements": [
                "modularmachinery:blockcasing@0"
            ]
        },
        {
            "x": 1,
            "y": -11,
            "z": 2,
            "elements": [
                "chisel:factory@6"
            ]
        },
        {
            "x": -1,
            "y": -8,
            "z": -2,
            "elements": [
                "chisel:technicalnew@2"
            ]
        },
        {
            "x": 0,
            "y": -30,
            "z": 0,
            "elements": [
                "chisel:factory@15"
            ]
        },
        {
            "x": 2,
            "y": -23,
            "z": -1,
            "elements": [
                "minecraft:quartz_stairs@6"
            ]
        },
        {
            "x": -1,
            "y": -7,
            "z": 2,
            "elements": [
                "minecraft:quartz_stairs@4"
            ]
        },
        {
            "x": 5,
            "y": -9,
            "z": 14,
            "elements": [
                "avaritia:block_resource@2"
            ]
        },
        {
            "x": 13,
            "y": -9,
            "z": 7,
            "elements": [
                "avaritia:block_resource@2"
            ]
        },
        {
            "x": 0,
            "y": -31,
            "z": 0,
            "elements": [
                "chisel:factory@15"
            ]
        },
        {
            "x": 1,
            "y": -10,
            "z": -2,
            "elements": [
                "chisel:technicalnew@2"
            ]
        },
        {
            "x": 0,
            "y": -9,
            "z": -6,
            "elements": [
                "avaritia:block_resource@2"
            ]
        },
        {
            "x": 2,
            "y": -12,
            "z": -2,
            "elements": [
                "chisel:factory@10"
            ]
        },
        {
            "x": 13,
            "y": -9,
            "z": -8,
            "elements": [
                "avaritia:block_resource@2"
            ]
        },
        {
            "x": -1,
            "y": -19,
            "z": -1,
            "elements": [
                "chisel:factory@10"
            ]
        },
        {
            "x": 2,
            "y": -21,
            "z": -1,
            "elements": [
                "chisel:factory@15"
            ]
        },
        {
            "x": -2,
            "y": -11,
            "z": -1,
            "elements": [
                "chisel:factory@6"
            ]
        },
        {
            "x": -9,
            "y": -10,
            "z": 0,
            "elements": [
                "modularmachinery:blockcasing@0"
            ]
        },
        {
            "x": -1,
            "y": -2,
            "z": -2,
            "elements": [
                "chisel:technicalnew@2"
            ]
        },
        {
            "x": -3,
            "y": -12,
            "z": 1,
            "elements": [
                "chisel:technicalnew@2"
            ]
        },
        {
            "x": -9,
            "y": -9,
            "z": 0,
            "elements": [
                "avaritia:block_resource@2"
            ]
        },
        {
            "x": 2,
            "y": -19,
            "z": -1,
            "elements": [
                "chisel:factory@6"
            ]
        },
        {
            "x": -2,
            "y": -19,
            "z": -3,
            "elements": [
                "minecraft:quartz_stairs@4"
            ]
        },
        {
            "x": -2,
            "y": -9,
            "z": -1,
            "elements": [
                "chisel:technicalnew@2"
            ]
        },
        {
            "x": -7,
            "y": -8,
            "z": 13,
            "elements": [
                "modularmachinery:blockcasing@0"
            ]
        },
        {
            "x": -12,
            "y": -10,
            "z": 0,
            "elements": [
                "modularmachinery:blockcasing@0"
            ]
        },
        {
            "x": -15,
            "y": -8,
            "z": 0,
            "elements": [
                "modularmachinery:blockcasing@0"
            ]
        },
        {
            "x": -1,
            "y": -4,
            "z": -2,
            "elements": [
                "chisel:technicalnew@2"
            ]
        },
        {
            "x": -2,
            "y": -18,
            "z": -3,
            "elements": [
                "chisel:factory@15"
            ]
        },
        {
            "x": -2,
            "y": -11,
            "z": 2,
            "elements": [
                "minecraft:quartz_stairs@3"
            ]
        },
        {
            "x": 8,
            "y": -8,
            "z": 13,
            "elements": [
                "modularmachinery:blockcasing@0"
            ]
        },
        {
            "x": 13,
            "y": -9,
            "z": -1,
            "elements": [
                "modularmachinery:blockcasing@0"
            ]
        },
        {
            "x": -12,
            "y": -9,
            "z": 0,
            "elements": [
                "avaritia:block_resource@2"
            ]
        },
        {
            "x": -2,
            "y": -17,
            "z": -3,
            "elements": [
                "chisel:factory@15"
            ]
        },
        {
            "x": 1,
            "y": -19,
            "z": -1,
            "elements": [
                "chisel:factory@10"
            ]
        },
        {
            "x": -1,
            "y": -18,
            "z": 3,
            "elements": [
                "chisel:technicalnew@2"
            ]
        },
        {
            "x": 0,
            "y": -4,
            "z": -2,
            "elements": [
                "thermalfoundation:glass_alloy@7"
            ]
        },
        {
            "x": 1,
            "y": -18,
            "z": -3,
            "elements": [
                "chisel:technicalnew@2"
            ]
        },
        {
            "x": -2,
            "y": -16,
            "z": -3,
            "elements": [
                "chisel:factory@15"
            ]
        },
        {
            "x": -14,
            "y": -8,
            "z": -5,
            "elements": [
                "modularmachinery:blockcasing@0"
            ]
        },
        {
            "x": 1,
            "y": -15,
            "z": -3,
            "elements": [
                "chisel:glasspane@9"
            ]
        },
        {
            "x": -14,
            "y": -9,
            "z": -5,
            "elements": [
                "avaritia:block_resource@2"
            ]
        },
        {
            "x": 1,
            "y": -7,
            "z": -1,
            "elements": [
                "minecraft:quartz_stairs@6"
            ]
        },
        {
            "x": 6,
            "y": -10,
            "z": -14,
            "elements": [
                "modularmachinery:blockcasing@0"
            ]
        },
        {
            "x": 1,
            "y": -17,
            "z": -3,
            "elements": [
                "chisel:glasspane@9"
            ]
        },
        {
            "x": 1,
            "y": 0,
            "z": 1,
            "elements": [
                "minecraft:stone_slab@7"
            ]
        },
        {
            "x": -2,
            "y": -13,
            "z": -3,
            "elements": [
                "chisel:factory@15"
            ]
        },
        {
            "x": -2,
            "y": -1,
            "z": -1,
            "elements": [
                "chisel:technicalnew@2"
            ]
        },
        {
            "x": 1,
            "y": -2,
            "z": -2,
            "elements": [
                "chisel:technicalnew@2"
            ]
        },
        {
            "x": -1,
            "y": 0,
            "z": -2,
            "elements": [
                "minecraft:stone_slab@7"
            ]
        },
        {
            "x": -2,
            "y": -15,
            "z": -3,
            "elements": [
                "chisel:factory@15"
            ]
        },
        {
            "x": 0,
            "y": -9,
            "z": -13,
            "elements": [
                "avaritia:block_resource@2"
            ]
        },
        {
            "x": 0,
            "y": -1,
            "z": 2,
            "elements": [
                "thermalfoundation:glass_alloy@7"
            ]
        },
        {
            "x": -1,
            "y": -3,
            "z": 2,
            "elements": [
                "chisel:technicalnew@2"
            ]
        },
        {
            "x": -1,
            "y": -19,
            "z": 3,
            "elements": [
                "minecraft:quartz_stairs@7"
            ]
        },
        {
            "x": 10,
            "y": -9,
            "z": -1,
            "elements": [
                "modularmachinery:blockcasing@0"
            ]
        },
        {
            "x": -14,
            "y": -9,
            "z": 1,
            "elements": [
                "modularmachinery:blockcasing@0"
            ]
        },
        {
            "x": -9,
            "y": -8,
            "z": 0,
            "elements": [
                "modularmachinery:blockcasing@0"
            ]
        },
        {
            "x": -7,
            "y": -10,
            "z": 13,
            "elements": [
                "modularmachinery:blockcasing@0"
            ]
        },
        {
            "x": -2,
            "y": -14,
            "z": -3,
            "elements": [
                "chisel:factory@15"
            ]
        },
        {
            "x": -6,
            "y": -10,
            "z": 0,
            "elements": [
                "modularmachinery:blockcasing@0"
            ]
        },
        {
            "x": -2,
            "y": -22,
            "z": 1,
            "elements": [
                "chisel:factory@15"
            ]
        },
        {
            "x": 6,
            "y": -8,
            "z": -14,
            "elements": [
                "modularmachinery:blockcasing@0"
            ]
        },
        {
            "x": 11,
            "y": -10,
            "z": 10,
            "elements": [
                "modularmachinery:blockcasing@0"
            ]
        },
        {
            "x": 1,
            "y": -13,
            "z": -3,
            "elements": [
                "chisel:glasspane@9"
            ]
        },
        {
            "x": 15,
            "y": -8,
            "z": 1,
            "elements": [
                "modularmachinery:blockcasing@0"
            ]
        },
        {
            "x": 1,
            "y": -4,
            "z": -2,
            "elements": [
                "chisel:technicalnew@2"
            ]
        },
        {
            "x": 0,
            "y": -2,
            "z": -2,
            "elements": [
                "thermalfoundation:glass_alloy@7"
            ]
        },
        {
            "x": -2,
            "y": -3,
            "z": -1,
            "elements": [
                "chisel:technicalnew@2"
            ]
        },
        {
            "x": -1,
            "y": -1,
            "z": 2,
            "elements": [
                "chisel:technicalnew@2"
            ]
        },
        {
            "x": 0,
            "y": 0,
            "z": -2,
            "elements": [
                "chisel:technicalnew@2"
            ]
        },
        {
            "x": -11,
            "y": -10,
            "z": -10,
            "elements": [
                "modularmachinery:blockcasing@0"
            ]
        },
        {
            "x": 2,
            "y": -18,
            "z": 3,
            "elements": [
                "chisel:factory@15"
            ]
        },
        {
            "x": 2,
            "y": -19,
            "z": 3,
            "elements": [
                "minecraft:quartz_stairs@5"
            ]
        },
        {
            "x": 11,
            "y": -9,
            "z": 10,
            "elements": [
                "avaritia:block_resource@2"
            ]
        },
        {
            "x": 15,
            "y": -10,
            "z": 1,
            "elements": [
                "modularmachinery:blockcasing@0"
            ]
        },
        {
            "x": 7,
            "y": -9,
            "z": -1,
            "elements": [
                "modularmachinery:blockcasing@0"
            ]
        },
        {
            "x": 0,
            "y": -3,
            "z": 2,
            "elements": [
                "thermalfoundation:glass_alloy@7"
            ]
        },
        {
            "x": 1,
            "y": -19,
            "z": -3,
            "elements": [
                "minecraft:quartz_stairs@6"
            ]
        },
        {
            "x": 1,
            "y": -5,
            "z": 2,
            "elements": [
                "chisel:technicalnew@2"
            ]
        },
        {
            "x": 1,
            "y": -14,
            "z": -3,
            "elements": [
                "chisel:glasspane@9"
            ]
        },
        {
            "x": -14,
            "y": -10,
            "z": -5,
            "elements": [
                "modularmachinery:blockcasing@0"
            ]
        },
        {
            "x": -2,
            "y": -20,
            "z": 1,
            "elements": [
                "chisel:factory@15"
            ]
        },
        {
            "x": -1,
            "y": -9,
            "z": 9,
            "elements": [
                "modularmachinery:blockcasing@0"
            ]
        },
        {
            "x": 14,
            "y": -9,
            "z": -6,
            "elements": [
                "avaritia:block_resource@2"
            ]
        },
        {
            "x": 1,
            "y": -6,
            "z": -2,
            "elements": [
                "chisel:technicalnew@2"
            ]
        },
        {
            "x": 13,
            "y": -8,
            "z": 0,
            "elements": [
                "modularmachinery:blockcasing@0"
            ]
        },
        {
            "x": -14,
            "y": -10,
            "z": -4,
            "elements": [
                "modularmachinery:blockcasing@0"
            ]
        },
        {
            "x": 11,
            "y": -8,
            "z": 10,
            "elements": [
                "modularmachinery:blockcasing@0"
            ]
        },
        {
            "x": -11,
            "y": -9,
            "z": -10,
            "elements": [
                "avaritia:block_resource@2"
            ]
        },
        {
            "x": 0,
            "y": -10,
            "z": -14,
            "elements": [
                "modularmachinery:blockcasing@0"
            ]
        },
        {
            "x": -2,
            "y": -5,
            "z": -1,
            "elements": [
                "chisel:technicalnew@2"
            ]
        },
        {
            "x": 0,
            "y": -8,
            "z": -7,
            "elements": [
                "modularmachinery:blockcasing@0"
            ]
        },
        {
            "x": 1,
            "y": 0,
            "z": -2,
            "elements": [
                "minecraft:stone_slab@7"
            ]
        },
        {
            "x": 1,
            "y": -3,
            "z": 2,
            "elements": [
                "chisel:technicalnew@2"
            ]
        },
        {
            "x": -1,
            "y": -14,
            "z": 3,
            "elements": [
                "chisel:glasspane@9"
            ]
        },
        {
            "x": -1,
            "y": -15,
            "z": 3,
            "elements": [
                "chisel:glasspane@9"
            ]
        },
        {
            "x": -11,
            "y": -8,
            "z": -10,
            "elements": [
                "modularmachinery:blockcasing@0"
            ]
        },
        {
            "x": 1,
            "y": -8,
            "z": -2,
            "elements": [
                "chisel:technicalnew@2"
            ]
        },
        {
            "x": 0,
            "y": -10,
            "z": 8,
            "elements": [
                "modularmachinery:blockcasing@0"
            ]
        },
        {
            "x": 1,
            "y": -11,
            "z": -1,
            "elements": [
                "chisel:factory@10"
            ]
        },
        {
            "x": -14,
            "y": -8,
            "z": -4,
            "elements": [
                "modularmachinery:blockcasing@0"
            ]
        },
        {
            "x": 1,
            "y": -7,
            "z": 2,
            "elements": [
                "minecraft:quartz_stairs@5"
            ]
        },
        {
            "x": 1,
            "y": -16,
            "z": -3,
            "elements": [
                "chisel:glasspane@9"
            ]
        },
        {
            "x": 1,
            "y": -9,
            "z": -4,
            "elements": [
                "modularmachinery:blockcasing@0"
            ]
        },
        {
            "x": 0,
            "y": -8,
            "z": -14,
            "elements": [
                "modularmachinery:blockcasing@0"
            ]
        },
        {
            "x": 0,
            "y": -10,
            "z": -7,
            "elements": [
                "modularmachinery:blockcasing@0"
            ]
        },
        {
            "x": 8,
            "y": -10,
            "z": 13,
            "elements": [
                "modularmachinery:blockcasing@0"
            ]
        },
        {
            "x": -1,
            "y": -16,
            "z": 3,
            "elements": [
                "chisel:glasspane@9"
            ]
        },
        {
            "x": 1,
            "y": -1,
            "z": 2,
            "elements": [
                "chisel:technicalnew@2"
            ]
        },
        {
            "x": 2,
            "y": -11,
            "z": 2,
            "elements": [
                "minecraft:quartz_stairs@1"
            ]
        },
        {
            "x": -2,
            "y": -11,
            "z": -3,
            "elements": [
                "minecraft:quartz_stairs@0"
            ]
        },
        {
            "x": -14,
            "y": -9,
            "z": -4,
            "elements": [
                "avaritia:block_resource@2"
            ]
        },
        {
            "x": -2,
            "y": -12,
            "z": -3,
            "elements": [
                "chisel:factory@15"
            ]
        },
        {
            "x": -9,
            "y": -9,
            "z": 12,
            "elements": [
                "avaritia:block_resource@2"
            ]
        },
        {
            "x": 0,
            "y": -8,
            "z": 8,
            "elements": [
                "modularmachinery:blockcasing@0"
            ]
        },
        {
            "x": -1,
            "y": -5,
            "z": 2,
            "elements": [
                "chisel:technicalnew@2"
            ]
        },
        {
            "x": -2,
            "y": -7,
            "z": -1,
            "elements": [
                "minecraft:quartz_stairs@6"
            ]
        },
        {
            "x": -1,
            "y": -17,
            "z": 3,
            "elements": [
                "chisel:glasspane@9"
            ]
        },
        {
            "x": 3,
            "y": -12,
            "z": 1,
            "elements": [
                "chisel:technicalnew@2"
            ]
        },
        {
            "x": 2,
            "y": -1,
            "z": -1,
            "elements": [
                "chisel:technicalnew@2"
            ]
        },
        {
            "x": 2,
            "y": -4,
            "z": 1,
            "elements": [
                "chisel:technicalnew@2"
            ]
        },
        {
            "x": 0,
            "y": -16,
            "z": 0,
            "elements": [
                "contenttweaker:fallenstarforcefieldcontrolblock@0"
            ]
        },
        {
            "x": 3,
            "y": -15,
            "z": 2,
            "elements": [
                "chisel:factory@15"
            ]
        },
        {
            "x": 15,
            "y": -9,
            "z": 3,
            "elements": [
                "avaritia:block_resource@2"
            ]
        },
        {
            "x": 6,
            "y": -9,
            "z": -1,
            "elements": [
                "modularmachinery:blockcasing@0"
            ]
        },
        {
            "x": 15,
            "y": -8,
            "z": 3,
            "elements": [
                "modularmachinery:blockcasing@0"
            ]
        },
        {
            "x": 0,
            "y": -15,
            "z": 0,
            "elements": [
                "contenttweaker:fallenstarforcefieldcontrolblock@0"
            ]
        },
        {
            "x": -3,
            "y": -12,
            "z": 0,
            "elements": [
                "chisel:technicalnew@2"
            ]
        },
        {
            "x": 2,
            "y": -2,
            "z": 1,
            "elements": [
                "chisel:technicalnew@2"
            ]
        },
        {
            "x": 0,
            "y": -14,
            "z": 0,
            "elements": [
                "contenttweaker:fallenstarforcefieldcontrolblock@0"
            ]
        },
        {
            "x": 3,
            "y": -11,
            "z": -1,
            "elements": [
                "minecraft:quartz_stairs@1"
            ]
        },
        {
            "x": 0,
            "y": -9,
            "z": 2,
            "elements": [
                "chisel:technicalnew@2"
            ]
        },
        {
            "x": 3,
            "y": -17,
            "z": 2,
            "elements": [
                "chisel:factory@15"
            ]
        },
        {
            "x": -3,
            "y": -9,
            "z": 0,
            "elements": [
                "avaritia:block_resource@2"
            ]
        },
        {
            "x": 0,
            "y": 0,
            "z": 1,
            "elements": [
                "casings_all"
            ]
        },
        {
            "x": 2,
            "y": -3,
            "z": -1,
            "elements": [
                "chisel:technicalnew@2"
            ]
        },
        {
            "x": -3,
            "y": -11,
            "z": 0,
            "elements": [
                "minecraft:quartz_stairs@0"
            ]
        },
        {
            "x": -1,
            "y": -20,
            "z": -2,
            "elements": [
                "chisel:factory@15"
            ]
        },
        {
            "x": 0,
            "y": -11,
            "z": 2,
            "elements": [
                "chisel:factory@6"
            ]
        },
        {
            "x": 15,
            "y": -9,
            "z": 2,
            "elements": [
                "avaritia:block_resource@2"
            ]
        },
        {
            "x": 0,
            "y": -13,
            "z": 0,
            "elements": [
                "contenttweaker:fallenstarforcefieldcontrolblock@0"
            ]
        },
        {
            "x": 3,
            "y": -9,
            "z": -1,
            "elements": [
                "modularmachinery:blockcasing@0"
            ]
        },
        {
            "x": -6,
            "y": -8,
            "z": 0,
            "elements": [
                "modularmachinery:blockcasing@0"
            ]
        },
        {
            "x": -3,
            "y": -10,
            "z": 0,
            "elements": [
                "modularmachinery:blockcasing@0"
            ]
        },
        {
            "x": 0,
            "y": -7,
            "z": -1,
            "elements": [
                "chisel:factory@10"
            ]
        },
        {
            "x": 2,
            "y": -10,
            "z": -15,
            "elements": [
                "modularmachinery:blockcasing@0"
            ]
        },
        {
            "x": 0,
            "y": -7,
            "z": 2,
            "elements": [
                "minecraft:quartz_stairs@7"
            ]
        },
        {
            "x": -1,
            "y": 0,
            "z": 1,
            "elements": [
                "minecraft:stone_slab@7"
            ]
        },
        {
            "x": 0,
            "y": -19,
            "z": 0,
            "elements": [
                "contenttweaker:fallenstarforcefieldcontrolblock@0"
            ]
        },
        {
            "x": 3,
            "y": -18,
            "z": 0,
            "elements": [
                "chisel:technicalnew@2"
            ]
        },
        {
            "x": -6,
            "y": -9,
            "z": 0,
            "elements": [
                "avaritia:block_resource@2"
            ]
        },
        {
            "x": -3,
            "y": -14,
            "z": 0,
            "elements": [
                "chisel:glasspane@9"
            ]
        },
        {
            "x": 2,
            "y": -6,
            "z": 1,
            "elements": [
                "chisel:technicalnew@2"
            ]
        },
        {
            "x": -3,
            "y": -13,
            "z": 0,
            "elements": [
                "chisel:glasspane@9"
            ]
        },
        {
            "x": 0,
            "y": -20,
            "z": 0,
            "elements": [
                "contenttweaker:fallenstarforcefieldcontrolblock@0"
            ]
        },
        {
            "x": 3,
            "y": -11,
            "z": 2,
            "elements": [
                "minecraft:quartz_stairs@3"
            ]
        },
        {
            "x": 0,
            "y": -9,
            "z": 12,
            "elements": [
                "avaritia:block_resource@2"
            ]
        },
        {
            "x": 2,
            "y": -5,
            "z": -1,
            "elements": [
                "chisel:technicalnew@2"
            ]
        },
        {
            "x": 4,
            "y": -9,
            "z": -1,
            "elements": [
                "modularmachinery:blockcasing@0"
            ]
        },
        {
            "x": -1,
            "y": -22,
            "z": -2,
            "elements": [
                "chisel:factory@15"
            ]
        },
        {
            "x": 3,
            "y": -17,
            "z": 0,
            "elements": [
                "chisel:glasspane@9"
            ]
        },
        {
            "x": -1,
            "y": -9,
            "z": 14,
            "elements": [
                "modularmachinery:blockcasing@0"
            ]
        },
        {
            "x": 0,
            "y": -5,
            "z": 2,
            "elements": [
                "thermalfoundation:glass_alloy@7"
            ]
        },
        {
            "x": -2,
            "y": 0,
            "z": 1,
            "elements": [
                "minecraft:stone_slab@7"
            ]
        },
        {
            "x": 2,
            "y": -8,
            "z": -15,
            "elements": [
                "modularmachinery:blockcasing@0"
            ]
        },
        {
            "x": 15,
            "y": -10,
            "z": 3,
            "elements": [
                "modularmachinery:blockcasing@0"
            ]
        },
        {
            "x": -1,
            "y": -9,
            "z": 7,
            "elements": [
                "modularmachinery:blockcasing@0"
            ]
        },
        {
            "x": 3,
            "y": -19,
            "z": 0,
            "elements": [
                "minecraft:quartz_stairs@5"
            ]
        },
        {
            "x": -3,
            "y": -16,
            "z": 0,
            "elements": [
                "chisel:glasspane@9"
            ]
        },
        {
            "x": 3,
            "y": -13,
            "z": 2,
            "elements": [
                "chisel:factory@15"
            ]
        },
        {
            "x": 2,
            "y": -7,
            "z": -1,
            "elements": [
                "minecraft:quartz_stairs@6"
            ]
        },
        {
            "x": 2,
            "y": -9,
            "z": -15,
            "elements": [
                "avaritia:block_resource@2"
            ]
        },
        {
            "x": 0,
            "y": -18,
            "z": 0,
            "elements": [
                "contenttweaker:fallenstarforcefieldcontrolblock@0"
            ]
        },
        {
            "x": -3,
            "y": -15,
            "z": 0,
            "elements": [
                "chisel:glasspane@9"
            ]
        },
        {
            "x": 0,
            "y": -17,
            "z": 0,
            "elements": [
                "contenttweaker:fallenstarforcefieldcontrolblock@0"
            ]
        },
        {
            "x": 5,
            "y": -9,
            "z": -1,
            "elements": [
                "modularmachinery:blockcasing@0"
            ]
        },
        {
            "x": -4,
            "y": -9,
            "z": 14,
            "elements": [
                "avaritia:block_resource@2"
            ]
        },
        {
            "x": 2,
            "y": -8,
            "z": 1,
            "elements": [
                "chisel:technicalnew@2"
            ]
        },
        {
            "x": 1,
            "y": -9,
            "z": -5,
            "elements": [
                "modularmachinery:blockcasing@0"
            ]
        },
        {
            "x": 0,
            "y": -9,
            "z": 7,
            "elements": [
                "avaritia:block_resource@2"
            ]
        },
        {
            "x": -3,
            "y": -17,
            "z": 0,
            "elements": [
                "chisel:glasspane@9"
            ]
        },
        {
            "x": 0,
            "y": -8,
            "z": 13,
            "elements": [
                "modularmachinery:blockcasing@0"
            ]
        },
        {
            "x": -15,
            "y": -10,
            "z": 0,
            "elements": [
                "modularmachinery:blockcasing@0"
            ]
        },
        {
            "x": -10,
            "y": -9,
            "z": 11,
            "elements": [
                "avaritia:block_resource@2"
            ]
        },
        {
            "x": 2,
            "y": -18,
            "z": -2,
            "elements": [
                "chisel:factory@10"
            ]
        },
        {
            "x": -3,
            "y": -11,
            "z": 2,
            "elements": [
                "minecraft:quartz_stairs@3"
            ]
        },
        {
            "x": -3,
            "y": -18,
            "z": 0,
            "elements": [
                "chisel:technicalnew@2"
            ]
        },
        {
            "x": 1,
            "y": -21,
            "z": 2,
            "elements": [
                "chisel:factory@15"
            ]
        },
        {
            "x": 3,
            "y": -18,
            "z": 1,
            "elements": [
                "chisel:technicalnew@2"
            ]
        },
        {
            "x": 9,
            "y": -10,
            "z": -12,
            "elements": [
                "modularmachinery:blockcasing@0"
            ]
        },
        {
            "x": -15,
            "y": -9,
            "z": 0,
            "elements": [
                "avaritia:block_resource@2"
            ]
        },
        {
            "x": -10,
            "y": -10,
            "z": 11,
            "elements": [
                "modularmachinery:blockcasing@0"
            ]
        },
        {
            "x": 1,
            "y": -9,
            "z": 14,
            "elements": [
                "modularmachinery:blockcasing@0"
            ]
        },
        {
            "x": 2,
            "y": -9,
            "z": -1,
            "elements": [
                "chisel:technicalnew@2"
            ]
        },
        {
            "x": -3,
            "y": -19,
            "z": 0,
            "elements": [
                "minecraft:quartz_stairs@4"
            ]
        },
        {
            "x": 1,
            "y": -9,
            "z": 7,
            "elements": [
                "modularmachinery:blockcasing@0"
            ]
        },
        {
            "x": 1,
            "y": -9,
            "z": -8,
            "elements": [
                "modularmachinery:blockcasing@0"
            ]
        },
        {
            "x": 3,
            "y": -1,
            "z": -1,
            "elements": [
                "minecraft:end_rod@5"
            ]
        },
        {
            "x": 0,
            "y": -24,
            "z": 0,
            "elements": [
                "chisel:factory@15"
            ]
        },
        {
            "x": -1,
            "y": -11,
            "z": -1,
            "elements": [
                "chisel:factory@10"
            ]
        },
        {
            "x": -2,
            "y": -2,
            "z": 1,
            "elements": [
                "chisel:technicalnew@2"
            ]
        },
        {
            "x": -3,
            "y": -13,
            "z": 2,
            "elements": [
                "chisel:factory@15"
            ]
        },
        {
            "x": -2,
            "y": -12,
            "z": -2,
            "elements": [
                "chisel:factory@10"
            ]
        },
        {
            "x": 8,
            "y": -9,
            "z": -13,
            "elements": [
                "avaritia:block_resource@2"
            ]
        },
        {
            "x": 0,
            "y": -21,
            "z": 0,
            "elements": [
                "contenttweaker:fallenstarforcefieldcontrolblock@0"
            ]
        },
        {
            "x": 0,
            "y": -23,
            "z": 0,
            "elements": [
                "chisel:factory@15"
            ]
        },
        {
            "x": 0,
            "y": -22,
            "z": 0,
            "elements": [
                "contenttweaker:fallenstarforcefieldcontrolblock@0"
            ]
        },
        {
            "x": -2,
            "y": -4,
            "z": 1,
            "elements": [
                "chisel:technicalnew@2"
            ]
        },
        {
            "x": 1,
            "y": -19,
            "z": 2,
            "elements": [
                "chisel:factory@6"
            ]
        },
        {
            "x": 0,
            "y": -26,
            "z": 0,
            "elements": [
                "chisel:factory@15"
            ]
        },
        {
            "x": -3,
            "y": -15,
            "z": 2,
            "elements": [
                "chisel:factory@15"
            ]
        },
        {
            "x": 2,
            "y": -11,
            "z": -1,
            "elements": [
                "chisel:factory@6"
            ]
        },
        {
            "x": -1,
            "y": -8,
            "z": -15,
            "elements": [
                "modularmachinery:blockcasing@0"
            ]
        },
        {
            "x": 5,
            "y": -8,
            "z": -14,
            "elements": [
                "modularmachinery:blockcasing@0"
            ]
        },
        {
            "x": -1,
            "y": -9,
            "z": -15,
            "elements": [
                "avaritia:block_resource@2"
            ]
        },
        {
            "x": 8,
            "y": -9,
            "z": -1,
            "elements": [
                "modularmachinery:blockcasing@0"
            ]
        },
        {
            "x": -2,
            "y": -6,
            "z": 1,
            "elements": [
                "chisel:technicalnew@2"
            ]
        },
        {
            "x": -3,
            "y": -17,
            "z": 2,
            "elements": [
                "chisel:factory@15"
            ]
        },
        {
            "x": -1,
            "y": -7,
            "z": -1,
            "elements": [
                "minecraft:quartz_stairs@4"
            ]
        },
        {
            "x": 1,
            "y": -9,
            "z": -11,
            "elements": [
                "modularmachinery:blockcasing@0"
            ]
        },
        {
            "x": 0,
            "y": -25,
            "z": 0,
            "elements": [
                "chisel:factory@15"
            ]
        },
        {
            "x": 0,
            "y": -19,
            "z": 2,
            "elements": [
                "chisel:factory@6"
            ]
        },
        {
            "x": -5,
            "y": -9,
            "z": 14,
            "elements": [
                "avaritia:block_resource@2"
            ]
        },
        {
            "x": 0,
            "y": -10,
            "z": 13,
            "elements": [
                "modularmachinery:blockcasing@0"
            ]
        },
        {
            "x": 0,
            "y": -28,
            "z": 0,
            "elements": [
                "chisel:factory@15"
            ]
        },
        {
            "x": -1,
            "y": -10,
            "z": -2,
            "elements": [
                "chisel:technicalnew@2"
            ]
        },
        {
            "x": 5,
            "y": -10,
            "z": -14,
            "elements": [
                "modularmachinery:blockcasing@0"
            ]
        },
        {
            "x": 2,
            "y": 0,
            "z": 1,
            "elements": [
                "minecraft:stone_slab@7"
            ]
        },
        {
            "x": 1,
            "y": -23,
            "z": 2,
            "elements": [
                "minecraft:quartz_stairs@5"
            ]
        },
        {
            "x": -3,
            "y": -1,
            "z": -1,
            "elements": [
                "minecraft:end_rod@4"
            ]
        },
        {
            "x": 3,
            "y": -14,
            "z": 1,
            "elements": [
                "chisel:glasspane@9"
            ]
        },
        {
            "x": -1,
            "y": -10,
            "z": -15,
            "elements": [
                "modularmachinery:blockcasing@0"
            ]
        },
        {
            "x": 3,
            "y": -16,
            "z": 1,
            "elements": [
                "chisel:glasspane@9"
            ]
        },
        {
            "x": 9,
            "y": -8,
            "z": -12,
            "elements": [
                "modularmachinery:blockcasing@0"
            ]
        },
        {
            "x": -1,
            "y": -9,
            "z": 12,
            "elements": [
                "modularmachinery:blockcasing@0"
            ]
        },
        {
            "x": 0,
            "y": -27,
            "z": 0,
            "elements": [
                "chisel:factory@15"
            ]
        },
        {
            "x": 0,
            "y": -21,
            "z": 2,
            "elements": [
                "thermalfoundation:glass_alloy@7"
            ]
        },
        {
            "x": 9,
            "y": -9,
            "z": -1,
            "elements": [
                "modularmachinery:blockcasing@0"
            ]
        },
        {
            "x": -2,
            "y": -8,
            "z": 1,
            "elements": [
                "chisel:technicalnew@2"
            ]
        },
        {
            "x": 3,
            "y": -19,
            "z": 2,
            "elements": [
                "minecraft:quartz_stairs@7"
            ]
        },
        {
            "x": -10,
            "y": -8,
            "z": 11,
            "elements": [
                "modularmachinery:blockcasing@0"
            ]
        },
        {
            "x": 2,
            "y": -16,
            "z": -3,
            "elements": [
                "chisel:factory@15"
            ]
        },
        {
            "x": 0,
            "y": -11,
            "z": -1,
            "elements": [
                "chisel:factory@10"
            ]
        },
        {
            "x": 0,
            "y": -10,
            "z": 6,
            "elements": [
                "modularmachinery:blockcasing@0"
            ]
        },
        {
            "x": 0,
            "y": -22,
            "z": 2,
            "elements": [
                "thermalfoundation:glass_alloy@7"
            ]
        },
        {
            "x": 4,
            "y": -9,
            "z": 0,
            "elements": [
                "avaritia:block_resource@2"
            ]
        },
        {
            "x": -2,
            "y": -9,
            "z": 15,
            "elements": [
                "avaritia:block_resource@2"
            ]
        },
        {
            "x": 0,
            "y": -23,
            "z": -2,
            "elements": [
                "minecraft:quartz_stairs@6"
            ]
        },
        {
            "x": 7,
            "y": -9,
            "z": -13,
            "elements": [
                "avaritia:block_resource@2"
            ]
        },
        {
            "x": 1,
            "y": -9,
            "z": 10,
            "elements": [
                "modularmachinery:blockcasing@0"
            ]
        },
        {
            "x": -2,
            "y": -18,
            "z": 2,
            "elements": [
                "chisel:factory@10"
            ]
        },
        {
            "x": -1,
            "y": -12,
            "z": -3,
            "elements": [
                "chisel:technicalnew@2"
            ]
        },
        {
            "x": 0,
            "y": -23,
            "z": 2,
            "elements": [
                "minecraft:quartz_stairs@7"
            ]
        },
        {
            "x": -15,
            "y": -9,
            "z": 2,
            "elements": [
                "avaritia:block_resource@2"
            ]
        },
        {
            "x": -15,
            "y": -10,
            "z": 2,
            "elements": [
                "modularmachinery:blockcasing@0"
            ]
        },
        {
            "x": -2,
            "y": -19,
            "z": 2,
            "elements": [
                "minecraft:quartz_stairs@7"
            ]
        },
        {
            "x": 2,
            "y": -14,
            "z": -3,
            "elements": [
                "chisel:factory@15"
            ]
        },
        {
            "x": 2,
            "y": -5,
            "z": 0,
            "elements": [
                "thermalfoundation:glass_alloy@7"
            ]
        },
        {
            "x": 0,
            "y": -9,
            "z": 6,
            "elements": [
                "avaritia:block_resource@2"
            ]
        },
        {
            "x": 0,
            "y": -17,
            "z": 3,
            "elements": [
                "chisel:glasspane@9"
            ]
        },
        {
            "x": 2,
            "y": -7,
            "z": 0,
            "elements": [
                "minecraft:quartz_stairs@5"
            ]
        },
        {
            "x": 7,
            "y": -8,
            "z": -13,
            "elements": [
                "modularmachinery:blockcasing@0"
            ]
        },
        {
            "x": -15,
            "y": -10,
            "z": -2,
            "elements": [
                "modularmachinery:blockcasing@0"
            ]
        },
        {
            "x": 5,
            "y": -9,
            "z": 0,
            "elements": [
                "avaritia:block_resource@2"
            ]
        },
        {
            "x": 1,
            "y": -9,
            "z": 5,
            "elements": [
                "modularmachinery:blockcasing@0"
            ]
        },
        {
            "x": -1,
            "y": -16,
            "z": -3,
            "elements": [
                "chisel:glasspane@9"
            ]
        },
        {
            "x": 0,
            "y": -15,
            "z": 3,
            "elements": [
                "chisel:glasspane@9"
            ]
        },
        {
            "x": -1,
            "y": -9,
            "z": -4,
            "elements": [
                "modularmachinery:blockcasing@0"
            ]
        },
        {
            "x": 0,
            "y": -9,
            "z": 10,
            "elements": [
                "avaritia:block_resource@2"
            ]
        },
        {
            "x": 0,
            "y": -8,
            "z": 6,
            "elements": [
                "modularmachinery:blockcasing@0"
            ]
        },
        {
            "x": 0,
            "y": -21,
            "z": -2,
            "elements": [
                "thermalfoundation:glass_alloy@7"
            ]
        },
        {
            "x": 15,
            "y": -8,
            "z": -2,
            "elements": [
                "modularmachinery:blockcasing@0"
            ]
        },
        {
            "x": -3,
            "y": -18,
            "z": 2,
            "elements": [
                "chisel:factory@15"
            ]
        },
        {
            "x": 6,
            "y": -10,
            "z": 14,
            "elements": [
                "modularmachinery:blockcasing@0"
            ]
        },
        {
            "x": 1,
            "y": -9,
            "z": -13,
            "elements": [
                "modularmachinery:blockcasing@0"
            ]
        },
        {
            "x": -3,
            "y": -19,
            "z": 2,
            "elements": [
                "minecraft:quartz_stairs@7"
            ]
        },
        {
            "x": -15,
            "y": -8,
            "z": 3,
            "elements": [
                "modularmachinery:blockcasing@0"
            ]
        },
        {
            "x": -15,
            "y": -9,
            "z": -2,
            "elements": [
                "avaritia:block_resource@2"
            ]
        },
        {
            "x": 0,
            "y": -22,
            "z": -2,
            "elements": [
                "thermalfoundation:glass_alloy@7"
            ]
        },
        {
            "x": 1,
            "y": -7,
            "z": 0,
            "elements": [
                "chisel:factory@10"
            ]
        },
        {
            "x": -3,
            "y": -9,
            "z": -1,
            "elements": [
                "modularmachinery:blockcasing@0"
            ]
        },
        {
            "x": -6,
            "y": -10,
            "z": 14,
            "elements": [
                "modularmachinery:blockcasing@0"
            ]
        },
        {
            "x": 0,
            "y": -9,
            "z": 5,
            "elements": [
                "avaritia:block_resource@2"
            ]
        },
        {
            "x": 2,
            "y": -9,
            "z": 0,
            "elements": [
                "chisel:technicalnew@2"
            ]
        },
        {
            "x": 7,
            "y": -10,
            "z": -13,
            "elements": [
                "modularmachinery:blockcasing@0"
            ]
        },
        {
            "x": -15,
            "y": -10,
            "z": 3,
            "elements": [
                "modularmachinery:blockcasing@0"
            ]
        },
        {
            "x": 13,
            "y": -8,
            "z": 8,
            "elements": [
                "modularmachinery:blockcasing@0"
            ]
        },
        {
            "x": -1,
            "y": -18,
            "z": -3,
            "elements": [
                "chisel:technicalnew@2"
            ]
        },
        {
            "x": 4,
            "y": -10,
            "z": -14,
            "elements": [
                "modularmachinery:blockcasing@0"
            ]
        },
        {
            "x": 0,
            "y": -13,
            "z": 3,
            "elements": [
                "chisel:glasspane@9"
            ]
        },
        {
            "x": -1,
            "y": -9,
            "z": 10,
            "elements": [
                "modularmachinery:blockcasing@0"
            ]
        },
        {
            "x": 12,
            "y": -9,
            "z": -1,
            "elements": [
                "modularmachinery:blockcasing@0"
            ]
        },
        {
            "x": -2,
            "y": -1,
            "z": 0,
            "elements": [
                "thermalfoundation:glass_alloy@7"
            ]
        },
        {
            "x": 14,
            "y": -9,
            "z": -4,
            "elements": [
                "avaritia:block_resource@2"
            ]
        },
        {
            "x": 13,
            "y": -9,
            "z": 8,
            "elements": [
                "avaritia:block_resource@2"
            ]
        },
        {
            "x": 1,
            "y": -9,
            "z": -14,
            "elements": [
                "modularmachinery:blockcasing@0"
            ]
        },
        {
            "x": 13,
            "y": -10,
            "z": 8,
            "elements": [
                "modularmachinery:blockcasing@0"
            ]
        },
        {
            "x": 0,
            "y": -11,
            "z": 3,
            "elements": [
                "minecraft:quartz_stairs@3"
            ]
        },
        {
            "x": 7,
            "y": -9,
            "z": 0,
            "elements": [
                "avaritia:block_resource@2"
            ]
        },
        {
            "x": -3,
            "y": -11,
            "z": -1,
            "elements": [
                "minecraft:quartz_stairs@0"
            ]
        },
        {
            "x": 13,
            "y": -9,
            "z": 1,
            "elements": [
                "modularmachinery:blockcasing@0"
            ]
        },
        {
            "x": 4,
            "y": -8,
            "z": -14,
            "elements": [
                "modularmachinery:blockcasing@0"
            ]
        },
        {
            "x": -3,
            "y": -9,
            "z": 15,
            "elements": [
                "avaritia:block_resource@2"
            ]
        },
        {
            "x": 2,
            "y": -11,
            "z": 0,
            "elements": [
                "chisel:factory@6"
            ]
        },
        {
            "x": 2,
            "y": -12,
            "z": -3,
            "elements": [
                "chisel:factory@15"
            ]
        },
        {
            "x": -2,
            "y": -3,
            "z": 0,
            "elements": [
                "thermalfoundation:glass_alloy@7"
            ]
        },
        {
            "x": 4,
            "y": -9,
            "z": -14,
            "elements": [
                "avaritia:block_resource@2"
            ]
        },
        {
            "x": -3,
            "y": -12,
            "z": -1,
            "elements": [
                "chisel:technicalnew@2"
            ]
        },
        {
            "x": 12,
            "y": -8,
            "z": 9,
            "elements": [
                "modularmachinery:blockcasing@0"
            ]
        },
        {
            "x": 3,
            "y": -18,
            "z": -1,
            "elements": [
                "chisel:technicalnew@2"
            ]
        },
        {
            "x": 2,
            "y": -9,
            "z": 15,
            "elements": [
                "avaritia:block_resource@2"
            ]
        },
        {
            "x": -9,
            "y": -9,
            "z": -1,
            "elements": [
                "modularmachinery:blockcasing@0"
            ]
        },
        {
            "x": 0,
            "y": -8,
            "z": 11,
            "elements": [
                "modularmachinery:blockcasing@0"
            ]
        },
        {
            "x": 1,
            "y": -9,
            "z": -12,
            "elements": [
                "modularmachinery:blockcasing@0"
            ]
        },
        {
            "x": 0,
            "y": -9,
            "z": 0,
            "elements": [
                "contenttweaker:fallenstarforcefieldcontrolblock@0"
            ]
        },
        {
            "x": 14,
            "y": -10,
            "z": 4,
            "elements": [
                "modularmachinery:blockcasing@0"
            ]
        },
        {
            "x": -3,
            "y": -13,
            "z": -1,
            "elements": [
                "chisel:glasspane@9"
            ]
        },
        {
            "x": 3,
            "y": -17,
            "z": -1,
            "elements": [
                "chisel:glasspane@9"
            ]
        },
        {
            "x": 3,
            "y": -13,
            "z": 0,
            "elements": [
                "chisel:glasspane@9"
            ]
        },
        {
            "x": 0,
            "y": -8,
            "z": 14,
            "elements": [
                "modularmachinery:blockcasing@0"
            ]
        },
        {
            "x": -3,
            "y": -14,
            "z": -1,
            "elements": [
                "chisel:glasspane@9"
            ]
        },
        {
            "x": 0,
            "y": -19,
            "z": -1,
            "elements": [
                "chisel:factory@10"
            ]
        },
        {
            "x": 12,
            "y": -10,
            "z": 9,
            "elements": [
                "modularmachinery:blockcasing@0"
            ]
        },
        {
            "x": 1,
            "y": -9,
            "z": -6,
            "elements": [
                "modularmachinery:blockcasing@0"
            ]
        },
        {
            "x": -3,
            "y": -16,
            "z": -1,
            "elements": [
                "chisel:glasspane@9"
            ]
        },
        {
            "x": -12,
            "y": -9,
            "z": -1,
            "elements": [
                "modularmachinery:blockcasing@0"
            ]
        },
        {
            "x": -1,
            "y": -9,
            "z": 15,
            "elements": [
                "avaritia:block_resource@2"
            ]
        },
        {
            "x": 0,
            "y": -11,
            "z": 0,
            "elements": [
                "contenttweaker:fallenstarforcefieldcontrolblock@0"
            ]
        },
        {
            "x": -6,
            "y": -8,
            "z": 14,
            "elements": [
                "modularmachinery:blockcasing@0"
            ]
        },
        {
            "x": -3,
            "y": -15,
            "z": -1,
            "elements": [
                "chisel:glasspane@9"
            ]
        },
        {
            "x": 3,
            "y": -15,
            "z": 0,
            "elements": [
                "chisel:glasspane@9"
            ]
        },
        {
            "x": 11,
            "y": -8,
            "z": -10,
            "elements": [
                "modularmachinery:blockcasing@0"
            ]
        },
        {
            "x": 3,
            "y": -19,
            "z": -1,
            "elements": [
                "minecraft:quartz_stairs@5"
            ]
        },
        {
            "x": 9,
            "y": -9,
            "z": 0,
            "elements": [
                "avaritia:block_resource@2"
            ]
        },
        {
            "x": -6,
            "y": -9,
            "z": 14,
            "elements": [
                "avaritia:block_resource@2"
            ]
        },
        {
            "x": -15,
            "y": -8,
            "z": -1,
            "elements": [
                "modularmachinery:blockcasing@0"
            ]
        },
        {
            "x": 6,
            "y": -9,
            "z": 0,
            "elements": [
                "avaritia:block_resource@2"
            ]
        },
        {
            "x": 6,
            "y": -9,
            "z": 14,
            "elements": [
                "avaritia:block_resource@2"
            ]
        },
        {
            "x": -3,
            "y": -17,
            "z": -2,
            "elements": [
                "chisel:factory@15"
            ]
        },
        {
            "x": 3,
            "y": -13,
            "z": -1,
            "elements": [
                "chisel:glasspane@9"
            ]
        },
        {
            "x": 1,
            "y": -9,
            "z": -9,
            "elements": [
                "modularmachinery:blockcasing@0"
            ]
        },
        {
            "x": 3,
            "y": -11,
            "z": 0,
            "elements": [
                "minecraft:quartz_stairs@1"
            ]
        },
        {
            "x": -15,
            "y": -8,
            "z": -2,
            "elements": [
                "modularmachinery:blockcasing@0"
            ]
        },
        {
            "x": 13,
            "y": -9,
            "z": -7,
            "elements": [
                "avaritia:block_resource@2"
            ]
        },
        {
            "x": -3,
            "y": -18,
            "z": -1,
            "elements": [
                "chisel:technicalnew@2"
            ]
        },
        {
            "x": -15,
            "y": -9,
            "z": -1,
            "elements": [
                "avaritia:block_resource@2"
            ]
        },
        {
            "x": 6,
            "y": -8,
            "z": 14,
            "elements": [
                "modularmachinery:blockcasing@0"
            ]
        },
        {
            "x": -3,
            "y": -18,
            "z": -2,
            "elements": [
                "chisel:factory@15"
            ]
        },
        {
            "x": -3,
            "y": -17,
            "z": -1,
            "elements": [
                "chisel:glasspane@9"
            ]
        },
        {
            "x": 13,
            "y": -10,
            "z": -7,
            "elements": [
                "modularmachinery:blockcasing@0"
            ]
        },
        {
            "x": 3,
            "y": -14,
            "z": -1,
            "elements": [
                "chisel:glasspane@9"
            ]
        },
        {
            "x": 0,
            "y": -23,
            "z": -1,
            "elements": [
