{
    "registryname": "crafting_ult3",
    "localizedname": "§a合成拓展矩阵「终极模式」",
    "failure-action": "still",
    "color": "00FF00",
    "requires-blueprint": false,
    "factory-only": true,

    "parts": [
        {
            "x": 0,
            "y": 0,
            "z": 0,
            "elements": [
                "modularmachinery:blockfactorycontroller@2"
            ]
        },
        {
            "x": -3,
            "y": 0,
            "z": 5,
            "elements": [
                "modularmachinery:blockcasing@4"
            ]
        },
        {
            "x": -9,
            "y": -2,
            "z": -8,
            "elements": [
                "astraladditions:block_marble_wall@0"
            ]
        },
        {
            "x": 11,
            "y": -3,
            "z": 2,
            "elements": [
                "minecraft:emerald_block@0"
            ]
        },
        {
            "x": -9,
            "y": -3,
            "z": -8,
            "elements": [
                "modularmachinery:blockcasing@4"
            ]
        },
        {
            "x": 11,
            "y": -3,
            "z": 10,
            "elements": [
                "novaeng_core:estorage_casing@0"
            ]
        },
        {
            "x": -5,
            "y": -1,
            "z": 3,
            "elements": [
                "minecraft:gold_block@0"
            ]
        },
        {
            "x": -11,
            "y": -3,
            "z": -2,
            "elements": [
                "novaeng_core:estorage_casing@0"
            ]
        },
        {
            "x": 6,
            "y": -3,
            "z": 11,
            "elements": [
                "astraladditions:block_marble_wall@0"
            ]
        },
        {
            "x": 0,
            "y": -1,
            "z": 0,
            "elements": [
                "appliedenergistics2:smooth_sky_stone_slab@8"
            ]
        },
        {
            "x": -1,
            "y": 1,
            "z": 0,
            "elements": [
                "appliedenergistics2:smooth_sky_stone_slab@0"
            ]
        },
        {
            "x": 3,
            "y": 0,
            "z": -2,
            "elements": [
                "astraladditions:block_marble_wall@0"
            ]
        },
        {
            "x": 3,
            "y": -3,
            "z": 14,
            "elements": [
                "minecraft:emerald_block@0"
            ]
        },
        {
            "x": -5,
            "y": 0,
            "z": 6,
            "elements": [
                "astraladditions:block_marble_wall@0"
            ]
        },
        {
            "x": 2,
            "y": -2,
            "z": -5,
            "elements": [
                "minecraft:diamond_block@0"
            ]
        },
        {
            "x": 7,
            "y": -3,
            "z": -8,
            "elements": [
                "novaeng_core:estorage_casing@0"
            ]
        },
        {
            "x": 5,
            "y": -1,
            "z": 1,
            "elements": [
                "minecraft:end_rod@3"
            ]
        },
        {
            "x": 11,
            "y": -3,
            "z": -4,
            "elements": [
                "novaeng_core:estorage_casing@0"
            ]
        },
        {
            "x": 1,
            "y": 0,
            "z": 0,
            "elements": [
                "chisel:laboratory@15"
            ]
        },
        {
            "x": -11,
            "y": -3,
            "z": 2,
            "elements": [
                "minecraft:emerald_block@0"
            ]
        },
        {
            "x": -8,
            "y": -2,
            "z": 7,
            "elements": [
                "novaeng_core:estorage_casing@0"
            ]
        },
        {
            "x": 11,
            "y": -3,
            "z": 7,
            "elements": [
                "minecraft:end_rod@2"
            ]
        },
        {
            "x": 3,
            "y": 1,
            "z": 2,
            "elements": [
                "appliedenergistics2:smooth_sky_stone_slab@0"
            ]
        },
        {
            "x": 3,
            "y": -1,
            "z": 4,
            "elements": [
                "appliedenergistics2:smooth_sky_stone_slab@8"
            ]
        },
        {
            "x": -11,
            "y": -3,
            "z": 9,
            "elements": [
                "novaeng_core:estorage_casing@0"
            ]
        },
        {
            "x": 1,
            "y": -1,
            "z": 0,
            "elements": [
                "appliedenergistics2:smooth_sky_stone_slab@8"
            ]
        },
        {
            "x": -5,
            "y": -1,
            "z": 2,
            "elements": [
                "minecraft:gold_block@0"
            ]
        },
        {
            "x": -6,
            "y": -3,
            "z": -8,
            "elements": [
                "novaeng_core:estorage_casing@0"
            ]
        },
        {
            "x": 8,
            "y": -2,
            "z": 7,
            "elements": [
                "novaeng_core:estorage_casing@0"
            ]
        },
        {
            "x": 2,
            "y": -3,
            "z": 14,
            "elements": [
                "minecraft:emerald_block@0"
            ]
        },
        {
            "x": 1,
            "y": -2,
            "z": -5,
            "elements": [
                "minecraft:diamond_block@0"
            ]
        },
        {
            "x": -9,
            "y": -4,
            "z": -8,
            "elements": [
                "astraladditions:block_marble_wall@0"
            ]
        },
        {
            "x": 6,
            "y": -2,
            "z": 11,
            "elements": [
                "modularmachinery:blockcasing@4"
            ]
        },
        {
            "x": -10,
            "y": -3,
            "z": 13,
            "elements": [
                "avaritia:block_resource@2"
            ]
        },
        {
            "x": 3,
            "y": 0,
            "z": 2,
            "elements": [
                "chisel:laboratory@15"
            ]
        },
        {
            "x": -10,
            "y": -3,
            "z": -7,
            "elements": [
                "avaritia:block_resource@2"
            ]
        },
        {
            "x": 2,
            "y": 0,
            "z": 0,
            "elements": [
                "modularmachinery:blockcasing@4"
            ]
        },
        {
            "x": 0,
            "y": -1,
            "z": 8,
            "elements": [
                "minecraft:gold_block@0"
            ]
        },
        {
            "x": 3,
            "y": 1,
            "z": 3,
            "elements": [
                "modularmachinery:blockinputbus",
                "modularmachinery:blockmepatternprovider",
                "modularmachinery:blockmeiteminputbus",
                "modularmachinery:blockoutputbus",
                "modularmachinery:blockmeitemoutputbus"
            ]
        },
        {
            "x": -7,
            "y": -2,
            "z": -4,
            "elements": [
                "avaritia:block_resource@2"
            ]
        },
        {
            "x": -8,
            "y": -2,
            "z": -1,
            "elements": [
                "novaeng_core:estorage_casing@0"
            ]
        },
        {
            "x": -11,
            "y": -2,
            "z": 12,
            "elements": [
                "astraladditions:block_marble_wall@0"
            ]
        },
        {
            "x": -8,
            "y": -2,
            "z": 4,
            "elements": [
                "minecraft:diamond_block@0"
            ]
        },
        {
            "x": 1,
            "y": 0,
            "z": 6,
            "elements": [
                "chisel:laboratory@15"
            ]
        },
        {
            "x": -3,
            "y": 0,
            "z": -2,
            "elements": [
                "astraladditions:block_marble_wall@0"
            ]
        },
        {
            "x": 0,
            "y": 1,
            "z": 2,
            "elements": [
                "astraladditions:block_marble_wall@0"
            ]
        },
        {
            "x": 1,
            "y": 1,
            "z": 0,
            "elements": [
                "appliedenergistics2:smooth_sky_stone_slab@0"
            ]
        },
        {
            "x": 8,
            "y": -2,
            "z": -1,
            "elements": [
                "novaeng_core:estorage_casing@0"
            ]
        },
        {
            "x": 1,
            "y": -3,
            "z": -8,
            "elements": [
                "minecraft:emerald_block@0"
            ]
        },
        {
            "x": 1,
            "y": -3,
            "z": 14,
            "elements": [
                "minecraft:emerald_block@0"
            ]
        },
        {
            "x": 4,
            "y": -2,
            "z": -5,
            "elements": [
                "novaeng_core:estorage_casing@0"
            ]
        },
        {
            "x": 1,
            "y": -1,
            "z": 6,
            "elements": [
                "appliedenergistics2:smooth_sky_stone_slab@8"
            ]
        },
        {
            "x": 6,
            "y": -1,
            "z": 11,
            "elements": [
                "astraladditions:block_marble_wall@0"
            ]
        },
        {
            "x": -1,
            "y": -2,
            "z": 11,
            "elements": [
                "minecraft:diamond_block@0"
            ]
        },
        {
            "x": -8,
            "y": -2,
            "z": 1,
            "elements": [
                "minecraft:diamond_block@0"
            ]
        },
        {
            "x": 1,
            "y": 1,
            "z": 6,
            "elements": [
                "appliedenergistics2:smooth_sky_stone_slab@0"
            ]
        },
        {
            "x": -1,
            "y": -1,
            "z": -2,
            "elements": [
                "minecraft:gold_block@0"
            ]
        },
        {
            "x": -1,
            "y": 0,
            "z": 0,
            "elements": [
                "chisel:laboratory@15"
            ]
        },
        {
            "x": -11,
            "y": -4,
            "z": 12,
            "elements": [
                "astraladditions:block_marble_wall@0"
            ]
        },
        {
            "x": 2,
            "y": -1,
            "z": -2,
            "elements": [
                "minecraft:end_rod@4"
            ]
        },
        {
            "x": -3,
            "y": 0,
            "z": 2,
            "elements": [
                "chisel:laboratory@15"
            ]
        },
        {
            "x": 11,
            "y": -3,
            "z": 3,
            "elements": [
                "minecraft:emerald_block@0"
            ]
        },
        {
            "x": 5,
            "y": -1,
            "z": 2,
            "elements": [
                "minecraft:gold_block@0"
            ]
        },
        {
            "x": 2,
            "y": 0,
            "z": 6,
            "elements": [
                "modularmachinery:blockcasing@4"
            ]
        },
        {
            "x": 5,
            "y": -1,
            "z": 4,
            "elements": [
                "minecraft:gold_block@0"
            ]
        },
        {
            "x": -7,
            "y": -2,
            "z": 10,
            "elements": [
                "avaritia:block_resource@2"
            ]
        },
        {
            "x": 8,
            "y": -2,
            "z": 1,
            "elements": [
                "minecraft:diamond_block@0"
            ]
        },
        {
            "x": -3,
            "y": 1,
            "z": 2,
            "elements": [
                "appliedenergistics2:smooth_sky_stone_slab@0"
            ]
        },
        {
            "x": 3,
            "y": 0,
            "z": 3,
            "elements": [
                "chisel:laboratory@15"
            ]
        },
        {
            "x": 0,
            "y": -3,
            "z": -8,
            "elements": [
                "minecraft:emerald_block@0"
            ]
        },
        {
            "x": -11,
            "y": -3,
            "z": 12,
            "elements": [
                "modularmachinery:blockcasing@4"
            ]
        },
        {
            "x": 4,
            "y": -3,
            "z": 14,
            "elements": [
                "minecraft:end_rod@4"
            ]
        },
        {
            "x": 0,
            "y": -1,
            "z": 6,
            "elements": [
                "appliedenergistics2:smooth_sky_stone_slab@8"
            ]
        },
        {
            "x": 0,
            "y": -2,
            "z": 11,
            "elements": [
                "minecraft:diamond_block@0"
            ]
        },
        {
            "x": -2,
            "y": -1,
            "z": 8,
            "elements": [
                "minecraft:end_rod@5"
            ]
        },
        {
            "x": -1,
            "y": -2,
            "z": -5,
            "elements": [
                "minecraft:diamond_block@0"
            ]
        },
        {
            "x": 6,
            "y": -1,
            "z": -5,
            "elements": [
                "astraladditions:block_marble_wall@0"
            ]
        },
        {
            "x": 1,
            "y": -1,
            "z": -2,
            "elements": [
                "minecraft:gold_block@0"
            ]
        },
        {
            "x": -9,
            "y": -3,
            "z": 14,
            "elements": [
                "modularmachinery:blockcasing@4"
            ]
        },
        {
            "x": -6,
            "y": -3,
            "z": 11,
            "elements": [
                "astraladditions:block_marble_wall@0"
            ]
        },
        {
            "x": -2,
            "y": 0,
            "z": 2,
            "elements": [
                "appliedenergistics2:smooth_sky_stone_slab@8"
            ]
        },
        {
            "x": 11,
            "y": -3,
            "z": -1,
            "elements": [
                "minecraft:end_rod@3"
            ]
        },
        {
            "x": -2,
            "y": 1,
            "z": 2,
            "elements": [
                "appliedenergistics2:smooth_sky_stone_stairs@0"
            ]
        },
        {
            "x": 0,
            "y": 1,
            "z": 4,
            "elements": [
                "astraladditions:block_marble_wall@0"
            ]
        },
        {
            "x": 1,
            "y": 0,
            "z": 1,
            "elements": [
                "appliedenergistics2:smooth_sky_stone_slab@8"
            ]
        },
        {
            "x": 7,
            "y": -3,
            "z": 14,
            "elements": [
                "novaeng_core:estorage_casing@0"
            ]
        },
        {
            "x": 6,
            "y": -2,
            "z": -5,
            "elements": [
                "modularmachinery:blockcasing@4"
            ]
        },
        {
            "x": 6,
            "y": -3,
            "z": -5,
            "elements": [
                "astraladditions:block_marble_wall@0"
            ]
        },
        {
            "x": -3,
            "y": -2,
            "z": 11,
            "elements": [
                "minecraft:end_rod@5"
            ]
        },
        {
            "x": -9,
            "y": -2,
            "z": 14,
            "elements": [
                "astraladditions:block_marble_wall@0"
            ]
        },
        {
            "x": 1,
            "y": 1,
            "z": 1,
            "elements": [
                "appliedenergistics2:smooth_sky_stone_stairs@2"
            ]
        },
        {
            "x": 3,
            "y": 0,
            "z": 4,
            "elements": [
                "chisel:laboratory@15"
            ]
        },
        {
            "x": 3,
            "y": -3,
            "z": -8,
            "elements": [
                "minecraft:emerald_block@0"
            ]
        },
        {
            "x": 11,
            "y": -2,
            "z": -6,
            "elements": [
                "astraladditions:block_marble_wall@0"
            ]
        },
        {
            "x": 5,
            "y": 0,
            "z": 0,
            "elements": [
                "astraladditions:block_marble_wall@0"
            ]
        },
        {
            "x": -11,
            "y": -3,
            "z": 4,
            "elements": [
                "minecraft:emerald_block@0"
            ]
        },
        {
            "x": -3,
            "y": 0,
            "z": 4,
            "elements": [
                "chisel:laboratory@15"
            ]
        },
        {
            "x": -6,
            "y": -1,
            "z": 11,
            "elements": [
                "astraladditions:block_marble_wall@0"
            ]
        },
        {
            "x": 3,
            "y": 1,
            "z": 4,
            "elements": [
                "appliedenergistics2:smooth_sky_stone_slab@0"
            ]
        },
        {
            "x": 8,
            "y": -2,
            "z": 5,
            "elements": [
                "minecraft:diamond_block@0"
            ]
        },
        {
            "x": -1,
            "y": 1,
            "z": 2,
            "elements": [
                "ic2:resource@13"
            ]
        },
        {
            "x": -6,
            "y": -2,
            "z": 11,
            "elements": [
                "modularmachinery:blockcasing@4"
            ]
        },
        {
            "x": 6,
            "y": -3,
            "z": 14,
            "elements": [
                "novaeng_core:estorage_casing@0"
            ]
        },
        {
            "x": -9,
            "y": -4,
            "z": 14,
            "elements": [
                "astraladditions:block_marble_wall@0"
            ]
        },
        {
            "x": 0,
            "y": -1,
            "z": -2,
            "elements": [
                "minecraft:gold_block@0"
            ]
        },
        {
            "x": -11,
            "y": -3,
            "z": 3,
            "elements": [
                "minecraft:emerald_block@0"
            ]
        },
        {
            "x": -1,
            "y": 0,
            "z": 2,
            "elements": [
                "appliedenergistics2:smooth_sky_stone_slab@8"
            ]
        },
        {
            "x": -3,
            "y": -2,
            "z": -5,
            "elements": [
                "minecraft:end_rod@5"
            ]
        },
        {
            "x": 6,
            "y": -3,
            "z": -8,
            "elements": [
                "novaeng_core:estorage_casing@0"
            ]
        },
        {
            "x": -2,
            "y": 0,
            "z": 0,
            "elements": [
                "modularmachinery:blockcasing@4"
            ]
        },
        {
            "x": 8,
            "y": -2,
            "z": 4,
            "elements": [
                "minecraft:diamond_block@0"
            ]
        },
        {
            "x": 11,
            "y": -3,
            "z": 5,
            "elements": [
                "minecraft:emerald_block@0"
            ]
        },
        {
            "x": 5,
            "y": 0,
            "z": 6,
            "elements": [
                "astraladditions:block_marble_wall@0"
            ]
        },
        {
            "x": 5,
            "y": -1,
            "z": 3,
            "elements": [
                "minecraft:gold_block@0"
            ]
        },
        {
            "x": 3,
            "y": -1,
            "z": -2,
            "elements": [
                "modularmachinery:blockcasing@4"
            ]
        },
        {
            "x": 4,
            "y": -1,
            "z": -1,
            "elements": [
                "avaritia:block_resource@2"
            ]
        },
        {
            "x": -8,
            "y": -2,
            "z": 3,
            "elements": [
                "minecraft:diamond_block@0"
            ]
        },
        {
            "x": 11,
            "y": -4,
            "z": -6,
            "elements": [
                "astraladditions:block_marble_wall@0"
            ]
        },
        {
            "x": 11,
            "y": -3,
            "z": 8,
            "elements": [
                "novaeng_core:estorage_casing@0"
            ]
        },
        {
            "x": -1,
            "y": 0,
            "z": 5,
            "elements": [
                "appliedenergistics2:smooth_sky_stone_slab@8"
            ]
        },
        {
            "x": -3,
            "y": -3,
            "z": 14,
            "elements": [
                "minecraft:emerald_block@0"
            ]
        },
        {
            "x": 5,
            "y": -2,
            "z": 6,
            "elements": [
                "astraladditions:block_marble_wall@0"
            ]
        },
        {
            "x": 11,
            "y": -3,
            "z": 4,
            "elements": [
                "minecraft:emerald_block@0"
            ]
        },
        {
            "x": -11,
            "y": -3,
            "z": -4,
            "elements": [
                "novaeng_core:estorage_casing@0"
            ]
        },
        {
            "x": 8,
            "y": -2,
            "z": -3,
            "elements": [
                "modularmachinery:blockcasing@4"
            ]
        },
        {
            "x": -5,
            "y": -1,
            "z": 5,
            "elements": [
                "minecraft:end_rod@2"
            ]
        },
        {
            "x": 3,
            "y": -2,
            "z": -2,
            "elements": [
                "astraladditions:block_marble_wall@0"
            ]
        },
        {
            "x": -3,
            "y": 0,
            "z": 8,
            "elements": [
                "astraladditions:block_marble_wall@0"
            ]
        },
        {
            "x": 11,
            "y": -3,
            "z": 11,
            "elements": [
                "novaeng_core:estorage_casing@0"
            ]
        },
        {
            "x": -11,
            "y": -3,
            "z": -1,
            "elements": [
                "minecraft:end_rod@3"
            ]
        },
        {
            "x": -5,
            "y": -2,
            "z": 11,
            "elements": [
                "novaeng_core:estorage_casing@0"
            ]
        },
        {
            "x": -11,
            "y": -3,
            "z": 10,
            "elements": [
                "novaeng_core:estorage_casing@0"
            ]
        },
        {
            "x": 11,
            "y": -3,
            "z": -6,
            "elements": [
                "modularmachinery:blockcasing@4"
            ]
        },
        {
            "x": 8,
            "y": -2,
            "z": 3,
            "elements": [
                "minecraft:diamond_block@0"
            ]
        },
        {
            "x": -1,
            "y": 1,
            "z": 5,
            "elements": [
                "appliedenergistics2:smooth_sky_stone_stairs@3"
            ]
        },
        {
            "x": 8,
            "y": -3,
            "z": -3,
            "elements": [
                "astraladditions:block_marble_wall@0"
            ]
        },
        {
            "x": -5,
            "y": 0,
            "z": 0,
            "elements": [
                "astraladditions:block_marble_wall@0"
            ]
        },
        {
            "x": 5,
            "y": -3,
            "z": -8,
            "elements": [
                "novaeng_core:estorage_casing@0"
            ]
        },
        {
            "x": 0,
            "y": -2,
            "z": -5,
            "elements": [
                "minecraft:diamond_block@0"
            ]
        },
        {
            "x": -8,
            "y": -2,
            "z": 5,
            "elements": [
                "minecraft:diamond_block@0"
            ]
        },
        {
            "x": 5,
            "y": -1,
            "z": 6,
            "elements": [
                "modularmachinery:blockcasing@4"
            ]
        },
        {
            "x": -3,
            "y": -1,
            "z": 8,
            "elements": [
                "modularmachinery:blockcasing@4"
            ]
        },
        {
            "x": 0,
            "y": -3,
            "z": 14,
            "elements": [
                "minecraft:emerald_block@0"
            ]
        },
        {
            "x": 1,
            "y": 1,
            "z": 2,
            "elements": [
                "ic2:resource@13"
            ]
        },
        {
            "x": -3,
            "y": -2,
            "z": 8,
            "elements": [
                "astraladditions:block_marble_wall@0"
            ]
        },
        {
            "x": -11,
            "y": -3,
            "z": 7,
            "elements": [
                "minecraft:end_rod@2"
            ]
        },
        {
            "x": -4,
            "y": -2,
            "z": 11,
            "elements": [
                "novaeng_core:estorage_casing@0"
            ]
        },
        {
            "x": 8,
            "y": -1,
            "z": -3,
            "elements": [
                "astraladditions:block_marble_wall@0"
            ]
        },
        {
            "x": 3,
            "y": -2,
            "z": -5,
            "elements": [
                "minecraft:end_rod@4"
            ]
        },
        {
            "x": 10,
            "y": -3,
            "z": -7,
            "elements": [
                "avaritia:block_resource@2"
            ]
        },
        {
            "x": 4,
            "y": -3,
            "z": -8,
            "elements": [
                "minecraft:end_rod@4"
            ]
        },
        {
            "x": -2,
            "y": -1,
            "z": -2,
            "elements": [
                "minecraft:end_rod@5"
            ]
        },
        {
            "x": 1,
            "y": 0,
            "z": 2,
            "elements": [
                "appliedenergistics2:smooth_sky_stone_slab@8"
            ]
        },
        {
            "x": -6,
            "y": -2,
            "z": -5,
            "elements": [
                "modularmachinery:blockcasing@4"
            ]
        },
        {
            "x": 1,
            "y": 1,
            "z": 3,
            "elements": [
                "astraladditions:block_marble_wall@0"
            ]
        },
        {
            "x": -3,
            "y": 0,
            "z": 1,
            "elements": [
                "modularmachinery:blockcasing@4"
            ]
        },
        {
            "x": 2,
            "y": -1,
            "z": 8,
            "elements": [
                "minecraft:end_rod@4"
            ]
        },
        {
            "x": 3,
            "y": -1,
            "z": 3,
            "elements": [
                "appliedenergistics2:smooth_sky_stone_slab@8"
            ]
        },
        {
            "x": -3,
            "y": -2,
            "z": -2,
            "elements": [
                "astraladditions:block_marble_wall@0"
            ]
        },
        {
            "x": 2,
            "y": 1,
            "z": 2,
            "elements": [
                "appliedenergistics2:smooth_sky_stone_stairs@1"
            ]
        },
        {
            "x": -6,
            "y": -3,
            "z": -5,
            "elements": [
                "astraladditions:block_marble_wall@0"
            ]
        },
        {
            "x": -6,
            "y": -1,
            "z": -5,
            "elements": [
                "astraladditions:block_marble_wall@0"
            ]
        },
        {
            "x": -5,
            "y": -3,
            "z": 14,
            "elements": [
                "novaeng_core:estorage_casing@0"
            ]
        },
        {
            "x": -8,
            "y": -2,
            "z": 0,
            "elements": [
                "minecraft:end_rod@3"
            ]
        },
        {
            "x": -8,
            "y": -1,
            "z": -3,
            "elements": [
                "astraladditions:block_marble_wall@0"
            ]
        },
        {
            "x": -1,
            "y": -3,
            "z": -8,
            "elements": [
                "minecraft:emerald_block@0"
            ]
        },
        {
            "x": -5,
            "y": -1,
            "z": 4,
            "elements": [
                "minecraft:gold_block@0"
            ]
        },
        {
            "x": 1,
            "y": -2,
            "z": 11,
            "elements": [
                "minecraft:diamond_block@0"
            ]
        },
        {
            "x": 11,
            "y": -3,
            "z": 9,
            "elements": [
                "novaeng_core:estorage_casing@0"
            ]
        },
        {
            "x": 3,
            "y": 0,
            "z": 8,
            "elements": [
                "astraladditions:block_marble_wall@0"
            ]
        },
        {
            "x": -1,
            "y": -1,
            "z": 6,
            "elements": [
                "appliedenergistics2:smooth_sky_stone_slab@8"
            ]
        },
        {
            "x": -1,
            "y": 0,
            "z": 4,
            "elements": [
                "appliedenergistics2:smooth_sky_stone_slab@8"
            ]
        },
        {
            "x": -3,
            "y": -1,
            "z": -2,
            "elements": [
                "modularmachinery:blockcasing@4"
            ]
        },
        {
            "x": 2,
            "y": 0,
            "z": 2,
            "elements": [
                "appliedenergistics2:smooth_sky_stone_slab@8"
            ]
        },
        {
            "x": 5,
            "y": -1,
            "z": 5,
            "elements": [
                "minecraft:end_rod@2"
            ]
        },
        {
            "x": -11,
            "y": -3,
            "z": 6,
            "elements": [
                "minecraft:emerald_block@0"
            ]
        },
        {
            "x": -1,
            "y": 1,
            "z": 4,
            "elements": [
                "ic2:resource@13"
            ]
        },
        {
            "x": -8,
            "y": -3,
            "z": -3,
            "elements": [
                "astraladditions:block_marble_wall@0"
            ]
        },
        {
            "x": 0,
            "y": 0,
            "z": 6,
            "elements": [
                "chisel:laboratory@15"
            ]
        },
        {
            "x": 3,
            "y": -1,
            "z": 2,
            "elements": [
                "appliedenergistics2:smooth_sky_stone_slab@8"
            ]
        },
        {
            "x": -6,
            "y": -3,
            "z": 14,
            "elements": [
                "novaeng_core:estorage_casing@0"
            ]
        },
        {
            "x": -2,
            "y": -2,
            "z": 11,
            "elements": [
                "minecraft:diamond_block@0"
            ]
        },
        {
            "x": 0,
            "y": 1,
            "z": 6,
            "elements": [
                "modularmachinery:blockinputbus",
                "modularmachinery:blockmepatternprovider",
                "modularmachinery:blockmeiteminputbus",
                "modularmachinery:blockoutputbus",
                "modularmachinery:blockmeitemoutputbus"
            ]
        },
        {
            "x": 8,
            "y": -2,
            "z": 0,
            "elements": [
                "minecraft:end_rod@3"
            ]
        },
        {
            "x": 2,
            "y": -3,
            "z": -8,
            "elements": [
                "minecraft:emerald_block@0"
            ]
        },
        {
            "x": -8,
            "y": -2,
            "z": -3,
            "elements": [
                "modularmachinery:blockcasing@4"
            ]
        },
        {
            "x": 11,
            "y": -3,
            "z": -3,
            "elements": [
                "novaeng_core:estorage_casing@0"
            ]
        },
        {
            "x": -1,
            "y": 0,
            "z": 1,
            "elements": [
                "appliedenergistics2:smooth_sky_stone_slab@8"
            ]
        },
        {
            "x": -4,
            "y": -2,
            "z": -5,
            "elements": [
                "novaeng_core:estorage_casing@0"
            ]
        },
        {
            "x": -11,
            "y": -3,
            "z": -3,
            "elements": [
                "novaeng_core:estorage_casing@0"
            ]
        },
        {
            "x": -8,
            "y": -2,
            "z": 8,
            "elements": [
                "novaeng_core:estorage_casing@0"
            ]
        },
        {
            "x": -2,
            "y": 1,
            "z": 4,
            "elements": [
                "appliedenergistics2:smooth_sky_stone_stairs@0"
            ]
        },
        {
            "x": 9,
            "y": -2,
            "z": 14,
            "elements": [
                "astraladditions:block_marble_wall@0"
            ]
        },
        {
            "x": -11,
            "y": -3,
            "z": 5,
            "elements": [
                "minecraft:emerald_block@0"
            ]
        },
        {
            "x": -7,
            "y": -3,
            "z": 14,
            "elements": [
                "novaeng_core:estorage_casing@0"
            ]
        },
        {
            "x": 3,
            "y": 0,
            "z": 5,
            "elements": [
                "modularmachinery:blockcasing@4"
            ]
        },
        {
            "x": -3,
            "y": -1,
            "z": 4,
            "elements": [
                "appliedenergistics2:smooth_sky_stone_slab@8"
            ]
        },
        {
            "x": -7,
            "y": -3,
            "z": -8,
            "elements": [
                "novaeng_core:estorage_casing@0"
            ]
        },
        {
            "x": 9,
            "y": -3,
            "z": -8,
            "elements": [
                "modularmachinery:blockcasing@4"
            ]
        },
        {
            "x": -1,
            "y": 1,
            "z": 1,
            "elements": [
                "appliedenergistics2:smooth_sky_stone_stairs@2"
            ]
        },
        {
            "x": 9,
            "y": -3,
            "z": 14,
            "elements": [
                "modularmachinery:blockcasing@4"
            ]
        },
        {
            "x": -1,
            "y": -1,
            "z": 8,
            "elements": [
                "minecraft:gold_block@0"
            ]
        },
        {
            "x": 9,
            "y": -4,
            "z": 14,
            "elements": [
                "astraladditions:block_marble_wall@0"
            ]
        },
        {
            "x": -3,
            "y": 1,
            "z": 4,
            "elements": [
                "appliedenergistics2:smooth_sky_stone_slab@0"
            ]
        },
        {
            "x": -8,
            "y": -3,
            "z": -8,
            "elements": [
                "novaeng_core:estorage_casing@0"
            ]
        },
        {
            "x": -5,
            "y": -2,
            "z": 0,
            "elements": [
                "astraladditions:block_marble_wall@0"
            ]
        },
        {
            "x": 9,
            "y": -4,
            "z": -8,
            "elements": [
                "astraladditions:block_marble_wall@0"
            ]
        },
        {
            "x": -4,
            "y": -3,
            "z": 14,
            "elements": [
                "minecraft:end_rod@5"
            ]
        },
        {
            "x": 8,
            "y": -2,
            "z": 6,
            "elements": [
                "minecraft:end_rod@2"
            ]
        },
        {
            "x": -3,
            "y": -1,
            "z": 2,
            "elements": [
                "appliedenergistics2:smooth_sky_stone_slab@8"
            ]
        },
        {
            "x": 11,
            "y": -3,
            "z": 6,
            "elements": [
                "minecraft:emerald_block@0"
            ]
        },
        {
            "x": -11,
            "y": -2,
            "z": -6,
            "elements": [
                "astraladditions:block_marble_wall@0"
            ]
        },
        {
            "x": -5,
            "y": -1,
            "z": 0,
            "elements": [
                "modularmachinery:blockcasing@4"
            ]
        },
        {
            "x": 8,
            "y": -2,
            "z": 8,
            "elements": [
                "novaeng_core:estorage_casing@0"
            ]
        },
        {
            "x": -2,
            "y": 0,
            "z": 4,
            "elements": [
                "appliedenergistics2:smooth_sky_stone_slab@8"
            ]
        },
        {
            "x": 8,
            "y": -3,
            "z": -8,
            "elements": [
                "novaeng_core:estorage_casing@0"
            ]
        },
        {
            "x": -8,
            "y": -2,
            "z": 6,
            "elements": [
                "minecraft:end_rod@2"
            ]
        },
        {
            "x": 11,
            "y": -3,
            "z": 12,
            "elements": [
                "modularmachinery:blockcasing@4"
            ]
        },
        {
            "x": -11,
            "y": -3,
            "z": 0,
            "elements": [
                "minecraft:emerald_block@0"
            ]
        },
        {
            "x": 8,
            "y": -1,
            "z": 9,
            "elements": [
                "astraladditions:block_marble_wall@0"
            ]
        },
        {
            "x": -5,
            "y": -1,
            "z": 6,
            "elements": [
                "modularmachinery:blockcasing@4"
            ]
        },
        {
            "x": -3,
            "y": 1,
            "z": 3,
            "elements": [
                "modularmachinery:blockinputbus",
                "modularmachinery:blockmepatternprovider",
                "modularmachinery:blockmeiteminputbus",
                "modularmachinery:blockoutputbus",
                "modularmachinery:blockmeitemoutputbus"
            ]
        },
        {
            "x": -8,
            "y": -2,
            "z": 2,
            "elements": [
                "minecraft:diamond_block@0"
            ]
        },
        {
            "x": -1,
            "y": 0,
            "z": 6,
            "elements": [
                "chisel:laboratory@15"
            ]
        },
        {
            "x": 1,
            "y": 0,
            "z": 5,
            "elements": [
                "appliedenergistics2:smooth_sky_stone_slab@8"
            ]
        },
        {
            "x": -1,
            "y": -3,
            "z": 14,
            "elements": [
                "minecraft:emerald_block@0"
            ]
        },
        {
            "x": -8,
            "y": -3,
            "z": 9,
            "elements": [
                "astraladditions:block_marble_wall@0"
            ]
        },
        {
            "x": -5,
            "y": -2,
            "z": 6,
            "elements": [
                "astraladditions:block_marble_wall@0"
            ]
        },
        {
            "x": -5,
            "y": -3,
            "z": -8,
            "elements": [
                "novaeng_core:estorage_casing@0"
            ]
        },
        {
            "x": -8,
            "y": -1,
            "z": 9,
            "elements": [
                "astraladditions:block_marble_wall@0"
            ]
        },
        {
            "x": 11,
            "y": -4,
            "z": 12,
            "elements": [
                "astraladditions:block_marble_wall@0"
            ]
        },
        {
            "x": 8,
            "y": -2,
            "z": 2,
            "elements": [
                "minecraft:diamond_block@0"
            ]
        },
        {
            "x": -1,
            "y": 1,
            "z": 6,
            "elements": [
                "appliedenergistics2:smooth_sky_stone_slab@0"
            ]
        },
        {
            "x": 1,
            "y": 1,
            "z": 5,
            "elements": [
                "appliedenergistics2:smooth_sky_stone_stairs@3"
            ]
        },
        {
            "x": -2,
            "y": -2,
            "z": -5,
            "elements": [
                "minecraft:diamond_block@0"
            ]
        },
        {
            "x": 5,
            "y": -2,
            "z": 11,
            "elements": [
                "novaeng_core:estorage_casing@0"
            ]
        },
        {
            "x": 0,
            "y": 1,
            "z": 3,
            "elements": [
                "minecraft:stone_slab@15"
            ]
        },
        {
            "x": 1,
            "y": -1,
            "z": 8,
            "elements": [
                "minecraft:gold_block@0"
            ]
        },
        {
            "x": -8,
            "y": -2,
            "z": -2,
            "elements": [
                "novaeng_core:estorage_casing@0"
            ]
        },
        {
            "x": -11,
            "y": -3,
            "z": -5,
            "elements": [
                "novaeng_core:estorage_casing@0"
            ]
        },
        {
            "x": -8,
            "y": -2,
            "z": 9,
            "elements": [
                "modularmachinery:blockcasing@4"
            ]
        },
        {
            "x": 8,
            "y": -2,
            "z": 9,
            "elements": [
                "modularmachinery:blockcasing@4"
            ]
        },
        {
            "x": -2,
            "y": -3,
            "z": 14,
            "elements": [
                "minecraft:emerald_block@0"
            ]
        },
        {
            "x": 11,
            "y": -3,
            "z": 0,
            "elements": [
                "minecraft:emerald_block@0"
            ]
        },
        {
            "x": -4,
            "y": -1,
            "z": 7,
            "elements": [
                "avaritia:block_resource@2"
            ]
        },
        {
            "x": 0,
            "y": 2,
            "z": 3,
            "elements": [
                "extendedcrafting:table_ultimate@0"
            ]
        },
        {
            "x": 9,
            "y": -2,
            "z": -8,
            "elements": [
                "astraladditions:block_marble_wall@0"
            ]
        },
        {
            "x": 7,
            "y": -2,
            "z": -4,
            "elements": [
                "avaritia:block_resource@2"
            ]
        },
        {
            "x": -2,
            "y": -3,
            "z": -8,
            "elements": [
                "minecraft:emerald_block@0"
            ]
        },
        {
            "x": 7,
            "y": -2,
            "z": 10,
            "elements": [
                "avaritia:block_resource@2"
            ]
        },
        {
            "x": 5,
            "y": -2,
            "z": -5,
            "elements": [
                "novaeng_core:estorage_casing@0"
            ]
        },
        {
            "x": 8,
            "y": -2,
            "z": -2,
            "elements": [
                "novaeng_core:estorage_casing@0"
            ]
        },
        {
            "x": 2,
            "y": -2,
            "z": 11,
            "elements": [
                "minecraft:diamond_block@0"
            ]
        },
        {
            "x": -11,
            "y": -3,
            "z": 11,
            "elements": [
                "novaeng_core:estorage_casing@0"
            ]
        },
        {
            "x": -3,
            "y": 0,
            "z": 3,
            "elements": [
                "chisel:laboratory@15"
            ]
        },
        {
            "x": 8,
            "y": -3,
            "z": 9,
            "elements": [
                "astraladditions:block_marble_wall@0"
            ]
        },
        {
            "x": 11,
            "y": -2,
            "z": 12,
            "elements": [
                "astraladditions:block_marble_wall@0"
            ]
        },
        {
            "x": -11,
            "y": -3,
            "z": 1,
            "elements": [
                "minecraft:emerald_block@0"
            ]
        },
        {
            "x": -1,
            "y": 1,
            "z": 3,
            "elements": [
                "astraladditions:block_marble_wall@0"
            ]
        },
        {
            "x": -3,
            "y": -1,
            "z": 3,
            "elements": [
                "appliedenergistics2:smooth_sky_stone_slab@8"
            ]
        },
        {
            "x": 3,
            "y": 0,
            "z": 1,
            "elements": [
                "modularmachinery:blockcasing@4"
            ]
        },
        {
            "x": 5,
            "y": -1,
            "z": 0,
            "elements": [
                "modularmachinery:blockcasing@4"
            ]
        },
        {
            "x": -4,
            "y": -1,
            "z": -1,
            "elements": [
                "avaritia:block_resource@2"
            ]
        },
        {
            "x": 2,
            "y": 1,
            "z": 4,
            "elements": [
                "appliedenergistics2:smooth_sky_stone_stairs@1"
            ]
        },
        {
            "x": 5,
            "y": -3,
            "z": 14,
            "elements": [
                "novaeng_core:estorage_casing@0"
            ]
        },
        {
            "x": 3,
            "y": -2,
            "z": 8,
            "elements": [
                "astraladditions:block_marble_wall@0"
            ]
        },
        {
            "x": 10,
            "y": -3,
            "z": 13,
            "elements": [
                "avaritia:block_resource@2"
            ]
        },
        {
            "x": -3,
            "y": -3,
            "z": -8,
            "elements": [
                "minecraft:emerald_block@0"
            ]
        },
        {
            "x": -5,
            "y": -1,
            "z": 1,
            "elements": [
                "minecraft:end_rod@3"
            ]
        },
        {
            "x": 1,
            "y": 0,
            "z": 4,
            "elements": [
                "appliedenergistics2:smooth_sky_stone_slab@8"
            ]
        },
        {
            "x": 5,
            "y": -2,
            "z": 0,
            "elements": [
                "astraladditions:block_marble_wall@0"
            ]
        },
        {
            "x": 3,
            "y": -2,
            "z": 11,
            "elements": [
                "minecraft:end_rod@4"
            ]
        },
        {
            "x": -8,
            "y": -3,
            "z": 14,
            "elements": [
                "novaeng_core:estorage_casing@0"
            ]
        },
        {
            "x": -5,
            "y": -2,
            "z": -5,
            "elements": [
                "novaeng_core:estorage_casing@0"
            ]
        },
        {
            "x": 11,
            "y": -3,
            "z": -2,
            "elements": [
                "novaeng_core:estorage_casing@0"
            ]
        },
        {
            "x": 3,
            "y": -1,
            "z": 8,
            "elements": [
                "modularmachinery:blockcasing@4"
            ]
        },
        {
            "x": -2,
            "y": 0,
            "z": 6,
            "elements": [
                "modularmachinery:blockcasing@4"
            ]
        },
        {
            "x": 1,
            "y": 1,
            "z": 4,
            "elements": [
                "ic2:resource@13"
            ]
        },
        {
            "x": -11,
            "y": -3,
            "z": 8,
            "elements": [
                "novaeng_core:estorage_casing@0"
            ]
        },
        {
            "x": -11,
            "y": -4,
            "z": -6,
            "elements": [
                "astraladditions:block_marble_wall@0"
            ]
        },
        {
            "x": 8,
            "y": -3,
            "z": 14,
            "elements": [
                "novaeng_core:estorage_casing@0"
            ]
        },
        {
            "x": 0,
            "y": 1,
            "z": 0,
            "elements": [
                "appliedenergistics2:smooth_sky_stone_slab@0"
            ]
        },
        {
            "x": -1,
            "y": -1,
            "z": 0,
            "elements": [
                "appliedenergistics2:smooth_sky_stone_slab@8"
            ]
        },
        {
            "x": -4,
            "y": -3,
            "z": -8,
            "elements": [
                "minecraft:end_rod@5"
            ]
        },
        {
            "x": 11,
            "y": -3,
            "z": -5,
            "elements": [
                "novaeng_core:estorage_casing@0"
            ]
        },
        {
            "x": -11,
            "y": -3,
            "z": -6,
            "elements": [
                "modularmachinery:blockcasing@4"
            ]
        },
        {
            "x": 11,
            "y": -3,
            "z": 1,
            "elements": [
                "minecraft:emerald_block@0"
            ]
        },
        {
            "x": 2,
            "y": 0,
            "z": 4,
            "elements": [
                "appliedenergistics2:smooth_sky_stone_slab@8"
            ]
        },
        {
            "x": 4,
            "y": -2,
            "z": 11,
            "elements": [
                "novaeng_core:estorage_casing@0"
            ]
        }
    ]}