{
    "registryname": "superelect",
    "localizedname": "§1「厘头」§5无原理§c电解器",
    "failure-action": "still",
    "requires-blueprint": false,
    "factory-only": true,
    
    "parts": [
        {
            "x": 0,
            "y": 0,
            "z": 0,
            "elements": [
                "modularmachinery:blockfactorycontroller@2"
            ]
        },
        {
            "x": -4,
            "y": 3,
            "z": 5,
            "elements": [
                "ic2:resource@13"
            ]
        },
        {
            "x": -3,
            "y": 0,
            "z": 5,
            "elements": [
                "ic2:resource@13"
            ]
        },
        {
            "x": -9,
            "y": 4,
            "z": 1,
            "elements": [
                "mekanism:basicblock@8"
            ]
        },
        {
            "x": -4,
            "y": 4,
            "z": 5,
            "elements": [
                "minecraft:quartz_stairs@2"
            ]
        },
        {
            "x": -3,
            "y": 2,
            "z": 5,
            "elements": [
                "modularmachinery:blockinputbus",
                "modularmachinery:blockmepatternprovider",
                "modularmachinery:blockmeiteminputbus",
                "modularmachinery:blockoutputbus",
                "modularmachinery:blockmeitemoutputbus",
                "modularmachinery:blockfluidinputhatch",
                "modularmachinery:blockmefluidinputbus",
                "modularmachinery:blockfluidoutputhatch",
                "modularmachinery:blockmefluidoutputbus",
                "modularmachinery:blockenergyinputhatch",
                "modularmachinery:blockenergyoutputhatch"
            ]
        },
        {
            "x": -5,
            "y": 0,
            "z": 6,
            "elements": [
                "mekanism:basicblock@8"
            ]
        },
        {
            "x": -5,
            "y": 1,
            "z": 6,
            "elements": [
                "chisel:blocksteel@6"
            ]
        },
        {
            "x": -3,
            "y": 1,
            "z": 5,
            "elements": [
                "minecraft:quartz_stairs@3"
            ]
        },
        {
            "x": -9,
            "y": 5,
            "z": 1,
            "elements": [
                "mekanism:basicblock@8"
            ]
        },
        {
            "x": 1,
            "y": 0,
            "z": 0,
            "elements": [
                "minecraft:quartz_stairs@2"
            ]
        },
        {
            "x": -8,
            "y": 1,
            "z": 6,
            "elements": [
                "chisel:blocksteel@6"
            ]
        },
        {
            "x": -2,
            "y": 0,
            "z": 5,
            "elements": [
                "ic2:resource@13"
            ]
        },
        {
            "x": 2,
            "y": 5,
            "z": 1,
            "elements": [
                "mekanism:basicblock@8"
            ]
        },
        {
            "x": -5,
            "y": 4,
            "z": 5,
            "elements": [
                "minecraft:quartz_stairs@2"
            ]
        },
        {
            "x": 2,
            "y": 4,
            "z": 1,
            "elements": [
                "chisel:blocksteel@2"
            ]
        },
        {
            "x": -2,
            "y": 2,
            "z": 5,
            "elements": [
                "modularmachinery:blockinputbus",
                "modularmachinery:blockmepatternprovider",
                "modularmachinery:blockmeiteminputbus",
                "modularmachinery:blockoutputbus",
                "modularmachinery:blockmeitemoutputbus",
                "modularmachinery:blockfluidinputhatch",
                "modularmachinery:blockmefluidinputbus",
                "modularmachinery:blockfluidoutputhatch",
                "modularmachinery:blockmefluidoutputbus",
                "modularmachinery:blockenergyinputhatch",
                "modularmachinery:blockenergyoutputhatch"
            ]
        },
        {
            "x": -8,
            "y": 0,
            "z": 6,
            "elements": [
                "chisel:blocksteel@0"
            ]
        },
        {
            "x": -2,
            "y": 1,
            "z": 5,
            "elements": [
                "minecraft:quartz_stairs@3"
            ]
        },
        {
            "x": 2,
            "y": 0,
            "z": 0,
            "elements": [
                "minecraft:quartz_stairs@2"
            ]
        },
        {
            "x": 3,
            "y": 1,
            "z": 3,
            "elements": [
                "chisel:laboratory@12"
            ]
        },
        {
            "x": -9,
            "y": 2,
            "z": 4,
            "elements": [
                "minecraft:stone_slab@7"
            ]
        },
        {
            "x": 3,
            "y": 3,
            "z": 4,
            "elements": [
                "mekanism:basicblock@10"
            ]
        },
        {
            "x": -5,
            "y": 0,
            "z": 5,
            "elements": [
                "chisel:blocksteel@2"
            ]
        },
        {
            "x": -8,
            "y": 2,
            "z": 6,
            "elements": [
                "chisel:blocksteel@2"
            ]
        },
        {
            "x": 3,
            "y": 4,
            "z": 4,
            "elements": [
                "mekanismgenerators:generator@10"
            ]
        },
        {
            "x": 1,
            "y": 0,
            "z": 6,
            "elements": [
                "chisel:blocksteel@2"
            ]
        },
        {
            "x": -6,
            "y": 4,
            "z": 5,
            "elements": [
                "chisel:blocksteel@2"
            ]
        },
        {
            "x": -9,
            "y": 1,
            "z": 1,
            "elements": [
                "mekanism:basicblock@8"
            ]
        },
        {
            "x": -9,
            "y": 1,
            "z": 4,
            "elements": [
                "minecraft:stone_slab@7"
            ]
        },
        {
            "x": -5,
            "y": 1,
            "z": 5,
            "elements": [
                "minecraft:stone_slab@7"
            ]
        },
        {
            "x": 0,
            "y": 5,
            "z": 3,
            "elements": [
                "minecraft:stone_brick_stairs@2"
            ]
        },
        {
            "x": -8,
            "y": 3,
            "z": 6,
            "elements": [
                "chisel:blocksteel@2"
            ]
        },
        {
            "x": 1,
            "y": 1,
            "z": 6,
            "elements": [
                "chisel:blocksteel@6"
            ]
        },
        {
            "x": -1,
            "y": 0,
            "z": 0,
            "elements": [
                "minecraft:stone_slab@7"
            ]
        },
        {
            "x": -9,
            "y": 2,
            "z": 1,
            "elements": [
                "mekanism:basicblock@8"
            ]
        },
        {
            "x": -9,
            "y": 0,
            "z": 4,
            "elements": [
                "minecraft:stone_slab@15"
            ]
        },
        {
            "x": 0,
            "y": 0,
            "z": 5,
            "elements": [
                "chisel:blocksteel@2"
            ]
        },
        {
            "x": 0,
            "y": 4,
            "z": 3,
            "elements": [
                "minecraft:stone_slab@15"
            ]
        },
        {
            "x": -8,
            "y": 4,
            "z": 6,
            "elements": [
                "mekanismgenerators:generator@10"
            ]
        },
        {
            "x": -3,
            "y": 4,
            "z": 5,
            "elements": [
                "minecraft:quartz_stairs@2"
            ]
        },
        {
            "x": 3,
            "y": 0,
            "z": 3,
            "elements": [
                "chisel:blocksteel@0"
            ]
        },
        {
            "x": -8,
            "y": 5,
            "z": 6,
            "elements": [
                "mekanism:basicblock@8"
            ]
        },
        {
            "x": -9,
            "y": 0,
            "z": 1,
            "elements": [
                "mekanism:basicblock@8"
            ]
        },
        {
            "x": 3,
            "y": 5,
            "z": 4,
            "elements": [
                "minecraft:stone_slab@15"
            ]
        },
        {
            "x": -9,
            "y": 3,
            "z": 1,
            "elements": [
                "mekanism:basicblock@8"
            ]
        },
        {
            "x": -3,
            "y": 3,
            "z": 5,
            "elements": [
                "minecraft:quartz_block@0"
            ]
        },
        {
            "x": -6,
            "y": 5,
            "z": 5,
            "elements": [
                "minecraft:stone_slab@7"
            ]
        },
        {
            "x": 0,
            "y": 1,
            "z": 5,
            "elements": [
                "minecraft:stone_slab@7"
            ]
        },
        {
            "x": -6,
            "y": 5,
            "z": 4,
            "elements": [
                "chisel:laboratory@12"
            ]
        },
        {
            "x": -7,
            "y": 0,
            "z": 5,
            "elements": [
                "chisel:blocksteel@2"
            ]
        },
        {
            "x": 1,
            "y": 4,
            "z": 6,
            "elements": [
                "chisel:blocksteel@2"
            ]
        },
        {
            "x": 0,
            "y": 4,
            "z": 5,
            "elements": [
                "minecraft:quartz_stairs@2"
            ]
        },
        {
            "x": 3,
            "y": 2,
            "z": 7,
            "elements": [
                "mekanismgenerators:generator@10"
            ]
        },
        {
            "x": 4,
            "y": 5,
            "z": 6,
            "elements": [
                "mekanism:basicblock@8"
            ]
        },
        {
            "x": -3,
            "y": 4,
            "z": 4,
            "elements": [
                "minecraft:stone_slab@15"
            ]
        },
        {
            "x": -7,
            "y": 1,
            "z": 5,
            "elements": [
                "minecraft:quartz_stairs@1"
            ]
        },
        {
            "x": 4,
            "y": 4,
            "z": 6,
            "elements": [
                "mekanism:basicblock@8"
            ]
        },
        {
            "x": -8,
            "y": 0,
            "z": 3,
            "elements": [
                "chisel:blocksteel@0"
            ]
        },
        {
            "x": 3,
            "y": 0,
            "z": 4,
            "elements": [
                "chisel:blocksteel@0"
            ]
        },
        {
            "x": 3,
            "y": 3,
            "z": 7,
            "elements": [
                "mekanismgenerators:generator@10"
            ]
        },
        {
            "x": 1,
            "y": 2,
            "z": 6,
            "elements": [
                "mekanism:basicblock@10"
            ]
        },
        {
            "x": 3,
            "y": 4,
            "z": 7,
            "elements": [
                "mekanismgenerators:generator@10"
            ]
        },
        {
            "x": -9,
            "y": 3,
            "z": 3,
            "elements": [
                "minecraft:stone_slab@7"
            ]
        },
        {
            "x": -3,
            "y": 5,
            "z": 4,
            "elements": [
                "minecraft:stone_brick_stairs@3"
            ]
        },
        {
            "x": -3,
            "y": 0,
            "z": 4,
            "elements": [
                "chisel:blocksteel@2"
            ]
        },
        {
            "x": -8,
            "y": 1,
            "z": 3,
            "elements": [
                "chisel:laboratory@12"
            ]
        },
        {
            "x": -1,
            "y": 4,
            "z": 5,
            "elements": [
                "minecraft:quartz_stairs@2"
            ]
        },
        {
            "x": 3,
            "y": 2,
            "z": 4,
            "elements": [
                "mekanism:basicblock@10"
            ]
        },
        {
            "x": 3,
            "y": 1,
            "z": 4,
            "elements": [
                "chisel:laboratory@12"
            ]
        },
        {
            "x": 3,
            "y": 2,
            "z": 3,
            "elements": [
                "mekanism:basicblock@10"
            ]
        },
        {
            "x": 2,
            "y": 0,
            "z": 5,
            "elements": [
                "chisel:blocksteel@2"
            ]
        },
        {
            "x": 4,
            "y": 0,
            "z": 6,
            "elements": [
                "mekanism:basicblock@8"
            ]
        },
        {
            "x": 4,
            "y": 1,
            "z": 6,
            "elements": [
                "mekanism:basicblock@8"
            ]
        },
        {
            "x": -9,
            "y": 4,
            "z": 3,
            "elements": [
                "minecraft:stone_slab@7"
            ]
        },
        {
            "x": 1,
            "y": 3,
            "z": 6,
            "elements": [
                "mekanism:basicblock@10"
            ]
        },
        {
            "x": 0,
            "y": 0,
            "z": 4,
            "elements": [
                "chisel:blocksteel@2"
            ]
        },
        {
            "x": -8,
            "y": 2,
            "z": 3,
            "elements": [
                "mekanism:basicblock@10"
            ]
        },
        {
            "x": -6,
            "y": 4,
            "z": 4,
            "elements": [
                "minecraft:stone_slab@15"
            ]
        },
        {
            "x": 2,
            "y": 1,
            "z": 5,
            "elements": [
                "minecraft:quartz_stairs@0"
            ]
        },
        {
            "x": -2,
            "y": 0,
            "z": 0,
            "elements": [
                "minecraft:stone_slab@7"
            ]
        },
        {
            "x": -1,
            "y": 3,
            "z": 5,
            "elements": [
                "ic2:resource@13"
            ]
        },
        {
            "x": -8,
            "y": 4,
            "z": 0,
            "elements": [
                "mekanismgenerators:generator@10"
            ]
        },
        {
            "x": -6,
            "y": 0,
            "z": 4,
            "elements": [
                "chisel:blocksteel@2"
            ]
        },
        {
            "x": 4,
            "y": 2,
            "z": 6,
            "elements": [
                "mekanism:basicblock@8"
            ]
        },
        {
            "x": 3,
            "y": 4,
            "z": 3,
            "elements": [
                "mekanismgenerators:generator@10"
            ]
        },
        {
            "x": -9,
            "y": 3,
            "z": 4,
            "elements": [
                "minecraft:stone_slab@7"
            ]
        },
        {
            "x": -1,
            "y": 0,
            "z": 5,
            "elements": [
                "chisel:blocksteel@2"
            ]
        },
        {
            "x": -6,
            "y": 2,
            "z": 1,
            "elements": [
                "mekanism:basicblock@10"
            ]
        },
        {
            "x": -9,
            "y": 1,
            "z": 3,
            "elements": [
                "minecraft:stone_slab@7"
            ]
        },
        {
            "x": -8,
            "y": 3,
            "z": 0,
            "elements": [
                "mekanismgenerators:generator@10"
            ]
        },
        {
            "x": -1,
            "y": 2,
            "z": 5,
            "elements": [
                "ic2:resource@13"
            ]
        },
        {
            "x": 4,
            "y": 3,
            "z": 6,
            "elements": [
                "mekanism:basicblock@8"
            ]
        },
        {
            "x": 3,
            "y": 0,
            "z": 7,
            "elements": [
                "chisel:blocksteel@0"
            ]
        },
        {
            "x": -1,
            "y": 1,
            "z": 5,
            "elements": [
                "mekanism:basicblock@8"
            ]
        },
        {
            "x": 3,
            "y": 3,
            "z": 3,
            "elements": [
                "mekanism:basicblock@10"
            ]
        },
        {
            "x": -5,
            "y": 0,
            "z": 0,
            "elements": [
                "modularmachinery:blockinputbus",
                "modularmachinery:blockmepatternprovider",
                "modularmachinery:blockmeiteminputbus",
                "modularmachinery:blockoutputbus",
                "modularmachinery:blockmeitemoutputbus",
                "modularmachinery:blockfluidinputhatch",
                "modularmachinery:blockmefluidinputbus",
                "modularmachinery:blockfluidoutputhatch",
                "modularmachinery:blockmefluidoutputbus",
                "modularmachinery:blockenergyinputhatch",
                "modularmachinery:blockenergyoutputhatch"
            ]
        },
        {
            "x": 0,
            "y": 5,
            "z": 4,
            "elements": [
                "minecraft:stone_brick_stairs@3"
            ]
        },
        {
            "x": -9,
            "y": 2,
            "z": 3,
            "elements": [
                "minecraft:stone_slab@7"
            ]
        },
        {
            "x": -9,
            "y": 4,
            "z": 4,
            "elements": [
                "minecraft:stone_slab@7"
            ]
        },
        {
            "x": -7,
            "y": 5,
            "z": 5,
            "elements": [
                "minecraft:stone_slab@7"
            ]
        },
        {
            "x": -6,
            "y": 3,
            "z": 1,
            "elements": [
                "mekanism:basicblock@10"
            ]
        },
        {
            "x": 3,
            "y": 2,
            "z": 6,
            "elements": [
                "chisel:blocksteel@2"
            ]
        },
        {
            "x": -6,
            "y": 0,
            "z": 1,
            "elements": [
                "chisel:blocksteel@2"
            ]
        },
        {
            "x": -4,
            "y": 0,
            "z": 5,
            "elements": [
                "chisel:blocksteel@2"
            ]
        },
        {
            "x": -8,
            "y": 1,
            "z": 7,
            "elements": [
                "mekanismgenerators:generator@10"
            ]
        },
        {
            "x": 3,
            "y": 5,
            "z": 6,
            "elements": [
                "mekanism:basicblock@8"
            ]
        },
        {
            "x": -4,
            "y": 2,
            "z": 5,
            "elements": [
                "ic2:resource@13"
            ]
        },
        {
            "x": -7,
            "y": 4,
            "z": 5,
            "elements": [
                "chisel:blocksteel@2"
            ]
        },
        {
            "x": -6,
            "y": 1,
            "z": 1,
            "elements": [
                "chisel:blocksteel@6"
            ]
        },
        {
            "x": 3,
            "y": 5,
            "z": 3,
            "elements": [
                "minecraft:stone_slab@15"
            ]
        },
        {
            "x": 3,
            "y": 3,
            "z": 6,
            "elements": [
                "chisel:blocksteel@2"
            ]
        },
        {
            "x": 0,
            "y": 4,
            "z": 4,
            "elements": [
                "minecraft:stone_slab@15"
            ]
        },
        {
            "x": 3,
            "y": 4,
            "z": 6,
            "elements": [
                "mekanismgenerators:generator@10"
            ]
        },
        {
            "x": 3,
            "y": 1,
            "z": 7,
            "elements": [
                "mekanismgenerators:generator@10"
            ]
        },
        {
            "x": -4,
            "y": 1,
            "z": 5,
            "elements": [
                "mekanism:basicblock@8"
            ]
        },
        {
            "x": -8,
            "y": 0,
            "z": 7,
            "elements": [
                "chisel:blocksteel@0"
            ]
        },
        {
            "x": -9,
            "y": 0,
            "z": 3,
            "elements": [
                "minecraft:stone_slab@15"
            ]
        },
        {
            "x": -2,
            "y": 5,
            "z": 4,
            "elements": [
                "minecraft:stone_brick_stairs@3"
            ]
        },
        {
            "x": -4,
            "y": 0,
            "z": 4,
            "elements": [
                "chisel:blocksteel@2"
            ]
        },
        {
            "x": 2,
            "y": 1,
            "z": 2,
            "elements": [
                "minecraft:quartz_stairs@0"
            ]
        },
        {
            "x": 1,
            "y": 4,
            "z": 3,
            "elements": [
                "minecraft:stone_slab@15"
            ]
        },
        {
            "x": -4,
            "y": 1,
            "z": 4,
            "elements": [
                "mekanism:basicblock@8"
            ]
        },
        {
            "x": -8,
            "y": 1,
            "z": 0,
            "elements": [
                "mekanismgenerators:generator@10"
            ]
        },
        {
            "x": 4,
            "y": 2,
            "z": 3,
            "elements": [
                "minecraft:stone_slab@7"
            ]
        },
        {
            "x": 4,
            "y": 0,
            "z": 3,
            "elements": [
                "minecraft:stone_slab@15"
            ]
        },
        {
            "x": 3,
            "y": 5,
            "z": 5,
            "elements": [
                "minecraft:quartz_stairs@3"
            ]
        },
        {
            "x": -7,
            "y": 0,
            "z": 0,
            "elements": [
                "minecraft:quartz_stairs@2"
            ]
        },
        {
            "x": -1,
            "y": 0,
            "z": 4,
            "elements": [
                "chisel:blocksteel@2"
            ]
        },
        {
            "x": 4,
            "y": 1,
            "z": 3,
            "elements": [
                "minecraft:stone_slab@7"
            ]
        },
        {
            "x": -2,
            "y": 5,
            "z": 3,
            "elements": [
                "minecraft:stone_brick_stairs@2"
            ]
        },
        {
            "x": -7,
            "y": 4,
            "z": 4,
            "elements": [
                "minecraft:stone_slab@15"
            ]
        },
        {
            "x": -8,
            "y": 2,
            "z": 0,
            "elements": [
                "mekanismgenerators:generator@10"
            ]
        },
        {
            "x": 2,
            "y": 0,
            "z": 2,
            "elements": [
                "chisel:blocksteel@2"
            ]
        },
        {
            "x": -7,
            "y": 5,
            "z": 2,
            "elements": [
                "minecraft:stone_slab@7"
            ]
        },
        {
            "x": -7,
            "y": 5,
            "z": 4,
            "elements": [
                "chisel:laboratory@12"
            ]
        },
        {
            "x": 3,
            "y": 4,
            "z": 5,
            "elements": [
                "mekanismgenerators:generator@10"
            ]
        },
        {
            "x": -1,
            "y": 1,
            "z": 4,
            "elements": [
                "mekanism:basicblock@8"
            ]
        },
        {
            "x": -2,
            "y": 4,
            "z": 3,
            "elements": [
                "minecraft:stone_slab@15"
            ]
        },
        {
            "x": -2,
            "y": 4,
            "z": 4,
            "elements": [
                "minecraft:stone_slab@15"
            ]
        },
        {
            "x": 1,
            "y": 0,
            "z": 3,
            "elements": [
                "chisel:blocksteel@2"
            ]
        },
        {
            "x": 1,
            "y": 5,
            "z": 3,
            "elements": [
                "chisel:laboratory@12"
            ]
        },
        {
            "x": 3,
            "y": 3,
            "z": 5,
            "elements": [
                "chisel:blocksteel@2"
            ]
        },
        {
            "x": -7,
            "y": 4,
            "z": 2,
            "elements": [
                "chisel:blocksteel@2"
            ]
        },
        {
            "x": 3,
            "y": 1,
            "z": 5,
            "elements": [
                "chisel:laboratory@12"
            ]
        },
        {
            "x": -4,
            "y": 5,
            "z": 4,
            "elements": [
                "minecraft:stone_brick_stairs@3"
            ]
        },
        {
            "x": -8,
            "y": 3,
            "z": 3,
            "elements": [
                "mekanism:basicblock@10"
            ]
        },
        {
            "x": -2,
            "y": 1,
            "z": 4,
            "elements": [
                "mekanism:basicblock@8"
            ]
        },
        {
            "x": 2,
            "y": 4,
            "z": 5,
            "elements": [
                "chisel:blocksteel@2"
            ]
        },
        {
            "x": 3,
            "y": 2,
            "z": 5,
            "elements": [
                "chisel:blocksteel@2"
            ]
        },
        {
            "x": 3,
            "y": 0,
            "z": 5,
            "elements": [
                "chisel:blocksteel@0"
            ]
        },
        {
            "x": -8,
            "y": 4,
            "z": 3,
            "elements": [
                "mekanismgenerators:generator@10"
            ]
        },
        {
            "x": -5,
            "y": 4,
            "z": 4,
            "elements": [
                "minecraft:stone_slab@15"
            ]
        },
        {
            "x": 2,
            "y": 4,
            "z": 2,
            "elements": [
                "chisel:blocksteel@2"
            ]
        },
        {
            "x": -6,
            "y": 0,
            "z": 3,
            "elements": [
                "chisel:blocksteel@2"
            ]
        },
        {
            "x": -5,
            "y": 5,
            "z": 4,
            "elements": [
                "minecraft:stone_brick_stairs@3"
            ]
        },
        {
            "x": -8,
            "y": 5,
            "z": 3,
            "elements": [
                "minecraft:stone_slab@15"
            ]
        },
        {
            "x": -3,
            "y": 1,
            "z": 4,
            "elements": [
                "mekanism:basicblock@8"
            ]
        },
        {
            "x": -1,
            "y": 4,
            "z": 2,
            "elements": [
                "minecraft:quartz_stairs@3"
            ]
        },
        {
            "x": -4,
            "y": 4,
            "z": 4,
            "elements": [
                "minecraft:stone_slab@15"
            ]
        },
        {
            "x": 2,
            "y": 5,
            "z": 5,
            "elements": [
                "minecraft:stone_slab@7"
            ]
        },
        {
            "x": -5,
            "y": 0,
            "z": 3,
            "elements": [
                "chisel:blocksteel@2"
            ]
        },
        {
            "x": -2,
            "y": 0,
            "z": 4,
            "elements": [
                "chisel:blocksteel@2"
            ]
        },
        {
            "x": 2,
            "y": 5,
            "z": 2,
            "elements": [
                "minecraft:stone_slab@7"
            ]
        },
        {
            "x": -4,
            "y": 0,
            "z": 0,
            "elements": [
                "minecraft:stone_slab@7"
            ]
        },
        {
            "x": -9,
            "y": 2,
            "z": 2,
            "elements": [
                "minecraft:stone_slab@7"
            ]
        },
        {
            "x": -8,
            "y": 0,
            "z": 4,
            "elements": [
                "chisel:blocksteel@0"
            ]
        },
        {
            "x": -3,
            "y": 1,
            "z": 3,
            "elements": [
                "mekanism:basicblock@8"
            ]
        },
        {
            "x": -3,
            "y": 4,
            "z": 3,
            "elements": [
                "minecraft:stone_slab@15"
            ]
        },
        {
            "x": -9,
            "y": 3,
            "z": 2,
            "elements": [
                "minecraft:stone_slab@7"
            ]
        },
        {
            "x": -6,
            "y": 4,
            "z": 3,
            "elements": [
                "minecraft:stone_slab@15"
            ]
        },
        {
            "x": 0,
            "y": 0,
            "z": 3,
            "elements": [
                "chisel:blocksteel@2"
            ]
        },
        {
            "x": 2,
            "y": 5,
            "z": 4,
            "elements": [
                "chisel:laboratory@12"
            ]
        },
        {
            "x": -6,
            "y": 5,
            "z": 3,
            "elements": [
                "chisel:laboratory@12"
            ]
        },
        {
            "x": -8,
            "y": 2,
            "z": 4,
            "elements": [
                "mekanism:basicblock@10"
            ]
        },
        {
            "x": -9,
            "y": 0,
            "z": 2,
            "elements": [
                "chisel:blocksteel@6"
            ]
        },
        {
            "x": -6,
            "y": 0,
            "z": 5,
            "elements": [
                "chisel:blocksteel@2"
            ]
        },
        {
            "x": -9,
            "y": 3,
            "z": 5,
            "elements": [
                "minecraft:stone_slab@7"
            ]
        },
        {
            "x": -9,
            "y": 4,
            "z": 5,
            "elements": [
                "minecraft:stone_slab@7"
            ]
        },
        {
            "x": -8,
            "y": 1,
            "z": 4,
            "elements": [
                "chisel:laboratory@12"
            ]
        },
        {
            "x": 2,
            "y": 4,
            "z": 4,
            "elements": [
                "minecraft:stone_slab@15"
            ]
        },
        {
            "x": -6,
            "y": 1,
            "z": 5,
            "elements": [
                "minecraft:stone_slab@7"
            ]
        },
        {
            "x": -9,
            "y": 1,
            "z": 2,
            "elements": [
                "chisel:blocksteel@6"
            ]
        },
        {
            "x": -3,
            "y": 5,
            "z": 3,
            "elements": [
                "minecraft:stone_brick_stairs@2"
            ]
        },
        {
            "x": -3,
            "y": 0,
            "z": 3,
            "elements": [
                "chisel:blocksteel@2"
            ]
        },
        {
            "x": -8,
            "y": 5,
            "z": 4,
            "elements": [
                "minecraft:stone_slab@15"
            ]
        },
        {
            "x": -9,
            "y": 0,
            "z": 5,
            "elements": [
                "chisel:blocksteel@6"
            ]
        },
        {
            "x": -1,
            "y": 1,
            "z": 3,
            "elements": [
                "mekanism:basicblock@8"
            ]
        },
        {
            "x": -5,
            "y": 4,
            "z": 3,
            "elements": [
                "minecraft:stone_slab@15"
            ]
        },
        {
            "x": 2,
            "y": 1,
            "z": 4,
            "elements": [
                "minecraft:stone_slab@7"
            ]
        },
        {
            "x": -9,
            "y": 1,
            "z": 5,
            "elements": [
                "chisel:blocksteel@6"
            ]
        },
        {
            "x": -1,
            "y": 4,
            "z": 4,
            "elements": [
                "minecraft:stone_slab@15"
            ]
        },
        {
            "x": 1,
            "y": 0,
            "z": 4,
            "elements": [
                "chisel:blocksteel@2"
            ]
        },
        {
            "x": -9,
            "y": 2,
            "z": 5,
            "elements": [
                "minecraft:stone_slab@7"
            ]
        },
        {
            "x": -2,
            "y": 0,
            "z": 3,
            "elements": [
                "chisel:blocksteel@2"
            ]
        },
        {
            "x": -4,
            "y": 5,
            "z": 3,
            "elements": [
                "minecraft:stone_brick_stairs@2"
            ]
        },
        {
            "x": -5,
            "y": 0,
            "z": 4,
            "elements": [
                "chisel:blocksteel@2"
            ]
        },
        {
            "x": -7,
            "y": 0,
            "z": 2,
            "elements": [
                "chisel:blocksteel@2"
            ]
        },
        {
            "x": -1,
            "y": 5,
            "z": 4,
            "elements": [
                "minecraft:stone_brick_stairs@3"
            ]
        },
        {
            "x": -2,
            "y": 1,
            "z": 3,
            "elements": [
                "mekanism:basicblock@8"
            ]
        },
        {
            "x": -8,
            "y": 3,
            "z": 4,
            "elements": [
                "mekanism:basicblock@10"
            ]
        },
        {
            "x": -4,
            "y": 4,
            "z": 3,
            "elements": [
                "minecraft:stone_slab@15"
            ]
        },
        {
            "x": -7,
            "y": 1,
            "z": 2,
            "elements": [
                "minecraft:quartz_stairs@1"
            ]
        },
        {
            "x": -1,
            "y": 0,
            "z": 3,
            "elements": [
                "chisel:blocksteel@2"
            ]
        },
        {
            "x": -5,
            "y": 5,
            "z": 3,
            "elements": [
                "minecraft:stone_brick_stairs@2"
            ]
        },
        {
            "x": 2,
            "y": 0,
            "z": 4,
            "elements": [
                "minecraft:stone_slab@15"
            ]
        },
        {
            "x": -8,
            "y": 4,
            "z": 4,
            "elements": [
                "mekanismgenerators:generator@10"
            ]
        },
        {
            "x": -8,
            "y": 2,
            "z": 1,
            "elements": [
                "chisel:blocksteel@2"
            ]
        },
        {
            "x": 3,
            "y": 3,
            "z": 2,
            "elements": [
                "chisel:blocksteel@2"
            ]
        },
        {
            "x": 4,
            "y": 1,
            "z": 4,
            "elements": [
                "minecraft:stone_slab@7"
            ]
        },
        {
            "x": 2,
            "y": 2,
            "z": 6,
            "elements": [
                "mekanism:basicblock@10"
            ]
        },
        {
            "x": -6,
            "y": 0,
            "z": 2,
            "elements": [
                "chisel:blocksteel@2"
            ]
        },
        {
            "x": -7,
            "y": 1,
            "z": 3,
            "elements": [
                "minecraft:stone_slab@7"
            ]
        },
        {
            "x": 4,
            "y": 2,
            "z": 4,
            "elements": [
                "minecraft:stone_slab@7"
            ]
        },
        {
            "x": 3,
            "y": 2,
            "z": 2,
            "elements": [
                "chisel:blocksteel@2"
            ]
        },
        {
            "x": 2,
            "y": 3,
            "z": 6,
            "elements": [
                "mekanism:basicblock@10"
            ]
        },
        {
            "x": -6,
            "y": 1,
            "z": 2,
            "elements": [
                "minecraft:stone_slab@7"
            ]
        },
        {
            "x": 1,
            "y": 4,
            "z": 4,
            "elements": [
                "minecraft:stone_slab@15"
            ]
        },
        {
            "x": -7,
            "y": 1,
            "z": 4,
            "elements": [
                "minecraft:stone_slab@7"
            ]
        },
        {
            "x": 0,
            "y": 4,
            "z": 2,
            "elements": [
                "minecraft:quartz_stairs@3"
            ]
        },
        {
            "x": -4,
            "y": 0,
            "z": 3,
            "elements": [
                "chisel:blocksteel@2"
            ]
        },
        {
            "x": -7,
            "y": 0,
            "z": 7,
            "elements": [
                "minecraft:quartz_stairs@3"
            ]
        },
        {
            "x": -8,
            "y": 3,
            "z": 1,
            "elements": [
                "chisel:blocksteel@2"
            ]
        },
        {
            "x": -7,
            "y": 0,
            "z": 4,
            "elements": [
                "minecraft:stone_slab@15"
            ]
        },
        {
            "x": -4,
            "y": 1,
            "z": 3,
            "elements": [
                "mekanism:basicblock@8"
            ]
        },
        {
            "x": -8,
            "y": 0,
            "z": 1,
            "elements": [
                "chisel:blocksteel@0"
            ]
        },
        {
            "x": 3,
            "y": 1,
            "z": 2,
            "elements": [
                "chisel:laboratory@12"
            ]
        },
        {
            "x": 2,
            "y": 0,
            "z": 7,
            "elements": [
                "minecraft:quartz_stairs@3"
            ]
        },
        {
            "x": -8,
            "y": 1,
            "z": 1,
            "elements": [
                "chisel:blocksteel@6"
            ]
        },
        {
            "x": 1,
            "y": 4,
            "z": 2,
            "elements": [
                "chisel:blocksteel@2"
            ]
        },
        {
            "x": 1,
            "y": 5,
            "z": 4,
            "elements": [
                "chisel:laboratory@12"
            ]
        },
        {
            "x": -7,
            "y": 0,
            "z": 3,
            "elements": [
                "minecraft:stone_slab@15"
            ]
        },
        {
            "x": 4,
            "y": 0,
            "z": 4,
            "elements": [
                "minecraft:stone_slab@15"
            ]
        },
        {
            "x": -7,
            "y": 5,
            "z": 3,
            "elements": [
                "chisel:laboratory@12"
            ]
        },
        {
            "x": 3,
            "y": 0,
            "z": 2,
            "elements": [
                "chisel:blocksteel@0"
            ]
        },
        {
            "x": -6,
            "y": 5,
            "z": 2,
            "elements": [
                "minecraft:stone_slab@7"
            ]
        },
        {
            "x": -1,
            "y": 4,
            "z": 6,
            "elements": [
                "minecraft:quartz_stairs@3"
            ]
        },
        {
            "x": -3,
            "y": 3,
            "z": 2,
            "elements": [
                "minecraft:quartz_block"
            ]
        },
        {
            "x": 0,
            "y": 1,
            "z": 2,
            "elements": [
                "minecraft:stone_slab@7"
            ]
        },
        {
            "x": -1,
            "y": 4,
            "z": 3,
            "elements": [
                "minecraft:stone_slab@15"
            ]
        },
        {
            "x": -1,
            "y": 0,
            "z": 7,
            "elements": [
                "minecraft:stone_slab@7"
            ]
        },
        {
            "x": 2,
            "y": 0,
            "z": 3,
            "elements": [
                "minecraft:stone_slab@15"
            ]
        },
        {
            "x": -6,
            "y": 4,
            "z": 2,
            "elements": [
                "chisel:blocksteel@2"
            ]
        },
        {
            "x": 0,
            "y": 0,
            "z": 2,
            "elements": [
                "chisel:blocksteel@2"
            ]
        },
        {
            "x": -3,
            "y": 2,
            "z": 2,
            "elements": [
                "modularmachinery:blockinputbus",
                "modularmachinery:blockmepatternprovider",
                "modularmachinery:blockmeiteminputbus",
                "modularmachinery:blockoutputbus",
                "modularmachinery:blockmeitemoutputbus",
                "modularmachinery:blockfluidinputhatch",
                "modularmachinery:blockmefluidinputbus",
                "modularmachinery:blockfluidoutputhatch",
                "modularmachinery:blockmefluidoutputbus",
                "modularmachinery:blockenergyinputhatch",
                "modularmachinery:blockenergyoutputhatch"
            ]
        },
        {
            "x": -3,
            "y": 0,
            "z": 2,
            "elements": [
                "ic2:resource@13"
            ]
        },
        {
            "x": 2,
            "y": 1,
            "z": 3,
            "elements": [
                "minecraft:stone_slab@7"
            ]
        },
        {
            "x": 4,
            "y": 3,
            "z": 4,
            "elements": [
                "minecraft:stone_slab@7"
            ]
        },
        {
            "x": -1,
            "y": 2,
            "z": 6,
            "elements": [
                "minecraft:quartz_stairs@7"
            ]
        },
        {
            "x": 4,
            "y": 4,
            "z": 4,
            "elements": [
                "minecraft:stone_slab@7"
            ]
        },
        {
            "x": 2,
            "y": 0,
            "z": 6,
            "elements": [
                "chisel:blocksteel@2"
            ]
        },
        {
            "x": -3,
            "y": 1,
            "z": 2,
            "elements": [
                "minecraft:quartz_stairs@2"
            ]
        },
        {
            "x": 4,
            "y": 5,
            "z": 1,
            "elements": [
                "mekanism:basicblock@8"
            ]
        },
        {
            "x": 4,
            "y": 4,
            "z": 1,
            "elements": [
                "mekanism:basicblock@8"
            ]
        },
        {
            "x": -1,
            "y": 3,
            "z": 6,
            "elements": [
                "chisel:technical1@1"
            ]
        },
        {
            "x": -7,
            "y": 4,
            "z": 3,
            "elements": [
                "minecraft:stone_slab@15"
            ]
        },
        {
            "x": -1,
            "y": 5,
            "z": 3,
            "elements": [
                "minecraft:stone_brick_stairs@2"
            ]
        },
        {
            "x": -9,
            "y": 4,
            "z": 2,
            "elements": [
                "minecraft:stone_slab@7"
            ]
        },
        {
            "x": 2,
            "y": 1,
            "z": 6,
            "elements": [
                "chisel:blocksteel@6"
            ]
        },
        {
            "x": -4,
            "y": 0,
            "z": 7,
            "elements": [
                "minecraft:stone_slab@7"
            ]
        },
        {
            "x": 4,
            "y": 3,
            "z": 1,
            "elements": [
                "mekanism:basicblock@8"
            ]
        },
        {
            "x": -2,
            "y": 0,
            "z": 2,
            "elements": [
                "ic2:resource@13"
            ]
        },
        {
            "x": -9,
            "y": 1,
            "z": 6,
            "elements": [
                "mekanism:basicblock@8"
            ]
        },
        {
            "x": -1,
            "y": 3,
            "z": 2,
            "elements": [
                "ic2:resource@13"
            ]
        },
        {
            "x": -5,
            "y": 4,
            "z": 1,
            "elements": [
                "minecraft:quartz_stairs@2"
            ]
        },
        {
            "x": -2,
            "y": 1,
            "z": 2,
            "elements": [
                "minecraft:quartz_stairs@2"
            ]
        },
        {
            "x": 1,
            "y": 0,
            "z": 1,
            "elements": [
                "chisel:blocksteel@2"
            ]
        },
        {
            "x": -4,
            "y": 4,
            "z": 2,
            "elements": [
                "minecraft:quartz_stairs@3"
            ]
        },
        {
            "x": -9,
            "y": 0,
            "z": 6,
            "elements": [
                "mekanism:basicblock@8"
            ]
        },
        {
            "x": 4,
            "y": 2,
            "z": 1,
            "elements": [
                "mekanism:basicblock@8"
            ]
        },
        {
            "x": 2,
            "y": 5,
            "z": 3,
            "elements": [
                "chisel:laboratory@12"
            ]
        },
        {
            "x": -1,
            "y": 2,
            "z": 2,
            "elements": [
                "ic2:resource@13"
            ]
        },
        {
            "x": 1,
            "y": 1,
            "z": 1,
            "elements": [
                "chisel:blocksteel@6"
            ]
        },
        {
            "x": 1,
            "y": 3,
            "z": 1,
            "elements": [
                "mekanism:basicblock@10"
            ]
        },
        {
            "x": 4,
            "y": 0,
            "z": 1,
            "elements": [
                "mekanism:basicblock@8"
            ]
        },
        {
            "x": -2,
            "y": 3,
            "z": 2,
            "elements": [
                "minecraft:quartz_block"
            ]
        },
        {
            "x": 1,
            "y": 2,
            "z": 1,
            "elements": [
                "mekanism:basicblock@10"
            ]
        },
        {
            "x": 2,
            "y": 4,
            "z": 3,
            "elements": [
                "minecraft:stone_slab@15"
            ]
        },
        {
            "x": -1,
            "y": 1,
            "z": 2,
            "elements": [
                "mekanism:basicblock@8"
            ]
        },
        {
            "x": -3,
            "y": 4,
            "z": 2,
            "elements": [
                "minecraft:quartz_stairs@3"
            ]
        },
        {
            "x": -2,
            "y": 4,
            "z": 1,
            "elements": [
                "minecraft:stone_slab@7"
            ]
        },
        {
            "x": 4,
            "y": 1,
            "z": 1,
            "elements": [
                "mekanism:basicblock@8"
            ]
        },
        {
            "x": -2,
            "y": 2,
            "z": 2,
            "elements": [
                "modularmachinery:blockinputbus",
                "modularmachinery:blockmepatternprovider",
                "modularmachinery:blockmeiteminputbus",
                "modularmachinery:blockoutputbus",
                "modularmachinery:blockmeitemoutputbus",
                "modularmachinery:blockfluidinputhatch",
                "modularmachinery:blockmefluidinputbus",
                "modularmachinery:blockfluidoutputhatch",
                "modularmachinery:blockmefluidoutputbus",
                "modularmachinery:blockenergyinputhatch",
                "modularmachinery:blockenergyoutputhatch"
            ]
        },
        {
            "x": -1,
            "y": 0,
            "z": 2,
            "elements": [
                "chisel:blocksteel@2"
            ]
        },
        {
            "x": -4,
            "y": 0,
            "z": 2,
            "elements": [
                "chisel:blocksteel@2"
            ]
        },
        {
            "x": -5,
            "y": 0,
            "z": 1,
            "elements": [
                "mekanism:basicblock@8"
            ]
        },
        {
            "x": 2,
            "y": 5,
            "z": 6,
            "elements": [
                "mekanism:basicblock@8"
            ]
        },
        {
            "x": -5,
            "y": 1,
            "z": 1,
            "elements": [
                "chisel:blocksteel@6"
            ]
        },
        {
            "x": -2,
            "y": 4,
            "z": 2,
            "elements": [
                "minecraft:quartz_stairs@3"
            ]
        },
        {
            "x": 1,
            "y": 4,
            "z": 1,
            "elements": [
                "chisel:blocksteel@2"
            ]
        },
        {
            "x": -4,
            "y": 1,
            "z": 2,
            "elements": [
                "mekanism:basicblock@8"
            ]
        },
        {
            "x": 2,
            "y": 4,
            "z": 6,
            "elements": [
                "chisel:blocksteel@2"
            ]
        },
        {
            "x": 4,
            "y": 4,
            "z": 3,
            "elements": [
                "minecraft:stone_slab@7"
            ]
        },
        {
            "x": -8,
            "y": 4,
            "z": 1,
            "elements": [
                "mekanismgenerators:generator@10"
            ]
        },
        {
            "x": -4,
            "y": 3,
            "z": 2,
            "elements": [
                "ic2:resource@13"
            ]
        },
        {
            "x": 1,
            "y": 1,
            "z": 2,
            "elements": [
                "minecraft:stone_slab@7"
            ]
        },
        {
            "x": -5,
            "y": 2,
            "z": 1,
            "elements": [
                "mekanism:basicblock@10"
            ]
        },
        {
            "x": -8,
            "y": 0,
            "z": 0,
            "elements": [
                "chisel:blocksteel@0"
            ]
        },
        {
            "x": -5,
            "y": 3,
            "z": 1,
            "elements": [
                "ic2:resource@13"
            ]
        },
        {
            "x": -8,
            "y": 5,
            "z": 1,
            "elements": [
                "mekanism:basicblock@8"
            ]
        },
        {
            "x": 4,
            "y": 3,
            "z": 3,
            "elements": [
                "minecraft:stone_slab@7"
            ]
        },
        {
            "x": -5,
            "y": 4,
            "z": 2,
            "elements": [
                "minecraft:quartz_stairs@3"
            ]
        },
        {
            "x": 1,
            "y": 0,
            "z": 2,
            "elements": [
                "chisel:blocksteel@2"
            ]
        },
        {
            "x": -4,
            "y": 2,
            "z": 2,
            "elements": [
                "ic2:resource@13"
            ]
        },
        {
            "x": -3,
            "y": 4,
            "z": 6,
            "elements": [
                "minecraft:stone_slab@7"
            ]
        },
        {
            "x": 0,
            "y": 3,
            "z": 1,
            "elements": [
                "ic2:resource@13"
            ]
        },
        {
            "x": -3,
            "y": 0,
            "z": 1,
            "elements": [
                "mekanism:basicblock@8"
            ]
        },
        {
            "x": 4,
            "y": 4,
            "z": 5,
            "elements": [
                "minecraft:stone_slab@7"
            ]
        },
        {
            "x": -8,
            "y": 3,
            "z": 7,
            "elements": [
                "mekanismgenerators:generator@10"
            ]
        },
        {
            "x": 0,
            "y": 2,
            "z": 1,
            "elements": [
                "mekanism:basicblock@10"
            ]
        },
        {
            "x": -6,
            "y": 2,
            "z": 6,
            "elements": [
                "mekanism:basicblock@10"
            ]
        },
        {
            "x": -8,
            "y": 5,
            "z": 2,
            "elements": [
                "minecraft:quartz_stairs@2"
            ]
        },
        {
            "x": 3,
            "y": 0,
            "z": 6,
            "elements": [
                "chisel:blocksteel@0"
            ]
        },
        {
            "x": -8,
            "y": 2,
            "z": 7,
            "elements": [
                "mekanismgenerators:generator@10"
            ]
        },
        {
            "x": 3,
            "y": 1,
            "z": 6,
            "elements": [
                "chisel:blocksteel@6"
            ]
        },
        {
            "x": 1,
            "y": 0,
            "z": 7,
            "elements": [
                "minecraft:quartz_stairs@3"
            ]
        },
        {
            "x": -1,
            "y": 4,
            "z": 1,
            "elements": [
                "minecraft:quartz_stairs@2"
            ]
        },
        {
            "x": 4,
            "y": 3,
            "z": 5,
            "elements": [
                "minecraft:stone_slab@7"
            ]
        },
        {
            "x": -6,
            "y": 3,
            "z": 6,
            "elements": [
                "mekanism:basicblock@10"
            ]
        },
        {
            "x": -8,
            "y": 4,
            "z": 2,
            "elements": [
                "mekanismgenerators:generator@10"
            ]
        },
        {
            "x": -5,
            "y": 0,
            "z": 2,
            "elements": [
                "chisel:blocksteel@2"
            ]
        },
        {
            "x": -6,
            "y": 4,
            "z": 6,
            "elements": [
                "chisel:blocksteel@2"
            ]
        },
        {
            "x": -6,
            "y": 4,
            "z": 1,
            "elements": [
                "chisel:blocksteel@2"
            ]
        },
        {
            "x": 0,
            "y": 0,
            "z": 6,
            "elements": [
                "mekanism:basicblock@8"
            ]
        },
        {
            "x": 0,
            "y": 0,
            "z": 1,
            "elements": [
                "mekanism:basicblock@8"
            ]
        },
        {
            "x": -3,
            "y": 3,
            "z": 6,
            "elements": [
                "minecraft:stone_slab@15"
            ]
        },
        {
            "x": -5,
            "y": 1,
            "z": 2,
            "elements": [
                "minecraft:stone_slab@7"
            ]
        },
        {
            "x": -8,
            "y": 4,
            "z": 7,
            "elements": [
                "mekanismgenerators:generator@10"
            ]
        },
        {
            "x": 0,
            "y": 1,
            "z": 6,
            "elements": [
                "chisel:blocksteel@6"
            ]
        },
        {
            "x": -6,
            "y": 0,
            "z": 0,
            "elements": [
                "minecraft:quartz_stairs@2"
            ]
        },
        {
            "x": -3,
            "y": 3,
            "z": 1,
            "elements": [
                "minecraft:stone_slab@15"
            ]
        },
        {
            "x": 0,
            "y": 1,
            "z": 1,
            "elements": [
                "chisel:blocksteel@6"
            ]
        },
        {
            "x": -6,
            "y": 0,
            "z": 7,
            "elements": [
                "minecraft:quartz_stairs@3"
            ]
        },
        {
            "x": 0,
            "y": 2,
            "z": 6,
            "elements": [
                "mekanism:basicblock@10"
            ]
        },
        {
            "x": -1,
            "y": 0,
            "z": 1,
            "elements": [
                "mekanism:basicblock@8"
            ]
        },
        {
            "x": -8,
            "y": 0,
            "z": 2,
            "elements": [
                "chisel:blocksteel@0"
            ]
        },
        {
            "x": -7,
            "y": 1,
            "z": 6,
            "elements": [
                "chisel:blocksteel@6"
            ]
        },
        {
            "x": -9,
            "y": 4,
            "z": 6,
            "elements": [
                "mekanism:basicblock@8"
            ]
        },
        {
            "x": -8,
            "y": 1,
            "z": 2,
            "elements": [
                "chisel:laboratory@12"
            ]
        },
        {
            "x": 0,
            "y": 3,
            "z": 6,
            "elements": [
                "ic2:resource@13"
            ]
        },
        {
            "x": -9,
            "y": 5,
            "z": 6,
            "elements": [
                "mekanism:basicblock@8"
            ]
        },
        {
            "x": -7,
            "y": 0,
            "z": 6,
            "elements": [
                "chisel:blocksteel@2"
            ]
        },
        {
            "x": -3,
            "y": 4,
            "z": 1,
            "elements": [
                "minecraft:stone_slab@7"
            ]
        },
        {
            "x": -2,
            "y": 3,
            "z": 1,
            "elements": [
                "minecraft:stone_slab@15"
            ]
        },
        {
            "x": -1,
            "y": 1,
            "z": 1,
            "elements": [
                "minecraft:quartz_stairs@2"
            ]
        },
        {
            "x": -8,
            "y": 0,
            "z": 5,
            "elements": [
                "chisel:blocksteel@0"
            ]
        },
        {
            "x": -2,
            "y": 0,
            "z": 1,
            "elements": [
                "mekanism:basicblock@8"
            ]
        },
        {
            "x": -8,
            "y": 2,
            "z": 2,
            "elements": [
                "chisel:blocksteel@2"
            ]
        },
        {
            "x": 0,
            "y": 4,
            "z": 6,
            "elements": [
                "minecraft:quartz_stairs@3"
            ]
        },
        {
            "x": -1,
            "y": 3,
            "z": 1,
            "elements": [
                "chisel:technical1@1"
            ]
        },
        {
            "x": -1,
            "y": 2,
            "z": 1,
            "elements": [
                "minecraft:quartz_stairs@6"
            ]
        },
        {
            "x": -9,
            "y": 2,
            "z": 6,
            "elements": [
                "mekanism:basicblock@8"
            ]
        },
        {
            "x": -4,
            "y": 4,
            "z": 1,
            "elements": [
                "minecraft:quartz_stairs@2"
            ]
        },
        {
            "x": -8,
            "y": 3,
            "z": 2,
            "elements": [
                "chisel:blocksteel@2"
            ]
        },
        {
            "x": -8,
            "y": 2,
            "z": 5,
            "elements": [
                "chisel:blocksteel@2"
            ]
        },
        {
            "x": -6,
            "y": 0,
            "z": 6,
            "elements": [
                "chisel:blocksteel@2"
            ]
        },
        {
            "x": -8,
            "y": 1,
            "z": 5,
            "elements": [
                "chisel:laboratory@12"
            ]
        },
        {
            "x": -6,
            "y": 1,
            "z": 6,
            "elements": [
                "chisel:blocksteel@6"
            ]
        },
        {
            "x": -9,
            "y": 3,
            "z": 6,
            "elements": [
                "mekanism:basicblock@8"
            ]
        },
        {
            "x": -8,
            "y": 3,
            "z": 5,
            "elements": [
                "chisel:blocksteel@2"
            ]
        },
        {
            "x": -7,
            "y": 0,
            "z": 1,
            "elements": [
                "chisel:blocksteel@2"
            ]
        },
        {
            "x": 3,
            "y": 2,
            "z": 0,
            "elements": [
                "mekanismgenerators:generator@10"
            ]
        },
        {
            "x": 1,
            "y": 0,
            "z": 5,
            "elements": [
                "chisel:blocksteel@2"
            ]
        },
        {
            "x": -1,
            "y": 0,
            "z": 6,
            "elements": [
                "mekanism:basicblock@8"
            ]
        },
        {
            "x": -7,
            "y": 5,
            "z": 6,
            "elements": [
                "mekanism:basicblock@8"
            ]
        },
        {
            "x": -7,
            "y": 4,
            "z": 6,
            "elements": [
                "chisel:blocksteel@2"
            ]
        },
        {
            "x": 3,
            "y": 5,
            "z": 1,
            "elements": [
                "mekanism:basicblock@8"
            ]
        },
        {
            "x": -4,
            "y": 2,
            "z": 1,
            "elements": [
                "minecraft:quartz_stairs@6"
            ]
        },
        {
            "x": -2,
            "y": 3,
            "z": 6,
            "elements": [
                "minecraft:stone_slab@15"
            ]
        },
        {
            "x": -3,
            "y": 0,
            "z": 7,
            "elements": [
                "minecraft:stone_slab@7"
            ]
        },
        {
            "x": -8,
            "y": 4,
            "z": 5,
            "elements": [
                "mekanismgenerators:generator@10"
            ]
        },
        {
            "x": -7,
            "y": 1,
            "z": 1,
            "elements": [
                "chisel:blocksteel@6"
            ]
        },
        {
            "x": 3,
            "y": 4,
            "z": 1,
            "elements": [
                "mekanismgenerators:generator@10"
            ]
        },
        {
            "x": 3,
            "y": 1,
            "z": 0,
            "elements": [
                "mekanismgenerators:generator@10"
            ]
        },
        {
            "x": -4,
            "y": 3,
            "z": 1,
            "elements": [
                "chisel:technical1@1"
            ]
        },
        {
            "x": 3,
            "y": 5,
            "z": 2,
            "elements": [
                "minecraft:quartz_stairs@2"
            ]
        },
        {
            "x": -1,
            "y": 1,
            "z": 6,
            "elements": [
                "minecraft:quartz_stairs@3"
            ]
        },
        {
            "x": 1,
            "y": 1,
            "z": 5,
            "elements": [
                "minecraft:stone_slab@7"
            ]
        },
        {
            "x": -3,
            "y": 0,
            "z": 0,
            "elements": [
                "minecraft:stone_slab@7"
            ]
        },
        {
            "x": -7,
            "y": 2,
            "z": 1,
            "elements": [
                "mekanism:basicblock@10"
            ]
        },
        {
            "x": -4,
            "y": 0,
            "z": 1,
            "elements": [
                "mekanism:basicblock@8"
            ]
        },
        {
            "x": -2,
            "y": 4,
            "z": 6,
            "elements": [
                "minecraft:stone_slab@7"
            ]
        },
        {
            "x": -7,
            "y": 2,
            "z": 6,
            "elements": [
                "mekanism:basicblock@10"
            ]
        },
        {
            "x": 4,
            "y": 4,
            "z": 2,
            "elements": [
                "minecraft:stone_slab@7"
            ]
        },
        {
            "x": 3,
            "y": 4,
            "z": 0,
            "elements": [
                "mekanismgenerators:generator@10"
            ]
        },
        {
            "x": -2,
            "y": 0,
            "z": 7,
            "elements": [
                "minecraft:stone_slab@7"
            ]
        },
        {
            "x": -4,
            "y": 1,
            "z": 1,
            "elements": [
                "minecraft:quartz_stairs@2"
            ]
        },
        {
            "x": -4,
            "y": 0,
            "z": 6,
            "elements": [
                "mekanism:basicblock@8"
            ]
        },
        {
            "x": 3,
            "y": 3,
            "z": 0,
            "elements": [
                "mekanismgenerators:generator@10"
            ]
        },
        {
            "x": -4,
            "y": 1,
            "z": 6,
            "elements": [
                "minecraft:quartz_stairs@3"
            ]
        },
        {
            "x": -8,
            "y": 5,
            "z": 5,
            "elements": [
                "minecraft:quartz_stairs@3"
            ]
        },
        {
            "x": -7,
            "y": 3,
            "z": 6,
            "elements": [
                "mekanism:basicblock@10"
            ]
        },
        {
            "x": -7,
            "y": 3,
            "z": 1,
            "elements": [
                "mekanism:basicblock@10"
            ]
        },
        {
            "x": -5,
            "y": 4,
            "z": 6,
            "elements": [
                "minecraft:quartz_stairs@3"
            ]
        },
        {
            "x": -7,
            "y": 4,
            "z": 1,
            "elements": [
                "chisel:blocksteel@2"
            ]
        },
        {
            "x": 2,
            "y": 3,
            "z": 1,
            "elements": [
                "mekanism:basicblock@10"
            ]
        },
        {
            "x": -3,
            "y": 0,
            "z": 6,
            "elements": [
                "mekanism:basicblock@8"
            ]
        },
        {
            "x": -2,
            "y": 4,
            "z": 5,
            "elements": [
                "minecraft:quartz_stairs@2"
            ]
        },
        {
            "x": 4,
            "y": 1,
            "z": 2,
            "elements": [
                "chisel:blocksteel@6"
            ]
        },
        {
            "x": -4,
            "y": 2,
            "z": 6,
            "elements": [
                "minecraft:quartz_stairs@7"
            ]
        },
        {
            "x": 3,
            "y": 0,
            "z": 1,
            "elements": [
                "chisel:blocksteel@0"
            ]
        },
        {
            "x": 1,
            "y": 5,
            "z": 5,
            "elements": [
                "minecraft:stone_slab@7"
            ]
        },
        {
            "x": 2,
            "y": 2,
            "z": 1,
            "elements": [
                "mekanism:basicblock@10"
            ]
        },
        {
            "x": 3,
            "y": 1,
            "z": 1,
            "elements": [
                "chisel:blocksteel@6"
            ]
        },
        {
            "x": 4,
            "y": 0,
            "z": 2,
            "elements": [
                "chisel:blocksteel@6"
            ]
        },
        {
            "x": 1,
            "y": 5,
            "z": 2,
            "elements": [
                "minecraft:stone_slab@7"
            ]
        },
        {
            "x": -7,
            "y": 5,
            "z": 1,
            "elements": [
                "mekanism:basicblock@8"
            ]
        },
        {
            "x": -2,
            "y": 3,
            "z": 5,
            "elements": [
                "minecraft:quartz_block@0"
            ]
        },
        {
            "x": -5,
            "y": 0,
            "z": 7,
            "elements": [
                "minecraft:stone_slab@7"
            ]
        },
        {
            "x": -4,
            "y": 3,
            "z": 6,
            "elements": [
                "chisel:technical1@1"
            ]
        },
        {
            "x": 4,
            "y": 3,
            "z": 2,
            "elements": [
                "minecraft:stone_slab@7"
            ]
        },
        {
            "x": -4,
            "y": 4,
            "z": 6,
            "elements": [
                "minecraft:quartz_stairs@3"
            ]
        },
        {
            "x": 3,
            "y": 0,
            "z": 0,
            "elements": [
                "chisel:blocksteel@0"
            ]
        },
        {
            "x": 4,
            "y": 1,
            "z": 5,
            "elements": [
                "chisel:blocksteel@6"
            ]
        },
        {
            "x": 3,
            "y": 3,
            "z": 1,
            "elements": [
                "chisel:blocksteel@2"
            ]
        },
        {
            "x": 4,
            "y": 0,
            "z": 5,
            "elements": [
                "chisel:blocksteel@6"
            ]
        },
        {
            "x": 4,
            "y": 2,
            "z": 5,
            "elements": [
                "minecraft:stone_slab@7"
            ]
        },
        {
            "x": -2,
            "y": 0,
            "z": 6,
            "elements": [
                "mekanism:basicblock@8"
            ]
        },
        {
            "x": -5,
            "y": 2,
            "z": 6,
            "elements": [
                "mekanism:basicblock@10"
            ]
        },
        {
            "x": 1,
            "y": 4,
            "z": 5,
            "elements": [
                "chisel:blocksteel@2"
            ]
        },
        {
            "x": 2,
            "y": 0,
            "z": 1,
            "elements": [
                "chisel:blocksteel@2"
            ]
        },
        {
            "x": 0,
            "y": 0,
            "z": 7,
            "elements": [
                "minecraft:stone_slab@7"
            ]
        },
        {
            "x": 3,
            "y": 2,
            "z": 1,
            "elements": [
                "chisel:blocksteel@2"
            ]
        },
        {
            "x": 3,
            "y": 4,
            "z": 2,
            "elements": [
                "mekanismgenerators:generator@10"
            ]
        },
        {
            "x": 0,
            "y": 4,
            "z": 1,
            "elements": [
                "minecraft:quartz_stairs@2"
            ]
        },
        {
            "x": 4,
            "y": 2,
            "z": 2,
            "elements": [
                "minecraft:stone_slab@7"
            ]
        },
        {
            "x": 2,
            "y": 1,
            "z": 1,
            "elements": [
                "chisel:blocksteel@6"
            ]
        },
        {
            "x": -5,
            "y": 3,
            "z": 6,
            "elements": [
                "ic2:resource@13"
            ]
        }
    ]}