{
    "registryname": "newengineerworkshop1",
    "localizedname": "§2更棒§5更好§6更强§7的§7工程师工坊",
    "failure-action": "still",
    "requires-blueprint": false,
    "has-factory": false,

    "parts": [
        {
            "x": 0,
            "y": 0,
            "z": 0,
            "elements": [
                "modularmachinery:newengineerworkshop1_controller@2"
            ]
        },
        {
            "x": -4,
            "y": -2,
            "z": 2,
            "elements": [
                "chisel:laboratory@7"
            ]
        },
        {
            "x": 3,
            "y": 3,
            "z": 2,
            "elements": [
                "jaopca:block_slabiron@0"
            ]
        },
        {
            "x": -1,
            "y": 2,
            "z": 0,
            "elements": [
                "chisel:laboratory@2"
            ]
        },
        {
            "x": -5,
            "y": -2,
            "z": -4,
            "elements": [
                "chisel:factory@6"
            ]
        },
        {
            "x": 0,
            "y": -2,
            "z": 0,
            "elements": [
                "chisel:laboratory@7"
            ]
        },
        {
            "x": -6,
            "y": -2,
            "z": -1,
            "elements": [
                "chisel:laboratory@7"
            ]
        },
        {
            "x": -6,
            "y": 0,
            "z": 2,
            "elements": [
                "chisel:iron@5"
            ]
        },
        {
            "x": 1,
            "y": 2,
            "z": -3,
            "elements": [
                "chisel:iron@5"
            ]
        },
        {
            "x": -6,
            "y": -1,
            "z": -1,
            "elements": [
                "chisel:iron@5"
            ]
        },
        {
            "x": -6,
            "y": 1,
            "z": -1,
            "elements": [
                "chisel:iron@5"
            ]
        },
        {
            "x": -5,
            "y": -1,
            "z": 3,
            "elements": [
                "chisel:iron@5"
            ]
        },
        {
            "x": 0,
            "y": -1,
            "z": 0,
            "elements": [
                "chisel:laboratory@4"
            ]
        },
        {
            "x": -1,
            "y": 1,
            "z": 0,
            "elements": [
                "chisel:laboratory@4"
            ]
        },
        {
            "x": -6,
            "y": 1,
            "z": 2,
            "elements": [
                "chisel:iron@5"
            ]
        },
        {
            "x": 3,
            "y": 2,
            "z": 2,
            "elements": [
                "chisel:iron@5"
            ]
        },
        {
            "x": -2,
            "y": 3,
            "z": -3,
            "elements": [
                "jaopca:block_slabiron@0"
            ]
        },
        {
            "x": -4,
            "y": 0,
            "z": 3,
            "elements": [
                "chisel:iron@5"
            ]
        },
        {
            "x": 3,
            "y": -1,
            "z": -3,
            "elements": [
                "minecraft:end_rod@1"
            ]
        },
        {
            "x": -2,
            "y": -2,
            "z": 3,
            "elements": [
                "chisel:laboratory@7"
            ]
        },
        {
            "x": -6,
            "y": -2,
            "z": 1,
            "elements": [
                "chisel:laboratory@7"
            ]
        },
        {
            "x": -6,
            "y": 0,
            "z": -1,
            "elements": [
                "chisel:iron@5"
            ]
        },
        {
            "x": -6,
            "y": 3,
            "z": -1,
            "elements": [
                "jaopca:block_slabiron@0"
            ]
        },
        {
            "x": 1,
            "y": -2,
            "z": 0,
            "elements": [
                "chisel:laboratory@7"
            ]
        },
        {
            "x": -2,
            "y": 2,
            "z": 0,
            "elements": [
                "chisel:laboratory@2"
            ]
        },
        {
            "x": -4,
            "y": 1,
            "z": 3,
            "elements": [
                "chisel:iron@5"
            ]
        },
        {
            "x": 3,
            "y": -2,
            "z": -3,
            "elements": [
                "chisel:laboratory@7"
            ]
        },
        {
            "x": 1,
            "y": 3,
            "z": -3,
            "elements": [
                "jaopca:block_slabiron@0"
            ]
        },
        {
            "x": -4,
            "y": -2,
            "z": -2,
            "elements": [
                "chisel:laboratory@7"
            ]
        },
        {
            "x": -2,
            "y": 2,
            "z": -3,
            "elements": [
                "chisel:iron@5"
            ]
        },
        {
            "x": 3,
            "y": 1,
            "z": 2,
            "elements": [
                "chisel:laboratory@14"
            ]
        },
        {
            "x": -5,
            "y": -2,
            "z": 2,
            "elements": [
                "chisel:laboratory@7"
            ]
        },
        {
            "x": -6,
            "y": 3,
            "z": 2,
            "elements": [
                "jaopca:block_slabiron@0"
            ]
        },
        {
            "x": 3,
            "y": 3,
            "z": -2,
            "elements": [
                "jaopca:block_slabiron@0"
            ]
        },
        {
            "x": -7,
            "y": -2,
            "z": 4,
            "elements": [
                "chisel:factory@6"
            ]
        },
        {
            "x": 1,
            "y": -1,
            "z": 0,
            "elements": [
                "minecraft:quartz_stairs@1"
            ]
        },
        {
            "x": -2,
            "y": 1,
            "z": 0,
            "elements": [
                "chisel:laboratory@4"
            ]
        },
        {
            "x": -6,
            "y": 2,
            "z": -1,
            "elements": [
                "chisel:iron@5"
            ]
        },
        {
            "x": -4,
            "y": 2,
            "z": 3,
            "elements": [
                "chisel:iron@5"
            ]
        },
        {
            "x": -6,
            "y": -1,
            "z": 1,
            "elements": [
                "chisel:iron@5"
            ]
        },
        {
            "x": 4,
            "y": -2,
            "z": 4,
            "elements": [
                "chisel:factory@6"
            ]
        },
        {
            "x": 3,
            "y": 2,
            "z": -2,
            "elements": [
                "chisel:iron@5"
            ]
        },
        {
            "x": 3,
            "y": 0,
            "z": 2,
            "elements": [
                "appliedenergistics2:quartz_glass@0"
            ]
        },
        {
            "x": -6,
            "y": 2,
            "z": 2,
            "elements": [
                "chisel:iron@5"
            ]
        },
        {
            "x": 1,
            "y": -2,
            "z": 3,
            "elements": [
                "chisel:laboratory@7"
            ]
        },
        {
            "x": -7,
            "y": -2,
            "z": -4,
            "elements": [
                "chisel:factory@6"
            ]
        },
        {
            "x": -3,
            "y": 1,
            "z": -2,
            "elements": [
                "chisel:laboratory@4"
            ]
        },
        {
            "x": 2,
            "y": -2,
            "z": 2,
            "elements": [
                "chisel:laboratory@7"
            ]
        },
        {
            "x": -4,
            "y": -2,
            "z": -3,
            "elements": [
                "chisel:laboratory@7"
            ]
        },
        {
            "x": 3,
            "y": 1,
            "z": 3,
            "elements": [
                "chisel:laboratory@14"
            ]
        },
        {
            "x": 1,
            "y": -1,
            "z": 3,
            "elements": [
                "chisel:laboratory@14"
            ]
        },
        {
            "x": -2,
            "y": -2,
            "z": 0,
            "elements": [
                "chisel:laboratory@7"
            ]
        },
        {
            "x": 1,
            "y": 2,
            "z": 0,
            "elements": [
                "chisel:laboratory@2"
            ]
        },
        {
            "x": -6,
            "y": 3,
            "z": -2,
            "elements": [
                "jaopca:block_slabiron@0"
            ]
        },
        {
            "x": -3,
            "y": 0,
            "z": -2,
            "elements": [
                "modularmachinery:blockoutputbus",
                "modularmachinery:blockmeitemoutputbus",
                "modularmachinery:blockfluidinputhatch",
                "modularmachinery:blockmefluidinputbus"
            ]
        },
        {
            "x": 2,
            "y": -1,
            "z": 2,
            "elements": [
                "minecraft:anvil@1"
            ]
        },
        {
            "x": 2,
            "y": 2,
            "z": 3,
            "elements": [
                "chisel:iron@5"
            ]
        },
        {
            "x": -1,
            "y": -2,
            "z": -2,
            "elements": [
                "chisel:laboratory@7"
            ]
        },
        {
            "x": -5,
            "y": 2,
            "z": -3,
            "elements": [
                "chisel:iron@5"
            ]
        },
        {
            "x": 4,
            "y": -2,
            "z": 3,
            "elements": [
                "chisel:factory@6"
            ]
        },
        {
            "x": -2,
            "y": -1,
            "z": 0,
            "elements": [
                "chisel:laboratory@4"
            ]
        },
        {
            "x": -6,
            "y": 2,
            "z": -2,
            "elements": [
                "chisel:iron@5"
            ]
        },
        {
            "x": -5,
            "y": 1,
            "z": -3,
            "elements": [
                "chisel:iron@5"
            ]
        },
        {
            "x": 1,
            "y": 1,
            "z": 0,
            "elements": [
                "minecraft:quartz_stairs@5"
            ]
        },
        {
            "x": -3,
            "y": -1,
            "z": -3,
            "elements": [
                "chisel:laboratory@11"
            ]
        },
        {
            "x": 2,
            "y": 0,
            "z": 3,
            "elements": [
                "appliedenergistics2:quartz_glass@0"
            ]
        },
        {
            "x": 3,
            "y": -2,
            "z": 0,
            "elements": [
                "chisel:laboratory@7"
            ]
        },
        {
            "x": -3,
            "y": 0,
            "z": -3,
            "elements": [
                "chisel:laboratory@11"
            ]
        },
        {
            "x": -4,
            "y": 2,
            "z": 0,
            "elements": [
                "chisel:laboratory@2"
            ]
        },
        {
            "x": -1,
            "y": 3,
            "z": 3,
            "elements": [
                "jaopca:block_slabiron@0"
            ]
        },
        {
            "x": 0,
            "y": 0,
            "z": 2,
            "elements": [
                "minecraft:anvil@1"
            ]
        },
        {
            "x": -3,
            "y": 2,
            "z": 2,
            "elements": [
                "chisel:laboratory@2"
            ]
        },
        {
            "x": -1,
            "y": 0,
            "z": 0,
            "elements": [
                "modularmachinery:blockoutputbus",
                "modularmachinery:blockmeitemoutputbus",
                "modularmachinery:blockfluidinputhatch",
                "modularmachinery:blockmefluidinputbus"
            ]
        },
        {
            "x": 2,
            "y": -1,
            "z": 3,
            "elements": [
                "chisel:laboratory@14"
            ]
        },
        {
            "x": 2,
            "y": -1,
            "z": -2,
            "elements": [
                "artisanworktables:workshop@6"
            ]
        },
        {
            "x": 2,
            "y": 1,
            "z": 3,
            "elements": [
                "chisel:laboratory@14"
            ]
        },
        {
            "x": -3,
            "y": -2,
            "z": -3,
            "elements": [
                "chisel:laboratory@7"
            ]
        },
        {
            "x": -5,
            "y": -2,
            "z": 3,
            "elements": [
                "chisel:laboratory@7"
            ]
        },
        {
            "x": -6,
            "y": -2,
            "z": -4,
            "elements": [
                "chisel:factory@6"
            ]
        },
        {
            "x": -7,
            "y": -2,
            "z": -1,
            "elements": [
                "chisel:factory@6"
            ]
        },
        {
            "x": -6,
            "y": 0,
            "z": -2,
            "elements": [
                "chisel:iron@5"
            ]
        },
        {
            "x": 2,
            "y": -2,
            "z": -2,
            "elements": [
                "chisel:laboratory@7"
            ]
        },
        {
            "x": 3,
            "y": 0,
            "z": 3,
            "elements": [
                "appliedenergistics2:quartz_glass@0"
            ]
        },
        {
            "x": -4,
            "y": -1,
            "z": -3,
            "elements": [
                "chisel:iron@5"
            ]
        },
        {
            "x": -3,
            "y": 2,
            "z": -2,
            "elements": [
                "chisel:laboratory@2"
            ]
        },
        {
            "x": -5,
            "y": 3,
            "z": -3,
            "elements": [
                "jaopca:block_slabiron@0"
            ]
        },
        {
            "x": -7,
            "y": -2,
            "z": 1,
            "elements": [
                "chisel:factory@6"
            ]
        },
        {
            "x": 0,
            "y": 2,
            "z": 2,
            "elements": [
                "chisel:laboratory@2"
            ]
        },
        {
            "x": 0,
            "y": 3,
            "z": 3,
            "elements": [
                "jaopca:block_slabiron@0"
            ]
        },
        {
            "x": -6,
            "y": 1,
            "z": -2,
            "elements": [
                "chisel:iron@5"
            ]
        },
        {
            "x": -5,
            "y": 2,
            "z": 0,
            "elements": [
                "chisel:laboratory@2"
            ]
        },
        {
            "x": 0,
            "y": -2,
            "z": 2,
            "elements": [
                "chisel:laboratory@7"
            ]
        },
        {
            "x": 4,
            "y": -2,
            "z": 0,
            "elements": [
                "chisel:factory@6"
            ]
        },
        {
            "x": -6,
            "y": -2,
            "z": 3,
            "elements": [
                "chisel:laboratory@7"
            ]
        },
        {
            "x": 2,
            "y": -2,
            "z": 4,
            "elements": [
                "chisel:factory@6"
            ]
        },
        {
            "x": -1,
            "y": -2,
            "z": -4,
            "elements": [
                "chisel:factory@6"
            ]
        },
        {
            "x": 1,
            "y": -2,
            "z": -2,
            "elements": [
                "chisel:laboratory@7"
            ]
        },
        {
            "x": 1,
            "y": 0,
            "z": 1,
            "elements": [
                "appliedenergistics2:quartz_glass@0"
            ]
        },
        {
            "x": 0,
            "y": -1,
            "z": 2,
            "elements": [
                "minecraft:anvil@1"
            ]
        },
        {
            "x": 0,
            "y": 2,
            "z": -2,
            "elements": [
                "chisel:laboratory@2"
            ]
        },
        {
            "x": -1,
            "y": 2,
            "z": 2,
            "elements": [
                "chisel:laboratory@2"
            ]
        },
        {
            "x": 1,
            "y": 1,
            "z": 1,
            "elements": [
                "chisel:laboratory@14"
            ]
        },
        {
            "x": -2,
            "y": -2,
            "z": -1,
            "elements": [
                "chisel:laboratory@7"
            ]
        },
        {
            "x": -6,
            "y": 3,
            "z": -3,
            "elements": [
                "jaopca:block_slabiron@0"
            ]
        },
        {
            "x": -3,
            "y": -2,
            "z": 0,
            "elements": [
                "chisel:laboratory@7"
            ]
        },
        {
            "x": -1,
            "y": -2,
            "z": 2,
            "elements": [
                "chisel:laboratory@7"
            ]
        },
        {
            "x": -5,
            "y": 0,
            "z": -3,
            "elements": [
                "chisel:iron@5"
            ]
        },
        {
            "x": 2,
            "y": 2,
            "z": 0,
            "elements": [
                "chisel:laboratory@2"
            ]
        },
        {
            "x": 0,
            "y": -2,
            "z": -2,
            "elements": [
                "chisel:laboratory@7"
            ]
        },
        {
            "x": 1,
            "y": 2,
            "z": 1,
            "elements": [
                "chisel:laboratory@2"
            ]
        },
        {
            "x": -4,
            "y": -2,
            "z": -4,
            "elements": [
                "chisel:factory@6"
            ]
        },
        {
            "x": -6,
            "y": 2,
            "z": -3,
            "elements": [
                "chisel:laboratory@11"
            ]
        },
        {
            "x": 3,
            "y": 2,
            "z": 3,
            "elements": [
                "chisel:iron@5"
            ]
        },
        {
            "x": -6,
            "y": 1,
            "z": -3,
            "elements": [
                "chisel:laboratory@11"
            ]
        },
        {
            "x": -1,
            "y": -1,
            "z": 2,
            "elements": [
                "minecraft:anvil@2"
            ]
        },
        {
            "x": -6,
            "y": -1,
            "z": -3,
            "elements": [
                "chisel:laboratory@11"
            ]
        },
        {
            "x": -3,
            "y": -1,
            "z": 0,
            "elements": [
                "chisel:laboratory@11"
            ]
        },
        {
            "x": -1,
            "y": 2,
            "z": -2,
            "elements": [
                "chisel:laboratory@2"
            ]
        },
        {
            "x": -5,
            "y": -2,
            "z": -1,
            "elements": [
                "chisel:laboratory@7"
            ]
        },
        {
            "x": 2,
            "y": 3,
            "z": 3,
            "elements": [
                "jaopca:block_slabiron@0"
            ]
        },
        {
            "x": -2,
            "y": 2,
            "z": 2,
            "elements": [
                "chisel:laboratory@2"
            ]
        },
        {
            "x": -1,
            "y": 0,
            "z": 2,
            "elements": [
                "minecraft:anvil@2"
            ]
        },
        {
            "x": -2,
            "y": 0,
            "z": 0,
            "elements": [
                "modularmachinery:blockoutputbus",
                "modularmachinery:blockmeitemoutputbus",
                "modularmachinery:blockfluidinputhatch",
                "modularmachinery:blockmefluidinputbus"
            ]
        },
        {
            "x": 3,
            "y": -2,
            "z": 1,
            "elements": [
                "chisel:laboratory@7"
            ]
        },
        {
            "x": -6,
            "y": 0,
            "z": -3,
            "elements": [
                "chisel:laboratory@11"
            ]
        },
        {
            "x": -4,
            "y": -2,
            "z": 4,
            "elements": [
                "chisel:factory@6"
            ]
        },
        {
            "x": -2,
            "y": -2,
            "z": 2,
            "elements": [
                "chisel:laboratory@7"
            ]
        },
        {
            "x": 2,
            "y": 2,
            "z": -1,
            "elements": [
                "chisel:laboratory@2"
            ]
        },
        {
            "x": -6,
            "y": -2,
            "z": 0,
            "elements": [
                "chisel:laboratory@7"
            ]
        },
        {
            "x": -6,
            "y": 2,
            "z": 1,
            "elements": [
                "chisel:iron@5"
            ]
        },
        {
            "x": 3,
            "y": -2,
            "z": -2,
            "elements": [
                "chisel:laboratory@7"
            ]
        },
        {
            "x": 4,
            "y": -2,
            "z": -1,
            "elements": [
                "chisel:factory@6"
            ]
        },
        {
            "x": -2,
            "y": 2,
            "z": -2,
            "elements": [
                "chisel:laboratory@2"
            ]
        },
        {
            "x": 3,
            "y": 3,
            "z": 3,
            "elements": [
                "jaopca:block_slabiron@0"
            ]
        },
        {
            "x": -6,
            "y": -1,
            "z": 0,
            "elements": [
                "chisel:iron@5"
            ]
        },
        {
            "x": -4,
            "y": -2,
            "z": 1,
            "elements": [
                "chisel:laboratory@7"
            ]
        },
        {
            "x": 1,
            "y": 2,
            "z": 2,
            "elements": [
                "chisel:laboratory@2"
            ]
        },
        {
            "x": 3,
            "y": -1,
            "z": 1,
            "elements": [
                "chisel:laboratory@14"
            ]
        },
        {
            "x": -6,
            "y": 3,
            "z": 1,
            "elements": [
                "jaopca:block_slabiron@0"
            ]
        },
        {
            "x": -7,
            "y": -2,
            "z": -3,
            "elements": [
                "chisel:factory@6"
            ]
        },
        {
            "x": -5,
            "y": -2,
            "z": 4,
            "elements": [
                "chisel:factory@6"
            ]
        },
        {
            "x": 1,
            "y": -2,
            "z": 2,
            "elements": [
                "chisel:laboratory@7"
            ]
        },
        {
            "x": -6,
            "y": 0,
            "z": 1,
            "elements": [
                "chisel:iron@5"
            ]
        },
        {
            "x": 1,
            "y": -1,
            "z": 2,
            "elements": [
                "minecraft:anvil@1"
            ]
        },
        {
            "x": -2,
            "y": -2,
            "z": -2,
            "elements": [
                "chisel:laboratory@7"
            ]
        },
        {
            "x": 3,
            "y": 2,
            "z": -1,
            "elements": [
                "chisel:iron@5"
            ]
        },
        {
            "x": -5,
            "y": 2,
            "z": 1,
            "elements": [
                "chisel:laboratory@2"
            ]
        },
        {
            "x": -6,
            "y": 1,
            "z": 1,
            "elements": [
                "chisel:iron@5"
            ]
        },
        {
            "x": -4,
            "y": 2,
            "z": -1,
            "elements": [
                "chisel:laboratory@2"
            ]
        },
        {
            "x": 1,
            "y": 2,
            "z": -2,
            "elements": [
                "chisel:laboratory@2"
            ]
        },
        {
            "x": -6,
            "y": -2,
            "z": -3,
            "elements": [
                "chisel:laboratory@7"
            ]
        },
        {
            "x": 3,
            "y": 3,
            "z": -1,
            "elements": [
                "jaopca:block_slabiron@0"
            ]
        },
        {
            "x": 1,
            "y": 0,
            "z": 2,
            "elements": [
                "minecraft:anvil@1"
            ]
        },
        {
            "x": -4,
            "y": 2,
            "z": 2,
            "elements": [
                "chisel:laboratory@2"
            ]
        },
        {
            "x": -2,
            "y": -2,
            "z": -3,
            "elements": [
                "chisel:laboratory@7"
            ]
        },
        {
            "x": 1,
            "y": 1,
            "z": 3,
            "elements": [
                "chisel:laboratory@14"
            ]
        },
        {
            "x": -2,
            "y": -2,
            "z": 4,
            "elements": [
                "chisel:factory@6"
            ]
        },
        {
            "x": 3,
            "y": -1,
            "z": 3,
            "elements": [
                "chisel:laboratory@14"
            ]
        },
        {
            "x": -3,
            "y": -2,
            "z": 1,
            "elements": [
                "chisel:laboratory@7"
            ]
        },
        {
            "x": -4,
            "y": 0,
            "z": -3,
            "elements": [
                "chisel:iron@5"
            ]
        },
        {
            "x": -3,
            "y": -2,
            "z": -2,
            "elements": [
                "chisel:laboratory@7"
            ]
        },
        {
            "x": 0,
            "y": 2,
            "z": 1,
            "elements": [
                "chisel:laboratory@2"
            ]
        },
        {
            "x": 3,
            "y": -2,
            "z": -4,
            "elements": [
                "chisel:factory@6"
            ]
        },
        {
            "x": -5,
            "y": -1,
            "z": -3,
            "elements": [
                "chisel:iron@5"
            ]
        },
        {
            "x": -4,
            "y": 2,
            "z": -2,
            "elements": [
                "chisel:laboratory@2"
            ]
        },
        {
            "x": -3,
            "y": 2,
            "z": -1,
            "elements": [
                "chisel:laboratory@2"
            ]
        },
        {
            "x": -3,
            "y": -1,
            "z": -2,
            "elements": [
                "chisel:laboratory@4"
            ]
        },
        {
            "x": 2,
            "y": 0,
            "z": 2,
            "elements": [
                "minecraft:anvil@1"
            ]
        },
        {
            "x": -5,
            "y": 2,
            "z": 2,
            "elements": [
                "chisel:laboratory@2"
            ]
        },
        {
            "x": 4,
            "y": -2,
            "z": 2,
            "elements": [
                "chisel:factory@6"
            ]
        },
        {
            "x": -5,
            "y": -2,
            "z": -3,
            "elements": [
                "chisel:laboratory@7"
            ]
        },
        {
            "x": 1,
            "y": 3,
            "z": 3,
            "elements": [
                "jaopca:block_slabiron@0"
            ]
        },
        {
            "x": 2,
            "y": -2,
            "z": -1,
            "elements": [
                "chisel:laboratory@7"
            ]
        },
        {
            "x": -5,
            "y": 3,
            "z": 3,
            "elements": [
                "jaopca:block_slabiron@0"
            ]
        },
        {
            "x": 2,
            "y": -2,
            "z": 1,
            "elements": [
                "chisel:laboratory@7"
            ]
        },
        {
            "x": 3,
            "y": -2,
            "z": 2,
            "elements": [
                "chisel:laboratory@7"
            ]
        },
        {
            "x": -3,
            "y": 1,
            "z": -1,
            "elements": [
                "chisel:laboratory@4"
            ]
        },
        {
            "x": -7,
            "y": -2,
            "z": 3,
            "elements": [
                "chisel:factory@6"
            ]
        },
        {
            "x": 1,
            "y": -2,
            "z": 4,
            "elements": [
                "chisel:factory@6"
            ]
        },
        {
            "x": -7,
            "y": -2,
            "z": 0,
            "elements": [
                "chisel:factory@6"
            ]
        },
        {
            "x": -1,
            "y": 0,
            "z": -3,
            "elements": [
                "minecraft:end_rod@0"
            ]
        },
        {
            "x": 0,
            "y": -1,
            "z": 3,
            "elements": [
                "chisel:laboratory@14"
            ]
        },
        {
            "x": 3,
            "y": -1,
            "z": 2,
            "elements": [
                "chisel:laboratory@14"
            ]
        },
        {
            "x": -3,
            "y": 2,
            "z": 1,
            "elements": [
                "chisel:laboratory@2"
            ]
        },
        {
            "x": 0,
            "y": 0,
            "z": 1,
            "elements": [
                "chisel:glowstone@7"
            ]
        },
        {
            "x": 0,
            "y": -2,
            "z": -4,
            "elements": [
                "chisel:factory@6"
            ]
        },
        {
            "x": 4,
            "y": -2,
            "z": -2,
            "elements": [
                "chisel:factory@6"
            ]
        },
        {
            "x": -5,
            "y": 2,
            "z": -2,
            "elements": [
                "chisel:laboratory@2"
            ]
        },
        {
            "x": 2,
            "y": 2,
            "z": 2,
            "elements": [
                "chisel:laboratory@2"
            ]
        },
        {
            "x": 1,
            "y": 0,
            "z": 3,
            "elements": [
                "appliedenergistics2:quartz_glass@0"
            ]
        },
        {
            "x": -6,
            "y": 0,
            "z": 0,
            "elements": [
                "chisel:iron@5"
            ]
        },
        {
            "x": -1,
            "y": -2,
            "z": -1,
            "elements": [
                "chisel:laboratory@7"
            ]
        },
        {
            "x": -2,
            "y": 3,
            "z": 3,
            "elements": [
                "jaopca:block_slabiron@0"
            ]
        },
        {
            "x": 0,
            "y": 1,
            "z": 1,
            "elements": [
                "chisel:glowstone@7"
            ]
        },
        {
            "x": 2,
            "y": -1,
            "z": 1,
            "elements": [
                "chisel:laboratory@14"
            ]
        },
        {
            "x": -3,
            "y": 0,
            "z": -1,
            "elements": [
                "modularmachinery:blockoutputbus",
                "modularmachinery:blockmeitemoutputbus",
                "modularmachinery:blockfluidinputhatch",
                "modularmachinery:blockmefluidinputbus"
            ]
        },
        {
            "x": 0,
            "y": -2,
            "z": 4,
            "elements": [
                "chisel:factory@6"
            ]
        },
        {
            "x": -1,
            "y": -2,
            "z": 1,
            "elements": [
                "chisel:laboratory@7"
            ]
        },
        {
            "x": 4,
            "y": -2,
            "z": -3,
            "elements": [
                "chisel:factory@6"
            ]
        },
        {
            "x": -2,
            "y": 2,
            "z": 1,
            "elements": [
                "chisel:laboratory@2"
            ]
        },
        {
            "x": -6,
            "y": -2,
            "z": 2,
            "elements": [
                "chisel:laboratory@7"
            ]
        },
        {
            "x": -5,
            "y": 1,
            "z": 3,
            "elements": [
                "chisel:iron@5"
            ]
        },
        {
            "x": 1,
            "y": -2,
            "z": -4,
            "elements": [
                "chisel:factory@6"
            ]
        },
        {
            "x": 3,
            "y": 2,
            "z": -3,
            "elements": [
                "chisel:iron@5"
            ]
        },
        {
            "x": -6,
            "y": -1,
            "z": 2,
            "elements": [
                "chisel:iron@5"
            ]
        },
        {
            "x": -1,
            "y": 2,
            "z": -1,
            "elements": [
                "chisel:laboratory@2"
            ]
        },
        {
            "x": -5,
            "y": 2,
            "z": 3,
            "elements": [
                "chisel:iron@5"
            ]
        },
        {
            "x": -4,
            "y": 3,
            "z": -3,
            "elements": [
                "jaopca:block_slabiron@0"
            ]
        },
        {
            "x": 2,
            "y": 2,
            "z": -2,
            "elements": [
                "chisel:laboratory@2"
            ]
        },
        {
            "x": 3,
            "y": 1,
            "z": -3,
            "elements": [
                "chisel:ironpane@0"
            ]
        },
        {
            "x": -4,
            "y": -2,
            "z": 3,
            "elements": [
                "chisel:laboratory@7"
            ]
        },
        {
            "x": 0,
            "y": -2,
            "z": -1,
            "elements": [
                "chisel:laboratory@7"
            ]
        },
        {
            "x": -6,
            "y": 0,
            "z": 3,
            "elements": [
                "chisel:laboratory@11"
            ]
        },
        {
            "x": 3,
            "y": 3,
            "z": -3,
            "elements": [
                "jaopca:block_slabiron@0"
            ]
        },
        {
            "x": 0,
            "y": -2,
            "z": 1,
            "elements": [
                "chisel:laboratory@7"
            ]
        },
        {
            "x": -1,
            "y": -2,
            "z": 4,
            "elements": [
                "chisel:factory@6"
            ]
        },
        {
            "x": -3,
            "y": -2,
            "z": 2,
            "elements": [
                "chisel:laboratory@7"
            ]
        },
        {
            "x": -6,
            "y": -2,
            "z": -2,
            "elements": [
                "chisel:laboratory@7"
            ]
        },
        {
            "x": -1,
            "y": 2,
            "z": 1,
            "elements": [
                "chisel:laboratory@2"
            ]
        },
        {
            "x": -5,
            "y": -2,
            "z": 0,
            "elements": [
                "chisel:laboratory@7"
            ]
        },
        {
            "x": -6,
            "y": 1,
            "z": 3,
            "elements": [
                "chisel:laboratory@11"
            ]
        },
        {
            "x": -6,
            "y": -1,
            "z": 3,
            "elements": [
                "chisel:laboratory@11"
            ]
        },
        {
            "x": 2,
            "y": -2,
            "z": -4,
            "elements": [
                "chisel:factory@6"
            ]
        },
        {
            "x": 1,
            "y": 2,
            "z": 3,
            "elements": [
                "chisel:iron@5"
            ]
        },
        {
            "x": -4,
            "y": 2,
            "z": -3,
            "elements": [
                "chisel:iron@5"
            ]
        },
        {
            "x": 0,
            "y": -1,
            "z": 1,
            "elements": [
                "chisel:glowstone@7"
            ]
        },
        {
            "x": -6,
            "y": 2,
            "z": 3,
            "elements": [
                "chisel:laboratory@11"
            ]
        },
        {
            "x": 0,
            "y": 2,
            "z": -1,
            "elements": [
                "chisel:laboratory@2"
            ]
        },
        {
            "x": -5,
            "y": 0,
            "z": 3,
            "elements": [
                "chisel:iron@5"
            ]
        },
        {
            "x": -6,
            "y": -1,
            "z": -2,
            "elements": [
                "chisel:iron@5"
            ]
        },
        {
            "x": 3,
            "y": -2,
            "z": 3,
            "elements": [
                "chisel:laboratory@7"
            ]
        },
        {
            "x": -4,
            "y": 1,
            "z": -3,
            "elements": [
                "chisel:iron@5"
            ]
        },
        {
            "x": 1,
            "y": -2,
            "z": -1,
            "elements": [
                "chisel:laboratory@7"
            ]
        },
        {
            "x": -6,
            "y": 3,
            "z": 3,
            "elements": [
                "jaopca:block_slabiron@0"
            ]
        },
        {
            "x": 3,
            "y": 2,
            "z": 0,
            "elements": [
                "chisel:iron@5"
            ]
        },
        {
            "x": 1,
            "y": -2,
            "z": 1,
            "elements": [
                "chisel:laboratory@7"
            ]
        },
        {
            "x": 2,
            "y": -2,
            "z": -3,
            "elements": [
                "chisel:laboratory@7"
            ]
        },
        {
            "x": -3,
            "y": 1,
            "z": 3,
            "elements": [
                "chisel:iron@5"
            ]
        },
        {
            "x": 2,
            "y": 3,
            "z": -3,
            "elements": [
                "jaopca:block_slabiron@0"
            ]
        },
        {
            "x": -7,
            "y": -2,
            "z": -2,
            "elements": [
                "chisel:factory@6"
            ]
        },
        {
            "x": -4,
            "y": -2,
            "z": 0,
            "elements": [
                "chisel:laboratory@7"
            ]
        },
        {
            "x": -1,
            "y": -1,
            "z": 3,
            "elements": [
                "chisel:laboratory@11"
            ]
        },
        {
            "x": -6,
            "y": -2,
            "z": 4,
            "elements": [
                "chisel:factory@6"
            ]
        },
        {
            "x": -3,
            "y": 2,
            "z": -3,
            "elements": [
                "chisel:laboratory@11"
            ]
        },
        {
            "x": -4,
            "y": 2,
            "z": 1,
            "elements": [
                "chisel:laboratory@2"
            ]
        },
        {
            "x": -3,
            "y": 2,
            "z": 3,
            "elements": [
                "chisel:iron@5"
            ]
        },
        {
            "x": 1,
            "y": -1,
            "z": 1,
            "elements": [
                "chisel:laboratory@14"
            ]
        },
        {
            "x": -6,
            "y": 3,
            "z": 0,
            "elements": [
                "jaopca:block_slabiron@0"
            ]
        },
        {
            "x": -1,
            "y": -1,
            "z": -3,
            "elements": [
                "minecraft:end_rod@1"
            ]
        },
        {
            "x": 0,
            "y": 0,
            "z": 3,
            "elements": [
                "appliedenergistics2:quartz_glass@0"
            ]
        },
        {
            "x": -3,
            "y": 0,
            "z": 0,
            "elements": [
                "chisel:laboratory@11"
            ]
        },
        {
            "x": -3,
            "y": 1,
            "z": -3,
            "elements": [
                "chisel:laboratory@11"
            ]
        },
        {
            "x": 2,
            "y": -2,
            "z": 3,
            "elements": [
                "chisel:laboratory@7"
            ]
        },
        {
            "x": 0,
            "y": 1,
            "z": 3,
            "elements": [
                "chisel:laboratory@14"
            ]
        },
        {
            "x": -1,
            "y": -2,
            "z": -3,
            "elements": [
                "chisel:laboratory@7"
            ]
        },
        {
            "x": -3,
            "y": -2,
            "z": 4,
            "elements": [
                "chisel:factory@6"
            ]
        },
        {
            "x": -2,
            "y": -2,
            "z": 1,
            "elements": [
                "chisel:laboratory@7"
            ]
        },
        {
            "x": 1,
            "y": 2,
            "z": -1,
            "elements": [
                "chisel:laboratory@2"
            ]
        },
        {
            "x": 4,
            "y": -2,
            "z": -4,
            "elements": [
                "chisel:factory@6"
            ]
        },
        {
            "x": 3,
            "y": 0,
            "z": -3,
            "elements": [
                "minecraft:end_rod@0"
            ]
        },
        {
            "x": -4,
            "y": -1,
            "z": 3,
            "elements": [
                "chisel:iron@5"
            ]
        },
        {
            "x": 3,
            "y": -2,
            "z": -1,
            "elements": [
                "chisel:laboratory@7"
            ]
        },
        {
            "x": 0,
            "y": 2,
            "z": 3,
            "elements": [
                "chisel:iron@5"
            ]
        },
        {
            "x": 2,
            "y": 2,
            "z": -3,
            "elements": [
                "chisel:iron@5"
            ]
        },
        {
            "x": -3,
            "y": 3,
            "z": -3,
            "elements": [
                "jaopca:block_slabiron@0"
            ]
        },
        {
            "x": -2,
            "y": 2,
            "z": -1,
            "elements": [
                "chisel:laboratory@2"
            ]
        },
        {
            "x": -3,
            "y": -2,
            "z": 3,
            "elements": [
                "chisel:laboratory@7"
            ]
        },
        {
            "x": -5,
            "y": -2,
            "z": 1,
            "elements": [
                "chisel:laboratory@7"
            ]
        },
        {
            "x": -3,
            "y": 0,
            "z": 3,
            "elements": [
                "chisel:iron@5"
            ]
        },
        {
            "x": 3,
            "y": 3,
            "z": 0,
            "elements": [
                "jaopca:block_slabiron@0"
            ]
        },
        {
            "x": -3,
            "y": 2,
            "z": 0,
            "elements": [
                "chisel:laboratory@2"
            ]
        },
        {
            "x": 2,
            "y": -2,
            "z": 0,
            "elements": [
                "chisel:laboratory@7"
            ]
        },
        {
            "x": -4,
            "y": 3,
            "z": 3,
            "elements": [
                "jaopca:block_slabiron@0"
            ]
        },
        {
            "x": 0,
            "y": 3,
            "z": -3,
            "elements": [
                "jaopca:block_slabiron@0"
            ]
        },
        {
            "x": -3,
            "y": -1,
            "z": 3,
            "elements": [
                "chisel:iron@5"
            ]
        },
        {
            "x": 0,
            "y": -2,
            "z": -3,
            "elements": [
                "chisel:laboratory@7"
            ]
        },
        {
            "x": -1,
            "y": 1,
            "z": 3,
            "elements": [
                "chisel:laboratory@11"
            ]
        },
        {
            "x": -1,
            "y": 2,
            "z": -3,
            "elements": [
                "chisel:iron@5"
            ]
        },
        {
            "x": -5,
            "y": -2,
            "z": -2,
            "elements": [
                "chisel:laboratory@7"
            ]
        },
        {
            "x": -3,
            "y": -2,
            "z": -4,
            "elements": [
                "chisel:factory@6"
            ]
        },
        {
            "x": -6,
            "y": 1,
            "z": 0,
            "elements": [
                "chisel:iron@5"
            ]
        },
        {
            "x": 3,
            "y": 0,
            "z": 1,
            "elements": [
                "appliedenergistics2:quartz_glass@0"
            ]
        },
        {
            "x": -5,
            "y": 2,
            "z": -1,
            "elements": [
                "chisel:laboratory@2"
            ]
        },
        {
            "x": -1,
            "y": 2,
            "z": 3,
            "elements": [
                "chisel:laboratory@11"
            ]
        },
        {
            "x": 2,
            "y": 2,
            "z": 1,
            "elements": [
                "chisel:laboratory@2"
            ]
        },
        {
            "x": 3,
            "y": 1,
            "z": 1,
            "elements": [
                "chisel:laboratory@14"
            ]
        },
        {
            "x": 3,
            "y": -2,
            "z": 4,
            "elements": [
                "chisel:factory@6"
            ]
        },
        {
            "x": -4,
            "y": -2,
            "z": -1,
            "elements": [
                "chisel:laboratory@7"
            ]
        },
        {
            "x": -2,
            "y": 0,
            "z": 3,
            "elements": [
                "chisel:iron@5"
            ]
        },
        {
            "x": -6,
            "y": 2,
            "z": 0,
            "elements": [
                "chisel:iron@5"
            ]
        },
        {
            "x": 0,
            "y": 2,
            "z": 0,
            "elements": [
                "chisel:laboratory@2"
            ]
        },
        {
            "x": -1,
            "y": 1,
            "z": -3,
            "elements": [
                "chisel:ironpane@0"
            ]
        },
        {
            "x": 0,
            "y": -2,
            "z": 3,
            "elements": [
                "chisel:laboratory@7"
            ]
        },
        {
            "x": 4,
            "y": -2,
            "z": 1,
            "elements": [
                "chisel:factory@6"
            ]
        },
        {
            "x": -3,
            "y": 3,
            "z": 3,
            "elements": [
                "jaopca:block_slabiron@0"
            ]
        },
        {
            "x": -1,
            "y": -2,
            "z": 0,
            "elements": [
                "chisel:laboratory@7"
            ]
        },
        {
            "x": -7,
            "y": -2,
            "z": 2,
            "elements": [
                "chisel:factory@6"
            ]
        },
        {
            "x": 3,
            "y": 3,
            "z": 1,
            "elements": [
                "jaopca:block_slabiron@0"
            ]
        },
        {
            "x": -1,
            "y": 3,
            "z": -3,
            "elements": [
                "jaopca:block_slabiron@0"
            ]
        },
        {
            "x": -2,
            "y": 1,
            "z": 3,
            "elements": [
                "chisel:iron@5"
            ]
        },
        {
            "x": 1,
            "y": -2,
            "z": -3,
            "elements": [
                "chisel:laboratory@7"
            ]
        },
        {
            "x": -2,
            "y": -1,
            "z": 3,
            "elements": [
                "chisel:iron@5"
            ]
        },
        {
            "x": -2,
            "y": -2,
            "z": -4,
            "elements": [
                "chisel:factory@6"
            ]
        },
        {
            "x": 0,
            "y": 2,
            "z": -3,
            "elements": [
                "chisel:iron@5"
            ]
        },
        {
            "x": 2,
            "y": 0,
            "z": 1,
            "elements": [
                "modularmachinery:blockinputbus",
                "modularmachinery:blockmepatternprovider",
                "modularmachinery:blockmeiteminputbus"
            ]
        },
        {
            "x": -3,
            "y": -1,
            "z": -1,
            "elements": [
                "chisel:laboratory@4"
            ]
        },
        {
            "x": -3,
            "y": 1,
            "z": 0,
            "elements": [
                "chisel:laboratory@11"
            ]
        },
        {
            "x": -2,
            "y": 2,
            "z": 3,
            "elements": [
                "chisel:iron@5"
            ]
        },
        {
            "x": 0,
            "y": 1,
            "z": 0,
            "elements": [
                "chisel:laboratory@4"
            ]
        },
        {
            "x": -1,
            "y": -1,
            "z": 0,
            "elements": [
                "chisel:laboratory@4"
            ]
        },
        {
            "x": 3,
            "y": 2,
            "z": 1,
            "elements": [
                "chisel:iron@5"
            ]
        },
        {
            "x": -1,
            "y": 0,
            "z": 3,
            "elements": [
                "chisel:laboratory@11"
            ]
        },
        {
            "x": -1,
            "y": -2,
            "z": 3,
            "elements": [
                "chisel:laboratory@7"
            ]
        },
        {
            "x": -3,
            "y": -2,
            "z": -1,
            "elements": [
                "chisel:laboratory@7"
            ]
        },
        {
            "x": 2,
            "y": 1,
            "z": 1,
            "elements": [
                "chisel:laboratory@14"
            ]
        }
    ]}