{
    "registryname": "huge_disscociation_device",
    "localizedname": "§e大型工业§9解离复合体",
    "failure-action": "still",
    "requires-blueprint": false,
    "color": "66B2FF",
    "factory-only": true,
    "parts": [
        {
            "x": 0,
            "y": 0,
            "z": 0,

            "elements": [
                "modularmachinery:blockfactorycontroller@2"
            ]
        },
        {
            "x": -5,
            "y": -4,
            "z": 10,
            "elements": [
                "techguns:metalpanel@4"
            ]
        },
        {
            "x": 0,
            "y": -2,
            "z": 0,
            "elements": [
                "techguns:metalpanel@4"
            ]
        },
        {
            "x": -8,
            "y": -4,
            "z": 12,
            "elements": [
                "techguns:metalpanel@4"
            ]
        },
        {
            "x": 1,
            "y": -4,
            "z": 0,
            "elements": [
                "techguns:metalpanel@4"
            ]
        },
        {
            "x": -4,
            "y": -2,
            "z": 10,
            "elements": [
                "techguns:metalpanel@4"
            ]
        },
        {
            "x": -6,
            "y": 0,
            "z": 10,
            "elements": [
                "thermalfoundation:glass_alloy@7"
            ]
        },
        {
            "x": 5,
            "y": -2,
            "z": 1,
            "elements": [
                "techguns:metalpanel@4"
            ]
        },
        {
            "x": -6,
            "y": 1,
            "z": -1,
            "elements": [
                "techguns:metalpanel@6"
            ]
        },
        {
            "x": -6,
            "y": 12,
            "z": 14,
            "elements": [
                "techguns:metalpanel@4"
            ]
        },
        {
            "x": 6,
            "y": 5,
            "z": 7,
            "elements": [
                "immersiveengineering:metal_decoration1@1"
            ]
        },
        {
            "x": -5,
            "y": 10,
            "z": 0,
            "elements": [
                "techguns:metalpanel@4"
            ]
        },
        {
            "x": -6,
            "y": 12,
            "z": 7,
            "elements": [
                "techguns:metalpanel@4"
            ]
        },
        {
            "x": -6,
            "y": 0,
            "z": -1,
            "elements": [
                "techguns:metalpanel@6"
            ]
        },
        {
            "x": 6,
            "y": 5,
            "z": 4,
            "elements": [
                "immersiveengineering:metal_decoration1@1"
            ]
        },
        {
            "x": -6,
            "y": 12,
            "z": 0,
            "elements": [
                "techguns:metalpanel@4"
            ]
        },
        {
            "x": -6,
            "y": 4,
            "z": 10,
            "elements": [
                "advancedrocketry:blocklens@0"
            ]
        },
        {
            "x": -6,
            "y": 12,
            "z": 3,
            "elements": [
                "techguns:metalpanel@4"
            ]
        },
        {
            "x": -8,
            "y": -2,
            "z": 12,
            "elements": [
                "techguns:metalpanel@4"
            ]
        },
        {
            "x": -5,
            "y": 4,
            "z": 5,
            "elements": [
                "immersiveengineering:metal_decoration0@7"
            ]
        },
        {
            "x": -6,
            "y": 2,
            "z": -1,
            "elements": [
                "techguns:metalpanel@6"
            ]
        },
        {
            "x": 3,
            "y": 10,
            "z": 3,
            "elements": [
                "techguns:metalpanel@4"
            ]
        },
        {
            "x": -6,
            "y": 10,
            "z": 7,
            "elements": [
                "techguns:metalpanel@4"
            ]
        },
        {
            "x": 6,
            "y": 3,
            "z": 1,
            "elements": [
                "immersiveengineering:metal_decoration1@1"
            ]
        },
        {
            "x": 2,
            "y": 0,
            "z": 0,
            "elements": [
                "techguns:metalpanel@6"
            ]
        },
        {
            "x": -7,
            "y": -4,
            "z": -1,
            "elements": [
                "techguns:metalpanel@4"
            ]
        },
        {
            "x": -7,
            "y": -4,
            "z": 10,
            "elements": [
                "techguns:metalpanel@4"
            ]
        },
        {
            "x": 3,
            "y": 3,
            "z": 4,
            "elements": [
                "techguns:metalpanel@6"
            ]
        },
        {
            "x": -2,
            "y": -2,
            "z": 0,
            "elements": [
                "techguns:metalpanel@4"
            ]
        },
        {
            "x": 3,
            "y": -4,
            "z": 0,
            "elements": [
                "techguns:metalpanel@4"
            ]
        },
        {
            "x": 3,
            "y": 10,
            "z": 6,
            "elements": [
                "techguns:metalpanel@4"
            ]
        },
        {
            "x": -7,
            "y": -3,
            "z": -1,
            "elements": [
                "ic2:resource@13"
            ]
        },
        {
            "x": -8,
            "y": 12,
            "z": 10,
            "elements": [
                "techguns:metalpanel@4"
            ]
        },
        {
            "x": -8,
            "y": 12,
            "z": 0,
            "elements": [
                "techguns:metalpanel@4"
            ]
        },
        {
            "x": -3,
            "y": 10,
            "z": 0,
            "elements": [
                "techguns:metalpanel@4"
            ]
        },
        {
            "x": -7,
            "y": 12,
            "z": 5,
            "elements": [
                "techguns:metalpanel@4"
            ]
        },
        {
            "x": 1,
            "y": 12,
            "z": 2,
            "elements": [
                "techguns:metalpanel@4"
            ]
        },
        {
            "x": -6,
            "y": 10,
            "z": 5,
            "elements": [
                "techguns:metalpanel@4"
            ]
        },
        {
            "x": -3,
            "y": 3,
            "z": 11,
            "elements": [
                "minecraft:quartz_stairs@5"
            ]
        },
        {
            "x": -9,
            "y": 3,
            "z": 11,
            "elements": [
                "minecraft:quartz_stairs@4"
            ]
        },
        {
            "x": -7,
            "y": -2,
            "z": -1,
            "elements": [
                "techguns:metalpanel@4"
            ]
        },
        {
            "x": 3,
            "y": 11,
            "z": -1,
            "elements": [
                "ic2:resource@13"
            ]
        },
        {
            "x": 0,
            "y": 12,
            "z": -1,
            "elements": [
                "techguns:metalpanel@4"
            ]
        },
        {
            "x": -7,
            "y": -2,
            "z": 1,
            "elements": [
                "techguns:metalpanel@4"
            ]
        },
        {
            "x": -5,
            "y": 2,
            "z": 0,
            "elements": [
                "techguns:metalpanel@6"
            ]
        },
        {
            "x": -6,
            "y": 5,
            "z": 4,
            "elements": [
                "techguns:metalpanel@6"
            ]
        },
        {
            "x": -3,
            "y": 11,
            "z": 14,
            "elements": [
                "ic2:resource@13"
            ]
        },
        {
            "x": 4,
            "y": -2,
            "z": 0,
            "elements": [
                "techguns:metalpanel@4"
            ]
        },
        {
            "x": 6,
            "y": 12,
            "z": 14,
            "elements": [
                "techguns:metalpanel@4"
            ]
        },
        {
            "x": 4,
            "y": 0,
            "z": 0,
            "elements": [
                "techguns:metalpanel@6"
            ]
        },
        {
            "x": -6,
            "y": -2,
            "z": 3,
            "elements": [
                "techguns:metalpanel@4"
            ]
        },
        {
            "x": -8,
            "y": 8,
            "z": 0,
            "elements": [
                "avaritia:block_resource@0"
            ]
        },
        {
            "x": 2,
            "y": 4,
            "z": 0,
            "elements": [
                "immersiveengineering:metal_decoration0@7"
            ]
        },
        {
            "x": -6,
            "y": 12,
            "z": 10,
            "elements": [
                "techguns:metalpanel@4"
            ]
        },
        {
            "x": -9,
            "y": 11,
            "z": 11,
            "elements": [
                "ic2:resource@13"
            ]
        },
        {
            "x": -8,
            "y": -2,
            "z": 10,
            "elements": [
                "techguns:metalpanel@4"
            ]
        },
        {
            "x": -3,
            "y": -4,
            "z": 0,
            "elements": [
                "techguns:metalpanel@4"
            ]
        },
        {
            "x": 4,
            "y": -4,
            "z": 12,
            "elements": [
                "techguns:metalpanel@4"
            ]
        },
        {
            "x": 0,
            "y": 10,
            "z": -1,
            "elements": [
                "techguns:metalpanel@4"
            ]
        },
        {
            "x": -1,
            "y": 10,
            "z": 0,
            "elements": [
                "techguns:metalpanel@4"
            ]
        },
        {
            "x": -10,
            "y": 12,
            "z": 0,
            "elements": [
                "techguns:metalpanel@4"
            ]
        },
        {
            "x": -5,
            "y": 3,
            "z": 11,
            "elements": [
                "appliedenergistics2:quartz_glass@0"
            ]
        },
        {
            "x": 6,
            "y": 5,
            "z": 8,
            "elements": [
                "immersiveengineering:metal_decoration1@1"
            ]
        },
        {
            "x": 3,
            "y": 3,
            "z": 7,
            "elements": [
                "techguns:metalpanel@6"
            ]
        },
        {
            "x": 5,
            "y": -4,
            "z": 3,
            "elements": [
                "techguns:metalpanel@4"
            ]
        },
        {
            "x": -3,
            "y": -3,
            "z": 11,
            "elements": [
                "ic2:resource@13"
            ]
        },
        {
            "x": -3,
            "y": 11,
            "z": -1,
            "elements": [
                "ic2:resource@13"
            ]
        },
        {
            "x": -1,
            "y": 5,
            "z": 12,
            "elements": [
                "immersiveengineering:metal_decoration1@1"
            ]
        },
        {
            "x": -6,
            "y": 12,
            "z": -1,
            "elements": [
                "techguns:metalpanel@4"
            ]
        },
        {
            "x": 2,
            "y": 3,
            "z": 12,
            "elements": [
                "appliedenergistics2:quartz_glass@0"
            ]
        },
        {
            "x": 5,
            "y": -3,
            "z": 4,
            "elements": [
                "ic2:resource@13"
            ]
        },
        {
            "x": 3,
            "y": 12,
            "z": 8,
            "elements": [
                "techguns:metalpanel@4"
            ]
        },
        {
            "x": -2,
            "y": 0,
            "z": 0,

            "elements": [
                "modularmachinery:blockcasing@0"
            ]
        },
        {
            "x": 7,
            "y": -4,
            "z": 0,
            "elements": [
                "techguns:metalpanel@4"
            ]
        },
        {
            "x": -8,
            "y": 4,
            "z": 0,
            "elements": [
                "avaritia:block_resource@0"
            ]
        },
        {
            "x": -5,
            "y": -2,
            "z": 5,
            "elements": [
                "techguns:metalpanel@4"
            ]
        },
        {
            "x": 4,
            "y": -4,
            "z": 5,
            "elements": [
                "techguns:metalpanel@4"
            ]
        },
        {
            "x": -6,
            "y": -2,
            "z": 0,
            "elements": [
                "techguns:metalpanel@4"
            ]
        },
        {
            "x": 5,
            "y": 2,
            "z": 0,
            "elements": [
                "avaritia:block_resource@0"
            ]
        },
        {
            "x": -9,
            "y": 3,
            "z": 4,
            "elements": [
                "immersiveengineering:metal_decoration1@1"
            ]
        },
        {
            "x": 5,
            "y": -3,
            "z": -1,
            "elements": [
                "ic2:resource@13"
            ]
        },
        {
            "x": 4,
            "y": -2,
            "z": 12,
            "elements": [
                "techguns:metalpanel@4"
            ]
        },
        {
            "x": -7,
            "y": 10,
            "z": 0,
            "elements": [
                "techguns:metalpanel@4"
            ]
        },
        {
            "x": 2,
            "y": -2,
            "z": 10,
            "elements": [
                "techguns:metalpanel@4"
            ]
        },
        {
            "x": 6,
            "y": 10,
            "z": -1,
            "elements": [
                "techguns:metalpanel@4"
            ]
        },
        {
            "x": -6,
            "y": 4,
            "z": -1,
            "elements": [
                "libvulpes:coil0@10"
            ]
        },
        {
            "x": -6,
            "y": 3,
            "z": 1,
            "elements": [
                "appliedenergistics2:quartz_glass@0"
            ]
        },
        {
            "x": -4,
            "y": 12,
            "z": 0,
            "elements": [
                "techguns:metalpanel@4"
            ]
        },
        {
            "x": -6,
            "y": 8,
            "z": 10,
            "elements": [
                "thermalfoundation:glass_alloy@7"
            ]
        },
        {
            "x": -8,
            "y": 11,
            "z": 9,
            "elements": [
                "ic2:resource@13"
            ]
        },
        {
            "x": 5,
            "y": -4,
            "z": -1,
            "elements": [
                "techguns:metalpanel@4"
            ]
        },
        {
            "x": -5,
            "y": 5,
            "z": 9,
            "elements": [
                "techguns:metalpanel@6"
            ]
        },
        {
            "x": 3,
            "y": 2,
            "z": 6,
            "elements": [
                "techguns:metalpanel@6"
            ]
        },
        {
            "x": 2,
            "y": -1,
            "z": 7,
            "elements": [
                "techguns:metalpanel@6"
            ]
        },
        {
            "x": -9,
            "y": 11,
            "z": -1,
            "elements": [
                "ic2:resource@13"
            ]
        },
        {
            "x": 4,
            "y": 3,
            "z": 9,
            "elements": [
                "techguns:metalpanel@6"
            ]
        },
        {
            "x": 5,
            "y": -2,
            "z": -1,
            "elements": [
                "techguns:metalpanel@4"
            ]
        },
        {
            "x": -7,
            "y": 4,
            "z": 5,
            "elements": [
                "immersiveengineering:metal_decoration0@7"
            ]
        },
        {
            "x": -6,
            "y": 1,
            "z": 1,
            "elements": [
                "minecraft:end_rod@1"
            ]
        },
        {
            "x": 3,
            "y": 3,
            "z": -1,
            "elements": [
                "techguns:metalpanel@6"
            ]
        },
        {
            "x": -4,
            "y": -4,
            "z": 1,
            "elements": [
                "techguns:metalpanel@4"
            ]
        },
        {
            "x": -7,
            "y": -4,
            "z": 3,
            "elements": [
                "techguns:metalpanel@4"
            ]
        },
        {
            "x": 6,
            "y": 12,
            "z": -1,
            "elements": [
                "techguns:metalpanel@4"
            ]
        },
        {
            "x": -7,
            "y": 3,
            "z": 4,
            "elements": [
                "techguns:metalpanel@6"
            ]
        },
        {
            "x": -6,
            "y": 5,
            "z": 8,
            "elements": [
                "techguns:metalpanel@6"
            ]
        },
        {
            "x": 3,
            "y": -4,
            "z": 10,
            "elements": [
                "techguns:metalpanel@4"
            ]
        },
        {
            "x": -8,
            "y": -2,
            "z": 0,
            "elements": [
                "techguns:metalpanel@4"
            ]
        },
        {
            "x": 6,
            "y": 10,
            "z": 11,
            "elements": [
                "techguns:metalpanel@4"
            ]
        },
        {
            "x": 6,
            "y": 5,
            "z": 11,
            "elements": [
                "minecraft:quartz_stairs@1"
            ]
        },
        {
            "x": 6,
            "y": 3,
            "z": 13,
            "elements": [
                "immersiveengineering:metal_decoration1@1"
            ]
        },
        {
            "x": 4,
            "y": -2,
            "z": 13,
            "elements": [
                "techguns:metalpanel@4"
            ]
        },
        {
            "x": -7,
            "y": 5,
            "z": 9,
            "elements": [
                "techguns:metalpanel@6"
            ]
        },
        {
            "x": 3,
            "y": 4,
            "z": 5,
            "elements": [
                "libvulpes:coil0@10"
            ]
        },
        {
            "x": 0,
            "y": 12,
            "z": 13,
            "elements": [
                "techguns:metalpanel@4"
            ]
        },
        {
            "x": 1,
            "y": -3,
            "z": 4,
            "elements": [
                "ic2:resource@13"
            ]
        },
        {
            "x": 3,
            "y": 11,
            "z": 14,
            "elements": [
                "ic2:resource@13"
            ]
        },
        {
            "x": -4,
            "y": -3,
            "z": 9,
            "elements": [
                "ic2:resource@13"
            ]
        },
        {
            "x": 6,
            "y": 12,
            "z": 12,
            "elements": [
                "techguns:metalpanel@4"
            ]
        },
        {
            "x": 3,
            "y": 10,
            "z": 13,
            "elements": [
                "techguns:metalpanel@4"
            ]
        },
        {
            "x": -6,
            "y": 3,
            "z": 9,
            "elements": [
                "techguns:metalpanel@6"
            ]
        },
        {
            "x": -5,
            "y": 10,
            "z": 3,
            "elements": [
                "techguns:metalpanel@4"
            ]
        },
        {
            "x": 0,
            "y": 12,
            "z": 14,
            "elements": [
                "techguns:metalpanel@4"
            ]
        },
        {
            "x": -5,
            "y": -4,
            "z": 0,
            "elements": [
                "techguns:metalpanel@4"
            ]
        },
        {
            "x": 6,
            "y": 5,
            "z": 6,
            "elements": [
                "immersiveengineering:metal_decoration1@1"
            ]
        },
        {
            "x": -6,
            "y": 10,
            "z": 8,
            "elements": [
                "techguns:metalpanel@4"
            ]
        },
        {
            "x": 5,
            "y": 2,
            "z": 13,
            "elements": [
                "avaritia:block_resource@0"
            ]
        },
        {
            "x": -5,
            "y": 3,
            "z": 4,
            "elements": [
                "techguns:metalpanel@6"
            ]
        },
        {
            "x": 4,
            "y": 4,
            "z": 0,
            "elements": [
                "immersiveengineering:metal_decoration0@7"
            ]
        },
        {
            "x": 5,
            "y": 1,
            "z": 13,
            "elements": [
                "avaritia:block_resource@0"
            ]
        },
        {
            "x": 5,
            "y": -1,
            "z": 13,
            "elements": [
                "avaritia:block_resource@0"
            ]
        },
        {
            "x": -5,
            "y": 10,
            "z": 10,
            "elements": [
                "techguns:metalpanel@4"
            ]
        },
        {
            "x": 2,
            "y": 10,
            "z": 5,
            "elements": [
                "techguns:metalpanel@4"
            ]
        },
        {
            "x": 7,
            "y": -4,
            "z": 13,
            "elements": [
                "techguns:metalpanel@4"
            ]
        },
        {
            "x": 3,
            "y": -4,
            "z": 3,
            "elements": [
                "techguns:metalpanel@4"
            ]
        },
        {
            "x": -4,
            "y": -2,
            "z": 3,
            "elements": [
                "techguns:metalpanel@4"
            ]
        },
        {
            "x": 4,
            "y": 4,
            "z": 10,
            "elements": [
                "appliedenergistics2:quartz_glass@0"
            ]
        },
        {
            "x": -6,
            "y": 0,
            "z": 3,
            "elements": [
                "thermalfoundation:glass_alloy@7"
            ]
        },
        {
            "x": 6,
            "y": 12,
            "z": 13,
            "elements": [
                "techguns:metalpanel@4"
            ]
        },
        {
            "x": 6,
            "y": 3,
            "z": 6,
            "elements": [
                "immersiveengineering:metal_decoration1@1"
            ]
        },
        {
            "x": 6,
            "y": 10,
            "z": 14,
            "elements": [
                "techguns:metalpanel@4"
            ]
        },
        {
            "x": -9,
            "y": 5,
            "z": 9,
            "elements": [
                "immersiveengineering:metal_decoration1@1"
            ]
        },
        {
            "x": -4,
            "y": 12,
            "z": 3,
            "elements": [
                "techguns:metalpanel@4"
            ]
        },
        {
            "x": -7,
            "y": -2,
            "z": 8,
            "elements": [
                "techguns:metalpanel@4"
            ]
        },
        {
            "x": 2,
            "y": -4,
            "z": 8,
            "elements": [
                "techguns:metalpanel@4"
            ]
        },
        {
            "x": 6,
            "y": 12,
            "z": 11,
            "elements": [
                "techguns:metalpanel@4"
            ]
        },
        {
            "x": 4,
            "y": -1,
            "z": 13,
            "elements": [
                "techguns:metalpanel@6"
            ]
        },
        {
            "x": -7,
            "y": -3,
            "z": 8,
            "elements": [
                "ic2:resource@13"
            ]
        },
        {
            "x": 6,
            "y": 3,
            "z": 8,
            "elements": [
                "immersiveengineering:metal_decoration1@1"
            ]
        },
        {
            "x": 6,
            "y": -2,
            "z": 0,
            "elements": [
                "techguns:metalpanel@4"
            ]
        },
        {
            "x": -4,
            "y": 0,
            "z": 0,

            "elements": [
                "modularmachinery:blockcasing@0"
            ]
        },
        {
            "x": -7,
            "y": 2,
            "z": 0,
            "elements": [
                "techguns:metalpanel@6"
            ]
        },
        {
            "x": -9,
            "y": -3,
            "z": 11,
            "elements": [
                "ic2:resource@13"
            ]
        },
        {
            "x": 2,
            "y": -4,
            "z": 5,
            "elements": [
                "techguns:metalpanel@4"
            ]
        },
        {
            "x": -8,
            "y": -3,
            "z": 9,
            "elements": [
                "ic2:resource@13"
            ]
        },
        {
            "x": -6,
            "y": 4,
            "z": 3,
            "elements": [
                "advancedrocketry:blocklens@0"
            ]
        },
        {
            "x": 2,
            "y": 5,
            "z": 4,
            "elements": [
                "techguns:metalpanel@6"
            ]
        },
        {
            "x": 2,
            "y": -2,
            "z": 3,
            "elements": [
                "techguns:metalpanel@4"
            ]
        },
        {
            "x": 3,
            "y": 8,
            "z": 1,
            "elements": [
                "thermalfoundation:glass_alloy@7"
            ]
        },
        {
            "x": 2,
            "y": -1,
            "z": 11,
            "elements": [
                "thermalfoundation:glass_alloy@7"
            ]
        },
        {
            "x": 3,
            "y": 3,
            "z": 14,
            "elements": [
                "techguns:metalpanel@6"
            ]
        },
        {
            "x": -2,
            "y": 12,
            "z": 0,
            "elements": [
                "techguns:metalpanel@4"
            ]
        },
        {
            "x": 5,
            "y": 5,
            "z": 13,
            "elements": [
                "avaritia:block_resource@0"
            ]
        },
        {
            "x": 6,
            "y": 5,
            "z": 1,
            "elements": [
                "immersiveengineering:metal_decoration1@1"
            ]
        },
        {
            "x": -7,
            "y": -4,
            "z": 2,
            "elements": [
                "techguns:metalpanel@4"
            ]
        },
        {
            "x": 0,
            "y": 10,
            "z": 14,
            "elements": [
                "techguns:metalpanel@4"
            ]
        },
        {
            "x": 5,
            "y": 6,
            "z": 13,
            "elements": [
                "avaritia:block_resource@0"
            ]
        },
        {
            "x": 5,
            "y": 10,
            "z": 12,
            "elements": [
                "techguns:metalpanel@4"
            ]
        },
        {
            "x": 5,
            "y": 3,
            "z": 13,
            "elements": [
                "avaritia:block_resource@0"
            ]
        },
        {
            "x": -7,
            "y": -2,
            "z": 5,
            "elements": [
                "techguns:metalpanel@4"
            ]
        },
        {
            "x": -3,
            "y": 11,
            "z": 11,
            "elements": [
                "ic2:resource@13"
            ]
        },
        {
            "x": 5,
            "y": 7,
            "z": 13,
            "elements": [
                "avaritia:block_resource@0"
            ]
        },
        {
            "x": 3,
            "y": 4,
            "z": 8,
            "elements": [
                "libvulpes:coil0@10"
            ]
        },
        {
            "x": 6,
            "y": 5,
            "z": 13,
            "elements": [
                "immersiveengineering:metal_decoration1@1"
            ]
        },
        {
            "x": 5,
            "y": -2,
            "z": 14,
            "elements": [
                "techguns:metalpanel@4"
            ]
        },
        {
            "x": 3,
            "y": 9,
            "z": 12,
            "elements": [
                "thermalfoundation:glass_alloy@7"
            ]
        },
        {
            "x": -6,
            "y": -2,
            "z": 10,
            "elements": [
                "techguns:metalpanel@4"
            ]
        },
        {
            "x": 6,
            "y": 11,
            "z": 12,
            "elements": [
                "ic2:resource@13"
            ]
        },
        {
            "x": 5,
            "y": -3,
            "z": 14,
            "elements": [
                "ic2:resource@13"
            ]
        },
        {
            "x": 0,
            "y": 5,
            "z": 11,
            "elements": [
                "minecraft:quartz_stairs@0"
            ]
        },
        {
            "x": 2,
            "y": -1,
            "z": 14,
            "elements": [
                "techguns:metalpanel@6"
            ]
        },
        {
            "x": 5,
            "y": 12,
            "z": 12,
            "elements": [
                "techguns:metalpanel@4"
            ]
        },
        {
            "x": 6,
            "y": 10,
            "z": 12,
            "elements": [
                "techguns:metalpanel@4"
            ]
        },
        {
            "x": 1,
            "y": 10,
            "z": 0,
            "elements": [
                "techguns:metalpanel@4"
            ]
        },
        {
            "x": 7,
            "y": 10,
            "z": 0,
            "elements": [
                "techguns:metalpanel@4"
            ]
        },
        {
            "x": -7,
            "y": 10,
            "z": 3,
            "elements": [
                "techguns:metalpanel@4"
            ]
        },
        {
            "x": -8,
            "y": 12,
            "z": 3,
            "elements": [
                "techguns:metalpanel@4"
            ]
        },
        {
            "x": 5,
            "y": -4,
            "z": 14,
            "elements": [
                "techguns:metalpanel@4"
            ]
        },
        {
            "x": 2,
            "y": 12,
            "z": 13,
            "elements": [
                "techguns:metalpanel@4"
            ]
        },
        {
            "x": -6,
            "y": 8,
            "z": 3,
            "elements": [
                "thermalfoundation:glass_alloy@7"
            ]
        },
        {
            "x": 4,
            "y": 12,
            "z": 0,
            "elements": [
                "techguns:metalpanel@4"
            ]
        },
        {
            "x": 5,
            "y": 10,
            "z": 13,
            "elements": [
                "techguns:metalpanel@4"
            ]
        },
        {
            "x": 6,
            "y": 10,
            "z": 1,
            "elements": [
                "techguns:metalpanel@4"
            ]
        },
        {
            "x": -7,
            "y": -2,
            "z": 2,
            "elements": [
                "techguns:metalpanel@4"
            ]
        },
        {
            "x": 5,
            "y": 9,
            "z": 13,
            "elements": [
                "avaritia:block_resource@0"
            ]
        },
        {
            "x": 3,
            "y": 12,
            "z": 1,
            "elements": [
                "techguns:metalpanel@4"
            ]
        },
        {
            "x": -7,
            "y": -1,
            "z": 2,
            "elements": [
                "thermalfoundation:glass_alloy@7"
            ]
        },
        {
            "x": 0,
            "y": 12,
            "z": 12,
            "elements": [
                "techguns:metalpanel@4"
            ]
        },
        {
            "x": 6,
            "y": 11,
            "z": 1,
            "elements": [
                "ic2:resource@13"
            ]
        },
        {
            "x": 0,
            "y": 11,
            "z": 12,
            "elements": [
                "ic2:resource@13"
            ]
        },
        {
            "x": 7,
            "y": -3,
            "z": -1,
            "elements": [
                "ic2:resource@13"
            ]
        },
        {
            "x": -7,
            "y": 12,
            "z": 8,
            "elements": [
                "techguns:metalpanel@4"
            ]
        },
        {
            "x": -7,
            "y": 10,
            "z": 6,
            "elements": [
                "techguns:metalpanel@4"
            ]
        },
        {
            "x": -4,
            "y": -2,
            "z": 13,
            "elements": [
                "techguns:metalpanel@4"
            ]
        },
        {
            "x": 4,
            "y": 1,
            "z": 11,
            "elements": [
                "minecraft:end_rod@1"
            ]
        },
        {
            "x": 6,
            "y": -4,
            "z": 11,
            "elements": [
                "techguns:metalpanel@4"
            ]
        },
        {
            "x": 2,
            "y": 1,
            "z": 14,
            "elements": [
                "techguns:metalpanel@6"
            ]
        },
        {
            "x": 5,
            "y": -4,
            "z": 9,
            "elements": [
                "techguns:metalpanel@4"
            ]
        },
        {
            "x": 1,
            "y": 12,
            "z": 1,
            "elements": [
                "techguns:metalpanel@4"
            ]
        },
        {
            "x": 4,
            "y": 10,
            "z": 1,
            "elements": [
                "techguns:metalpanel@4"
            ]
        },
        {
            "x": 1,
            "y": 11,
            "z": -1,
            "elements": [
                "ic2:resource@13"
            ]
        },
        {
            "x": -7,
            "y": -4,
            "z": 13,
            "elements": [
                "techguns:metalpanel@4"
            ]
        },
        {
            "x": -5,
            "y": -3,
            "z": 7,
            "elements": [
                "ic2:resource@13"
            ]
        },
        {
            "x": 3,
            "y": 5,
            "z": 12,
            "elements": [
                "appliedenergistics2:quartz_glass@0"
            ]
        },
        {
            "x": -5,
            "y": -1,
            "z": 2,
            "elements": [
                "thermalfoundation:glass_alloy@7"
            ]
        },
        {
            "x": 6,
            "y": 3,
            "z": 12,
            "elements": [
                "immersiveengineering:metal_decoration1@1"
            ]
        },
        {
            "x": 2,
            "y": 5,
            "z": -1,
            "elements": [
                "techguns:stairs_metal@12"
            ]
        },
        {
            "x": -9,
            "y": -2,
            "z": 1,
            "elements": [
                "techguns:metalpanel@4"
            ]
        },
        {
            "x": 6,
            "y": -2,
            "z": 11,
            "elements": [
                "techguns:metalpanel@4"
            ]
        },
        {
            "x": -6,
            "y": -4,
            "z": 1,
            "elements": [
                "techguns:metalpanel@4"
            ]
        },
        {
            "x": 2,
            "y": 12,
            "z": 6,
            "elements": [
                "techguns:metalpanel@4"
            ]
        },
        {
            "x": 5,
            "y": -2,
            "z": 9,
            "elements": [
                "techguns:metalpanel@4"
            ]
        },
        {
            "x": 3,
            "y": 10,
            "z": 10,
            "elements": [
                "techguns:metalpanel@4"
            ]
        },
        {
            "x": -1,
            "y": -4,
            "z": 13,
            "elements": [
                "techguns:metalpanel@4"
            ]
        },
        {
            "x": 4,
            "y": 5,
            "z": 11,
            "elements": [
                "appliedenergistics2:quartz_glass@0"
            ]
        },
        {
            "x": -10,
            "y": -2,
            "z": 13,
            "elements": [
                "techguns:metalpanel@4"
            ]
        },
        {
            "x": 1,
            "y": 10,
            "z": 11,
            "elements": [
                "techguns:metalpanel@4"
            ]
        },
        {
            "x": 1,
            "y": -3,
            "z": 14,
            "elements": [
                "ic2:resource@13"
            ]
        },
        {
            "x": 2,
            "y": 1,
            "z": 7,
            "elements": [
                "techguns:metalpanel@6"
            ]
        },
        {
            "x": 4,
            "y": 5,
            "z": 4,
            "elements": [
                "techguns:metalpanel@6"
            ]
        },
        {
            "x": 0,
            "y": 3,
            "z": 2,
            "elements": [
                "minecraft:quartz_stairs@4"
            ]
        },
        {
            "x": -6,
            "y": -4,
            "z": 8,
            "elements": [
                "techguns:metalpanel@4"
            ]
        },
        {
            "x": 6,
            "y": 5,
            "z": 10,
            "elements": [
                "immersiveengineering:metal_decoration1@1"
            ]
        },
        {
            "x": -7,
            "y": 3,
            "z": 7,
            "elements": [
                "techguns:metalpanel@6"
            ]
        },
        {
            "x": 0,
            "y": 3,
            "z": 12,
            "elements": [
                "immersiveengineering:metal_decoration1@1"
            ]
        },
        {
            "x": 1,
            "y": 10,
            "z": 4,
            "elements": [
                "techguns:metalpanel@4"
            ]
        },
        {
            "x": -9,
            "y": 5,
            "z": 2,
            "elements": [
                "minecraft:quartz_stairs@0"
            ]
        },
        {
            "x": 2,
            "y": 0,
            "z": 6,
            "elements": [
                "techguns:metalpanel@6"
            ]
        },
        {
            "x": 4,
            "y": 12,
            "z": 3,
            "elements": [
                "techguns:metalpanel@4"
            ]
        },
        {
            "x": 3,
            "y": 1,
            "z": 12,
            "elements": [
                "minecraft:end_rod@1"
            ]
        },
        {
            "x": -8,
            "y": -4,
            "z": 1,
            "elements": [
                "techguns:metalpanel@4"
            ]
        },
        {
            "x": -3,
            "y": 5,
            "z": 12,
            "elements": [
                "immersiveengineering:metal_decoration1@1"
            ]
        },
        {
            "x": 4,
            "y": 5,
            "z": -1,
            "elements": [
                "techguns:stairs_metal@12"
            ]
        },
        {
            "x": -7,
            "y": 3,
            "z": -1,
            "elements": [
                "techguns:metalpanel@6"
            ]
        },
        {
            "x": 3,
            "y": 2,
            "z": 13,
            "elements": [
                "techguns:metalpanel@6"
            ]
        },
        {
            "x": 6,
            "y": -4,
            "z": 1,
            "elements": [
                "techguns:metalpanel@4"
            ]
        },
        {
            "x": 4,
            "y": 9,
            "z": 11,
            "elements": [
                "thermalfoundation:glass_alloy@7"
            ]
        },
        {
            "x": 1,
            "y": 12,
            "z": 11,
            "elements": [
                "techguns:metalpanel@4"
            ]
        },
        {
            "x": 2,
            "y": 4,
            "z": 13,
            "elements": [
                "immersiveengineering:metal_decoration0@7"
            ]
        },
        {
            "x": 1,
            "y": 10,
            "z": 10,
            "elements": [
                "techguns:metalpanel@4"
            ]
        },
        {
            "x": -5,
            "y": 4,
            "z": 1,
            "elements": [
                "appliedenergistics2:quartz_glass@0"
            ]
        },
        {
            "x": 7,
            "y": -3,
            "z": 14,
            "elements": [
                "ic2:resource@13"
            ]
        },
        {
            "x": -5,
            "y": -3,
            "z": -1,
            "elements": [
                "ic2:resource@13"
            ]
        },
        {
            "x": 2,
            "y": 5,
            "z": 7,
            "elements": [
                "techguns:stairs_metal@12"
            ]
        },
        {
            "x": 6,
            "y": 3,
            "z": 10,
            "elements": [
                "immersiveengineering:metal_decoration1@1"
            ]
        },
        {
            "x": -7,
            "y": 9,
            "z": 2,
            "elements": [
                "thermalfoundation:glass_alloy@7"
            ]
        },
        {
            "x": 4,
            "y": -1,
            "z": 14,
            "elements": [
                "techguns:metalpanel@6"
            ]
        },
        {
            "x": 5,
            "y": -4,
            "z": 13,
            "elements": [
                "techguns:metalpanel@4"
            ]
        },
        {
            "x": -8,
            "y": 10,
            "z": 1,
            "elements": [
                "techguns:metalpanel@4"
            ]
        },
        {
            "x": -7,
            "y": 4,
            "z": 8,
            "elements": [
                "immersiveengineering:metal_decoration0@7"
            ]
        },
        {
            "x": 5,
            "y": 10,
            "z": 0,
            "elements": [
                "techguns:metalpanel@4"
            ]
        },
        {
            "x": 1,
            "y": 11,
            "z": 4,
            "elements": [
                "ic2:resource@13"
            ]
        },
        {
            "x": 4,
            "y": -1,
            "z": 7,
            "elements": [
                "techguns:metalpanel@6"
            ]
        },
        {
            "x": 2,
            "y": 5,
            "z": 14,
            "elements": [
                "techguns:stairs_metal@14"
            ]
        },
        {
            "x": -3,
            "y": 5,
            "z": 2,
            "elements": [
                "minecraft:quartz_stairs@1"
            ]
        },
        {
            "x": -5,
            "y": -2,
            "z": 8,
            "elements": [
                "techguns:metalpanel@4"
            ]
        },
        {
            "x": 1,
            "y": 12,
            "z": 4,
            "elements": [
                "techguns:metalpanel@4"
            ]
        },
        {
            "x": 0,
            "y": -3,
            "z": 2,
            "elements": [
                "ic2:resource@13"
            ]
        },
        {
            "x": -7,
            "y": -4,
            "z": 6,
            "elements": [
                "techguns:metalpanel@4"
            ]
        },
        {
            "x": -1,
            "y": 11,
            "z": 14,
            "elements": [
                "ic2:resource@13"
            ]
        },
        {
            "x": -4,
            "y": 12,
            "z": 13,
            "elements": [
                "techguns:metalpanel@4"
            ]
        },
        {
            "x": 1,
            "y": 11,
            "z": 10,
            "elements": [
                "ic2:resource@13"
            ]
        },
        {
            "x": -1,
            "y": 10,
            "z": 13,
            "elements": [
                "techguns:metalpanel@4"
            ]
        },
        {
            "x": 3,
            "y": -2,
            "z": 1,
            "elements": [
                "techguns:metalpanel@4"
            ]
        },
        {
            "x": 2,
            "y": 0,
            "z": 13,
            "elements": [
                "techguns:metalpanel@6"
            ]
        },
        {
            "x": 4,
            "y": 12,
            "z": 10,
            "elements": [
                "techguns:metalpanel@4"
            ]
        },
        {
            "x": 4,
            "y": -1,
            "z": -1,
            "elements": [
                "techguns:metalpanel@6"
            ]
        },
        {
            "x": 5,
            "y": -3,
            "z": 10,
            "elements": [
                "ic2:resource@13"
            ]
        },
        {
            "x": -7,
            "y": -2,
            "z": 9,
            "elements": [
                "techguns:metalpanel@4"
            ]
        },
        {
            "x": 5,
            "y": -4,
            "z": 10,
            "elements": [
                "techguns:metalpanel@4"
            ]
        },
        {
            "x": -5,
            "y": 12,
            "z": 4,
            "elements": [
                "techguns:metalpanel@4"
            ]
        },
        {
            "x": -9,
            "y": -4,
            "z": 0,
            "elements": [
                "techguns:metalpanel@4"
            ]
        },
        {
            "x": 2,
            "y": 4,
            "z": 6,
            "elements": [
                "techguns:metalpanel@6"
            ]
        },
        {
            "x": -5,
            "y": 4,
            "z": 8,
            "elements": [
                "immersiveengineering:metal_decoration0@7"
            ]
        },
        {
            "x": -7,
            "y": -4,
            "z": 9,
            "elements": [
                "techguns:metalpanel@4"
            ]
        },
        {
            "x": -5,
            "y": 9,
            "z": 2,
            "elements": [
                "thermalfoundation:glass_alloy@7"
            ]
        },
        {
            "x": 2,
            "y": -2,
            "z": 13,
            "elements": [
                "techguns:metalpanel@4"
            ]
        },
        {
            "x": -5,
            "y": 5,
            "z": 2,
            "elements": [
                "appliedenergistics2:quartz_glass@0"
            ]
        },
        {
            "x": -7,
            "y": 11,
            "z": 14,
            "elements": [
                "ic2:resource@13"
            ]
        },
        {
            "x": 4,
            "y": 4,
            "z": 3,
            "elements": [
                "appliedenergistics2:quartz_glass@0"
            ]
        },
        {
            "x": -5,
            "y": 12,
            "z": 1,
            "elements": [
                "techguns:metalpanel@4"
            ]
        },
        {
            "x": 4,
            "y": -2,
            "z": 6,
            "elements": [
                "techguns:metalpanel@4"
            ]
        },
        {
            "x": 1,
            "y": 11,
            "z": 3,
            "elements": [
                "ic2:resource@13"
            ]
        },
        {
            "x": -8,
            "y": 0,
            "z": 0,
            "elements": [
                "avaritia:block_resource@0"
            ]
        },
        {
            "x": 1,
            "y": 10,
            "z": 3,
            "elements": [
                "techguns:metalpanel@4"
            ]
        },
        {
            "x": -6,
            "y": 12,
            "z": 13,
            "elements": [
                "techguns:metalpanel@4"
            ]
        },
        {
            "x": -3,
            "y": 10,
            "z": 13,
            "elements": [
                "techguns:metalpanel@4"
            ]
        },
        {
            "x": 2,
            "y": -1,
            "z": -1,
            "elements": [
                "techguns:metalpanel@6"
            ]
        },
        {
            "x": 2,
            "y": -4,
            "z": 1,
            "elements": [
                "techguns:metalpanel@4"
            ]
        },
        {
            "x": 2,
            "y": 1,
            "z": -1,
            "elements": [
                "techguns:metalpanel@6"
            ]
        },
        {
            "x": -3,
            "y": -2,
            "z": 1,
            "elements": [
                "techguns:metalpanel@4"
            ]
        },
        {
            "x": -5,
            "y": 11,
            "z": 7,
            "elements": [
                "ic2:resource@13"
            ]
        },
        {
            "x": -1,
            "y": -3,
            "z": -1,
            "elements": [
                "ic2:resource@13"
            ]
        },
        {
            "x": -5,
            "y": -3,
            "z": 14,
            "elements": [
                "ic2:resource@13"
            ]
        },
        {
            "x": 6,
            "y": 11,
            "z": 2,
            "elements": [
                "ic2:resource@13"
            ]
        },
        {
            "x": 5,
            "y": 6,
            "z": 0,
            "elements": [
                "avaritia:block_resource@0"
            ]
        },
        {
            "x": -6,
            "y": 1,
            "z": 14,
            "elements": [
                "techguns:metalpanel@6"
            ]
        },
        {
            "x": 1,
            "y": -4,
            "z": 13,
            "elements": [
                "techguns:metalpanel@4"
            ]
        },
        {
            "x": -6,
            "y": 4,
            "z": 6,
            "elements": [
                "techguns:metalpanel@6"
            ]
        },
        {
            "x": -6,
            "y": 1,
            "z": 7,
            "elements": [
                "techguns:metalpanel@6"
            ]
        },
        {
            "x": -8,
            "y": 5,
            "z": 14,
            "elements": [
                "immersiveengineering:metal_decoration1@1"
            ]
        },
        {
            "x": 0,
            "y": -3,
            "z": 12,
            "elements": [
                "ic2:resource@13"
            ]
        },
        {
            "x": 2,
            "y": 12,
            "z": 0,
            "elements": [
                "techguns:metalpanel@4"
            ]
        },
        {
            "x": -7,
            "y": 12,
            "z": 1,
            "elements": [
                "techguns:metalpanel@4"
            ]
        },
        {
            "x": -9,
            "y": 3,
            "z": 7,
            "elements": [
                "immersiveengineering:metal_decoration1@1"
            ]
        },
        {
            "x": -4,
            "y": 10,
            "z": 1,
            "elements": [
                "techguns:metalpanel@4"
            ]
        },
        {
            "x": -7,
            "y": 11,
            "z": -1,
            "elements": [
                "ic2:resource@13"
            ]
        },
        {
            "x": 2,
            "y": -2,
            "z": 6,
            "elements": [
                "techguns:metalpanel@4"
            ]
        },
        {
            "x": -5,
            "y": 5,
            "z": 12,
            "elements": [
                "appliedenergistics2:quartz_glass@0"
            ]
        },
        {
            "x": -2,
            "y": 3,
            "z": 12,
            "elements": [
                "immersiveengineering:metal_decoration1@1"
            ]
        },
        {
            "x": 4,
            "y": 10,
            "z": 8,
            "elements": [
                "techguns:metalpanel@4"
            ]
        },
        {
            "x": -5,
            "y": 1,
            "z": 2,
            "elements": [
                "minecraft:end_rod@1"
            ]
        },
        {
            "x": -6,
            "y": 5,
            "z": -1,
            "elements": [
                "techguns:stairs_metal@12"
            ]
        },
        {
            "x": 1,
            "y": -3,
            "z": -1,
            "elements": [
                "ic2:resource@13"
            ]
        },
        {
            "x": -7,
            "y": -3,
            "z": 14,
            "elements": [
                "ic2:resource@13"
            ]
        },
        {
            "x": -6,
            "y": 12,
            "z": 6,
            "elements": [
                "techguns:metalpanel@4"
            ]
        },
        {
            "x": -5,
            "y": 10,
            "z": 6,
            "elements": [
                "techguns:metalpanel@4"
            ]
        },
        {
            "x": -7,
            "y": 3,
            "z": 14,
            "elements": [
                "techguns:metalpanel@6"
            ]
        },
        {
            "x": -2,
            "y": -2,
            "z": 13,
            "elements": [
                "techguns:metalpanel@4"
            ]
        },
        {
            "x": -6,
            "y": 10,
            "z": 1,
            "elements": [
                "techguns:metalpanel@4"
            ]
        },
        {
            "x": -5,
            "y": 11,
            "z": -1,
            "elements": [
                "ic2:resource@13"
            ]
        },
        {
            "x": -9,
            "y": 12,
            "z": 1,
            "elements": [
                "techguns:metalpanel@4"
            ]
        },
        {
            "x": -9,
            "y": -4,
            "z": 13,
            "elements": [
                "techguns:metalpanel@4"
            ]
        },
        {
            "x": -10,
            "y": 12,
            "z": 13,
            "elements": [
                "techguns:metalpanel@4"
            ]
        },
        {
            "x": -7,
            "y": 10,
            "z": 13,
            "elements": [
                "techguns:metalpanel@4"
            ]
        },
        {
            "x": -5,
            "y": -4,
            "z": 6,
            "elements": [
                "techguns:metalpanel@4"
            ]
        },
        {
            "x": -6,
            "y": 0,
            "z": 6,
            "elements": [
                "techguns:metalpanel@6"
            ]
        },
        {
            "x": -7,
            "y": -3,
            "z": 7,
            "elements": [
                "ic2:resource@13"
            ]
        },
        {
            "x": 0,
            "y": -4,
            "z": 1,
            "elements": [
                "techguns:metalpanel@4"
            ]
        },
        {
            "x": -6,
            "y": -4,
            "z": 5,
            "elements": [
                "techguns:metalpanel@4"
            ]
        },
        {
            "x": -6,
            "y": 4,
            "z": 13,
            "elements": [
                "taiga:nucleum_block@0"
            ]
        },
        {
            "x": 1,
            "y": -2,
            "z": 1,
            "elements": [
                "techguns:metalpanel@4"
            ]
        },
        {
            "x": -1,
            "y": -3,
            "z": 14,
            "elements": [
                "ic2:resource@13"
            ]
        },
        {
            "x": -5,
            "y": 11,
            "z": 5,
            "elements": [
                "ic2:resource@13"
            ]
        },
        {
            "x": 3,
            "y": -3,
            "z": -1,
            "elements": [
                "ic2:resource@13"
            ]
        },
        {
            "x": 3,
            "y": 4,
            "z": 1,
            "elements": [
                "advancedrocketry:blocklens@0"
            ]
        },
        {
            "x": -8,
            "y": -2,
            "z": 13,
            "elements": [
                "techguns:metalpanel@4"
            ]
        },
        {
            "x": -3,
            "y": -4,
            "z": 13,
            "elements": [
                "techguns:metalpanel@4"
            ]
        },
        {
            "x": 4,
            "y": 7,
            "z": 2,
            "elements": [
                "minecraft:end_rod@0"
            ]
        },
        {
            "x": -8,
            "y": 0,
            "z": 13,
            "elements": [
                "avaritia:block_resource@0"
            ]
        },
        {
            "x": 4,
            "y": 10,
            "z": 5,
            "elements": [
                "techguns:metalpanel@4"
            ]
        },
        {
            "x": -5,
            "y": 12,
            "z": 5,
            "elements": [
                "techguns:metalpanel@4"
            ]
        },
        {
            "x": -5,
            "y": 2,
            "z": 13,
            "elements": [
                "techguns:metalpanel@6"
            ]
        },
        {
            "x": -6,
            "y": 5,
            "z": 7,
            "elements": [
                "techguns:stairs_metal@12"
            ]
        },
        {
            "x": -9,
            "y": 11,
            "z": 14,
            "elements": [
                "ic2:resource@13"
            ]
        },
        {
            "x": 6,
            "y": 3,
            "z": 2,
            "elements": [
                "minecraft:quartz_stairs@5"
            ]
        },
        {
            "x": -3,
            "y": 12,
            "z": 1,
            "elements": [
                "techguns:metalpanel@4"
            ]
        },
        {
            "x": -5,
            "y": 3,
            "z": 7,
            "elements": [
                "techguns:metalpanel@6"
            ]
        },
        {
            "x": 0,
            "y": 10,
            "z": 1,
            "elements": [
                "techguns:metalpanel@4"
            ]
        },
        {
            "x": -7,
            "y": 2,
            "z": 6,
            "elements": [
                "techguns:metalpanel@6"
            ]
        },
        {
            "x": -9,
            "y": 5,
            "z": 12,
            "elements": [
                "immersiveengineering:metal_decoration1@1"
            ]
        },
        {
            "x": -6,
            "y": 3,
            "z": 12,
            "elements": [
                "appliedenergistics2:quartz_glass@0"
            ]
        },
        {
            "x": 4,
            "y": -4,
            "z": 8,
            "elements": [
                "techguns:metalpanel@4"
            ]
        },
        {
            "x": 6,
            "y": 3,
            "z": 9,
            "elements": [
                "immersiveengineering:metal_decoration1@1"
            ]
        },
        {
            "x": -9,
            "y": 10,
            "z": 13,
            "elements": [
                "techguns:metalpanel@4"
            ]
        },
        {
            "x": -5,
            "y": 12,
            "z": 8,
            "elements": [
                "techguns:metalpanel@4"
            ]
        },
        {
            "x": 4,
            "y": 1,
            "z": -1,
            "elements": [
                "techguns:metalpanel@6"
            ]
        },
        {
            "x": -5,
            "y": -2,
            "z": 1,
            "elements": [
                "techguns:metalpanel@4"
            ]
        },
        {
            "x": -7,
            "y": 4,
            "z": 1,
            "elements": [
                "appliedenergistics2:quartz_glass@0"
            ]
        },
        {
            "x": -5,
            "y": 3,
            "z": -1,
            "elements": [
                "techguns:metalpanel@6"
            ]
        },
        {
            "x": 4,
            "y": -4,
            "z": 1,
            "elements": [
                "techguns:metalpanel@4"
            ]
        },
        {
            "x": -7,
            "y": 11,
            "z": 7,
            "elements": [
                "ic2:resource@13"
            ]
        },
        {
            "x": -8,
            "y": 4,
            "z": 13,
            "elements": [
                "avaritia:block_resource@0"
            ]
        },
        {
            "x": 0,
            "y": 11,
            "z": 2,
            "elements": [
                "ic2:resource@13"
            ]
        },
        {
            "x": 3,
            "y": -2,
            "z": 5,
            "elements": [
                "techguns:metalpanel@4"
            ]
        },
        {
            "x": 3,
            "y": 0,
            "z": 1,
            "elements": [
                "thermalfoundation:glass_alloy@7"
            ]
        },
        {
            "x": 3,
            "y": -2,
            "z": 8,
            "elements": [
                "techguns:metalpanel@4"
            ]
        },
        {
            "x": -3,
            "y": -3,
            "z": -1,
            "elements": [
                "ic2:resource@13"
            ]
        },
        {
            "x": -6,
            "y": -2,
            "z": 13,
            "elements": [
                "techguns:metalpanel@4"
            ]
        },
        {
            "x": -7,
            "y": 2,
            "z": 13,
            "elements": [
                "techguns:metalpanel@6"
            ]
        },
        {
            "x": -6,
            "y": 0,
            "z": 13,
            "elements": [
                "techguns:metalpanel@6"
            ]
        },
        {
            "x": -6,
            "y": 5,
            "z": 14,
            "elements": [
                "techguns:stairs_metal@14"
            ]
        },
        {
            "x": 4,
            "y": 3,
            "z": 2,
            "elements": [
                "appliedenergistics2:quartz_glass@0"
            ]
        },
        {
            "x": -1,
            "y": 11,
            "z": -1,
            "elements": [
                "ic2:resource@13"
            ]
        },
        {
            "x": 3,
            "y": 5,
            "z": 9,
            "elements": [
                "techguns:metalpanel@6"
            ]
        },
        {
            "x": -4,
            "y": 3,
            "z": 12,
            "elements": [
                "immersiveengineering:metal_decoration1@1"
            ]
        },
        {
            "x": -5,
            "y": 2,
            "z": 6,
            "elements": [
                "techguns:metalpanel@6"
            ]
        },
        {
            "x": -6,
            "y": -1,
            "z": 7,
            "elements": [
                "techguns:metalpanel@6"
            ]
        },
        {
            "x": -5,
            "y": -4,
            "z": 13,
            "elements": [
                "techguns:metalpanel@4"
            ]
        },
        {
            "x": -7,
            "y": 5,
            "z": 12,
            "elements": [
                "appliedenergistics2:quartz_glass@0"
            ]
        },
        {
            "x": -5,
            "y": 12,
            "z": 11,
            "elements": [
                "techguns:metalpanel@4"
            ]
        },
        {
            "x": 6,
            "y": -3,
            "z": 2,
            "elements": [
                "ic2:resource@13"
            ]
        },
        {
            "x": 4,
            "y": 0,
            "z": 13,
            "elements": [
                "techguns:metalpanel@6"
            ]
        },
        {
            "x": 3,
            "y": -2,
            "z": 14,
            "elements": [
                "techguns:metalpanel@4"
            ]
        },
        {
            "x": 4,
            "y": 4,
            "z": 12,
            "elements": [
                "appliedenergistics2:quartz_glass@0"
            ]
        },
        {
            "x": -6,
            "y": 1,
            "z": 10,
            "elements": [
                "minecraft:end_rod@1"
            ]
        },
        {
            "x": -6,
            "y": -1,
            "z": -1,
            "elements": [
                "techguns:metalpanel@6"
            ]
        },
        {
            "x": -8,
            "y": 8,
            "z": 13,
            "elements": [
                "avaritia:block_resource@0"
            ]
        },
        {
            "x": 3,
            "y": -1,
            "z": 13,
            "elements": [
                "techguns:metalpanel@6"
            ]
        },
        {
            "x": 3,
            "y": -2,
            "z": 9,
            "elements": [
                "techguns:metalpanel@4"
            ]
        },
        {
            "x": -5,
            "y": 3,
            "z": 10,
            "elements": [
                "appliedenergistics2:quartz_glass@0"
            ]
        },
        {
            "x": 0,
            "y": -1,
            "z": 0,

            "elements": [
                "item_out"
            ]
        },
        {
            "x": -5,
            "y": 0,
            "z": 6,
            "elements": [
                "techguns:metalpanel@6"
            ]
        },
        {
            "x": -5,
            "y": 10,
            "z": 11,
            "elements": [
                "techguns:metalpanel@4"
            ]
        },
        {
            "x": -8,
            "y": 7,
            "z": 13,
            "elements": [
                "avaritia:block_resource@0"
            ]
        },
        {
            "x": -2,
            "y": 10,
            "z": 13,
            "elements": [
                "techguns:metalpanel@4"
            ]
        },
        {
            "x": -6,
            "y": -4,
            "z": -1,
            "elements": [
                "techguns:metalpanel@4"
            ]
        },
        {
            "x": -5,
            "y": 3,
            "z": 5,
            "elements": [
                "techguns:metalpanel@6"
            ]
        },
        {
            "x": -6,
            "y": -1,
            "z": 6,
            "elements": [
                "techguns:metalpanel@6"
            ]
        },
        {
            "x": -9,
            "y": -2,
            "z": -1,
            "elements": [
                "techguns:metalpanel@4"
            ]
        },
        {
            "x": -5,
            "y": 12,
            "z": 14,
            "elements": [
                "techguns:metalpanel@4"
            ]
        },
        {
            "x": 3,
            "y": 9,
            "z": 3,
            "elements": [
                "thermalfoundation:glass_alloy@7"
            ]
        },
        {
            "x": -6,
            "y": -2,
            "z": 6,
            "elements": [
                "techguns:metalpanel@4"
            ]
        },
        {
            "x": 2,
            "y": 5,
            "z": 1,
            "elements": [
                "appliedenergistics2:quartz_glass@0"
            ]
        },
        {
            "x": 4,
            "y": 2,
            "z": 13,
            "elements": [
                "techguns:metalpanel@6"
            ]
        },
        {
            "x": -7,
            "y": -2,
            "z": 4,
            "elements": [
                "techguns:metalpanel@4"
            ]
        },
        {
            "x": -7,
            "y": -4,
            "z": 11,
            "elements": [
                "techguns:metalpanel@4"
            ]
        },
        {
            "x": -2,
            "y": 1,
            "z": 0,

            "elements": [
                "modularmachinery:blockcasing@0"
            ]
        },
        {
            "x": 1,
            "y": 10,
            "z": 12,
            "elements": [
                "techguns:metalpanel@4"
            ]
        },
        {
            "x": -6,
            "y": -3,
            "z": -1,
            "elements": [
                "ic2:resource@13"
            ]
        },
        {
            "x": 6,
            "y": 3,
            "z": 3,
            "elements": [
                "immersiveengineering:metal_decoration1@1"
            ]
        },
        {
            "x": -5,
            "y": 11,
            "z": 14,
            "elements": [
                "ic2:resource@13"
            ]
        },
        {
            "x": -8,
            "y": 12,
            "z": 13,
            "elements": [
                "techguns:metalpanel@4"
            ]
        },
        {
            "x": 2,
            "y": 11,
            "z": 8,
            "elements": [
                "ic2:resource@13"
            ]
        },
        {
            "x": 3,
            "y": 1,
            "z": 3,
            "elements": [
                "minecraft:end_rod@1"
            ]
        },
        {
            "x": -7,
            "y": 3,
            "z": 10,
            "elements": [
                "appliedenergistics2:quartz_glass@0"
            ]
        },
        {
            "x": 3,
            "y": 4,
            "z": 4,
            "elements": [
                "taiga:nucleum_block@0"
            ]
        },
        {
            "x": 4,
            "y": 4,
            "z": 13,
            "elements": [
                "immersiveengineering:metal_decoration0@7"
            ]
        },
        {
            "x": -7,
            "y": 11,
            "z": 5,
            "elements": [
                "ic2:resource@13"
            ]
        },
        {
            "x": -2,
            "y": -1,
            "z": 0,

            "elements": [
                "modularmachinery:blockcasing@0"
            ]
        },
        {
            "x": -8,
            "y": 10,
            "z": 13,
            "elements": [
                "techguns:metalpanel@4"
            ]
        },
        {
            "x": -6,
            "y": -4,
            "z": 6,
            "elements": [
                "techguns:metalpanel@4"
            ]
        },
        {
            "x": 2,
            "y": 12,
            "z": 8,
            "elements": [
                "techguns:metalpanel@4"
            ]
        },
        {
            "x": -5,
            "y": 5,
            "z": 13,
            "elements": [
                "techguns:metalpanel@6"
            ]
        },
        {
            "x": 4,
            "y": 3,
            "z": 13,
            "elements": [
                "techguns:metalpanel@6"
            ]
        },
        {
            "x": -8,
            "y": 12,
            "z": 11,
            "elements": [
                "techguns:metalpanel@4"
            ]
        },
        {
            "x": -8,
            "y": 9,
            "z": 0,
            "elements": [
                "avaritia:block_resource@0"
            ]
        },
        {
            "x": -2,
            "y": 11,
            "z": 13,
            "elements": [
                "ic2:resource@13"
            ]
        },
        {
            "x": -2,
            "y": 10,
            "z": 14,
            "elements": [
                "techguns:metalpanel@4"
            ]
        },
        {
            "x": 2,
            "y": 10,
            "z": 8,
            "elements": [
                "techguns:metalpanel@4"
            ]
        },
        {
            "x": -2,
            "y": 12,
            "z": 13,
            "elements": [
                "techguns:metalpanel@4"
            ]
        },
        {
            "x": 4,
            "y": 12,
            "z": 12,
            "elements": [
                "techguns:metalpanel@4"
            ]
        },
        {
            "x": 0,
            "y": -2,
            "z": 11,
            "elements": [
                "techguns:metalpanel@4"
            ]
        },
        {
            "x": -8,
            "y": -4,
            "z": 9,
            "elements": [
                "techguns:metalpanel@4"
            ]
        },
        {
            "x": -6,
            "y": 5,
            "z": 5,
            "elements": [
                "techguns:metalpanel@6"
            ]
        },
        {
            "x": 0,
            "y": 3,
            "z": 3,
            "elements": [
                "immersiveengineering:metal_decoration1@1"
            ]
        },
        {
            "x": -9,
            "y": 5,
            "z": 3,
            "elements": [
                "immersiveengineering:metal_decoration1@1"
            ]
        },
        {
            "x": -9,
            "y": 3,
            "z": 10,
            "elements": [
                "immersiveengineering:metal_decoration1@1"
            ]
        },
        {
            "x": -5,
            "y": 5,
            "z": 14,
            "elements": [
                "techguns:stairs_metal@14"
            ]
        },
        {
            "x": 6,
            "y": -4,
            "z": 14,
            "elements": [
                "techguns:metalpanel@4"
            ]
        },
        {
            "x": 4,
            "y": 5,
            "z": 6,
            "elements": [
                "techguns:stairs_metal@14"
            ]
        },
        {
            "x": 1,
            "y": 3,
            "z": 12,
            "elements": [
                "immersiveengineering:metal_decoration1@1"
            ]
        },
        {
            "x": -5,
            "y": -3,
            "z": 5,
            "elements": [
                "ic2:resource@13"
            ]
        },
        {
            "x": -4,
            "y": 1,
            "z": 0,

            "elements": [
                "modularmachinery:blockcasing@0"
            ]
        },
        {
            "x": -5,
            "y": 4,
            "z": 14,
            "elements": [
                "immersiveengineering:metal_decoration0@7"
            ]
        },
        {
            "x": -9,
            "y": -2,
            "z": 14,
            "elements": [
                "techguns:metalpanel@4"
            ]
        },
        {
            "x": 5,
            "y": -2,
            "z": 4,
            "elements": [
                "techguns:metalpanel@4"
            ]
        },
        {
            "x": 4,
            "y": 1,
            "z": 7,
            "elements": [
                "techguns:metalpanel@6"
            ]
        },
        {
            "x": -5,
            "y": 3,
            "z": 14,
            "elements": [
                "techguns:metalpanel@6"
            ]
        },
        {
            "x": -9,
            "y": 10,
            "z": 11,
            "elements": [
                "techguns:metalpanel@4"
            ]
        },
        {
            "x": 2,
            "y": -4,
            "z": 4,
            "elements": [
                "techguns:metalpanel@4"
            ]
        },
        {
            "x": -6,
            "y": 9,
            "z": 10,
            "elements": [
                "thermalfoundation:glass_alloy@7"
            ]
        },
        {
            "x": 1,
            "y": 12,
            "z": 9,
            "elements": [
                "techguns:metalpanel@4"
            ]
        },
        {
            "x": -5,
            "y": 3,
            "z": 0,
            "elements": [
                "techguns:metalpanel@6"
            ]
        },
        {
            "x": 4,
            "y": -1,
            "z": 0,
            "elements": [
                "techguns:metalpanel@6"
            ]
        },
        {
            "x": 5,
            "y": 12,
            "z": 1,
            "elements": [
                "techguns:metalpanel@4"
            ]
        },
        {
            "x": -1,
            "y": 11,
            "z": 0,
            "elements": [
                "ic2:resource@13"
            ]
        },
        {
            "x": -6,
            "y": -2,
            "z": 11,
            "elements": [
                "techguns:metalpanel@4"
            ]
        },
        {
            "x": 3,
            "y": -4,
            "z": 12,
            "elements": [
                "techguns:metalpanel@4"
            ]
        },
        {
            "x": 4,
            "y": 1,
            "z": 6,
            "elements": [
                "techguns:metalpanel@6"
            ]
        },
        {
            "x": 4,
            "y": 2,
            "z": 14,
            "elements": [
                "techguns:metalpanel@6"
            ]
        },
        {
            "x": 6,
            "y": -3,
            "z": 14,
            "elements": [
                "ic2:resource@13"
            ]
        },
        {
            "x": -3,
            "y": -4,
            "z": 11,
            "elements": [
                "techguns:metalpanel@4"
            ]
        },
        {
            "x": 2,
            "y": 1,
            "z": 0,
            "elements": [
                "techguns:metalpanel@6"
            ]
        },
        {
            "x": -8,
            "y": 5,
            "z": 0,
            "elements": [
                "avaritia:block_resource@0"
            ]
        },
        {
            "x": -8,
            "y": 10,
            "z": 14,
            "elements": [
                "techguns:metalpanel@4"
            ]
        },
        {
            "x": -5,
            "y": 0,
            "z": 14,
            "elements": [
                "techguns:metalpanel@6"
            ]
        },
        {
            "x": -5,
            "y": 10,
            "z": 12,
            "elements": [
                "techguns:metalpanel@4"
            ]
        },
        {
            "x": 5,
            "y": 10,
            "z": 1,
            "elements": [
                "techguns:metalpanel@4"
            ]
        },
        {
            "x": -6,
            "y": -1,
            "z": 14,
            "elements": [
                "techguns:metalpanel@6"
            ]
        },
        {
            "x": -3,
            "y": 3,
            "z": 10,
            "elements": [
                "immersiveengineering:metal_decoration1@1"
            ]
        },
        {
            "x": 7,
            "y": -3,
            "z": 0,
            "elements": [
                "ic2:resource@13"
            ]
        },
        {
            "x": 3,
            "y": -4,
            "z": 13,
            "elements": [
                "techguns:metalpanel@4"
            ]
        },
        {
            "x": -6,
            "y": -1,
            "z": 0,
            "elements": [
                "techguns:metalpanel@6"
            ]
        },
        {
            "x": -6,
            "y": 5,
            "z": 10,
            "elements": [
                "appliedenergistics2:quartz_glass@0"
            ]
        },
        {
            "x": 0,
            "y": -4,
            "z": 14,
            "elements": [
                "techguns:metalpanel@4"
            ]
        },
        {
            "x": -3,
            "y": -2,
            "z": 14,
            "elements": [
                "techguns:metalpanel@4"
            ]
        },
        {
            "x": 2,
            "y": 5,
            "z": 0,
            "elements": [
                "techguns:metalpanel@6"
            ]
        },
        {
            "x": -7,
            "y": 3,
            "z": 5,
            "elements": [
                "techguns:metalpanel@6"
            ]
        },
        {
            "x": -5,
            "y": 12,
            "z": 9,
            "elements": [
                "techguns:metalpanel@4"
            ]
        },
        {
            "x": 0,
            "y": -3,
            "z": 14,
            "elements": [
                "ic2:resource@13"
            ]
        },
        {
            "x": -4,
            "y": -4,
            "z": 4,
            "elements": [
                "techguns:metalpanel@4"
            ]
        },
        {
            "x": -8,
            "y": 10,
            "z": 9,
            "elements": [
                "techguns:metalpanel@4"
            ]
        },
        {
            "x": -5,
            "y": -4,
            "z": 11,
            "elements": [
                "techguns:metalpanel@4"
            ]
        },
        {
            "x": 3,
            "y": 5,
            "z": 3,
            "elements": [
                "appliedenergistics2:quartz_glass@0"
            ]
        },
        {
            "x": -8,
            "y": 12,
            "z": 12,
            "elements": [
                "techguns:metalpanel@4"
            ]
        },
        {
            "x": -5,
            "y": 1,
            "z": 14,
            "elements": [
                "techguns:metalpanel@6"
            ]
        },
        {
            "x": -4,
            "y": -2,
            "z": 11,
            "elements": [
                "techguns:metalpanel@4"
            ]
        },
        {
            "x": 1,
            "y": 5,
            "z": 12,
            "elements": [
                "immersiveengineering:metal_decoration1@1"
            ]
        },
        {
            "x": 5,
            "y": 3,
            "z": 0,
            "elements": [
                "avaritia:block_resource@0"
            ]
        },
        {
            "x": 3,
            "y": -2,
            "z": 13,
            "elements": [
                "techguns:metalpanel@4"
            ]
        },
        {
            "x": -8,
            "y": 10,
            "z": 4,
            "elements": [
                "techguns:metalpanel@4"
            ]
        },
        {
            "x": 6,
            "y": 4,
            "z": 11,
            "elements": [
                "redstonearsenal:storage@0"
            ]
        },
        {
            "x": -5,
            "y": -2,
            "z": 9,
            "elements": [
                "techguns:metalpanel@4"
            ]
        },
        {
            "x": 3,
            "y": -1,
            "z": 3,
            "elements": [
                "thermalfoundation:glass_alloy@7"
            ]
        },
        {
            "x": 2,
            "y": 1,
            "z": 2,
            "elements": [
                "minecraft:end_rod@1"
            ]
        },
        {
            "x": -8,
            "y": 1,
            "z": 0,
            "elements": [
                "avaritia:block_resource@0"
            ]
        },
        {
            "x": 7,
            "y": 11,
            "z": -1,
            "elements": [
                "ic2:resource@13"
            ]
        },
        {
            "x": -8,
            "y": 11,
            "z": 3,
            "elements": [
                "ic2:resource@13"
            ]
        },
        {
            "x": -6,
            "y": 12,
            "z": 11,
            "elements": [
                "techguns:metalpanel@4"
            ]
        },
        {
            "x": 3,
            "y": 10,
            "z": 11,
            "elements": [
                "techguns:metalpanel@4"
            ]
        },
        {
            "x": 2,
            "y": 12,
            "z": 7,
            "elements": [
                "techguns:metalpanel@4"
            ]
        },
        {
            "x": 2,
            "y": 11,
            "z": 14,
            "elements": [
                "ic2:resource@13"
            ]
        },
        {
            "x": -5,
            "y": 4,
            "z": 9,
            "elements": [
                "immersiveengineering:metal_decoration0@7"
            ]
        },
        {
            "x": 6,
            "y": -2,
            "z": 12,
            "elements": [
                "techguns:metalpanel@4"
            ]
        },
        {
            "x": -8,
            "y": -1,
            "z": 0,
            "elements": [
                "avaritia:block_resource@0"
            ]
        },
        {
            "x": 6,
            "y": 11,
            "z": 11,
            "elements": [
                "ic2:resource@13"
            ]
        },
        {
            "x": -7,
            "y": 4,
            "z": 4,
            "elements": [
                "immersiveengineering:metal_decoration0@7"
            ]
        },
        {
            "x": 4,
            "y": -2,
            "z": 2,
            "elements": [
                "techguns:metalpanel@4"
            ]
        },
        {
            "x": 2,
            "y": 0,
            "z": 2,
            "elements": [
                "thermalfoundation:glass_alloy@7"
            ]
        },
        {
            "x": 4,
            "y": 5,
            "z": 0,
            "elements": [
                "techguns:metalpanel@6"
            ]
        },
        {
            "x": 2,
            "y": 3,
            "z": 2,
            "elements": [
                "appliedenergistics2:quartz_glass@0"
            ]
        },
        {
            "x": 6,
            "y": -3,
            "z": 12,
            "elements": [
                "ic2:resource@13"
            ]
        },
        {
            "x": 1,
            "y": -2,
            "z": 4,
            "elements": [
                "techguns:metalpanel@4"
            ]
        },
        {
            "x": -4,
            "y": 12,
            "z": 2,
            "elements": [
                "techguns:metalpanel@4"
            ]
        },
        {
            "x": 0,
            "y": 5,
            "z": 10,
            "elements": [
                "immersiveengineering:metal_decoration1@1"
            ]
        },
        {
            "x": 4,
            "y": 10,
            "z": 14,
            "elements": [
                "techguns:metalpanel@4"
            ]
        },
        {
            "x": 1,
            "y": 5,
            "z": 3,
            "elements": [
                "immersiveengineering:metal_decoration1@1"
            ]
        },
        {
            "x": 5,
            "y": 10,
            "z": 2,
            "elements": [
                "techguns:metalpanel@4"
            ]
        },
        {
            "x": 3,
            "y": 3,
            "z": 5,
            "elements": [
                "techguns:metalpanel@6"
            ]
        },
        {
            "x": -2,
            "y": 3,
            "z": 3,
            "elements": [
                "immersiveengineering:metal_decoration1@1"
            ]
        },
        {
            "x": 4,
            "y": 4,
            "z": 7,
            "elements": [
                "techguns:metalpanel@6"
            ]
        },
        {
            "x": 1,
            "y": 3,
            "z": 10,
            "elements": [
                "immersiveengineering:metal_decoration1@1"
            ]
        },
        {
            "x": -6,
            "y": 10,
            "z": 4,
            "elements": [
                "techguns:metalpanel@4"
            ]
        },
        {
            "x": -5,
            "y": 4,
            "z": 4,
            "elements": [
                "immersiveengineering:metal_decoration0@7"
            ]
        },
        {
            "x": 4,
            "y": 5,
            "z": 7,
            "elements": [
                "techguns:stairs_metal@12"
            ]
        },
        {
            "x": 2,
            "y": 4,
            "z": 2,
            "elements": [
                "appliedenergistics2:quartz_glass@0"
            ]
        },
        {
            "x": -4,
            "y": -3,
            "z": 3,
            "elements": [
                "ic2:resource@13"
            ]
        },
        {
            "x": 0,
            "y": 12,
            "z": 11,
            "elements": [
                "techguns:metalpanel@4"
            ]
        },
        {
            "x": 2,
            "y": 7,
            "z": 2,
            "elements": [
                "minecraft:end_rod@0"
            ]
        },
        {
            "x": 5,
            "y": 12,
            "z": 14,
            "elements": [
                "techguns:metalpanel@4"
            ]
        },
        {
            "x": 7,
            "y": 12,
            "z": -1,
            "elements": [
                "techguns:metalpanel@4"
            ]
        },
        {
            "x": -9,
            "y": -4,
            "z": 11,
            "elements": [
                "techguns:metalpanel@4"
            ]
        },
        {
            "x": -2,
            "y": 5,
            "z": 10,
            "elements": [
                "immersiveengineering:metal_decoration1@1"
            ]
        },
        {
            "x": 4,
            "y": 3,
            "z": 7,
            "elements": [
                "techguns:metalpanel@6"
            ]
        },
        {
            "x": -7,
            "y": 3,
            "z": 0,
            "elements": [
                "techguns:metalpanel@6"
            ]
        },
        {
            "x": 4,
            "y": 1,
            "z": 0,
            "elements": [
                "techguns:metalpanel@6"
            ]
        },
        {
            "x": 2,
            "y": 5,
            "z": 5,
            "elements": [
                "techguns:metalpanel@6"
            ]
        },
        {
            "x": 2,
            "y": 5,
            "z": 2,
            "elements": [
                "appliedenergistics2:quartz_glass@0"
            ]
        },
        {
            "x": -6,
            "y": 3,
            "z": 3,
            "elements": [
                "appliedenergistics2:quartz_glass@0"
            ]
        },
        {
            "x": -8,
            "y": -2,
            "z": 2,
            "elements": [
                "techguns:metalpanel@4"
            ]
        },
        {
            "x": -7,
            "y": 12,
            "z": 4,
            "elements": [
                "techguns:metalpanel@4"
            ]
        },
        {
            "x": -4,
            "y": 10,
            "z": 4,
            "elements": [
                "techguns:metalpanel@4"
            ]
        },
        {
            "x": -4,
            "y": 11,
            "z": 3,
            "elements": [
                "ic2:resource@13"
            ]
        },
        {
            "x": 2,
            "y": 8,
            "z": 2,
            "elements": [
                "thermalfoundation:glass_alloy@7"
            ]
        },
        {
            "x": 4,
            "y": 12,
            "z": 13,
            "elements": [
                "techguns:metalpanel@4"
            ]
        },
        {
            "x": 5,
            "y": 12,
            "z": -1,
            "elements": [
                "techguns:metalpanel@4"
            ]
        },
        {
            "x": -6,
            "y": 10,
            "z": 9,
            "elements": [
                "techguns:metalpanel@4"
            ]
        },
        {
            "x": -9,
            "y": 3,
            "z": 5,
            "elements": [
                "immersiveengineering:metal_decoration1@1"
            ]
        },
        {
            "x": -6,
            "y": -4,
            "z": 4,
            "elements": [
                "techguns:metalpanel@4"
            ]
        },
        {
            "x": -7,
            "y": 12,
            "z": 9,
            "elements": [
                "techguns:metalpanel@4"
            ]
        },
        {
            "x": 7,
            "y": 11,
            "z": 14,
            "elements": [
                "ic2:resource@13"
            ]
        },
        {
            "x": 2,
            "y": 9,
            "z": 2,
            "elements": [
                "thermalfoundation:glass_alloy@7"
            ]
        },
        {
            "x": 2,
            "y": -2,
            "z": 11,
            "elements": [
                "techguns:metalpanel@4"
            ]
        },
        {
            "x": 5,
            "y": -4,
            "z": 11,
            "elements": [
                "techguns:metalpanel@4"
            ]
        },
        {
            "x": -3,
            "y": 5,
            "z": 3,
            "elements": [
                "immersiveengineering:metal_decoration1@1"
            ]
        },
        {
            "x": -6,
            "y": -4,
            "z": 9,
            "elements": [
                "techguns:metalpanel@4"
            ]
        },
        {
            "x": 4,
            "y": -4,
            "z": 9,
            "elements": [
                "techguns:metalpanel@4"
            ]
        },
        {
            "x": -4,
            "y": 3,
            "z": 3,
            "elements": [
                "immersiveengineering:metal_decoration1@1"
            ]
        },
        {
            "x": 0,
            "y": 4,
            "z": 11,
            "elements": [
                "redstonearsenal:storage@0"
            ]
        },
        {
            "x": 1,
            "y": -2,
            "z": 9,
            "elements": [
                "techguns:metalpanel@4"
            ]
        },
        {
            "x": -7,
            "y": -3,
            "z": 5,
            "elements": [
                "ic2:resource@13"
            ]
        },
        {
            "x": -7,
            "y": 4,
            "z": 9,
            "elements": [
                "immersiveengineering:metal_decoration0@7"
            ]
        },
        {
            "x": 7,
            "y": 11,
            "z": 0,
            "elements": [
                "ic2:resource@13"
            ]
        },
        {
            "x": -3,
            "y": 10,
            "z": 11,
            "elements": [
                "techguns:metalpanel@4"
            ]
        },
        {
            "x": 3,
            "y": -2,
            "z": 4,
            "elements": [
                "techguns:metalpanel@4"
            ]
        },
        {
            "x": 4,
            "y": 10,
            "z": 13,
            "elements": [
                "techguns:metalpanel@4"
            ]
        },
        {
            "x": -6,
            "y": -1,
            "z": 10,
            "elements": [
                "thermalfoundation:glass_alloy@7"
            ]
        },
        {
            "x": 7,
            "y": 12,
