{
    "registryname": "helios",
    "localizedname": "§9HELIOS§b-§e量子计算系统",
    "failure-action": "still",
    "requires-blueprint": false,
    "factory-only": true,
    "color": "606060",
    "parts": [
        {
            "x": 0,
            "y": 0,
            "z": 0,

            "elements": [
                "modularmachinery:blockcontroller@2"
            ]
        },
        {
            "x": 20,
            "y": 2,
            "z": 4,
            "elements": [
                "appliedenergistics2:smooth_sky_stone_block@0"
            ]
        },
        {
            "x": 17,
            "y": 4,
            "z": -3,
            "elements": [
                "appliedenergistics2:smooth_sky_stone_block@0"
            ]
        },
        {
            "x": 21,
            "y": 1,
            "z": -1,
            "elements": [
                "minecraft:iron_block@0"
            ]
        },
        {
            "x": -3,
            "y": 0,
            "z": 5,
            "elements": [
                "minecraft:stained_glass@0"
            ]
        },
        {
            "x": 21,
            "y": 0,
            "z": -1,
            "elements": [
                "minecraft:iron_block@0"
            ]
        },
        {
            "x": 11,
            "y": -3,
            "z": 2,
            "elements": [
                "minecraft:concrete@7"
            ]
        },
        {
            "x": -2,
            "y": 4,
            "z": 0,
            "elements": [
                "minecraft:iron_block@0"
            ]
        },
        {
            "x": 10,
            "y": 2,
            "z": 2,
            "elements": [
                "minecraft:quartz_stairs@3"
            ]
        },
        {
            "x": -4,
            "y": 4,
            "z": 5,
            "elements": [
                "minecraft:quartz_stairs@7"
            ]
        },
        {
            "x": 5,
            "y": -2,
            "z": 1,
            "elements": [
                "minecraft:iron_block@0"
            ]
        },
        {
            "x": -3,
            "y": 2,
            "z": 5,
            "elements": [
                "minecraft:stained_glass@0"
            ]
        },
        {
            "x": 10,
            "y": 0,
            "z": 2,
            "elements": [
                "mekanism:glowplasticblock@15"
            ]
        },
        {
            "x": 26,
            "y": -3,
            "z": -1,
            "elements": [
                "minecraft:concrete@7"
            ]
        },
        {
            "x": 17,
            "y": -3,
            "z": 3,
            "elements": [
                "minecraft:concrete@7"
            ]
        },
        {
            "x": 20,
            "y": 4,
            "z": 4,
            "elements": [
                "appliedenergistics2:smooth_sky_stone_block@0"
            ]
        },
        {
            "x": 12,
            "y": 0,
            "z": -4,
            "elements": [
                "appliedenergistics2:smooth_sky_stone_block@0"
            ]
        },
        {
            "x": 5,
            "y": -1,
            "z": 1,
            "elements": [
                "minecraft:iron_block@0"
            ]
        },
        {
            "x": 11,
            "y": -1,
            "z": 2,
            "elements": [
                "minecraft:iron_block@0"
            ]
        },
        {
            "x": 26,
            "y": 0,
            "z": -3,
            "elements": [
                "mekanism:glowplasticblock@15"
            ]
        },
        {
            "x": -4,
            "y": -2,
            "z": 5,
            "elements": [
                "minecraft:quartz_stairs@3"
            ]
        },
        {
            "x": -2,
            "y": 0,
            "z": 5,
            "elements": [
                "minecraft:stained_glass@0"
            ]
        },
        {
            "x": 1,
            "y": -2,
            "z": 0,
            "elements": [
                "appliedenergistics2:smooth_sky_stone_stairs@1"
            ]
        },
        {
            "x": 16,
            "y": 4,
            "z": 2,
            "elements": [
                "appliedenergistics2:smooth_sky_stone_block@0"
            ]
        },
        {
            "x": 26,
            "y": -1,
            "z": -1,
            "elements": [
                "minecraft:iron_block@0"
            ]
        },
        {
            "x": 26,
            "y": -2,
            "z": -1,
            "elements": [
                "minecraft:iron_block@0"
            ]
        },
        {
            "x": 6,
            "y": 4,
            "z": 3,
            "elements": [
                "appliedenergistics2:smooth_sky_stone_block@0"
            ]
        },
        {
            "x": 20,
            "y": -2,
            "z": 4,
            "elements": [
                "appliedenergistics2:smooth_sky_stone_block@0"
            ]
        },
        {
            "x": 12,
            "y": -3,
            "z": 2,
            "elements": [
                "minecraft:concrete@7"
            ]
        },
        {
            "x": -5,
            "y": 4,
            "z": 5,
            "elements": [
                "minecraft:quartz_stairs@7"
            ]
        },
        {
            "x": -1,
            "y": 4,
            "z": 0,
            "elements": [
                "minecraft:iron_block@0"
            ]
        },
        {
            "x": 20,
            "y": 4,
            "z": -3,
            "elements": [
                "appliedenergistics2:smooth_sky_stone_block@0"
            ]
        },
        {
            "x": 20,
            "y": 0,
            "z": 4,
            "elements": [
                "appliedenergistics2:smooth_sky_stone_block@0"
            ]
        },
        {
            "x": 5,
            "y": -3,
            "z": 1,
            "elements": [
                "minecraft:concrete@7"
            ]
        },
        {
            "x": -2,
            "y": 2,
            "z": 5,
            "elements": [
                "minecraft:stained_glass@0"
            ]
        },
        {
            "x": 11,
            "y": -2,
            "z": 2,
            "elements": [
                "minecraft:iron_block@0"
            ]
        },
        {
            "x": -7,
            "y": -3,
            "z": 4,
            "elements": [
                "minecraft:concrete@7"
            ]
        },
        {
            "x": 18,
            "y": -1,
            "z": 2,
            "elements": [
                "minecraft:stained_glass@8"
            ]
        },
        {
            "x": 21,
            "y": 2,
            "z": -1,
            "elements": [
                "minecraft:iron_block@0"
            ]
        },
        {
            "x": 20,
            "y": -3,
            "z": 3,
            "elements": [
                "minecraft:concrete@7"
            ]
        },
        {
            "x": -7,
            "y": -3,
            "z": -1,
            "elements": [
                "minecraft:concrete@7"
            ]
        },
        {
            "x": -1,
            "y": -2,
            "z": 5,
            "elements": [
                "minecraft:quartz_stairs@3"
            ]
        },
        {
            "x": 21,
            "y": -3,
            "z": 2,
            "elements": [
                "minecraft:concrete@7"
            ]
        },
        {
            "x": 8,
            "y": 4,
            "z": -4,
            "elements": [
                "appliedenergistics2:smooth_sky_stone_block@0"
            ]
        },
        {
            "x": 6,
            "y": 3,
            "z": 1,
            "elements": [
                "minecraft:iron_block@0"
            ]
        },
        {
            "x": 23,
            "y": -2,
            "z": -1,
            "elements": [
                "minecraft:iron_block@0"
            ]
        },
        {
            "x": 3,
            "y": 3,
            "z": 4,
            "elements": [
                "minecraft:iron_block@0"
            ]
        },
        {
            "x": -4,
            "y": 4,
            "z": 0,
            "elements": [
                "minecraft:iron_block@0"
            ]
        },
        {
            "x": -5,
            "y": 0,
            "z": 5,
            "elements": [
                "minecraft:stained_glass@0"
            ]
        },
        {
            "x": -6,
            "y": 4,
            "z": 5,
            "elements": [
                "minecraft:quartz_stairs@7"
            ]
        },
        {
            "x": 19,
            "y": 0,
            "z": 2,
            "elements": [
                "minecraft:iron_block@0"
            ]
        },
        {
            "x": 26,
            "y": 2,
            "z": -3,
            "elements": [
                "mekanism:glowplasticblock@15"
            ]
        },
        {
            "x": 6,
            "y": 2,
            "z": -1,
            "elements": [
                "minecraft:iron_block@0"
            ]
        },
        {
            "x": 21,
            "y": -2,
            "z": 2,
            "elements": [
                "minecraft:iron_block@0"
            ]
        },
        {
            "x": -7,
            "y": -3,
            "z": 1,
            "elements": [
                "minecraft:concrete@7"
            ]
        },
        {
            "x": 6,
            "y": 3,
            "z": -1,
            "elements": [
                "minecraft:iron_block@0"
            ]
        },
        {
            "x": 18,
            "y": -2,
            "z": 2,
            "elements": [
                "minecraft:quartz_stairs@3"
            ]
        },
        {
            "x": 8,
            "y": -2,
            "z": -4,
            "elements": [
                "appliedenergistics2:smooth_sky_stone_block@0"
            ]
        },
        {
            "x": 6,
            "y": 2,
            "z": 1,
            "elements": [
                "minecraft:iron_block@0"
            ]
        },
        {
            "x": 23,
            "y": -1,
            "z": -1,
            "elements": [
                "minecraft:iron_block@0"
            ]
        },
        {
            "x": -5,
            "y": 2,
            "z": 5,
            "elements": [
                "minecraft:stained_glass@0"
            ]
        },
        {
            "x": 19,
            "y": 1,
            "z": 2,
            "elements": [
                "minecraft:iron_block@0"
            ]
        },
        {
            "x": -1,
            "y": 0,
            "z": 0,

            "elements": [
                "item_in"
            ]
        },
        {
            "x": 8,
            "y": -3,
            "z": -1,
            "elements": [
                "minecraft:concrete@7"
            ]
        },
        {
            "x": 8,
            "y": -3,
            "z": 1,
            "elements": [
                "minecraft:concrete@7"
            ]
        },
        {
            "x": 21,
            "y": -1,
            "z": 2,
            "elements": [
                "minecraft:iron_block@0"
            ]
        },
        {
            "x": 3,
            "y": -2,
            "z": 0,
            "elements": [
                "minecraft:iron_block@0"
            ]
        },
        {
            "x": -4,
            "y": 2,
            "z": 0,
            "elements": [
                "minecraft:quartz_stairs@6"
            ]
        },
        {
            "x": 6,
            "y": 1,
            "z": 1,
            "elements": [
                "minecraft:iron_block@0"
            ]
        },
        {
            "x": -6,
            "y": -2,
            "z": 5,
            "elements": [
                "minecraft:quartz_stairs@3"
            ]
        },
        {
            "x": 19,
            "y": 2,
            "z": 2,
            "elements": [
                "minecraft:quartz_stairs@3"
            ]
        },
        {
            "x": 6,
            "y": 0,
            "z": -1,
            "elements": [
                "minecraft:iron_block@0"
            ]
        },
        {
            "x": 0,
            "y": 0,
            "z": 5,
            "elements": [
                "minecraft:stained_glass@0"
            ]
        },
        {
            "x": 18,
            "y": -3,
            "z": 2,
            "elements": [
                "minecraft:concrete@7"
            ]
        },
        {
            "x": 6,
            "y": 0,
            "z": 1,
            "elements": [
                "minecraft:iron_block@0"
            ]
        },
        {
            "x": 0,
            "y": 4,
            "z": 3,
            "elements": [
                "minecraft:iron_block@0"
            ]
        },
        {
            "x": 26,
            "y": 4,
            "z": -3,
            "elements": [
                "appliedenergistics2:smooth_sky_stone_block@0"
            ]
        },
        {
            "x": 0,
            "y": 2,
            "z": 5,
            "elements": [
                "minecraft:stained_glass@0"
            ]
        },
        {
            "x": 1,
            "y": 4,
            "z": 0,
            "elements": [
                "minecraft:iron_block@0"
            ]
        },
        {
            "x": -3,
            "y": 4,
            "z": 5,
            "elements": [
                "minecraft:quartz_stairs@7"
            ]
        },
        {
            "x": 3,
            "y": 0,
            "z": 3,
            "elements": [
                "minecraft:iron_block@0"
            ]
        },
        {
            "x": 26,
            "y": -3,
            "z": 3,
            "elements": [
                "minecraft:concrete@7"
            ]
        },
        {
            "x": 13,
            "y": 0,
            "z": 2,
            "elements": [
                "minecraft:iron_block@0"
            ]
        },
        {
            "x": 23,
            "y": -3,
            "z": -1,
            "elements": [
                "minecraft:concrete@7"
            ]
        },
        {
            "x": 6,
            "y": 1,
            "z": -1,
            "elements": [
                "minecraft:iron_block@0"
            ]
        },
        {
            "x": 11,
            "y": -3,
            "z": -1,
            "elements": [
                "minecraft:concrete@7"
            ]
        },
        {
            "x": 4,
            "y": -2,
            "z": 0,
            "elements": [
                "ic2:coolant@1"
            ]
        },
        {
            "x": 13,
            "y": -3,
            "z": -3,
            "elements": [
                "minecraft:concrete@7"
            ]
        },
        {
            "x": 8,
            "y": 2,
            "z": -4,
            "elements": [
                "appliedenergistics2:smooth_sky_stone_block@0"
            ]
        },
        {
            "x": -6,
            "y": 5,
            "z": 4,
            "elements": [
                "minecraft:stone_slab@0"
            ]
        },
        {
            "x": -5,
            "y": 2,
            "z": 0,
            "elements": [
                "minecraft:quartz_stairs@6"
            ]
        },
        {
            "x": -7,
            "y": 0,
            "z": 5,
            "elements": [
                "minecraft:stained_glass@0"
            ]
        },
        {
            "x": 15,
            "y": -3,
            "z": 2,
            "elements": [
                "minecraft:concrete@7"
            ]
        },
        {
            "x": 4,
            "y": 0,
            "z": 0,
            "elements": [
                "ic2:coolant@1"
            ]
        },
        {
            "x": 5,
            "y": 1,
            "z": -3,
            "elements": [
                "minecraft:iron_block@0"
            ]
        },
        {
            "x": 1,
            "y": -2,
            "z": 5,
            "elements": [
                "minecraft:quartz_stairs@3"
            ]
        },
        {
            "x": 15,
            "y": 2,
            "z": -2,
            "elements": [
                "minecraft:quartz_stairs@2"
            ]
        },
        {
            "x": 0,
            "y": 4,
            "z": 5,
            "elements": [
                "minecraft:quartz_stairs@7"
            ]
        },
        {
            "x": 2,
            "y": 4,
            "z": 0,
            "elements": [
                "minecraft:iron_block@0"
            ]
        },
        {
            "x": 9,
            "y": 0,
            "z": -1,
            "elements": [
                "minecraft:iron_block@0"
            ]
        },
        {
            "x": 12,
            "y": 4,
            "z": -2,
            "elements": [
                "appliedenergistics2:smooth_sky_stone_block@0"
            ]
        },
        {
            "x": 27,
            "y": 1,
            "z": 0,
            "elements": [
                "minecraft:iron_block@0"
            ]
        },
        {
            "x": 17,
            "y": -2,
            "z": -1,
            "elements": [
                "minecraft:iron_block@0"
            ]
        },
        {
            "x": 3,
            "y": 4,
            "z": -1,
            "elements": [
                "minecraft:iron_block@0"
            ]
        },
        {
            "x": 17,
            "y": -1,
            "z": -1,
            "elements": [
                "minecraft:iron_block@0"
            ]
        },
        {
            "x": 2,
            "y": -3,
            "z": 4,
            "elements": [
                "minecraft:concrete@7"
            ]
        },
        {
            "x": -7,
            "y": 2,
            "z": 5,
            "elements": [
                "minecraft:stained_glass@0"
            ]
        },
        {
            "x": 17,
            "y": -2,
            "z": -2,
            "elements": [
                "minecraft:iron_block@0"
            ]
        },
        {
            "x": 10,
            "y": -3,
            "z": -3,
            "elements": [
                "minecraft:concrete@7"
            ]
        },
        {
            "x": 13,
            "y": 1,
            "z": 2,
            "elements": [
                "minecraft:iron_block@0"
            ]
        },
        {
            "x": 9,
            "y": 1,
            "z": -1,
            "elements": [
                "minecraft:iron_block@0"
            ]
        },
        {
            "x": 14,
            "y": -3,
            "z": -1,
            "elements": [
                "minecraft:concrete@7"
            ]
        },
        {
            "x": 7,
            "y": -1,
            "z": -3,
            "elements": [
                "minecraft:iron_block@0"
            ]
        },
        {
            "x": -8,
            "y": 0,
            "z": 3,
            "elements": [
                "minecraft:stained_glass@0"
            ]
        },
        {
            "x": 15,
            "y": -1,
            "z": 2,
            "elements": [
                "minecraft:iron_block@0"
            ]
        },
        {
            "x": 15,
            "y": 0,
            "z": -2,
            "elements": [
                "minecraft:iron_block@0"
            ]
        },
        {
            "x": 9,
            "y": 2,
            "z": -1,
            "elements": [
                "minecraft:iron_block@0"
            ]
        },
        {
            "x": 12,
            "y": 4,
            "z": 2,
            "elements": [
                "appliedenergistics2:smooth_sky_stone_block@0"
            ]
        },
        {
            "x": 5,
            "y": 3,
            "z": -3,
            "elements": [
                "minecraft:iron_block@0"
            ]
        },
        {
            "x": 5,
            "y": 0,
            "z": 0,
            "elements": [
                "minecraft:iron_block@0"
            ]
        },
        {
            "x": -1,
            "y": 4,
            "z": 5,
            "elements": [
                "minecraft:quartz_stairs@7"
            ]
        },
        {
            "x": -3,
            "y": 5,
            "z": 4,
            "elements": [
                "minecraft:stone_slab@0"
            ]
        },
        {
            "x": -5,
            "y": 4,
            "z": 0,
            "elements": [
                "minecraft:iron_block@0"
            ]
        },
        {
            "x": 2,
            "y": 0,
            "z": 5,
            "elements": [
                "minecraft:stained_glass@0"
            ]
        },
        {
            "x": 8,
            "y": -3,
            "z": 4,
            "elements": [
                "appliedenergistics2:smooth_sky_stone_block@0"
            ]
        },
        {
            "x": 14,
            "y": -2,
            "z": -1,
            "elements": [
                "minecraft:iron_block@0"
            ]
        },
        {
            "x": 17,
            "y": -3,
            "z": -2,
            "elements": [
                "minecraft:concrete@7"
            ]
        },
        {
            "x": 2,
            "y": 2,
            "z": 5,
            "elements": [
                "minecraft:stained_glass@0"
            ]
        },
        {
            "x": -4,
            "y": -3,
            "z": -3,
            "elements": [
                "minecraft:concrete@7"
            ]
        },
        {
            "x": 13,
            "y": 2,
            "z": 2,
            "elements": [
                "minecraft:quartz_stairs@3"
            ]
        },
        {
            "x": 3,
            "y": 2,
            "z": 3,
            "elements": [
                "minecraft:iron_block@0"
            ]
        },
        {
            "x": 15,
            "y": 1,
            "z": -2,
            "elements": [
                "minecraft:iron_block@0"
            ]
        },
        {
            "x": 5,
            "y": -2,
            "z": 3,
            "elements": [
                "minecraft:iron_block@0"
            ]
        },
        {
            "x": 15,
            "y": 0,
            "z": 2,
            "elements": [
                "minecraft:iron_block@0"
            ]
        },
        {
            "x": 15,
            "y": -2,
            "z": 2,
            "elements": [
                "minecraft:iron_block@0"
            ]
        },
        {
            "x": 17,
            "y": -3,
            "z": -1,
            "elements": [
                "minecraft:concrete@7"
            ]
        },
        {
            "x": -1,
            "y": 0,
            "z": 5,
            "elements": [
                "minecraft:stained_glass@0"
            ]
        },
        {
            "x": -8,
            "y": 2,
            "z": 3,
            "elements": [
                "minecraft:stained_glass@0"
            ]
        },
        {
            "x": 7,
            "y": -3,
            "z": -3,
            "elements": [
                "minecraft:concrete@7"
            ]
        },
        {
            "x": -6,
            "y": 4,
            "z": -1,
            "elements": [
                "minecraft:iron_block@0"
            ]
        },
        {
            "x": 14,
            "y": -1,
            "z": -1,
            "elements": [
                "minecraft:iron_block@0"
            ]
        },
        {
            "x": -2,
            "y": 0,
            "z": 0,

            "elements": [
                "fluid_in"
            ]
        },
        {
            "x": 8,
            "y": -1,
            "z": 4,
            "elements": [
                "appliedenergistics2:smooth_sky_stone_block@0"
            ]
        },
        {
            "x": 14,
            "y": -1,
            "z": 2,
            "elements": [
                "minecraft:stained_glass@8"
            ]
        },
        {
            "x": -8,
            "y": 4,
            "z": 0,
            "elements": [
                "minecraft:quartz_stairs@4"
            ]
        },
        {
            "x": -5,
            "y": -2,
            "z": 5,
            "elements": [
                "minecraft:quartz_stairs@3"
            ]
        },
        {
            "x": -6,
            "y": -2,
            "z": 0,
            "elements": [
                "appliedenergistics2:smooth_sky_stone_stairs@0"
            ]
        },
        {
            "x": -7,
            "y": -3,
            "z": -3,
            "elements": [
                "minecraft:concrete@7"
            ]
        },
        {
            "x": 17,
            "y": -3,
            "z": 2,
            "elements": [
                "minecraft:concrete@7"
            ]
        },
        {
            "x": 14,
            "y": -3,
            "z": -2,
            "elements": [
                "minecraft:concrete@7"
            ]
        },
        {
            "x": 11,
            "y": -2,
            "z": -1,
            "elements": [
                "minecraft:iron_block@0"
            ]
        },
        {
            "x": 6,
            "y": 2,
            "z": 3,
            "elements": [
                "mekanism:glowplasticblock@15"
            ]
        },
        {
            "x": 3,
            "y": 4,
            "z": 3,
            "elements": [
                "minecraft:iron_block@0"
            ]
        },
        {
            "x": 5,
            "y": 2,
            "z": 0,
            "elements": [
                "minecraft:iron_block@0"
            ]
        },
        {
            "x": -1,
            "y": 2,
            "z": 5,
            "elements": [
                "minecraft:stained_glass@0"
            ]
        },
        {
            "x": 5,
            "y": -3,
            "z": -1,
            "elements": [
                "minecraft:concrete@7"
            ]
        },
        {
            "x": 8,
            "y": -3,
            "z": -3,
            "elements": [
                "minecraft:concrete@7"
            ]
        },
        {
            "x": 14,
            "y": -2,
            "z": 2,
            "elements": [
                "minecraft:quartz_stairs@3"
            ]
        },
        {
            "x": 23,
            "y": 4,
            "z": -3,
            "elements": [
                "appliedenergistics2:smooth_sky_stone_block@0"
            ]
        },
        {
            "x": -8,
            "y": -2,
            "z": 5,
            "elements": [
                "minecraft:iron_block@0"
            ]
        },
        {
            "x": 27,
            "y": 3,
            "z": 0,
            "elements": [
                "minecraft:iron_block@0"
            ]
        },
        {
            "x": 23,
            "y": -3,
            "z": 3,
            "elements": [
                "minecraft:concrete@7"
            ]
        },
        {
            "x": 6,
            "y": 0,
            "z": 3,
            "elements": [
                "mekanism:glowplasticblock@15"
            ]
        },
        {
            "x": 15,
            "y": 1,
            "z": 2,
            "elements": [
                "minecraft:iron_block@0"
            ]
        },
        {
            "x": 11,
            "y": -1,
            "z": -1,
            "elements": [
                "minecraft:iron_block@0"
            ]
        },
        {
            "x": 20,
            "y": 3,
            "z": -4,
            "elements": [
                "appliedenergistics2:smooth_sky_stone_block@0"
            ]
        },
        {
            "x": 28,
            "y": -3,
            "z": -4,
            "elements": [
                "appliedenergistics2:smooth_sky_stone_block@0"
            ]
        },
        {
            "x": 18,
            "y": 2,
            "z": -1,
            "elements": [
                "minecraft:iron_block@0"
            ]
        },
        {
            "x": 3,
            "y": 1,
            "z": -1,
            "elements": [
                "minecraft:stained_glass@0"
            ]
        },
        {
            "x": 0,
            "y": 5,
            "z": 4,
            "elements": [
                "minecraft:stone_slab@0"
            ]
        },
        {
            "x": -5,
            "y": 0,
            "z": 0,

            "elements": [
                "item_out"
            ]
        },
        {
            "x": -4,
            "y": -3,
            "z": 4,
            "elements": [
                "minecraft:concrete@7"
            ]
        },
        {
            "x": 20,
            "y": -3,
            "z": -1,
            "elements": [
                "minecraft:concrete@7"
            ]
        },
        {
            "x": 26,
            "y": -3,
            "z": 0,
            "elements": [
                "minecraft:concrete@7"
            ]
        },
        {
            "x": -4,
            "y": 0,
            "z": 5,
            "elements": [
                "minecraft:stained_glass@0"
            ]
        },
        {
            "x": -2,
            "y": -2,
            "z": 5,
            "elements": [
                "minecraft:quartz_stairs@3"
            ]
        },
        {
            "x": 0,
            "y": 4,
            "z": -1,
            "elements": [
                "minecraft:iron_block@0"
            ]
        },
        {
            "x": 17,
            "y": -1,
            "z": 2,
            "elements": [
                "minecraft:iron_block@0"
            ]
        },
        {
            "x": 18,
            "y": 0,
            "z": -1,
            "elements": [
                "mekanism:glowplasticblock@15"
            ]
        },
        {
            "x": -6,
            "y": 0,
            "z": 1,
            "elements": [
                "appliedenergistics2:smooth_sky_stone_stairs@0"
            ]
        },
        {
            "x": 5,
            "y": -1,
            "z": -1,
            "elements": [
                "minecraft:iron_block@0"
            ]
        },
        {
            "x": 15,
            "y": 2,
            "z": 2,
            "elements": [
                "minecraft:quartz_stairs@3"
            ]
        },
        {
            "x": -4,
            "y": -3,
            "z": 1,
            "elements": [
                "minecraft:concrete@7"
            ]
        },
        {
            "x": 3,
            "y": 2,
            "z": -1,
            "elements": [
                "minecraft:stained_glass@0"
            ]
        },
        {
            "x": 14,
            "y": -3,
            "z": 2,
            "elements": [
                "minecraft:concrete@7"
            ]
        },
        {
            "x": 14,
            "y": -1,
            "z": -2,
            "elements": [
                "minecraft:stained_glass@8"
            ]
        },
        {
            "x": 17,
            "y": -2,
            "z": 2,
            "elements": [
                "minecraft:iron_block@0"
            ]
        },
        {
            "x": 17,
            "y": -1,
            "z": -2,
            "elements": [
                "minecraft:iron_block@0"
            ]
        },
        {
            "x": 5,
            "y": -2,
            "z": -1,
            "elements": [
                "minecraft:iron_block@0"
            ]
        },
        {
            "x": -4,
            "y": 2,
            "z": 5,
            "elements": [
                "minecraft:stained_glass@0"
            ]
        },
        {
            "x": -7,
            "y": 4,
            "z": 5,
            "elements": [
                "minecraft:quartz_stairs@7"
            ]
        },
        {
            "x": -4,
            "y": -1,
            "z": 1,
            "elements": [
                "minecraft:concrete@7"
            ]
        },
        {
            "x": 3,
            "y": 0,
            "z": -1,
            "elements": [
                "minecraft:stained_glass@0"
            ]
        },
        {
            "x": 18,
            "y": 1,
            "z": -1,
            "elements": [
                "minecraft:iron_block@0"
            ]
        },
        {
            "x": 20,
            "y": 1,
            "z": -4,
            "elements": [
                "appliedenergistics2:smooth_sky_stone_block@0"
            ]
        },
        {
            "x": 26,
            "y": -1,
            "z": 0,
            "elements": [
                "minecraft:iron_block@0"
            ]
        },
        {
            "x": -2,
            "y": 5,
            "z": 4,
            "elements": [
                "minecraft:stone_slab@0"
            ]
        },
        {
            "x": 28,
            "y": -1,
            "z": -4,
            "elements": [
                "appliedenergistics2:smooth_sky_stone_block@0"
            ]
        },
        {
            "x": 14,
            "y": -2,
            "z": -2,
            "elements": [
                "minecraft:quartz_stairs@2"
            ]
        },
        {
            "x": 3,
            "y": 3,
            "z": -1,
            "elements": [
                "minecraft:iron_block@0"
            ]
        },
        {
            "x": 13,
            "y": 1,
            "z": 1,
            "elements": [
                "minecraft:iron_block@0"
            ]
        },
        {
            "x": 0,
            "y": 5,
            "z": -1,
            "elements": [
                "minecraft:stone_slab@0"
            ]
        },
        {
            "x": 25,
            "y": -2,
            "z": -3,
            "elements": [
                "minecraft:iron_block@0"
            ]
        },
        {
            "x": 24,
            "y": -3,
            "z": 0,
            "elements": [
                "minecraft:concrete@7"
            ]
        },
        {
            "x": -8,
            "y": -2,
            "z": 0,
            "elements": [
                "minecraft:quartz_stairs@0"
            ]
        },
        {
            "x": 6,
            "y": 3,
            "z": -3,
            "elements": [
                "minecraft:quartz_stairs@6"
            ]
        },
        {
            "x": 18,
            "y": 0,
            "z": -2,
            "elements": [
                "mekanism:glowplasticblock@15"
            ]
        },
        {
            "x": -2,
            "y": -3,
            "z": 4,
            "elements": [
                "minecraft:concrete@7"
            ]
        },
        {
            "x": 18,
            "y": -3,
            "z": 1,
            "elements": [
                "minecraft:concrete@7"
            ]
        },
        {
            "x": 8,
            "y": 0,
            "z": 0,
            "elements": [
                "minecraft:iron_block@0"
            ]
        },
        {
            "x": 27,
            "y": 3,
            "z": -2,
            "elements": [
                "minecraft:iron_block@0"
            ]
        },
        {
            "x": 1,
            "y": 4,
            "z": 3,
            "elements": [
                "minecraft:iron_block@0"
            ]
        },
        {
            "x": 25,
            "y": 4,
            "z": -3,
            "elements": [
                "appliedenergistics2:smooth_sky_stone_block@0"
            ]
        },
        {
            "x": 20,
            "y": -3,
            "z": -2,
            "elements": [
                "minecraft:concrete@7"
            ]
        },
        {
            "x": 4,
            "y": 2,
            "z": 3,
            "elements": [
                "ic2:coolant@1"
            ]
        },
        {
            "x": 7,
            "y": 2,
            "z": 0,
            "elements": [
                "minecraft:iron_block@0"
            ]
        },
        {
            "x": 25,
            "y": -3,
            "z": 3,
            "elements": [
                "minecraft:concrete@7"
            ]
        },
        {
            "x": 4,
            "y": 0,
            "z": 3,
            "elements": [
                "ic2:coolant@1"
            ]
        },
        {
            "x": -5,
            "y": -3,
            "z": -3,
            "elements": [
                "minecraft:concrete@7"
            ]
        },
        {
            "x": 27,
            "y": 2,
            "z": -2,
            "elements": [
                "minecraft:iron_block@0"
            ]
        },
        {
            "x": 6,
            "y": -2,
            "z": 3,
            "elements": [
                "minecraft:quartz_stairs@3"
            ]
        },
        {
            "x": 28,
            "y": 4,
            "z": 4,
            "elements": [
                "appliedenergistics2:smooth_sky_stone_block@0"
            ]
        },
        {
            "x": 13,
            "y": 0,
            "z": 1,
            "elements": [
                "minecraft:iron_block@0"
            ]
        },
        {
            "x": 4,
            "y": 0,
            "z": -4,
            "elements": [
                "appliedenergistics2:smooth_sky_stone_block@0"
            ]
        },
        {
            "x": 18,
            "y": 1,
            "z": -2,

            "elements": [
                "modularmachinery:blockupgradebus"
            ]
        },
        {
            "x": 24,
            "y": 4,
            "z": -2,
            "elements": [
                "appliedenergistics2:smooth_sky_stone_block@0"
            ]
        },
        {
            "x": 7,
            "y": -2,
            "z": 0,
            "elements": [
                "minecraft:iron_block@0"
            ]
        },
        {
            "x": -8,
            "y": 2,
            "z": 0,
            "elements": [
                "minecraft:stained_glass@0"
            ]
        },
        {
            "x": 6,
            "y": 1,
            "z": -3,
            "elements": [
                "mekanism:glowplasticblock@15"
            ]
        },
        {
            "x": 28,
            "y": -2,
            "z": 4,
            "elements": [
                "appliedenergistics2:smooth_sky_stone_block@0"
            ]
        },
        {
            "x": -7,
            "y": 5,
            "z": 4,
            "elements": [
                "minecraft:stone_slab@0"
            ]
        },
        {
            "x": 25,
            "y": 2,
            "z": -3,
            "elements": [
                "minecraft:iron_block@0"
            ]
        },
        {
            "x": 3,
            "y": 4,
            "z": 5,
            "elements": [
                "minecraft:iron_block@0"
            ]
        },
        {
            "x": 28,
            "y": 0,
            "z": 4,
            "elements": [
                "appliedenergistics2:smooth_sky_stone_block@0"
            ]
        },
        {
            "x": 28,
            "y": 3,
            "z": -4,
            "elements": [
                "appliedenergistics2:smooth_sky_stone_block@0"
            ]
        },
        {
            "x": 22,
            "y": 1,
            "z": 0,
            "elements": [
                "minecraft:iron_block@0"
            ]
        },
        {
            "x": 18,
            "y": 2,
            "z": -2,
            "elements": [
                "minecraft:quartz_stairs@2"
            ]
        },
        {
            "x": 27,
            "y": 0,
            "z": -2,
            "elements": [
                "minecraft:iron_block@0"
            ]
        },
        {
            "x": 18,
            "y": -1,
            "z": 1,
            "elements": [
                "minecraft:iron_block@0"
            ]
        },
        {
            "x": -2,
            "y": 4,
            "z": 3,
            "elements": [
                "minecraft:iron_block@0"
            ]
        },
        {
            "x": 18,
            "y": -2,
            "z": 1,
            "elements": [
                "minecraft:iron_block@0"
            ]
        },
        {
            "x": 1,
            "y": -3,
            "z": 4,
            "elements": [
                "minecraft:concrete@7"
            ]
        },
        {
            "x": 28,
            "y": 4,
            "z": -3,
            "elements": [
                "appliedenergistics2:smooth_sky_stone_block@0"
            ]
        },
        {
            "x": 28,
            "y": -3,
            "z": 3,
            "elements": [
                "minecraft:concrete@7"
            ]
        },
        {
            "x": 27,
            "y": -2,
            "z": -3,
            "elements": [
                "minecraft:iron_block@0"
            ]
        },
        {
            "x": 27,
            "y": 1,
            "z": -2,
            "elements": [
                "minecraft:iron_block@0"
            ]
        },
        {
            "x": 13,
            "y": 2,
            "z": 1,
            "elements": [
                "minecraft:iron_block@0"
            ]
        },
        {
            "x": 15,
            "y": 0,
            "z": -1,
            "elements": [
                "minecraft:iron_block@0"
            ]
        },
        {
            "x": 15,
            "y": -1,
            "z": 1,
            "elements": [
                "minecraft:iron_block@0"
            ]
        },
        {
            "x": 25,
            "y": 1,
            "z": 0,
            "elements": [
                "minecraft:iron_block@0"
            ]
        },
        {
            "x": 0,
            "y": -3,
            "z": 4,
            "elements": [
                "minecraft:concrete@7"
            ]
        },
        {
            "x": -4,
            "y": 5,
            "z": 4,
            "elements": [
                "minecraft:stone_slab@0"
            ]
        },
        {
            "x": 26,
            "y": -2,
            "z": -2,
            "elements": [
                "minecraft:iron_block@0"
            ]
        },
        {
            "x": 26,
            "y": 1,
            "z": 3,
            "elements": [
                "mekanism:glowplasticblock@15"
            ]
        },
        {
            "x": 10,
            "y": 0,
            "z": 0,
            "elements": [
                "mekanism:glowplasticblock@15"
            ]
        },
        {
            "x": 2,
            "y": 4,
            "z": 5,
            "elements": [
                "minecraft:quartz_stairs@7"
            ]
        },
        {
            "x": 15,
            "y": 1,
            "z": 1,
            "elements": [
                "minecraft:iron_block@0"
            ]
        },
        {
            "x": 21,
            "y": 2,
            "z": -2,
            "elements": [
                "minecraft:quartz_stairs@2"
            ]
        },
        {
            "x": 4,
            "y": 4,
            "z": 0,
            "elements": [
                "appliedenergistics2:smooth_sky_stone_block@0"
            ]
        },
        {
            "x": 3,
            "y": 2,
            "z": 5,
            "elements": [
                "minecraft:iron_block@0"
            ]
        },
        {
            "x": 3,
            "y": 0,
            "z": 5,
            "elements": [
                "minecraft:iron_block@0"
            ]
        },
        {
            "x": -8,
            "y": 4,
            "z": 3,
            "elements": [
                "minecraft:quartz_stairs@4"
            ]
        },
        {
            "x": 15,
            "y": 0,
            "z": 1,
            "elements": [
                "minecraft:iron_block@0"
            ]
        },
        {
            "x": 15,
            "y": 1,
            "z": -1,
            "elements": [
                "minecraft:iron_block@0"
            ]
        },
        {
            "x": 15,
            "y": -2,
            "z": 1,
            "elements": [
                "minecraft:iron_block@0"
            ]
        },
        {
            "x": 4,
            "y": -3,
            "z": -3,
            "elements": [
                "minecraft:concrete@7"
            ]
        },
        {
            "x": 26,
            "y": -1,
            "z": -2,
            "elements": [
                "minecraft:iron_block@0"
            ]
        },
        {
            "x": 3,
            "y": 1,
            "z": -3,
            "elements": [
                "minecraft:iron_block@0"
            ]
        },
        {
            "x": 9,
            "y": -2,
            "z": 0,
            "elements": [
                "minecraft:iron_block@0"
            ]
        },
        {
            "x": 5,
            "y": -1,
            "z": -3,
            "elements": [
                "minecraft:iron_block@0"
            ]
        },
        {
            "x": 3,
            "y": 3,
            "z": -3,
            "elements": [
                "minecraft:iron_block@0"
            ]
        },
        {
            "x": -5,
            "y": 5,
            "z": 4,
            "elements": [
                "minecraft:stone_slab@0"
            ]
        },
        {
            "x": 7,
            "y": 0,
            "z": 0,
            "elements": [
                "minecraft:iron_block@0"
            ]
        },
        {
            "x": 2,
            "y": -2,
            "z": 5,
            "elements": [
                "minecraft:quartz_stairs@3"
            ]
        },
        {
            "x": -7,
            "y": 4,
            "z": 0,
            "elements": [
                "minecraft:iron_block@0"
            ]
        },
        {
            "x": 21,
            "y": 0,
            "z": -2,
            "elements": [
                "minecraft:iron_block@0"
            ]
        },
        {
            "x": 15,
            "y": 2,
            "z": -1,
            "elements": [
                "minecraft:iron_block@0"
            ]
        },
        {
            "x": 4,
            "y": 2,
            "z": 0,
            "elements": [
                "ic2:coolant@1"
            ]
        },
        {
            "x": -2,
            "y": -3,
            "z": -3,
            "elements": [
                "minecraft:concrete@7"
            ]
        },
        {
            "x": 25,
            "y": -1,
            "z": 3,
            "elements": [
                "minecraft:iron_block@0"
            ]
        },
        {
            "x": -1,
            "y": -3,
            "z": 4,
            "elements": [
                "minecraft:concrete@7"
            ]
        },
        {
            "x": 26,
            "y": -3,
            "z": -2,
            "elements": [
                "minecraft:concrete@7"
            ]
        },
        {
            "x": 12,
            "y": 4,
            "z": -1,
            "elements": [
                "appliedenergistics2:smooth_sky_stone_block@0"
            ]
        },
        {
            "x": 15,
            "y": -3,
            "z": 1,
            "elements": [
                "minecraft:concrete@7"
            ]
        },
        {
            "x": 5,
            "y": -3,
            "z": -3,
            "elements": [
                "minecraft:concrete@7"
            ]
        },
        {
            "x": 15,
            "y": 2,
            "z": 1,
            "elements": [
                "minecraft:iron_block@0"
            ]
        },
        {
            "x": 28,
            "y": 2,
            "z": 4,
            "elements": [
                "appliedenergistics2:smooth_sky_stone_block@0"
            ]
        },
        {
            "x": 4,
            "y": -1,
            "z": -3,
            "elements": [
                "ic2:coolant@1"
            ]
        },
        {
            "x": 21,
            "y": 1,
            "z": -2,
            "elements": [
                "minecraft:iron_block@0"
            ]
        },
        {
            "x": 12,
            "y": 4,
            "z": 1,
            "elements": [
                "appliedenergistics2:smooth_sky_stone_block@0"
            ]
        },
        {
            "x": 3,
            "y": -2,
            "z": 3,
            "elements": [
                "minecraft:iron_block@0"
            ]
        },
        {
            "x": -4,
            "y": 0,
            "z": 0,

            "elements": [
                "fluid_out"
            ]
        },
        {
            "x": 6,
            "y": -2,
            "z": 0,
            "elements": [
                "minecraft:iron_block@0"
            ]
        },
        {
            "x": 22,
            "y": 2,
            "z": 2,
            "elements": [
                "minecraft:quartz_stairs@3"
            ]
        },
        {
            "x": 17,
            "y": -1,
            "z": 1,
            "elements": [
                "minecraft:iron_block@0"
            ]
        },
        {
            "x": 9,
            "y": 1,
            "z": 1,
            "elements": [
                "minecraft:iron_block@0"
            ]
        },
        {
            "x": 8,
            "y": -3,
            "z": -2,
            "elements": [
                "minecraft:concrete@7"
            ]
        },
        {
            "x": 24,
            "y": 2,
            "z": 4,
            "elements": [
                "appliedenergistics2:smooth_sky_stone_block@0"
            ]
        },
        {
            "x": 19,
            "y": 1,
            "z": 0,
            "elements": [
                "minecraft:iron_block@0"
            ]
        },
        {
            "x": -3,
            "y": 4,
            "z": 3,
            "elements": [
                "minecraft:iron_block@0"
            ]
        },
        {
            "x": 26,
            "y": -1,
            "z": 3,
            "elements": [
                "mekanism:glowplasticblock@15"
            ]
        },
        {
            "x": 25,
            "y": 3,
            "z": 0,
            "elements": [
                "minecraft:iron_block@0"
            ]
        },
        {
            "x": 2,
            "y": -3,
            "z": -3,
            "elements": [
                "minecraft:concrete@7"
            ]
        },
        {
            "x": 23,
            "y": -3,
            "z": -2,
            "elements": [
                "minecraft:concrete@7"
            ]
        },
        {
            "x": -6,
            "y": 4,
            "z": 3,
            "elements": [
                "minecraft:iron_block@0"
            ]
        },
        {
            "x": 17,
            "y": -2,
            "z": 1,
            "elements": [
                "minecraft:iron_block@0"
            ]
        },
        {
            "x": 9,
            "y": 0,
            "z": 1,
            "elements": [
                "minecraft:iron_block@0"
            ]
        },
        {
            "x": 27,
            "y": -1,
            "z": 0,
            "elements": [
                "minecraft:iron_block@0"
            ]
        },
        {
            "x": 2,
            "y": 5,
            "z": 4,
            "elements": [
                "minecraft:stone_slab@0"
            ]
        },
        {
            "x": 8,
            "y": 0,
            "z": -4,
            "elements": [
                "appliedenergistics2:smooth_sky_stone_block@0"
            ]
        },
        {
            "x": 14,
            "y": -3,
            "z": 1,
            "elements": [
                "minecraft:concrete@7"
            ]
        },
        {
            "x": -6,
            "y": -3,
            "z": 4,
            "elements": [
                "minecraft:concrete@7"
            ]
        },
        {
            "x": 24,
            "y": 4,
            "z": 4,
            "elements": [
                "appliedenergistics2:smooth_sky_stone_block@0"
            ]
        },
        {
            "x": 24,
            "y": 0,
            "z": 4,
            "elements": [
                "appliedenergistics2:smooth_sky_stone_block@0"
            ]
        },
        {
            "x": 23,
            "y": -2,
            "z": -2,
            "elements": [
                "minecraft:iron_block@0"
            ]
        },
        {
            "x": 24,
            "y": 3,
            "z": -4,
            "elements": [
                "appliedenergistics2:smooth_sky_stone_block@0"
            ]
        },
        {
            "x": 14,
            "y": -1,
            "z": 1,
            "elements": [
                "minecraft:iron_block@0"
            ]
        },
        {
            "x": -6,
            "y": 0,
            "z": 5,
            "elements": [
                "minecraft:stained_glass@0"
            ]
        },
        {
            "x": 17,
            "y": -3,
            "z": 1,
            "elements": [
                "minecraft:concrete@7"
            ]
        },
        {
            "x": 26,
            "y": 3,
            "z": 3,
            "elements": [
                "minecraft:quartz_stairs@7"
            ]
        },
        {
            "x": 22,
            "y": 0,
            "z": 2,
            "elements": [
                "mekanism:glowplasticblock@15"
            ]
        },
        {
            "x": 27,
            "y": 1,
            "z": 3,
            "elements": [
                "minecraft:iron_block@0"
            ]
        },
        {
            "x": 4,
            "y": -2,
            "z": -4,
            "elements": [
                "appliedenergistics2:smooth_sky_stone_block@0"
            ]
        },
        {
            "x": 13,
            "y": 0,
            "z": 0,
            "elements": [
                "minecraft:iron_block@0"
            ]
        },
        {
            "x": 10,
            "y": 2,
            "z": 0,
            "elements": [
                "minecraft:iron_block@0"
            ]
        },
        {
            "x": 14,
            "y": -2,
            "z": 1,
            "elements": [
                "minecraft:iron_block@0"
            ]
        },
        {
            "x": 6,
            "y": 3,
            "z": -2,
            "elements": [
                "minecraft:iron_block@0"
            ]
        },
        {
            "x": 9,
            "y": 2,
            "z": 1,
            "elements": [
                "minecraft:iron_block@0"
            ]
        },
        {
            "x": -1,
            "y": -3,
            "z": -3,
            "elements": [
                "minecraft:concrete@7"
            ]
        },
        {
            "x": 22,
            "y": 1,
            "z": 2,

            "elements": [
                "modularmachinery:blockupgradebus"
            ]
        },
        {
            "x": -8,
            "y": 1,
            "z": 4,
            "elements": [
                "minecraft:stained_glass@0"
            ]
        },
        {
            "x": 23,
            "y": -1,
            "z": -2,
            "elements": [
                "minecraft:iron_block@0"
            ]
        },
        {
            "x": -6,
            "y": 2,
            "z": 5,
            "elements": [
                "minecraft:stained_glass@0"
            ]
        },
        {
            "x": -7,
            "y": -2,
            "z": 5,
            "elements": [
                "minecraft:quartz_stairs@3"
            ]
        },
        {
            "x": 27,
            "y": -3,
            "z": 0,
            "elements": [
                "minecraft:concrete@7"
            ]
        },
        {
            "x": -3,
            "y": -3,
            "z": 4,
            "elements": [
                "minecraft:concrete@7"
            ]
        },
        {
            "x": 9,
            "y": 2,
            "z": -2,
            "elements": [
                "minecraft:quartz_stairs@2"
            ]
        },
        {
            "x": 27,
            "y": 3,
            "z": 3,
            "elements": [
                "minecraft:iron_block@0"
            ]
        },
        {
            "x": 20,
            "y": -3,
            "z": 1,
            "elements": [
                "minecraft:concrete@7"
            ]
        },
        {
            "x": 18,
            "y": -3,
            "z": 0,
            "elements": [
                "minecraft:concrete@7"
            ]
        },
        {
            "x": 16,
            "y": 4,
            "z": 1,
            "elements": [
                "appliedenergistics2:smooth_sky_stone_block@0"
            ]
        },
        {
            "x": 11,
            "y": -1,
            "z": 1,
            "elements": [
                "minecraft:iron_block@0"
            ]
        },
        {
            "x": 11,
            "y": -2,
            "z": 1,
            "elements": [
                "minecraft:iron_block@0"
            ]
        },
        {
            "x": 11,
            "y": -1,
            "z": -2,
            "elements": [
                "minecraft:iron_block@0"
            ]
        },
        {
            "x": 19,
            "y": 1,
            "z": 1,
            "elements": [
                "minecraft:iron_block@0"
            ]
        },
        {
            "x": 9,
            "y": 1,
            "z": -2,
            "elements": [
                "minecraft:iron_block@0"
            ]
        },
        {
            "x": -5,
            "y": 4,
            "z": 3,
            "elements": [
                "minecraft:iron_block@0"
            ]
        },
        {
            "x": 0,
            "y": -3,
            "z": -3,
            "elements": [
                "minecraft:concrete@7"
            ]
        },
        {
            "x": 13,
            "y": 2,
            "z": 0,
            "elements": [
                "minecraft:iron_block@0"
            ]
        },
        {
            "x": 11,
            "y": -2,
            "z": -2,
            "elements": [
                "minecraft:iron_block@0"
            ]
        },
        {
            "x": 4,
            "y": -3,
            "z": 4,
            "elements": [
                "appliedenergistics2:smooth_sky_stone_block@0"
            ]
        },
        {
            "x": 9,
            "y": 0,
            "z": -2,
            "elements": [
                "minecraft:iron_block@0"
            ]
        },
        {
            "x": 18,
            "y": 2,
            "z": 1,
            "elements": [
                "minecraft:iron_block@0"
            ]
        },
        {
            "x": 21,
            "y": -1,
            "z": 0,
            "elements": [
                "minecraft:iron_block@0"
            ]
        },
        {
            "x": 6,
            "y": 2,
            "z": -2,
            "elements": [
                "minecraft:iron_block@0"
            ]
        },
        {
            "x": 19,
            "y": 0,
            "z": 1,
            "elements": [
                "minecraft:iron_block@0"
            ]
        },
        {
            "x": -7,
            "y": -3,
            "z": 2,
            "elements": [
                "minecraft:concrete@7"
            ]
        },
        {
            "x": 18,
            "y": -1,
            "z": 0,
            "elements": [
                "minecraft:iron_block@0"
            ]
        },
        {
            "x": 21,
            "y": -3,
            "z": 0,
            "elements": [
                "minecraft:concrete@7"
            ]
        },
        {
            "x": 3,
            "y": 4,
            "z": -2,
            "elements": [
                "minecraft:iron_block@0"
            ]
        },
        {
            "x": 11,
            "y": -3,
            "z": -2,
            "elements": [
                "minecraft:concrete@7"
            ]
        },
        {
            "x": -1,
            "y": 5,
            "z": 4,
            "elements": [
                "minecraft:stone_slab@0"
            ]
        },
        {
            "x": 6,
            "y": 1,
            "z": -2,
            "elements": [
                "minecraft:iron_block@0"
            ]
        },
        {
            "x": -8,
            "y": 3,
            "z": 4,
            "elements": [
                "minecraft:stained_glass@0"
            ]
        },
        {
            "x": 18,
            "y": 1,
            "z": 1,
            "elements": [
                "minecraft:iron_block@0"
            ]
        },
        {
            "x": -4,
            "y": 4,
            "z": 3,
            "elements": [
                "minecraft:iron_block@0"
            ]
        },
        {
            "x": 1,
            "y": -3,
            "z": -3,
            "elements": [
                "minecraft:concrete@7"
            ]
        },
        {
            "x": 3,
            "y": -3,
            "z": 4,
            "elements": [
                "minecraft:concrete@7"
            ]
        },
        {
            "x": 6,
            "y": 0,
            "z": -2,
            "elements": [
                "minecraft:iron_block@0"
            ]
        },
        {
            "x": 18,
            "y": 0,
            "z": 1,
            "elements": [
                "mekanism:glowplasticblock@15"
            ]
        },
        {
            "x": 11,
            "y": -3,
            "z": 1,
            "elements": [
                "minecraft:concrete@7"
            ]
        },
        {
            "x": 15,
            "y": -1,
            "z": 0,
            "elements": [
                "minecraft:iron_block@0"
            ]
        },
        {
            "x": -8,
            "y": 2,
            "z": 1,
            "elements": [
                "minecraft:stained_glass@0"
            ]
        },
        {
            "x": 28,
            "y": 1,
            "z": -4,
            "elements": [
                "appliedenergistics2:smooth_sky_stone_block@0"
            ]
        },
        {
            "x": 3,
            "y": 3,
            "z": 2,
            "elements": [
                "minecraft:iron_block@0"
            ]
        },
        {
            "x": 21,
            "y": -2,
            "z": -1,
            "elements": [
                "minecraft:iron_block@0"
            ]
        },
        {
            "x": 7,
            "y": -3,
            "z": -1,
            "elements": [
                "minecraft:concrete@7"
            ]
        },
        {
            "x": 4,
            "y": 1,
            "z": 4,
            "elements": [
                "appliedenergistics2:smooth_sky_stone_block@0"
            ]
        },
        {
            "x": 0,
            "y": 5,
            "z": 2,
            "elements": [
                "minecraft:stone_slab@0"
            ]
        },
        {
            "x": 25,
            "y": 0,
            "z": 2,
            "elements": [
                "minecraft:iron_block@0"
            ]
        },
        {
            "x": 25,
            "y": 3,
            "z": 3,
            "elements": [
                "minecraft:iron_block@0"
            ]
        },
        {
            "x": 16,
            "y": -3,
            "z": 0,
            "elements": [
                "minecraft:concrete@7"
            ]
        },
        {
            "x": 28,
            "y": 4,
            "z": 3,
            "elements": [
                "appliedenergistics2:smooth_sky_stone_block@0"
            ]
        },
        {
            "x": 21,
            "y": 1,
            "z": 1,
            "elements": [
                "minecraft:iron_block@0"
            ]
        },
        {
            "x": 27,
            "y": -2,
            "z": 2,
            "elements": [
                "minecraft:iron_block@0"
            ]
        },
        {
            "x": 25,
            "y": 4,
            "z": 3,
            "elements": [
                "appliedenergistics2:smooth_sky_stone_block@0"
            ]
        },
        {
            "x": 26,
            "y": -3,
            "z": 1,
            "elements": [
                "minecraft:concrete@7"
            ]
        },
        {
            "x": 21,
            "y": -1,
            "z": 1,
            "elements": [
                "minecraft:iron_block@0"
            ]
        },
        {
            "x": 4,
            "y": 2,
            "z": 4,
            "elements": [
                "appliedenergistics2:smooth_sky_stone_block@0"
            ]
        },
        {
            "x": 16,
            "y": 0,
            "z": 0,
            "elements": [
                "minecraft:iron_block@0"
            ]
        },
        {
            "x": 5,
            "y": -2,
            "z": -2,
            "elements": [
                "minecraft:iron_block@0"
            ]
        },
        {
            "x": 15,
            "y": -2,
            "z": 0,
            "elements": [
                "minecraft:iron_block@0"
            ]
        },
        {
            "x": 3,
            "y": 0,
            "z": -2,
            "elements": [
                "minecraft:stained_glass@0"
            ]
        },
        {
            "x": 1,
            "y": 4,
            "z": 4,
            "elements": [
                "minecraft:iron_block@0"
            ]
        },
        {
            "x": 27,
            "y": -3,
            "z": -2,
            "elements": [
                "minecraft:concrete@7"
            ]
        },
        {
            "x": -4,
            "y": -1,
            "z": 2,
            "elements": [
                "minecraft:concrete@7"
            ]
        },
        {
            "x": -5,
            "y": -3,
            "z": -4,
            "elements": [
                "minecraft:concrete@7"
            ]
        },
        {
            "x": -5,
            "y": -3,
            "z": 2,
            "elements": [
                "minecraft:concrete@7"
            ]
        },
        {
            "x": -6,
            "y": -2,
            "z": 1,
            "elements": [
                "appliedenergistics2:smooth_sky_stone_stairs@0"
            ]
        },
        {
            "x": 4,
            "y": 2,
            "z": -2,
            "elements": [
                "ic2:coolant@1"
            ]
        },
        {
            "x": 5,
            "y": 1,
            "z": -1,
            "elements": [
                "minecraft:iron_block@0"
            ]
        },
        {
            "x": 26,
            "y": 2,
            "z": 2,
            "elements": [
                "minecraft:iron_block@0"
            ]
        },
        {
            "x": 1,
            "y": 4,
            "z": -2,
            "elements": [
                "minecraft:iron_block@0"
            ]
        },
        {
            "x": 26,
            "y": 1,
            "z": -2,
            "elements": [
                "minecraft:iron_block@0"
            ]
        },
        {
            "x": 26,
            "y": 3,
            "z": -2,
            "elements": [
                "minecraft:iron_block@0"
            ]
        },
        {
            "x": 14,
            "y": 1,
            "z": 0,
            "elements": [
                "minecraft:iron_block@0"
            ]
        },
        {
            "x": 25,
            "y": 2,
            "z": 2,
            "elements": [
                "minecraft:iron_block@0"
            ]
        },
        {
            "x": 21,
            "y": -3,
            "z": 1,
            "elements": [
                "minecraft:concrete@7"
            ]
        },
        {
            "x": 10,
            "y": -3,
            "z": -1,
            "elements": [
                "minecraft:concrete@7"
            ]
        },
        {
            "x": 15,
            "y": -3,
            "z": 0,
            "elements": [
                "minecraft:concrete@7"
            ]
        },
        {
            "x": 26,
            "y": 0,
            "z": 2,
            "elements": [
                "minecraft:iron_block@0"
            ]
        },
        {
            "x": -8,
            "y": 0,
            "z": 1,
            "elements": [
                "minecraft:stained_glass@0"
            ]
        },
        {
            "x": 7,
            "y": -1,
            "z": -1,
            "elements": [
                "minecraft:iron_block@0"
            ]
        },
        {
            "x": -4,
            "y": -2,
            "z": -2,
            "elements": [
                "appliedenergistics2:smooth_sky_stone_stairs@2"
            ]
        },
        {
            "x": 3,
            "y": 1,
            "z": 2,
            "elements": [
                "minecraft:stained_glass@0"
            ]
        },
        {
            "x": 27,
            "y": -1,
            "z": 3,
            "elements": [
                "minecraft:iron_block@0"
            ]
        },
        {
            "x": 14,
            "y": 2,
            "z": 0,
            "elements": [
                "minecraft:iron_block@0"
            ]
        },
        {
            "x": 17,
            "y": 0,
            "z": 0,
            "elements": [
                "minecraft:iron_block@0"
            ]
        },
        {
            "x": 10,
            "y": -1,
            "z": -1,
            "elements": [
                "minecraft:iron_block@0"
            ]
        },
        {
            "x": -8,
            "y": -3,
            "z": -4,
            "elements": [
                "minecraft:concrete@7"
            ]
        },
        {
            "x": 28,
            "y": -3,
            "z": -2,
            "elements": [
                "minecraft:concrete@7"
            ]
        },
        {
            "x": -6,
            "y": 4,
            "z": -2,
            "elements": [
                "minecraft:iron_block@0"
            ]
        },
        {
            "x": 4,
            "y": 0,
            "z": -2,
            "elements": [
                "ic2:coolant@1"
            ]
        },
        {
            "x": -5,
            "y": -1,
            "z": 2,
            "elements": [
                "minecraft:concrete@7"
            ]
        },
        {
            "x": 22,
            "y": 4,
            "z": 3,
            "elements": [
                "appliedenergistics2:smooth_sky_stone_block@0"
            ]
        },
        {
            "x": 3,
            "y": 2,
            "z": -2,
            "elements": [
                "minecraft:stained_glass@0"
            ]
        },
        {
            "x": -4,
            "y": -3,
            "z": 2,
            "elements": [
                "minecraft:concrete@7"
            ]
        },
        {
            "x": 27,
            "y": -1,
            "z": -2,
            "elements": [
                "minecraft:iron_block@0"
            ]
        },
        {
            "x": 1,
            "y": 5,
            "z": 4,
            "elements": [
                "minecraft:stone_slab@0"
            ]
        },
        {
            "x": 2,
            "y": 5,
            "z": -1,
            "elements": [
                "minecraft:stone_slab@0"
            ]
        },
        {
            "x": 4,
            "y": 0,
            "z": 4,
            "elements": [
                "appliedenergistics2:smooth_sky_stone_block@0"
            ]
        },
        {
            "x": 5,
            "y": 3,
            "z": -1,
            "elements": [
                "minecraft:iron_block@0"
            ]
        },
        {
            "x": 9,
            "y": -3,
            "z": -1,
            "elements": [
                "minecraft:concrete@7"
            ]
        },
        {
            "x": 17,
            "y": 1,
            "z": 0,
            "elements": [
                "minecraft:iron_block@0"
            ]
        },
        {
            "x": -6,
            "y": 5,
            "z": 2,
            "elements": [
                "minecraft:stone_slab@0"
            ]
        },
        {
            "x": 27,
            "y": -2,
            "z": 3,
            "elements": [
                "minecraft:iron_block@0"
            ]
        },
        {
            "x": -8,
            "y": -1,
            "z": -1,
            "elements": [
                "minecraft:stained_glass@0"
            ]
        },
        {
            "x": 7,
            "y": 0,
            "z": 1,
            "elements": [
                "minecraft:iron_block@0"
            ]
        },
        {
            "x": 23,
            "y": -1,
            "z": 1,
            "elements": [
                "minecraft:iron_block@0"
            ]
        },
        {
            "x": 27,
            "y": 4,
            "z": -3,
            "elements": [
                "appliedenergistics2:smooth_sky_stone_block@0"
            ]
        },
        {
            "x": -1,
            "y": -2,
            "z": -2,
            "elements": [
                "appliedenergistics2:smooth_sky_stone_stairs@2"
            ]
        },
        {
            "x": 24,
            "y": -3,
            "z": 1,
            "elements": [
                "minecraft:concrete@7"
            ]
        },
        {
            "x": 5,
            "y": -3,
            "z": 2,
            "elements": [
                "minecraft:concrete@7"
            ]
        },
        {
            "x": 17,
            "y": 2,
            "z": 0,
            "elements": [
                "minecraft:iron_block@0"
            ]
        },
        {
            "x": 22,
            "y": 1,
            "z": 1,
            "elements": [
                "minecraft:iron_block@0"
            ]
        },
        {
            "x": 27,
            "y": -3,
            "z": 3,
            "elements": [
                "minecraft:concrete@7"
            ]
        },
        {
            "x": 27,
            "y": 3,
            "z": -3,
            "elements": [
                "minecraft:iron_block@0"
            ]
        },
        {
            "x": 22,
            "y": 2,
            "z": -1,
            "elements": [
                "minecraft:iron_block@0"
            ]
        },
        {
            "x": -8,
            "y": -2,
            "z": 1,
            "elements": [
                "minecraft:quartz_stairs@0"
            ]
        },
        {
            "x": 7,
            "y": 1,
            "z": -1,
            "elements": [
                "minecraft:iron_block@0"
            ]
        },
        {
            "x": 25,
            "y": 0,
            "z": 3,
            "elements": [
                "minecraft:iron_block@0"
            ]
        },
        {
            "x": 23,
            "y": -3,
            "z": 1,
            "elements": [
                "minecraft:concrete@7"
            ]
        },
        {
            "x": 4,
            "y": 3,
            "z": 4,
            "elements": [
                "appliedenergistics2:smooth_sky_stone_block@0"
            ]
        },
        {
            "x": 25,
            "y": 1,
            "z": 3,
            "elements": [
                "minecraft:iron_block@0"
            ]
        },
        {
            "x": 22,
            "y": 0,
            "z": -1,
            "elements": [
                "mekanism:glowplasticblock@15"
            ]
        },
        {
            "x": 5,
            "y": -1,
            "z": 2,
            "elements": [
                "minecraft:iron_block@0"
            ]
        },
        {
            "x": 4,
            "y": 4,
            "z": 4,
            "elements": [
                "appliedenergistics2:smooth_sky_stone_block@0"
            ]
        },
        {
            "x": 27,
            "y": 2,
            "z": -3,
            "elements": [
                "minecraft:iron_block@0"
            ]
        },
        {
            "x": 24,
            "y": 2,
            "z": -4,
            "elements": [
                "appliedenergistics2:smooth_sky_stone_block@0"
            ]
        },
        {
            "x": 7,
            "y": 2,
            "z": 1,
            "elements": [
                "minecraft:iron_block@0"
            ]
        },
        {
            "x": 7,
            "y": 3,
            "z": -1,
            "elements": [
                "minecraft:iron_block@0"
            ]
        },
        {
            "x": -8,
            "y": -3,
            "z": -1,
            "elements": [
                "minecraft:concrete@7"
            ]
        },
        {
            "x": 4,
            "y": 4,
            "z": 1,
            "elements": [
                "appliedenergistics2:smooth_sky_stone_block@0"
            ]
        },
        {
            "x": 27,
            "y": 1,
            "z": -3,
            "elements": [
                "minecraft:iron_block@0"
            ]
        },
        {
            "x": 2,
            "y": -3,
            "z": 2,
            "elements": [
                "minecraft:concrete@7"
            ]
        },
        {
            "x": 16,
            "y": 4,
            "z": 3,
            "elements": [
                "appliedenergistics2:smooth_sky_stone_block@0"
            ]
        },
        {
            "x": 25,
            "y": 2,
            "z": 3,
            "elements": [
                "minecraft:iron_block@0"
            ]
        },
        {
            "x": 24,
            "y": 1,
            "z": -4,
            "elements": [
                "appliedenergistics2:smooth_sky_stone_block@0"
            ]
        },
        {
            "x": -4,
            "y": 5,
            "z": 2,
            "elements": [
                "minecraft:stone_slab@0"
            ]
        },
        {
            "x": 27,
            "y": 0,
            "z": -3,
            "elements": [
                "minecraft:iron_block@0"
            ]
        },
        {
            "x": -2,
            "y": -1,
            "z": -1,
            "elements": [
                "minecraft:concrete@7"
            ]
        },
        {
            "x": 26,
            "y": -3,
            "z": -3,
            "elements": [
                "minecraft:concrete@7"
            ]
        },
        {
            "x": 19,
            "y": -2,
            "z": 0,
            "elements": [
                "minecraft:iron_block@0"
            ]
        },
        {
            "x": 9,
            "y": -2,
            "z": 1,
            "elements": [
                "minecraft:iron_block@0"
            ]
        },
        {
            "x": -5,
            "y": 4,
            "z": 1,
            "elements": [
                "minecraft:iron_block@0"
            ]
        },
        {
            "x": 16,
            "y": 2,
            "z": 4,
            "elements": [
                "appliedenergistics2:smooth_sky_stone_block@0"
            ]
        },
        {
            "x": 21,
            "y": 4,
            "z": -3,
            "elements": [
                "appliedenergistics2:smooth_sky_stone_block@0"
            ]
        },
        {
            "x": 1,
            "y": -2,
            "z": -2,
            "elements": [
                "appliedenergistics2:smooth_sky_stone_block@0"
            ]
        },
        {
            "x": 1,
            "y": 0,
            "z": 1,
            "elements": [
                "appliedenergistics2:smooth_sky_stone_stairs@1"
            ]
        },
        {
            "x": 11,
            "y": 2,
            "z": 0,
            "elements": [
                "minecraft:iron_block@0"
            ]
        },
        {
            "x": 26,
            "y": -1,
            "z": -3,
            "elements": [
                "mekanism:glowplasticblock@15"
            ]
        },
        {
            "x": 0,
            "y": -1,
            "z": 2,
            "elements": [
                "minecraft:concrete@7"
            ]
        },
        {
            "x": 20,
            "y": 0,
            "z": 0,
            "elements": [
                "minecraft:iron_block@0"
            ]
        },
        {
            "x": -1,
            "y": -3,
            "z": 2,
            "elements": [
                "minecraft:concrete@7"
            ]
        },
        {
            "x": -5,
            "y": -3,
            "z": -1,
            "elements": [
                "minecraft:concrete@7"
            ]
        },
        {
            "x": 4,
            "y": 2,
            "z": 1,
            "elements": [
                "ic2:coolant@1"
            ]
        },
        {
            "x": -3,
            "y": 4,
            "z": -2,
            "elements": [
                "minecraft:iron_block@0"
            ]
        },
        {
            "x": 25,
            "y": 0,
            "z": -1,
            "elements": [
                "minecraft:iron_block@0"
            ]
        },
        {
            "x": 21,
            "y": -3,
            "z": 3,
            "elements": [
                "minecraft:concrete@7"
            ]
        },
        {
            "x": 26,
            "y": -2,
            "z": -3,
            "elements": [
                "minecraft:quartz_stairs@2"
            ]
        },
        {
            "x": 11,
            "y": 1,
            "z": 0,
            "elements": [
                "minecraft:iron_block@0"
            ]
        },
        {
            "x": 16,
            "y": 1,
            "z": 4,
            "elements": [
                "appliedenergistics2:smooth_sky_stone_block@0"
            ]
        },
        {
            "x": 19,
            "y": -1,
            "z": 0,
            "elements": [
                "minecraft:iron_block@0"
            ]
        },
        {
            "x": 0,
            "y": -2,
            "z": -2,
            "elements": [
                "appliedenergistics2:smooth_sky_stone_stairs@2"
            ]
        },
        {
            "x": 19,
            "y": -3,
            "z": 0,
            "elements": [
                "minecraft:concrete@7"
            ]
        },
        {
            "x": -2,
            "y": -3,
            "z": -1,
            "elements": [
                "minecraft:concrete@7"
            ]
        },
        {
            "x": -3,
            "y": 5,
            "z": 2,
            "elements": [
                "minecraft:stone_slab@0"
            ]
        },
        {
            "x": 24,
            "y": 4,
            "z": -3,
            "elements": [
                "appliedenergistics2:smooth_sky_stone_block@0"
            ]
        },
        {
            "x": 4,
            "y": 0,
            "z": 1,
            "elements": [
                "ic2:coolant@1"
            ]
        },
        {
            "x": 16,
            "y": 0,
            "z": 4,
            "elements": [
                "appliedenergistics2:smooth_sky_stone_block@0"
            ]
        },
        {
            "x": -5,
            "y": -1,
            "z": -1,
            "elements": [
                "minecraft:concrete@7"
            ]
        },
        {
            "x": 23,
            "y": -3,
            "z": -3,
            "elements": [
                "minecraft:concrete@7"
            ]
        },
        {
            "x": 24,
            "y": -2,
            "z": 4,
            "elements": [
                "appliedenergistics2:smooth_sky_stone_block@0"
            ]
        },
        {
            "x": 6,
            "y": -2,
            "z": 1,
            "elements": [
                "minecraft:iron_block@0"
            ]
        },
        {
            "x": 24,
            "y": -3,
            "z": 3,
            "elements": [
                "minecraft:concrete@7"
            ]
        },
        {
            "x": 25,
            "y": 2,
            "z": -1,
            "elements": [
                "minecraft:iron_block@0"
            ]
        },
        {
            "x": -1,
            "y": -1,
            "z": 2,
            "elements": [
                "minecraft:concrete@7"
            ]
        },
        {
            "x": -2,
            "y": 4,
            "z": 1,
            "elements": [
                "minecraft:iron_block@0"
            ]
        },
        {
            "x": 0,
            "y": -3,
            "z": 2,
            "elements": [
                "minecraft:concrete@7"
            ]
        },
        {
            "x": -2,
            "y": 4,
            "z": -2,
            "elements": [
                "minecraft:iron_block@0"
            ]
        },
        {
            "x": 24,
            "y": -3,
            "z": 4,
            "elements": [
                "appliedenergistics2:smooth_sky_stone_block@0"
            ]
        },
        {
            "x": 28,
            "y": 4,
            "z": 2,
            "elements": [
                "appliedenergistics2:smooth_sky_stone_block@0"
            ]
        },
        {
            "x": 3,
            "y": -2,
            "z": 1,
            "elements": [
                "minecraft:iron_block@0"
            ]
        },
        {
            "x": 19,
            "y": 0,
            "z": -1,
            "elements": [
                "minecraft:iron_block@0"
            ]
        },
        {
            "x": 13,
            "y": -1,
            "z": 0,
            "elements": [
                "minecraft:iron_block@0"
            ]
        },
        {
            "x": 4,
            "y": -1,
            "z": -1,
            "elements": [
                "ic2:coolant@1"
            ]
        },
        {
            "x": -5,
            "y": 0,
            "z": 1,
            "elements": [
                "minecraft:end_rod@5"
            ]
        },
        {
            "x": -2,
            "y": 5,
            "z": 2,
            "elements": [
                "minecraft:stone_slab@0"
            ]
        },
        {
            "x": 14,
            "y": 0,
            "z": 0,
            "elements": [
                "mekanism:glowplasticblock@15"
            ]
        },
        {
            "x": 10,
            "y": -3,
            "z": 0,
            "elements": [
                "minecraft:concrete@7"
            ]
        },
        {
            "x": 10,
            "y": 2,
            "z": 1,
            "elements": [
                "minecraft:iron_block@0"
            ]
        },
        {
            "x": -2,
            "y": -1,
            "z": 2,
            "elements": [
                "minecraft:concrete@7"
            ]
        },
        {
            "x": 3,
            "y": -2,
            "z": -2,
            "elements": [
                "minecraft:iron_block@0"
            ]
        },
        {
            "x": 1,
            "y": 4,
            "z": 1,
            "elements": [
                "minecraft:iron_block@0"
            ]
        },
        {
            "x": 8,
            "y": 4,
            "z": 0,
            "elements": [
                "appliedenergistics2:smooth_sky_stone_block@0"
            ]
        },
        {
            "x": 1,
            "y": -3,
            "z": 2,
            "elements": [
                "minecraft:concrete@7"
            ]
        },
        {
            "x": -7,
            "y": 5,
            "z": -1,
            "elements": [
                "minecraft:stone_slab@0"
            ]
        },
        {
            "x": 13,
            "y": -2,
            "z": 0,
            "elements": [
                "minecraft:iron_block@0"
            ]
        },
        {
            "x": 27,
            "y": -2,
            "z": -1,
            "elements": [
                "minecraft:iron_block@0"
            ]
        },
        {
            "x": 19,
            "y": 4,
            "z": 3,
            "elements": [
                "appliedenergistics2:smooth_sky_stone_block@0"
            ]
        },
        {
            "x": -5,
            "y": 4,
            "z": -2,
            "elements": [
                "minecraft:iron_block@0"
            ]
        },
        {
            "x": 24,
            "y": -1,
            "z": 4,
            "elements": [
                "appliedenergistics2:smooth_sky_stone_block@0"
            ]
        },
        {
            "x": -5,
            "y": 5,
            "z": 2,
            "elements": [
                "minecraft:stone_slab@0"
            ]
        },
        {
            "x": 6,
            "y": -1,
            "z": 3,
            "elements": [
                "mekanism:glowplasticblock@15"
            ]
        },
        {
            "x": -8,
            "y": 4,
            "z": 1,
            "elements": [
                "minecraft:quartz_stairs@4"
            ]
        },
        {
            "x": 4,
            "y": 4,
            "z": 3,
            "elements": [
                "appliedenergistics2:smooth_sky_stone_block@0"
            ]
        },
        {
            "x": 11,
            "y": 0,
            "z": 0,
            "elements": [
                "minecraft:iron_block@0"
            ]
        },
        {
            "x": 16,
            "y": 4,
            "z": 4,
            "elements": [
                "appliedenergistics2:smooth_sky_stone_block@0"
            ]
        },
        {
            "x": 10,
            "y": -1,
            "z": 0,
            "elements": [
                "minecraft:iron_block@0"
            ]
        },
        {
            "x": 13,
            "y": -3,
            "z": 0,
            "elements": [
                "minecraft:concrete@7"
            ]
        },
        {
            "x": -2,
            "y": -2,
            "z": -2,
            "elements": [
                "appliedenergistics2:smooth_sky_stone_stairs@2"
            ]
        },
        {
            "x": 1,
            "y": -1,
            "z": 2,
            "elements": [
                "minecraft:concrete@7"
            ]
        },
        {
            "x": -5,
            "y": 2,
            "z": 1,
            "elements": [
                "minecraft:quartz_stairs@7"
            ]
        },
        {
            "x": 4,
            "y": -3,
            "z": -1,
            "elements": [
                "minecraft:concrete@7"
            ]
        },
        {
            "x": 16,
            "y": 3,
            "z": 4,
            "elements": [
                "appliedenergistics2:smooth_sky_stone_block@0"
            ]
        },
        {
            "x": 16,
            "y": 4,
            "z": -1,
            "elements": [
                "appliedenergistics2:smooth_sky_stone_block@0"
            ]
        },
        {
            "x": 10,
            "y": 0,
            "z": 1,
            "elements": [
                "mekanism:glowplasticblock@15"
            ]
        },
        {
            "x": -2,
            "y": -3,
            "z": 2,
            "elements": [
                "minecraft:concrete@7"
            ]
        },
        {
            "x": -8,
            "y": 0,
            "z": 0,
            "elements": [
                "minecraft:stained_glass@0"
            ]
        },
        {
            "x": 19,
            "y": 2,
            "z": -1,
            "elements": [
                "minecraft:iron_block@0"
            ]
        },
        {
            "x": 10,
            "y": -2,
            "z": 0,
            "elements": [
                "minecraft:iron_block@0"
            ]
        },
        {
            "x": 4,
            "y": 3,
            "z": 3,
            "elements": [
                "ic2:coolant@0"
            ]
        },
        {
            "x": 0,
            "y": 4,
            "z": -2,
            "elements": [
                "minecraft:iron_block@0"
            ]
        },
        {
            "x": 11,
            "y": 2,
            "z": -2,
            "elements": [
                "minecraft:quartz_stairs@2"
            ]
        },
        {
            "x": -3,
            "y": 0,
            "z": 1,
            "elements": [
                "minecraft:end_rod@5"
            ]
        },
        {
            "x": 20,
            "y": 0,
            "z": -4,
            "elements": [
                "appliedenergistics2:smooth_sky_stone_block@0"
            ]
        },
        {
            "x": 18,
            "y": 2,
            "z": 2,
            "elements": [
                "minecraft:quartz_stairs@3"
            ]
        },
        {
            "x": 8,
            "y": 4,
            "z": -2,
            "elements": [
                "appliedenergistics2:smooth_sky_stone_block@0"
            ]
        },
        {
            "x": 23,
            "y": 1,
            "z": 0,
            "elements": [
                "minecraft:iron_block@0"
            ]
        },
        {
            "x": -1,
            "y": -3,
            "z": -1,
            "elements": [
                "minecraft:concrete@7"
            ]
        },
        {
            "x": 7,
            "y": 0,
            "z": 3,
            "elements": [
                "minecraft:iron_block@0"
            ]
        },
        {
            "x": -8,
            "y": -1,
            "z": -3,
            "elements": [
                "minecraft:iron_block@0"
            ]
        },
        {
            "x": 3,
            "y": -3,
            "z": 2,
            "elements": [
                "minecraft:concrete@7"
            ]
        },
        {
            "x": -1,
            "y": 5,
            "z": -1,
            "elements": [
                "minecraft:stone_slab@0"
            ]
        },
        {
            "x": -7,
            "y": 4,
            "z": -2,
            "elements": [
                "minecraft:iron_block@0"
            ]
        },
        {
            "x": -1,
            "y": 4,
            "z": 1,
            "elements": [
                "minecraft:iron_block@0"
            ]
        },
        {
            "x": 13,
            "y": -2,
            "z": -2,
            "elements": [
                "minecraft:iron_block@0"
            ]
        },
        {
            "x": 11,
            "y": 0,
            "z": -2,
            "elements": [
                "minecraft:iron_block@0"
            ]
        },
        {
            "x": 23,
            "y": 2,
            "z": 0,
            "elements": [
                "minecraft:iron_block@0"
            ]
        },
        {
            "x": 14,
            "y": -3,
            "z": -3,
            "elements": [
                "minecraft:concrete@7"
            ]
        },
        {
            "x": 27,
            "y": 3,
            "z": 1,
            "elements": [
                "minecraft:iron_block@0"
            ]
        },
        {
            "x": 9,
