{
    "registryname": "east_tokamak",
    "localizedname": "§9全超导§c托卡马克等离子体生成设施",
    "failure-action": "still",
    "requires-blueprint": false,
    "color": "808080",
    "parts": [
        {
            "x": 0,
            "y": 0,
            "z": 0,

            "elements": [
                "modularmachinery:blockcontroller@2"
            ]
        },
        {
            "x": -5,
            "y": -4,
            "z": 10,
            "elements": [
                "minecraft:iron_block@0"
            ]
        },
        {
            "x": 0,
            "y": -2,
            "z": 0,

            "elements": [
                "modularmachinery:blockenergyinputhatch"
            ]
        },
        {
            "x": -8,
            "y": -4,
            "z": 12,
            "elements": [
                "minecraft:iron_block@0"
            ]
        },
        {
            "x": -3,
            "y": -4,
            "z": 15,
            "elements": [
                "minecraft:iron_block@0"
            ]
        },
        {
            "x": -3,
            "y": 6,
            "z": 7,
            "elements": [
                "chisel:laboratory@1"
            ]
        },
        {
            "x": 1,
            "y": -4,
            "z": 0,
            "elements": [
                "minecraft:iron_block@0"
            ]
        },
        {
            "x": -7,
            "y": -1,
            "z": 11,
            "elements": [
                "chisel:laboratory@13"
            ]
        },
        {
            "x": -4,
            "y": 4,
            "z": 5,
            "elements": [
                "extendedcrafting:storage@0"
            ]
        },
        {
            "x": 1,
            "y": -4,
            "z": 19,
            "elements": [
                "minecraft:iron_block@0"
            ]
        },
        {
            "x": -5,
            "y": 2,
            "z": 10,
            "elements": [
                "thermalfoundation:storage_alloy@0"
            ]
        },
        {
            "x": -8,
            "y": -3,
            "z": 12,
            "elements": [
                "chisel:laboratory@1"
            ]
        },
        {
            "x": 6,
            "y": 5,
            "z": 4,
            "elements": [
                "chisel:glasspane@13"
            ]
        },
        {
            "x": 2,
            "y": 4,
            "z": 17,
            "elements": [
                "chisel:glasspane@13"
            ]
        },
        {
            "x": -1,
            "y": -4,
            "z": 5,
            "elements": [
                "minecraft:iron_block@0"
            ]
        },
        {
            "x": -6,
            "y": 4,
            "z": 10,
            "elements": [
                "extendedcrafting:storage@0"
            ]
        },
        {
            "x": -4,
            "y": -4,
            "z": 10,
            "elements": [
                "minecraft:iron_block@0"
            ]
        },
        {
            "x": -5,
            "y": 0,
            "z": 15,
            "elements": [
                "cfm:castle_netting@0"
            ]
        },
        {
            "x": 5,
            "y": -4,
            "z": 1,
            "elements": [
                "minecraft:iron_block@0"
            ]
        },
        {
            "x": -2,
            "y": 0,
            "z": 5,
            "elements": [
                "contenttweaker:fixed_star_alloys_coil@0"
            ]
        },
        {
            "x": 0,
            "y": -4,
            "z": 0,
            "elements": [
                "minecraft:iron_block@0"
            ]
        },
        {
            "x": -5,
            "y": -2,
            "z": 10,
            "elements": [
                "thermalfoundation:storage_alloy@0"
            ]
        },
        {
            "x": -3,
            "y": 9,
            "z": 7,
            "elements": [
                "minecraft:iron_block@0"
            ]
        },
        {
            "x": 2,
            "y": 3,
            "z": 17,
            "elements": [
                "chisel:glasspane@13"
            ]
        },
        {
            "x": -6,
            "y": 2,
            "z": 10,
            "elements": [
                "thermalfoundation:storage_alloy@0"
            ]
        },
        {
            "x": 0,
            "y": 7,
            "z": 4,
            "elements": [
                "minecraft:iron_block@0"
            ]
        },
        {
            "x": 6,
            "y": 3,
            "z": 7,
            "elements": [
                "mets:titanium_block@0"
            ]
        },
        {
            "x": 8,
            "y": -2,
            "z": 7,
            "elements": [
                "chisel:laboratory@4"
            ]
        },
        {
            "x": 2,
            "y": 5,
            "z": 17,
            "elements": [
                "chisel:glasspane@13"
            ]
        },
        {
            "x": -8,
            "y": -4,
            "z": 15,
            "elements": [
                "minecraft:iron_block@0"
            ]
        },
        {
            "x": 6,
            "y": 3,
            "z": 4,
            "elements": [
                "chisel:glasspane@13"
            ]
        },
        {
            "x": 3,
            "y": -1,
            "z": 9,
            "elements": [
                "appliedenergistics2:smooth_sky_stone_slab@8"
            ]
        },
        {
            "x": -7,
            "y": -3,
            "z": 4,
            "elements": [
                "chisel:laboratory@1"
            ]
        },
        {
            "x": 2,
            "y": 2,
            "z": 17,
            "elements": [
                "minecraft:iron_block@0"
            ]
        },
        {
            "x": -2,
            "y": 9,
            "z": 9,
            "elements": [
                "minecraft:iron_block@0"
            ]
        },
        {
            "x": 6,
            "y": 1,
            "z": 4,
            "elements": [
                "cfm:castle_netting@0"
            ]
        },
        {
            "x": 3,
            "y": 6,
            "z": 7,
            "elements": [
                "chisel:laboratory@1"
            ]
        },
        {
            "x": 0,
            "y": -4,
            "z": 5,
            "elements": [
                "minecraft:iron_block@0"
            ]
        },
        {
            "x": -7,
            "y": -4,
            "z": 10,
            "elements": [
                "minecraft:iron_block@0"
            ]
        },
        {
            "x": -3,
            "y": 6,
            "z": 5,
            "elements": [
                "environmentalmaterials:alabaster_wall_silver@0"
            ]
        },
        {
            "x": 3,
            "y": -4,
            "z": 0,
            "elements": [
                "minecraft:iron_block@0"
            ]
        },
        {
            "x": -5,
            "y": -4,
            "z": 15,
            "elements": [
                "minecraft:iron_block@0"
            ]
        },
        {
            "x": -6,
            "y": 4,
            "z": 5,
            "elements": [
                "chisel:glasspane@13"
            ]
        },
        {
            "x": -7,
            "y": 2,
            "z": 10,
            "elements": [
                "thermalfoundation:storage_alloy@0"
            ]
        },
        {
            "x": 9,
            "y": 3,
            "z": 7,
            "elements": [
                "chisel:laboratory@1"
            ]
        },
        {
            "x": -4,
            "y": 0,
            "z": 10,
            "elements": [
                "contenttweaker:fixed_star_alloys_coil@0"
            ]
        },
        {
            "x": -3,
            "y": -4,
            "z": 5,
            "elements": [
                "minecraft:iron_block@0"
            ]
        },
        {
            "x": -9,
            "y": 3,
            "z": 11,
            "elements": [
                "chisel:laboratory@1"
            ]
        },
        {
            "x": 0,
            "y": 4,
            "z": 3,
            "elements": [
                "extendedcrafting:storage@0"
            ]
        },
        {
            "x": -6,
            "y": -2,
            "z": 5,
            "elements": [
                "chisel:laboratory@1"
            ]
        },
        {
            "x": -9,
            "y": -3,
            "z": 9,
            "elements": [
                "chisel:laboratory@1"
            ]
        },
        {
            "x": 3,
            "y": 9,
            "z": 7,
            "elements": [
                "minecraft:iron_block@0"
            ]
        },
        {
            "x": 1,
            "y": -1,
            "z": 17,
            "elements": [
                "chisel:futura@0"
            ]
        },
        {
            "x": 0,
            "y": -1,
            "z": 11,
            "elements": [
                "appliedenergistics2:smooth_sky_stone_slab@8"
            ]
        },
        {
            "x": 0,
            "y": 0,
            "z": 5,
            "elements": [
                "contenttweaker:fixed_star_alloys_coil@0"
            ]
        },
        {
            "x": 4,
            "y": -4,
            "z": 17,
            "elements": [
                "minecraft:iron_block@0"
            ]
        },
        {
            "x": 1,
            "y": -2,
            "z": 17,
            "elements": [
                "chisel:laboratory@4"
            ]
        },
        {
            "x": 5,
            "y": -1,
            "z": 4,
            "elements": [
                "chisel:laboratory@15"
            ]
        },
        {
            "x": -7,
            "y": -2,
            "z": 10,
            "elements": [
                "thermalfoundation:storage_alloy@0"
            ]
        },
        {
            "x": -2,
            "y": -4,
            "z": 0,
            "elements": [
                "minecraft:iron_block@0"
            ]
        },
        {
            "x": -2,
            "y": -4,
            "z": 10,
            "elements": [
                "minecraft:iron_block@0"
            ]
        },
        {
            "x": -6,
            "y": -4,
            "z": 15,
            "elements": [
                "minecraft:iron_block@0"
            ]
        },
        {
            "x": 0,
            "y": 10,
            "z": 7,
            "elements": [
                "minecraft:iron_block@0"
            ]
        },
        {
            "x": 4,
            "y": -3,
            "z": 17,
            "elements": [
                "chisel:laboratory@1"
            ]
        },
        {
            "x": -6,
            "y": 5,
            "z": 4,
            "elements": [
                "chisel:glasspane@13"
            ]
        },
        {
            "x": -1,
            "y": 6,
            "z": 5,
            "elements": [
                "chisel:laboratory@4"
            ]
        },
        {
            "x": 3,
            "y": 7,
            "z": 6,
            "elements": [
                "minecraft:iron_block@0"
            ]
        },
        {
            "x": -8,
            "y": 3,
            "z": 11,
            "elements": [
                "chisel:glasspane@13"
            ]
        },
        {
            "x": -1,
            "y": 6,
            "z": 12,
            "elements": [
                "extendedcrafting:storage@0"
            ]
        },
        {
            "x": 3,
            "y": 9,
            "z": 8,
            "elements": [
                "minecraft:iron_block@0"
            ]
        },
        {
            "x": 5,
            "y": -1,
            "z": 7,
            "elements": [
                "extendedcrafting:storage@0"
            ]
        },
        {
            "x": 0,
            "y": 9,
            "z": 7,
            "elements": [
                "minecraft:iron_block@0"
            ]
        },
        {
            "x": 7,
            "y": 3,
            "z": 9,
            "elements": [
                "mets:titanium_block@0"
            ]
        },
        {
            "x": 2,
            "y": -1,
            "z": 4,
            "elements": [
                "extendedcrafting:storage@0"
            ]
        },
        {
            "x": -3,
            "y": -4,
            "z": 0,
            "elements": [
                "minecraft:iron_block@0"
            ]
        },
        {
            "x": -8,
            "y": -2,
            "z": 10,
            "elements": [
                "chisel:laboratory@4"
            ]
        },
        {
            "x": -1,
            "y": -4,
            "z": 10,
            "elements": [
                "minecraft:iron_block@0"
            ]
        },
        {
            "x": 4,
            "y": -4,
            "z": 12,
            "elements": [
                "minecraft:iron_block@0"
            ]
        },
        {
            "x": 0,
            "y": 1,
            "z": 4,
            "elements": [
                "extendedcrafting:storage@0"
            ]
        },
        {
            "x": 4,
            "y": 7,
            "z": 9,
            "elements": [
                "mets:titanium_block@0"
            ]
        },
        {
            "x": -7,
            "y": -4,
            "z": 15,
            "elements": [
                "minecraft:iron_block@0"
            ]
        },
        {
            "x": 9,
            "y": 3,
            "z": 8,
            "elements": [
                "chisel:laboratory@1"
            ]
        },
        {
            "x": -4,
            "y": 3,
            "z": 16,
            "elements": [
                "chisel:glasspane@13"
            ]
        },
        {
            "x": -7,
            "y": 2,
            "z": 5,
            "elements": [
                "chisel:laboratory@2"
            ]
        },
        {
            "x": 4,
            "y": -3,
            "z": 16,
            "elements": [
                "chisel:laboratory@2"
            ]
        },
        {
            "x": -1,
            "y": -1,
            "z": 4,
            "elements": [
                "extendedcrafting:storage@0"
            ]
        },
        {
            "x": -5,
            "y": -4,
            "z": 5,
            "elements": [
                "minecraft:iron_block@0"
            ]
        },
        {
            "x": -2,
            "y": 1,
            "z": 9,
            "elements": [
                "appliedenergistics2:smooth_sky_stone_slab@0"
            ]
        },
        {
            "x": 1,
            "y": 9,
            "z": 9,
            "elements": [
                "minecraft:iron_block@0"
            ]
        },
        {
            "x": 3,
            "y": 6,
            "z": 6,
            "elements": [
                "chisel:laboratory@1"
            ]
        },
        {
            "x": 5,
            "y": -4,
            "z": 3,
            "elements": [
                "minecraft:iron_block@0"
            ]
        },
        {
            "x": -6,
            "y": -4,
            "z": 3,
            "elements": [
                "minecraft:iron_block@0"
            ]
        },
        {
            "x": 0,
            "y": 6,
            "z": 7,
            "elements": [
                "extendedcrafting:storage@0"
            ]
        },
        {
            "x": -8,
            "y": -4,
            "z": 10,
            "elements": [
                "minecraft:iron_block@0"
            ]
        },
        {
            "x": 4,
            "y": -4,
            "z": 0,
            "elements": [
                "minecraft:iron_block@0"
            ]
        },
        {
            "x": 0,
            "y": 6,
            "z": 5,
            "elements": [
                "chisel:laboratory@4"
            ]
        },
        {
            "x": -4,
            "y": -4,
            "z": 15,
            "elements": [
                "minecraft:iron_block@0"
            ]
        },
        {
            "x": -4,
            "y": 5,
            "z": 16,
            "elements": [
                "chisel:glasspane@13"
            ]
        },
        {
            "x": 2,
            "y": 0,
            "z": 5,
            "elements": [
                "contenttweaker:fixed_star_alloys_coil@0"
            ]
        },
        {
            "x": 1,
            "y": 3,
            "z": 16,
            "elements": [
                "mets:titanium_block@0"
            ]
        },
        {
            "x": -6,
            "y": 3,
            "z": 4,
            "elements": [
                "chisel:glasspane@13"
            ]
        },
        {
            "x": 2,
            "y": 1,
            "z": 16,
            "elements": [
                "chisel:laboratory@13"
            ]
        },
        {
            "x": 5,
            "y": -2,
            "z": 3,
            "elements": [
                "cfm:castle_netting@0"
            ]
        },
        {
            "x": -2,
            "y": -1,
            "z": 16,
            "elements": [
                "chisel:laboratory@14"
            ]
        },
        {
            "x": 5,
            "y": -3,
            "z": 4,
            "elements": [
                "chisel:laboratory@15"
            ]
        },
        {
            "x": 3,
            "y": 8,
            "z": 6,
            "elements": [
                "chisel:laboratory@2"
            ]
        },
        {
            "x": -2,
            "y": -4,
            "z": 19,
            "elements": [
                "minecraft:iron_block@0"
            ]
        },
        {
            "x": 8,
            "y": -3,
            "z": 7,
            "elements": [
                "chisel:laboratory@2"
            ]
        },
        {
            "x": 4,
            "y": -4,
            "z": 5,
            "elements": [
                "minecraft:iron_block@0"
            ]
        },
        {
            "x": 4,
            "y": 1,
            "z": 9,
            "elements": [
                "thermalfoundation:storage_alloy@0"
            ]
        },
        {
            "x": -5,
            "y": 1,
            "z": 11,
            "elements": [
                "extendedcrafting:storage@0"
            ]
        },
        {
            "x": 0,
            "y": 9,
            "z": 6,
            "elements": [
                "minecraft:iron_block@0"
            ]
        },
        {
            "x": 4,
            "y": -1,
            "z": 12,
            "elements": [
                "extendedcrafting:storage@0"
            ]
        },
        {
            "x": -1,
            "y": 0,
            "z": 5,
            "elements": [
                "contenttweaker:fixed_star_alloys_coil@0"
            ]
        },
        {
            "x": -5,
            "y": -1,
            "z": 11,
            "elements": [
                "extendedcrafting:storage@0"
            ]
        },
        {
            "x": -4,
            "y": -2,
            "z": 15,
            "elements": [
                "chisel:laboratory@1"
            ]
        },
        {
            "x": -1,
            "y": -4,
            "z": 15,
            "elements": [
                "minecraft:iron_block@0"
            ]
        },
        {
            "x": -5,
            "y": 7,
            "z": 9,
            "elements": [
                "minecraft:iron_block@0"
            ]
        },
        {
            "x": 0,
            "y": 0,
            "z": 10,
            "elements": [
                "minecraft:stone@6"
            ]
        },
        {
            "x": -2,
            "y": 3,
            "z": 16,
            "elements": [
                "chisel:glasspane@13"
            ]
        },
        {
            "x": 8,
            "y": -4,
            "z": 7,
            "elements": [
                "minecraft:iron_block@0"
            ]
        },
        {
            "x": -3,
            "y": 6,
            "z": 10,
            "elements": [
                "extendedcrafting:storage@0"
            ]
        },
        {
            "x": -8,
            "y": 5,
            "z": 11,
            "elements": [
                "chisel:glasspane@13"
            ]
        },
        {
            "x": 9,
            "y": -3,
            "z": 9,
            "elements": [
                "chisel:laboratory@1"
            ]
        },
        {
            "x": 0,
            "y": 5,
            "z": 4,
            "elements": [
                "minecraft:iron_block@0"
            ]
        },
        {
            "x": -5,
            "y": 4,
            "z": 15,
            "elements": [
                "chisel:glasspane@13"
            ]
        },
        {
            "x": -5,
            "y": 5,
            "z": 9,
            "elements": [
                "minecraft:iron_block@0"
            ]
        },
        {
            "x": 1,
            "y": -4,
            "z": 5,
            "elements": [
                "minecraft:iron_block@0"
            ]
        },
        {
            "x": 9,
            "y": -1,
            "z": 9,

            "elements": [
                "fluid_in"
            ]
        },
        {
            "x": 1,
            "y": 1,
            "z": 9,
            "elements": [
                "appliedenergistics2:smooth_sky_stone_slab@0"
            ]
        },
        {
            "x": -4,
            "y": -3,
            "z": 1,
            "elements": [
                "chisel:laboratory@1"
            ]
        },
        {
            "x": -2,
            "y": 5,
            "z": 16,
            "elements": [
                "chisel:glasspane@13"
            ]
        },
        {
            "x": 2,
            "y": -4,
            "z": 10,
            "elements": [
                "minecraft:iron_block@0"
            ]
        },
        {
            "x": 1,
            "y": -4,
            "z": 12,
            "elements": [
                "minecraft:iron_block@0"
            ]
        },
        {
            "x": -1,
            "y": 3,
            "z": 16,
            "elements": [
                "mets:titanium_block@0"
            ]
        },
        {
            "x": -7,
            "y": 4,
            "z": 5,
            "elements": [
                "chisel:glasspane@13"
            ]
        },
        {
            "x": -6,
            "y": 1,
            "z": 4,
            "elements": [
                "cfm:castle_netting@0"
            ]
        },
        {
            "x": 0,
            "y": 6,
            "z": 6,
            "elements": [
                "extendedcrafting:storage@0"
            ]
        },
        {
            "x": -4,
            "y": -1,
            "z": 9,
            "elements": [
                "thermalfoundation:storage_alloy@0"
            ]
        },
        {
            "x": -7,
            "y": 3,
            "z": 4,
            "elements": [
                "chisel:laboratory@1"
            ]
        },
        {
            "x": -5,
            "y": 2,
            "z": 15,
            "elements": [
                "chisel:laboratory@2"
            ]
        },
        {
            "x": 5,
            "y": -4,
            "z": 7,
            "elements": [
                "minecraft:iron_block@0"
            ]
        },
        {
            "x": 8,
            "y": -4,
            "z": 3,
            "elements": [
                "minecraft:iron_block@0"
            ]
        },
        {
            "x": -4,
            "y": -4,
            "z": 1,
            "elements": [
                "minecraft:iron_block@0"
            ]
        },
        {
            "x": -6,
            "y": 3,
            "z": 11,
            "elements": [
                "mets:titanium_block@0"
            ]
        },
        {
            "x": -2,
            "y": -4,
            "z": 5,
            "elements": [
                "minecraft:iron_block@0"
            ]
        },
        {
            "x": 5,
            "y": -4,
            "z": 8,
            "elements": [
                "minecraft:iron_block@0"
            ]
        },
        {
            "x": 3,
            "y": 7,
            "z": 13,
            "elements": [
                "minecraft:iron_block@0"
            ]
        },
        {
            "x": 8,
            "y": -3,
            "z": 6,
            "elements": [
                "chisel:laboratory@1"
            ]
        },
        {
            "x": 7,
            "y": -3,
            "z": 12,
            "elements": [
                "chisel:laboratory@2"
            ]
        },
        {
            "x": 3,
            "y": 6,
            "z": 5,
            "elements": [
                "environmentalmaterials:alabaster_wall_silver@0"
            ]
        },
        {
            "x": -7,
            "y": -4,
            "z": 3,
            "elements": [
                "minecraft:iron_block@0"
            ]
        },
        {
            "x": 6,
            "y": 3,
            "z": 14,
            "elements": [
                "chisel:glasspane@13"
            ]
        },
        {
            "x": 0,
            "y": 9,
            "z": 11,
            "elements": [
                "minecraft:iron_block@0"
            ]
        },
        {
            "x": -8,
            "y": 5,
            "z": 9,
            "elements": [
                "chisel:glasspane@13"
            ]
        },
        {
            "x": 8,
            "y": -4,
            "z": 6,
            "elements": [
                "minecraft:iron_block@0"
            ]
        },
        {
            "x": 1,
            "y": 4,
            "z": 3,
            "elements": [
                "extendedcrafting:storage@0"
            ]
        },
        {
            "x": -6,
            "y": 5,
            "z": 8,
            "elements": [
                "chisel:laboratory@4"
            ]
        },
        {
            "x": 3,
            "y": -4,
            "z": 10,
            "elements": [
                "minecraft:iron_block@0"
            ]
        },
        {
            "x": 4,
            "y": 2,
            "z": 3,
            "elements": [
                "chisel:laboratory@1"
            ]
        },
        {
            "x": -3,
            "y": -3,
            "z": 16,
            "elements": [
                "chisel:laboratory@2"
            ]
        },
        {
            "x": -7,
            "y": 7,
            "z": 9,
            "elements": [
                "environmentalmaterials:alabaster_wall_silver@0"
            ]
        },
        {
            "x": -2,
            "y": -3,
            "z": 18,
            "elements": [
                "chisel:laboratory@1"
            ]
        },
        {
            "x": 4,
            "y": 0,
            "z": 3,
            "elements": [
                "chisel:laboratory@1"
            ]
        },
        {
            "x": 8,
            "y": -4,
            "z": 8,
            "elements": [
                "minecraft:iron_block@0"
            ]
        },
        {
            "x": 7,
            "y": -4,
            "z": 12,
            "elements": [
                "minecraft:iron_block@0"
            ]
        },
        {
            "x": -5,
            "y": -1,
            "z": 4,
            "elements": [
                "chisel:laboratory@15"
            ]
        },
        {
            "x": -3,
            "y": -1,
            "z": 16,
            "elements": [
                "mets:titanium_block@0"
            ]
        },
        {
            "x": 5,
            "y": -2,
            "z": 8,
            "elements": [
                "thermalfoundation:storage_alloy@0"
            ]
        },
        {
            "x": 6,
            "y": 3,
            "z": 13,
            "elements": [
                "chisel:glasspane@13"
            ]
        },
        {
            "x": 6,
            "y": 4,
            "z": 14,
            "elements": [
                "chisel:glasspane@13"
            ]
        },
        {
            "x": -1,
            "y": 3,
            "z": 18,
            "elements": [
                "chisel:laboratory@1"
            ]
        },
        {
            "x": -7,
            "y": 5,
            "z": 9,
            "elements": [
                "environmentalmaterials:alabaster_wall_silver@0"
            ]
        },
        {
            "x": 7,
            "y": -4,
            "z": 5,
            "elements": [
                "minecraft:iron_block@0"
            ]
        },
        {
            "x": 3,
            "y": 9,
            "z": 11,
            "elements": [
                "minecraft:iron_block@0"
            ]
        },
        {
            "x": 5,
            "y": -1,
            "z": 8,
            "elements": [
                "extendedcrafting:storage@0"
            ]
        },
        {
            "x": -1,
            "y": 1,
            "z": 4,
            "elements": [
                "extendedcrafting:storage@0"
            ]
        },
        {
            "x": 6,
            "y": 5,
            "z": 14,
            "elements": [
                "chisel:glasspane@13"
            ]
        },
        {
            "x": 7,
            "y": -1,
            "z": 12,
            "elements": [
                "mets:titanium_block@0"
            ]
        },
        {
            "x": 6,
            "y": 2,
            "z": 5,
            "elements": [
                "chisel:laboratory@1"
            ]
        },
        {
            "x": 1,
            "y": -3,
            "z": 18,
            "elements": [
                "chisel:laboratory@1"
            ]
        },
        {
            "x": 6,
            "y": 0,
            "z": 5,
            "elements": [
                "chisel:laboratory@1"
            ]
        },
        {
            "x": -5,
            "y": -1,
            "z": 9,
            "elements": [
                "extendedcrafting:storage@0"
            ]
        },
        {
            "x": -2,
            "y": 1,
            "z": 16,
            "elements": [
                "chisel:laboratory@14"
            ]
        },
        {
            "x": -2,
            "y": 10,
            "z": 10,
            "elements": [
                "minecraft:iron_block@0"
            ]
        },
        {
            "x": 7,
            "y": -2,
            "z": 12,
            "elements": [
                "mets:titanium_block@0"
            ]
        },
        {
            "x": -5,
            "y": 1,
            "z": 9,
            "elements": [
                "extendedcrafting:storage@0"
            ]
        },
        {
            "x": 6,
            "y": -4,
            "z": 3,
            "elements": [
                "minecraft:iron_block@0"
            ]
        },
        {
            "x": 4,
            "y": -4,
            "z": 13,
            "elements": [
                "minecraft:iron_block@0"
            ]
        },
        {
            "x": 0,
            "y": 6,
            "z": 10,
            "elements": [
                "extendedcrafting:storage@0"
            ]
        },
        {
            "x": 4,
            "y": -4,
            "z": 18,
            "elements": [
                "minecraft:iron_block@0"
            ]
        },
        {
            "x": 0,
            "y": 8,
            "z": 5,
            "elements": [
                "mets:titanium_block@0"
            ]
        },
        {
            "x": -9,
            "y": 3,
            "z": 8,
            "elements": [
                "chisel:laboratory@1"
            ]
        },
        {
            "x": 8,
            "y": -3,
            "z": 11,
            "elements": [
                "chisel:laboratory@2"
            ]
        },
        {
            "x": -6,
            "y": 5,
            "z": 9,
            "elements": [
                "chisel:laboratory@4"
            ]
        },
        {
            "x": 8,
            "y": -1,
            "z": 8,
            "elements": [
                "chisel:futura@0"
            ]
        },
        {
            "x": -1,
            "y": 8,
            "z": 5,
            "elements": [
                "chisel:laboratory@2"
            ]
        },
        {
            "x": 8,
            "y": -3,
            "z": 8,
            "elements": [
                "chisel:laboratory@2"
            ]
        },
        {
            "x": -2,
            "y": 1,
            "z": 4,
            "elements": [
                "extendedcrafting:storage@0"
            ]
        },
        {
            "x": 6,
            "y": 0,
            "z": 13,
            "elements": [
                "chisel:laboratory@1"
            ]
        },
        {
            "x": 6,
            "y": 3,
            "z": 6,
            "elements": [
                "mets:titanium_block@0"
            ]
        },
        {
            "x": 2,
            "y": 6,
            "z": 5,
            "elements": [
                "environmentalmaterials:alabaster_wall_silver@0"
            ]
        },
        {
            "x": -3,
            "y": -1,
            "z": 9,
            "elements": [
                "appliedenergistics2:smooth_sky_stone_slab@8"
            ]
        },
        {
            "x": -2,
            "y": -1,
            "z": 4,
            "elements": [
                "extendedcrafting:storage@0"
            ]
        },
        {
            "x": 8,
            "y": -4,
            "z": 5,
            "elements": [
                "minecraft:iron_block@0"
            ]
        },
        {
            "x": -3,
            "y": 6,
            "z": 8,
            "elements": [
                "extendedcrafting:storage@0"
            ]
        },
        {
            "x": -5,
            "y": -4,
            "z": 0,
            "elements": [
                "minecraft:iron_block@0"
            ]
        },
        {
            "x": -5,
            "y": 3,
            "z": 4,
            "elements": [
                "chisel:glasspane@13"
            ]
        },
        {
            "x": 0,
            "y": 9,
            "z": 13,
            "elements": [
                "mets:titanium_block@0"
            ]
        },
        {
            "x": 4,
            "y": 0,
            "z": 10,
            "elements": [
                "contenttweaker:fixed_star_alloys_coil@0"
            ]
        },
        {
            "x": -8,
            "y": 1,
            "z": 9,
            "elements": [
                "chisel:futura@0"
            ]
        },
        {
            "x": 6,
            "y": -2,
            "z": 10,
            "elements": [
                "thermalfoundation:storage_alloy@0"
            ]
        },
        {
            "x": -1,
            "y": 4,
            "z": 15,
            "elements": [
                "extendedcrafting:storage@0"
            ]
        },
        {
            "x": 3,
            "y": 6,
            "z": 13,
            "elements": [
                "environmentalmaterials:alabaster_wall_silver@0"
            ]
        },
        {
            "x": 2,
            "y": 6,
            "z": 13,
            "elements": [
                "environmentalmaterials:alabaster_wall_silver@0"
            ]
        },
        {
            "x": -5,
            "y": 2,
            "z": 3,
            "elements": [
                "chisel:laboratory@2"
            ]
        },
        {
            "x": 6,
            "y": 2,
            "z": 8,
            "elements": [
                "thermalfoundation:storage_alloy@0"
            ]
        },
        {
            "x": 7,
            "y": -4,
            "z": 13,
            "elements": [
                "minecraft:iron_block@0"
            ]
        },
        {
            "x": 3,
            "y": -4,
            "z": 3,
            "elements": [
                "minecraft:iron_block@0"
            ]
        },
        {
            "x": 3,
            "y": 5,
            "z": 13,
            "elements": [
                "chisel:laboratory@0"
            ]
        },
        {
            "x": -4,
            "y": -2,
            "z": 3,
            "elements": [
                "chisel:laboratory@1"
            ]
        },
        {
            "x": -4,
            "y": 3,
            "z": 4,
            "elements": [
                "mets:titanium_block@0"
            ]
        },
        {
            "x": 1,
            "y": 6,
            "z": 10,
            "elements": [
                "extendedcrafting:storage@0"
            ]
        },
        {
            "x": 1,
            "y": -4,
            "z": 18,
            "elements": [
                "minecraft:iron_block@0"
            ]
        },
        {
            "x": 2,
            "y": -4,
            "z": 8,
            "elements": [
                "minecraft:iron_block@0"
            ]
        },
        {
            "x": -4,
            "y": -4,
            "z": 3,
            "elements": [
                "minecraft:iron_block@0"
            ]
        },
        {
            "x": -5,
            "y": 5,
            "z": 4,
            "elements": [
                "chisel:glasspane@13"
            ]
        },
        {
            "x": 6,
            "y": 4,
            "z": 8,
            "elements": [
                "extendedcrafting:storage@0"
            ]
        },
        {
            "x": 5,
            "y": 4,
            "z": 12,
            "elements": [
                "extendedcrafting:storage@0"
            ]
        },
        {
            "x": 2,
            "y": 9,
            "z": 12,
            "elements": [
                "minecraft:iron_block@0"
            ]
        },
        {
            "x": 0,
            "y": 7,
            "z": 13,
            "elements": [
                "mets:titanium_block@0"
            ]
        },
        {
            "x": 5,
            "y": -4,
            "z": 5,
            "elements": [
                "minecraft:iron_block@0"
            ]
        },
        {
            "x": 1,
            "y": -2,
            "z": 15,
            "elements": [
                "thermalfoundation:storage_alloy@0"
            ]
        },
        {
            "x": -7,
            "y": -2,
            "z": 8,
            "elements": [
                "thermalfoundation:storage_alloy@0"
            ]
        },
        {
            "x": 0,
            "y": 10,
            "z": 10,
            "elements": [
                "minecraft:iron_block@0"
            ]
        },
        {
            "x": -5,
            "y": 0,
            "z": 3,
            "elements": [
                "cfm:castle_netting@0"
            ]
        },
        {
            "x": 2,
            "y": 6,
            "z": 12,
            "elements": [
                "chisel:laboratory@1"
            ]
        },
        {
            "x": 7,
            "y": -3,
            "z": 13,
            "elements": [
                "chisel:laboratory@2"
            ]
        },
        {
            "x": 1,
            "y": 2,
            "z": 3,
            "elements": [
                "thermalfoundation:storage_alloy@0"
            ]
        },
        {
            "x": -6,
            "y": 7,
            "z": 9,
            "elements": [
                "environmentalmaterials:alabaster_wall_silver@0"
            ]
        },
        {
            "x": 6,
            "y": 2,
            "z": 13,
            "elements": [
                "chisel:laboratory@1"
            ]
        },
        {
            "x": 6,
            "y": 3,
            "z": 11,
            "elements": [
                "mets:titanium_block@0"
            ]
        },
        {
            "x": 8,
            "y": 3,
            "z": 12,
            "elements": [
                "chisel:laboratory@1"
            ]
        },
        {
            "x": 0,
            "y": 8,
            "z": 13,
            "elements": [
                "mets:titanium_block@0"
            ]
        },
        {
            "x": -5,
            "y": 3,
            "z": 16,
            "elements": [
                "chisel:laboratory@1"
            ]
        },
        {
            "x": 0,
            "y": 0,
            "z": 8,
            "elements": [
                "minecraft:stone@6"
            ]
        },
        {
            "x": 6,
            "y": 1,
            "z": 13,
            "elements": [
                "chisel:laboratory@1"
            ]
        },
        {
            "x": 6,
            "y": -4,
            "z": 10,
            "elements": [
                "minecraft:iron_block@0"
            ]
        },
        {
            "x": 8,
            "y": -2,
            "z": 8,
            "elements": [
                "chisel:laboratory@4"
            ]
        },
        {
            "x": -8,
            "y": 3,
            "z": 9,
            "elements": [
                "chisel:glasspane@13"
            ]
        },
        {
            "x": 2,
            "y": 8,
            "z": 5,
            "elements": [
                "chisel:laboratory@2"
            ]
        },
        {
            "x": -3,
            "y": 1,
            "z": 9,
            "elements": [
                "appliedenergistics2:smooth_sky_stone_slab@0"
            ]
        },
        {
            "x": -1,
            "y": 9,
            "z": 12,
            "elements": [
                "minecraft:iron_block@0"
            ]
        },
        {
            "x": -9,
            "y": -3,
            "z": 11,
            "elements": [
                "chisel:laboratory@1"
            ]
        },
        {
            "x": -1,
            "y": 2,
            "z": 15,
            "elements": [
                "thermalfoundation:storage_alloy@0"
            ]
        },
        {
            "x": -2,
            "y": 6,
            "z": 10,
            "elements": [
                "extendedcrafting:storage@0"
            ]
        },
        {
            "x": 2,
            "y": -4,
            "z": 5,
            "elements": [
                "minecraft:iron_block@0"
            ]
        },
        {
            "x": -4,
            "y": 0,
            "z": 15,
            "elements": [
                "chisel:laboratory@1"
            ]
        },
        {
            "x": -7,
            "y": -4,
            "z": 8,
            "elements": [
                "minecraft:iron_block@0"
            ]
        },
        {
            "x": -9,
            "y": -4,
            "z": 10,
            "elements": [
                "minecraft:iron_block@0"
            ]
        },
        {
            "x": -3,
            "y": -4,
            "z": 3,
            "elements": [
                "minecraft:iron_block@0"
            ]
        },
        {
            "x": 0,
            "y": 7,
            "z": 14,
            "elements": [
                "minecraft:iron_block@0"
            ]
        },
        {
            "x": -8,
            "y": -3,
            "z": 9,
            "elements": [
                "chisel:laboratory@2"
            ]
        },
        {
            "x": -1,
            "y": 3,
            "z": 17,
            "elements": [
                "chisel:glasspane@13"
            ]
        },
        {
            "x": 8,
            "y": -3,
            "z": 13,
            "elements": [
                "chisel:laboratory@1"
            ]
        },
        {
            "x": 1,
            "y": -4,
            "z": 15,
            "elements": [
                "minecraft:iron_block@0"
            ]
        },
        {
            "x": -1,
            "y": 2,
            "z": 17,
            "elements": [
                "minecraft:iron_block@0"
            ]
        },
        {
            "x": -1,
            "y": 7,
            "z": 4,
            "elements": [
                "minecraft:iron_block@0"
            ]
        },
        {
            "x": -8,
            "y": -1,
            "z": 9,
            "elements": [
                "chisel:futura@0"
            ]
        },
        {
            "x": -4,
            "y": 2,
            "z": 15,
            "elements": [
                "chisel:laboratory@1"
            ]
        },
        {
            "x": 0,
            "y": 9,
            "z": 8,
            "elements": [
                "minecraft:iron_block@0"
            ]
        },
        {
            "x": -6,
            "y": -3,
            "z": 4,
            "elements": [
                "chisel:laboratory@2"
            ]
        },
        {
            "x": 0,
            "y": 1,
            "z": 11,
            "elements": [
                "appliedenergistics2:smooth_sky_stone_slab@0"
            ]
        },
        {
            "x": 2,
            "y": 7,
            "z": 13,
            "elements": [
                "minecraft:iron_block@0"
            ]
        },
        {
            "x": 4,
            "y": -4,
            "z": 15,
            "elements": [
                "minecraft:iron_block@0"
            ]
        },
        {
            "x": 0,
            "y": 2,
            "z": 3,
            "elements": [
                "thermalfoundation:storage_alloy@0"
            ]
        },
        {
            "x": -6,
            "y": 0,
            "z": 5,
            "elements": [
                "chisel:laboratory@1"
            ]
        },
        {
            "x": 0,
            "y": -4,
            "z": 10,
            "elements": [
                "minecraft:iron_block@0"
            ]
        },
        {
            "x": -4,
            "y": 7,
            "z": 9,
            "elements": [
                "mets:titanium_block@0"
            ]
        },
        {
            "x": -4,
            "y": -3,
            "z": 16,
            "elements": [
                "chisel:laboratory@2"
            ]
        },
        {
            "x": -1,
            "y": 5,
            "z": 17,
            "elements": [
                "chisel:glasspane@13"
            ]
        },
        {
            "x": -5,
            "y": 1,
            "z": 4,
            "elements": [
                "chisel:laboratory@15"
            ]
        },
        {
            "x": -5,
            "y": -2,
            "z": 15,
            "elements": [
                "cfm:castle_netting@0"
            ]
        },
        {
            "x": 6,
            "y": 0,
            "z": 14,
            "elements": [
                "cfm:castle_netting@0"
            ]
        },
        {
            "x": 3,
            "y": 6,
            "z": 8,
            "elements": [
                "extendedcrafting:storage@0"
            ]
        },
        {
            "x": 2,
            "y": 8,
            "z": 13,
            "elements": [
                "chisel:laboratory@2"
            ]
        },
        {
            "x": -7,
            "y": -4,
            "z": 2,
            "elements": [
                "minecraft:iron_block@0"
            ]
        },
        {
            "x": -9,
            "y": -1,
            "z": 9,

            "elements": [
                "fluid_out"
            ]
        },
        {
            "x": -4,
            "y": 4,
            "z": 15,
            "elements": [
                "chisel:glasspane@13"
            ]
        },
        {
            "x": 10,
            "y": -4,
            "z": 12,
            "elements": [
                "minecraft:iron_block@0"
            ]
        },
        {
            "x": 0,
            "y": 10,
            "z": 8,
            "elements": [
                "minecraft:iron_block@0"
            ]
        },
        {
            "x": 2,
            "y": -4,
            "z": 3,
            "elements": [
                "minecraft:iron_block@0"
            ]
        },
        {
            "x": -6,
            "y": 2,
            "z": 5,
            "elements": [
                "chisel:laboratory@1"
            ]
        },
        {
            "x": 3,
            "y": 4,
            "z": 14,
            "elements": [
                "extendedcrafting:storage@0"
            ]
        },
        {
            "x": -1,
            "y": 1,
            "z": 9,
            "elements": [
                "appliedenergistics2:smooth_sky_stone_slab@0"
            ]
        },
        {
            "x": 5,
            "y": 3,
            "z": 13,
            "elements": [
                "mets:titanium_block@0"
            ]
        },
        {
            "x": 5,
            "y": -1,
            "z": 14,
            "elements": [
                "chisel:laboratory@15"
            ]
        },
        {
            "x": 5,
            "y": -1,
            "z": 11,
            "elements": [
                "extendedcrafting:storage@0"
            ]
        },
        {
            "x": -3,
            "y": 9,
            "z": 8,
            "elements": [
                "minecraft:iron_block@0"
            ]
        },
        {
            "x": -1,
            "y": 4,
            "z": 17,
            "elements": [
                "chisel:glasspane@13"
            ]
        },
        {
            "x": 8,
            "y": -4,
            "z": 13,
            "elements": [
                "minecraft:iron_block@0"
            ]
        },
        {
            "x": -4,
            "y": -4,
            "z": 5,
            "elements": [
                "minecraft:iron_block@0"
            ]
        },
        {
            "x": -3,
            "y": -4,
            "z": 10,
            "elements": [
                "minecraft:iron_block@0"
            ]
        },
        {
            "x": -1,
            "y": -4,
            "z": 3,
            "elements": [
                "minecraft:iron_block@0"
            ]
        },
        {
            "x": 0,
            "y": 6,
            "z": 8,
            "elements": [
                "extendedcrafting:storage@0"
            ]
        },
        {
            "x": 8,
            "y": -4,
            "z": 14,
            "elements": [
                "minecraft:iron_block@0"
            ]
        },
        {
            "x": 4,
            "y": -2,
            "z": 15,
            "elements": [
                "chisel:laboratory@1"
            ]
        },
        {
            "x": 6,
            "y": 5,
            "z": 13,
            "elements": [
                "chisel:glasspane@13"
            ]
        },
        {
            "x": 5,
            "y": -2,
            "z": 14,
            "elements": [
                "chisel:laboratory@15"
            ]
        },
        {
            "x": 7,
            "y": -4,
            "z": 15,
            "elements": [
                "minecraft:iron_block@0"
            ]
        },
        {
            "x": 0,
            "y": -1,
            "z": 4,
            "elements": [
                "extendedcrafting:storage@0"
            ]
        },
        {
            "x": -8,
            "y": 0,
            "z": 10,
            "elements": [
                "chisel:futura@0"
            ]
        },
        {
            "x": -5,
            "y": -3,
            "z": 16,
            "elements": [
                "chisel:laboratory@1"
            ]
        },
        {
            "x": -5,
            "y": 4,
            "z": 3,
            "elements": [
                "chisel:glasspane@13"
            ]
        },
        {
            "x": 2,
            "y": 1,
            "z": 4,
            "elements": [
                "extendedcrafting:storage@0"
            ]
        },
        {
            "x": -6,
            "y": -2,
            "z": 10,
            "elements": [
                "thermalfoundation:storage_alloy@0"
            ]
        },
        {
            "x": -1,
            "y": 2,
            "z": 3,
            "elements": [
                "thermalfoundation:storage_alloy@0"
            ]
        },
        {
            "x": 5,
            "y": -3,
            "z": 14,
            "elements": [
                "chisel:laboratory@15"
            ]
        },
        {
            "x": 2,
            "y": -1,
            "z": 14,
            "elements": [
                "extendedcrafting:storage@0"
            ]
        },
        {
            "x": 8,
            "y": 3,
            "z": 13,
            "elements": [
                "chisel:laboratory@1"
            ]
        },
        {
            "x": -8,
            "y": 4,
            "z": 10,
            "elements": [
                "chisel:glasspane@13"
            ]
        },
        {
            "x": -7,
            "y": -4,
            "z": 5,
            "elements": [
                "minecraft:iron_block@0"
            ]
        },
        {
            "x": -7,
            "y": 3,
            "z": 9,
            "elements": [
                "mets:titanium_block@0"
            ]
        },
        {
            "x": 5,
            "y": 0,
            "z": 15,
            "elements": [
                "cfm:castle_netting@0"
            ]
        },
        {
            "x": -4,
            "y": 1,
            "z": 9,
            "elements": [
                "thermalfoundation:storage_alloy@0"
            ]
        },
        {
            "x": -2,
            "y": -1,
            "z": 9,
            "elements": [
                "appliedenergistics2:smooth_sky_stone_slab@8"
            ]
        },
        {
            "x": 0,
            "y": -2,
            "z": 3,
            "elements": [
                "thermalfoundation:storage_alloy@0"
            ]
        },
        {
            "x": 6,
            "y": 1,
            "z": 14,
            "elements": [
                "cfm:castle_netting@0"
            ]
        },
        {
            "x": -10,
            "y": -4,
            "z": 8,
            "elements": [
                "minecraft:iron_block@0"
            ]
        },
        {
            "x": -6,
            "y": -4,
            "z": 10,
            "elements": [
                "minecraft:iron_block@0"
            ]
        },
        {
            "x": 0,
            "y": -4,
            "z": 3,
            "elements": [
                "minecraft:iron_block@0"
            ]
        },
        {
            "x": -1,
            "y": 5,
            "z": 4,
            "elements": [
                "chisel:laboratory@0"
            ]
        },
        {
            "x": 5,
            "y": -4,
            "z": 14,
            "elements": [
                "minecraft:iron_block@0"
            ]
        },
        {
            "x": 0,
            "y": 5,
            "z": 14,
            "elements": [
                "minecraft:iron_block@0"
            ]
        },
        {
            "x": -2,
            "y": -4,
            "z": 15,
            "elements": [
                "minecraft:iron_block@0"
            ]
        },
        {
            "x": 1,
            "y": -1,
            "z": 4,
            "elements": [
                "extendedcrafting:storage@0"
            ]
        },
        {
            "x": 3,
            "y": 8,
            "z": 12,
            "elements": [
                "chisel:laboratory@2"
            ]
        },
        {
            "x": -3,
            "y": 9,
            "z": 11,
            "elements": [
                "minecraft:iron_block@0"
            ]
        },
        {
            "x": -4,
            "y": 4,
            "z": 3,
            "elements": [
                "chisel:glasspane@13"
            ]
        },
        {
            "x": 1,
            "y": 1,
            "z": 4,
            "elements": [
                "extendedcrafting:storage@0"
            ]
        },
        {
            "x": -6,
            "y": -1,
            "z": 4,
            "elements": [
                "cfm:castle_netting@0"
            ]
        },
        {
            "x": 6,
            "y": 2,
            "z": 14,
            "elements": [
                "chisel:laboratory@2"
            ]
        },
        {
            "x": 6,
            "y": 4,
            "z": 13,
            "elements": [
                "chisel:glasspane@13"
            ]
        },
        {
            "x": -8,
            "y": 2,
            "z": 10,
            "elements": [
                "minecraft:iron_block@0"
            ]
        },
        {
            "x": -1,
            "y": -2,
            "z": 3,
            "elements": [
                "thermalfoundation:storage_alloy@0"
            ]
        },
        {
            "x": 0,
            "y": 6,
            "z": 14,
            "elements": [
                "minecraft:iron_block@0"
            ]
        },
        {
            "x": 7,
            "y": -2,
            "z": 6,
            "elements": [
                "mets:titanium_block@0"
            ]
        },
        {
            "x": 1,
            "y": -1,
            "z": 9,
            "elements": [
                "appliedenergistics2:smooth_sky_stone_slab@8"
            ]
        },
        {
            "x": 2,
            "y": 3,
            "z": 18,
            "elements": [
                "chisel:laboratory@1"
            ]
        },
        {
            "x": 3,
            "y": 3,
            "z": 2,
            "elements": [
                "chisel:glasspane@13"
            ]
        },
        {
            "x": 0,
            "y": 2,
            "z": 16,
            "elements": [
                "thermalfoundation:storage_alloy@0"
            ]
        },
        {
            "x": 1,
            "y": 6,
            "z": 11,
            "elements": [
                "extendedcrafting:storage@0"
            ]
        },
        {
            "x": 6,
            "y": -1,
            "z": 4,
            "elements": [
                "cfm:castle_netting@0"
            ]
        },
        {
            "x": 3,
            "y": 1,
            "z": 16,
            "elements": [
                "mets:titanium_block@0"
            ]
        },
        {
            "x": -1,
            "y": 5,
            "z": 14,
            "elements": [
                "chisel:laboratory@0"
            ]
        },
        {
            "x": 0,
            "y": 5,
            "z": 2,
            "elements": [
                "environmentalmaterials:alabaster_wall_silver@0"
            ]
        },
        {
            "x": 7,
            "y": 2,
            "z": 11,
            "elements": [
                "mets:titanium_block@0"
            ]
        },
        {
            "x": -3,
            "y": -4,
            "z": 8,
            "elements": [
                "minecraft:iron_block@0"
            ]
        },
        {
            "x": 3,
            "y": 0,
            "z": 16,
            "elements": [
                "mets:titanium_block@0"
            ]
        },
        {
            "x": -6,
            "y": -2,
            "z": 8,
            "elements": [
                "thermalfoundation:storage_alloy@0"
            ]
        },
        {
            "x": 5,
            "y": -1,
            "z": 15,
            "elements": [
                "cfm:castle_netting@0"
            ]
        },
        {
            "x": -8,
            "y": 0,
            "z": 8,
            "elements": [
                "chisel:futura@0"
            ]
        },
        {
            "x": -3,
            "y": 5,
            "z": 16,
            "elements": [
                "chisel:glasspane@13"
            ]
        },
        {
            "x": 4,
            "y": 0,
            "z": 11,
            "elements": [
                "contenttweaker:fixed_star_alloys_coil@0"
            ]
        },
        {
            "x": -7,
            "y": 1,
            "z": 7,
            "elements": [
                "chisel:laboratory@14"
            ]
        },
        {
            "x": 0,
            "y": 3,
            "z": 16,
            "elements": [
                "mets:titanium_block@0"
            ]
        },
        {
            "x": 7,
            "y": 3,
            "z": 11,
            "elements": [
                "chisel:glasspane@13"
            ]
        },
        {
            "x": -3,
            "y": -3,
            "z": 17,
            "elements": [
                "chisel:laboratory@1"
            ]
        },
        {
            "x": -10,
            "y": -4,
            "z": 9,
            "elements": [
                "minecraft:iron_block@0"
            ]
        },
        {
            "x": -8,
            "y": 4,
            "z": 8,
            "elements": [
                "chisel:glasspane@13"
            ]
        },
        {
            "x": 0,
            "y": 6,
            "z": 9,
            "elements": [
                "extendedcrafting:storage@0"
            ]
        },
        {
            "x": -8,
            "y": 2,
            "z": 8,
            "elements": [
                "minecraft:iron_block@0"
            ]
        },
        {
            "x": 3,
            "y": 7,
            "z": 12,
            "elements": [
                "minecraft:iron_block@0"
            ]
        },
        {
            "x": -3,
            "y": 9,
            "z": 9,
            "elements": [
                "minecraft:iron_block@0"
            ]
        },
        {
            "x": -5,
            "y": -3,
            "z": 2,
            "elements": [
                "chisel:laboratory@1"
            ]
        },
        {
            "x": -1,
            "y": 6,
            "z": 6,
            "elements": [
                "extendedcrafting:storage@0"
            ]
        },
        {
            "x": 6,
            "y": -4,
            "z": 11,
            "elements": [
                "minecraft:iron_block@0"
            ]
        },
        {
            "x": 5,
            "y": -2,
            "z": 15,
            "elements": [
                "cfm:castle_netting@0"
            ]
        },
        {
            "x": -1,
            "y": 6,
            "z": 8,
            "elements": [
                "extendedcrafting:storage@0"
            ]
        },
        {
            "x": 2,
            "y": 1,
            "z": 14,
            "elements": [
                "extendedcrafting:storage@0"
            ]
        },
        {
            "x": -3,
            "y": 4,
            "z": 16,
            "elements": [
                "chisel:glasspane@13"
            ]
        },
        {
            "x": 0,
            "y": 7,
            "z": 2,
            "elements": [
                "environmentalmaterials:alabaster_wall_silver@0"
            ]
        },
        {
            "x": 5,
            "y": -4,
            "z": 9,
            "elements": [
                "minecraft:iron_block@0"
            ]
        },
        {
            "x": 3,
            "y": 1,
            "z": 9,
            "elements": [
                "appliedenergistics2:smooth_sky_stone_slab@0"
            ]
        },
        {
            "x": 6,
            "y": -4,
            "z": 4,
            "elements": [
                "minecraft:iron_block@0"
            ]
        },
        {
            "x": -3,
            "y": 2,
            "z": 16,
            "elements": [
                "mets:titanium_block@0"
            ]
        },
        {
            "x": -4,
            "y": -4,
            "z": 18,
            "elements": [
                "minecraft:iron_block@0"
            ]
        },
        {
            "x": 7,
            "y": 0,
            "z": 11,
            "elements": [
                "chisel:laboratory@14"
            ]
        },
        {
            "x": 8,
            "y": -4,
            "z": 15,
            "elements": [
                "minecraft:iron_block@0"
            ]
        },
        {
            "x": 0,
            "y": -4,
            "z": 8,
            "elements": [
                "minecraft:iron_block@0"
            ]
        },
        {
            "x": 0,
            "y": 5,
            "z": 16,
            "elements": [
                "environmentalmaterials:alabaster_wall_silver@0"
            ]
        },
        {
            "x": 0,
            "y": 1,
            "z": 12,
            "elements": [
                "appliedenergistics2:smooth_sky_stone_slab@0"
            ]
        },
        {
            "x": -4,
            "y": -4,
            "z": 13,
            "elements": [
                "minecraft:iron_block@0"
            ]
        },
        {
            "x": 3,
            "y": 1,
            "z": 2,
            "elements": [
                "mets:titanium_block@0"
            ]
        },
        {
            "x": 9,
            "y": -3,
            "z": 11,
            "elements": [
                "chisel:laboratory@1"
            ]
        },
        {
            "x": 1,
            "y": 5,
            "z": 4,
            "elements": [
                "chisel:laboratory@0"
            ]
        },
        {
            "x": -7,
            "y": -4,
            "z": 13,
            "elements": [
                "minecraft:iron_block@0"
            ]
        },
        {
            "x": 6,
            "y": 3,
            "z": 12,
            "elements": [
                "mets:titanium_block@0"
            ]
        },
        {
            "x": -2,
            "y": -3,
            "z": 17,
            "elements": [
                "chisel:laboratory@2"
            ]
        },
        {
            "x": -4,
            "y": -3,
            "z": 2,
            "elements": [
                "chisel:laboratory@2"
            ]
        },
        {
            "x": -3,
            "y": 3,
            "z": 16,
            "elements": [
                "chisel:glasspane@13"
            ]
        },
        {
            "x": 9,
            "y": 3,
            "z": 10,
            "elements": [
                "chisel:laboratory@1"
            ]
        },
        {
            "x": -4,
            "y": 7,
            "z": 7,
            "elements": [
                "minecraft:iron_block@0"
            ]
        },
        {
            "x": 1,
            "y": -1,
            "z": 14,
            "elements": [
                "extendedcrafting:storage@0"
            ]
        },
        {
            "x": 5,
            "y": 4,
            "z": 6,
            "elements": [
                "extendedcrafting:storage@0"
            ]
        },
        {
            "x": 2,
            "y": -1,
            "z": 16,
            "elements": [
                "chisel:laboratory@13"
            ]
        },
        {
            "x": 7,
            "y": -1,
            "z": 7,
            "elements": [
                "chisel:laboratory@13"
            ]
        },
        {
            "x": 9,
            "y": -4,
            "z": 4,
            "elements": [
                "minecraft:iron_block@0"
            ]
        },
        {
            "x": -6,
            "y": -4,
            "z": 1,
            "elements": [
                "minecraft:iron_block@0"
            ]
        },
        {
            "x": 7,
            "y": 1,
            "z": 11,
            "elements": [
                "chisel:laboratory@14"
            ]
        },
        {
            "x": 2,
            "y": 6,
            "z": 6,
            "elements": [
                "chisel:laboratory@1"
            ]
        },
        {
            "x": 0,
            "y": 4,
            "z": 16,
            "elements": [
                "environmentalmaterials:alabaster_wall_silver@0"
            ]
        },
        {
            "x": 1,
            "y": 7,
            "z": 4,
            "elements": [
                "minecraft:iron_block@0"
            ]
        },
        {
            "x": 9,
            "y": -4,
            "z": 11,
            "elements": [
                "minecraft:iron_block@0"
            ]
        },
        {
            "x": 0,
            "y": 7,
            "z": 16,
            "elements": [
                "environmentalmaterials:alabaster_wall_silver@0"
            ]
        },
        {
            "x": 9,
            "y": -3,
            "z": 10,
            "elements": [
                "chisel:laboratory@1"
            ]
        },
        {
            "x": 3,
            "y": -4,
            "z": 8,
            "elements": [
                "minecraft:iron_block@0"
            ]
        },
        {
            "x": 6,
            "y": 3,
            "z": 15,
            "elements": [
                "chisel:laboratory@1"
            ]
        },
        {
            "x": 10,
            "y": -4,
            "z": 6,
            "elements": [
                "minecraft:iron_block@0"
            ]
        },
        {
            "x": -3,
            "y": 0,
            "z": 16,
            "elements": [
                "mets:titanium_block@0"
            ]
        },
        {
            "x": 3,
            "y": 5,
            "z": 16,
            "elements": [
                "chisel:glasspane@13"
            ]
        },
        {
            "x": -4,
            "y": 6,
            "z": 8,
            "elements": [
                "chisel:laboratory@4"
            ]
        },
        {
            "x": -3,
            "y": 3,
            "z": 2,
            "elements": [
                "chisel:glasspane@13"
            ]
        },
        {
            "x": 3,
            "y": 0,
            "z": 9,
            "elements": [
                "minecraft:stone@6"
            ]
        },
        {
            "x": 8,
            "y": -4,
            "z": 9,
            "elements": [
                "minecraft:iron_block@0"
            ]
        },
        {
            "x": 5,
            "y": -2,
            "z": 9,
            "elements": [
                "thermalfoundation:storage_alloy@0"
            ]
        },
        {
            "x": -5,
            "y": -1,
            "z": 7,
            "elements": [
                "extendedcrafting:storage@0"
            ]
        },
        {
            "x": 2,
            "y": -1,
            "z": 2,
            "elements": [
                "chisel:laboratory@14"
            ]
        },
        {
            "x": 9,
            "y": -4,
            "z": 10,
            "elements": [
                "minecraft:iron_block@0"
            ]
        },
        {
            "x": -3,
            "y": 7,
            "z": 12,
            "elements": [
                "minecraft:iron_block@0"
            ]
        },
        {
            "x": -1,
            "y": -4,
            "z": 13,
            "elements": [
                "minecraft:iron_block@0"
            ]
        },
        {
            "x": 4,
            "y": 5,
            "z": 11,
            "elements": [
                "chisel:laboratory@0"
            ]
        },
        {
            "x": 5,
            "y": -3,
            "z": 2,
            "elements": [
                "chisel:laboratory@1"
            ]
        },
        {
            "x": -2,
            "y": -1,
            "z": 14,
            "elements": [
                "extendedcrafting:storage@0"
            ]
        },
        {
            "x": 1,
            "y": 10,
            "z": 11,
            "elements": [
                "minecraft:iron_block@0"
            ]
        },
        {
            "x": 0,
            "y": 6,
            "z": 16,
            "elements": [
                "environmentalmaterials:alabaster_wall_silver@0"
            ]
        },
        {
            "x": -3,
            "y": 1,
            "z": 16,
            "elements": [
                "mets:titanium_block@0"
            ]
        },
        {
            "x": 3,
            "y": 4,
            "z": 16,
            "elements": [
                "chisel:glasspane@13"
            ]
        },
        {
            "x": 3,
            "y": 9,
            "z": 10,
            "elements": [
                "minecraft:iron_block@0"
            ]
        },
        {
            "x": 2,
            "y": -1,
            "z": 9,
            "elements": [
                "appliedenergistics2:smooth_sky_stone_slab@8"
            ]
        },
        {
            "x": -4,
            "y": 5,
            "z": 7,
            "elements": [
                "chisel:laboratory@0"
            ]
        },
        {
            "x": -1,
            "y": -4,
            "z": 16,
            "elements": [
                "minecraft:iron_block@0"
            ]
        },
        {
            "x": -4,
            "y": 3,
            "z": 17,
            "elements": [
                "chisel:laboratory@1"
            ]
        },
        {
            "x": 7,
            "y": 2,
            "z": 10,
            "elements": [
                "thermalfoundation:storage_alloy@0"
            ]
        },
        {
            "x": -4,
            "y": 8,
            "z": 8,
            "elements": [
                "chisel:laboratory@2"
            ]
        },
        {
            "x": -1,
            "y": 1,
            "z": 17,
            "elements": [
                "chisel:futura@0"
            ]
        },
        {
            "x": -6,
            "y": -4,
            "z": 8,
            "elements": [
                "minecraft:iron_block@0"
            ]
        },
        {
            "x": -7,
            "y": 3,
            "z": 7,
            "elements": [
                "chisel:glasspane@13"
            ]
        },
        {
            "x": 5,
            "y": -4,
            "z": 16,
            "elements": [
                "minecraft:iron_block@0"
            ]
        },
        {
            "x": 0,
            "y": 3,
            "z": 2,
            "elements": [
                "mets:titanium_block@0"
            ]
        },
        {
            "x": 4,
            "y": 3,
            "z": 4,
            "elements": [
                "mets:titanium_block@0"
            ]
        },
        {
            "x": 1,
            "y": 9,
            "z": 11,
            "elements": [
                "minecraft:iron_block@0"
            ]
        },
        {
            "x": 8,
            "y": -3,
            "z": 12,
            "elements": [
                "chisel:laboratory@1"
            ]
        },
        {
            "x": 6,
            "y": -3,
            "z": 4,
            "elements": [
                "chisel:laboratory@2"
            ]
        },
        {
            "x": 4,
            "y": 7,
            "z": 11,
            "elements": [
                "minecraft:iron_block@0"
            ]
        },
        {
            "x": 3,
            "y": 3,
            "z": 16,
            "elements": [
                "chisel:glasspane@13"
            ]
        },
        {
            "x": -3,
            "y": 1,
            "z": 2,
            "elements": [
                "mets:titanium_block@0"
            ]
        },
        {
            "x": 7,
            "y": 3,
            "z": 10,
            "elements": [
                "mets:titanium_block@0"
            ]
        },
        {
            "x": 5,
            "y": -3,
            "z": 16,
            "elements": [
                "chisel:laboratory@1"
            ]
        },
        {
            "x": 4,
            "y": 6,
            "z": 11,
            "elements": [
                "environmentalmaterials:alabaster_wall_silver@0"
            ]
        },
        {
            "x": -1,
            "y": 1,
            "z": 14,
            "elements": [
                "extendedcrafting:storage@0"
            ]
        },
        {
            "x": 5,
            "y": -1,
            "z": 9,
            "elements": [
                "extendedcrafting:storage@0"
            ]
        },
        {
            "x": -4,
            "y": 6,
            "z": 6,
            "elements": [
                "environmentalmaterials:alabaster_wall_silver@0"
            ]
        },
        {
            "x": 6,
            "y": -2,
            "z": 4,
            "elements": [
                "cfm:castle_netting@0"
            ]
        },
        {
            "x": -7,
            "y": 5,
            "z": 7,
            "elements": [
                "chisel:glasspane@13"
            ]
        },
        {
            "x": 1,
            "y": 9,
            "z": 10,
            "elements": [
                "minecraft:iron_block@0"
            ]
        },
        {
            "x": 3,
            "y": 2,
            "z": 16,
            "elements": [
                "mets:titanium_block@0"
            ]
        },
        {
            "x": 2,
            "y": -4,
            "z": 9,
            "elements": [
                "minecraft:iron_block@0"
            ]
        },
        {
            "x": -4,
            "y": 5,
            "z": 2,
            "elements": [
                "chisel:glasspane@13"
            ]
        },
        {
            "x": -5,
            "y": -4,
            "z": 18,
            "elements": [
                "minecraft:iron_block@0"
            ]
        },
        {
            "x": 8,
            "y": -2,
            "z": 11,
            "elements": [
                "chisel:laboratory@4"
            ]
        },
        {
            "x": 6,
            "y": -4,
            "z": 1,
            "elements": [
                "minecraft:iron_block@0"
            ]
        },
        {
            "x": 6,
            "y": 2,
            "z": 10,
            "elements": [
                "thermalfoundation:storage_alloy@0"
            ]
        },
        {
            "x": -1,
            "y": 3,
            "z": 2,
            "elements": [
                "mets:titanium_block@0"
            ]
        },
        {
            "x": 4,
            "y": 7,
            "z": 10,
            "elements": [
                "minecraft:iron_block@0"
            ]
        },
        {
            "x": -3,
            "y": 6,
            "z": 13,
            "elements": [
                "environmentalmaterials:alabaster_wall_silver@0"
            ]
        },
        {
            "x": 1,
            "y": 10,
            "z": 10,
            "elements": [
                "minecraft:iron_block@0"
            ]
        },
        {
            "x": 1,
            "y": -4,
            "z": 8,
            "elements": [
                "minecraft:iron_block@0"
            ]
        },
        {
            "x": -2,
            "y": 1,
            "z": 2,
            "elements": [
                "chisel:laboratory@13"
            ]
        },
        {
            "x": 8,
            "y": -1,
            "z": 10,
            "elements": [
                "chisel:futura@0"
            ]
        },
        {
            "x": 1,
            "y": 0,
            "z": 1,
            "elements": [
                "chisel:futura@0"
            ]
        },
        {
            "x": 7,
            "y": -3,
            "z": 14,
            "elements": [
                "chisel:laboratory@1"
            ]
        },
        {
            "x": -1,
            "y": 8,
            "z": 13,
            "elements": [
                "chisel:laboratory@2"
            ]
        },
        {
            "x": 3,
            "y": 6,
            "z": 10,
            "elements": [
                "extendedcrafting:storage@0"
            ]
        },
        {
            "x": 4,
            "y": 8,
            "z": 10,
            "elements": [
                "chisel:laboratory@2"
            ]
        },
        {
            "x": 4,
            "y": 8,
            "z": 11,
            "elements": [
                "chisel:laboratory@2"
            ]
        },
        {
            "x": 4,
            "y": -4,
            "z": 6,
            "elements": [
                "minecraft:iron_block@0"
            ]
        },
        {
            "x": 0,
            "y": 0,
            "z": 13,
            "elements": [
                "contenttweaker:fixed_star_alloys_coil@0"
            ]
        },
        {
            "x": -9,
            "y": 3,
            "z": 9,
            "elements": [
                "chisel:laboratory@1"
            ]
        },
        {
            "x": 5,
            "y": -4,
            "z": 13,
            "elements": [
                "minecraft:iron_block@0"
            ]
        },
        {
            "x": 8,
            "y": -2,
            "z": 10,
            "elements": [
                "chisel:laboratory@4"
            ]
        },
        {
            "x": 6,
            "y": 4,
            "z": 10,
            "elements": [
                "extendedcrafting:storage@0"
            ]
        },
        {
            "x": 8,
            "y": -3,
            "z": 10,
            "elements": [
                "chisel:laboratory@2"
            ]
        },
        {
            "x": -10,
            "y": -4,
            "z": 6,
            "elements": [
                "minecraft:iron_block@0"
            ]
        },
        {
            "x": -4,
            "y": -4,
            "z": 8,
            "elements": [
                "minecraft:iron_block@0"
            ]
        },
        {
            "x": 0,
            "y": 0,
            "z": 9,
            "elements": [
                "contenttweaker:universalforcefieldcontrolblock@0"
            ]
        },
        {
            "x": -3,
            "y": 5,
            "z": 2,
            "elements": [
                "chisel:glasspane@13"
            ]
        },
        {
            "x": 1,
            "y": 9,
            "z": 7,
            "elements": [
                "minecraft:iron_block@0"
            ]
        },
        {
            "x": -2,
            "y": 3,
            "z": 2,
            "elements": [
                "chisel:glasspane@13"
            ]
        },
        {
            "x": 1,
            "y": 2,
            "z": 1,
            "elements": [
                "minecraft:iron_block@0"
            ]
        },
        {
            "x": -5,
            "y": -2,
            "z": 8,
            "elements": [
                "thermalfoundation:storage_alloy@0"
            ]
        },
        {
            "x": -9,
            "y": 2,
            "z": 9,
            "elements": [
                "chisel:laboratory@11"
            ]
        },
        {
            "x": 4,
            "y": 6,
            "z": 10,
            "elements": [
                "chisel:laboratory@4"
            ]
        },
        {
            "x": -9,
            "y": 1,
            "z": 9,

            "elements": [
                "fluid_out"
            ]
        },
        {
            "x": -7,
            "y": 2,
            "z": 8,
            "elements": [
                "thermalfoundation:storage_alloy@0"
            ]
        },
        {
            "x": -2,
            "y": 4,
            "z": 1,
            "elements": [
                "chisel:glasspane@13"
            ]
        },
        {
            "x": 8,
            "y": -4,
            "z": 10,
            "elements": [
                "minecraft:iron_block@0"
            ]
        },
        {
            "x": -7,
            "y": -4,
            "z": 6,
            "elements": [
                "minecraft:iron_block@0"
            ]
        },
        {
            "x": -4,
            "y": 3,
            "z": 14,
            "elements": [
                "mets:titanium_block@0"
            ]
        },
        {
            "x": 5,
            "y": 1,
            "z": 7,
            "elements": [
                "extendedcrafting:storage@0"
            ]
        },
        {
            "x": 5,
            "y": 1,
            "z": 14,
            "elements": [
                "chisel:laboratory@15"
            ]
        },
        {
            "x": -1,
            "y": -1,
            "z": 9,
            "elements": [
                "appliedenergistics2:smooth_sky_stone_slab@8"
            ]
        },
        {
            "x": 1,
            "y": 3,
            "z": 2,
            "elements": [
                "mets:titanium_block@0"
            ]
        },
        {
            "x": 2,
            "y": 0,
            "z": 13,
            "elements": [
                "contenttweaker:fixed_star_alloys_coil@0"
            ]
        },
        {
            "x": -1,
            "y": -2,
            "z": 16,
            "elements": [
                "thermalfoundation:storage_alloy@0"
            ]
        },
        {
            "x": -2,
            "y": 5,
            "z": 2,
            "elements": [
                "chisel:glasspane@13"
            ]
        },
        {
            "x": 5,
            "y": -4,
            "z": 10,
            "elements": [
                "minecraft:iron_block@0"
            ]
        },
        {
            "x": -9,
            "y": 0,
            "z": 9,

            "elements": [
                "fluid_out"
            ]
        },
        {
            "x": -7,
            "y": -2,
            "z": 9,
            "elements": [
                "thermalfoundation:storage_alloy@0"
            ]
        },
        {
            "x": 2,
            "y": 9,
            "z": 7,
            "elements": [
                "minecraft:iron_block@0"
            ]
        },
        {
            "x": 5,
            "y": 5,
            "z": 14,
            "elements": [
                "chisel:glasspane@13"
            ]
        },
        {
            "x": -1,
            "y": -4,
            "z": 8,
            "elements": [
                "minecraft:iron_block@0"
            ]
        },
        {
            "x": -1,
            "y": 6,
            "z": 13,
            "elements": [
                "chisel:laboratory@4"
            ]
        },
        {
            "x": -2,
            "y": -1,
            "z": 2,
            "elements": [
                "chisel:laboratory@13"
            ]
        },
        {
            "x": 1,
            "y": 4,
            "z": 1,
            "elements": [
                "chisel:glasspane@13"
            ]
        },
        {
            "x": 9,
            "y": 3,
            "z": 11,
            "elements": [
                "chisel:laboratory@1"
            ]
        },
        {
            "x": -6,
            "y": 2,
            "z": 8,
            "elements": [
                "thermalfoundation:storage_alloy@0"
            ]
        },
        {
            "x": 4,
            "y": 5,
            "z": 3,
            "elements": [
                "chisel:glasspane@13"
            ]
        },
        {
            "x": -8,
            "y": -3,
            "z": 7,
            "elements": [
                "chisel:laboratory@2"
            ]
        },
        {
            "x": 0,
            "y": 9,
            "z": 12,
            "elements": [
                "minecraft:iron_block@0"
            ]
        },
        {
            "x": 7,
            "y": 3,
            "z": 4,
            "elements": [
                "chisel:laboratory@1"
            ]
        },
        {
            "x": -7,
            "y": -4,
            "z": 9,
            "elements": [
                "minecraft:iron_block@0"
            ]
        },
        {
            "x": -3,
            "y": -4,
            "z": 1,
            "elements": [
                "minecraft:iron_block@0"
            ]
        },
        {
            "x": -2,
            "y": -4,
            "z": 18,
            "elements": [
                "minecraft:iron_block@0"
            ]
        },
        {
            "x": 7,
            "y": 4,
            "z": 11,
            "elements": [
                "chisel:glasspane@13"
            ]
        },
        {
            "x": 4,
            "y": 4,
            "z": 3,
            "elements": [
                "chisel:glasspane@13"
            ]
        },
        {
            "x": 3,
            "y": -4,
            "z": 1,
            "elements": [
                "minecraft:iron_block@0"
            ]
        },
        {
            "x": 5,
            "y": 3,
            "z": 14,
            "elements": [
                "chisel:glasspane@13"
            ]
        },
        {
            "x": -2,
            "y": -4,
            "z": 8,
            "elements": [
                "minecraft:iron_block@0"
            ]
        },
        {
            "x": -1,
            "y": -4,
            "z": 9,
            "elements": [
                "minecraft:iron_block@0"
            ]
        },
        {
            "x": 5,
            "y": -1,
            "z": 10,
            "elements": [
                "extendedcrafting:storage@0"
            ]
        },
        {
            "x": -4,
            "y": 3,
            "z": 2,
            "elements": [
                "chisel:glasspane@13"
            ]
        },
        {
            "x": -1,
            "y": 7,
            "z": 14,
            "elements": [
                "minecraft:iron_block@0"
            ]
        },
        {
            "x": 0,
            "y": 6,
            "z": 13,
            "elements": [
                "chisel:laboratory@4"
            ]
        },
        {
            "x": -1,
            "y": 9,
            "z": 7,
            "elements": [
                "minecraft:iron_block@0"
            ]
        },
        {
            "x": 7,
            "y": 5,
            "z": 11,
            "elements": [
                "chisel:glasspane@13"
            ]
        },
        {
            "x": -4,
            "y": 0,
            "z": 8,
            "elements": [
                "contenttweaker:fixed_star_alloys_coil@0"
            ]
        },
        {
            "x": 5,
            "y": -2,
            "z": 10,
            "elements": [
                "thermalfoundation:storage_alloy@0"
            ]
        },
        {
            "x": -5,
            "y": 2,
            "z": 8,
            "elements": [
                "thermalfoundation:storage_alloy@0"
            ]
        },
        {
            "x": 2,
            "y": -4,
            "z": 13,
            "elements": [
                "minecraft:iron_block@0"
            ]
        },
        {
            "x": 7,
            "y": -4,
            "z": 6,
            "elements": [
                "minecraft:iron_block@0"
            ]
        },
        {
            "x": -4,
            "y": -4,
            "z": 9,
            "elements": [
                "minecraft:iron_block@0"
            ]
        },
        {
            "x": 4,
            "y": 3,
            "z": 3,
            "elements": [
                "chisel:glasspane@13"
            ]
        },
        {
            "x": 2,
            "y": -4,
            "z": 16,
            "elements": [
                "minecraft:iron_block@0"
            ]
        },
        {
            "x": -6,
            "y": 4,
            "z": 8,
            "elements": [
                "extendedcrafting:storage@0"
            ]
        },
        {
            "x": 7,
            "y": 6,
            "z": 9,
            "elements": [
                "environmentalmaterials:alabaster_wall_silver@0"
            ]
        },
        {
            "x": 5,
            "y": -4,
            "z": 15,
            "elements": [
                "minecraft:iron_block@0"
            ]
        },
        {
            "x": 4,
            "y": 4,
            "z": 5,
            "elements": [
                "extendedcrafting:storage@0"
            ]
        },
        {
            "x": 6,
            "y": -4,
            "z": 5,
            "elements": [
                "minecraft:iron_block@0"
            ]
        },
        {
            "x": -8,
            "y": 3,
            "z": 7,
            "elements": [
                "chisel:glasspane@13"
            ]
        },
        {
            "x": 2,
            "y": -4,
            "z": 1,
            "elements": [
                "minecraft:iron_block@0"
            ]
        },
        {
            "x": -5,
            "y": 3,
            "z": 2,
            "elements": [
                "chisel:laboratory@1"
            ]
        },
        {
            "x": -7,
            "y": -1,
            "z": 7,
            "elements": [
                "chisel:laboratory@14"
            ]
        },
        {
            "x": 0,
            "y": 2,
            "z": 1,
            "elements": [
                "minecraft:iron_block@0"
            ]
        },
        {
            "x": -1,
            "y": 4,
            "z": 1,
            "elements": [
                "chisel:glasspane@13"
            ]
        },
        {
            "x": -5,
            "y": -3,
            "z": 14,
            "elements": [
                "chisel:laboratory@15"
            ]
        },
        {
            "x": 3,
            "y": 0,
            "z": 6,
            "elements": [
                "contenttweaker:fixed_star_alloys_coil@0"
            ]
        },
        {
            "x": 3,
            "y": -3,
            "z": 2,
            "elements": [
                "chisel:laboratory@2"
            ]
        },
        {
            "x": -6,
            "y": 1,
            "z": 14,
            "elements": [
                "cfm:castle_netting@0"
            ]
        },
        {
            "x": 1,
            "y": 5,
            "z": 17,
            "elements": [
                "chisel:glasspane@13"
            ]
        },
        {
            "x": -4,
            "y": 5,
            "z": 12,
            "elements": [
                "chisel:laboratory@0"
            ]
        },
        {
            "x": 1,
            "y": -4,
            "z": 13,
            "elements": [
                "minecraft:iron_block@0"
            ]
        },
        {
            "x": -9,
            "y": -4,
            "z": 5,
            "elements": [
                "minecraft:iron_block@0"
            ]
        },
        {
            "x": 7,
            "y": 5,
            "z": 9,
            "elements": [
                "environmentalmaterials:alabaster_wall_silver@0"
            ]
        },
        {
            "x": 5,
            "y": -3,
            "z": 15,
            "elements": [
                "chisel:laboratory@2"
            ]
        },
        {
            "x": -8,
            "y": -4,
            "z": 6,
            "elements": [
                "minecraft:iron_block@0"
            ]
        },
        {
            "x": -1,
            "y": -4,
            "z": 1,
            "elements": [
                "minecraft:iron_block@0"
            ]
        },
        {
            "x": 6,
            "y": -3,
            "z": 5,
            "elements": [
