{
    "registryname": "dustcollector",
    "localizedname": "§8尘埃物质§9吸积盘",
    "failure-action": "still",
    "requires-blueprint": false,
    "color": "808080",
    "parts": [
        {
            "x": 0,
            "y": 0,
            "z": 0,

            "elements": [
                "modularmachinery:blockcontroller@2"
            ]
        },
        {
            "x": 4,
            "y": -1,
            "z": 17,
            "elements": [
                "minecraft:iron_block@0"
            ]
        },
        {
            "x": -6,
            "y": 0,
            "z": 10,
            "elements": [
                "appliedenergistics2:smooth_sky_stone_block@0"
            ]
        },
        {
            "x": -1,
            "y": 0,
            "z": 19,
            "elements": [
                "mets:titanium_block@0"
            ]
        },
        {
            "x": -6,
            "y": 1,
            "z": -1,
            "elements": [
                "minecraft:iron_block@0"
            ]
        },
        {
            "x": -5,
            "y": 2,
            "z": 10,
            "elements": [
                "avaritia:block_resource@0"
            ]
        },
        {
            "x": -15,
            "y": 0,
            "z": 22,
            "elements": [
                "mets:titanium_block@0"
            ]
        },
        {
            "x": -12,
            "y": 0,
            "z": 20,
            "elements": [
                "avaritia:block_resource@0"
            ]
        },
        {
            "x": -2,
            "y": 5,
            "z": 11,
            "elements": [
                "avaritia:block_resource@0"
            ]
        },
        {
            "x": 8,
            "y": -1,
            "z": 7,
            "elements": [
                "minecraft:iron_block@0"
            ]
        },
        {
            "x": 1,
            "y": -5,
            "z": 12,
            "elements": [
                "avaritia:block_resource@0"
            ]
        },
        {
            "x": -6,
            "y": 0,
            "z": -1,
            "elements": [
                "minecraft:iron_block@0"
            ]
        },
        {
            "x": 5,
            "y": -1,
            "z": 1,
            "elements": [
                "mets:titanium_block@0"
            ]
        },
        {
            "x": -12,
            "y": 0,
            "z": -2,
            "elements": [
                "avaritia:block_resource@0"
            ]
        },
        {
            "x": -6,
            "y": -1,
            "z": 21,
            "elements": [
                "minecraft:iron_block@0"
            ]
        },
        {
            "x": 12,
            "y": 0,
            "z": 3,
            "elements": [
                "mets:titanium_block@0"
            ]
        },
        {
            "x": -10,
            "y": -1,
            "z": 11,
            "elements": [
                "minecraft:stone_slab@8"
            ]
        },
        {
            "x": 1,
            "y": 5,
            "z": 9,
            "elements": [
                "avaritia:block_resource@0"
            ]
        },
        {
            "x": 5,
            "y": 0,
            "z": 17,
            "elements": [
                "minecraft:iron_block@0"
            ]
        },
        {
            "x": -12,
            "y": 1,
            "z": 4,
            "elements": [
                "minecraft:iron_block@0"
            ]
        },
        {
            "x": -6,
            "y": 2,
            "z": -1,
            "elements": [
                "minecraft:iron_block@0"
            ]
        },
        {
            "x": -13,
            "y": 0,
            "z": 25,
            "elements": [
                "minecraft:iron_block@0"
            ]
        },
        {
            "x": 6,
            "y": 1,
            "z": 4,
            "elements": [
                "minecraft:iron_block@0"
            ]
        },
        {
            "x": 16,
            "y": -1,
            "z": 22,
            "elements": [
                "minecraft:stone_slab@8"
            ]
        },
        {
            "x": 2,
            "y": 1,
            "z": 17,
            "elements": [
                "minecraft:stone@6"
            ]
        },
        {
            "x": -1,
            "y": -2,
            "z": 5,
            "elements": [
                "avaritia:block_resource@0"
            ]
        },
        {
            "x": -14,
            "y": 0,
            "z": 3,
            "elements": [
                "minecraft:iron_block@0"
            ]
        },
        {
            "x": 6,
            "y": 2,
            "z": -1,
            "elements": [
                "minecraft:iron_block@0"
            ]
        },
        {
            "x": -7,
            "y": 2,
            "z": 10,
            "elements": [
                "minecraft:stone@4"
            ]
        },
        {
            "x": 2,
            "y": -5,
            "z": 11,
            "elements": [
                "avaritia:block_resource@0"
            ]
        },
        {
            "x": 11,
            "y": 1,
            "z": 22,
            "elements": [
                "avaritia:block_resource@0"
            ]
        },
        {
            "x": -7,
            "y": 0,
            "z": 15,
            "elements": [
                "minecraft:iron_block@0"
            ]
        },
        {
            "x": 6,
            "y": 0,
            "z": -1,
            "elements": [
                "minecraft:iron_block@0"
            ]
        },
        {
            "x": -12,
            "y": -1,
            "z": 21,
            "elements": [
                "avaritia:block_resource@0"
            ]
        },
        {
            "x": 6,
            "y": 1,
            "z": 1,
            "elements": [
                "environmentalmaterials:alabaster_wall_silver@0"
            ]
        },
        {
            "x": -10,
            "y": 0,
            "z": 20,
            "elements": [
                "avaritia:block_resource@0"
            ]
        },
        {
            "x": -7,
            "y": -1,
            "z": 1,
            "elements": [
                "minecraft:quartz_stairs@6"
            ]
        },
        {
            "x": -11,
            "y": -1,
            "z": 16,
            "elements": [
                "minecraft:iron_block@0"
            ]
        },
        {
            "x": 0,
            "y": 2,
            "z": 5,
            "elements": [
                "avaritia:block_resource@0"
            ]
        },
        {
            "x": 13,
            "y": 0,
            "z": 2,
            "elements": [
                "mets:titanium_block@0"
            ]
        },
        {
            "x": 9,
            "y": 0,
            "z": -4,
            "elements": [
                "mets:titanium_block@0"
            ]
        },
        {
            "x": 6,
            "y": 1,
            "z": -1,
            "elements": [
                "minecraft:iron_block@0"
            ]
        },
        {
            "x": -11,
            "y": 0,
            "z": 25,
            "elements": [
                "mets:titanium_block@0"
            ]
        },
        {
            "x": -10,
            "y": -1,
            "z": 4,
            "elements": [
                "minecraft:iron_block@0"
            ]
        },
        {
            "x": 11,
            "y": 0,
            "z": 19,
            "elements": [
                "avaritia:block_resource@0"
            ]
        },
        {
            "x": -7,
            "y": 0,
            "z": 5,
            "elements": [
                "minecraft:iron_block@0"
            ]
        },
        {
            "x": -6,
            "y": -2,
            "z": 3,
            "elements": [
                "minecraft:stone_slab@8"
            ]
        },
        {
            "x": 1,
            "y": -2,
            "z": 5,
            "elements": [
                "avaritia:block_resource@0"
            ]
        },
        {
            "x": -5,
            "y": -1,
            "z": 19,
            "elements": [
                "mets:titanium_block@0"
            ]
        },
        {
            "x": -8,
            "y": -2,
            "z": 10,
            "elements": [
                "minecraft:stone@4"
            ]
        },
        {
            "x": 8,
            "y": 1,
            "z": 17,
            "elements": [
                "minecraft:iron_block@0"
            ]
        },
        {
            "x": 0,
            "y": 1,
            "z": 4,
            "elements": [
                "appliedenergistics2:smooth_sky_stone_block@0"
            ]
        },
        {
            "x": -10,
            "y": 0,
            "z": 10,
            "elements": [
                "minecraft:stone@4"
            ]
        },
        {
            "x": -9,
            "y": 2,
            "z": 10,
            "elements": [
                "minecraft:stone@4"
            ]
        },
        {
            "x": -1,
            "y": 1,
            "z": 16,
            "elements": [
                "appliedenergistics2:smooth_sky_stone_block@0"
            ]
        },
        {
            "x": 1,
            "y": -1,
            "z": 16,
            "elements": [
                "appliedenergistics2:smooth_sky_stone_block@0"
            ]
        },
        {
            "x": -6,
            "y": -2,
            "z": 20,
            "elements": [
                "minecraft:iron_block@0"
            ]
        },
        {
            "x": 15,
            "y": -1,
            "z": 2,
            "elements": [
                "minecraft:iron_block@0"
            ]
        },
        {
            "x": 7,
            "y": -1,
            "z": -3,
            "elements": [
                "minecraft:iron_block@0"
            ]
        },
        {
            "x": -8,
            "y": 0,
            "z": 3,
            "elements": [
                "minecraft:iron_block@0"
            ]
        },
        {
            "x": 3,
            "y": 3,
            "z": 7,
            "elements": [
                "avaritia:block_resource@0"
            ]
        },
        {
            "x": 16,
            "y": -1,
            "z": 20,
            "elements": [
                "mets:titanium_block@0"
            ]
        },
        {
            "x": 7,
            "y": 1,
            "z": 9,
            "elements": [
                "minecraft:stone@6"
            ]
        },
        {
            "x": -16,
            "y": 0,
            "z": -2,
            "elements": [
                "minecraft:iron_block@0"
            ]
        },
        {
            "x": 0,
            "y": -5,
            "z": 11,
            "elements": [
                "avaritia:block_resource@0"
            ]
        },
        {
            "x": -8,
            "y": 1,
            "z": 11,
            "elements": [
                "minecraft:iron_block@0"
            ]
        },
        {
            "x": -10,
            "y": -1,
            "z": 21,
            "elements": [
                "avaritia:block_resource@0"
            ]
        },
        {
            "x": -6,
            "y": -1,
            "z": 11,
            "elements": [
                "appliedenergistics2:smooth_sky_stone_block@0"
            ]
        },
        {
            "x": 11,
            "y": 0,
            "z": 26,
            "elements": [
                "minecraft:iron_block@0"
            ]
        },
        {
            "x": -10,
            "y": 1,
            "z": 21,
            "elements": [
                "avaritia:block_resource@0"
            ]
        },
        {
            "x": 12,
            "y": 0,
            "z": -1,
            "elements": [
                "avaritia:block_resource@0"
            ]
        },
        {
            "x": -9,
            "y": 0,
            "z": 15,
            "elements": [
                "mets:titanium_block@0"
            ]
        },
        {
            "x": 12,
            "y": 1,
            "z": -1,
            "elements": [
                "avaritia:block_resource@0"
            ]
        },
        {
            "x": -1,
            "y": 5,
            "z": 12,
            "elements": [
                "avaritia:block_resource@0"
            ]
        },
        {
            "x": 11,
            "y": 1,
            "z": 26,
            "elements": [
                "minecraft:stone_slab@0"
            ]
        },
        {
            "x": -15,
            "y": 0,
            "z": 1,
            "elements": [
                "minecraft:iron_block@0"
            ]
        },
        {
            "x": 8,
            "y": -1,
            "z": 4,
            "elements": [
                "minecraft:stone@6"
            ]
        },
        {
            "x": -7,
            "y": 1,
            "z": 19,
            "elements": [
                "minecraft:quartz_stairs@3"
            ]
        },
        {
            "x": -9,
            "y": 0,
            "z": -4,
            "elements": [
                "mets:titanium_block@0"
            ]
        },
        {
            "x": 11,
            "y": -2,
            "z": -1,
            "elements": [
                "avaritia:block_resource@0"
            ]
        },
        {
            "x": 5,
            "y": 0,
            "z": 19,
            "elements": [
                "mets:titanium_block@0"
            ]
        },
        {
            "x": -6,
            "y": -2,
            "z": 0,
            "elements": [
                "minecraft:iron_block@0"
            ]
        },
        {
            "x": -1,
            "y": 0,
            "z": 5,
            "elements": [
                "avaritia:block_resource@0"
            ]
        },
        {
            "x": 0,
            "y": 4,
            "z": 7,
            "elements": [
                "avaritia:block_resource@0"
            ]
        },
        {
            "x": 1,
            "y": 1,
            "z": 16,
            "elements": [
                "appliedenergistics2:smooth_sky_stone_block@0"
            ]
        },
        {
            "x": -7,
            "y": -1,
            "z": -3,
            "elements": [
                "minecraft:iron_block@0"
            ]
        },
        {
            "x": 6,
            "y": 0,
            "z": 3,
            "elements": [
                "mets:titanium_block@0"
            ]
        },
        {
            "x": 4,
            "y": -2,
            "z": 12,
            "elements": [
                "avaritia:block_resource@0"
            ]
        },
        {
            "x": 15,
            "y": 1,
            "z": 2,
            "elements": [
                "minecraft:iron_block@0"
            ]
        },
        {
            "x": 6,
            "y": 0,
            "z": 6,
            "elements": [
                "mets:titanium_block@0"
            ]
        },
        {
            "x": 3,
            "y": 2,
            "z": 6,
            "elements": [
                "avaritia:block_resource@0"
            ]
        },
        {
            "x": 4,
            "y": -3,
            "z": 12,
            "elements": [
                "avaritia:block_resource@0"
            ]
        },
        {
            "x": 9,
            "y": -1,
            "z": 9,
            "elements": [
                "minecraft:stone@6"
            ]
        },
        {
            "x": -6,
            "y": 1,
            "z": 11,
            "elements": [
                "appliedenergistics2:smooth_sky_stone_block@0"
            ]
        },
        {
            "x": 4,
            "y": 3,
            "z": 9,
            "elements": [
                "avaritia:block_resource@0"
            ]
        },
        {
            "x": -6,
            "y": 1,
            "z": 1,
            "elements": [
                "environmentalmaterials:alabaster_wall_silver@0"
            ]
        },
        {
            "x": -6,
            "y": 1,
            "z": 4,
            "elements": [
                "minecraft:iron_block@0"
            ]
        },
        {
            "x": -15,
            "y": 1,
            "z": 2,
            "elements": [
                "minecraft:iron_block@0"
            ]
        },
        {
            "x": 1,
            "y": -1,
            "z": 19,
            "elements": [
                "minecraft:stone@6"
            ]
        },
        {
            "x": -2,
            "y": -5,
            "z": 11,
            "elements": [
                "avaritia:block_resource@0"
            ]
        },
        {
            "x": 11,
            "y": 0,
            "z": 17,
            "elements": [
                "mets:titanium_block@0"
            ]
        },
        {
            "x": -1,
            "y": 1,
            "z": 19,
            "elements": [
                "minecraft:stone@6"
            ]
        },
        {
            "x": -6,
            "y": 2,
            "z": 22,
            "elements": [
                "minecraft:quartz_stairs@3"
            ]
        },
        {
            "x": 3,
            "y": -4,
            "z": 10,
            "elements": [
                "avaritia:block_resource@0"
            ]
        },
        {
            "x": -7,
            "y": 0,
            "z": 22,
            "elements": [
                "mets:titanium_block@0"
            ]
        },
        {
            "x": -1,
            "y": -5,
            "z": 9,
            "elements": [
                "avaritia:block_resource@0"
            ]
        },
        {
            "x": 4,
            "y": 0,
            "z": 3,
            "elements": [
                "minecraft:iron_block@0"
            ]
        },
        {
            "x": -7,
            "y": 1,
            "z": -3,
            "elements": [
                "minecraft:iron_block@0"
            ]
        },
        {
            "x": 6,
            "y": -2,
            "z": 3,
            "elements": [
                "minecraft:stone_slab@8"
            ]
        },
        {
            "x": -3,
            "y": 4,
            "z": 8,
            "elements": [
                "avaritia:block_resource@0"
            ]
        },
        {
            "x": 4,
            "y": -2,
            "z": 13,
            "elements": [
                "avaritia:block_resource@0"
            ]
        },
        {
            "x": 5,
            "y": -1,
            "z": 8,
            "elements": [
                "avaritia:block_resource@0"
            ]
        },
        {
            "x": -2,
            "y": -1,
            "z": 18,
            "elements": [
                "minecraft:iron_block@0"
            ]
        },
        {
            "x": 5,
            "y": 1,
            "z": 12,
            "elements": [
                "avaritia:block_resource@0"
            ]
        },
        {
            "x": 7,
            "y": -1,
            "z": 12,
            "elements": [
                "minecraft:stone@6"
            ]
        },
        {
            "x": -6,
            "y": 1,
            "z": 21,
            "elements": [
                "minecraft:iron_block@0"
            ]
        },
        {
            "x": -9,
            "y": -1,
            "z": 16,
            "elements": [
                "environmentalmaterials:alabaster_wall_silver@0"
            ]
        },
        {
            "x": -5,
            "y": -1,
            "z": 9,
            "elements": [
                "avaritia:block_resource@0"
            ]
        },
        {
            "x": -1,
            "y": 0,
            "z": 18,
            "elements": [
                "minecraft:iron_block@0"
            ]
        },
        {
            "x": 5,
            "y": 1,
            "z": 19,
            "elements": [
                "mets:titanium_block@0"
            ]
        },
        {
            "x": -4,
            "y": -3,
            "z": 9,
            "elements": [
                "avaritia:block_resource@0"
            ]
        },
        {
            "x": 1,
            "y": -2,
            "z": 18,
            "elements": [
                "minecraft:stone_slab@8"
            ]
        },
        {
            "x": 7,
            "y": -1,
            "z": 19,
            "elements": [
                "minecraft:quartz_stairs@7"
            ]
        },
        {
            "x": 5,
            "y": 0,
            "z": 12,
            "elements": [
                "avaritia:block_resource@0"
            ]
        },
        {
            "x": -5,
            "y": 1,
            "z": 9,
            "elements": [
                "avaritia:block_resource@0"
            ]
        },
        {
            "x": 12,
            "y": 0,
            "z": -2,
            "elements": [
                "avaritia:block_resource@0"
            ]
        },
        {
            "x": -1,
            "y": 1,
            "z": 18,
            "elements": [
                "minecraft:iron_block@0"
            ]
        },
        {
            "x": 10,
            "y": 0,
            "z": 0,
            "elements": [
                "avaritia:block_resource@0"
            ]
        },
        {
            "x": -8,
            "y": 1,
            "z": -5,
            "elements": [
                "minecraft:iron_block@0"
            ]
        },
        {
            "x": -16,
            "y": -1,
            "z": -1,
            "elements": [
                "minecraft:stone_slab@8"
            ]
        },
        {
            "x": 15,
            "y": 0,
            "z": 1,
            "elements": [
                "minecraft:iron_block@0"
            ]
        },
        {
            "x": -16,
            "y": 1,
            "z": -1,
            "elements": [
                "minecraft:stone_slab@0"
            ]
        },
        {
            "x": 6,
            "y": 1,
            "z": 11,
            "elements": [
                "appliedenergistics2:smooth_sky_stone_block@0"
            ]
        },
        {
            "x": -7,
            "y": -1,
            "z": 8,
            "elements": [
                "minecraft:stone@6"
            ]
        },
        {
            "x": 9,
            "y": 0,
            "z": 8,
            "elements": [
                "mets:titanium_block@0"
            ]
        },
        {
            "x": -6,
            "y": 0,
            "z": 3,
            "elements": [
                "mets:titanium_block@0"
            ]
        },
        {
            "x": -11,
            "y": 1,
            "z": 16,
            "elements": [
                "minecraft:iron_block@0"
            ]
        },
        {
            "x": 1,
            "y": -2,
            "z": 15,
            "elements": [
                "avaritia:block_resource@0"
            ]
        },
        {
            "x": -12,
            "y": 1,
            "z": 21,
            "elements": [
                "avaritia:block_resource@0"
            ]
        },
        {
            "x": 2,
            "y": -4,
            "z": 8,
            "elements": [
                "avaritia:block_resource@0"
            ]
        },
        {
            "x": 1,
            "y": 2,
            "z": 3,
            "elements": [
                "environmentalmaterials:alabaster_stairs_silver@1"
            ]
        },
        {
            "x": 4,
            "y": -1,
            "z": 13,
            "elements": [
                "avaritia:block_resource@0"
            ]
        },
        {
            "x": 6,
            "y": -2,
            "z": 0,
            "elements": [
                "minecraft:iron_block@0"
            ]
        },
        {
            "x": 8,
            "y": 0,
            "z": 13,
            "elements": [
                "minecraft:iron_block@0"
            ]
        },
        {
            "x": -11,
            "y": 0,
            "z": 22,
            "elements": [
                "avaritia:block_resource@0"
            ]
        },
        {
            "x": -1,
            "y": 2,
            "z": 17,
            "elements": [
                "environmentalmaterials:alabaster_stairs_silver@0"
            ]
        },
        {
            "x": 0,
            "y": 0,
            "z": 3,
            "elements": [
                "mets:titanium_block@0"
            ]
        },
        {
            "x": -10,
            "y": -1,
            "z": -1,
            "elements": [
                "avaritia:block_resource@0"
            ]
        },
        {
            "x": -12,
            "y": 0,
            "z": -6,
            "elements": [
                "minecraft:iron_block@0"
            ]
        },
        {
            "x": -9,
            "y": 1,
            "z": 16,
            "elements": [
                "environmentalmaterials:alabaster_wall_silver@0"
            ]
        },
        {
            "x": 0,
            "y": 0,
            "z": 20,
            "elements": [
                "minecraft:stone@4"
            ]
        },
        {
            "x": -1,
            "y": 0,
            "z": 15,
            "elements": [
                "avaritia:block_resource@0"
            ]
        },
        {
            "x": 10,
            "y": 1,
            "z": 25,
            "elements": [
                "minecraft:quartz_stairs@1"
            ]
        },
        {
            "x": -9,
            "y": 0,
            "z": 8,
            "elements": [
                "mets:titanium_block@0"
            ]
        },
        {
            "x": 6,
            "y": 0,
            "z": 14,
            "elements": [
                "mets:titanium_block@0"
            ]
        },
        {
            "x": 1,
            "y": -5,
            "z": 9,
            "elements": [
                "avaritia:block_resource@0"
            ]
        },
        {
            "x": 9,
            "y": 1,
            "z": 12,
            "elements": [
                "astraladditions:block_marble_wall@0"
            ]
        },
        {
            "x": -9,
            "y": -1,
            "z": 9,
            "elements": [
                "minecraft:stone@6"
            ]
        },
        {
            "x": -8,
            "y": 1,
            "z": 4,
            "elements": [
                "minecraft:stone@6"
            ]
        },
        {
            "x": -10,
            "y": 0,
            "z": 0,
            "elements": [
                "avaritia:block_resource@0"
            ]
        },
        {
            "x": 9,
            "y": -1,
            "z": 25,
            "elements": [
                "minecraft:iron_block@0"
            ]
        },
        {
            "x": -3,
            "y": -4,
            "z": 10,
            "elements": [
                "avaritia:block_resource@0"
            ]
        },
        {
            "x": 8,
            "y": -1,
            "z": -5,
            "elements": [
                "minecraft:iron_block@0"
            ]
        },
        {
            "x": -9,
            "y": 0,
            "z": 5,
            "elements": [
                "mets:titanium_block@0"
            ]
        },
        {
            "x": 3,
            "y": 4,
            "z": 8,
            "elements": [
                "avaritia:block_resource@0"
            ]
        },
        {
            "x": -12,
            "y": 0,
            "z": -1,
            "elements": [
                "avaritia:block_resource@0"
            ]
        },
        {
            "x": -12,
            "y": 1,
            "z": -1,
            "elements": [
                "avaritia:block_resource@0"
            ]
        },
        {
            "x": 0,
            "y": -1,
            "z": 4,
            "elements": [
                "appliedenergistics2:smooth_sky_stone_block@0"
            ]
        },
        {
            "x": -8,
            "y": 0,
            "z": 10,
            "elements": [
                "minecraft:iron_block@0"
            ]
        },
        {
            "x": 11,
            "y": -1,
            "z": -2,
            "elements": [
                "avaritia:block_resource@0"
            ]
        },
        {
            "x": 11,
            "y": -1,
            "z": 20,
            "elements": [
                "avaritia:block_resource@0"
            ]
        },
        {
            "x": -14,
            "y": 0,
            "z": 23,
            "elements": [
                "mets:titanium_block@0"
            ]
        },
        {
            "x": 11,
            "y": 0,
            "z": 21,
            "elements": [
                "avaritia:block_resource@0"
            ]
        },
        {
            "x": -1,
            "y": 2,
            "z": 3,
            "elements": [
                "environmentalmaterials:alabaster_stairs_silver@0"
            ]
        },
        {
            "x": 0,
            "y": 5,
            "z": 8,
            "elements": [
                "avaritia:block_resource@0"
            ]
        },
        {
            "x": 0,
            "y": 5,
            "z": 11,
            "elements": [
                "avaritia:block_resource@0"
            ]
        },
        {
            "x": -15,
            "y": -1,
            "z": 23,
            "elements": [
                "minecraft:stone_slab@8"
            ]
        },
        {
            "x": -2,
            "y": 0,
            "z": 3,
            "elements": [
                "mets:titanium_block@0"
            ]
        },
        {
            "x": -7,
            "y": 1,
            "z": 16,
            "elements": [
                "avaritia:block_resource@0"
            ]
        },
        {
            "x": 11,
            "y": 2,
            "z": 21,
            "elements": [
                "avaritia:block_resource@0"
            ]
        },
        {
            "x": 0,
            "y": -2,
            "z": 3,
            "elements": [
                "minecraft:stone@4"
            ]
        },
        {
            "x": -16,
            "y": -1,
            "z": 21,
            "elements": [
                "minecraft:stone_slab@8"
            ]
        },
        {
            "x": -4,
            "y": 3,
            "z": 9,
            "elements": [
                "avaritia:block_resource@0"
            ]
        },
        {
            "x": 6,
            "y": 1,
            "z": -2,
            "elements": [
                "minecraft:iron_block@0"
            ]
        },
        {
            "x": -6,
            "y": 0,
            "z": 20,
            "elements": [
                "minecraft:iron_block@0"
            ]
        },
        {
            "x": -7,
            "y": -1,
            "z": 16,
            "elements": [
                "avaritia:block_resource@0"
            ]
        },
        {
            "x": 5,
            "y": 0,
            "z": 18,
            "elements": [
                "mets:titanium_block@0"
            ]
        },
        {
            "x": -6,
            "y": -1,
            "z": 4,
            "elements": [
                "minecraft:iron_block@0"
            ]
        },
        {
            "x": -7,
            "y": -1,
            "z": 2,
            "elements": [
                "minecraft:iron_block@0"
            ]
        },
        {
            "x": 14,
            "y": 1,
            "z": 17,
            "elements": [
                "minecraft:iron_block@0"
            ]
        },
        {
            "x": 6,
            "y": 0,
            "z": -2,
            "elements": [
                "minecraft:iron_block@0"
            ]
        },
        {
            "x": 14,
            "y": -1,
            "z": -5,
            "elements": [
                "minecraft:stone_slab@8"
            ]
        },
        {
            "x": -7,
            "y": 1,
            "z": 9,
            "elements": [
                "minecraft:stone@6"
            ]
        },
        {
            "x": -16,
            "y": 1,
            "z": 0,
            "elements": [
                "mets:titanium_block@0"
            ]
        },
        {
            "x": -1,
            "y": -1,
            "z": 19,
            "elements": [
                "minecraft:stone@6"
            ]
        },
        {
            "x": -8,
            "y": 0,
            "z": 23,
            "elements": [
                "mets:titanium_block@0"
            ]
        },
        {
            "x": 7,
            "y": 2,
            "z": 11,
            "elements": [
                "environmentalmaterials:alabaster_stairs_silver@3"
            ]
        },
        {
            "x": -7,
            "y": 0,
            "z": -4,
            "elements": [
                "minecraft:iron_block@0"
            ]
        },
        {
            "x": 11,
            "y": -2,
            "z": 21,
            "elements": [
                "avaritia:block_resource@0"
            ]
        },
        {
            "x": 6,
            "y": -1,
            "z": 4,
            "elements": [
                "minecraft:iron_block@0"
            ]
        },
        {
            "x": 16,
            "y": 0,
            "z": 0,
            "elements": [
                "minecraft:iron_block@0"
            ]
        },
        {
            "x": 7,
            "y": 0,
            "z": 4,
            "elements": [
                "mets:titanium_block@0"
            ]
        },
        {
            "x": -14,
            "y": -1,
            "z": -5,
            "elements": [
                "minecraft:stone_slab@8"
            ]
        },
        {
            "x": -4,
            "y": -2,
            "z": 13,
            "elements": [
                "avaritia:block_resource@0"
            ]
        },
        {
            "x": -4,
            "y": 1,
            "z": 17,
            "elements": [
                "minecraft:iron_block@0"
            ]
        },
        {
            "x": 10,
            "y": 0,
            "z": 10,
            "elements": [
                "minecraft:stone@4"
            ]
        },
        {
            "x": 8,
            "y": 1,
            "z": 7,
            "elements": [
                "minecraft:iron_block@0"
            ]
        },
        {
            "x": -1,
            "y": 3,
            "z": 14,
            "elements": [
                "avaritia:block_resource@0"
            ]
        },
        {
            "x": 8,
            "y": 0,
            "z": 6,
            "elements": [
                "mets:titanium_block@0"
            ]
        },
        {
            "x": -11,
            "y": 1,
            "z": -6,
            "elements": [
                "minecraft:stone_slab@0"
            ]
        },
        {
            "x": 9,
            "y": 2,
            "z": 10,
            "elements": [
                "minecraft:stone@4"
            ]
        },
        {
            "x": -13,
            "y": 0,
            "z": -5,
            "elements": [
                "minecraft:iron_block@0"
            ]
        },
        {
            "x": 7,
            "y": 0,
            "z": 11,
            "elements": [
                "mets:titanium_block@0"
            ]
        },
        {
            "x": -8,
            "y": -1,
            "z": 7,
            "elements": [
                "minecraft:iron_block@0"
            ]
        },
        {
            "x": 3,
            "y": 1,
            "z": 2,
            "elements": [
                "minecraft:iron_block@0"
            ]
        },
        {
            "x": 6,
            "y": 0,
            "z": 16,
            "elements": [
                "minecraft:iron_block@0"
            ]
        },
        {
            "x": -5,
            "y": 0,
            "z": 8,
            "elements": [
                "avaritia:block_resource@0"
            ]
        },
        {
            "x": 7,
            "y": 2,
            "z": 4,
            "elements": [
                "minecraft:stone_slab@0"
            ]
        },
        {
            "x": -5,
            "y": -1,
            "z": 2,
            "elements": [
                "mets:titanium_block@0"
            ]
        },
        {
            "x": 10,
            "y": -1,
            "z": 21,
            "elements": [
                "avaritia:block_resource@0"
            ]
        },
        {
            "x": 10,
            "y": -1,
            "z": -1,
            "elements": [
                "avaritia:block_resource@0"
            ]
        },
        {
            "x": -11,
            "y": 0,
            "z": 1,
            "elements": [
                "avaritia:block_resource@0"
            ]
        },
        {
            "x": -9,
            "y": 0,
            "z": 18,
            "elements": [
                "mets:titanium_block@0"
            ]
        },
        {
            "x": -3,
            "y": 1,
            "z": 19,
            "elements": [
                "astraladditions:block_marble_wall@0"
            ]
        },
        {
            "x": -3,
            "y": -1,
            "z": 19,
            "elements": [
                "astraladditions:block_marble_wall@0"
            ]
        },
        {
            "x": 11,
            "y": -1,
            "z": 16,
            "elements": [
                "minecraft:iron_block@0"
            ]
        },
        {
            "x": 5,
            "y": 1,
            "z": 20,
            "elements": [
                "mets:titanium_block@0"
            ]
        },
        {
            "x": 7,
            "y": 0,
            "z": 1,
            "elements": [
                "mets:titanium_block@0"
            ]
        },
        {
            "x": 5,
            "y": -2,
            "z": 9,
            "elements": [
                "avaritia:block_resource@0"
            ]
        },
        {
            "x": -1,
            "y": -4,
            "z": 13,
            "elements": [
                "avaritia:block_resource@0"
            ]
        },
        {
            "x": 11,
            "y": -2,
            "z": 16,
            "elements": [
                "minecraft:iron_block@0"
            ]
        },
        {
            "x": -14,
            "y": 1,
            "z": 17,
            "elements": [
                "minecraft:iron_block@0"
            ]
        },
        {
            "x": 9,
            "y": 0,
            "z": 15,
            "elements": [
                "mets:titanium_block@0"
            ]
        },
        {
            "x": 1,
            "y": -3,
            "z": 14,
            "elements": [
                "avaritia:block_resource@0"
            ]
        },
        {
            "x": -2,
            "y": -1,
            "z": 17,
            "elements": [
                "minecraft:stone@6"
            ]
        },
        {
            "x": 6,
            "y": -1,
            "z": 11,
            "elements": [
                "appliedenergistics2:smooth_sky_stone_block@0"
            ]
        },
        {
            "x": -4,
            "y": 1,
            "z": 7,
            "elements": [
                "avaritia:block_resource@0"
            ]
        },
        {
            "x": 7,
            "y": 2,
            "z": 10,
            "elements": [
                "minecraft:stone@4"
            ]
        },
        {
            "x": 6,
            "y": 1,
            "z": 20,
            "elements": [
                "minecraft:iron_block@0"
            ]
        },
        {
            "x": 5,
            "y": -1,
            "z": 12,
            "elements": [
                "avaritia:block_resource@0"
            ]
        },
        {
            "x": -6,
            "y": 0,
            "z": -2,
            "elements": [
                "minecraft:iron_block@0"
            ]
        },
        {
            "x": 12,
            "y": 0,
            "z": 21,
            "elements": [
                "avaritia:block_resource@0"
            ]
        },
        {
            "x": -3,
            "y": 1,
            "z": 2,
            "elements": [
                "minecraft:iron_block@0"
            ]
        },
        {
            "x": 7,
            "y": 3,
            "z": 10,
            "elements": [
                "minecraft:stone_slab@0"
            ]
        },
        {
            "x": 12,
            "y": 0,
            "z": 16,
            "elements": [
                "minecraft:iron_block@0"
            ]
        },
        {
            "x": 6,
            "y": 0,
            "z": 9,
            "elements": [
                "appliedenergistics2:smooth_sky_stone_block@0"
            ]
        },
        {
            "x": 6,
            "y": 0,
            "z": 20,
            "elements": [
                "minecraft:iron_block@0"
            ]
        },
        {
            "x": 5,
            "y": -1,
            "z": 9,
            "elements": [
                "avaritia:block_resource@0"
            ]
        },
        {
            "x": -7,
            "y": 1,
            "z": -4,
            "elements": [
                "minecraft:iron_block@0"
            ]
        },
        {
            "x": -7,
            "y": 0,
            "z": 18,
            "elements": [
                "minecraft:iron_block@0"
            ]
        },
        {
            "x": 6,
            "y": 2,
            "z": 21,
            "elements": [
                "minecraft:iron_block@0"
            ]
        },
        {
            "x": 11,
            "y": 1,
            "z": 20,
            "elements": [
                "avaritia:block_resource@0"
            ]
        },
        {
            "x": 5,
            "y": 0,
            "z": 21,
            "elements": [
                "mets:titanium_block@0"
            ]
        },
        {
            "x": 6,
            "y": 1,
            "z": 10,
            "elements": [
                "appliedenergistics2:smooth_sky_stone_block@0"
            ]
        },
        {
            "x": 2,
            "y": 4,
            "z": 13,
            "elements": [
                "avaritia:block_resource@0"
            ]
        },
        {
            "x": -10,
            "y": 1,
            "z": -1,
            "elements": [
                "avaritia:block_resource@0"
            ]
        },
        {
            "x": 12,
            "y": 0,
            "z": 26,
            "elements": [
                "minecraft:iron_block@0"
            ]
        },
        {
            "x": 1,
            "y": 0,
            "z": 1,
            "elements": [
                "mets:titanium_block@0"
            ]
        },
        {
            "x": -8,
            "y": -1,
            "z": 17,
            "elements": [
                "minecraft:iron_block@0"
            ]
        },
        {
            "x": -4,
            "y": 2,
            "z": 8,
            "elements": [
                "avaritia:block_resource@0"
            ]
        },
        {
            "x": 12,
            "y": 2,
            "z": 16,
            "elements": [
                "minecraft:quartz_stairs@1"
            ]
        },
        {
            "x": 8,
            "y": -2,
            "z": 10,
            "elements": [
                "minecraft:stone@4"
            ]
        },
        {
            "x": -12,
            "y": 0,
            "z": 16,
            "elements": [
                "minecraft:iron_block@0"
            ]
        },
        {
            "x": -8,
            "y": 1,
            "z": 17,
            "elements": [
                "minecraft:iron_block@0"
            ]
        },
        {
            "x": 8,
            "y": -1,
            "z": 11,
            "elements": [
                "minecraft:iron_block@0"
            ]
        },
        {
            "x": 6,
            "y": 0,
            "z": 10,
            "elements": [
                "appliedenergistics2:smooth_sky_stone_block@0"
            ]
        },
        {
            "x": -13,
            "y": 0,
            "z": 18,
            "elements": [
                "mets:titanium_block@0"
            ]
        },
        {
            "x": 4,
            "y": -1,
            "z": 7,
            "elements": [
                "avaritia:block_resource@0"
            ]
        },
        {
            "x": 6,
            "y": 0,
            "z": 21,
            "elements": [
                "minecraft:iron_block@0"
            ]
        },
        {
            "x": 7,
            "y": 1,
            "z": 10,
            "elements": [
                "minecraft:stone@6"
            ]
        },
        {
            "x": -1,
            "y": 1,
            "z": 2,
            "elements": [
                "minecraft:iron_block@0"
            ]
        },
        {
            "x": -9,
            "y": 1,
            "z": 9,
            "elements": [
                "minecraft:stone@6"
            ]
        },
        {
            "x": -1,
            "y": -1,
            "z": 2,
            "elements": [
                "minecraft:iron_block@0"
            ]
        },
        {
            "x": 14,
            "y": 1,
            "z": -5,
            "elements": [
                "minecraft:stone_slab@0"
            ]
        },
        {
            "x": 6,
            "y": 1,
            "z": 21,
            "elements": [
                "minecraft:iron_block@0"
            ]
        },
        {
            "x": 11,
            "y": -1,
            "z": -6,
            "elements": [
                "minecraft:stone_slab@8"
            ]
        },
        {
            "x": 10,
            "y": 0,
            "z": 26,
            "elements": [
                "minecraft:iron_block@0"
            ]
        },
        {
            "x": 10,
            "y": 1,
            "z": 4,
            "elements": [
                "minecraft:iron_block@0"
            ]
        },
        {
            "x": -5,
            "y": 0,
            "z": 1,
            "elements": [
                "mets:titanium_block@0"
            ]
        },
        {
            "x": -7,
            "y": -2,
            "z": 9,
            "elements": [
                "environmentalmaterials:alabaster_stairs_silver@6"
            ]
        },
        {
            "x": -15,
            "y": -1,
            "z": 19,
            "elements": [
                "minecraft:iron_block@0"
            ]
        },
        {
            "x": 0,
            "y": 4,
            "z": 13,
            "elements": [
                "avaritia:block_resource@0"
            ]
        },
        {
            "x": -1,
            "y": -1,
            "z": 16,
            "elements": [
                "appliedenergistics2:smooth_sky_stone_block@0"
            ]
        },
        {
            "x": 10,
            "y": 1,
            "z": 11,
            "elements": [
                "minecraft:stone_slab@0"
            ]
        },
        {
            "x": -7,
            "y": 0,
            "z": -3,
            "elements": [
                "minecraft:iron_block@0"
            ]
        },
        {
            "x": -6,
            "y": -1,
            "z": 17,
            "elements": [
                "avaritia:block_resource@0"
            ]
        },
        {
            "x": -6,
            "y": 0,
            "z": 9,
            "elements": [
                "appliedenergistics2:smooth_sky_stone_block@0"
            ]
        },
        {
            "x": 6,
            "y": -1,
            "z": 3,
            "elements": [
                "avaritia:block_resource@0"
            ]
        },
        {
            "x": -2,
            "y": -4,
            "z": 8,
            "elements": [
                "avaritia:block_resource@0"
            ]
        },
        {
            "x": 0,
            "y": 0,
            "z": 16,
            "elements": [
                "appliedenergistics2:smooth_sky_stone_block@0"
            ]
        },
        {
            "x": -11,
            "y": 1,
            "z": 0,
            "elements": [
                "avaritia:block_resource@0"
            ]
        },
        {
            "x": 1,
            "y": 1,
            "z": 2,
            "elements": [
                "minecraft:iron_block@0"
            ]
        },
        {
            "x": 1,
            "y": -1,
            "z": 2,
            "elements": [
                "minecraft:iron_block@0"
            ]
        },
        {
            "x": 5,
            "y": -1,
            "z": 10,
            "elements": [
                "avaritia:block_resource@0"
            ]
        },
        {
            "x": -7,
            "y": -1,
            "z": 9,
            "elements": [
                "minecraft:stone@6"
            ]
        },
        {
            "x": 15,
            "y": 0,
            "z": 22,
            "elements": [
                "mets:titanium_block@0"
            ]
        },
        {
            "x": -6,
            "y": 2,
            "z": 18,
            "elements": [
                "minecraft:stone@6"
            ]
        },
        {
            "x": 15,
            "y": -1,
            "z": 23,
            "elements": [
                "minecraft:stone_slab@8"
            ]
        },
        {
            "x": -3,
            "y": 0,
            "z": 18,
            "elements": [
                "minecraft:iron_block@0"
            ]
        },
        {
            "x": -12,
            "y": 0,
            "z": 3,
            "elements": [
                "mets:titanium_block@0"
            ]
        },
        {
            "x": 4,
            "y": 1,
            "z": 17,
            "elements": [
                "minecraft:iron_block@0"
            ]
        },
        {
            "x": -3,
            "y": 0,
            "z": 1,
            "elements": [
                "mets:titanium_block@0"
            ]
        },
        {
            "x": 0,
            "y": 2,
            "z": 1,
            "elements": [
                "minecraft:stone@4"
            ]
        },
        {
            "x": -13,
            "y": -1,
            "z": 3,
            "elements": [
                "minecraft:iron_block@0"
            ]
        },
        {
            "x": 1,
            "y": -4,
            "z": 13,
            "elements": [
                "avaritia:block_resource@0"
            ]
        },
        {
            "x": -1,
            "y": 1,
            "z": 20,
            "elements": [
                "minecraft:stone_slab@0"
            ]
        },
        {
            "x": -4,
            "y": 0,
            "z": 13,
            "elements": [
                "avaritia:block_resource@0"
            ]
        },
        {
            "x": -9,
            "y": -1,
            "z": 12,
            "elements": [
                "astraladditions:block_marble_wall@0"
            ]
        },
        {
            "x": 10,
            "y": -1,
            "z": 25,
            "elements": [
                "minecraft:quartz_stairs@5"
            ]
        },
        {
            "x": 0,
            "y": 2,
            "z": 15,
            "elements": [
                "avaritia:block_resource@0"
            ]
        },
        {
            "x": -1,
            "y": -2,
            "z": 15,
            "elements": [
                "avaritia:block_resource@0"
            ]
        },
        {
            "x": 2,
            "y": -2,
            "z": 6,
            "elements": [
                "avaritia:block_resource@0"
            ]
        },
        {
            "x": 11,
            "y": 0,
            "z": 25,
            "elements": [
                "mets:titanium_block@0"
            ]
        },
        {
            "x": -3,
            "y": 2,
            "z": 6,
            "elements": [
                "avaritia:block_resource@0"
            ]
        },
        {
            "x": 7,
            "y": 2,
            "z": 3,
            "elements": [
                "minecraft:stone@6"
            ]
        },
        {
            "x": 3,
            "y": -3,
            "z": 7,
            "elements": [
                "avaritia:block_resource@0"
            ]
        },
        {
            "x": 3,
            "y": -1,
            "z": 2,
            "elements": [
                "minecraft:iron_block@0"
            ]
        },
        {
            "x": -5,
            "y": 1,
            "z": 2,
            "elements": [
                "mets:titanium_block@0"
            ]
        },
        {
            "x": -1,
            "y": -1,
            "z": 15,
            "elements": [
                "avaritia:block_resource@0"
            ]
        },
        {
            "x": 15,
            "y": 0,
            "z": -4,
            "elements": [
                "minecraft:iron_block@0"
            ]
        },
        {
            "x": 7,
            "y": 1,
            "z": 3,
            "elements": [
                "minecraft:stone@6"
            ]
        },
        {
            "x": -1,
            "y": 0,
            "z": 1,
            "elements": [
                "mets:titanium_block@0"
            ]
        },
        {
            "x": 6,
            "y": -1,
            "z": 17,
            "elements": [
                "avaritia:block_resource@0"
            ]
        },
        {
            "x": 12,
            "y": -1,
            "z": 4,
            "elements": [
                "minecraft:iron_block@0"
            ]
        },
        {
            "x": -13,
            "y": 0,
            "z": -4,
            "elements": [
                "mets:titanium_block@0"
            ]
        },
        {
            "x": -11,
            "y": -1,
            "z": 26,
            "elements": [
                "minecraft:stone_slab@8"
            ]
        },
        {
            "x": 6,
            "y": 1,
            "z": 22,
            "elements": [
                "minecraft:iron_block@0"
            ]
        },
        {
            "x": 11,
            "y": 0,
            "z": -5,
            "elements": [
                "mets:titanium_block@0"
            ]
        },
        {
            "x": 10,
            "y": 0,
            "z": 17,
            "elements": [
                "mets:titanium_block@0"
            ]
        },
        {
            "x": -5,
            "y": 1,
            "z": 12,
            "elements": [
                "avaritia:block_resource@0"
            ]
        },
        {
            "x": 0,
            "y": 1,
            "z": 15,
            "elements": [
                "avaritia:block_resource@0"
            ]
        },
        {
            "x": 11,
            "y": -1,
            "z": 22,
            "elements": [
                "avaritia:block_resource@0"
            ]
        },
        {
            "x": -7,
            "y": 0,
            "z": 8,
            "elements": [
                "mets:titanium_block@0"
            ]
        },
        {
            "x": 10,
            "y": 0,
            "z": 3,
            "elements": [
                "mets:titanium_block@0"
            ]
        },
        {
            "x": -3,
            "y": -1,
            "z": 2,
            "elements": [
                "minecraft:iron_block@0"
            ]
        },
        {
            "x": -6,
            "y": 0,
            "z": 6,
            "elements": [
                "mets:titanium_block@0"
            ]
        },
        {
            "x": 1,
            "y": 0,
            "z": 18,
            "elements": [
                "minecraft:iron_block@0"
            ]
        },
        {
            "x": 15,
            "y": -1,
            "z": 18,
            "elements": [
                "minecraft:iron_block@0"
            ]
        },
        {
            "x": -11,
            "y": 0,
            "z": 5,
            "elements": [
                "mets:titanium_block@0"
            ]
        },
        {
            "x": 6,
            "y": 2,
            "z": 22,
            "elements": [
                "minecraft:quartz_stairs@3"
            ]
        },
        {
            "x": 8,
            "y": 1,
            "z": -5,
            "elements": [
                "minecraft:iron_block@0"
            ]
        },
        {
            "x": -11,
            "y": 1,
            "z": 26,
            "elements": [
                "minecraft:stone_slab@0"
            ]
        },
        {
            "x": -5,
            "y": 1,
            "z": 19,
            "elements": [
                "mets:titanium_block@0"
            ]
        },
        {
            "x": -11,
            "y": 2,
            "z": 4,
            "elements": [
                "minecraft:iron_block@0"
            ]
        },
        {
            "x": 6,
            "y": -1,
            "z": -1,
            "elements": [
                "minecraft:iron_block@0"
            ]
        },
        {
            "x": -7,
            "y": 0,
            "z": 1,
            "elements": [
                "mets:titanium_block@0"
            ]
        },
        {
            "x": 1,
            "y": 0,
            "z": 5,
            "elements": [
                "avaritia:block_resource@0"
            ]
        },
        {
            "x": -1,
            "y": -3,
            "z": 14,
            "elements": [
                "avaritia:block_resource@0"
            ]
        },
        {
            "x": -10,
            "y": 1,
            "z": -5,
            "elements": [
                "minecraft:quartz_stairs@0"
            ]
        },
        {
            "x": -16,
            "y": 0,
            "z": 20,
            "elements": [
                "minecraft:iron_block@0"
            ]
        },
        {
            "x": -8,
            "y": 0,
            "z": 13,
            "elements": [
                "minecraft:iron_block@0"
            ]
        },
        {
            "x": 7,
            "y": 0,
            "z": 8,
            "elements": [
                "mets:titanium_block@0"
            ]
        },
        {
            "x": 0,
            "y": -1,
            "z": 17,
            "elements": [
                "minecraft:stone@6"
            ]
        },
        {
            "x": 4,
            "y": 2,
            "z": 8,
            "elements": [
                "avaritia:block_resource@0"
            ]
        },
        {
            "x": -4,
            "y": -3,
            "z": 12,
            "elements": [
                "avaritia:block_resource@0"
            ]
        },
        {
            "x": 1,
            "y": 1,
            "z": 5,
            "elements": [
                "avaritia:block_resource@0"
            ]
        },
        {
            "x": -5,
            "y": -1,
            "z": 12,
            "elements": [
                "avaritia:block_resource@0"
            ]
        },
        {
            "x": -7,
            "y": 1,
            "z": 12,
            "elements": [
                "minecraft:stone@6"
            ]
        },
        {
            "x": 7,
            "y": 1,
            "z": 2,
            "elements": [
                "minecraft:iron_block@0"
            ]
        },
        {
            "x": -4,
            "y": -1,
            "z": 7,
            "elements": [
                "avaritia:block_resource@0"
            ]
        },
        {
            "x": -11,
            "y": 0,
            "z": 4,
            "elements": [
                "minecraft:iron_block@0"
            ]
        },
        {
            "x": -2,
            "y": -2,
            "z": 6,
            "elements": [
                "avaritia:block_resource@0"
            ]
        },
        {
            "x": -5,
            "y": 0,
            "z": 18,
            "elements": [
                "mets:titanium_block@0"
            ]
        },
        {
            "x": 5,
            "y": 0,
            "z": 22,
            "elements": [
                "mets:titanium_block@0"
            ]
        },
        {
            "x": 0,
            "y": -1,
            "z": 5,
            "elements": [
                "avaritia:block_resource@0"
            ]
        },
        {
            "x": -12,
            "y": -1,
            "z": 4,
            "elements": [
                "minecraft:iron_block@0"
            ]
        },
        {
            "x": 11,
            "y": -1,
            "z": 15,
            "elements": [
                "mets:titanium_block@0"
            ]
        },
        {
            "x": -7,
            "y": -1,
            "z": 19,
            "elements": [
                "minecraft:quartz_stairs@7"
            ]
        },
        {
            "x": 7,
            "y": 1,
            "z": 5,
            "elements": [
                "minecraft:iron_block@0"
            ]
        },
        {
            "x": -2,
            "y": 1,
            "z": 17,
            "elements": [
                "minecraft:stone@6"
            ]
        },
        {
            "x": -15,
            "y": 1,
            "z": 19,
            "elements": [
                "minecraft:iron_block@0"
            ]
        },
        {
            "x": 9,
            "y": 1,
            "z": 16,
            "elements": [
                "environmentalmaterials:alabaster_wall_silver@0"
            ]
        },
        {
            "x": 3,
            "y": 0,
            "z": 1,
            "elements": [
                "mets:titanium_block@0"
            ]
        },
        {
            "x": 15,
            "y": 1,
            "z": -3,
            "elements": [
                "minecraft:stone_slab@0"
            ]
        },
        {
            "x": -8,
            "y": -1,
            "z": -5,
            "elements": [
                "minecraft:iron_block@0"
            ]
        },
        {
            "x": 7,
            "y": 0,
            "z": 5,
            "elements": [
                "minecraft:iron_block@0"
            ]
        },
        {
            "x": -1,
            "y": -5,
            "z": 12,
            "elements": [
                "avaritia:block_resource@0"
            ]
        },
        {
            "x": -14,
            "y": -1,
            "z": 17,
            "elements": [
                "minecraft:iron_block@0"
            ]
        },
        {
            "x": -3,
            "y": 3,
            "z": 7,
            "elements": [
                "avaritia:block_resource@0"
            ]
        },
        {
            "x": 5,
            "y": 0,
            "z": 8,
            "elements": [
                "avaritia:block_resource@0"
            ]
        },
        {
            "x": -7,
            "y": -1,
            "z": 12,
            "elements": [
                "minecraft:stone@6"
            ]
        },
        {
            "x": -9,
            "y": 1,
            "z": 12,
            "elements": [
                "astraladditions:block_marble_wall@0"
            ]
        },
        {
            "x": -16,
            "y": 1,
            "z": 21,
            "elements": [
                "minecraft:stone_slab@0"
            ]
        },
        {
            "x": -10,
            "y": 0,
            "z": -2,
            "elements": [
                "avaritia:block_resource@0"
            ]
        },
        {
            "x": -15,
            "y": 1,
            "z": -3,
            "elements": [
                "minecraft:stone_slab@0"
            ]
        },
        {
            "x": -4,
            "y": 3,
            "z": 12,
            "elements": [
                "avaritia:block_resource@0"
            ]
        },
        {
            "x": -3,
            "y": -3,
            "z": 7,
            "elements": [
                "avaritia:block_resource@0"
            ]
        },
        {
            "x": 9,
            "y": 1,
            "z": 9,
            "elements": [
                "minecraft:stone@6"
            ]
        },
        {
            "x": 13,
            "y": 1,
            "z": 3,
            "elements": [
                "minecraft:iron_block@0"
            ]
        },
        {
            "x": 4,
            "y": 0,
            "z": 13,
            "elements": [
                "avaritia:block_resource@0"
            ]
        },
        {
            "x": -14,
            "y": -1,
            "z": 25,
            "elements": [
                "minecraft:stone_slab@8"
            ]
        },
        {
            "x": 3,
            "y": -2,
            "z": 14,
            "elements": [
                "avaritia:block_resource@0"
            ]
        },
        {
            "x": -6,
            "y": 1,
            "z": 10,
            "elements": [
                "appliedenergistics2:smooth_sky_stone_block@0"
            ]
        },
        {
            "x": -10,
            "y": 1,
            "z": 25,
            "elements": [
                "minecraft:quartz_stairs@0"
            ]
        },
        {
            "x": -6,
            "y": -1,
            "z": -1,
            "elements": [
                "minecraft:iron_block@0"
            ]
        },
        {
            "x": 5,
            "y": 0,
            "z": 1,
            "elements": [
                "mets:titanium_block@0"
            ]
        },
        {
            "x": -2,
            "y": 4,
            "z": 13,
            "elements": [
                "avaritia:block_resource@0"
            ]
        },
        {
            "x": 0,
            "y": -1,
            "z": 0,
            "elements": [
                "minecraft:stone@4"
            ]
        },
        {
            "x": -2,
            "y": -5,
            "z": 10,
            "elements": [
                "avaritia:block_resource@0"
            ]
        },
        {
            "x": 6,
            "y": -2,
            "z": 18,
            "elements": [
                "minecraft:stone@6"
            ]
        },
        {
            "x": 12,
            "y": 0,
            "z": 17,
            "elements": [
                "mets:titanium_block@0"
            ]
        },
        {
            "x": -11,
            "y": 0,
            "z": -1,
            "elements": [
                "avaritia:block_resource@0"
            ]
        },
        {
            "x": -12,
            "y": 2,
            "z": 4,
            "elements": [
                "minecraft:quartz_stairs@0"
            ]
        },
        {
            "x": -11,
            "y": 1,
            "z": -1,
            "elements": [
                "avaritia:block_resource@0"
            ]
        },
        {
            "x": 5,
            "y": 1,
            "z": 8,
            "elements": [
                "avaritia:block_resource@0"
            ]
        },
        {
            "x": 4,
            "y": 2,
            "z": 13,
            "elements": [
                "avaritia:block_resource@0"
            ]
        },
        {
            "x": -7,
            "y": -2,
            "z": 4,
            "elements": [
                "minecraft:stone_slab@8"
            ]
        },
        {
            "x": 15,
            "y": -1,
            "z": 19,
            "elements": [
                "minecraft:iron_block@0"
            ]
        },
        {
            "x": -2,
            "y": 1,
            "z": 5,
            "elements": [
                "avaritia:block_resource@0"
            ]
        },
        {
            "x": -6,
            "y": -2,
            "z": 21,
            "elements": [
                "minecraft:iron_block@0"
            ]
        },
        {
            "x": 7,
            "y": 1,
            "z": 18,
            "elements": [
                "minecraft:iron_block@0"
            ]
        },
        {
            "x": 11,
            "y": -1,
            "z": 3,
            "elements": [
                "minecraft:iron_bars@0"
            ]
        },
        {
            "x": -15,
            "y": 0,
            "z": 19,
            "elements": [
                "minecraft:iron_block@0"
            ]
        },
        {
            "x": 16,
            "y": 0,
            "z": -2,
            "elements": [
                "minecraft:iron_block@0"
            ]
        },
        {
            "x": -7,
            "y": 3,
            "z": 10,
            "elements": [
                "minecraft:stone_slab@0"
            ]
        },
        {
            "x": 6,
            "y": 2,
            "z": 18,
            "elements": [
                "minecraft:stone@6"
            ]
        },
        {
            "x": 14,
            "y": -1,
            "z": 17,
            "elements": [
                "minecraft:iron_block@0"
            ]
        },
        {
            "x": 7,
            "y": 0,
            "z": 18,
            "elements": [
                "minecraft:iron_block@0"
            ]
        },
        {
            "x": -7,
            "y": -3,
            "z": 10,
            "elements": [
                "minecraft:stone_slab@8"
            ]
        },
        {
            "x": 14,
            "y": 0,
            "z": -3,
            "elements": [
                "mets:titanium_block@0"
            ]
        },
        {
            "x": 15,
            "y": 0,
            "z": 24,
            "elements": [
                "minecraft:iron_block@0"
            ]
        },
        {
            "x": -10,
            "y": 0,
            "z": 16,
            "elements": [
                "minecraft:iron_block@0"
            ]
        },
        {
            "x": -9,
            "y": 0,
            "z": 4,
            "elements": [
                "mets:titanium_block@0"
            ]
        },
        {
            "x": 1,
            "y": 3,
            "z": 14,
            "elements": [
                "avaritia:block_resource@0"
            ]
        },
        {
            "x": 12,
            "y": -1,
            "z": 16,
            "elements": [
                "minecraft:iron_block@0"
            ]
        },
        {
            "x": -4,
            "y": 0,
            "z": 16,
            "elements": [
                "mets:titanium_block@0"
            ]
        },
        {
            "x": 7,
            "y": -1,
            "z": 8,
            "elements": [
                "minecraft:stone@6"
            ]
        },
        {
            "x": -7,
            "y": -1,
            "z": 24,
            "elements": [
                "minecraft:iron_block@0"
            ]
        },
        {
            "x": 9,
            "y": 1,
            "z": 3,
            "elements": [
                "minecraft:quartz_stairs@1"
            ]
        },
        {
            "x": 10,
            "y": 0,
            "z": -2,
            "elements": [
                "avaritia:block_resource@0"
            ]
        },
        {
            "x": 8,
            "y": 0,
            "z": 8,
            "elements": [
                "minecraft:iron_block@0"
            ]
        },
        {
            "x": 0,
            "y": 3,
            "z": 3,
            "elements": [
                "minecraft:stone_slab@0"
            ]
        },
        {
            "x": 0,
            "y": 1,
            "z": 5,
            "elements": [
                "avaritia:block_resource@0"
            ]
        },
        {
            "x": 8,
            "y": -1,
            "z": 17,
            "elements": [
                "minecraft:iron_block@0"
            ]
        },
        {
            "x": 7,
            "y": 0,
            "z": 6,
            "elements": [
                "minecraft:iron_block@0"
            ]
        },
        {
            "x": -2,
            "y": 2,
            "z": 14,
            "elements": [
                "avaritia:block_resource@0"
            ]
        },
        {
            "x": -14,
            "y": 1,
            "z": 25,
            "elements": [
                "minecraft:stone_slab@0"
            ]
        },
        {
            "x": 6,
            "y": 0,
            "z": 18,
            "elements": [
                "minecraft:stone@6"
            ]
        },
        {
            "x": 14,
            "y": 0,
            "z": 2,
            "elements": [
                "mets:titanium_block@0"
            ]
        },
        {
            "x": -9,
            "y": -1,
            "z": 3,
            "elements": [
                "minecraft:quartz_stairs@4"
            ]
        },
        {
            "x": 8,
            "y": 0,
            "z": -3,
            "elements": [
                "mets:titanium_block@0"
            ]
        },
        {
            "x": 9,
            "y": 0,
            "z": 24,
            "elements": [
                "mets:titanium_block@0"
            ]
        },
        {
            "x": 7,
            "y": 2,
            "z": 17,
            "elements": [
                "minecraft:stone@6"
            ]
        },
        {
            "x": 4,
            "y": 1,
            "z": 7,
            "elements": [
                "avaritia:block_resource@0"
            ]
        },
        {
            "x": -10,
            "y": 1,
            "z": 10,
            "elements": [
                "minecraft:stone@4"
            ]
        },
        {
            "x": -10,
            "y": -1,
            "z": 15,
            "elements": [
                "mets:titanium_block@0"
            ]
        },
        {
            "x": 2,
            "y": -5,
            "z": 10,
            "elements": [
                "avaritia:block_resource@0"
            ]
        },
        {
            "x": -8,
            "y": -1,
            "z": 10,
            "elements": [
                "minecraft:iron_block@0"
            ]
        },
        {
            "x": 9,
            "y": 1,
            "z": 17,
            "elements": [
                "minecraft:quartz_stairs@1"
            ]
        },
        {
            "x": 9,
            "y": -1,
            "z": 8,
            "elements": [
                "astraladditions:block_marble_wall@0"
            ]
        },
        {
            "x": 3,
            "y": -4,
            "z": 12,
            "elements": [
                "avaritia:block_resource@0"
            ]
        },
        {
            "x": -11,
            "y": 2,
            "z": 21,
            "elements": [
                "avaritia:block_resource@0"
            ]
        },
        {
            "x": -8,
            "y": -1,
            "z": 5,
            "elements": [
                "mets:titanium_block@0"
            ]
        },
        {
            "x": 0,
            "y": 2,
            "z": 18,
            "elements": [
                "minecraft:stone@4"
            ]
        },
        {
            "x": -3,
            "y": -4,
            "z": 11,
            "elements": [
                "avaritia:block_resource@0"
            ]
        },
        {
            "x": 1,
            "y": 3,
            "z": 6,
            "elements": [
                "avaritia:block_resource@0"
            ]
        },
        {
            "x": -8,
            "y": 0,
            "z": 11,
            "elements": [
                "minecraft:iron_block@0"
            ]
        },
        {
            "x": -10,
            "y": 0,
            "z": 21,
            "elements": [
                "avaritia:block_resource@0"
            ]
        },
        {
            "x": 2,
            "y": 1,
            "z": 5,
            "elements": [
                "avaritia:block_resource@0"
            ]
        },
        {
            "x": 5,
            "y": -1,
            "z": 3,
            "elements": [
                "minecraft:iron_block@0"
            ]
        },
        {
            "x": 3,
            "y": 1,
            "z": 18,
            "elements": [
                "minecraft:iron_block@0"
            ]
        },
        {
            "x": -9,
            "y": -1,
            "z": 7,
            "elements": [
                "astraladditions:block_marble_wall@0"
            ]
        },
        {
            "x": -8,
            "y": -1,
            "z": 25,
            "elements": [
                "minecraft:iron_block@0"
            ]
        },
        {
            "x": 6,
            "y": 0,
            "z": 17,
            "elements": [
                "mets:titanium_block@0"
            ]
        },
        {
            "x": -9,
            "y": 1,
            "z": 3,
            "elements": [
                "minecraft:quartz_stairs@0"
            ]
        },
        {
            "x": 11,
            "y": -2,
            "z": 4,
            "elements": [
                "minecraft:iron_block@0"
            ]
        },
        {
            "x": -12,
            "y": -1,
            "z": -1,
            "elements": [
                "avaritia:block_resource@0"
            ]
        },
        {
            "x": 9,
            "y": 0,
            "z": 4,
            "elements": [
                "mets:titanium_block@0"
            ]
        },
        {
            "x": 10,
            "y": -1,
            "z": -6,
            "elements": [
                "mets:titanium_block@0"
            ]
        },
        {
            "x": 11,
            "y": 0,
            "z": 1,
            "elements": [
                "avaritia:block_resource@0"
            ]
        },
        {
            "x": 7,
            "y": 0,
            "z": 9,
            "elements": [
                "mets:titanium_block@0"
            ]
        },
        {
            "x": -8,
            "y": 1,
            "z": 25,
            "elements": [
                "minecraft:iron_block@0"
            ]
        },
        {
            "x": -6,
            "y": -1,
            "z": 0,
            "elements": [
                "minecraft:iron_block@0"
            ]
        },
        {
            "x": -2,
            "y": 4,
            "z": 12,
            "elements": [
                "avaritia:block_resource@0"
            ]
        },
        {
            "x": -3,
            "y": -2,
            "z": 14,
            "elements": [
                "avaritia:block_resource@0"
            ]
        },
        {
            "x": 0,
            "y": -3,
            "z": 14,
            "elements": [
                "avaritia:block_resource@0"
            ]
        },
        {
            "x": 11,
            "y": 0,
            "z": -6,
            "elements": [
                "minecraft:iron_block@0"
            ]
        },
        {
            "x": -8,
            "y": 1,
            "z": 7,
            "elements": [
                "minecraft:iron_block@0"
            ]
        },
        {
            "x": -5,
            "y": 2,
            "z": 11,
            "elements": [
                "avaritia:block_resource@0"
            ]
        },
        {
            "x": -2,
            "y": -1,
            "z": 5,
            "elements": [
                "avaritia:block_resource@0"
            ]
        },
        {
            "x": 1,
            "y": 5,
            "z": 12,
            "elements": [
                "avaritia:block_resource@0"
            ]
        },
        {
            "x": -6,
            "y": 0,
            "z": 11,
            "elements": [
                "appliedenergistics2:smooth_sky_stone_block@0"
            ]
        },
        {
            "x": 11,
            "y": 1,
            "z": -6,
            "elements": [
                "minecraft:stone_slab@0"
            ]
        },
        {
            "x": -6,
            "y": -1,
            "z": 20,
            "elements": [
                "minecraft:iron_block@0"
            ]
        },
        {
            "x": -8,
            "y": 0,
            "z": 7,
            "elements": [
                "minecraft:iron_block@0"
            ]
        },
        {
            "x": 1,
            "y": 1,
            "z": 3,
            "elements": [
                "minecraft:stone@6"
            ]
        },
        {
            "x": -5,
            "y": -2,
            "z": 9,
            "elements": [
                "avaritia:block_resource@0"
            ]
        },
        {
            "x": -12,
            "y": 0,
            "z": 17,
            "elements": [
                "mets:titanium_block@0"
            ]
        },
        {
            "x": 7,
            "y": 0,
            "z": 19,
            "elements": [
                "mets:titanium_block@0"
            ]
        },
        {
            "x": 2,
            "y": 1,
            "z": 2,
            "elements": [
                "minecraft:iron_block@0"
            ]
        },
        {
            "x": -10,
            "y": -1,
            "z": 5,
            "elements": [
                "mets:titanium_block@0"
            ]
        },
        {
            "x": 9,
            "y": 0,
            "z": -5,
            "elements": [
                "minecraft:iron_block@0"
            ]
        },
        {
            "x": 13,
            "y": 0,
            "z": -1,
            "elements": [
                "avaritia:block_resource@0"
            ]
        },
        {
            "x": -15,
            "y": 1,
            "z": 18,
            "elements": [
                "minecraft:iron_block@0"
            ]
        },
        {
            "x": -1,
            "y": 0,
            "z": 4,
            "elements": [
                "appliedenergistics2:smooth_sky_stone_block@0"
            ]
        },
        {
            "x": -14,
            "y": 0,
            "z": 1,
            "elements": [
                "mets:titanium_block@0"
            ]
        },
        {
            "x": -4,
            "y": -1,
            "z": 17,
            "elements": [
                "minecraft:iron_block@0"
            ]
        },
        {
            "x": 2,
            "y": 0,
            "z": 2,
            "elements": [
                "minecraft:iron_block@0"
            ]
        },
        {
            "x": 0,
            "y": 5,
            "z": 10,
            "elements": [
                "avaritia:block_resource@0"
            ]
        },
        {
            "x": -11,
            "y": 2,
            "z": 16,
            "elements": [
                "minecraft:iron_block@0"
            ]
        },
        {
            "x": 7,
            "y": 1,
            "z": 14,
            "elements": [
                "minecraft:iron_block@0"
            ]
        },
        {
            "x": 12,
            "y": 0,
            "z": 20,
            "elements": [
                "avaritia:block_resource@0"
            ]
        },
        {
            "x": -6,
            "y": 0,
            "z": 21,
            "elements": [
                "minecraft:iron_block@0"
            ]
        },
        {
            "x": -16,
            "y": -1,
            "z": 20,
            "elements": [
                "mets:titanium_block@0"
            ]
        },
        {
            "x": -5,
            "y": 0,
            "z": 9,
            "elements": [
                "avaritia:block_resource@0"
            ]
        },
        {
            "x": -11,
            "y": -1,
            "z": 22,
            "elements": [
                "avaritia:block_resource@0"
            ]
        },
        {
            "x": 6,
            "y": 0,
            "z": 11,
            "elements": [
                "appliedenergistics2:smooth_sky_stone_block@0"
            ]
        },
        {
            "x": 6,
            "y": -1,
            "z": 10,
            "elements": [
                "appliedenergistics2:smooth_sky_stone_block@0"
            ]
        },
        {
            "x": -1,
            "y": -1,
            "z": 18,
            "elements": [
                "minecraft:iron_block@0"
            ]
        },
        {
            "x": -5,
            "y": 1,
            "z": 3,
            "elements": [
                "minecraft:iron_block@0"
            ]
        },
        {
            "x": -7,
            "y": -1,
            "z": 3,
            "elements": [
                "minecraft:stone@6"
            ]
        },
        {
            "x": -6,
            "y": 0,
            "z": 17,
            "elements": [
                "mets:titanium_block@0"
            ]
        },
        {
            "x": 7,
            "y": 0,
            "z": 14,
            "elements": [
                "minecraft:iron_block@0"
            ]
        },
        {
            "x": -8,
            "y": 2,
            "z": 9,
            "elements": [
                "minecraft:stone_slab@0"
            ]
        },
        {
            "x": -3,
            "y": 4,
            "z": 9,
            "elements": [
                "avaritia:block_resource@0"
            ]
        },
        {
            "x": 8,
            "y": 0,
            "z": 2,
            "elements": [
                "mets:titanium_block@0"
            ]
        },
        {
            "x": 0,
            "y": 0,
            "z": 18,
            "elements": [
                "minecraft:iron_block@0"
            ]
        },
        {
            "x": -11,
            "y": 1,
            "z": -2,
            "elements": [
                "avaritia:block_resource@0"
            ]
        },
        {
            "x": 6,
            "y": -1,
            "z": 0,
            "elements": [
                "minecraft:iron_block@0"
            ]
        },
        {
            "x": -2,
            "y": 5,
            "z": 10,
            "elements": [
                "avaritia:block_resource@0"
            ]
        },
        {
            "x": -12,
            "y": 0,
            "z": 21,
            "elements": [
                "avaritia:block_resource@0"
            ]
        },
        {
            "x": 2,
            "y": -1,
            "z": 5,
            "elements": [
                "avaritia:block_resource@0"
            ]
        },
        {
            "x": 9,
            "y": -1,
            "z": 7,
            "elements": [
                "astraladditions:block_marble_wall@0"
            ]
        },
        {
            "x": 3,
            "y": 1,
            "z": 19,
            "elements": [
                "astraladditions:block_marble_wall@0"
            ]
        },
        {
            "x": -9,
            "y": 1,
            "z": 17,
            "elements": [
                "minecraft:quartz_stairs@0"
            ]
        },
        {
            "x": -1,
            "y": -2,
            "z": 18,
            "elements": [
                "minecraft:stone_slab@8"
            ]
        },
        {
            "x": -7,
            "y": 0,
            "z": 9,
            "elements": [
                "mets:titanium_block@0"
            ]
        },
        {
            "x": 3,
            "y": 0,
            "z": 19,
            "elements": [
                "mets:titanium_block@0"
            ]
        },
        {
            "x": 10,
            "y": 0,
            "z": 25,
            "elements": [
                "mets:titanium_block@0"
            ]
        },
        {
            "x": -1,
            "y": -1,
            "z": 3,
            "elements": [
                "minecraft:stone@6"
            ]
        },
        {
            "x": 15,
            "y": 0,
            "z": 23,
            "elements": [
                "minecraft:iron_block@0"
            ]
        },
        {
            "x": -2,
            "y": -1,
            "z": 15,
            "elements": [
                "avaritia:block_resource@0"
            ]
        },
        {
            "x": 0,
            "y": 0,
            "z": 17,
            "elements": [
                "mets:titanium_block@0"
            ]
        },
        {
            "x": -10,
            "y": -2,
            "z": 16,
            "elements": [
                "minecraft:iron_block@0"
            ]
        },
        {
            "x": -11,
            "y": 1,
            "z": 22,
            "elements": [
                "avaritia:block_resource@0"
            ]
        },
        {
            "x": 2,
            "y": -1,
            "z": 19,
            "elements": [
                "astraladditions:block_marble_wall@0"
            ]
        },
        {
            "x": -6,
            "y": 0,
            "z": 16,
            "elements": [
                "minecraft:iron_block@0"
            ]
        },
        {
            "x": -8,
            "y": 2,
            "z": 4,
            "elements": [
                "minecraft:stone@6"
            ]
        },
        {
            "x": -7,
            "y": 2,
            "z": 16,
            "elements": [
                "minecraft:stone_slab@0"
            ]
        },
        {
            "x": 7,
            "y": -1,
            "z": 2,
            "elements": [
                "minecraft:iron_block@0"
            ]
        },
        {
            "x": 2,
            "y": 1,
            "z": 15,
            "elements": [
                "avaritia:block_resource@0"
            ]
        },
        {
            "x": 0,
            "y": 1,
            "z": 20,
            "elements": [
                "minecraft:stone@4"
            ]
        },
        {
            "x": 15,
            "y": 1,
            "z": 23,
            "elements": [
                "minecraft:stone_slab@0"
            ]
        },
        {
            "x": 3,
            "y": -1,
            "z": 19,
            "elements": [
                "astraladditions:block_marble_wall@0"
            ]
        },
        {
            "x": 16,
            "y": -1,
            "z": 21,
            "elements": [
                "minecraft:stone_slab@8"
            ]
        },
        {
            "x": -8,
            "y": 1,
            "z": 10,
            "elements": [
                "minecraft:iron_block@0"
            ]
        },
        {
            "x": 2,
            "y": -1,
            "z": 17,
            "elements": [
                "minecraft:stone@6"
            ]
        },
        {
            "x": -1,
            "y": 1,
            "z": 3,
            "elements": [
                "minecraft:stone@6"
            ]
        },
        {
            "x": 0,
            "y": -3,
            "z": 3,
            "elements": [
                "minecraft:stone_slab@8"
            ]
        },
        {
            "x": 11,
            "y": 0,
            "z": -1,
            "elements": [
                "avaritia:block_resource@0"
            ]
        },
        {
            "x": -10,
            "y": 1,
            "z": 15,
            "elements": [
                "mets:titanium_block@0"
            ]
        },
        {
            "x": 9,
            "y": -1,
            "z": 13,
            "elements": [
                "astraladditions:block_marble_wall@0"
            ]
        },
        {
            "x": -6,
            "y": -1,
            "z": 10,
            "elements": [
                "appliedenergistics2:smooth_sky_stone_block@0"
            ]
        },
        {
            "x": -8,
            "y": -2,
            "z": 16,
            "elements": [
                "minecraft:stone@6"
            ]
        },
        {
            "x": 1,
            "y": 0,
            "z": 4,
            "elements": [
                "appliedenergistics2:smooth_sky_stone_block@0"
            ]
        },
        {
            "x": 0,
            "y": -5,
            "z": 10,
            "elements": [
                "avaritia:block_resource@0"
            ]
        },
        {
            "x": -8,
            "y": 0,
            "z": 16,
            "elements": [
                "minecraft:stone@6"
            ]
        },
        {
            "x": 11,
            "y": 1,
            "z": 21,
            "elements": [
                "avaritia:block_resource@0"
            ]
        },
        {
            "x": -5,
            "y": 0,
            "z": 4,
            "elements": [
                "mets:titanium_block@0"
            ]
        },
        {
            "x": 7,
            "y": 1,
            "z": 12,
            "elements": [
                "minecraft:stone@6"
            ]
        },
        {
            "x": -16,
            "y": 0,
            "z": 0,
            "elements": [
                "minecraft:iron_block@0"
            ]
        },
        {
            "x": 3,
            "y": -4,
            "z": 11,
            "elements": [
                "avaritia:block_resource@0"
            ]
        },
        {
            "x": -6,
            "y": 1,
            "z": 20,
            "elements": [
                "minecraft:iron_block@0"
            ]
        },
        {
            "x": 12,
            "y": -1,
            "z": -1,
            "elements": [
                "avaritia:block_resource@0"
            ]
        },
        {
            "x": -16,
            "y": -1,
            "z": 0,
            "elements": [
                "mets:titanium_block@0"
            ]
        },
        {
            "x": -9,
            "y": 1,
            "z": 13,
            "elements": [
                "astraladditions:block_marble_wall@0"
            ]
        },
        {
            "x": -6,
            "y": 0,
            "z": 2,
            "elements": [
                "minecraft:stone@6"
            ]
        },
        {
            "x": -7,
            "y": 1,
            "z": 18,
            "elements": [
                "minecraft:iron_block@0"
            ]
        },
        {
            "x": -7,
            "y": 1,
            "z": 3,
            "elements": [
                "minecraft:stone@6"
            ]
        },
        {
            "x": -4,
            "y": 0,
            "z": 17,
            "elements": [
                "minecraft:iron_block@0"
            ]
        },
        {
            "x": 8,
            "y": 0,
            "z": 7,
            "elements": [
                "minecraft:iron_block@0"
            ]
        },
        {
            "x": -7,
            "y": -1,
            "z": 18,
            "elements": [
                "minecraft:iron_block@0"
            ]
        },
        {
            "x": -5,
            "y": -1,
            "z": 3,
            "elements": [
                "minecraft:iron_block@0"
            ]
        },
        {
            "x": 2,
            "y": 2,
            "z": 14,
            "elements": [
                "avaritia:block_resource@0"
            ]
        },
        {
            "x": -15,
            "y": 0,
            "z": 0,
