{
    "registryname": "orionengine",
    "localizedname": "§c猎户座§4极限内燃引擎",
    "failure-action": "still",
    "requires-blueprint": false,
    "factory-only": true,
    "color": "808080",
    "parts": [
        {
            "x": 0,
            "y": 0,
            "z": 0,

            "elements": [
                "modularmachinery:blockcontroller@2"
            ]
        },
        {
            "x": -3,
            "y": 0,
            "z": 5,
            "elements": [
                "minecraft:iron_block@0"
            ]
        },
        {
            "x": -4,
            "y": -2,
            "z": 10,
            "elements": [
                "extendedcrafting:storage@0"
            ]
        },
        {
            "x": 4,
            "y": -2,
            "z": 28,
            "elements": [
                "minecraft:stone@6"
            ]
        },
        {
            "x": 1,
            "y": -5,
            "z": 19,
            "elements": [
                "minecraft:iron_block@0"
            ]
        },
        {
            "x": -3,
            "y": -3,
            "z": 24,
            "elements": [
                "mets:titanium_block@0"
            ]
        },
        {
            "x": 4,
            "y": -2,
            "z": 17,
            "elements": [
                "minecraft:stained_glass@7"
            ]
        },
        {
            "x": 4,
            "y": -1,
            "z": 28,
            "elements": [
                "minecraft:stone@6"
            ]
        },
        {
            "x": -5,
            "y": 0,
            "z": 15,
            "elements": [
                "minecraft:iron_block@0"
            ]
        },
        {
            "x": -1,
            "y": 3,
            "z": 28,
            "elements": [
                "mets:titanium_block@0"
            ]
        },
        {
            "x": -2,
            "y": 2,
            "z": 5,
            "elements": [
                "mets:titanium_block@0"
            ]
        },
        {
            "x": 1,
            "y": -3,
            "z": 28,
            "elements": [
                "mets:titanium_block@0"
            ]
        },
        {
            "x": 3,
            "y": -1,
            "z": 9,
            "elements": [
                "minecraft:iron_block@0"
            ]
        },
        {
            "x": -1,
            "y": 4,
            "z": 28,
            "elements": [
                "minecraft:stone@6"
            ]
        },
        {
            "x": -1,
            "y": 4,
            "z": 22,
            "elements": [
                "mets:titanium_block@0"
            ]
        },
        {
            "x": 2,
            "y": 0,
            "z": 0,
            "elements": [
                "extendedcrafting:storage@0"
            ]
        },
        {
            "x": 4,
            "y": 1,
            "z": 23,
            "elements": [
                "mets:titanium_block@0"
            ]
        },
        {
            "x": 2,
            "y": 1,
            "z": 17,

            "elements": [
                "advancedrocketry:loader@5"
            ]
        },
        {
            "x": -2,
            "y": -2,
            "z": 0,
            "elements": [
                "mets:titanium_block@0"
            ]
        },
        {
            "x": -1,
            "y": -2,
            "z": 5,
            "elements": [
                "minecraft:stained_glass@7"
            ]
        },
        {
            "x": 4,
            "y": -1,
            "z": 23,
            "elements": [
                "mets:titanium_block@0"
            ]
        },
        {
            "x": -5,
            "y": -1,
            "z": 16,
            "elements": [
                "mets:titanium_block@0"
            ]
        },
        {
            "x": -4,
            "y": 0,
            "z": 10,
            "elements": [
                "extendedcrafting:storage@0"
            ]
        },
        {
            "x": 5,
            "y": 3,
            "z": 18,
            "elements": [
                "minecraft:iron_block@0"
            ]
        },
        {
            "x": 5,
            "y": 1,
            "z": 23,
            "elements": [
                "minecraft:iron_block@0"
            ]
        },
        {
            "x": -1,
            "y": -3,
            "z": 11,
            "elements": [
                "minecraft:iron_block@0"
            ]
        },
        {
            "x": 2,
            "y": 4,
            "z": 23,
            "elements": [
                "mets:titanium_block@0"
            ]
        },
        {
            "x": 4,
            "y": -4,
            "z": 28,
            "elements": [
                "mets:titanium_block@0"
            ]
        },
        {
            "x": 0,
            "y": 2,
            "z": 5,
            "elements": [
                "minecraft:stained_glass@7"
            ]
        },
        {
            "x": -2,
            "y": -3,
            "z": 16,
            "elements": [
                "mets:titanium_block@0"
            ]
        },
        {
            "x": -4,
            "y": 1,
            "z": 21,
            "elements": [
                "mets:titanium_block@0"
            ]
        },
        {
            "x": 5,
            "y": 2,
            "z": 23,
            "elements": [
                "minecraft:iron_block@0"
            ]
        },
        {
            "x": 5,
            "y": 1,
            "z": 18,
            "elements": [
                "mets:titanium_block@0"
            ]
        },
        {
            "x": 4,
            "y": 0,
            "z": 23,
            "elements": [
                "mets:titanium_block@0"
            ]
        },
        {
            "x": -3,
            "y": 0,
            "z": 22,
            "elements": [
                "minecraft:magma@0"
            ]
        },
        {
            "x": -5,
            "y": -1,
            "z": 26,
            "elements": [
                "mets:titanium_block@0"
            ]
        },
        {
            "x": -2,
            "y": -3,
            "z": 26,
            "elements": [
                "minecraft:stained_glass@3"
            ]
        },
        {
            "x": 1,
            "y": -2,
            "z": 5,
            "elements": [
                "minecraft:stained_glass@7"
            ]
        },
        {
            "x": -5,
            "y": -1,
            "z": 19,
            "elements": [
                "minecraft:iron_block@0"
            ]
        },
        {
            "x": -2,
            "y": -4,
            "z": 22,
            "elements": [
                "mets:titanium_block@0"
            ]
        },
        {
            "x": 1,
            "y": 5,
            "z": 16,
            "elements": [
                "mets:titanium_block@0"
            ]
        },
        {
            "x": 2,
            "y": -1,
            "z": 4,
            "elements": [
                "mets:titanium_block@0"
            ]
        },
        {
            "x": -1,
            "y": -4,
            "z": 10,
            "elements": [
                "extendedcrafting:storage@0"
            ]
        },
        {
            "x": -4,
            "y": 3,
            "z": 16,
            "elements": [
                "minecraft:iron_block@0"
            ]
        },
        {
            "x": 4,
            "y": -3,
            "z": 16,
            "elements": [
                "minecraft:iron_block@0"
            ]
        },
        {
            "x": -2,
            "y": -4,
            "z": 26,
            "elements": [
                "minecraft:stone@6"
            ]
        },
        {
            "x": -1,
            "y": 4,
            "z": 12,
            "elements": [
                "mets:titanium_block@0"
            ]
        },
        {
            "x": -2,
            "y": 3,
            "z": 9,
            "elements": [
                "minecraft:iron_block@0"
            ]
        },
        {
            "x": 2,
            "y": 5,
            "z": 28,
            "elements": [
                "mets:titanium_block@0"
            ]
        },
        {
            "x": 1,
            "y": -5,
            "z": 16,
            "elements": [
                "mets:titanium_block@0"
            ]
        },
        {
            "x": 2,
            "y": 2,
            "z": 5,
            "elements": [
                "mets:titanium_block@0"
            ]
        },
        {
            "x": 2,
            "y": 3,
            "z": 19,
            "elements": [
                "minecraft:magma@0"
            ]
        },
        {
            "x": -1,
            "y": 5,
            "z": 19,
            "elements": [
                "minecraft:iron_block@0"
            ]
        },
        {
            "x": 0,
            "y": -3,
            "z": 9,
            "elements": [
                "minecraft:iron_block@0"
            ]
        },
        {
            "x": 2,
            "y": 3,
            "z": 12,
            "elements": [
                "minecraft:iron_block@0"
            ]
        },
        {
            "x": 4,
            "y": 3,
            "z": 23,
            "elements": [
                "minecraft:iron_block@0"
            ]
        },
        {
            "x": -2,
            "y": 0,
            "z": 0,
            "elements": [
                "extendedcrafting:storage@0"
            ]
        },
        {
            "x": -2,
            "y": -4,
            "z": 19,
            "elements": [
                "minecraft:iron_block@0"
            ]
        },
        {
            "x": -1,
            "y": 4,
            "z": 19,
            "elements": [
                "minecraft:iron_block@0"
            ]
        },
        {
            "x": -2,
            "y": -3,
            "z": 19,
            "elements": [
                "minecraft:magma@0"
            ]
        },
        {
            "x": -4,
            "y": 2,
            "z": 22,
            "elements": [
                "mets:titanium_block@0"
            ]
        },
        {
            "x": 3,
            "y": -4,
            "z": 23,
            "elements": [
                "minecraft:iron_block@0"
            ]
        },
        {
            "x": 5,
            "y": 3,
            "z": 17,
            "elements": [
                "minecraft:iron_block@0"
            ]
        },
        {
            "x": 5,
            "y": 0,
            "z": 19,
            "elements": [
                "extendedcrafting:storage@0"
            ]
        },
        {
            "x": -1,
            "y": 1,
            "z": 26,
            "elements": [
                "minecraft:stained_glass@3"
            ]
        },
        {
            "x": -1,
            "y": 5,
            "z": 16,
            "elements": [
                "mets:titanium_block@0"
            ]
        },
        {
            "x": 2,
            "y": 4,
            "z": 27,
            "elements": [
                "minecraft:stone@6"
            ]
        },
        {
            "x": -2,
            "y": 3,
            "z": 16,
            "elements": [
                "mets:titanium_block@0"
            ]
        },
        {
            "x": -3,
            "y": 2,
            "z": 10,
            "elements": [
                "minecraft:iron_block@0"
            ]
        },
        {
            "x": 4,
            "y": -2,
            "z": 12,
            "elements": [
                "mets:titanium_block@0"
            ]
        },
        {
            "x": -1,
            "y": 0,
            "z": 26,
            "elements": [
                "minecraft:stained_glass@3"
            ]
        },
        {
            "x": 0,
            "y": 4,
            "z": 10,
            "elements": [
                "extendedcrafting:storage@0"
            ]
        },
        {
            "x": 5,
            "y": 2,
            "z": 28,
            "elements": [
                "mets:titanium_block@0"
            ]
        },
        {
            "x": -2,
            "y": 5,
            "z": 23,
            "elements": [
                "minecraft:iron_block@0"
            ]
        },
        {
            "x": -3,
            "y": -6,
            "z": 32,
            "elements": [
                "mets:titanium_block@0"
            ]
        },
        {
            "x": -6,
            "y": -4,
            "z": 32,
            "elements": [
                "mets:titanium_block@0"
            ]
        },
        {
            "x": -3,
            "y": -2,
            "z": 15,
            "elements": [
                "mets:titanium_block@0"
            ]
        },
        {
            "x": 2,
            "y": -1,
            "z": 7,
            "elements": [
                "minecraft:stained_glass@7"
            ]
        },
        {
            "x": -3,
            "y": 0,
            "z": 15,
            "elements": [
                "minecraft:iron_block@0"
            ]
        },
        {
            "x": 0,
            "y": 2,
            "z": 7,
            "elements": [
                "minecraft:stained_glass@7"
            ]
        },
        {
            "x": -4,
            "y": -3,
            "z": 29,
            "elements": [
                "extendedcrafting:storage@0"
            ]
        },
        {
            "x": -1,
            "y": -5,
            "z": 29,
            "elements": [
                "minecraft:iron_block@0"
            ]
        },
        {
            "x": 4,
            "y": -2,
            "z": 19,
            "elements": [
                "minecraft:iron_block@0"
            ]
        },
        {
            "x": -2,
            "y": -2,
            "z": 26,
            "elements": [
                "minecraft:stained_glass@3"
            ]
        },
        {
            "x": 3,
            "y": -3,
            "z": 23,
            "elements": [
                "mets:titanium_block@0"
            ]
        },
        {
            "x": -2,
            "y": 4,
            "z": 23,
            "elements": [
                "mets:titanium_block@0"
            ]
        },
        {
            "x": 5,
            "y": 2,
            "z": 12,
            "elements": [
                "mets:titanium_block@0"
            ]
        },
        {
            "x": 4,
            "y": 1,
            "z": 24,
            "elements": [
                "mets:titanium_block@0"
            ]
        },
        {
            "x": 4,
            "y": -1,
            "z": 27,
            "elements": [
                "minecraft:stone@6"
            ]
        },
        {
            "x": 1,
            "y": -5,
            "z": 26,
            "elements": [
                "mets:titanium_block@0"
            ]
        },
        {
            "x": 4,
            "y": -2,
            "z": 27,
            "elements": [
                "minecraft:stone@6"
            ]
        },
        {
            "x": 0,
            "y": -3,
            "z": 16,
            "elements": [
                "extendedcrafting:storage@0"
            ]
        },
        {
            "x": -2,
            "y": -3,
            "z": 18,
            "elements": [
                "mets:titanium_block@0"
            ]
        },
        {
            "x": -3,
            "y": -4,
            "z": 23,
            "elements": [
                "minecraft:iron_block@0"
            ]
        },
        {
            "x": 5,
            "y": 0,
            "z": 24,
            "elements": [
                "extendedcrafting:storage@0"
            ]
        },
        {
            "x": 4,
            "y": 2,
            "z": 24,
            "elements": [
                "mets:titanium_block@0"
            ]
        },
        {
            "x": -4,
            "y": 4,
            "z": 27,
            "elements": [
                "mets:titanium_block@0"
            ]
        },
        {
            "x": 4,
            "y": -3,
            "z": 27,
            "elements": [
                "mets:titanium_block@0"
            ]
        },
        {
            "x": -3,
            "y": -1,
            "z": 16,
            "elements": [
                "mets:titanium_block@0"
            ]
        },
        {
            "x": 3,
            "y": 0,
            "z": 8,
            "elements": [
                "minecraft:iron_block@0"
            ]
        },
        {
            "x": 3,
            "y": 2,
            "z": 10,
            "elements": [
                "minecraft:iron_block@0"
            ]
        },
        {
            "x": -5,
            "y": 1,
            "z": 16,
            "elements": [
                "mets:titanium_block@0"
            ]
        },
        {
            "x": -3,
            "y": -1,
            "z": 32,
            "elements": [
                "environmentalmaterials:alabaster_wall_gray@0"
            ]
        },
        {
            "x": 0,
            "y": 2,
            "z": 8,
            "elements": [
                "minecraft:stained_glass@7"
            ]
        },
        {
            "x": 4,
            "y": -2,
            "z": 13,
            "elements": [
                "minecraft:stained_glass@7"
            ]
        },
        {
            "x": -1,
            "y": 3,
            "z": 18,
            "elements": [
                "mets:titanium_block@0"
            ]
        },
        {
            "x": 4,
            "y": -1,
            "z": 24,
            "elements": [
                "mets:titanium_block@0"
            ]
        },
        {
            "x": 5,
            "y": 2,
            "z": 19,
            "elements": [
                "minecraft:iron_block@0"
            ]
        },
        {
            "x": -5,
            "y": 0,
            "z": 25,
            "elements": [
                "extendedcrafting:storage@0"
            ]
        },
        {
            "x": -4,
            "y": -2,
            "z": 20,
            "elements": [
                "mets:titanium_block@0"
            ]
        },
        {
            "x": 0,
            "y": 3,
            "z": 8,
            "elements": [
                "minecraft:iron_block@0"
            ]
        },
        {
            "x": 3,
            "y": -2,
            "z": 32,
            "elements": [
                "environmentalmaterials:alabaster_wall_gray@0"
            ]
        },
        {
            "x": 5,
            "y": 1,
            "z": 12,
            "elements": [
                "mets:titanium_block@0"
            ]
        },
        {
            "x": -1,
            "y": -2,
            "z": 8,
            "elements": [
                "minecraft:stained_glass@7"
            ]
        },
        {
            "x": -4,
            "y": 1,
            "z": 31,
            "elements": [
                "extendedcrafting:storage@0"
            ]
        },
        {
            "x": 4,
            "y": 0,
            "z": 24,
            "elements": [
                "mets:titanium_block@0"
            ]
        },
        {
            "x": -3,
            "y": -3,
            "z": 23,
            "elements": [
                "mets:titanium_block@0"
            ]
        },
        {
            "x": 5,
            "y": 1,
            "z": 19,
            "elements": [
                "minecraft:iron_block@0"
            ]
        },
        {
            "x": -4,
            "y": 2,
            "z": 18,
            "elements": [
                "minecraft:stained_glass@7"
            ]
        },
        {
            "x": -2,
            "y": 3,
            "z": 32,
            "elements": [
                "environmentalmaterials:alabaster_wall_gray@0"
            ]
        },
        {
            "x": -1,
            "y": -3,
            "z": 8,
            "elements": [
                "minecraft:iron_block@0"
            ]
        },
        {
            "x": -3,
            "y": -2,
            "z": 25,
            "elements": [
                "minecraft:magma@0"
            ]
        },
        {
            "x": 3,
            "y": -3,
            "z": 32,
            "elements": [
                "extendedcrafting:storage@0"
            ]
        },
        {
            "x": -5,
            "y": 2,
            "z": 23,
            "elements": [
                "minecraft:iron_block@0"
            ]
        },
        {
            "x": 0,
            "y": -4,
            "z": 25,
            "elements": [
                "mets:titanium_block@0"
            ]
        },
        {
            "x": -4,
            "y": 1,
            "z": 28,
            "elements": [
                "minecraft:stone@6"
            ]
        },
        {
            "x": 3,
            "y": -1,
            "z": 32,
            "elements": [
                "environmentalmaterials:alabaster_wall_gray@0"
            ]
        },
        {
            "x": 5,
            "y": 1,
            "z": 30,
            "elements": [
                "minecraft:iron_block@0"
            ]
        },
        {
            "x": -2,
            "y": 1,
            "z": 4,
            "elements": [
                "mets:titanium_block@0"
            ]
        },
        {
            "x": 5,
            "y": 2,
            "z": 27,
            "elements": [
                "mets:titanium_block@0"
            ]
        },
        {
            "x": -2,
            "y": -5,
            "z": 28,
            "elements": [
                "mets:titanium_block@0"
            ]
        },
        {
            "x": 3,
            "y": 0,
            "z": 5,
            "elements": [
                "minecraft:iron_block@0"
            ]
        },
        {
            "x": -1,
            "y": 4,
            "z": 15,
            "elements": [
                "minecraft:iron_block@0"
            ]
        },
        {
            "x": 5,
            "y": -1,
            "z": 13,
            "elements": [
                "mets:titanium_block@0"
            ]
        },
        {
            "x": 5,
            "y": 1,
            "z": 13,
            "elements": [
                "mets:titanium_block@0"
            ]
        },
        {
            "x": -1,
            "y": -4,
            "z": 20,
            "elements": [
                "mets:titanium_block@0"
            ]
        },
        {
            "x": 4,
            "y": -4,
            "z": 31,
            "elements": [
                "mets:titanium_block@0"
            ]
        },
        {
            "x": 2,
            "y": 6,
            "z": 32,
            "elements": [
                "mets:titanium_block@0"
            ]
        },
        {
            "x": 4,
            "y": 0,
            "z": 10,
            "elements": [
                "extendedcrafting:storage@0"
            ]
        },
        {
            "x": 1,
            "y": -2,
            "z": 15,
            "elements": [
                "minecraft:iron_block@0"
            ]
        },
        {
            "x": 2,
            "y": -5,
            "z": 21,
            "elements": [
                "minecraft:iron_block@0"
            ]
        },
        {
            "x": -3,
            "y": -2,
            "z": 32,
            "elements": [
                "environmentalmaterials:alabaster_wall_gray@0"
            ]
        },
        {
            "x": 4,
            "y": -2,
            "z": 24,
            "elements": [
                "mets:titanium_block@0"
            ]
        },
        {
            "x": 5,
            "y": 3,
            "z": 30,
            "elements": [
                "minecraft:iron_block@0"
            ]
        },
        {
            "x": 6,
            "y": -4,
            "z": 32,
            "elements": [
                "mets:titanium_block@0"
            ]
        },
        {
            "x": -4,
            "y": -1,
            "z": 21,
            "elements": [
                "mets:titanium_block@0"
            ]
        },
        {
            "x": -3,
            "y": -1,
            "z": 9,
            "elements": [
                "minecraft:iron_block@0"
            ]
        },
        {
            "x": 4,
            "y": 3,
            "z": 32,
            "elements": [
                "mets:titanium_block@0"
            ]
        },
        {
            "x": -4,
            "y": 5,
            "z": 31,
            "elements": [
                "mets:titanium_block@0"
            ]
        },
        {
            "x": -2,
            "y": -1,
            "z": 4,
            "elements": [
                "mets:titanium_block@0"
            ]
        },
        {
            "x": -3,
            "y": -3,
            "z": 32,
            "elements": [
                "extendedcrafting:storage@0"
            ]
        },
        {
            "x": -3,
            "y": 1,
            "z": 9,
            "elements": [
                "minecraft:iron_block@0"
            ]
        },
        {
            "x": -5,
            "y": -2,
            "z": 25,
            "elements": [
                "minecraft:iron_block@0"
            ]
        },
        {
            "x": 4,
            "y": -2,
            "z": 31,
            "elements": [
                "extendedcrafting:storage@0"
            ]
        },
        {
            "x": -2,
            "y": -4,
            "z": 25,
            "elements": [
                "mets:titanium_block@0"
            ]
        },
        {
            "x": 1,
            "y": -4,
            "z": 27,
            "elements": [
                "minecraft:stone@6"
            ]
        },
        {
            "x": 4,
            "y": 3,
            "z": 25,
            "elements": [
                "minecraft:iron_block@0"
            ]
        },
        {
            "x": -1,
            "y": 3,
            "z": 17,
            "elements": [
                "mets:titanium_block@0"
            ]
        },
        {
            "x": -1,
            "y": 2,
            "z": 17,

            "elements": [
                "advancedrocketry:loader@5"
            ]
        },
        {
            "x": -1,
            "y": 4,
            "z": 24,
            "elements": [
                "mets:titanium_block@0"
            ]
        },
        {
            "x": -5,
            "y": -3,
            "z": 31,
            "elements": [
                "mets:titanium_block@0"
            ]
        },
        {
            "x": 0,
            "y": 0,
            "z": 3,
            "elements": [
                "minecraft:iron_block@0"
            ]
        },
        {
            "x": -1,
            "y": 3,
            "z": 32,
            "elements": [
                "environmentalmaterials:alabaster_wall_gray@0"
            ]
        },
        {
            "x": -4,
            "y": 2,
            "z": 15,
            "elements": [
                "minecraft:stained_glass@7"
            ]
        },
        {
            "x": 4,
            "y": -3,
            "z": 32,
            "elements": [
                "mets:titanium_block@0"
            ]
        },
        {
            "x": 2,
            "y": -2,
            "z": 3,
            "elements": [
                "mets:titanium_block@0"
            ]
        },
        {
            "x": -4,
            "y": -5,
            "z": 31,
            "elements": [
                "mets:titanium_block@0"
            ]
        },
        {
            "x": -4,
            "y": 6,
            "z": 32,
            "elements": [
                "mets:titanium_block@0"
            ]
        },
        {
            "x": 3,
            "y": 3,
            "z": 14,
            "elements": [
                "mets:titanium_block@0"
            ]
        },
        {
            "x": -2,
            "y": -4,
            "z": 28,
            "elements": [
                "minecraft:stone@6"
            ]
        },
        {
            "x": -2,
            "y": 4,
            "z": 10,
            "elements": [
                "extendedcrafting:storage@0"
            ]
        },
        {
            "x": -1,
            "y": 0,
            "z": 15,
            "elements": [
                "minecraft:iron_block@0"
            ]
        },
        {
            "x": 4,
            "y": -4,
            "z": 32,
            "elements": [
                "mets:titanium_block@0"
            ]
        },
        {
            "x": -4,
            "y": -3,
            "z": 16,
            "elements": [
                "minecraft:iron_block@0"
            ]
        },
        {
            "x": -5,
            "y": -2,
            "z": 15,
            "elements": [
                "minecraft:iron_block@0"
            ]
        },
        {
            "x": -2,
            "y": 4,
            "z": 24,
            "elements": [
                "mets:titanium_block@0"
            ]
        },
        {
            "x": -3,
            "y": 3,
            "z": 21,
            "elements": [
                "mets:titanium_block@0"
            ]
        },
        {
            "x": 4,
            "y": -2,
            "z": 26,
            "elements": [
                "minecraft:stone@6"
            ]
        },
        {
            "x": 2,
            "y": 3,
            "z": 26,
            "elements": [
                "minecraft:stained_glass@3"
            ]
        },
        {
            "x": 5,
            "y": 4,
            "z": 31,
            "elements": [
                "mets:titanium_block@0"
            ]
        },
        {
            "x": -2,
            "y": -5,
            "z": 27,
            "elements": [
                "mets:titanium_block@0"
            ]
        },
        {
            "x": -1,
            "y": 2,
            "z": 26,
            "elements": [
                "minecraft:stained_glass@3"
            ]
        },
        {
            "x": -5,
            "y": -4,
            "z": 30,
            "elements": [
                "minecraft:iron_block@0"
            ]
        },
        {
            "x": 1,
            "y": -1,
            "z": 26,
            "elements": [
                "minecraft:stained_glass@3"
            ]
        },
        {
            "x": 4,
            "y": -3,
            "z": 18,
            "elements": [
                "minecraft:iron_block@0"
            ]
        },
        {
            "x": 2,
            "y": 1,
            "z": 4,
            "elements": [
                "mets:titanium_block@0"
            ]
        },
        {
            "x": 0,
            "y": 4,
            "z": 14,
            "elements": [
                "minecraft:iron_block@0"
            ]
        },
        {
            "x": 3,
            "y": -3,
            "z": 24,
            "elements": [
                "mets:titanium_block@0"
            ]
        },
        {
            "x": 2,
            "y": -1,
            "z": 14,
            "elements": [
                "mets:titanium_block@0"
            ]
        },
        {
            "x": 2,
            "y": 2,
            "z": 15,
            "elements": [
                "minecraft:iron_block@0"
            ]
        },
        {
            "x": 1,
            "y": 3,
            "z": 11,
            "elements": [
                "minecraft:iron_block@0"
            ]
        },
        {
            "x": -2,
            "y": 0,
            "z": 3,
            "elements": [
                "extendedcrafting:storage@0"
            ]
        },
        {
            "x": 5,
            "y": 0,
            "z": 15,
            "elements": [
                "minecraft:iron_block@0"
            ]
        },
        {
            "x": -4,
            "y": -6,
            "z": 30,
            "elements": [
                "mets:titanium_block@0"
            ]
        },
        {
            "x": -4,
            "y": 0,
            "z": 27,
            "elements": [
                "minecraft:stone@6"
            ]
        },
        {
            "x": -2,
            "y": 6,
            "z": 32,
            "elements": [
                "mets:titanium_block@0"
            ]
        },
        {
            "x": 3,
            "y": -6,
            "z": 32,
            "elements": [
                "mets:titanium_block@0"
            ]
        },
        {
            "x": -1,
            "y": 4,
            "z": 26,
            "elements": [
                "minecraft:stone@6"
            ]
        },
        {
            "x": 5,
            "y": 0,
            "z": 26,
            "elements": [
                "mets:titanium_block@0"
            ]
        },
        {
            "x": 0,
            "y": 5,
            "z": 14,
            "elements": [
                "extendedcrafting:storage@0"
            ]
        },
        {
            "x": -2,
            "y": -4,
            "z": 15,
            "elements": [
                "minecraft:iron_block@0"
            ]
        },
        {
            "x": 0,
            "y": -5,
            "z": 24,
            "elements": [
                "extendedcrafting:storage@0"
            ]
        },
        {
            "x": 5,
            "y": 1,
            "z": 26,
            "elements": [
                "mets:titanium_block@0"
            ]
        },
        {
            "x": -1,
            "y": 5,
            "z": 26,
            "elements": [
                "mets:titanium_block@0"
            ]
        },
        {
            "x": -2,
            "y": -3,
            "z": 9,
            "elements": [
                "minecraft:iron_block@0"
            ]
        },
        {
            "x": -1,
            "y": 5,
            "z": 18,
            "elements": [
                "mets:titanium_block@0"
            ]
        },
        {
            "x": 0,
            "y": 2,
            "z": 16,
            "elements": [
                "extendedcrafting:storage@0"
            ]
        },
        {
            "x": 0,
            "y": 4,
            "z": 20,
            "elements": [
                "mets:titanium_block@0"
            ]
        },
        {
            "x": -1,
            "y": 4,
            "z": 21,
            "elements": [
                "mets:titanium_block@0"
            ]
        },
        {
            "x": 0,
            "y": -3,
            "z": 19,
            "elements": [
                "minecraft:magma@0"
            ]
        },
        {
            "x": 4,
            "y": 2,
            "z": 31,
            "elements": [
                "extendedcrafting:storage@0"
            ]
        },
        {
            "x": 5,
            "y": -1,
            "z": 15,
            "elements": [
                "minecraft:iron_block@0"
            ]
        },
        {
            "x": 0,
            "y": 3,
            "z": 16,
            "elements": [
                "extendedcrafting:storage@0"
            ]
        },
        {
            "x": -3,
            "y": -3,
            "z": 17,
            "elements": [
                "minecraft:iron_block@0"
            ]
        },
        {
            "x": 3,
            "y": 1,
            "z": 16,
            "elements": [
                "mets:titanium_block@0"
            ]
        },
        {
            "x": -4,
            "y": -2,
            "z": 13,
            "elements": [
                "minecraft:stained_glass@7"
            ]
        },
        {
            "x": 3,
            "y": -3,
            "z": 25,
            "elements": [
                "mets:titanium_block@0"
            ]
        },
        {
            "x": 5,
            "y": -1,
            "z": 16,
            "elements": [
                "mets:titanium_block@0"
            ]
        },
        {
            "x": 5,
            "y": -2,
            "z": 15,
            "elements": [
                "minecraft:iron_block@0"
            ]
        },
        {
            "x": -4,
            "y": 1,
            "z": 24,
            "elements": [
                "mets:titanium_block@0"
            ]
        },
        {
            "x": 2,
            "y": 1,
            "z": 14,
            "elements": [
                "mets:titanium_block@0"
            ]
        },
        {
            "x": 1,
            "y": -6,
            "z": 32,
            "elements": [
                "mets:titanium_block@0"
            ]
        },
        {
            "x": -1,
            "y": 3,
            "z": 14,
            "elements": [
                "mets:titanium_block@0"
            ]
        },
        {
            "x": 1,
            "y": 4,
            "z": 11,
            "elements": [
                "mets:titanium_block@0"
            ]
        },
        {
            "x": 4,
            "y": -2,
            "z": 20,
            "elements": [
                "mets:titanium_block@0"
            ]
        },
        {
            "x": 3,
            "y": 1,
            "z": 9,
            "elements": [
                "minecraft:iron_block@0"
            ]
        },
        {
            "x": 0,
            "y": 4,
            "z": 21,
            "elements": [
                "mets:titanium_block@0"
            ]
        },
        {
            "x": 6,
            "y": -1,
            "z": 31,
            "elements": [
                "mets:titanium_block@0"
            ]
        },
        {
            "x": -3,
            "y": 1,
            "z": 12,
            "elements": [
                "minecraft:iron_block@0"
            ]
        },
        {
            "x": -3,
            "y": -5,
            "z": 29,
            "elements": [
                "minecraft:iron_block@0"
            ]
        },
        {
            "x": 4,
            "y": 1,
            "z": 31,
            "elements": [
                "extendedcrafting:storage@0"
            ]
        },
        {
            "x": 0,
            "y": -4,
            "z": 8,
            "elements": [
                "extendedcrafting:storage@0"
            ]
        },
        {
            "x": -2,
            "y": 3,
            "z": 26,
            "elements": [
                "minecraft:stained_glass@3"
            ]
        },
        {
            "x": 4,
            "y": -1,
            "z": 20,
            "elements": [
                "mets:titanium_block@0"
            ]
        },
        {
            "x": 4,
            "y": 0,
            "z": 31,
            "elements": [
                "extendedcrafting:storage@0"
            ]
        },
        {
            "x": -2,
            "y": 3,
            "z": 19,
            "elements": [
                "minecraft:magma@0"
            ]
        },
        {
            "x": -3,
            "y": -4,
            "z": 29,
            "elements": [
                "extendedcrafting:storage@0"
            ]
        },
        {
            "x": 0,
            "y": 4,
            "z": 16,
            "elements": [
                "extendedcrafting:storage@0"
            ]
        },
        {
            "x": -3,
            "y": 1,
            "z": 19,
            "elements": [
                "minecraft:magma@0"
            ]
        },
        {
            "x": -3,
            "y": -1,
            "z": 19,
            "elements": [
                "minecraft:magma@0"
            ]
        },
        {
            "x": 0,
            "y": -3,
            "z": 26,
            "elements": [
                "minecraft:stained_glass@3"
            ]
        },
        {
            "x": -3,
            "y": 2,
            "z": 13,
            "elements": [
                "mets:titanium_block@0"
            ]
        },
        {
            "x": 2,
            "y": -3,
            "z": 19,
            "elements": [
                "minecraft:magma@0"
            ]
        },
        {
            "x": 4,
            "y": 6,
            "z": 31,
            "elements": [
                "mets:titanium_block@0"
            ]
        },
        {
            "x": -3,
            "y": -1,
            "z": 26,
            "elements": [
                "minecraft:stained_glass@3"
            ]
        },
        {
            "x": -5,
            "y": 1,
            "z": 26,
            "elements": [
                "mets:titanium_block@0"
            ]
        },
        {
            "x": -2,
            "y": 2,
            "z": 8,
            "elements": [
                "mets:titanium_block@0"
            ]
        },
        {
            "x": -1,
            "y": -4,
            "z": 13,
            "elements": [
                "minecraft:iron_block@0"
            ]
        },
        {
            "x": 4,
            "y": -1,
            "z": 25,
            "elements": [
                "mets:titanium_block@0"
            ]
        },
        {
            "x": -2,
            "y": -1,
            "z": 14,
            "elements": [
                "mets:titanium_block@0"
            ]
        },
        {
            "x": 1,
            "y": 4,
            "z": 25,
            "elements": [
                "mets:titanium_block@0"
            ]
        },
        {
            "x": -3,
            "y": 1,
            "z": 16,
            "elements": [
                "mets:titanium_block@0"
            ]
        },
        {
            "x": 1,
            "y": -3,
            "z": 14,
            "elements": [
                "mets:titanium_block@0"
            ]
        },
        {
            "x": 0,
            "y": 2,
            "z": 9,
            "elements": [
                "extendedcrafting:storage@0"
            ]
        },
        {
            "x": 2,
            "y": 1,
            "z": 7,
            "elements": [
                "minecraft:stained_glass@7"
            ]
        },
        {
            "x": -2,
            "y": -1,
            "z": 17,

            "elements": [
                "advancedrocketry:loader@5"
            ]
        },
        {
            "x": -3,
            "y": -2,
            "z": 29,
            "elements": [
                "minecraft:iron_block@0"
            ]
        },
        {
            "x": 4,
            "y": 1,
            "z": 25,
            "elements": [
                "mets:titanium_block@0"
            ]
        },
        {
            "x": 0,
            "y": 3,
            "z": 9,
            "elements": [
                "minecraft:iron_block@0"
            ]
        },
        {
            "x": 4,
            "y": -2,
            "z": 21,
            "elements": [
                "mets:titanium_block@0"
            ]
        },
        {
            "x": 0,
            "y": 3,
            "z": 2,
            "elements": [
                "minecraft:iron_block@0"
            ]
        },
        {
            "x": 3,
            "y": -2,
            "z": 25,
            "elements": [
                "minecraft:magma@0"
            ]
        },
        {
            "x": 4,
            "y": 4,
            "z": 31,
            "elements": [
                "mets:titanium_block@0"
            ]
        },
        {
            "x": 2,
            "y": -3,
            "z": 9,
            "elements": [
                "minecraft:iron_block@0"
            ]
        },
        {
            "x": -2,
            "y": -1,
            "z": 7,
            "elements": [
                "minecraft:stained_glass@7"
            ]
        },
        {
            "x": 5,
            "y": -1,
            "z": 12,
            "elements": [
                "mets:titanium_block@0"
            ]
        },
        {
            "x": 2,
            "y": 0,
            "z": 6,
            "elements": [
                "minecraft:stained_glass@7"
            ]
        },
        {
            "x": -1,
            "y": -5,
            "z": 16,
            "elements": [
                "mets:titanium_block@0"
            ]
        },
        {
            "x": 5,
            "y": 0,
            "z": 25,
            "elements": [
                "extendedcrafting:storage@0"
            ]
        },
        {
            "x": 0,
            "y": 3,
            "z": 12,
            "elements": [
                "minecraft:iron_block@0"
            ]
        },
        {
            "x": -1,
            "y": 2,
            "z": 6,
            "elements": [
                "minecraft:stained_glass@7"
            ]
        },
        {
            "x": 3,
            "y": 1,
            "z": 12,
            "elements": [
                "minecraft:iron_block@0"
            ]
        },
        {
            "x": 3,
            "y": -1,
            "z": 25,
            "elements": [
                "minecraft:magma@0"
            ]
        },
        {
            "x": 1,
            "y": 1,
            "z": 26,
            "elements": [
                "minecraft:stained_glass@3"
            ]
        },
        {
            "x": 0,
            "y": 3,
            "z": 19,
            "elements": [
                "minecraft:magma@0"
            ]
        },
        {
            "x": 4,
            "y": -1,
            "z": 21,
            "elements": [
                "mets:titanium_block@0"
            ]
        },
        {
            "x": -5,
            "y": 1,
            "z": 29,
            "elements": [
                "minecraft:iron_block@0"
            ]
        },
        {
            "x": 5,
            "y": 1,
            "z": 25,
            "elements": [
                "minecraft:iron_block@0"
            ]
        },
        {
            "x": 4,
            "y": 5,
            "z": 31,
            "elements": [
                "mets:titanium_block@0"
            ]
        },
        {
            "x": 0,
            "y": 4,
            "z": 9,
            "elements": [
                "extendedcrafting:storage@0"
            ]
        },
        {
            "x": -1,
            "y": -2,
            "z": 9,
            "elements": [
                "extendedcrafting:storage@0"
            ]
        },
        {
            "x": -4,
            "y": -2,
            "z": 23,
            "elements": [
                "mets:titanium_block@0"
            ]
        },
        {
            "x": -2,
            "y": 6,
            "z": 31,
            "elements": [
                "mets:titanium_block@0"
            ]
        },
        {
            "x": 3,
            "y": 2,
            "z": 13,
            "elements": [
                "mets:titanium_block@0"
            ]
        },
        {
            "x": -1,
            "y": 5,
            "z": 25,
            "elements": [
                "minecraft:iron_block@0"
            ]
        },
        {
            "x": 5,
            "y": 0,
            "z": 21,
            "elements": [
                "extendedcrafting:storage@0"
            ]
        },
        {
            "x": 4,
            "y": 3,
            "z": 29,
            "elements": [
                "extendedcrafting:storage@0"
            ]
        },
        {
            "x": 2,
            "y": 4,
            "z": 13,
            "elements": [
                "minecraft:iron_block@0"
            ]
        },
        {
            "x": -1,
            "y": 4,
            "z": 31,
            "elements": [
                "extendedcrafting:storage@0"
            ]
        },
        {
            "x": 1,
            "y": 0,
            "z": 1,
            "elements": [
                "minecraft:iron_block@0"
            ]
        },
        {
            "x": -2,
            "y": -1,
            "z": -1,
            "elements": [
                "mets:titanium_block@0"
            ]
        },
        {
            "x": 2,
            "y": 5,
            "z": 21,
            "elements": [
                "minecraft:iron_block@0"
            ]
        },
        {
            "x": 4,
            "y": 4,
            "z": 29,
            "elements": [
                "extendedcrafting:storage@0"
            ]
        },
        {
            "x": 4,
            "y": -1,
            "z": 14,
            "elements": [
                "extendedcrafting:storage@0"
            ]
        },
        {
            "x": 0,
            "y": 0,
            "z": 13,
            "elements": [
                "mets:titanium_block@0"
            ]
        },
        {
            "x": 5,
            "y": 2,
            "z": 21,
            "elements": [
                "minecraft:iron_block@0"
            ]
        },
        {
            "x": 2,
            "y": -3,
            "z": 12,
            "elements": [
                "minecraft:iron_block@0"
            ]
        },
        {
            "x": -4,
            "y": 2,
            "z": 25,
            "elements": [
                "mets:titanium_block@0"
            ]
        },
        {
            "x": -2,
            "y": 4,
            "z": 31,
            "elements": [
                "extendedcrafting:storage@0"
            ]
        },
        {
            "x": -1,
            "y": 6,
            "z": 31,
            "elements": [
                "mets:titanium_block@0"
            ]
        },
        {
            "x": -1,
            "y": 1,
            "z": 2,
            "elements": [
                "minecraft:iron_block@0"
            ]
        },
        {
            "x": -1,
            "y": -1,
            "z": 2,
            "elements": [
                "minecraft:iron_block@0"
            ]
        },
        {
            "x": 0,
            "y": -3,
            "z": 2,
            "elements": [
                "minecraft:iron_block@0"
            ]
        },
        {
            "x": 4,
            "y": 2,
            "z": 29,
            "elements": [
                "extendedcrafting:storage@0"
            ]
        },
        {
            "x": 4,
            "y": -3,
            "z": 25,
            "elements": [
                "minecraft:iron_block@0"
            ]
        },
        {
            "x": -2,
            "y": 3,
            "z": 29,
            "elements": [
                "minecraft:iron_block@0"
            ]
        },
        {
            "x": 2,
            "y": 4,
            "z": 20,
            "elements": [
                "mets:titanium_block@0"
            ]
        },
        {
            "x": -1,
            "y": -2,
            "z": 16,

            "elements": [
                "advancedrocketry:loader@5"
            ]
        },
        {
            "x": 5,
            "y": -2,
            "z": 21,
            "elements": [
                "minecraft:iron_block@0"
            ]
        },
        {
            "x": 2,
            "y": 0,
            "z": 13,
            "elements": [
                "mets:titanium_block@0"
            ]
        },
        {
            "x": 1,
            "y": 5,
            "z": 29,
            "elements": [
                "minecraft:iron_block@0"
            ]
        },
        {
            "x": 5,
            "y": 5,
            "z": 32,
            "elements": [
                "mets:titanium_block@0"
            ]
        },
        {
            "x": 0,
            "y": 5,
            "z": 21,
            "elements": [
                "extendedcrafting:storage@0"
            ]
        },
        {
            "x": 0,
            "y": 4,
            "z": 13,
            "elements": [
                "minecraft:iron_block@0"
            ]
        },
        {
            "x": 3,
            "y": -4,
            "z": 30,
            "elements": [
                "minecraft:iron_block@0"
            ]
        },
        {
            "x": -3,
            "y": 0,
            "z": 8,
            "elements": [
                "minecraft:iron_block@0"
            ]
        },
        {
            "x": -5,
            "y": -3,
            "z": 17,
            "elements": [
                "minecraft:iron_block@0"
            ]
        },
        {
            "x": 2,
            "y": -3,
            "z": 16,
            "elements": [
                "mets:titanium_block@0"
            ]
        },
        {
            "x": -1,
            "y": 3,
            "z": 25,
            "elements": [
                "minecraft:magma@0"
            ]
        },
        {
            "x": 2,
            "y": -2,
            "z": 13,
            "elements": [
                "mets:titanium_block@0"
            ]
        },
        {
            "x": 3,
            "y": -6,
            "z": 31,
            "elements": [
                "mets:titanium_block@0"
            ]
        },
        {
            "x": -2,
            "y": -4,
            "z": 18,
            "elements": [
                "minecraft:stained_glass@7"
            ]
        },
        {
            "x": 1,
            "y": 1,
            "z": 2,
            "elements": [
                "minecraft:iron_block@0"
            ]
        },
        {
            "x": 0,
            "y": 0,
            "z": 16,
            "elements": [
                "extendedcrafting:storage@0"
            ]
        },
        {
            "x": 3,
            "y": -3,
            "z": 31,
            "elements": [
                "mets:titanium_block@0"
            ]
        },
        {
            "x": -2,
            "y": 5,
            "z": 30,
            "elements": [
                "minecraft:iron_block@0"
            ]
        },
        {
            "x": -1,
            "y": 4,
            "z": 25,
            "elements": [
                "mets:titanium_block@0"
            ]
        },
        {
            "x": 1,
            "y": -1,
            "z": 2,
            "elements": [
                "minecraft:iron_block@0"
            ]
        },
        {
            "x": 3,
            "y": 3,
            "z": 21,
            "elements": [
                "mets:titanium_block@0"
            ]
        },
        {
            "x": -3,
            "y": 0,
            "z": 18,
            "elements": [
                "minecraft:magma@0"
            ]
        },
        {
            "x": 3,
            "y": -4,
            "z": 31,
            "elements": [
                "mets:titanium_block@0"
            ]
        },
        {
            "x": -5,
            "y": 3,
            "z": 17,
            "elements": [
                "minecraft:iron_block@0"
            ]
        },
        {
            "x": 0,
            "y": 3,
            "z": 15,
            "elements": [
                "minecraft:iron_block@0"
            ]
        },
        {
            "x": 2,
            "y": -1,
            "z": -1,
            "elements": [
                "mets:titanium_block@0"
            ]
        },
        {
            "x": -1,
            "y": 2,
            "z": 13,
            "elements": [
                "mets:titanium_block@0"
            ]
        },
        {
            "x": 2,
            "y": 1,
            "z": -1,
            "elements": [
                "mets:titanium_block@0"
            ]
        },
        {
            "x": -3,
            "y": -4,
            "z": 30,
            "elements": [
                "minecraft:iron_block@0"
            ]
        },
        {
            "x": 3,
            "y": -2,
            "z": 29,
            "elements": [
                "minecraft:iron_block@0"
            ]
        },
        {
            "x": 2,
            "y": -4,
            "z": 22,
            "elements": [
                "mets:titanium_block@0"
            ]
        },
        {
            "x": 1,
            "y": -4,
            "z": 13,
            "elements": [
                "minecraft:iron_block@0"
            ]
        },
        {
            "x": -4,
            "y": 0,
            "z": 13,
            "elements": [
                "extendedcrafting:storage@0"
            ]
        },
        {
            "x": 3,
            "y": 0,
            "z": 15,
            "elements": [
                "minecraft:iron_block@0"
            ]
        },
        {
            "x": 0,
            "y": 2,
            "z": 15,
            "elements": [
                "minecraft:iron_block@0"
            ]
        },
        {
            "x": 0,
            "y": -3,
            "z": 12,
            "elements": [
                "minecraft:iron_block@0"
            ]
        },
        {
            "x": -1,
            "y": -2,
            "z": 15,
            "elements": [
                "minecraft:iron_block@0"
            ]
        },
        {
            "x": 2,
            "y": -2,
            "z": 6,
            "elements": [
                "mets:titanium_block@0"
            ]
        },
        {
            "x": 1,
            "y": -4,
            "z": 20,
            "elements": [
                "mets:titanium_block@0"
            ]
        },
        {
            "x": 4,
            "y": 0,
            "z": 29,
            "elements": [
                "environmentalmaterials:alabaster_wall_gray@0"
            ]
        },
        {
            "x": 0,
            "y": 3,
            "z": 22,
            "elements": [
                "minecraft:magma@0"
            ]
        },
        {
            "x": -4,
            "y": 0,
            "z": 20,
            "elements": [
                "mets:titanium_block@0"
            ]
        },
        {
            "x": -2,
            "y": 3,
            "z": 12,
            "elements": [
                "minecraft:iron_block@0"
            ]
        },
        {
            "x": -5,
            "y": 2,
            "z": 30,
            "elements": [
                "minecraft:iron_block@0"
            ]
        },
        {
            "x": 3,
            "y": -5,
            "z": 30,
            "elements": [
                "minecraft:iron_block@0"
            ]
        },
        {
            "x": 0,
            "y": 5,
            "z": 15,
            "elements": [
                "extendedcrafting:storage@0"
            ]
        },
        {
            "x": -4,
            "y": -1,
            "z": 28,
            "elements": [
                "minecraft:stone@6"
            ]
        },
        {
            "x": -1,
            "y": 0,
            "z": 1,
            "elements": [
                "minecraft:iron_block@0"
            ]
        },
        {
            "x": 0,
            "y": 5,
            "z": 22,
            "elements": [
                "extendedcrafting:storage@0"
            ]
        },
        {
            "x": 3,
            "y": 0,
            "z": 22,
            "elements": [
                "minecraft:magma@0"
            ]
        },
        {
            "x": -2,
            "y": 2,
            "z": 1,
            "elements": [
                "mets:titanium_block@0"
            ]
        },
        {
            "x": 4,
            "y": 3,
            "z": 30,
            "elements": [
                "minecraft:iron_block@0"
            ]
        },
        {
            "x": 1,
            "y": 3,
            "z": 17,
            "elements": [
                "mets:titanium_block@0"
            ]
        },
        {
            "x": -2,
            "y": 4,
            "z": 29,
            "elements": [
                "extendedcrafting:storage@0"
            ]
        },
        {
            "x": -4,
            "y": 1,
            "z": 14,
            "elements": [
                "extendedcrafting:storage@0"
            ]
        },
        {
            "x": -2,
            "y": -2,
            "z": 13,
            "elements": [
                "mets:titanium_block@0"
            ]
        },
        {
            "x": -3,
            "y": -1,
            "z": 12,
            "elements": [
                "minecraft:iron_block@0"
            ]
        },
        {
            "x": -5,
            "y": 1,
            "z": 12,
            "elements": [
                "mets:titanium_block@0"
            ]
        },
        {
            "x": 2,
            "y": -4,
            "z": 15,
            "elements": [
                "minecraft:iron_block@0"
            ]
        },
        {
            "x": 0,
            "y": 1,
            "z": 15,
            "elements": [
                "minecraft:iron_block@0"
            ]
        },
        {
            "x": 3,
            "y": -5,
            "z": 29,
            "elements": [
                "minecraft:iron_block@0"
            ]
        },
        {
            "x": 0,
            "y": -3,
            "z": 29,

            "elements": [
                "modularmachinery:blockenergyoutputhatch"
            ]
        },
        {
            "x": -4,
            "y": 0,
            "z": 23,
            "elements": [
                "mets:titanium_block@0"
            ]
        },
        {
            "x": 3,
            "y": -4,
            "z": 29,
            "elements": [
                "extendedcrafting:storage@0"
            ]
        },
        {
            "x": 1,
            "y": -4,
            "z": 23,
            "elements": [
                "mets:titanium_block@0"
            ]
        },
        {
            "x": -2,
            "y": 1,
            "z": -1,
            "elements": [
                "mets:titanium_block@0"
            ]
        },
        {
            "x": -5,
            "y": 1,
            "z": 19,
            "elements": [
                "minecraft:iron_block@0"
            ]
        },
        {
            "x": -1,
            "y": -3,
            "z": 14,
            "elements": [
                "mets:titanium_block@0"
            ]
        },
        {
            "x": 1,
            "y": -2,
            "z": 8,
            "elements": [
                "minecraft:stained_glass@7"
            ]
        },
        {
            "x": -4,
            "y": -1,
            "z": 14,
            "elements": [
                "extendedcrafting:storage@0"
            ]
        },
        {
            "x": -2,
            "y": -4,
            "z": 21,
            "elements": [
                "mets:titanium_block@0"
            ]
        },
        {
            "x": 0,
            "y": -1,
            "z": 17,
            "elements": [
                "minecraft:magma@0"
            ]
        },
        {
            "x": -5,
            "y": 2,
            "z": 27,
            "elements": [
                "mets:titanium_block@0"
            ]
        },
        {
            "x": 1,
            "y": -3,
            "z": 17,
            "elements": [
                "mets:titanium_block@0"
            ]
        },
        {
            "x": -5,
            "y": -1,
            "z": 12,
            "elements": [
                "mets:titanium_block@0"
            ]
        },
        {
            "x": 0,
            "y": -4,
            "z": 18,
            "elements": [
                "extendedcrafting:storage@0"
            ]
        },
        {
            "x": -2,
            "y": 1,
            "z": 7,
            "elements": [
                "minecraft:stained_glass@7"
            ]
        },
        {
            "x": -6,
            "y": -1,
            "z": 31,
            "elements": [
                "mets:titanium_block@0"
            ]
        },
        {
            "x": 5,
            "y": -2,
            "z": 28,
            "elements": [
                "mets:titanium_block@0"
            ]
        },
        {
            "x": -3,
            "y": -6,
            "z": 31,
            "elements": [
                "mets:titanium_block@0"
            ]
        },
        {
            "x": 4,
            "y": 5,
            "z": 30,
            "elements": [
                "minecraft:iron_block@0"
            ]
        },
        {
            "x": -2,
            "y": -2,
            "z": 6,
            "elements": [
                "mets:titanium_block@0"
            ]
        },
        {
            "x": 5,
            "y": 0,
            "z": 22,
            "elements": [
                "extendedcrafting:storage@0"
            ]
        },
        {
            "x": -4,
            "y": 0,
            "z": 6,
            "elements": [
                "extendedcrafting:storage@0"
            ]
        },
        {
            "x": 4,
            "y": -2,
            "z": 23,
            "elements": [
                "mets:titanium_block@0"
            ]
        },
        {
            "x": 4,
            "y": 4,
            "z": 30,
            "elements": [
                "minecraft:iron_block@0"
            ]
        },
        {
            "x": -3,
            "y": -2,
            "z": 18,
            "elements": [
                "mets:titanium_block@0"
            ]
        },
        {
            "x": -3,
            "y": -4,
            "z": 31,
            "elements": [
                "mets:titanium_block@0"
            ]
        },
        {
            "x": -2,
            "y": 1,
            "z": 17,

            "elements": [
                "advancedrocketry:loader@5"
            ]
        },
        {
            "x": -1,
            "y": -5,
            "z": 19,
            "elements": [
                "minecraft:iron_block@0"
            ]
        },
        {
            "x": 2,
            "y": 2,
            "z": 1,
            "elements": [
                "mets:titanium_block@0"
            ]
        },
        {
            "x": -3,
            "y": -3,
            "z": 31,
            "elements": [
                "mets:titanium_block@0"
            ]
        },
        {
            "x": -3,
            "y": 3,
            "z": 14,
            "elements": [
                "mets:titanium_block@0"
            ]
        },
        {
            "x": 3,
            "y": -3,
            "z": 17,
            "elements": [
                "minecraft:iron_block@0"
            ]
        },
        {
            "x": 0,
            "y": 1,
            "z": 14,
            "elements": [
                "mets:titanium_block@0"
            ]
        },
        {
            "x": 2,
            "y": 2,
            "z": 8,
            "elements": [
                "mets:titanium_block@0"
            ]
        },
        {
            "x": -2,
            "y": -3,
            "z": 12,
            "elements": [
                "minecraft:iron_block@0"
            ]
        },
        {
            "x": -5,
            "y": 3,
            "z": 31,
            "elements": [
                "mets:titanium_block@0"
            ]
        },
        {
            "x": -2,
            "y": -5,
            "z": 21,
            "elements": [
                "minecraft:iron_block@0"
            ]
        },
        {
            "x": -3,
            "y": 3,
            "z": 28,
            "elements": [
                "minecraft:stone@6"
            ]
        },
        {
            "x": -3,
            "y": -5,
            "z": 30,
            "elements": [
                "minecraft:iron_block@0"
            ]
        },
        {
            "x": -2,
            "y": 0,
            "z": 6,
            "elements": [
                "minecraft:stained_glass@7"
            ]
        },
        {
            "x": 0,
            "y": -5,
            "z": 17,
            "elements": [
                "extendedcrafting:storage@0"
            ]
        },
        {
            "x": 4,
            "y": -1,
            "z": 22,
            "elements": [
                "mets:titanium_block@0"
            ]
        },
        {
            "x": -1,
            "y": -3,
            "z": 28,
            "elements": [
                "mets:titanium_block@0"
            ]
        },
        {
            "x": 3,
            "y": -2,
            "z": 18,
            "elements": [
                "mets:titanium_block@0"
            ]
        },
        {
            "x": -3,
            "y": -4,
            "z": 27,
            "elements": [
                "mets:titanium_block@0"
            ]
        },
        {
            "x": -4,
            "y": -2,
            "z": 27,
            "elements": [
                "minecraft:stone@6"
            ]
        },
        {
            "x": 4,
            "y": 0,
            "z": 13,
            "elements": [
                "extendedcrafting:storage@0"
            ]
        },
        {
            "x": 3,
            "y": -2,
            "z": 14,
            "elements": [
                "mets:titanium_block@0"
            ]
        },
        {
            "x": 3,
            "y": 3,
            "z": 17,
            "elements": [
                "minecraft:iron_block@0"
            ]
        },
        {
            "x": 1,
            "y": 0,
            "z": 14,
            "elements": [
                "mets:titanium_block@0"
            ]
        },
        {
            "x": 4,
            "y": 4,
            "z": 27,
            "elements": [
                "mets:titanium_block@0"
            ]
        },
        {
            "x": -3,
            "y": 0,
            "z": 24,
            "elements": [
                "minecraft:magma@0"
            ]
        },
        {
            "x": -2,
            "y": 4,
            "z": 13,
            "elements": [
                "minecraft:iron_block@0"
            ]
        },
        {
            "x": 3,
            "y": -1,
            "z": 13,
            "elements": [
                "mets:titanium_block@0"
            ]
        },
        {
            "x": 3,
            "y": -2,
            "z": 9,
            "elements": [
                "minecraft:iron_block@0"
            ]
        },
        {
            "x": -2,
            "y": 3,
            "z": 13,
            "elements": [
                "mets:titanium_block@0"
            ]
        },
        {
            "x": 0,
            "y": -1,
            "z": 0,

            "elements": [
                "modularmachinery:blockmefluidinputbus@0",
                "modularmachinery:blockfluidinputhatch"
            ]
        },
        {
            "x": 0,
            "y": -1,
            "z": 14,
            "elements": [
                "mets:titanium_block@0"
            ]
        },
        {
            "x": 6,
            "y": 0,
            "z": 32,
            "elements": [
                "mets:titanium_block@0"
            ]
        },
        {
            "x": -4,
            "y": -1,
            "z": 10,
            "elements": [
                "extendedcrafting:storage@0"
            ]
        },
        {
            "x": -4,
            "y": -4,
            "z": 29,
            "elements": [
                "extendedcrafting:storage@0"
            ]
        },
        {
            "x": 3,
            "y": 2,
            "z": 17,
            "elements": [
                "mets:titanium_block@0"
            ]
        },
        {
            "x": 0,
            "y": 6,
            "z": 32,
            "elements": [
                "mets:titanium_block@0"
            ]
        },
        {
            "x": -3,
            "y": -3,
            "z": 15,
            "elements": [
                "minecraft:iron_block@0"
            ]
        },
        {
            "x": 3,
            "y": 0,
            "z": 23,
            "elements": [
                "minecraft:magma@0"
            ]
        },
        {
            "x": 6,
            "y": 2,
            "z": 32,
            "elements": [
                "mets:titanium_block@0"
            ]
        },
        {
            "x": 0,
            "y": 3,
            "z": 23,
            "elements": [
                "minecraft:magma@0"
            ]
        },
        {
            "x": 2,
            "y": -4,
            "z": 28,
            "elements": [
                "minecraft:stone@6"
            ]
        },
        {
            "x": 4,
            "y": 2,
            "z": 13,
            "elements": [
                "minecraft:stained_glass@7"
            ]
        },
        {
            "x": 5,
            "y": -1,
            "z": 23,
            "elements": [
                "minecraft:iron_block@0"
            ]
        },
        {
            "x": 6,
            "y": 3,
            "z": 32,
            "elements": [
                "mets:titanium_block@0"
            ]
        },
        {
            "x": 1,
            "y": 5,
            "z": 18,
            "elements": [
                "mets:titanium_block@0"
            ]
        },
        {
            "x": 4,
            "y": 2,
            "z": 27,
            "elements": [
                "minecraft:stone@6"
            ]
        },
        {
            "x": 3,
            "y": 1,
            "z": 32,
            "elements": [
                "environmentalmaterials:alabaster_wall_gray@0"
            ]
        },
        {
            "x": 4,
            "y": 3,
            "z": 18,
            "elements": [
                "minecraft:iron_block@0"
            ]
        },
        {
            "x": -2,
            "y": 1,
            "z": 5,
            "elements": [
                "minecraft:stained_glass@7"
            ]
        },
        {
            "x": 1,
            "y": 1,
            "z": 14,
            "elements": [
                "mets:titanium_block@0"
            ]
        },
        {
            "x": 4,
            "y": 2,
            "z": 28,
            "elements": [
                "minecraft:stone@6"
            ]
        },
        {
            "x": 4,
            "y": 3,
            "z": 27,
            "elements": [
                "mets:titanium_block@0"
            ]
        },
        {
            "x": -4,
            "y": 1,
            "z": 10,
            "elements": [
                "extendedcrafting:storage@0"
            ]
        },
        {
            "x": -6,
            "y": 4,
            "z": 32,
            "elements": [
                "mets:titanium_block@0"
            ]
        },
        {
            "x": -3,
            "y": -1,
            "z": 13,
            "elements": [
                "mets:titanium_block@0"
            ]
        },
        {
            "x": 3,
            "y": 4,
            "z": 23,
            "elements": [
                "minecraft:iron_block@0"
            ]
        },
        {
            "x": -3,
            "y": 2,
            "z": 11,
            "elements": [
                "minecraft:iron_block@0"
            ]
        },
        {
            "x": -2,
            "y": 4,
            "z": 27,
            "elements": [
                "minecraft:stone@6"
            ]
        },
        {
            "x": 5,
            "y": -5,
            "z": 32,
            "elements": [
                "mets:titanium_block@0"
            ]
        },
        {
            "x": -2,
            "y": 0,
            "z": 13,
            "elements": [
                "mets:titanium_block@0"
            ]
        },
        {
            "x": 2,
            "y": -4,
            "z": 27,
            "elements": [
                "minecraft:stone@6"
            ]
        },
        {
            "x": 1,
            "y": 3,
            "z": 14,
            "elements": [
                "mets:titanium_block@0"
            ]
        },
        {
            "x": -4,
            "y": 0,
            "z": 16,
            "elements": [
                "extendedcrafting:storage@0"
            ]
        },
        {
            "x": -2,
            "y": 2,
            "z": 13,
            "elements": [
                "mets:titanium_block@0"
            ]
        },
        {
            "x": 1,
            "y": 3,
            "z": 28,
            "elements": [
                "mets:titanium_block@0"
            ]
        },
        {
            "x": 3,
            "y": -2,
            "z": 28,
            "elements": [
                "mets:titanium_block@0"
            ]
        },
        {
            "x": 1,
            "y": 4,
            "z": 14,
            "elements": [
                "minecraft:iron_block@0"
            ]
        },
        {
            "x": -1,
            "y": -4,
            "z": 11,
            "elements": [
                "mets:titanium_block@0"
            ]
        },
        {
            "x": 3,
            "y": 0,
            "z": 28,
            "elements": [
                "mets:titanium_block@0"
            ]
        },
        {
            "x": -3,
            "y": 4,
            "z": 27,
            "elements": [
                "mets:titanium_block@0"
            ]
        },
        {
            "x": 0,
            "y": -2,
            "z": 6,
            "elements": [
                "minecraft:stained_glass@7"
            ]
        },
        {
            "x": 1,
            "y": 4,
            "z": 28,
            "elements": [
                "minecraft:stone@6"
            ]
        },
        {
            "x": -4,
            "y": 0,
            "z": 21,
            "elements": [
                "mets:titanium_block@0"
            ]
        },
        {
            "x": -3,
            "y": 1,
            "z": 32,
            "elements": [
                "environmentalmaterials:alabaster_wall_gray@0"
            ]
        },
        {
            "x": 0,
            "y": 3,
            "z": 3,
            "elements": [
                "minecraft:iron_block@0"
            ]
        },
        {
            "x": 5,
            "y": -1,
            "z": 18,
            "elements": [
                "mets:titanium_block@0"
            ]
        },
        {
            "x": 0,
            "y": -3,
            "z": 13,
            "elements": [
                "mets:titanium_block@0"
            ]
        },
        {
            "x": 0,
            "y": -5,
            "z": 20,
            "elements": [
                "extendedcrafting:storage@0"
            ]
        },
        {
            "x": 2,
            "y": -4,
            "z": 24,
            "elements": [
                "mets:titanium_block@0"
            ]
        },
        {
            "x": -6,
            "y": 0,
            "z": 32,
            "elements": [
                "mets:titanium_block@0"
            ]
        },
        {
            "x": -2,
            "y": 2,
            "z": 14,
            "elements": [
                "mets:titanium_block@0"
            ]
        },
        {
            "x": -3,
            "y": 4,
            "z": 29,
            "elements": [
                "extendedcrafting:storage@0"
            ]
        },
        {
            "x": 2,
            "y": -3,
            "z": 18,
            "elements": [
                "mets:titanium_block@0"
            ]
        },
        {
            "x": 1,
            "y": 3,
            "z": 12,
            "elements": [
                "minecraft:iron_block@0"
            ]
        },
        {
            "x": -3,
            "y": 1,
            "z": 22,
            "elements": [
                "minecraft:magma@0"
            ]
        },
        {
            "x": -4,
            "y": -3,
            "z": 32,
            "elements": [
                "mets:titanium_block@0"
            ]
        },
        {
            "x": -2,
            "y": 2,
            "z": 9,
            "elements": [
                "extendedcrafting:storage@0"
            ]
        },
        {
            "x": 0,
            "y": -3,
            "z": 28,
            "elements": [
                "mets:titanium_block@0"
            ]
        },
        {
            "x": -1,
            "y": -6,
            "z": 32,
            "elements": [
                "mets:titanium_block@0"
            ]
        },
        {
            "x": -1,
            "y": -3,
            "z": 10,
            "elements": [
                "minecraft:iron_block@0"
            ]
        },
        {
            "x": 0,
            "y": 2,
            "z": 4,
            "elements": [
                "mets:titanium_block@0"
            ]
        },
        {
            "x": 3,
            "y": 0,
            "z": 4,
            "elements": [
                "extendedcrafting:storage@0"
            ]
        },
        {
            "x": 1,
            "y": 2,
            "z": 16,

            "elements": [
                "advancedrocketry:loader@5"
            ]
        },
        {
            "x": 1,
            "y": 2,
            "z": 6,
            "elements": [
                "minecraft:stained_glass@7"
            ]
        },
        {
            "x": -2,
            "y": -2,
            "z": 16,

            "elements": [
                "advancedrocketry:loader@5"
            ]
        },
        {
            "x": -2,
            "y": -3,
            "z": 22,
            "elements": [
                "minecraft:magma@0"
            ]
        },
        {
            "x": -3,
            "y": 0,
            "z": 4,
            "elements": [
                "extendedcrafting:storage@0"
            ]
        },
        {
            "x": -3,
            "y": -2,
            "z": 28,
            "elements": [
                "mets:titanium_block@0"
            ]
        },
        {
            "x": 3,
            "y": 4,
            "z": 27,
            "elements": [
                "mets:titanium_block@0"
            ]
        },
        {
            "x": 2,
            "y": 0,
            "z": 16,
            "elements": [
                "extendedcrafting:storage@0"
            ]
        },
        {
            "x": 0,
            "y": 4,
            "z": 18,
            "elements": [
                "extendedcrafting:storage@0"
            ]
        },
        {
            "x": -6,
            "y": 2,
            "z": 32,
            "elements": [
                "mets:titanium_block@0"
            ]
        },
        {
            "x": 4,
            "y": 2,
            "z": 14,
            "elements": [
                "minecraft:stained_glass@7"
            ]
        },
        {
            "x": -4,
            "y": -2,
            "z": 26,
            "elements": [
                "minecraft:stone@6"
            ]
        },
        {
            "x": 1,
            "y": 3,
            "z": 6,
            "elements": [
                "mets:titanium_block@0"
            ]
        },
        {
            "x": -3,
            "y": -3,
            "z": 20,
            "elements": [
                "mets:titanium_block@0"
            ]
        },
        {
            "x": -6,
            "y": 3,
            "z": 32,
            "elements": [
                "mets:titanium_block@0"
            ]
        },
        {
            "x": 2,
            "y": 1,
            "z": 5,
            "elements": [
                "minecraft:stained_glass@7"
            ]
        },
        {
            "x": 0,
            "y": 3,
            "z": 18,
            "elements": [
                "minecraft:magma@0"
            ]
        },
        {
            "x": 3,
            "y": -4,
            "z": 27,
            "elements": [
                "mets:titanium_block@0"
            ]
        },
        {
            "x": 3,
            "y": 1,
            "z": 18,
            "elements": [
                "mets:titanium_block@0"
            ]
        },
        {
            "x": -3,
            "y": 0,
            "z": 29,

            "elements": [
                "modularmachinery:blockenergyoutputhatch"
            ]
        },
        {
            "x": 0,
            "y": 5,
            "z": 24,
            "elements": [
                "extendedcrafting:storage@0"
            ]
        },
        {
            "x": 0,
            "y": -5,
            "z": 14,
            "elements": [
                "extendedcrafting:storage@0"
            ]
        },
        {
            "x": -3,
            "y": 3,
            "z": 10,
            "elements": [
                "extendedcrafting:storage@0"
            ]
        },
        {
            "x": 3,
            "y": 0,
            "z": 24,
            "elements": [
                "minecraft:magma@0"
            ]
        },
        {
            "x": 1,
            "y": 1,
            "z": 13,
            "elements": [
                "mets:titanium_block@0"
            ]
        },
        {
            "x": -4,
            "y": -1,
            "z": 15,
            "elements": [
                "extendedcrafting:storage@0"
            ]
        },
        {
            "x": 4,
            "y": 0,
            "z": 27,
            "elements": [
                "minecraft:stone@6"
            ]
        },
        {
            "x": -1,
            "y": -5,
            "z": 26,
            "elements": [
                "mets:titanium_block@0"
            ]
        },
        {
            "x": 4,
            "y": 0,
            "z": 12,
            "elements": [
                "extendedcrafting:storage@0"
            ]
        },
        {
            "x": 0,
            "y": -4,
            "z": 14,
            "elements": [
                "minecraft:iron_block@0"
            ]
        },
        {
            "x": -1,
            "y": -3,
            "z": 15,
            "elements": [
                "mets:titanium_block@0"
            ]
        },
        {
            "x": 2,
            "y": -4,
            "z": 29,
            "elements": [
                "extendedcrafting:storage@0"
            ]
        },
        {
            "x": -1,
            "y": 2,
            "z": 16,

            "elements": [
                "advancedrocketry:loader@5"
            ]
        },
        {
            "x": -3,
            "y": -2,
            "z": 14,
            "elements": [
                "mets:titanium_block@0"
            ]
        },
        {
            "x": 2,
            "y": -4,
            "z": 23,
            "elements": [
                "mets:titanium_block@0"
            ]
        },
        {
            "x": 0,
            "y": 3,
            "z": 24,
            "elements": [
                "minecraft:magma@0"
            ]
        },
        {
            "x": -1,
            "y": -3,
            "z": 26,
            "elements": [
                "minecraft:stained_glass@3"
            ]
        },
        {
            "x": 0,
            "y": -2,
            "z": 16,
            "elements": [
                "extendedcrafting:storage@0"
            ]
        },
        {
            "x": 0,
            "y": -4,
            "z": 28,
            "elements": [
                "minecraft:stone@6"
            ]
        },
        {
            "x": 0,
            "y": -3,
            "z": 14,
            "elements": [
                "mets:titanium_block@0"
            ]
        },
        {
            "x": -5,
            "y": 1,
            "z": 14,
            "elements": [
                "mets:titanium_block@0"
            ]
        },
        {
            "x": -2,
            "y": -1,
            "z": 5,
            "elements": [
                "minecraft:stained_glass@7"
            ]
        },
        {
            "x": -1,
            "y": -4,
            "z": 26,
            "elements": [
                "minecraft:stone@6"
            ]
        },
        {
            "x": 6,
            "y": 4,
            "z": 32,
            "elements": [
                "mets:titanium_block@0"
            ]
        },
        {
            "x": 3,
            "y": -2,
            "z": 13,
            "elements": [
                "mets:titanium_block@0"
            ]
        },
        {
            "x": -2,
            "y": 4,
            "z": 16,
            "elements": [
                "minecraft:stained_glass@7"
            ]
        },
        {
            "x": 1,
            "y": 1,
            "z": 3,
            "elements": [
                "minecraft:iron_block@0"
            ]
        },
        {
            "x": -3,
            "y": 2,
            "z": 26,
            "elements": [
                "minecraft:stained_glass@3"
            ]
        },
        {
            "x": 3,
            "y": -3,
            "z": 10,
            "elements": [
                "extendedcrafting:storage@0"
            ]
        },
        {
            "x": 0,
            "y": -5,
            "z": 25,
            "elements": [
                "extendedcrafting:storage@0"
            ]
        },
        {
            "x": -4,
            "y": -2,
            "z": 17,
            "elements": [
                "minecraft:stained_glass@7"
            ]
        },
        {
            "x": -1,
            "y": -1,
            "z": 26,
            "elements": [
                "minecraft:stained_glass@3"
            ]
        },
        {
            "x": -3,
            "y": 0,
            "z": 9,
            "elements": [
                "minecraft:iron_block@0"
            ]
        },
        {
            "x": -3,
            "y": 4,
            "z": 23,
            "elements": [
                "minecraft:iron_block@0"
            ]
        },
        {
            "x": -1,
            "y": -5,
            "z": 18,
            "elements": [
                "mets:titanium_block@0"
            ]
        },
        {
            "x": 0,
            "y": 1,
            "z": 26,
            "elements": [
                "minecraft:stained_glass@3"
            ]
        },
        {
            "x": 5,
            "y": 4,
            "z": 30,
            "elements": [
                "minecraft:iron_block@0"
            ]
        },
        {
            "x": 2,
            "y": 0,
            "z": 2,
            "elements": [
                "extendedcrafting:storage@0"
            ]
        },
        {
            "x": -3,
            "y": 1,
            "z": 17,
            "elements": [
                "mets:titanium_block@0"
            ]
        },
        {
            "x": -2,
            "y": 0,
            "z": 16,
            "elements": [
                "extendedcrafting:storage@0"
            ]
        },
        {
            "x": 1,
            "y": -2,
            "z": 4,
            "elements": [
                "mets:titanium_block@0"
            ]
        },
        {
            "x": 0,
            "y": 0,
            "z": 26,
            "elements": [
                "minecraft:stained_glass@3"
            ]
        },
        {
            "x": -4,
            "y": -1,
            "z": 20,
            "elements": [
                "mets:titanium_block@0"
            ]
        },
        {
            "x": -4,
            "y": 0,
            "z": 31,
            "elements": [
                "extendedcrafting:storage@0"
            ]
        },
        {
            "x": 0,
            "y": -4,
            "z": 9,
            "elements": [
                "extendedcrafting:storage@0"
            ]
        },
        {
            "x": -3,
            "y": -2,
            "z": 9,
            "elements": [
                "minecraft:iron_block@0"
            ]
        },
        {
            "x": 0,
            "y": 4,
            "z": 26,
            "elements": [
                "minecraft:stone@6"
            ]
        },
        {
            "x": 3,
            "y": 2,
            "z": 26,
            "elements": [
                "minecraft:stained_glass@3"
            ]
        },
        {
            "x": -2,
            "y": -5,
            "z": 25,
            "elements": [
                "minecraft:iron_block@0"
            ]
        },
        {
            "x": 1,
            "y": -4,
            "z": 31,
            "elements": [
                "extendedcrafting:storage@0"
            ]
        },
        {
            "x": 5,
            "y": -2,
            "z": 19,
            "elements": [
                "minecraft:iron_block@0"
            ]
        },
        {
            "x": 1,
            "y": 3,
            "z": 10,
            "elements": [
                "minecraft:iron_block@0"
            ]
        },
        {
            "x": -3,
            "y": -3,
            "z": 25,
            "elements": [
                "mets:titanium_block@0"
            ]
        },
        {
            "x": 4,
            "y": 1,
            "z": 10,
            "elements": [
                "extendedcrafting:storage@0"
            ]
        },
        {
            "x": 3,
            "y": 3,
            "z": 19,
            "elements": [
                "minecraft:iron_block@0"
            ]
        },
        {
            "x": 0,
            "y": 5,
            "z": 26,
            "elements": [
                "mets:titanium_block@0"
            ]
        },
        {
            "x": -4,
            "y": 1,
            "z": 25,
            "elements": [
                "mets:titanium_block@0"
            ]
        },
        {
            "x": 5,
            "y": 0,
            "z": 30,
            "elements": [
                "minecraft:iron_block@0"
            ]
        },
        {
            "x": -3,
            "y": 0,
            "z": 23,
            "elements": [
                "minecraft:magma@0"
            ]
        },
        {
            "x": -1,
            "y": -5,
            "z": 23,
            "elements": [
                "minecraft:iron_block@0"
            ]
        },
        {
            "x": -1,
            "y": -2,
            "z": 4,
            "elements": [
                "mets:titanium_block@0"
            ]
        },
        {
            "x": -3,
            "y": 3,
            "z": 20,
            "elements": [
                "mets:titanium_block@0"
            ]
        },
        {
            "x": -1,
            "y": 3,
            "z": 15,
            "elements": [
                "mets:titanium_block@0"
            ]
        },
        {
            "x": -4,
            "y": -3,
            "z": 17,
            "elements": [
                "minecraft:iron_block@0"
            ]
        },
        {
            "x": 0,
            "y": 3,
            "z": 26,
            "elements": [
                "minecraft:stained_glass@3"
            ]
        },
        {
            "x": 5,
            "y": -1,
            "z": 26,
            "elements": [
                "mets:titanium_block@0"
            ]
        },
        {
            "x": -4,
            "y": 4,
            "z": 31,
            "elements": [
                "mets:titanium_block@0"
            ]
        },
        {
            "x": 2,
            "y": -1,
            "z": 5,
            "elements": [
                "minecraft:stained_glass@7"
            ]
        },
        {
            "x": -4,
            "y": -2,
            "z": 21,
            "elements": [
                "mets:titanium_block@0"
            ]
        },
        {
            "x": 3,
            "y": 1,
            "z": 19,
            "elements": [
                "minecraft:magma@0"
            ]
        },
        {
