{
     "registryname": "lightpressurelaunchunit",
    "localizedname": "§e光帆虹吸单元驱动设施",
    "failure-action": "still",
    "requires-blueprint": false,
    "factory-only": true,
    "color": "606060",
    "parts": [
        {
            "x": 0,
            "y": 0,
            "z": 0,

            "elements": [
                "modularmachinery:blockcontroller@2"
            ]
        },
        {
            "x": -8,
            "y": 0,
            "z": 15,
            "elements": [
                "avaritia:block_resource@0"
            ]
        },
        {
            "x": -1,
            "y": 1,
            "z": 28,
            "elements": [
                "contenttweaker:starmachineblock@0"
            ]
        },
        {
            "x": 4,
            "y": -1,
            "z": 17,
            "elements": [
                "appliedenergistics2:smooth_sky_stone_stairs@5"
            ]
        },
        {
            "x": 10,
            "y": -10,
            "z": 18,
            "elements": [
                "mekanism:glowplasticblock@11"
            ]
        },
        {
            "x": 1,
            "y": 1,
            "z": 33,
            "elements": [
                "contenttweaker:starmachineblock@0"
            ]
        },
        {
            "x": -3,
            "y": -4,
            "z": 15,
            "elements": [
                "avaritia:block_resource@0"
            ]
        },
        {
            "x": -1,
            "y": 0,
            "z": 19,
            "elements": [
                "mekanism:glowplasticblock@11"
            ]
        },
        {
            "x": -5,
            "y": -1,
            "z": 21,
            "elements": [
                "actuallyadditions:block_quartz_stair@7"
            ]
        },
        {
            "x": -6,
            "y": -2,
            "z": 15,
            "elements": [
                "minecraft:concrete@7"
            ]
        },
        {
            "x": 10,
            "y": -11,
            "z": 18,
            "elements": [
                "minecraft:stained_glass@4"
            ]
        },
        {
            "x": 1,
            "y": -1,
            "z": 28,
            "elements": [
                "contenttweaker:starmachineblock@0"
            ]
        },
        {
            "x": 1,
            "y": 0,
            "z": 0,
            "elements": [
                "appliedenergistics2:smooth_sky_stone_block@0"
            ]
        },
        {
            "x": 0,
            "y": -1,
            "z": 33,
            "elements": [
                "contenttweaker:starmachineblock@0"
            ]
        },
        {
            "x": -5,
            "y": 0,
            "z": 15,
            "elements": [
                "avaritia:block_resource@0"
            ]
        },
        {
            "x": 1,
            "y": -12,
            "z": 15,
            "elements": [
                "avaritia:block_resource@0"
            ]
        },
        {
            "x": -1,
            "y": 6,
            "z": 17,
            "elements": [
                "appliedenergistics2:smooth_sky_stone_stairs@0"
            ]
        },
        {
            "x": 2,
            "y": 0,
            "z": 22,
            "elements": [
                "avaritia:block_resource@0"
            ]
        },
        {
            "x": -6,
            "y": 2,
            "z": 15,
            "elements": [
                "minecraft:concrete@7"
            ]
        },
        {
            "x": -9,
            "y": -2,
            "z": 15,
            "elements": [
                "avaritia:block_resource@0"
            ]
        },
        {
            "x": 5,
            "y": 1,
            "z": 17,
            "elements": [
                "appliedenergistics2:smooth_sky_stone_stairs@1"
            ]
        },
        {
            "x": 5,
            "y": 0,
            "z": 17,
            "elements": [
                "mekanism:glowplasticblock@11"
            ]
        },
        {
            "x": 7,
            "y": -7,
            "z": 18,
            "elements": [
                "mekanism:glowplasticblock@11"
            ]
        },
        {
            "x": -2,
            "y": -8,
            "z": 15,
            "elements": [
                "avaritia:block_resource@0"
            ]
        },
        {
            "x": -3,
            "y": -6,
            "z": 15,
            "elements": [
                "avaritia:block_resource@0"
            ]
        },
        {
            "x": 10,
            "y": -9,
            "z": 18,
            "elements": [
                "minecraft:stained_glass@4"
            ]
        },
        {
            "x": 2,
            "y": 2,
            "z": 17,
            "elements": [
                "contenttweaker:starmachineblock@0"
            ]
        },
        {
            "x": 7,
            "y": -6,
            "z": 18,
            "elements": [
                "minecraft:stained_glass@4"
            ]
        },
        {
            "x": 1,
            "y": 0,
            "z": 33,
            "elements": [
                "contenttweaker:starmachineblock@0"
            ]
        },
        {
            "x": 2,
            "y": 1,
            "z": 17,
            "elements": [
                "contenttweaker:starmachineblock@0"
            ]
        },
        {
            "x": -6,
            "y": 0,
            "z": 15,
            "elements": [
                "avaritia:block_resource@0"
            ]
        },
        {
            "x": 0,
            "y": -12,
            "z": 15,
            "elements": [
                "minecraft:concrete@7"
            ]
        },
        {
            "x": 5,
            "y": 4,
            "z": 18,
            "elements": [
                "minecraft:stained_glass@4"
            ]
        },
        {
            "x": 1,
            "y": -7,
            "z": 16,
            "elements": [
                "minecraft:concrete@7"
            ]
        },
        {
            "x": -9,
            "y": 2,
            "z": 15,
            "elements": [
                "avaritia:block_resource@0"
            ]
        },
        {
            "x": -1,
            "y": -1,
            "z": 11,
            "elements": [
                "appliedenergistics2:smooth_sky_stone_stairs@4"
            ]
        },
        {
            "x": -8,
            "y": -2,
            "z": 15,
            "elements": [
                "avaritia:block_resource@0"
            ]
        },
        {
            "x": -2,
            "y": -5,
            "z": 16,
            "elements": [
                "minecraft:concrete@7"
            ]
        },
        {
            "x": 0,
            "y": -2,
            "z": 33,
            "elements": [
                "actuallyadditions:block_quartz_slab@1"
            ]
        },
        {
            "x": 5,
            "y": 0,
            "z": 23,
            "elements": [
                "minecraft:stained_glass@4"
            ]
        },
        {
            "x": -5,
            "y": -1,
            "z": 16,
            "elements": [
                "avaritia:block_resource@0"
            ]
        },
        {
            "x": 2,
            "y": 0,
            "z": 17,
            "elements": [
                "minecraft:stained_glass@4"
            ]
        },
        {
            "x": -7,
            "y": 0,
            "z": 15,
            "elements": [
                "avaritia:block_resource@0"
            ]
        },
        {
            "x": -1,
            "y": 0,
            "z": 0,
            "elements": [
                "appliedenergistics2:smooth_sky_stone_block@0"
            ]
        },
        {
            "x": 1,
            "y": 7,
            "z": 16,
            "elements": [
                "minecraft:concrete@7"
            ]
        },
        {
            "x": -1,
            "y": -12,
            "z": 15,
            "elements": [
                "avaritia:block_resource@0"
            ]
        },
        {
            "x": 1,
            "y": -9,
            "z": 16,
            "elements": [
                "minecraft:concrete@7"
            ]
        },
        {
            "x": 5,
            "y": 1,
            "z": 23,
            "elements": [
                "actuallyadditions:block_quartz_slab@0"
            ]
        },
        {
            "x": -8,
            "y": 2,
            "z": 15,
            "elements": [
                "avaritia:block_resource@0"
            ]
        },
        {
            "x": 0,
            "y": -14,
            "z": 15,
            "elements": [
                "avaritia:block_resource@0"
            ]
        },
        {
            "x": 1,
            "y": -1,
            "z": 17,
            "elements": [
                "contenttweaker:starmachineblock@0"
            ]
        },
        {
            "x": 0,
            "y": -1,
            "z": 11,
            "elements": [
                "appliedenergistics2:smooth_sky_stone_block@0"
            ]
        },
        {
            "x": 0,
            "y": 0,
            "z": 5,
            "elements": [
                "minecraft:stone@4"
            ]
        },
        {
            "x": 1,
            "y": -2,
            "z": 17,
            "elements": [
                "contenttweaker:starmachineblock@0"
            ]
        },
        {
            "x": -7,
            "y": -2,
            "z": 15,
            "elements": [
                "avaritia:block_resource@0"
            ]
        },
        {
            "x": -2,
            "y": -3,
            "z": 16,
            "elements": [
                "avaritia:block_resource@0"
            ]
        },
        {
            "x": -4,
            "y": 1,
            "z": 16,
            "elements": [
                "avaritia:block_resource@0"
            ]
        },
        {
            "x": 0,
            "y": 0,
            "z": 43,
            "elements": [
                "minecraft:end_rod@2"
            ]
        },
        {
            "x": 0,
            "y": -1,
            "z": 37,
            "elements": [
                "contenttweaker:starmachineblock@0"
            ]
        },
        {
            "x": 1,
            "y": 5,
            "z": 16,
            "elements": [
                "avaritia:block_resource@0"
            ]
        },
        {
            "x": -3,
            "y": -2,
            "z": 20,
            "elements": [
                "contenttweaker:starmachineblock@0"
            ]
        },
        {
            "x": -5,
            "y": 0,
            "z": 20,
            "elements": [
                "mekanism:glowplasticblock@11"
            ]
        },
        {
            "x": -12,
            "y": 0,
            "z": 15,
            "elements": [
                "minecraft:concrete@7"
            ]
        },
        {
            "x": -12,
            "y": -12,
            "z": 18,
            "elements": [
                "minecraft:stained_glass@4"
            ]
        },
        {
            "x": 0,
            "y": 1,
            "z": 4,
            "elements": [
                "minecraft:end_rod@2"
            ]
        },
        {
            "x": -1,
            "y": -8,
            "z": 15,
            "elements": [
                "minecraft:concrete@7"
            ]
        },
        {
            "x": -1,
            "y": 1,
            "z": 16,
            "elements": [
                "avaritia:block_resource@0"
            ]
        },
        {
            "x": 1,
            "y": -1,
            "z": 16,
            "elements": [
                "avaritia:block_resource@0"
            ]
        },
        {
            "x": 1,
            "y": 0,
            "z": 37,
            "elements": [
                "contenttweaker:starmachineblock@0"
            ]
        },
        {
            "x": 0,
            "y": -1,
            "z": 9,
            "elements": [
                "minecraft:end_rod@2"
            ]
        },
        {
            "x": 8,
            "y": 0,
            "z": 17,
            "elements": [
                "contenttweaker:starmachineblock@0"
            ]
        },
        {
            "x": 0,
            "y": 1,
            "z": 43,
            "elements": [
                "appliedenergistics2:smooth_sky_stone_stairs@7"
            ]
        },
        {
            "x": 0,
            "y": -1,
            "z": 42,
            "elements": [
                "appliedenergistics2:smooth_sky_stone_stairs@3"
            ]
        },
        {
            "x": 1,
            "y": -5,
            "z": 16,
            "elements": [
                "avaritia:block_resource@0"
            ]
        },
        {
            "x": 1,
            "y": 3,
            "z": 16,
            "elements": [
                "avaritia:block_resource@0"
            ]
        },
        {
            "x": -9,
            "y": 0,
            "z": 15,
            "elements": [
                "avaritia:block_resource@0"
            ]
        },
        {
            "x": 0,
            "y": -2,
            "z": 37,
            "elements": [
                "actuallyadditions:block_quartz_slab@1"
            ]
        },
        {
            "x": 2,
            "y": -8,
            "z": 15,
            "elements": [
                "avaritia:block_resource@0"
            ]
        },
        {
            "x": 2,
            "y": 1,
            "z": 16,
            "elements": [
                "avaritia:block_resource@0"
            ]
        },
        {
            "x": -2,
            "y": -1,
            "z": 16,
            "elements": [
                "avaritia:block_resource@0"
            ]
        },
        {
            "x": -1,
            "y": -1,
            "z": 29,
            "elements": [
                "contenttweaker:starmachineblock@0"
            ]
        },
        {
            "x": 0,
            "y": 2,
            "z": 43,
            "elements": [
                "appliedenergistics2:smooth_sky_stone_slab@0"
            ]
        },
        {
            "x": -1,
            "y": -10,
            "z": 15,
            "elements": [
                "avaritia:block_resource@0"
            ]
        },
        {
            "x": 0,
            "y": -1,
            "z": 45,
            "elements": [
                "appliedenergistics2:smooth_sky_stone_stairs@3"
            ]
        },
        {
            "x": 0,
            "y": -2,
            "z": 45,
            "elements": [
                "appliedenergistics2:smooth_sky_stone_slab@8"
            ]
        },
        {
            "x": 7,
            "y": -8,
            "z": 18,
            "elements": [
                "minecraft:stained_glass@4"
            ]
        },
        {
            "x": -2,
            "y": 0,
            "z": 15,
            "elements": [
                "avaritia:block_resource@0"
            ]
        },
        {
            "x": 1,
            "y": 0,
            "z": 34,
            "elements": [
                "minecraft:stained_glass@4"
            ]
        },
        {
            "x": -1,
            "y": 1,
            "z": 26,
            "elements": [
                "contenttweaker:starmachineblock@0"
            ]
        },
        {
            "x": 0,
            "y": -1,
            "z": 23,
            "elements": [
                "minecraft:concrete@7"
            ]
        },
        {
            "x": 5,
            "y": 0,
            "z": 19,
            "elements": [
                "minecraft:end_rod@2"
            ]
        },
        {
            "x": -1,
            "y": 0,
            "z": 5,
            "elements": [
                "appliedenergistics2:smooth_sky_stone_block@0"
            ]
        },
        {
            "x": -1,
            "y": 5,
            "z": 16,
            "elements": [
                "avaritia:block_resource@0"
            ]
        },
        {
            "x": -4,
            "y": -2,
            "z": 15,
            "elements": [
                "minecraft:concrete@7"
            ]
        },
        {
            "x": 1,
            "y": -1,
            "z": 33,
            "elements": [
                "contenttweaker:starmachineblock@0"
            ]
        },
        {
            "x": -1,
            "y": 1,
            "z": 33,
            "elements": [
                "contenttweaker:starmachineblock@0"
            ]
        },
        {
            "x": -1,
            "y": -4,
            "z": 15,
            "elements": [
                "avaritia:block_resource@0"
            ]
        },
        {
            "x": 0,
            "y": 0,
            "z": 10,
            "elements": [
                "mekanism:glowplasticblock@11"
            ]
        },
        {
            "x": -2,
            "y": 3,
            "z": 16,
            "elements": [
                "avaritia:block_resource@0"
            ]
        },
        {
            "x": 1,
            "y": 1,
            "z": 16,
            "elements": [
                "avaritia:block_resource@0"
            ]
        },
        {
            "x": -1,
            "y": 0,
            "z": 26,
            "elements": [
                "minecraft:stained_glass@4"
            ]
        },
        {
            "x": 1,
            "y": 0,
            "z": 23,
            "elements": [
                "minecraft:concrete@7"
            ]
        },
        {
            "x": -3,
            "y": -2,
            "z": 15,
            "elements": [
                "avaritia:block_resource@0"
            ]
        },
        {
            "x": -3,
            "y": 0,
            "z": 15,
            "elements": [
                "avaritia:block_resource@0"
            ]
        },
        {
            "x": 1,
            "y": -1,
            "z": 12,
            "elements": [
                "appliedenergistics2:smooth_sky_stone_stairs@5"
            ]
        },
        {
            "x": -2,
            "y": 5,
            "z": 16,
            "elements": [
                "minecraft:concrete@7"
            ]
        },
        {
            "x": -1,
            "y": 1,
            "z": 12,
            "elements": [
                "appliedenergistics2:smooth_sky_stone_stairs@0"
            ]
        },
        {
            "x": 1,
            "y": 1,
            "z": 23,
            "elements": [
                "minecraft:concrete@7"
            ]
        },
        {
            "x": 2,
            "y": 0,
            "z": 19,
            "elements": [
                "avaritia:block_resource@0"
            ]
        },
        {
            "x": 1,
            "y": -3,
            "z": 16,
            "elements": [
                "avaritia:block_resource@0"
            ]
        },
        {
            "x": -1,
            "y": 3,
            "z": 16,
            "elements": [
                "avaritia:block_resource@0"
            ]
        },
        {
            "x": -1,
            "y": -6,
            "z": 15,
            "elements": [
                "avaritia:block_resource@0"
            ]
        },
        {
            "x": -1,
            "y": 0,
            "z": 12,
            "elements": [
                "minecraft:stained_glass@4"
            ]
        },
        {
            "x": 0,
            "y": -1,
            "z": 16,
            "elements": [
                "avaritia:block_resource@0"
            ]
        },
        {
            "x": -5,
            "y": 2,
            "z": 15,
            "elements": [
                "minecraft:concrete@7"
            ]
        },
        {
            "x": -1,
            "y": 0,
            "z": 33,
            "elements": [
                "contenttweaker:starmachineblock@0"
            ]
        },
        {
            "x": 0,
            "y": -2,
            "z": 23,
            "elements": [
                "minecraft:concrete@7"
            ]
        },
        {
            "x": 8,
            "y": 9,
            "z": 18,
            "elements": [
                "minecraft:stained_glass@4"
            ]
        },
        {
            "x": 0,
            "y": 1,
            "z": 8,
            "elements": [
                "appliedenergistics2:smooth_sky_stone_block@0"
            ]
        },
        {
            "x": -7,
            "y": 8,
            "z": 18,
            "elements": [
                "minecraft:stained_glass@4"
            ]
        },
        {
            "x": 9,
            "y": 1,
            "z": 14,
            "elements": [
                "appliedenergistics2:smooth_sky_stone_block@0"
            ]
        },
        {
            "x": -4,
            "y": 3,
            "z": 18,
            "elements": [
                "minecraft:stained_glass@4"
            ]
        },
        {
            "x": 1,
            "y": -1,
            "z": 18,
            "elements": [
                "minecraft:concrete@7"
            ]
        },
        {
            "x": -2,
            "y": 0,
            "z": 25,
            "elements": [
                "appliedenergistics2:smooth_sky_stone_stairs@0"
            ]
        },
        {
            "x": 11,
            "y": 10,
            "z": 18,
            "elements": [
                "minecraft:stained_glass@4"
            ]
        },
        {
            "x": 0,
            "y": -5,
            "z": 16,
            "elements": [
                "avaritia:block_resource@0"
            ]
        },
        {
            "x": 0,
            "y": -2,
            "z": 32,
            "elements": [
                "actuallyadditions:block_quartz_slab@1"
            ]
        },
        {
            "x": -3,
            "y": -3,
            "z": 16,
            "elements": [
                "minecraft:concrete@7"
            ]
        },
        {
            "x": 5,
            "y": 0,
            "z": 24,
            "elements": [
                "minecraft:stained_glass@4"
            ]
        },
        {
            "x": -2,
            "y": -3,
            "z": 18,
            "elements": [
                "minecraft:stained_glass@4"
            ]
        },
        {
            "x": 0,
            "y": -3,
            "z": 16,
            "elements": [
                "avaritia:block_resource@0"
            ]
        },
        {
            "x": 0,
            "y": -1,
            "z": 39,
            "elements": [
                "appliedenergistics2:smooth_sky_stone_stairs@3"
            ]
        },
        {
            "x": -3,
            "y": -1,
            "z": 16,
            "elements": [
                "avaritia:block_resource@0"
            ]
        },
        {
            "x": 2,
            "y": 0,
            "z": 18,
            "elements": [
                "avaritia:block_resource@0"
            ]
        },
        {
            "x": -5,
            "y": 1,
            "z": 16,
            "elements": [
                "avaritia:block_resource@0"
            ]
        },
        {
            "x": -7,
            "y": 7,
            "z": 18,
            "elements": [
                "mekanism:glowplasticblock@11"
            ]
        },
        {
            "x": -1,
            "y": 10,
            "z": 15,
            "elements": [
                "avaritia:block_resource@0"
            ]
        },
        {
            "x": 8,
            "y": -1,
            "z": 14,
            "elements": [
                "appliedenergistics2:smooth_sky_stone_block@0"
            ]
        },
        {
            "x": -2,
            "y": -2,
            "z": 18,
            "elements": [
                "mekanism:glowplasticblock@11"
            ]
        },
        {
            "x": 5,
            "y": 1,
            "z": 24,
            "elements": [
                "actuallyadditions:block_quartz_slab@0"
            ]
        },
        {
            "x": 8,
            "y": 1,
            "z": 14,
            "elements": [
                "appliedenergistics2:smooth_sky_stone_block@0"
            ]
        },
        {
            "x": 1,
            "y": -1,
            "z": 27,
            "elements": [
                "contenttweaker:starmachineblock@0"
            ]
        },
        {
            "x": -5,
            "y": 0,
            "z": 25,
            "elements": [
                "contenttweaker:starmachineblock@0"
            ]
        },
        {
            "x": -5,
            "y": 0,
            "z": 23,
            "elements": [
                "minecraft:stained_glass@4"
            ]
        },
        {
            "x": -5,
            "y": 1,
            "z": 23,
            "elements": [
                "actuallyadditions:block_quartz_slab@0"
            ]
        },
        {
            "x": -7,
            "y": 6,
            "z": 18,
            "elements": [
                "minecraft:stained_glass@4"
            ]
        },
        {
            "x": -4,
            "y": 4,
            "z": 18,
            "elements": [
                "mekanism:glowplasticblock@11"
            ]
        },
        {
            "x": -13,
            "y": 0,
            "z": 15,
            "elements": [
                "avaritia:block_resource@0"
            ]
        },
        {
            "x": 0,
            "y": -2,
            "z": 39,
            "elements": [
                "appliedenergistics2:smooth_sky_stone_slab@8"
            ]
        },
        {
            "x": -9,
            "y": -1,
            "z": 16,
            "elements": [
                "minecraft:concrete@7"
            ]
        },
        {
            "x": 11,
            "y": 12,
            "z": 18,
            "elements": [
                "minecraft:stained_glass@4"
            ]
        },
        {
            "x": 4,
            "y": -5,
            "z": 18,
            "elements": [
                "minecraft:stained_glass@4"
            ]
        },
        {
            "x": -6,
            "y": -1,
            "z": 16,
            "elements": [
                "avaritia:block_resource@0"
            ]
        },
        {
            "x": -1,
            "y": 8,
            "z": 15,
            "elements": [
                "minecraft:concrete@7"
            ]
        },
        {
            "x": -1,
            "y": 0,
            "z": 18,
            "elements": [
                "minecraft:concrete@7"
            ]
        },
        {
            "x": 1,
            "y": 0,
            "z": 3,
            "elements": [
                "appliedenergistics2:smooth_sky_stone_block@0"
            ]
        },
        {
            "x": -2,
            "y": 1,
            "z": 16,
            "elements": [
                "avaritia:block_resource@0"
            ]
        },
        {
            "x": -2,
            "y": 0,
            "z": 23,
            "elements": [
                "minecraft:concrete@7"
            ]
        },
        {
            "x": 11,
            "y": 11,
            "z": 18,
            "elements": [
                "mekanism:glowplasticblock@11"
            ]
        },
        {
            "x": 4,
            "y": -4,
            "z": 18,
            "elements": [
                "mekanism:glowplasticblock@11"
            ]
        },
        {
            "x": -1,
            "y": 1,
            "z": 31,
            "elements": [
                "contenttweaker:starmachineblock@0"
            ]
        },
        {
            "x": 0,
            "y": 2,
            "z": 36,
            "elements": [
                "actuallyadditions:block_quartz_slab@0"
            ]
        },
        {
            "x": 0,
            "y": 12,
            "z": 14,
            "elements": [
                "appliedenergistics2:smooth_sky_stone_block@0"
            ]
        },
        {
            "x": -1,
            "y": 1,
            "z": 18,
            "elements": [
                "minecraft:concrete@7"
            ]
        },
        {
            "x": -4,
            "y": 0,
            "z": 25,
            "elements": [
                "appliedenergistics2:smooth_sky_stone_stairs@0"
            ]
        },
        {
            "x": -1,
            "y": 6,
            "z": 15,
            "elements": [
                "avaritia:block_resource@0"
            ]
        },
        {
            "x": -1,
            "y": -2,
            "z": 20,
            "elements": [
                "minecraft:concrete@7"
            ]
        },
        {
            "x": -3,
            "y": 0,
            "z": 20,
            "elements": [
                "minecraft:concrete@7"
            ]
        },
        {
            "x": -1,
            "y": 4,
            "z": 15,
            "elements": [
                "avaritia:block_resource@0"
            ]
        },
        {
            "x": -1,
            "y": 2,
            "z": 18,
            "elements": [
                "minecraft:stained_glass@4"
            ]
        },
        {
            "x": -4,
            "y": 5,
            "z": 18,
            "elements": [
                "minecraft:stained_glass@4"
            ]
        },
        {
            "x": 0,
            "y": 11,
            "z": 14,
            "elements": [
                "appliedenergistics2:smooth_sky_stone_block@0"
            ]
        },
        {
            "x": 0,
            "y": -9,
            "z": 16,
            "elements": [
                "avaritia:block_resource@0"
            ]
        },
        {
            "x": -1,
            "y": -1,
            "z": 8,
            "elements": [
                "appliedenergistics2:smooth_sky_stone_stairs@4"
            ]
        },
        {
            "x": -1,
            "y": 1,
            "z": 27,
            "elements": [
                "contenttweaker:starmachineblock@0"
            ]
        },
        {
            "x": -3,
            "y": 2,
            "z": 20,
            "elements": [
                "contenttweaker:starmachineblock@0"
            ]
        },
        {
            "x": 1,
            "y": -2,
            "z": 15,
            "elements": [
                "avaritia:block_resource@0"
            ]
        },
        {
            "x": 0,
            "y": -7,
            "z": 16,
            "elements": [
                "avaritia:block_resource@0"
            ]
        },
        {
            "x": -15,
            "y": 0,
            "z": 15,
            "elements": [
                "avaritia:block_resource@0"
            ]
        },
        {
            "x": 1,
            "y": 1,
            "z": 37,
            "elements": [
                "contenttweaker:starmachineblock@0"
            ]
        },
        {
            "x": 1,
            "y": 0,
            "z": 10,
            "elements": [
                "appliedenergistics2:smooth_sky_stone_block@0"
            ]
        },
        {
            "x": 0,
            "y": 0,
            "z": 8,
            "elements": [
                "minecraft:stone@4"
            ]
        },
        {
            "x": -1,
            "y": 0,
            "z": 27,
            "elements": [
                "contenttweaker:starmachineblock@0"
            ]
        },
        {
            "x": 1,
            "y": -1,
            "z": 24,
            "elements": [
                "avaritia:block_resource@0"
            ]
        },
        {
            "x": -1,
            "y": 2,
            "z": 15,
            "elements": [
                "avaritia:block_resource@0"
            ]
        },
        {
            "x": -2,
            "y": -2,
            "z": 15,
            "elements": [
                "avaritia:block_resource@0"
            ]
        },
        {
            "x": -4,
            "y": 0,
            "z": 15,
            "elements": [
                "avaritia:block_resource@0"
            ]
        },
        {
            "x": 3,
            "y": 0,
            "z": 20,
            "elements": [
                "minecraft:concrete@7"
            ]
        },
        {
            "x": -1,
            "y": -7,
            "z": 16,
            "elements": [
                "minecraft:concrete@7"
            ]
        },
        {
            "x": -7,
            "y": 2,
            "z": 15,
            "elements": [
                "avaritia:block_resource@0"
            ]
        },
        {
            "x": 1,
            "y": 0,
            "z": 24,
            "elements": [
                "avaritia:block_resource@0"
            ]
        },
        {
            "x": 1,
            "y": -4,
            "z": 15,
            "elements": [
                "avaritia:block_resource@0"
            ]
        },
        {
            "x": -1,
            "y": 3,
            "z": 17,
            "elements": [
                "contenttweaker:starmachineblock@0"
            ]
        },
        {
            "x": -1,
            "y": 2,
            "z": 17,
            "elements": [
                "contenttweaker:starmachineblock@0"
            ]
        },
        {
            "x": 12,
            "y": 0,
            "z": 14,
            "elements": [
                "appliedenergistics2:smooth_sky_stone_block@0"
            ]
        },
        {
            "x": 0,
            "y": 0,
            "z": 3,
            "elements": [
                "minecraft:stone@4"
            ]
        },
        {
            "x": -4,
            "y": 2,
            "z": 15,
            "elements": [
                "minecraft:concrete@7"
            ]
        },
        {
            "x": 0,
            "y": 2,
            "z": 46,
            "elements": [
                "appliedenergistics2:smooth_sky_stone_slab@0"
            ]
        },
        {
            "x": 0,
            "y": -1,
            "z": 24,
            "elements": [
                "avaritia:block_resource@0"
            ]
        },
        {
            "x": 0,
            "y": 2,
            "z": 20,
            "elements": [
                "avaritia:block_resource@0"
            ]
        },
        {
            "x": 0,
            "y": 1,
            "z": 11,
            "elements": [
                "appliedenergistics2:smooth_sky_stone_block@0"
            ]
        },
        {
            "x": -9,
            "y": 1,
            "z": 16,
            "elements": [
                "minecraft:concrete@7"
            ]
        },
        {
            "x": 1,
            "y": -1,
            "z": 32,
            "elements": [
                "contenttweaker:starmachineblock@0"
            ]
        },
        {
            "x": 0,
            "y": 0,
            "z": 20,
            "elements": [
                "minecraft:stained_glass@4"
            ]
        },
        {
            "x": 3,
            "y": 3,
            "z": 14,
            "elements": [
                "appliedenergistics2:smooth_sky_stone_block@0"
            ]
        },
        {
            "x": 5,
            "y": 6,
            "z": 18,
            "elements": [
                "minecraft:stained_glass@4"
            ]
        },
        {
            "x": -1,
            "y": 0,
            "z": 15,
            "elements": [
                "avaritia:block_resource@0"
            ]
        },
        {
            "x": 1,
            "y": 1,
            "z": 24,
            "elements": [
                "avaritia:block_resource@0"
            ]
        },
        {
            "x": 1,
            "y": -6,
            "z": 15,
            "elements": [
                "avaritia:block_resource@0"
            ]
        },
        {
            "x": -1,
            "y": 5,
            "z": 17,
            "elements": [
                "appliedenergistics2:smooth_sky_stone_stairs@0"
            ]
        },
        {
            "x": -5,
            "y": -2,
            "z": 15,
            "elements": [
                "minecraft:concrete@7"
            ]
        },
        {
            "x": -1,
            "y": 0,
            "z": 32,
            "elements": [
                "minecraft:stained_glass@4"
            ]
        },
        {
            "x": 0,
            "y": 10,
            "z": 14,
            "elements": [
                "appliedenergistics2:smooth_sky_stone_block@0"
            ]
        },
        {
            "x": 0,
            "y": -1,
            "z": 44,
            "elements": [
                "appliedenergistics2:smooth_sky_stone_stairs@3"
            ]
        },
        {
            "x": 5,
            "y": 5,
            "z": 18,
            "elements": [
                "mekanism:glowplasticblock@11"
            ]
        },
        {
            "x": 3,
            "y": 2,
            "z": 20,
            "elements": [
                "contenttweaker:starmachineblock@0"
            ]
        },
        {
            "x": 2,
            "y": 0,
            "z": 15,
            "elements": [
                "avaritia:block_resource@0"
            ]
        },
        {
            "x": 0,
            "y": -11,
            "z": 16,
            "elements": [
                "minecraft:concrete@7"
            ]
        },
        {
            "x": -6,
            "y": 1,
            "z": 16,
            "elements": [
                "avaritia:block_resource@0"
            ]
        },
        {
            "x": -1,
            "y": -9,
            "z": 16,
            "elements": [
                "minecraft:concrete@7"
            ]
        },
        {
            "x": -1,
            "y": 1,
            "z": 32,
            "elements": [
                "contenttweaker:starmachineblock@0"
            ]
        },
        {
            "x": -1,
            "y": 4,
            "z": 17,
            "elements": [
                "appliedenergistics2:smooth_sky_stone_stairs@0"
            ]
        },
        {
            "x": 0,
            "y": -2,
            "z": 44,
            "elements": [
                "appliedenergistics2:smooth_sky_stone_slab@8"
            ]
        },
        {
            "x": -10,
            "y": 10,
            "z": 18,
            "elements": [
                "mekanism:glowplasticblock@11"
            ]
        },
        {
            "x": 4,
            "y": -2,
            "z": 15,
            "elements": [
                "minecraft:concrete@7"
            ]
        },
        {
            "x": 1,
            "y": -1,
            "z": 26,
            "elements": [
                "contenttweaker:starmachineblock@0"
            ]
        },
        {
            "x": 0,
            "y": -2,
            "z": 25,
            "elements": [
                "actuallyadditions:block_quartz_slab@1"
            ]
        },
        {
            "x": 5,
            "y": -2,
            "z": 14,
            "elements": [
                "appliedenergistics2:smooth_sky_stone_block@0"
            ]
        },
        {
            "x": 0,
            "y": -1,
            "z": 4,
            "elements": [
                "minecraft:end_rod@2"
            ]
        },
        {
            "x": 4,
            "y": -3,
            "z": 18,
            "elements": [
                "minecraft:stained_glass@4"
            ]
        },
        {
            "x": 2,
            "y": 2,
            "z": 18,
            "elements": [
                "mekanism:glowplasticblock@11"
            ]
        },
        {
            "x": -10,
            "y": 0,
            "z": 15,
            "elements": [
                "minecraft:concrete@7"
            ]
        },
        {
            "x": -8,
            "y": -1,
            "z": 16,
            "elements": [
                "minecraft:concrete@7"
            ]
        },
        {
            "x": -10,
            "y": 9,
            "z": 18,
            "elements": [
                "minecraft:stained_glass@4"
            ]
        },
        {
            "x": 1,
            "y": -8,
            "z": 15,
            "elements": [
                "minecraft:concrete@7"
            ]
        },
        {
            "x": -2,
            "y": -6,
            "z": 15,
            "elements": [
                "minecraft:concrete@7"
            ]
        },
        {
            "x": -7,
            "y": 1,
            "z": 16,
            "elements": [
                "minecraft:concrete@7"
            ]
        },
        {
            "x": 5,
            "y": 0,
            "z": 15,
            "elements": [
                "avaritia:block_resource@0"
            ]
        },
        {
            "x": 2,
            "y": 2,
            "z": 15,
            "elements": [
                "avaritia:block_resource@0"
            ]
        },
        {
            "x": 1,
            "y": 0,
            "z": 25,
            "elements": [
                "contenttweaker:starmachineblock@0"
            ]
        },
        {
            "x": 2,
            "y": 1,
            "z": 18,
            "elements": [
                "minecraft:stained_glass@4"
            ]
        },
        {
            "x": 0,
            "y": -2,
            "z": 38,
            "elements": [
                "appliedenergistics2:smooth_sky_stone_slab@8"
            ]
        },
        {
            "x": 0,
            "y": -2,
            "z": 24,
            "elements": [
                "actuallyadditions:block_quartz_stair@7"
            ]
        },
        {
            "x": -2,
            "y": -4,
            "z": 15,
            "elements": [
                "minecraft:concrete@7"
            ]
        },
        {
            "x": 0,
            "y": -1,
            "z": 38,
            "elements": [
                "appliedenergistics2:smooth_sky_stone_stairs@3"
            ]
        },
        {
            "x": 1,
            "y": 0,
            "z": 32,
            "elements": [
                "minecraft:stained_glass@4"
            ]
        },
        {
            "x": -1,
            "y": 0,
            "z": 28,
            "elements": [
                "minecraft:stained_glass@4"
            ]
        },
        {
            "x": -6,
            "y": 0,
            "z": 20,
            "elements": [
                "contenttweaker:starmachineblock@0"
            ]
        },
        {
            "x": 2,
            "y": -2,
            "z": 20,
            "elements": [
                "actuallyadditions:block_quartz_stair@5"
            ]
        },
        {
            "x": 8,
            "y": 7,
            "z": 18,
            "elements": [
                "minecraft:stained_glass@4"
            ]
        },
        {
            "x": -7,
            "y": -1,
            "z": 16,
            "elements": [
                "minecraft:concrete@7"
            ]
        },
        {
            "x": -1,
            "y": 0,
            "z": 3,
            "elements": [
                "appliedenergistics2:smooth_sky_stone_block@0"
            ]
        },
        {
            "x": 6,
            "y": 2,
            "z": 14,
            "elements": [
                "appliedenergistics2:smooth_sky_stone_block@0"
            ]
        },
        {
            "x": 5,
            "y": 0,
            "z": 18,
            "elements": [
                "minecraft:end_rod@3"
            ]
        },
        {
            "x": 2,
            "y": 4,
            "z": 15,
            "elements": [
                "minecraft:concrete@7"
            ]
        },
        {
            "x": 2,
            "y": 6,
            "z": 15,
            "elements": [
                "minecraft:concrete@7"
            ]
        },
        {
            "x": 0,
            "y": 0,
            "z": 46,
            "elements": [
                "minecraft:end_rod@3"
            ]
        },
        {
            "x": -10,
            "y": 11,
            "z": 18,
            "elements": [
                "minecraft:stained_glass@4"
            ]
        },
        {
            "x": 0,
            "y": 1,
            "z": 21,
            "elements": [
                "mekanism:glowplasticblock@11"
            ]
        },
        {
            "x": 1,
            "y": -10,
            "z": 15,
            "elements": [
                "avaritia:block_resource@0"
            ]
        },
        {
            "x": 1,
            "y": 1,
            "z": 32,
            "elements": [
                "contenttweaker:starmachineblock@0"
            ]
        },
        {
            "x": 8,
            "y": 8,
            "z": 18,
            "elements": [
                "mekanism:glowplasticblock@11"
            ]
        },
        {
            "x": -8,
            "y": 1,
            "z": 16,
            "elements": [
                "minecraft:concrete@7"
            ]
        },
        {
            "x": 1,
            "y": 1,
            "z": 11,
            "elements": [
                "appliedenergistics2:smooth_sky_stone_stairs@1"
            ]
        },
        {
            "x": 2,
            "y": 3,
            "z": 18,
            "elements": [
                "minecraft:stained_glass@4"
            ]
        },
        {
            "x": 0,
            "y": 0,
            "z": 45,
            "elements": [
                "minecraft:end_rod@2"
            ]
        },
        {
            "x": 0,
            "y": 2,
            "z": 16,
            "elements": [
                "avaritia:block_resource@0"
            ]
        },
        {
            "x": 1,
            "y": -1,
            "z": 7,
            "elements": [
                "appliedenergistics2:smooth_sky_stone_stairs@5"
            ]
        },
        {
            "x": 0,
            "y": 2,
            "z": 41,
            "elements": [
                "appliedenergistics2:smooth_sky_stone_slab@0"
            ]
        },
        {
            "x": 5,
            "y": -2,
            "z": 16,
            "elements": [
                "minecraft:concrete@7"
            ]
        },
        {
            "x": 2,
            "y": -5,
            "z": 14,
            "elements": [
                "appliedenergistics2:smooth_sky_stone_block@0"
            ]
        },
        {
            "x": 5,
            "y": -1,
            "z": 15,
            "elements": [
                "avaritia:block_resource@0"
            ]
        },
        {
            "x": 3,
            "y": 0,
            "z": 16,
            "elements": [
                "avaritia:block_resource@0"
            ]
        },
        {
            "x": 0,
            "y": 3,
            "z": 16,
            "elements": [
                "avaritia:block_resource@0"
            ]
        },
        {
            "x": 3,
            "y": 1,
            "z": 16,
            "elements": [
                "avaritia:block_resource@0"
            ]
        },
        {
            "x": 0,
            "y": -9,
            "z": 17,
            "elements": [
                "contenttweaker:starmachineblock@0"
            ]
        },
        {
            "x": 0,
            "y": 0,
            "z": 41,
            "elements": [
                "minecraft:end_rod@2"
            ]
        },
        {
            "x": -4,
            "y": 1,
            "z": 17,
            "elements": [
                "appliedenergistics2:smooth_sky_stone_stairs@0"
            ]
        },
        {
            "x": 5,
            "y": -2,
            "z": 15,
            "elements": [
                "minecraft:concrete@7"
            ]
        },
        {
            "x": 5,
            "y": -1,
            "z": 16,
            "elements": [
                "avaritia:block_resource@0"
            ]
        },
        {
            "x": 6,
            "y": 1,
            "z": 15,
            "elements": [
                "avaritia:block_resource@0"
            ]
        },
        {
            "x": -1,
            "y": -1,
            "z": 12,
            "elements": [
                "appliedenergistics2:smooth_sky_stone_stairs@4"
            ]
        },
        {
            "x": -3,
            "y": 2,
            "z": 16,
            "elements": [
                "avaritia:block_resource@0"
            ]
        },
        {
            "x": -4,
            "y": -4,
            "z": 18,
            "elements": [
                "mekanism:glowplasticblock@11"
            ]
        },
        {
            "x": 2,
            "y": -2,
            "z": 16,
            "elements": [
                "avaritia:block_resource@0"
            ]
        },
        {
            "x": 2,
            "y": 0,
            "z": 21,
            "elements": [
                "avaritia:block_resource@0"
            ]
        },
        {
            "x": 0,
            "y": 5,
            "z": 16,
            "elements": [
                "avaritia:block_resource@0"
            ]
        },
        {
            "x": 6,
            "y": 0,
            "z": 16,
            "elements": [
                "avaritia:block_resource@0"
            ]
        },
        {
            "x": 6,
            "y": 1,
            "z": 16,
            "elements": [
                "avaritia:block_resource@0"
            ]
        },
        {
            "x": -3,
            "y": 3,
            "z": 16,
            "elements": [
                "minecraft:concrete@7"
            ]
        },
        {
            "x": 0,
            "y": 1,
            "z": 41,
            "elements": [
                "appliedenergistics2:smooth_sky_stone_stairs@7"
            ]
        },
        {
            "x": -5,
            "y": -1,
            "z": 24,
            "elements": [
                "actuallyadditions:block_quartz_slab@1"
            ]
        },
        {
            "x": 2,
            "y": -1,
            "z": 16,
            "elements": [
                "avaritia:block_resource@0"
            ]
        },
        {
            "x": 6,
            "y": 0,
            "z": 15,
            "elements": [
                "avaritia:block_resource@0"
            ]
        },
        {
            "x": -5,
            "y": -1,
            "z": 17,
            "elements": [
                "appliedenergistics2:smooth_sky_stone_stairs@4"
            ]
        },
        {
            "x": 0,
            "y": 4,
            "z": 16,
            "elements": [
                "avaritia:block_resource@0"
            ]
        },
        {
            "x": 0,
            "y": 2,
            "z": 47,
            "elements": [
                "appliedenergistics2:smooth_sky_stone_slab@0"
            ]
        },
        {
            "x": -1,
            "y": 0,
            "z": 21,
            "elements": [
                "mekanism:glowplasticblock@11"
            ]
        },
        {
            "x": -3,
            "y": -1,
            "z": 19,
            "elements": [
                "contenttweaker:starmachineblock@0"
            ]
        },
        {
            "x": 0,
            "y": 7,
            "z": 16,
            "elements": [
                "avaritia:block_resource@0"
            ]
        },
        {
            "x": 5,
            "y": 0,
            "z": 20,
            "elements": [
                "mekanism:glowplasticblock@11"
            ]
        },
        {
            "x": 9,
            "y": 1,
            "z": 15,
            "elements": [
                "minecraft:concrete@7"
            ]
        },
        {
            "x": -1,
            "y": 1,
            "z": 7,
            "elements": [
                "appliedenergistics2:smooth_sky_stone_stairs@0"
            ]
        },
        {
            "x": -3,
            "y": 0,
            "z": 16,
            "elements": [
                "avaritia:block_resource@0"
            ]
        },
        {
            "x": 6,
            "y": 3,
            "z": 15,
            "elements": [
                "avaritia:block_resource@0"
            ]
        },
        {
            "x": -6,
            "y": 2,
            "z": 16,
            "elements": [
                "minecraft:concrete@7"
            ]
        },
        {
            "x": 0,
            "y": 1,
            "z": 47,
            "elements": [
                "appliedenergistics2:smooth_sky_stone_stairs@7"
            ]
        },
        {
            "x": 5,
            "y": 1,
            "z": 20,
            "elements": [
                "contenttweaker:starmachineblock@0"
            ]
        },
        {
            "x": 0,
            "y": 1,
            "z": 12,
            "elements": [
                "appliedenergistics2:smooth_sky_stone_block@0"
            ]
        },
        {
            "x": 1,
            "y": 0,
            "z": 36,
            "elements": [
                "minecraft:stained_glass@4"
            ]
        },
        {
            "x": 0,
            "y": 1,
            "z": 2,
            "elements": [
                "appliedenergistics2:smooth_sky_stone_block@0"
            ]
        },
        {
            "x": -6,
            "y": -6,
            "z": 18,
            "elements": [
                "mekanism:glowplasticblock@11"
            ]
        },
        {
            "x": -1,
            "y": -3,
            "z": 16,
            "elements": [
                "avaritia:block_resource@0"
            ]
        },
        {
            "x": 4,
            "y": 0,
            "z": 25,
            "elements": [
                "appliedenergistics2:smooth_sky_stone_stairs@1"
            ]
        },
        {
            "x": 9,
            "y": 0,
            "z": 15,
            "elements": [
                "avaritia:block_resource@0"
            ]
        },
        {
            "x": 4,
            "y": -1,
            "z": 25,
            "elements": [
                "contenttweaker:starmachineblock@0"
            ]
        },
        {
            "x": 6,
            "y": 2,
            "z": 15,
            "elements": [
                "minecraft:concrete@7"
            ]
        },
        {
            "x": 1,
            "y": 1,
            "z": 36,
            "elements": [
                "contenttweaker:starmachineblock@0"
            ]
        },
        {
            "x": 0,
            "y": 1,
            "z": 19,
            "elements": [
                "mekanism:glowplasticblock@11"
            ]
        },
        {
            "x": 1,
            "y": 0,
            "z": 8,
            "elements": [
                "appliedenergistics2:smooth_sky_stone_block@0"
            ]
        },
        {
            "x": -3,
            "y": 1,
            "z": 16,
            "elements": [
                "avaritia:block_resource@0"
            ]
        },
        {
            "x": 0,
            "y": 6,
            "z": 16,
            "elements": [
                "avaritia:block_resource@0"
            ]
        },
        {
            "x": 0,
            "y": -1,
            "z": 19,
            "elements": [
                "mekanism:glowplasticblock@11"
            ]
        },
        {
            "x": 0,
            "y": 1,
            "z": 9,
            "elements": [
                "minecraft:end_rod@2"
            ]
        },
        {
            "x": -1,
            "y": -4,
            "z": 16,
            "elements": [
                "avaritia:block_resource@0"
            ]
        },
        {
            "x": -2,
            "y": -1,
            "z": 17,
            "elements": [
                "contenttweaker:starmachineblock@0"
            ]
        },
        {
            "x": 0,
            "y": 9,
            "z": 16,
            "elements": [
                "avaritia:block_resource@0"
            ]
        },
        {
            "x": 4,
            "y": 1,
            "z": 25,
            "elements": [
                "contenttweaker:starmachineblock@0"
            ]
        },
        {
            "x": -4,
            "y": -2,
            "z": 16,
            "elements": [
                "minecraft:concrete@7"
            ]
        },
        {
            "x": -1,
            "y": 1,
            "z": 17,
            "elements": [
                "contenttweaker:starmachineblock@0"
            ]
        },
        {
            "x": 6,
            "y": 1,
            "z": 20,
            "elements": [
                "actuallyadditions:block_quartz_stair@1"
            ]
        },
        {
            "x": 5,
            "y": 0,
            "z": 25,
            "elements": [
                "contenttweaker:starmachineblock@0"
            ]
        },
        {
            "x": 3,
            "y": 3,
            "z": 16,
            "elements": [
                "minecraft:concrete@7"
            ]
        },
        {
            "x": -1,
            "y": -5,
            "z": 16,
            "elements": [
                "avaritia:block_resource@0"
            ]
        },
        {
            "x": -7,
            "y": -6,
            "z": 18,
            "elements": [
                "minecraft:stained_glass@4"
            ]
        },
        {
            "x": 8,
            "y": -1,
            "z": 15,
            "elements": [
                "minecraft:concrete@7"
            ]
        },
        {
            "x": 3,
            "y": -1,
            "z": 25,
            "elements": [
                "contenttweaker:starmachineblock@0"
            ]
        },
        {
            "x": -4,
            "y": -1,
            "z": 16,
            "elements": [
                "avaritia:block_resource@0"
            ]
        },
        {
            "x": 0,
            "y": 8,
            "z": 16,
            "elements": [
                "avaritia:block_resource@0"
            ]
        },
        {
            "x": 1,
            "y": 1,
            "z": 26,
            "elements": [
                "contenttweaker:starmachineblock@0"
            ]
        },
        {
            "x": 12,
            "y": 0,
            "z": 16,
            "elements": [
                "minecraft:concrete@7"
            ]
        },
        {
            "x": -1,
            "y": -6,
            "z": 16,
            "elements": [
                "avaritia:block_resource@0"
            ]
        },
        {
            "x": 0,
            "y": -2,
            "z": 36,
            "elements": [
                "actuallyadditions:block_quartz_slab@1"
            ]
        },
        {
            "x": 6,
            "y": 0,
            "z": 20,
            "elements": [
                "contenttweaker:starmachineblock@0"
            ]
        },
        {
            "x": 8,
            "y": -2,
            "z": 15,
            "elements": [
                "avaritia:block_resource@0"
            ]
        },
        {
            "x": -1,
            "y": 1,
            "z": 24,
            "elements": [
                "avaritia:block_resource@0"
            ]
        },
        {
            "x": 5,
            "y": 1,
            "z": 25,
            "elements": [
                "actuallyadditions:block_quartz_slab@0"
            ]
        },
        {
            "x": 3,
            "y": 2,
            "z": 16,
            "elements": [
                "avaritia:block_resource@0"
            ]
        },
        {
            "x": 0,
            "y": 15,
            "z": 15,
            "elements": [
                "avaritia:block_resource@0"
            ]
        },
        {
            "x": 2,
            "y": 0,
            "z": 25,
            "elements": [
                "appliedenergistics2:smooth_sky_stone_stairs@1"
            ]
        },
        {
            "x": 1,
            "y": 1,
            "z": 31,
            "elements": [
                "contenttweaker:starmachineblock@0"
            ]
        },
        {
            "x": 5,
            "y": 0,
            "z": 21,
            "elements": [
                "minecraft:stained_glass@4"
            ]
        },
        {
            "x": -5,
            "y": -4,
            "z": 18,
            "elements": [
                "minecraft:stained_glass@4"
            ]
        },
        {
            "x": -6,
            "y": 6,
            "z": 18,
            "elements": [
                "mekanism:glowplasticblock@11"
            ]
        },
        {
            "x": 1,
            "y": 0,
            "z": 1,

            "elements": [
                "modularmachinery:blockinputbus",
                "modularmachinery:blockmeiteminputbus",
                "modularmachinery:blockmepatternprovider@0"
            ]
        },
        {
            "x": 1,
            "y": 0,
            "z": 31,
            "elements": [
                "contenttweaker:starmachineblock@0"
            ]
        },
        {
            "x": -3,
            "y": 2,
            "z": 18,
            "elements": [
                "minecraft:stained_glass@4"
            ]
        },
        {
            "x": -1,
            "y": 0,
            "z": 8,
            "elements": [
                "appliedenergistics2:smooth_sky_stone_block@0"
            ]
        },
        {
            "x": 0,
            "y": -1,
            "z": 2,
            "elements": [
                "appliedenergistics2:smooth_sky_stone_block@0"
            ]
        },
        {
            "x": -1,
            "y": -1,
            "z": 36,
            "elements": [
                "contenttweaker:starmachineblock@0"
            ]
        },
        {
            "x": -2,
            "y": -1,
            "z": 25,
            "elements": [
                "contenttweaker:starmachineblock@0"
            ]
        },
        {
            "x": 5,
            "y": 1,
            "z": 21,
            "elements": [
                "actuallyadditions:block_quartz_stair@3"
            ]
        },
        {
            "x": 10,
            "y": 11,
            "z": 18,
            "elements": [
                "minecraft:stained_glass@4"
            ]
        },
        {
            "x": 0,
            "y": 0,
            "z": 13,
            "elements": [
                "minecraft:stone@4"
            ]
        },
        {
            "x": -12,
            "y": 0,
            "z": 16,
            "elements": [
                "minecraft:concrete@7"
            ]
        },
        {
            "x": 0,
            "y": 2,
            "z": 45,
            "elements": [
                "appliedenergistics2:smooth_sky_stone_slab@0"
            ]
        },
        {
            "x": 2,
            "y": 1,
            "z": 25,
            "elements": [
                "contenttweaker:starmachineblock@0"
            ]
        },
        {
            "x": -1,
            "y": 0,
            "z": 25,
            "elements": [
                "contenttweaker:starmachineblock@0"
            ]
        },
        {
            "x": -9,
            "y": 10,
            "z": 18,
            "elements": [
                "minecraft:stained_glass@4"
            ]
        },
        {
            "x": 2,
            "y": 5,
            "z": 14,
            "elements": [
                "appliedenergistics2:smooth_sky_stone_block@0"
            ]
        },
        {
            "x": -12,
            "y": 12,
            "z": 18,
            "elements": [
                "minecraft:stained_glass@4"
            ]
        },
        {
            "x": 0,
            "y": 0,
            "z": 36,
            "elements": [
                "mekanism:glowplasticblock@11"
            ]
        },
        {
            "x": 0,
            "y": 0,
            "z": 9,
            "elements": [
                "minecraft:stone@4"
            ]
        },
        {
            "x": -5,
            "y": -6,
            "z": 18,
            "elements": [
                "minecraft:stained_glass@4"
            ]
        },
        {
            "x": -1,
            "y": 1,
            "z": 2,
            "elements": [
                "appliedenergistics2:smooth_sky_stone_stairs@0"
            ]
        },
        {
            "x": -1,
            "y": 1,
            "z": 25,
            "elements": [
                "contenttweaker:starmachineblock@0"
            ]
        },
        {
            "x": 1,
            "y": -1,
            "z": 25,
            "elements": [
                "contenttweaker:starmachineblock@0"
            ]
        },
        {
            "x": -1,
            "y": -1,
            "z": 2,
            "elements": [
                "appliedenergistics2:smooth_sky_stone_stairs@4"
            ]
        },
        {
            "x": 1,
            "y": 1,
            "z": 30,
            "elements": [
                "contenttweaker:starmachineblock@0"
            ]
        },
        {
            "x": -1,
            "y": -2,
            "z": 16,
            "elements": [
                "avaritia:block_resource@0"
            ]
        },
        {
            "x": 3,
            "y": 0,
            "z": 21,
            "elements": [
                "minecraft:end_rod@5"
            ]
        },
        {
            "x": -9,
            "y": 8,
            "z": 18,
            "elements": [
                "minecraft:stained_glass@4"
            ]
        },
        {
            "x": -1,
            "y": 9,
            "z": 14,
            "elements": [
                "appliedenergistics2:smooth_sky_stone_block@0"
            ]
        },
        {
            "x": 2,
            "y": -5,
            "z": 16,
            "elements": [
                "minecraft:concrete@7"
            ]
        },
        {
            "x": 1,
            "y": 0,
            "z": 30,
            "elements": [
                "minecraft:stained_glass@4"
            ]
        },
        {
            "x": 5,
            "y": -1,
            "z": 21,
            "elements": [
                "actuallyadditions:block_quartz_stair@7"
            ]
        },
        {
            "x": 2,
            "y": -3,
            "z": 16,
            "elements": [
                "avaritia:block_resource@0"
            ]
        },
        {
            "x": -1,
            "y": -1,
            "z": 16,
            "elements": [
                "avaritia:block_resource@0"
            ]
        },
        {
            "x": -8,
            "y": -8,
            "z": 18,
            "elements": [
                "mekanism:glowplasticblock@11"
            ]
        },
        {
            "x": 2,
            "y": -6,
            "z": 16,
            "elements": [
                "minecraft:concrete@7"
            ]
        },
        {
            "x": 2,
            "y": 2,
            "z": 20,
            "elements": [
                "actuallyadditions:block_quartz_stair@1"
            ]
        },
        {
            "x": -6,
            "y": -1,
            "z": 17,
            "elements": [
                "appliedenergistics2:smooth_sky_stone_stairs@4"
            ]
        },
        {
            "x": 2,
            "y": 0,
            "z": 20,
            "elements": [
                "avaritia:block_resource@0"
            ]
        },
        {
            "x": 1,
            "y": 1,
            "z": 2,
            "elements": [
                "appliedenergistics2:smooth_sky_stone_stairs@1"
            ]
        },
        {
            "x": 0,
            "y": 0,
            "z": 16,
            "elements": [
                "mekanism:glowplasticblock@11"
            ]
        },
        {
            "x": -1,
            "y": 7,
            "z": 14,
            "elements": [
                "appliedenergistics2:smooth_sky_stone_block@0"
            ]
        },
        {
            "x": 1,
            "y": -1,
            "z": 2,
            "elements": [
                "appliedenergistics2:smooth_sky_stone_stairs@5"
            ]
        },
        {
            "x": 0,
            "y": -1,
            "z": 31,
            "elements": [
                "contenttweaker:starmachineblock@0"
            ]
        },
        {
            "x": 11,
            "y": 0,
            "z": 14,
            "elements": [
                "appliedenergistics2:smooth_sky_stone_block@0"
            ]
        },
        {
            "x": 2,
            "y": 1,
            "z": 20,
            "elements": [
                "minecraft:concrete@7"
            ]
        },
        {
            "x": 0,
            "y": 1,
            "z": 16,
            "elements": [
                "avaritia:block_resource@0"
            ]
        },
        {
            "x": 0,
            "y": -2,
            "z": 31,
            "elements": [
                "actuallyadditions:block_quartz_slab@1"
            ]
        },
        {
            "x": -5,
            "y": 1,
            "z": 17,
            "elements": [
                "appliedenergistics2:smooth_sky_stone_stairs@0"
            ]
        },
        {
            "x": 0,
            "y": 1,
            "z": 44,
            "elements": [
                "appliedenergistics2:smooth_sky_stone_stairs@7"
            ]
        },
        {
            "x": 7,
            "y": -1,
            "z": 14,
            "elements": [
                "appliedenergistics2:smooth_sky_stone_block@0"
            ]
        },
        {
            "x": 2,
            "y": -4,
            "z": 16,
            "elements": [
                "minecraft:concrete@7"
            ]
        },
        {
            "x": 0,
            "y": 3,
            "z": 15,
            "elements": [
                "avaritia:block_resource@0"
            ]
        },
        {
            "x": 4,
            "y": 1,
            "z": 17,
            "elements": [
                "appliedenergistics2:smooth_sky_stone_stairs@1"
            ]
        },
        {
            "x": -1,
            "y": -1,
            "z": 34,
            "elements": [
                "contenttweaker:starmachineblock@0"
            ]
        },
        {
            "x": 0,
            "y": 0,
            "z": 15,
            "elements": [
                "mekanism:glowplasticblock@11"
            ]
        },
        {
            "x": 2,
            "y": -2,
            "z": 15,
            "elements": [
                "avaritia:block_resource@0"
            ]
        },
        {
            "x": 1,
            "y": 1,
            "z": 7,
            "elements": [
                "appliedenergistics2:smooth_sky_stone_stairs@1"
            ]
        },
        {
            "x": 0,
            "y": 2,
            "z": 34,
            "elements": [
                "actuallyadditions:block_quartz_slab@0"
            ]
        },
        {
            "x": 0,
            "y": -2,
            "z": 30,
            "elements": [
                "actuallyadditions:block_quartz_slab@1"
            ]
        },
        {
            "x": -3,
            "y": 6,
            "z": 15,
            "elements": [
                "avaritia:block_resource@0"
            ]
        },
        {
            "x": 3,
            "y": 1,
            "z": 15,
            "elements": [
                "avaritia:block_resource@0"
            ]
        },
        {
            "x": -8,
            "y": -1,
            "z": 14,
            "elements": [
                "appliedenergistics2:smooth_sky_stone_block@0"
            ]
        },
        {
            "x": 1,
            "y": -2,
            "z": 20,
            "elements": [
                "minecraft:concrete@7"
            ]
        },
        {
            "x": -3,
            "y": 4,
            "z": 15,
            "elements": [
                "avaritia:block_resource@0"
            ]
        },
        {
            "x": 1,
            "y": 5,
            "z": 17,
            "elements": [
                "appliedenergistics2:smooth_sky_stone_stairs@1"
            ]
        },
        {
            "x": -9,
            "y": -10,
            "z": 18,
            "elements": [
                "minecraft:stained_glass@4"
            ]
        },
        {
            "x": 5,
            "y": -3,
            "z": 15,
            "elements": [
                "avaritia:block_resource@0"
            ]
        },
        {
            "x": 2,
            "y": -1,
            "z": 15,
            "elements": [
                "avaritia:block_resource@0"
            ]
        },
        {
            "x": 3,
            "y": 0,
            "z": 15,
            "elements": [
                "avaritia:block_resource@0"
            ]
        },
        {
            "x": 0,
            "y": 2,
            "z": 15,
            "elements": [
                "avaritia:block_resource@0"
            ]
        },
        {
            "x": 0,
            "y": -11,
            "z": 14,
            "elements": [
                "appliedenergistics2:smooth_sky_stone_block@0"
            ]
        },
        {
            "x": -3,
            "y": 5,
            "z": 15,
            "elements": [
                "avaritia:block_resource@0"
            ]
        },
        {
            "x": -1,
            "y": -2,
            "z": 15,
            "elements": [
                "avaritia:block_resource@0"
            ]
        },
        {
            "x": 0,
            "y": -1,
            "z": 7,
            "elements": [
                "appliedenergistics2:smooth_sky_stone_block@0"
            ]
        },
        {
            "x": -1,
            "y": 2,
            "z": 20,
            "elements": [
                "minecraft:concrete@7"
            ]
        },
        {
            "x": 3,
            "y": -1,
            "z": 17,
            "elements": [
                "contenttweaker:starmachineblock@0"
            ]
        },
        {
            "x": 0,
            "y": 0,
            "z": 34,
            "elements": [
                "mekanism:glowplasticblock@11"
            ]
        },
        {
            "x": -4,
            "y": 0,
            "z": 20,
            "elements": [
                "contenttweaker:starmachineblock@0"
            ]
        },
        {
            "x": -3,
            "y": 3,
            "z": 15,
            "elements": [
                "minecraft:concrete@7"
            ]
        },
        {
            "x": 0,
            "y": 0,
            "z": 6,
            "elements": [
                "mekanism:glowplasticblock@11"
            ]
        },
        {
            "x": -11,
            "y": -12,
            "z": 18,
            "elements": [
                "minecraft:stained_glass@4"
            ]
        },
        {
            "x": 0,
            "y": 0,
            "z": 1,
            "elements": [
                "mekanism:glowplasticblock@11"
            ]
        },
        {
            "x": -7,
            "y": -1,
            "z": 14,
            "elements": [
                "appliedenergistics2:smooth_sky_stone_block@0"
            ]
        },
        {
            "x": 0,
            "y": 4,
            "z": 15,
            "elements": [
                "avaritia:block_resource@0"
            ]
        },
        {
            "x": -7,
            "y": 1,
            "z": 14,
            "elements": [
                "appliedenergistics2:smooth_sky_stone_block@0"
            ]
        },
        {
            "x": -9,
            "y": -8,
            "z": 18,
            "elements": [
                "minecraft:stained_glass@4"
            ]
        },
        {
            "x": -1,
            "y": -1,
            "z": 15,
            "elements": [
                "avaritia:block_resource@0"
            ]
        },
        {
            "x": 0,
            "y": 6,
            "z": 15,
            "elements": [
                "avaritia:block_resource@0"
            ]
        },
        {
            "x": 0,
            "y": 2,
            "z": 22,
            "elements": [
                "avaritia:block_resource@0"
            ]
        },
        {
            "x": 0,
            "y": 5,
            "z": 15,
            "elements": [
                "avaritia:block_resource@0"
            ]
        },
        {
            "x": 1,
            "y": 1,
            "z": 29,
            "elements": [
                "contenttweaker:starmachineblock@0"
            ]
        },
        {
            "x": -3,
            "y": 2,
            "z": 15,
            "elements": [
                "avaritia:block_resource@0"
            ]
        },
        {
            "x": -1,
            "y": 0,
            "z": 13,
            "elements": [
                "appliedenergistics2:smooth_sky_stone_block@0"
            ]
        },
        {
            "x": -1,
            "y": 0,
            "z": 1,

              "elements": [
                "modularmachinery:blockoutputbus",
                "modularmachinery:blockmeitemoutputbus"
            ]
        },
        {
            "x": 6,
            "y": -1,
            "z": 17,
            "elements": [
                "appliedenergistics2:smooth_sky_stone_stairs@5"
            ]
        },
        {
            "x": 0,
            "y": 0,
            "z": 40,
            "elements": [
                "minecraft:end_rod@3"
            ]
        },
        {
            "x": 0,
            "y": -1,
            "z": 12,
            "elements": [
                "appliedenergistics2:smooth_sky_stone_block@0"
            ]
        },
        {
            "x": -1,
            "y": -7,
            "z": 14,
            "elements": [
                "appliedenergistics2:smooth_sky_stone_block@0"
            ]
        },
        {
            "x": 1,
            "y": 0,
            "z": 29,
            "elements": [
                "contenttweaker:starmachineblock@0"
            ]
        },
        {
            "x": 2,
            "y": -6,
            "z": 15,
            "elements": [
                "minecraft:concrete@7"
            ]
        },
        {
            "x": 1,
            "y": 3,
            "z": 17,
            "elements": [
                "contenttweaker:starmachineblock@0"
            ]
        },
        {
            "x": 0,
            "y": 1,
            "z": 40,
            "elements": [
                "appliedenergistics2:smooth_sky_stone_stairs@7"
            ]
        },
        {
            "x": -11,
            "y": -10,
            "z": 18,
            "elements": [
                "minecraft:stained_glass@4"
            ]
        },
        {
            "x": 5,
            "y": -1,
            "z": 22,
            "elements": [
                "actuallyadditions:block_quartz_slab@1"
            ]
        },
        {
            "x": 0,
            "y": -1,
            "z": 29,
            "elements": [
                "contenttweaker:starmachineblock@0"
            ]
        },
        {
            "x": 0,
            "y": -2,
            "z": 18,
            "elements": [
                "avaritia:block_resource@0"
            ]
        },
        {
            "x": -1,
            "y": -9,
            "z": 14,
            "elements": [
                "appliedenergistics2:smooth_sky_stone_block@0"
            ]
        },
        {
            "x": 2,
            "y": -5,
            "z": 15,
            "elements": [
                "minecraft:concrete@7"
            ]
        },
        {
            "x": 9,
            "y": 9,
            "z": 18,
            "elements": [
                "mekanism:glowplasticblock@11"
            ]
        },
        {
            "x": 0,
            "y": -2,
            "z": 29,
            "elements": [
                "actuallyadditions:block_quartz_slab@1"
            ]
        },
        {
            "x": 0,
            "y": 0,
            "z": 22,
            "elements": [
                "minecraft:stained_glass@4"
            ]
        },
        {
            "x": 0,
            "y": 1,
            "z": 15,
            "elements": [
                "avaritia:block_resource@0"
            ]
        },
        {
            "x": -2,
            "y": -2,
            "z": 20,
            "elements": [
                "actuallyadditions:block_quartz_stair@4"
            ]
        },
        {
            "x": 2,
            "y": -4,
            "z": 15,
            "elements": [
                "minecraft:concrete@7"
            ]
        },
        {
            "x": 0,
            "y": 2,
            "z": 40,
            "elements": [
                "appliedenergistics2:smooth_sky_stone_slab@0"
            ]
        },
        {
            "x": -5,
            "y": 6,
            "z": 18,
            "elements": [
                "minecraft:stained_glass@4"
            ]
        },
        {
            "x": -9,
            "y": 1,
            "z": 14,
            "elements": [
                "appliedenergistics2:smooth_sky_stone_block@0"
            ]
        },
        {
            "x": -2,
            "y": 2,
            "z": 18,
            "elements": [
                "mekanism:glowplasticblock@11"
            ]
        },
        {
            "x": 2,
            "y": -3,
            "z": 15,
            "elements": [
                "avaritia:block_resource@0"
            ]
        },
        {
            "x": 1,
            "y": 0,
            "z": 18,
            "elements": [
                "minecraft:concrete@7"
            ]
        },
        {
            "x": -2,
            "y": -1,
            "z": 20,
            "elements": [
                "minecraft:concrete@7"
            ]
        },
        {
            "x": 0,
            "y": 14,
            "z": 15,
            "elements": [
                "avaritia:block_resource@0"
            ]
        },
        {
            "x": 9,
            "y": -8,
            "z": 18,
            "elements": [
                "minecraft:stained_glass@4"
            ]
        },
        {
            "x": 1,
            "y": -7,
            "z": 14,
            "elements": [
                "appliedenergistics2:smooth_sky_stone_block@0"
            ]
        },
        {
            "x": 0,
            "y": 12,
            "z": 16,
            "elements": [
                "minecraft:concrete@7"
            ]
        },
        {
            "x": 0,
            "y": -2,
            "z": 43,
            "elements": [
                "appliedenergistics2:smooth_sky_stone_slab@8"
            ]
        },
        {
            "x": 1,
            "y": 0,
            "z": 5,
            "elements": [
                "appliedenergistics2:smooth_sky_stone_block@0"
            ]
        },
        {
            "x": -1,
            "y": 0,
            "z": 6,
            "elements": [
                "fluid_out"
            ]
        },
        {
            "x": 0,
            "y": 11,
            "z": 15,
            "elements": [
                "minecraft:concrete@7"
            ]
        },
        {
            "x": 1,
            "y": -5,
            "z": 17,
            "elements": [
                "appliedenergistics2:smooth_sky_stone_stairs@1"
            ]
        },
        {
            "x": 0,
            "y": -2,
            "z": 35,
            "elements": [
                "actuallyadditions:block_quartz_slab@1"
            ]
        },
        {
            "x": -2,
            "y": -5,
            "z": 14,
            "elements": [
                "appliedenergistics2:smooth_sky_stone_block@0"
            ]
        },
        {
            "x": 0,
            "y": 13,
            "z": 15,
            "elements": [
                "avaritia:block_resource@0"
            ]
        },
        {
            "x": 0,
            "y": -1,
            "z": 35,
            "elements": [
                "contenttweaker:starmachineblock@0"
            ]
        },
        {
            "x": 15,
            "y": 0,
            "z": 15,
            "elements": [
                "avaritia:block_resource@0"
            ]
        },
        {
            "x": -1,
            "y": 0,
            "z": 23,
            "elements": [
                "minecraft:concrete@7"
            ]
        },
        {
            "x": 1,
            "y": -9,
            "z": 14,
            "elements": [
                "appliedenergistics2:smooth_sky_stone_block@0"
            ]
        },
        {
            "x": 0,
            "y": -1,
            "z": 17,
            "elements": [
                "minecraft:stained_glass@4"
            ]
        },
        {
            "x": 1,
            "y": -3,
            "z": 17,
            "elements": [
                "contenttweaker:starmachineblock@0"
            ]
        },
        {
            "x": -2,
            "y": 0,
            "z": 18,
            "elements": [
                "avaritia:block_resource@0"
            ]
        },
        {
            "x": 1,
            "y": 1,
            "z": 5,
            "elements": [
                "appliedenergistics2:smooth_sky_stone_stairs@1"
            ]
        },
        {
            "x": 3,
            "y": -4,
            "z": 18,
            "elements": [
                "minecraft:stained_glass@4"
            ]
        },
        {
            "x": 1,
            "y": 1,
            "z": 17,
            "elements": [
                "contenttweaker:starmachineblock@0"
            ]
        },
        {
            "x": 0,
            "y": 12,
            "z": 15,
            "elements": [
                "minecraft:concrete@7"
            ]
        },
        {
            "x": 12,
            "y": -12,
            "z": 18,
            "elements": [
                "minecraft:stained_glass@4"
            ]
        },
        {
            "x": 1,
            "y": 0,
            "z": 35,
            "elements": [
                "contenttweaker:starmachineblock@0"
            ]
        },
        {
            "x": 9,
            "y": -10,
            "z": 18,
            "elements": [
                "minecraft:stained_glass@4"
            ]
        },
        {
            "x": 0,
            "y": 10,
            "z": 16,
            "elements": [
                "minecraft:concrete@7"
            ]
        },
        {
            "x": 0,
            "y": 0,
            "z": 47,
            "elements": [
                "minecraft:end_rod@2"
            ]
        },
        {
            "x": 5,
            "y": 1,
            "z": 22,
            "elements": [
                "actuallyadditions:block_quartz_slab@0"
            ]
        },
        {
            "x": 1,
            "y": 1,
            "z": 35,
            "elements": [
                "contenttweaker:starmachineblock@0"
            ]
        },
        {
            "x": 5,
            "y": 0,
            "z": 22,
            "elements": [
                "minecraft:stained_glass@4"
            ]
        },
        {
            "x": 9,
            "y": 2,
            "z": 15,
            "elements": [
                "avaritia:block_resource@0"
            ]
        },
        {
            "x": -5,
            "y": 0,
            "z": 18,
            "elements": [
                "minecraft:end_rod@3"
            ]
        },
        {
            "x": 0,
            "y": -1,
            "z": 5,
            "elements": [
                "appliedenergistics2:smooth_sky_stone_block@0"
            ]
        },
        {
            "x": 0,
            "y": 11,
            "z": 16,
            "elements": [
                "minecraft:concrete@7"
            ]
        },
        {
            "x": 0,
            "y": 2,
            "z": 35,
            "elements": [
                "actuallyadditions:block_quartz_slab@0"
            ]
        },
        {
            "x": -3,
            "y": -2,
            "z": 18,
            "elements": [
                "minecraft:stained_glass@4"
            ]
        },
        {
            "x": 2,
            "y": 0,
            "z": 23,
            "elements": [
                "minecraft:concrete@7"
            ]
        },
        {
            "x": 11,
            "y": -1,
            "z": 15,
            "elements": [
                "avaritia:block_resource@0"
            ]
        },
        {
            "x": -1,
            "y": -1,
            "z": 7,
            "elements": [
                "appliedenergistics2:smooth_sky_stone_stairs@4"
            ]
        },
        {
            "x": 6,
            "y": -6,
            "z": 18,
            "elements": [
                "mekanism:glowplasticblock@11"
            ]
        },
        {
            "x": 0,
            "y": 0,
            "z": 42,
            "elements": [
                "minecraft:end_rod@3"
            ]
        },
        {
            "x": -3,
            "y": -4,
            "z": 18,
            "elements": [
                "minecraft:stained_glass@4"
            ]
        },
        {
            "x": 0,
            "y": 0,
            "z": 35,
            "elements": [
                "mekanism:glowplasticblock@11"
            ]
        },
        {
            "x": 0,
            "y": 7,
            "z": 15,
            "elements": [
                "avaritia:block_resource@0"
            ]
        },
        {
            "x": 3,
            "y": 5,
            "z": 15,
            "elements": [
                "avaritia:block_resource@0"
            ]
        },
        {
            "x": -2,
            "y": 1,
            "z": 17,
            "elements": [
                "contenttweaker:starmachineblock@0"
            ]
        },
        {
            "x": 9,
            "y": 1,
            "z": 16,
            "elements": [
                "minecraft:concrete@7"
            ]
        },
        {
            "x": 0,
            "y": 1,
            "z": 35,
            "elements": [
                "contenttweaker:starmachineblock@0"
            ]
        },
        {
            "x": 0,
            "y": 8,
            "z": 15,
            "elements": [
                "avaritia:block_resource@0"
            ]
        },
        {
            "x": 9,
            "y": 0,
            "z": 16,
            "elements": [
                "avaritia:block_resource@0"
            ]
        },
        {
            "x": 3,
            "y": 6,
            "z": 15,
            "elements": [
                "avaritia:block_resource@0"
            ]
        },
        {
            "x": -1,
            "y": -1,
            "z": 28,
            "elements": [
                "contenttweaker:starmachineblock@0"
            ]
        },
        {
            "x": 3,
            "y": 4,
            "z": 15,
            "elements": [
                "avaritia:block_resource@0"
            ]
        },
        {
            "x": -11,
            "y": 12,
            "z": 18,
            "elements": [
                "minecraft:stained_glass@4"
            ]
        },
        {
            "x": -5,
            "y": -1,
            "z": 20,
            "elements": [
                "contenttweaker:starmachineblock@0"
            ]
        },
        {
            "x": 12,
            "y": 11,
            "z": 18,
            "elements": [
                "minecraft:stained_glass@4"
            ]
        },
        {
            "x": 0,
            "y": 1,
            "z": 14,
            "elements": [
                "minecraft:end_rod@2"
            ]
        },
        {
            "x": 6,
            "y": 2,
            "z": 16,
            "elements": [
                "minecraft:concrete@7"
            ]
        },
        {
            "x": -3,
            "y": 3,
            "z": 14,
            "elements": [
                "appliedenergistics2:smooth_sky_stone_block@0"
            ]
        },
        {
            "x": -11,
            "y": 10,
            "z": 18,
            "elements": [
                "minecraft:stained_glass@4"
            ]
        },
        {
            "x": 3,
            "y": 3,
            "z": 15,
            "elements": [
                "minecraft:concrete@7"
            ]
        },
        {
            "x": -8,
            "y": 8,
            "z": 18,
            "elements": [
                "mekanism:glowplasticblock@11"
            ]
        },
        {
            "x": 12,
            "y": 1,
            "z": 15,
            "elements": [
                "avaritia:block_resource@0"
            ]
        },
        {
            "x": 0,
            "y": 1,
            "z": 7,
            "elements": [
                "appliedenergistics2:smooth_sky_stone_block@0"
            ]
        },
        {
            "x": 0,
            "y": -5,
            "z": 17,
            "elements": [
                "mekanism:glowplasticblock@11"
            ]
        },
        {
            "x": 0,
            "y": 2,
            "z": 42,
            "elements": [
                "appliedenergistics2:smooth_sky_stone_slab@0"
            ]
        },
        {
            "x": 1,
            "y": 2,
            "z": 18,
            "elements": [
                "minecraft:stained_glass@4"
            ]
        },
        {
            "x": 0,
            "y": 9,
            "z": 15,
            "elements": [
                "avaritia:block_resource@0"
            ]
        },
        {
            "x": 3,
            "y": 2,
            "z": 15,
            "elements": [
                "avaritia:block_resource@0"
            ]
        },
        {
            "x": 12,
            "y": 0,
            "z": 15,
            "elements": [
                "minecraft:concrete@7"
            ]
        },
        {
            "x": -5,
            "y": 4,
            "z": 18,
            "elements": [
                "minecraft:stained_glass@4"
            ]
        },
        {
            "x": 0,
            "y": -7,
            "z": 17,
            "elements": [
                "contenttweaker:starmachineblock@0"
            ]
        },
        {
            "x": 0,
            "y": 1,
            "z": 42,
            "elements": [
                "appliedenergistics2:smooth_sky_stone_stairs@7"
            ]
        },
        {
            "x": -1,
            "y": -1,
            "z": 35,
            "elements": [
                "contenttweaker:starmachineblock@0"
            ]
        },
        {
            "x": 0,
            "y": 10,
            "z": 15,
            "elements": [
                "minecraft:concrete@7"
            ]
        },
        {
            "x": -3,
            "y": -1,
            "z": 17,
            "elements": [
                "contenttweaker:starmachineblock@0"
            ]
        },
        {
            "x": 3,
            "y": -2,
            "z": 18,
            "elements": [
                "minecraft:stained_glass@4"
            ]
        },
        {
            "x": -5,
            "y": 1,
            "z": 24,
            "elements": [
                "actuallyadditions:block_quartz_slab@0"
            ]
        },
        {
            "x": 8,
            "y": -1,
